I0530 00:00:21.477240       1 wrap.go:47] GET /healthz: (99.711µs) 200 [kube-probe/1.15+ 127.0.0.1:44316]
I0530 00:00:31.476633       1 wrap.go:47] GET /healthz: (81.638µs) 200 [kube-probe/1.15+ 127.0.0.1:44350]
I0530 00:00:41.476679       1 wrap.go:47] GET /healthz: (74.22µs) 200 [kube-probe/1.15+ 127.0.0.1:44384]
I0530 00:00:51.477054       1 wrap.go:47] GET /healthz: (131.919µs) 200 [kube-probe/1.15+ 127.0.0.1:44416]
I0530 00:01:01.476759       1 wrap.go:47] GET /healthz: (76.783µs) 200 [kube-probe/1.15+ 127.0.0.1:44466]
I0530 00:01:03.767620       1 reflector.go:384] k8s.io/client-go/informers/factory.go:133: Watch close - *v1.ReplicationController total 5 items received
I0530 00:01:11.476601       1 wrap.go:47] GET /healthz: (63.545µs) 200 [kube-probe/1.15+ 127.0.0.1:44502]
I0530 00:01:21.476676       1 wrap.go:47] GET /healthz: (93.135µs) 200 [kube-probe/1.15+ 127.0.0.1:44538]
I0530 00:01:31.476938       1 wrap.go:47] GET /healthz: (58.992µs) 200 [kube-probe/1.15+ 127.0.0.1:44576]
I0530 00:01:32.762783       1 reflector.go:384] k8s.io/client-go/informers/factory.go:133: Watch close - *v1.Node total 76 items received
I0530 00:01:41.476735       1 wrap.go:47] GET /healthz: (121.233µs) 200 [kube-probe/1.15+ 127.0.0.1:44610]
I0530 00:01:51.476653       1 wrap.go:47] GET /healthz: (67.114µs) 200 [kube-probe/1.15+ 127.0.0.1:44644]
I0530 00:02:01.476765       1 wrap.go:47] GET /healthz: (52.909µs) 200 [kube-probe/1.15+ 127.0.0.1:44692]
I0530 00:02:02.810380       1 reflector.go:384] k8s.io/client-go/informers/factory.go:133: Watch close - *v1.PersistentVolumeClaim total 0 items received
I0530 00:02:09.467737       1 scheduling_queue.go:895] About to try and schedule pod container-runtime-355/image-pull-teste249573a-04f7-4463-bc0a-5ff80208a22a
I0530 00:02:09.467750       1 scheduler.go:454] Attempting to schedule pod: container-runtime-355/image-pull-teste249573a-04f7-4463-bc0a-5ff80208a22a
I0530 00:02:09.468185       1 scheduler_binder.go:255] AssumePodVolumes for pod "container-runtime-355/image-pull-teste249573a-04f7-4463-bc0a-5ff80208a22a", node "e2e-test-peterhornyack-windows-node-group-1vjk"
I0530 00:02:09.468198       1 scheduler_binder.go:265] AssumePodVolumes for pod "container-runtime-355/image-pull-teste249573a-04f7-4463-bc0a-5ff80208a22a", node "e2e-test-peterhornyack-windows-node-group-1vjk": all PVCs bound and nothing to do
I0530 00:02:09.468250       1 factory.go:734] Attempting to bind image-pull-teste249573a-04f7-4463-bc0a-5ff80208a22a to e2e-test-peterhornyack-windows-node-group-1vjk
I0530 00:02:09.481720       1 scheduler.go:575] pod container-runtime-355/image-pull-teste249573a-04f7-4463-bc0a-5ff80208a22a is bound successfully on node e2e-test-peterhornyack-windows-node-group-1vjk, 6 nodes evaluated, 3 nodes were found feasible
I0530 00:02:11.476998       1 wrap.go:47] GET /healthz: (65.652µs) 200 [kube-probe/1.15+ 127.0.0.1:44728]
I0530 00:02:20.857182       1 scheduling_queue.go:895] About to try and schedule pod provisioning-6812/pvc-volume-tester-writer-xr8z7
I0530 00:02:20.857194       1 scheduler.go:454] Attempting to schedule pod: provisioning-6812/pvc-volume-tester-writer-xr8z7
I0530 00:02:20.857321       1 predicates.go:452] PVC provisioning-6812/pvc-j5kkr is not bound, assuming PVC matches predicate when counting limits
I0530 00:02:20.857414       1 predicates.go:452] PVC provisioning-6812/pvc-j5kkr is not bound, assuming PVC matches predicate when counting limits
I0530 00:02:20.857428       1 predicates.go:452] PVC provisioning-6812/pvc-j5kkr is not bound, assuming PVC matches predicate when counting limits
I0530 00:02:20.857449       1 scheduler_binder.go:683] No matching volumes for Pod "provisioning-6812/pvc-volume-tester-writer-xr8z7", PVC "provisioning-6812/pvc-j5kkr" on node "e2e-test-peterhornyack-windows-node-group-9q9v"
I0530 00:02:20.857507       1 scheduler_binder.go:738] Provisioning for claims of pod "provisioning-6812/pvc-volume-tester-writer-xr8z7" that has no matching volumes on node "e2e-test-peterhornyack-windows-node-group-9q9v" ...
I0530 00:02:20.857551       1 predicates.go:452] PVC provisioning-6812/pvc-j5kkr is not bound, assuming PVC matches predicate when counting limits
I0530 00:02:20.857586       1 predicates.go:452] PVC provisioning-6812/pvc-j5kkr is not bound, assuming PVC matches predicate when counting limits
I0530 00:02:20.857597       1 predicates.go:452] PVC provisioning-6812/pvc-j5kkr is not bound, assuming PVC matches predicate when counting limits
I0530 00:02:20.857606       1 scheduler_binder.go:683] No matching volumes for Pod "provisioning-6812/pvc-volume-tester-writer-xr8z7", PVC "provisioning-6812/pvc-j5kkr" on node "e2e-test-peterhornyack-windows-node-group-1vjk"
I0530 00:02:20.857614       1 scheduler_binder.go:738] Provisioning for claims of pod "provisioning-6812/pvc-volume-tester-writer-xr8z7" that has no matching volumes on node "e2e-test-peterhornyack-windows-node-group-1vjk" ...
I0530 00:02:20.857626       1 predicates.go:452] PVC provisioning-6812/pvc-j5kkr is not bound, assuming PVC matches predicate when counting limits
I0530 00:02:20.857641       1 predicates.go:452] PVC provisioning-6812/pvc-j5kkr is not bound, assuming PVC matches predicate when counting limits
I0530 00:02:20.857662       1 predicates.go:452] PVC provisioning-6812/pvc-j5kkr is not bound, assuming PVC matches predicate when counting limits
I0530 00:02:20.857670       1 scheduler_binder.go:683] No matching volumes for Pod "provisioning-6812/pvc-volume-tester-writer-xr8z7", PVC "provisioning-6812/pvc-j5kkr" on node "e2e-test-peterhornyack-windows-node-group-jpxd"
I0530 00:02:20.857684       1 scheduler_binder.go:738] Provisioning for claims of pod "provisioning-6812/pvc-volume-tester-writer-xr8z7" that has no matching volumes on node "e2e-test-peterhornyack-windows-node-group-jpxd" ...
I0530 00:02:20.857851       1 scheduler_binder.go:255] AssumePodVolumes for pod "provisioning-6812/pvc-volume-tester-writer-xr8z7", node "e2e-test-peterhornyack-windows-node-group-jpxd"
I0530 00:02:20.857868       1 scheduler_assume_cache.go:319] Assumed v1.PersistentVolumeClaim "provisioning-6812/pvc-j5kkr", version 9194
I0530 00:02:20.857920       1 scheduler_binder.go:330] BindPodVolumes for pod "provisioning-6812/pvc-volume-tester-writer-xr8z7", node "e2e-test-peterhornyack-windows-node-group-jpxd"
I0530 00:02:21.476850       1 wrap.go:47] GET /healthz: (49.288µs) 200 [kube-probe/1.15+ 127.0.0.1:44768]
I0530 00:02:21.757377       1 cache.go:643] Couldn't expire cache for pod provisioning-6812/pvc-volume-tester-writer-xr8z7. Binding is still in progress.
I0530 00:02:22.757616       1 cache.go:643] Couldn't expire cache for pod provisioning-6812/pvc-volume-tester-writer-xr8z7. Binding is still in progress.
I0530 00:02:23.758023       1 cache.go:643] Couldn't expire cache for pod provisioning-6812/pvc-volume-tester-writer-xr8z7. Binding is still in progress.
I0530 00:02:23.865013       1 scheduler_binder.go:545] All PVCs for pod "provisioning-6812/pvc-volume-tester-writer-xr8z7" are bound
I0530 00:02:23.865043       1 factory.go:734] Attempting to bind pvc-volume-tester-writer-xr8z7 to e2e-test-peterhornyack-windows-node-group-jpxd
I0530 00:02:23.875164       1 scheduler.go:575] pod provisioning-6812/pvc-volume-tester-writer-xr8z7 is bound successfully on node e2e-test-peterhornyack-windows-node-group-jpxd, 6 nodes evaluated, 3 nodes were found feasible
I0530 00:02:31.476988       1 wrap.go:47] GET /healthz: (75.11µs) 200 [kube-probe/1.15+ 127.0.0.1:44806]
I0530 00:02:41.476700       1 wrap.go:47] GET /healthz: (65.057µs) 200 [kube-probe/1.15+ 127.0.0.1:44842]
I0530 00:02:51.476739       1 wrap.go:47] GET /healthz: (68.495µs) 200 [kube-probe/1.15+ 127.0.0.1:44874]
I0530 00:02:57.811247       1 reflector.go:384] k8s.io/client-go/informers/factory.go:133: Watch close - *v1.PersistentVolume total 2 items received
I0530 00:03:01.476707       1 wrap.go:47] GET /healthz: (82.492µs) 200 [kube-probe/1.15+ 127.0.0.1:45054]
I0530 00:03:11.477043       1 wrap.go:47] GET /healthz: (114.822µs) 200 [kube-probe/1.15+ 127.0.0.1:45092]
I0530 00:03:21.476762       1 wrap.go:47] GET /healthz: (54.209µs) 200 [kube-probe/1.15+ 127.0.0.1:45130]
I0530 00:03:31.477144       1 wrap.go:47] GET /healthz: (67.271µs) 200 [kube-probe/1.15+ 127.0.0.1:45164]
I0530 00:03:41.476617       1 wrap.go:47] GET /healthz: (62.626µs) 200 [kube-probe/1.15+ 127.0.0.1:45198]
I0530 00:03:51.476651       1 wrap.go:47] GET /healthz: (67.155µs) 200 [kube-probe/1.15+ 127.0.0.1:45230]
I0530 00:03:59.492824       1 scheduling_queue.go:895] About to try and schedule pod kubectl-2007/redis-master-25c8n
I0530 00:03:59.492838       1 scheduler.go:454] Attempting to schedule pod: kubectl-2007/redis-master-25c8n
I0530 00:03:59.496719       1 scheduler_binder.go:255] AssumePodVolumes for pod "kubectl-2007/redis-master-25c8n", node "e2e-test-peterhornyack-windows-node-group-1vjk"
I0530 00:03:59.496734       1 scheduler_binder.go:265] AssumePodVolumes for pod "kubectl-2007/redis-master-25c8n", node "e2e-test-peterhornyack-windows-node-group-1vjk": all PVCs bound and nothing to do
I0530 00:03:59.496800       1 factory.go:734] Attempting to bind redis-master-25c8n to e2e-test-peterhornyack-windows-node-group-1vjk
I0530 00:03:59.512153       1 scheduler.go:575] pod kubectl-2007/redis-master-25c8n is bound successfully on node e2e-test-peterhornyack-windows-node-group-1vjk, 6 nodes evaluated, 3 nodes were found feasible
I0530 00:04:01.476777       1 wrap.go:47] GET /healthz: (54.782µs) 200 [kube-probe/1.15+ 127.0.0.1:45280]
I0530 00:04:09.783144       1 reflector.go:384] k8s.io/client-go/informers/factory.go:133: Watch close - *v1.StorageClass total 2 items received
I0530 00:04:11.476740       1 wrap.go:47] GET /healthz: (67.336µs) 200 [kube-probe/1.15+ 127.0.0.1:45314]
I0530 00:04:16.800510       1 reflector.go:384] k8s.io/client-go/informers/factory.go:133: Watch close - *v1beta1.PodDisruptionBudget total 0 items received
I0530 00:04:20.805451       1 reflector.go:384] k8s.io/client-go/informers/factory.go:133: Watch close - *v1.ReplicaSet total 0 items received
I0530 00:04:21.477072       1 wrap.go:47] GET /healthz: (67.022µs) 200 [kube-probe/1.15+ 127.0.0.1:45350]
I0530 00:04:31.476416       1 wrap.go:47] GET /healthz: (72.083µs) 200 [kube-probe/1.15+ 127.0.0.1:45384]
I0530 00:04:37.142367       1 scheduling_queue.go:895] About to try and schedule pod kubectl-6303/e2e-test-nginx-deployment-54fc8fc46-h8wbl
I0530 00:04:37.142380       1 scheduler.go:454] Attempting to schedule pod: kubectl-6303/e2e-test-nginx-deployment-54fc8fc46-h8wbl
I0530 00:04:37.143840       1 scheduler_binder.go:255] AssumePodVolumes for pod "kubectl-6303/e2e-test-nginx-deployment-54fc8fc46-h8wbl", node "e2e-test-peterhornyack-windows-node-group-jpxd"
I0530 00:04:37.143853       1 scheduler_binder.go:265] AssumePodVolumes for pod "kubectl-6303/e2e-test-nginx-deployment-54fc8fc46-h8wbl", node "e2e-test-peterhornyack-windows-node-group-jpxd": all PVCs bound and nothing to do
I0530 00:04:37.143887       1 factory.go:734] Attempting to bind e2e-test-nginx-deployment-54fc8fc46-h8wbl to e2e-test-peterhornyack-windows-node-group-jpxd
I0530 00:04:37.159085       1 scheduler.go:575] pod kubectl-6303/e2e-test-nginx-deployment-54fc8fc46-h8wbl is bound successfully on node e2e-test-peterhornyack-windows-node-group-jpxd, 6 nodes evaluated, 3 nodes were found feasible
I0530 00:04:41.476820       1 wrap.go:47] GET /healthz: (65.999µs) 200 [kube-probe/1.15+ 127.0.0.1:45420]
I0530 00:04:45.523999       1 scheduling_queue.go:895] About to try and schedule pod gc-2790/simpletest.rc-fksqb
I0530 00:04:45.524024       1 scheduler.go:454] Attempting to schedule pod: gc-2790/simpletest.rc-fksqb
I0530 00:04:45.524350       1 scheduler_binder.go:255] AssumePodVolumes for pod "gc-2790/simpletest.rc-fksqb", node "e2e-test-peterhornyack-windows-node-group-jpxd"
I0530 00:04:45.524360       1 scheduler_binder.go:265] AssumePodVolumes for pod "gc-2790/simpletest.rc-fksqb", node "e2e-test-peterhornyack-windows-node-group-jpxd": all PVCs bound and nothing to do
I0530 00:04:45.524397       1 factory.go:734] Attempting to bind simpletest.rc-fksqb to e2e-test-peterhornyack-windows-node-group-jpxd
I0530 00:04:45.541224       1 scheduling_queue.go:895] About to try and schedule pod gc-2790/simpletest.rc-bcfvp
I0530 00:04:45.541235       1 scheduler.go:454] Attempting to schedule pod: gc-2790/simpletest.rc-bcfvp
I0530 00:04:45.546053       1 scheduler_binder.go:255] AssumePodVolumes for pod "gc-2790/simpletest.rc-bcfvp", node "e2e-test-peterhornyack-windows-node-group-jpxd"
I0530 00:04:45.546068       1 scheduler_binder.go:265] AssumePodVolumes for pod "gc-2790/simpletest.rc-bcfvp", node "e2e-test-peterhornyack-windows-node-group-jpxd": all PVCs bound and nothing to do
I0530 00:04:45.546108       1 factory.go:734] Attempting to bind simpletest.rc-bcfvp to e2e-test-peterhornyack-windows-node-group-jpxd
I0530 00:04:45.549926       1 scheduler.go:575] pod gc-2790/simpletest.rc-fksqb is bound successfully on node e2e-test-peterhornyack-windows-node-group-jpxd, 6 nodes evaluated, 3 nodes were found feasible
I0530 00:04:45.550206       1 scheduling_queue.go:895] About to try and schedule pod gc-2790/simpletest.rc-ndzlq
I0530 00:04:45.550213       1 scheduler.go:454] Attempting to schedule pod: gc-2790/simpletest.rc-ndzlq
I0530 00:04:45.554500       1 scheduler_binder.go:255] AssumePodVolumes for pod "gc-2790/simpletest.rc-ndzlq", node "e2e-test-peterhornyack-windows-node-group-jpxd"
I0530 00:04:45.554527       1 scheduler_binder.go:265] AssumePodVolumes for pod "gc-2790/simpletest.rc-ndzlq", node "e2e-test-peterhornyack-windows-node-group-jpxd": all PVCs bound and nothing to do
I0530 00:04:45.554588       1 factory.go:734] Attempting to bind simpletest.rc-ndzlq to e2e-test-peterhornyack-windows-node-group-jpxd
I0530 00:04:45.570310       1 scheduling_queue.go:895] About to try and schedule pod gc-2790/simpletest.rc-bzbxg
I0530 00:04:45.570321       1 scheduler.go:454] Attempting to schedule pod: gc-2790/simpletest.rc-bzbxg
I0530 00:04:45.570641       1 scheduler_binder.go:255] AssumePodVolumes for pod "gc-2790/simpletest.rc-bzbxg", node "e2e-test-peterhornyack-windows-node-group-jpxd"
I0530 00:04:45.570651       1 scheduler_binder.go:265] AssumePodVolumes for pod "gc-2790/simpletest.rc-bzbxg", node "e2e-test-peterhornyack-windows-node-group-jpxd": all PVCs bound and nothing to do
I0530 00:04:45.570681       1 factory.go:734] Attempting to bind simpletest.rc-bzbxg to e2e-test-peterhornyack-windows-node-group-jpxd
I0530 00:04:45.588516       1 scheduler.go:575] pod gc-2790/simpletest.rc-ndzlq is bound successfully on node e2e-test-peterhornyack-windows-node-group-jpxd, 6 nodes evaluated, 3 nodes were found feasible
I0530 00:04:45.588579       1 scheduler.go:575] pod gc-2790/simpletest.rc-bcfvp is bound successfully on node e2e-test-peterhornyack-windows-node-group-jpxd, 6 nodes evaluated, 3 nodes were found feasible
I0530 00:04:45.588922       1 scheduling_queue.go:895] About to try and schedule pod gc-2790/simpletest.rc-fzkdz
I0530 00:04:45.588928       1 scheduler.go:454] Attempting to schedule pod: gc-2790/simpletest.rc-fzkdz
I0530 00:04:45.589246       1 scheduler_binder.go:255] AssumePodVolumes for pod "gc-2790/simpletest.rc-fzkdz", node "e2e-test-peterhornyack-windows-node-group-9q9v"
I0530 00:04:45.589255       1 scheduler_binder.go:265] AssumePodVolumes for pod "gc-2790/simpletest.rc-fzkdz", node "e2e-test-peterhornyack-windows-node-group-9q9v": all PVCs bound and nothing to do
I0530 00:04:45.590555       1 factory.go:734] Attempting to bind simpletest.rc-fzkdz to e2e-test-peterhornyack-windows-node-group-9q9v
I0530 00:04:45.593930       1 scheduling_queue.go:895] About to try and schedule pod gc-2790/simpletest.rc-vrwbd
I0530 00:04:45.593945       1 scheduler.go:454] Attempting to schedule pod: gc-2790/simpletest.rc-vrwbd
I0530 00:04:45.594245       1 scheduler_binder.go:255] AssumePodVolumes for pod "gc-2790/simpletest.rc-vrwbd", node "e2e-test-peterhornyack-windows-node-group-1vjk"
I0530 00:04:45.594254       1 scheduler_binder.go:265] AssumePodVolumes for pod "gc-2790/simpletest.rc-vrwbd", node "e2e-test-peterhornyack-windows-node-group-1vjk": all PVCs bound and nothing to do
I0530 00:04:45.594279       1 factory.go:734] Attempting to bind simpletest.rc-vrwbd to e2e-test-peterhornyack-windows-node-group-1vjk
I0530 00:04:45.598501       1 scheduling_queue.go:895] About to try and schedule pod gc-2790/simpletest.rc-mddk7
I0530 00:04:45.598520       1 scheduler.go:454] Attempting to schedule pod: gc-2790/simpletest.rc-mddk7
I0530 00:04:45.598794       1 scheduler_binder.go:255] AssumePodVolumes for pod "gc-2790/simpletest.rc-mddk7", node "e2e-test-peterhornyack-windows-node-group-jpxd"
I0530 00:04:45.598803       1 scheduler_binder.go:265] AssumePodVolumes for pod "gc-2790/simpletest.rc-mddk7", node "e2e-test-peterhornyack-windows-node-group-jpxd": all PVCs bound and nothing to do
I0530 00:04:45.598835       1 factory.go:734] Attempting to bind simpletest.rc-mddk7 to e2e-test-peterhornyack-windows-node-group-jpxd
I0530 00:04:45.608850       1 scheduler.go:575] pod gc-2790/simpletest.rc-bzbxg is bound successfully on node e2e-test-peterhornyack-windows-node-group-jpxd, 6 nodes evaluated, 3 nodes were found feasible
I0530 00:04:45.626632       1 scheduling_queue.go:895] About to try and schedule pod gc-2790/simpletest.rc-wt2wg
I0530 00:04:45.626644       1 scheduler.go:454] Attempting to schedule pod: gc-2790/simpletest.rc-wt2wg
I0530 00:04:45.631580       1 scheduler_binder.go:255] AssumePodVolumes for pod "gc-2790/simpletest.rc-wt2wg", node "e2e-test-peterhornyack-windows-node-group-jpxd"
I0530 00:04:45.631595       1 scheduler_binder.go:265] AssumePodVolumes for pod "gc-2790/simpletest.rc-wt2wg", node "e2e-test-peterhornyack-windows-node-group-jpxd": all PVCs bound and nothing to do
I0530 00:04:45.631637       1 factory.go:734] Attempting to bind simpletest.rc-wt2wg to e2e-test-peterhornyack-windows-node-group-jpxd
I0530 00:04:45.633609       1 scheduling_queue.go:895] About to try and schedule pod gc-2790/simpletest.rc-v4wz6
I0530 00:04:45.633621       1 scheduler.go:454] Attempting to schedule pod: gc-2790/simpletest.rc-v4wz6
I0530 00:04:45.635973       1 scheduler_binder.go:255] AssumePodVolumes for pod "gc-2790/simpletest.rc-v4wz6", node "e2e-test-peterhornyack-windows-node-group-jpxd"
I0530 00:04:45.635985       1 scheduler_binder.go:265] AssumePodVolumes for pod "gc-2790/simpletest.rc-v4wz6", node "e2e-test-peterhornyack-windows-node-group-jpxd": all PVCs bound and nothing to do
I0530 00:04:45.636014       1 factory.go:734] Attempting to bind simpletest.rc-v4wz6 to e2e-test-peterhornyack-windows-node-group-jpxd
I0530 00:04:45.643988       1 scheduler.go:575] pod gc-2790/simpletest.rc-fzkdz is bound successfully on node e2e-test-peterhornyack-windows-node-group-9q9v, 6 nodes evaluated, 3 nodes were found feasible
I0530 00:04:45.644325       1 scheduler.go:575] pod gc-2790/simpletest.rc-mddk7 is bound successfully on node e2e-test-peterhornyack-windows-node-group-jpxd, 6 nodes evaluated, 3 nodes were found feasible
I0530 00:04:45.645410       1 scheduler.go:575] pod gc-2790/simpletest.rc-vrwbd is bound successfully on node e2e-test-peterhornyack-windows-node-group-1vjk, 6 nodes evaluated, 3 nodes were found feasible
I0530 00:04:45.645571       1 scheduling_queue.go:895] About to try and schedule pod gc-2790/simpletest.rc-zx48r
I0530 00:04:45.645585       1 scheduler.go:454] Attempting to schedule pod: gc-2790/simpletest.rc-zx48r
I0530 00:04:45.649957       1 scheduler_binder.go:255] AssumePodVolumes for pod "gc-2790/simpletest.rc-zx48r", node "e2e-test-peterhornyack-windows-node-group-jpxd"
I0530 00:04:45.649971       1 scheduler_binder.go:265] AssumePodVolumes for pod "gc-2790/simpletest.rc-zx48r", node "e2e-test-peterhornyack-windows-node-group-jpxd": all PVCs bound and nothing to do
I0530 00:04:45.650003       1 factory.go:734] Attempting to bind simpletest.rc-zx48r to e2e-test-peterhornyack-windows-node-group-jpxd
I0530 00:04:45.659911       1 scheduler.go:575] pod gc-2790/simpletest.rc-wt2wg is bound successfully on node e2e-test-peterhornyack-windows-node-group-jpxd, 6 nodes evaluated, 3 nodes were found feasible
I0530 00:04:45.684801       1 scheduler.go:575] pod gc-2790/simpletest.rc-zx48r is bound successfully on node e2e-test-peterhornyack-windows-node-group-jpxd, 6 nodes evaluated, 3 nodes were found feasible
I0530 00:04:45.689327       1 scheduler.go:575] pod gc-2790/simpletest.rc-v4wz6 is bound successfully on node e2e-test-peterhornyack-windows-node-group-jpxd, 6 nodes evaluated, 3 nodes were found feasible
I0530 00:04:51.476705       1 wrap.go:47] GET /healthz: (62.14µs) 200 [kube-probe/1.15+ 127.0.0.1:45452]
I0530 00:04:59.821144       1 scheduling_queue.go:895] About to try and schedule pod container-probe-2368/liveness-http
I0530 00:04:59.821169       1 scheduler.go:454] Attempting to schedule pod: container-probe-2368/liveness-http
I0530 00:04:59.821516       1 scheduler_binder.go:255] AssumePodVolumes for pod "container-probe-2368/liveness-http", node "e2e-test-peterhornyack-windows-node-group-9q9v"
I0530 00:04:59.821527       1 scheduler_binder.go:265] AssumePodVolumes for pod "container-probe-2368/liveness-http", node "e2e-test-peterhornyack-windows-node-group-9q9v": all PVCs bound and nothing to do
I0530 00:04:59.821578       1 factory.go:734] Attempting to bind liveness-http to e2e-test-peterhornyack-windows-node-group-9q9v
I0530 00:04:59.827719       1 scheduler.go:575] pod container-probe-2368/liveness-http is bound successfully on node e2e-test-peterhornyack-windows-node-group-9q9v, 6 nodes evaluated, 3 nodes were found feasible
I0530 00:05:01.476955       1 wrap.go:47] GET /healthz: (64.898µs) 200 [kube-probe/1.15+ 127.0.0.1:45502]
I0530 00:05:11.476742       1 wrap.go:47] GET /healthz: (65.183µs) 200 [kube-probe/1.15+ 127.0.0.1:45536]
I0530 00:05:21.476551       1 wrap.go:47] GET /healthz: (85.111µs) 200 [kube-probe/1.15+ 127.0.0.1:45572]
I0530 00:05:31.477102       1 wrap.go:47] GET /healthz: (72.124µs) 200 [kube-probe/1.15+ 127.0.0.1:45608]
I0530 00:05:41.476604       1 wrap.go:47] GET /healthz: (72.317µs) 200 [kube-probe/1.15+ 127.0.0.1:45642]
I0530 00:05:42.808852       1 scheduling_queue.go:895] About to try and schedule pod pod-network-test-9417/netserver-0
I0530 00:05:42.808863       1 scheduler.go:454] Attempting to schedule pod: pod-network-test-9417/netserver-0
I0530 00:05:42.809166       1 scheduler_binder.go:255] AssumePodVolumes for pod "pod-network-test-9417/netserver-0", node "e2e-test-peterhornyack-windows-node-group-1vjk"
I0530 00:05:42.809179       1 scheduler_binder.go:265] AssumePodVolumes for pod "pod-network-test-9417/netserver-0", node "e2e-test-peterhornyack-windows-node-group-1vjk": all PVCs bound and nothing to do
I0530 00:05:42.809242       1 factory.go:734] Attempting to bind netserver-0 to e2e-test-peterhornyack-windows-node-group-1vjk
I0530 00:05:42.814644       1 scheduler.go:575] pod pod-network-test-9417/netserver-0 is bound successfully on node e2e-test-peterhornyack-windows-node-group-1vjk, 6 nodes evaluated, 1 nodes were found feasible
I0530 00:05:42.854306       1 scheduling_queue.go:895] About to try and schedule pod pod-network-test-9417/netserver-1
I0530 00:05:42.854318       1 scheduler.go:454] Attempting to schedule pod: pod-network-test-9417/netserver-1
I0530 00:05:42.854533       1 scheduler_binder.go:255] AssumePodVolumes for pod "pod-network-test-9417/netserver-1", node "e2e-test-peterhornyack-windows-node-group-jpxd"
I0530 00:05:42.854555       1 scheduler_binder.go:265] AssumePodVolumes for pod "pod-network-test-9417/netserver-1", node "e2e-test-peterhornyack-windows-node-group-jpxd": all PVCs bound and nothing to do
I0530 00:05:42.854587       1 factory.go:734] Attempting to bind netserver-1 to e2e-test-peterhornyack-windows-node-group-jpxd
I0530 00:05:42.863112       1 scheduler.go:575] pod pod-network-test-9417/netserver-1 is bound successfully on node e2e-test-peterhornyack-windows-node-group-jpxd, 6 nodes evaluated, 1 nodes were found feasible
I0530 00:05:42.899454       1 scheduling_queue.go:895] About to try and schedule pod pod-network-test-9417/netserver-2
I0530 00:05:42.899478       1 scheduler.go:454] Attempting to schedule pod: pod-network-test-9417/netserver-2
I0530 00:05:42.899699       1 scheduler_binder.go:255] AssumePodVolumes for pod "pod-network-test-9417/netserver-2", node "e2e-test-peterhornyack-windows-node-group-9q9v"
I0530 00:05:42.899709       1 scheduler_binder.go:265] AssumePodVolumes for pod "pod-network-test-9417/netserver-2", node "e2e-test-peterhornyack-windows-node-group-9q9v": all PVCs bound and nothing to do
I0530 00:05:42.899743       1 factory.go:734] Attempting to bind netserver-2 to e2e-test-peterhornyack-windows-node-group-9q9v
I0530 00:05:42.906841       1 scheduler.go:575] pod pod-network-test-9417/netserver-2 is bound successfully on node e2e-test-peterhornyack-windows-node-group-9q9v, 6 nodes evaluated, 1 nodes were found feasible
I0530 00:05:51.479337       1 wrap.go:47] GET /healthz: (79.497µs) 200 [kube-probe/1.15+ 127.0.0.1:45676]
I0530 00:06:01.476958       1 wrap.go:47] GET /healthz: (82.651µs) 200 [kube-probe/1.15+ 127.0.0.1:45724]
I0530 00:06:07.239358       1 scheduling_queue.go:895] About to try and schedule pod pod-network-test-9417/test-container-pod
I0530 00:06:07.239513       1 scheduler.go:454] Attempting to schedule pod: pod-network-test-9417/test-container-pod
I0530 00:06:07.239921       1 scheduler_binder.go:255] AssumePodVolumes for pod "pod-network-test-9417/test-container-pod", node "e2e-test-peterhornyack-windows-node-group-1vjk"
I0530 00:06:07.239932       1 scheduler_binder.go:265] AssumePodVolumes for pod "pod-network-test-9417/test-container-pod", node "e2e-test-peterhornyack-windows-node-group-1vjk": all PVCs bound and nothing to do
I0530 00:06:07.239990       1 factory.go:734] Attempting to bind test-container-pod to e2e-test-peterhornyack-windows-node-group-1vjk
I0530 00:06:07.246736       1 scheduler.go:575] pod pod-network-test-9417/test-container-pod is bound successfully on node e2e-test-peterhornyack-windows-node-group-1vjk, 6 nodes evaluated, 3 nodes were found feasible
I0530 00:06:07.283838       1 scheduling_queue.go:895] About to try and schedule pod pod-network-test-9417/host-test-container-pod
I0530 00:06:07.283853       1 scheduler.go:454] Attempting to schedule pod: pod-network-test-9417/host-test-container-pod
I0530 00:06:07.284171       1 scheduler_binder.go:255] AssumePodVolumes for pod "pod-network-test-9417/host-test-container-pod", node "e2e-test-peterhornyack-windows-node-group-jpxd"
I0530 00:06:07.284182       1 scheduler_binder.go:265] AssumePodVolumes for pod "pod-network-test-9417/host-test-container-pod", node "e2e-test-peterhornyack-windows-node-group-jpxd": all PVCs bound and nothing to do
I0530 00:06:07.284240       1 factory.go:734] Attempting to bind host-test-container-pod to e2e-test-peterhornyack-windows-node-group-jpxd
I0530 00:06:07.292424       1 scheduler.go:575] pod pod-network-test-9417/host-test-container-pod is bound successfully on node e2e-test-peterhornyack-windows-node-group-jpxd, 6 nodes evaluated, 3 nodes were found feasible
I0530 00:06:08.789480       1 reflector.go:384] k8s.io/client-go/informers/factory.go:133: Watch close - *v1.StatefulSet total 0 items received
I0530 00:06:11.476665       1 wrap.go:47] GET /healthz: (58.796µs) 200 [kube-probe/1.15+ 127.0.0.1:45758]
I0530 00:06:21.476840       1 wrap.go:47] GET /healthz: (81.477µs) 200 [kube-probe/1.15+ 127.0.0.1:45800]
I0530 00:06:31.476789       1 wrap.go:47] GET /healthz: (62.547µs) 200 [kube-probe/1.15+ 127.0.0.1:45836]
I0530 00:06:40.769866       1 reflector.go:384] k8s.io/client-go/informers/factory.go:133: Watch close - *v1.ReplicationController total 15 items received
I0530 00:06:41.279919       1 scheduling_queue.go:895] About to try and schedule pod gc-5744/simpletest.deployment-6744478b56-slkcz
I0530 00:06:41.279939       1 scheduler.go:454] Attempting to schedule pod: gc-5744/simpletest.deployment-6744478b56-slkcz
I0530 00:06:41.283276       1 scheduler_binder.go:255] AssumePodVolumes for pod "gc-5744/simpletest.deployment-6744478b56-slkcz", node "e2e-test-peterhornyack-windows-node-group-9q9v"
I0530 00:06:41.283303       1 scheduler_binder.go:265] AssumePodVolumes for pod "gc-5744/simpletest.deployment-6744478b56-slkcz", node "e2e-test-peterhornyack-windows-node-group-9q9v": all PVCs bound and nothing to do
I0530 00:06:41.283343       1 factory.go:734] Attempting to bind simpletest.deployment-6744478b56-slkcz to e2e-test-peterhornyack-windows-node-group-9q9v
I0530 00:06:41.300989       1 scheduler.go:575] pod gc-5744/simpletest.deployment-6744478b56-slkcz is bound successfully on node e2e-test-peterhornyack-windows-node-group-9q9v, 6 nodes evaluated, 3 nodes were found feasible
I0530 00:06:41.302917       1 scheduling_queue.go:895] About to try and schedule pod gc-5744/simpletest.deployment-6744478b56-j7j9s
I0530 00:06:41.302933       1 scheduler.go:454] Attempting to schedule pod: gc-5744/simpletest.deployment-6744478b56-j7j9s
I0530 00:06:41.304994       1 scheduler_binder.go:255] AssumePodVolumes for pod "gc-5744/simpletest.deployment-6744478b56-j7j9s", node "e2e-test-peterhornyack-windows-node-group-jpxd"
I0530 00:06:41.305005       1 scheduler_binder.go:265] AssumePodVolumes for pod "gc-5744/simpletest.deployment-6744478b56-j7j9s", node "e2e-test-peterhornyack-windows-node-group-jpxd": all PVCs bound and nothing to do
I0530 00:06:41.305038       1 factory.go:734] Attempting to bind simpletest.deployment-6744478b56-j7j9s to e2e-test-peterhornyack-windows-node-group-jpxd
I0530 00:06:41.330558       1 scheduler.go:575] pod gc-5744/simpletest.deployment-6744478b56-j7j9s is bound successfully on node e2e-test-peterhornyack-windows-node-group-jpxd, 6 nodes evaluated, 3 nodes were found feasible
I0530 00:06:41.476604       1 wrap.go:47] GET /healthz: (65.595µs) 200 [kube-probe/1.15+ 127.0.0.1:45870]
I0530 00:06:51.476705       1 wrap.go:47] GET /healthz: (65.836µs) 200 [kube-probe/1.15+ 127.0.0.1:45902]
I0530 00:07:01.477737       1 wrap.go:47] GET /healthz: (65.965µs) 200 [kube-probe/1.15+ 127.0.0.1:45954]
I0530 00:07:11.476852       1 wrap.go:47] GET /healthz: (78.145µs) 200 [kube-probe/1.15+ 127.0.0.1:45988]
I0530 00:07:19.798807       1 scheduling_queue.go:895] About to try and schedule pod pod-network-test-2811/netserver-0
I0530 00:07:19.798822       1 scheduler.go:454] Attempting to schedule pod: pod-network-test-2811/netserver-0
I0530 00:07:19.799131       1 scheduler_binder.go:255] AssumePodVolumes for pod "pod-network-test-2811/netserver-0", node "e2e-test-peterhornyack-windows-node-group-1vjk"
I0530 00:07:19.799142       1 scheduler_binder.go:265] AssumePodVolumes for pod "pod-network-test-2811/netserver-0", node "e2e-test-peterhornyack-windows-node-group-1vjk": all PVCs bound and nothing to do
I0530 00:07:19.799298       1 factory.go:734] Attempting to bind netserver-0 to e2e-test-peterhornyack-windows-node-group-1vjk
I0530 00:07:19.806449       1 scheduler.go:575] pod pod-network-test-2811/netserver-0 is bound successfully on node e2e-test-peterhornyack-windows-node-group-1vjk, 6 nodes evaluated, 1 nodes were found feasible
I0530 00:07:19.843588       1 scheduling_queue.go:895] About to try and schedule pod pod-network-test-2811/netserver-1
I0530 00:07:19.843603       1 scheduler.go:454] Attempting to schedule pod: pod-network-test-2811/netserver-1
I0530 00:07:19.845184       1 scheduler_binder.go:255] AssumePodVolumes for pod "pod-network-test-2811/netserver-1", node "e2e-test-peterhornyack-windows-node-group-9q9v"
I0530 00:07:19.845200       1 scheduler_binder.go:265] AssumePodVolumes for pod "pod-network-test-2811/netserver-1", node "e2e-test-peterhornyack-windows-node-group-9q9v": all PVCs bound and nothing to do
I0530 00:07:19.845253       1 factory.go:734] Attempting to bind netserver-1 to e2e-test-peterhornyack-windows-node-group-9q9v
I0530 00:07:19.855018       1 scheduler.go:575] pod pod-network-test-2811/netserver-1 is bound successfully on node e2e-test-peterhornyack-windows-node-group-9q9v, 6 nodes evaluated, 1 nodes were found feasible
I0530 00:07:19.889527       1 scheduling_queue.go:895] About to try and schedule pod pod-network-test-2811/netserver-2
I0530 00:07:19.889560       1 scheduler.go:454] Attempting to schedule pod: pod-network-test-2811/netserver-2
I0530 00:07:19.889822       1 scheduler_binder.go:255] AssumePodVolumes for pod "pod-network-test-2811/netserver-2", node "e2e-test-peterhornyack-windows-node-group-jpxd"
I0530 00:07:19.889846       1 scheduler_binder.go:265] AssumePodVolumes for pod "pod-network-test-2811/netserver-2", node "e2e-test-peterhornyack-windows-node-group-jpxd": all PVCs bound and nothing to do
I0530 00:07:19.891097       1 factory.go:734] Attempting to bind netserver-2 to e2e-test-peterhornyack-windows-node-group-jpxd
I0530 00:07:19.900983       1 scheduler.go:575] pod pod-network-test-2811/netserver-2 is bound successfully on node e2e-test-peterhornyack-windows-node-group-jpxd, 6 nodes evaluated, 1 nodes were found feasible
I0530 00:07:21.476740       1 wrap.go:47] GET /healthz: (86.034µs) 200 [kube-probe/1.15+ 127.0.0.1:46024]
I0530 00:07:29.819233       1 reflector.go:384] cmd/kube-scheduler/app/server.go:223: Watch close - *v1.Pod total 167 items received
I0530 00:07:31.476680       1 wrap.go:47] GET /healthz: (74.279µs) 200 [kube-probe/1.15+ 127.0.0.1:46058]
I0530 00:07:41.490099       1 wrap.go:47] GET /healthz: (75.427µs) 200 [kube-probe/1.15+ 127.0.0.1:46092]
I0530 00:07:44.312366       1 scheduling_queue.go:895] About to try and schedule pod pod-network-test-2811/test-container-pod
I0530 00:07:44.312379       1 scheduler.go:454] Attempting to schedule pod: pod-network-test-2811/test-container-pod
I0530 00:07:44.313257       1 scheduler_binder.go:255] AssumePodVolumes for pod "pod-network-test-2811/test-container-pod", node "e2e-test-peterhornyack-windows-node-group-jpxd"
I0530 00:07:44.313269       1 scheduler_binder.go:265] AssumePodVolumes for pod "pod-network-test-2811/test-container-pod", node "e2e-test-peterhornyack-windows-node-group-jpxd": all PVCs bound and nothing to do
I0530 00:07:44.313303       1 factory.go:734] Attempting to bind test-container-pod to e2e-test-peterhornyack-windows-node-group-jpxd
I0530 00:07:44.321599       1 scheduler.go:575] pod pod-network-test-2811/test-container-pod is bound successfully on node e2e-test-peterhornyack-windows-node-group-jpxd, 6 nodes evaluated, 3 nodes were found feasible
I0530 00:07:44.358141       1 scheduling_queue.go:895] About to try and schedule pod pod-network-test-2811/host-test-container-pod
I0530 00:07:44.358154       1 scheduler.go:454] Attempting to schedule pod: pod-network-test-2811/host-test-container-pod
I0530 00:07:44.360417       1 scheduler_binder.go:255] AssumePodVolumes for pod "pod-network-test-2811/host-test-container-pod", node "e2e-test-peterhornyack-windows-node-group-jpxd"
I0530 00:07:44.360434       1 scheduler_binder.go:265] AssumePodVolumes for pod "pod-network-test-2811/host-test-container-pod", node "e2e-test-peterhornyack-windows-node-group-jpxd": all PVCs bound and nothing to do
I0530 00:07:44.360539       1 factory.go:734] Attempting to bind host-test-container-pod to e2e-test-peterhornyack-windows-node-group-jpxd
I0530 00:07:44.365736       1 scheduler.go:575] pod pod-network-test-2811/host-test-container-pod is bound successfully on node e2e-test-peterhornyack-windows-node-group-jpxd, 6 nodes evaluated, 3 nodes were found feasible
I0530 00:07:51.476812       1 wrap.go:47] GET /healthz: (79.126µs) 200 [kube-probe/1.15+ 127.0.0.1:46124]
I0530 00:08:01.477924       1 wrap.go:47] GET /healthz: (52.628µs) 200 [kube-probe/1.15+ 127.0.0.1:46174]
I0530 00:08:11.477116       1 wrap.go:47] GET /healthz: (72.229µs) 200 [kube-probe/1.15+ 127.0.0.1:46210]
I0530 00:08:21.476892       1 wrap.go:47] GET /healthz: (72.152µs) 200 [kube-probe/1.15+ 127.0.0.1:46254]
I0530 00:08:31.476981       1 wrap.go:47] GET /healthz: (48.554µs) 200 [kube-probe/1.15+ 127.0.0.1:46290]
I0530 00:08:41.476609       1 wrap.go:47] GET /healthz: (64.096µs) 200 [kube-probe/1.15+ 127.0.0.1:46324]
I0530 00:08:41.764816       1 reflector.go:384] k8s.io/client-go/informers/factory.go:133: Watch close - *v1.Node total 61 items received
I0530 00:08:42.701870       1 scheduling_queue.go:895] About to try and schedule pod services-4909/nodeport-test-fplkp
I0530 00:08:42.701882       1 scheduler.go:454] Attempting to schedule pod: services-4909/nodeport-test-fplkp
I0530 00:08:42.702289       1 scheduler_binder.go:255] AssumePodVolumes for pod "services-4909/nodeport-test-fplkp", node "e2e-test-peterhornyack-windows-node-group-1vjk"
I0530 00:08:42.702299       1 scheduler_binder.go:265] AssumePodVolumes for pod "services-4909/nodeport-test-fplkp", node "e2e-test-peterhornyack-windows-node-group-1vjk": all PVCs bound and nothing to do
I0530 00:08:42.702351       1 factory.go:734] Attempting to bind nodeport-test-fplkp to e2e-test-peterhornyack-windows-node-group-1vjk
I0530 00:08:42.717485       1 scheduler.go:575] pod services-4909/nodeport-test-fplkp is bound successfully on node e2e-test-peterhornyack-windows-node-group-1vjk, 6 nodes evaluated, 3 nodes were found feasible
I0530 00:08:51.476752       1 wrap.go:47] GET /healthz: (63.185µs) 200 [kube-probe/1.15+ 127.0.0.1:46358]
I0530 00:08:53.037184       1 scheduling_queue.go:895] About to try and schedule pod services-4909/pod-ce867205-d1e3-49d8-a31b-791de19e4b1f
I0530 00:08:53.037210       1 scheduler.go:454] Attempting to schedule pod: services-4909/pod-ce867205-d1e3-49d8-a31b-791de19e4b1f
I0530 00:08:53.037625       1 scheduler_binder.go:255] AssumePodVolumes for pod "services-4909/pod-ce867205-d1e3-49d8-a31b-791de19e4b1f", node "e2e-test-peterhornyack-windows-node-group-jpxd"
I0530 00:08:53.037635       1 scheduler_binder.go:265] AssumePodVolumes for pod "services-4909/pod-ce867205-d1e3-49d8-a31b-791de19e4b1f", node "e2e-test-peterhornyack-windows-node-group-jpxd": all PVCs bound and nothing to do
I0530 00:08:53.037675       1 factory.go:734] Attempting to bind pod-ce867205-d1e3-49d8-a31b-791de19e4b1f to e2e-test-peterhornyack-windows-node-group-jpxd
I0530 00:08:53.048827       1 scheduler.go:575] pod services-4909/pod-ce867205-d1e3-49d8-a31b-791de19e4b1f is bound successfully on node e2e-test-peterhornyack-windows-node-group-jpxd, 6 nodes evaluated, 3 nodes were found feasible
I0530 00:09:01.477618       1 wrap.go:47] GET /healthz: (64.776µs) 200 [kube-probe/1.15+ 127.0.0.1:46406]
I0530 00:09:11.476741       1 wrap.go:47] GET /healthz: (48.827µs) 200 [kube-probe/1.15+ 127.0.0.1:46440]
I0530 00:09:12.792269       1 reflector.go:384] k8s.io/client-go/informers/factory.go:133: Watch close - *v1.Service total 5 items received
I0530 00:09:21.476807       1 wrap.go:47] GET /healthz: (62.894µs) 200 [kube-probe/1.15+ 127.0.0.1:46482]
I0530 00:09:31.476670       1 wrap.go:47] GET /healthz: (63.316µs) 200 [kube-probe/1.15+ 127.0.0.1:46518]
I0530 00:09:41.476908       1 wrap.go:47] GET /healthz: (55.308µs) 200 [kube-probe/1.15+ 127.0.0.1:46566]
I0530 00:09:51.476863       1 wrap.go:47] GET /healthz: (77.574µs) 200 [kube-probe/1.15+ 127.0.0.1:46598]
I0530 00:10:01.476986       1 wrap.go:47] GET /healthz: (77.066µs) 200 [kube-probe/1.15+ 127.0.0.1:46648]
I0530 00:10:11.476775       1 wrap.go:47] GET /healthz: (52.198µs) 200 [kube-probe/1.15+ 127.0.0.1:46682]
I0530 00:10:21.476745       1 wrap.go:47] GET /healthz: (66.033µs) 200 [kube-probe/1.15+ 127.0.0.1:46718]
I0530 00:10:31.477239       1 wrap.go:47] GET /healthz: (70.463µs) 200 [kube-probe/1.15+ 127.0.0.1:46754]
I0530 00:10:41.476821       1 wrap.go:47] GET /healthz: (64.175µs) 200 [kube-probe/1.15+ 127.0.0.1:46788]
I0530 00:10:44.815148       1 reflector.go:384] k8s.io/client-go/informers/factory.go:133: Watch close - *v1.PersistentVolumeClaim total 7 items received
I0530 00:10:49.354323       1 scheduling_queue.go:895] About to try and schedule pod configmap-2289/pod-configmaps-92c383a2-695a-40c9-87e1-0db03e1b29e2
I0530 00:10:49.354336       1 scheduler.go:454] Attempting to schedule pod: configmap-2289/pod-configmaps-92c383a2-695a-40c9-87e1-0db03e1b29e2
I0530 00:10:49.354873       1 scheduler_binder.go:255] AssumePodVolumes for pod "configmap-2289/pod-configmaps-92c383a2-695a-40c9-87e1-0db03e1b29e2", node "e2e-test-peterhornyack-windows-node-group-9q9v"
I0530 00:10:49.354887       1 scheduler_binder.go:265] AssumePodVolumes for pod "configmap-2289/pod-configmaps-92c383a2-695a-40c9-87e1-0db03e1b29e2", node "e2e-test-peterhornyack-windows-node-group-9q9v": all PVCs bound and nothing to do
I0530 00:10:49.354928       1 factory.go:734] Attempting to bind pod-configmaps-92c383a2-695a-40c9-87e1-0db03e1b29e2 to e2e-test-peterhornyack-windows-node-group-9q9v
I0530 00:10:49.361163       1 scheduler.go:575] pod configmap-2289/pod-configmaps-92c383a2-695a-40c9-87e1-0db03e1b29e2 is bound successfully on node e2e-test-peterhornyack-windows-node-group-9q9v, 6 nodes evaluated, 3 nodes were found feasible
I0530 00:10:51.476670       1 wrap.go:47] GET /healthz: (69.126µs) 200 [kube-probe/1.15+ 127.0.0.1:46820]
I0530 00:11:01.476900       1 wrap.go:47] GET /healthz: (55.83µs) 200 [kube-probe/1.15+ 127.0.0.1:46870]
I0530 00:11:03.729117       1 scheduling_queue.go:895] About to try and schedule pod kubelet-test-7782/bin-false2825a82c-0f40-4025-8105-da614971c5b1
I0530 00:11:03.729130       1 scheduler.go:454] Attempting to schedule pod: kubelet-test-7782/bin-false2825a82c-0f40-4025-8105-da614971c5b1
I0530 00:11:03.729432       1 scheduler_binder.go:255] AssumePodVolumes for pod "kubelet-test-7782/bin-false2825a82c-0f40-4025-8105-da614971c5b1", node "e2e-test-peterhornyack-windows-node-group-1vjk"
I0530 00:11:03.729442       1 scheduler_binder.go:265] AssumePodVolumes for pod "kubelet-test-7782/bin-false2825a82c-0f40-4025-8105-da614971c5b1", node "e2e-test-peterhornyack-windows-node-group-1vjk": all PVCs bound and nothing to do
I0530 00:11:03.729538       1 factory.go:734] Attempting to bind bin-false2825a82c-0f40-4025-8105-da614971c5b1 to e2e-test-peterhornyack-windows-node-group-1vjk
I0530 00:11:03.737045       1 scheduler.go:575] pod kubelet-test-7782/bin-false2825a82c-0f40-4025-8105-da614971c5b1 is bound successfully on node e2e-test-peterhornyack-windows-node-group-1vjk, 6 nodes evaluated, 3 nodes were found feasible
I0530 00:11:11.477364       1 wrap.go:47] GET /healthz: (87.599µs) 200 [kube-probe/1.15+ 127.0.0.1:46904]
I0530 00:11:20.086862       1 scheduling_queue.go:895] About to try and schedule pod kubectl-340/e2e-test-nginx-pod
I0530 00:11:20.086876       1 scheduler.go:454] Attempting to schedule pod: kubectl-340/e2e-test-nginx-pod
I0530 00:11:20.087371       1 scheduler_binder.go:255] AssumePodVolumes for pod "kubectl-340/e2e-test-nginx-pod", node "e2e-test-peterhornyack-windows-node-group-jpxd"
I0530 00:11:20.087382       1 scheduler_binder.go:265] AssumePodVolumes for pod "kubectl-340/e2e-test-nginx-pod", node "e2e-test-peterhornyack-windows-node-group-jpxd": all PVCs bound and nothing to do
I0530 00:11:20.087436       1 factory.go:734] Attempting to bind e2e-test-nginx-pod to e2e-test-peterhornyack-windows-node-group-jpxd
I0530 00:11:20.092334       1 scheduler.go:575] pod kubectl-340/e2e-test-nginx-pod is bound successfully on node e2e-test-peterhornyack-windows-node-group-jpxd, 6 nodes evaluated, 3 nodes were found feasible
I0530 00:11:21.476708       1 wrap.go:47] GET /healthz: (78.253µs) 200 [kube-probe/1.15+ 127.0.0.1:46940]
I0530 00:11:30.610807       1 scheduling_queue.go:895] About to try and schedule pod downward-api-8112/downwardapi-volume-ccaf1c26-78c2-4359-b48d-49025a44fa20
I0530 00:11:30.610821       1 scheduler.go:454] Attempting to schedule pod: downward-api-8112/downwardapi-volume-ccaf1c26-78c2-4359-b48d-49025a44fa20
I0530 00:11:30.611974       1 scheduler_binder.go:255] AssumePodVolumes for pod "downward-api-8112/downwardapi-volume-ccaf1c26-78c2-4359-b48d-49025a44fa20", node "e2e-test-peterhornyack-windows-node-group-9q9v"
I0530 00:11:30.612001       1 scheduler_binder.go:265] AssumePodVolumes for pod "downward-api-8112/downwardapi-volume-ccaf1c26-78c2-4359-b48d-49025a44fa20", node "e2e-test-peterhornyack-windows-node-group-9q9v": all PVCs bound and nothing to do
I0530 00:11:30.612048       1 factory.go:734] Attempting to bind downwardapi-volume-ccaf1c26-78c2-4359-b48d-49025a44fa20 to e2e-test-peterhornyack-windows-node-group-9q9v
I0530 00:11:30.620946       1 scheduler.go:575] pod downward-api-8112/downwardapi-volume-ccaf1c26-78c2-4359-b48d-49025a44fa20 is bound successfully on node e2e-test-peterhornyack-windows-node-group-9q9v, 6 nodes evaluated, 3 nodes were found feasible
I0530 00:11:31.476613       1 wrap.go:47] GET /healthz: (66.017µs) 200 [kube-probe/1.15+ 127.0.0.1:46976]
I0530 00:11:41.476743       1 wrap.go:47] GET /healthz: (80.908µs) 200 [kube-probe/1.15+ 127.0.0.1:47012]
I0530 00:11:51.476694       1 wrap.go:47] GET /healthz: (92.106µs) 200 [kube-probe/1.15+ 127.0.0.1:47044]
I0530 00:12:01.477014       1 wrap.go:47] GET /healthz: (65.272µs) 200 [kube-probe/1.15+ 127.0.0.1:47092]
I0530 00:12:11.476655       1 wrap.go:47] GET /healthz: (75.957µs) 200 [kube-probe/1.15+ 127.0.0.1:47126]
I0530 00:12:21.476794       1 wrap.go:47] GET /healthz: (58.906µs) 200 [kube-probe/1.15+ 127.0.0.1:47162]
I0530 00:12:24.814741       1 reflector.go:384] k8s.io/client-go/informers/factory.go:133: Watch close - *v1.PersistentVolume total 3 items received
I0530 00:12:26.771905       1 reflector.go:384] k8s.io/client-go/informers/factory.go:133: Watch close - *v1.ReplicationController total 5 items received
I0530 00:12:31.476685       1 wrap.go:47] GET /healthz: (71.097µs) 200 [kube-probe/1.15+ 127.0.0.1:47196]
I0530 00:12:33.802600       1 reflector.go:384] k8s.io/client-go/informers/factory.go:133: Watch close - *v1beta1.PodDisruptionBudget total 0 items received
I0530 00:12:35.785206       1 reflector.go:384] k8s.io/client-go/informers/factory.go:133: Watch close - *v1.StorageClass total 0 items received
I0530 00:12:41.476821       1 wrap.go:47] GET /healthz: (77.196µs) 200 [kube-probe/1.15+ 127.0.0.1:47230]
I0530 00:12:51.476661       1 wrap.go:47] GET /healthz: (64.891µs) 200 [kube-probe/1.15+ 127.0.0.1:47266]
I0530 00:12:57.605217       1 scheduling_queue.go:895] About to try and schedule pod downward-api-2450/downward-api-92b32be9-5fae-4594-bf0f-f8e40311ed01
I0530 00:12:57.605228       1 scheduler.go:454] Attempting to schedule pod: downward-api-2450/downward-api-92b32be9-5fae-4594-bf0f-f8e40311ed01
I0530 00:12:57.605651       1 scheduler_binder.go:255] AssumePodVolumes for pod "downward-api-2450/downward-api-92b32be9-5fae-4594-bf0f-f8e40311ed01", node "e2e-test-peterhornyack-windows-node-group-9q9v"
I0530 00:12:57.605662       1 scheduler_binder.go:265] AssumePodVolumes for pod "downward-api-2450/downward-api-92b32be9-5fae-4594-bf0f-f8e40311ed01", node "e2e-test-peterhornyack-windows-node-group-9q9v": all PVCs bound and nothing to do
I0530 00:12:57.605716       1 factory.go:734] Attempting to bind downward-api-92b32be9-5fae-4594-bf0f-f8e40311ed01 to e2e-test-peterhornyack-windows-node-group-9q9v
I0530 00:12:57.616655       1 scheduler.go:575] pod downward-api-2450/downward-api-92b32be9-5fae-4594-bf0f-f8e40311ed01 is bound successfully on node e2e-test-peterhornyack-windows-node-group-9q9v, 6 nodes evaluated, 3 nodes were found feasible
I0530 00:13:01.476862       1 wrap.go:47] GET /healthz: (76.544µs) 200 [kube-probe/1.15+ 127.0.0.1:47310]
I0530 00:13:11.476743       1 wrap.go:47] GET /healthz: (76.328µs) 200 [kube-probe/1.15+ 127.0.0.1:47348]
I0530 00:13:19.973770       1 scheduling_queue.go:895] About to try and schedule pod pods-6483/pod-hostip-0c4d1ff4-bbfa-4be3-ad64-c8164ff51b26
I0530 00:13:19.973785       1 scheduler.go:454] Attempting to schedule pod: pods-6483/pod-hostip-0c4d1ff4-bbfa-4be3-ad64-c8164ff51b26
I0530 00:13:19.974181       1 scheduler_binder.go:255] AssumePodVolumes for pod "pods-6483/pod-hostip-0c4d1ff4-bbfa-4be3-ad64-c8164ff51b26", node "e2e-test-peterhornyack-windows-node-group-jpxd"
I0530 00:13:19.974193       1 scheduler_binder.go:265] AssumePodVolumes for pod "pods-6483/pod-hostip-0c4d1ff4-bbfa-4be3-ad64-c8164ff51b26", node "e2e-test-peterhornyack-windows-node-group-jpxd": all PVCs bound and nothing to do
I0530 00:13:19.974253       1 factory.go:734] Attempting to bind pod-hostip-0c4d1ff4-bbfa-4be3-ad64-c8164ff51b26 to e2e-test-peterhornyack-windows-node-group-jpxd
I0530 00:13:19.977367       1 cache.go:643] Couldn't expire cache for pod pods-6483/pod-hostip-0c4d1ff4-bbfa-4be3-ad64-c8164ff51b26. Binding is still in progress.
I0530 00:13:19.981997       1 scheduler.go:575] pod pods-6483/pod-hostip-0c4d1ff4-bbfa-4be3-ad64-c8164ff51b26 is bound successfully on node e2e-test-peterhornyack-windows-node-group-jpxd, 6 nodes evaluated, 3 nodes were found feasible
I0530 00:13:21.476926       1 wrap.go:47] GET /healthz: (79.601µs) 200 [kube-probe/1.15+ 127.0.0.1:47384]
I0530 00:13:31.476988       1 wrap.go:47] GET /healthz: (93.126µs) 200 [kube-probe/1.15+ 127.0.0.1:47418]
I0530 00:13:41.476620       1 wrap.go:47] GET /healthz: (79.564µs) 200 [kube-probe/1.15+ 127.0.0.1:47452]
I0530 00:13:49.807633       1 reflector.go:384] k8s.io/client-go/informers/factory.go:133: Watch close - *v1.ReplicaSet total 13 items received
I0530 00:13:51.476848       1 wrap.go:47] GET /healthz: (81.032µs) 200 [kube-probe/1.15+ 127.0.0.1:47484]
I0530 00:13:52.239426       1 scheduling_queue.go:895] About to try and schedule pod projected-2980/projected-volume-1b8a133b-84cd-4339-9c9c-80c4fb5c7641
I0530 00:13:52.239439       1 scheduler.go:454] Attempting to schedule pod: projected-2980/projected-volume-1b8a133b-84cd-4339-9c9c-80c4fb5c7641
I0530 00:13:52.240088       1 scheduler_binder.go:255] AssumePodVolumes for pod "projected-2980/projected-volume-1b8a133b-84cd-4339-9c9c-80c4fb5c7641", node "e2e-test-peterhornyack-windows-node-group-9q9v"
I0530 00:13:52.240102       1 scheduler_binder.go:265] AssumePodVolumes for pod "projected-2980/projected-volume-1b8a133b-84cd-4339-9c9c-80c4fb5c7641", node "e2e-test-peterhornyack-windows-node-group-9q9v": all PVCs bound and nothing to do
I0530 00:13:52.240166       1 factory.go:734] Attempting to bind projected-volume-1b8a133b-84cd-4339-9c9c-80c4fb5c7641 to e2e-test-peterhornyack-windows-node-group-9q9v
I0530 00:13:52.247166       1 scheduler.go:575] pod projected-2980/projected-volume-1b8a133b-84cd-4339-9c9c-80c4fb5c7641 is bound successfully on node e2e-test-peterhornyack-windows-node-group-9q9v, 6 nodes evaluated, 3 nodes were found feasible
I0530 00:14:01.476746       1 wrap.go:47] GET /healthz: (50.163µs) 200 [kube-probe/1.15+ 127.0.0.1:47534]
I0530 00:14:11.478363       1 wrap.go:47] GET /healthz: (57.899µs) 200 [kube-probe/1.15+ 127.0.0.1:47568]
I0530 00:14:13.194025       1 scheduling_queue.go:895] About to try and schedule pod kubectl-1997/redis-master-4jd5h
I0530 00:14:13.194039       1 scheduler.go:454] Attempting to schedule pod: kubectl-1997/redis-master-4jd5h
I0530 00:14:13.194419       1 scheduler_binder.go:255] AssumePodVolumes for pod "kubectl-1997/redis-master-4jd5h", node "e2e-test-peterhornyack-windows-node-group-1vjk"
I0530 00:14:13.194430       1 scheduler_binder.go:265] AssumePodVolumes for pod "kubectl-1997/redis-master-4jd5h", node "e2e-test-peterhornyack-windows-node-group-1vjk": all PVCs bound and nothing to do
I0530 00:14:13.194494       1 factory.go:734] Attempting to bind redis-master-4jd5h to e2e-test-peterhornyack-windows-node-group-1vjk
I0530 00:14:13.205713       1 scheduler.go:575] pod kubectl-1997/redis-master-4jd5h is bound successfully on node e2e-test-peterhornyack-windows-node-group-1vjk, 6 nodes evaluated, 3 nodes were found feasible
I0530 00:14:21.476742       1 wrap.go:47] GET /healthz: (75.291µs) 200 [kube-probe/1.15+ 127.0.0.1:47606]
I0530 00:14:31.476870       1 wrap.go:47] GET /healthz: (67.564µs) 200 [kube-probe/1.15+ 127.0.0.1:47640]
I0530 00:14:33.631489       1 scheduling_queue.go:895] About to try and schedule pod dns-5269/dns-test-85af534c-5fe4-40d1-bfc3-18ad6d7b516f
I0530 00:14:33.631504       1 scheduler.go:454] Attempting to schedule pod: dns-5269/dns-test-85af534c-5fe4-40d1-bfc3-18ad6d7b516f
I0530 00:14:33.632168       1 scheduler_binder.go:255] AssumePodVolumes for pod "dns-5269/dns-test-85af534c-5fe4-40d1-bfc3-18ad6d7b516f", node "e2e-test-peterhornyack-windows-node-group-jpxd"
I0530 00:14:33.632192       1 scheduler_binder.go:265] AssumePodVolumes for pod "dns-5269/dns-test-85af534c-5fe4-40d1-bfc3-18ad6d7b516f", node "e2e-test-peterhornyack-windows-node-group-jpxd": all PVCs bound and nothing to do
I0530 00:14:33.632235       1 factory.go:734] Attempting to bind dns-test-85af534c-5fe4-40d1-bfc3-18ad6d7b516f to e2e-test-peterhornyack-windows-node-group-jpxd
I0530 00:14:33.640619       1 scheduler.go:575] pod dns-5269/dns-test-85af534c-5fe4-40d1-bfc3-18ad6d7b516f is bound successfully on node e2e-test-peterhornyack-windows-node-group-jpxd, 6 nodes evaluated, 3 nodes were found feasible
I0530 00:14:34.791877       1 reflector.go:384] k8s.io/client-go/informers/factory.go:133: Watch close - *v1.StatefulSet total 0 items received
I0530 00:14:41.476962       1 wrap.go:47] GET /healthz: (67.885µs) 200 [kube-probe/1.15+ 127.0.0.1:47676]
I0530 00:14:51.476972       1 wrap.go:47] GET /healthz: (51.912µs) 200 [kube-probe/1.15+ 127.0.0.1:47708]
I0530 00:15:00.312574       1 scheduling_queue.go:895] About to try and schedule pod dns-5269/dns-test-3a6b50f9-95ef-456d-879b-6299380f723b
I0530 00:15:00.312590       1 scheduler.go:454] Attempting to schedule pod: dns-5269/dns-test-3a6b50f9-95ef-456d-879b-6299380f723b
I0530 00:15:00.313078       1 scheduler_binder.go:255] AssumePodVolumes for pod "dns-5269/dns-test-3a6b50f9-95ef-456d-879b-6299380f723b", node "e2e-test-peterhornyack-windows-node-group-jpxd"
I0530 00:15:00.314511       1 scheduler_binder.go:265] AssumePodVolumes for pod "dns-5269/dns-test-3a6b50f9-95ef-456d-879b-6299380f723b", node "e2e-test-peterhornyack-windows-node-group-jpxd": all PVCs bound and nothing to do
I0530 00:15:00.314690       1 factory.go:734] Attempting to bind dns-test-3a6b50f9-95ef-456d-879b-6299380f723b to e2e-test-peterhornyack-windows-node-group-jpxd
I0530 00:15:00.322628       1 scheduler.go:575] pod dns-5269/dns-test-3a6b50f9-95ef-456d-879b-6299380f723b is bound successfully on node e2e-test-peterhornyack-windows-node-group-jpxd, 6 nodes evaluated, 3 nodes were found feasible
I0530 00:15:01.476800       1 wrap.go:47] GET /healthz: (83.523µs) 200 [kube-probe/1.15+ 127.0.0.1:47758]
I0530 00:15:11.476662       1 wrap.go:47] GET /healthz: (74.962µs) 200 [kube-probe/1.15+ 127.0.0.1:47794]
I0530 00:15:14.847967       1 scheduling_queue.go:895] About to try and schedule pod dns-5269/dns-test-72a136c3-d3b3-4d5f-aca8-8c67a8c3625d
I0530 00:15:14.847980       1 scheduler.go:454] Attempting to schedule pod: dns-5269/dns-test-72a136c3-d3b3-4d5f-aca8-8c67a8c3625d
I0530 00:15:14.849245       1 scheduler_binder.go:255] AssumePodVolumes for pod "dns-5269/dns-test-72a136c3-d3b3-4d5f-aca8-8c67a8c3625d", node "e2e-test-peterhornyack-windows-node-group-jpxd"
I0530 00:15:14.849271       1 scheduler_binder.go:265] AssumePodVolumes for pod "dns-5269/dns-test-72a136c3-d3b3-4d5f-aca8-8c67a8c3625d", node "e2e-test-peterhornyack-windows-node-group-jpxd": all PVCs bound and nothing to do
I0530 00:15:14.849350       1 factory.go:734] Attempting to bind dns-test-72a136c3-d3b3-4d5f-aca8-8c67a8c3625d to e2e-test-peterhornyack-windows-node-group-jpxd
I0530 00:15:14.867060       1 scheduler.go:575] pod dns-5269/dns-test-72a136c3-d3b3-4d5f-aca8-8c67a8c3625d is bound successfully on node e2e-test-peterhornyack-windows-node-group-jpxd, 6 nodes evaluated, 3 nodes were found feasible
I0530 00:15:21.476827       1 wrap.go:47] GET /healthz: (114.081µs) 200 [kube-probe/1.15+ 127.0.0.1:47832]
I0530 00:15:31.476832       1 wrap.go:47] GET /healthz: (73.979µs) 200 [kube-probe/1.15+ 127.0.0.1:47868]
I0530 00:15:37.766996       1 reflector.go:384] k8s.io/client-go/informers/factory.go:133: Watch close - *v1.Node total 57 items received
I0530 00:15:41.476601       1 wrap.go:47] GET /healthz: (65.469µs) 200 [kube-probe/1.15+ 127.0.0.1:47902]
I0530 00:15:44.368765       1 scheduling_queue.go:895] About to try and schedule pod projected-6365/downwardapi-volume-0d1dba4b-1bb4-4968-8b1e-5dec8d6e24f3
I0530 00:15:44.368779       1 scheduler.go:454] Attempting to schedule pod: projected-6365/downwardapi-volume-0d1dba4b-1bb4-4968-8b1e-5dec8d6e24f3
I0530 00:15:44.369038       1 scheduler_binder.go:255] AssumePodVolumes for pod "projected-6365/downwardapi-volume-0d1dba4b-1bb4-4968-8b1e-5dec8d6e24f3", node "e2e-test-peterhornyack-windows-node-group-9q9v"
I0530 00:15:44.369049       1 scheduler_binder.go:265] AssumePodVolumes for pod "projected-6365/downwardapi-volume-0d1dba4b-1bb4-4968-8b1e-5dec8d6e24f3", node "e2e-test-peterhornyack-windows-node-group-9q9v": all PVCs bound and nothing to do
I0530 00:15:44.369086       1 factory.go:734] Attempting to bind downwardapi-volume-0d1dba4b-1bb4-4968-8b1e-5dec8d6e24f3 to e2e-test-peterhornyack-windows-node-group-9q9v
I0530 00:15:44.381614       1 scheduler.go:575] pod projected-6365/downwardapi-volume-0d1dba4b-1bb4-4968-8b1e-5dec8d6e24f3 is bound successfully on node e2e-test-peterhornyack-windows-node-group-9q9v, 6 nodes evaluated, 3 nodes were found feasible
I0530 00:15:50.795219       1 reflector.go:384] k8s.io/client-go/informers/factory.go:133: Watch close - *v1.Service total 5 items received
I0530 00:15:51.476732       1 wrap.go:47] GET /healthz: (64.528µs) 200 [kube-probe/1.15+ 127.0.0.1:47936]
I0530 00:15:51.821937       1 reflector.go:384] k8s.io/client-go/informers/factory.go:133: Watch close - *v1.PersistentVolumeClaim total 0 items received
I0530 00:16:01.476527       1 wrap.go:47] GET /healthz: (76.762µs) 200 [kube-probe/1.15+ 127.0.0.1:47986]
I0530 00:16:11.476781       1 wrap.go:47] GET /healthz: (74.14µs) 200 [kube-probe/1.15+ 127.0.0.1:48020]
I0530 00:16:14.323846       1 scheduling_queue.go:895] About to try and schedule pod volume-5889/gcepd-injector-vngq
I0530 00:16:14.323874       1 scheduler.go:454] Attempting to schedule pod: volume-5889/gcepd-injector-vngq
I0530 00:16:14.324431       1 scheduler_binder.go:651] All bound volumes for Pod "volume-5889/gcepd-injector-vngq" match with Node "e2e-test-peterhornyack-windows-node-group-9q9v"
I0530 00:16:14.324507       1 scheduler_binder.go:651] All bound volumes for Pod "volume-5889/gcepd-injector-vngq" match with Node "e2e-test-peterhornyack-windows-node-group-1vjk"
I0530 00:16:14.324540       1 scheduler_binder.go:651] All bound volumes for Pod "volume-5889/gcepd-injector-vngq" match with Node "e2e-test-peterhornyack-windows-node-group-jpxd"
I0530 00:16:14.324736       1 scheduler_binder.go:255] AssumePodVolumes for pod "volume-5889/gcepd-injector-vngq", node "e2e-test-peterhornyack-windows-node-group-jpxd"
I0530 00:16:14.324745       1 scheduler_binder.go:265] AssumePodVolumes for pod "volume-5889/gcepd-injector-vngq", node "e2e-test-peterhornyack-windows-node-group-jpxd": all PVCs bound and nothing to do
I0530 00:16:14.324800       1 factory.go:734] Attempting to bind gcepd-injector-vngq to e2e-test-peterhornyack-windows-node-group-jpxd
I0530 00:16:14.333618       1 scheduler.go:575] pod volume-5889/gcepd-injector-vngq is bound successfully on node e2e-test-peterhornyack-windows-node-group-jpxd, 6 nodes evaluated, 3 nodes were found feasible
I0530 00:16:21.476769       1 wrap.go:47] GET /healthz: (73.437µs) 200 [kube-probe/1.15+ 127.0.0.1:48058]
I0530 00:16:31.476679       1 wrap.go:47] GET /healthz: (61.066µs) 200 [kube-probe/1.15+ 127.0.0.1:48094]
I0530 00:16:41.476772       1 wrap.go:47] GET /healthz: (64.926µs) 200 [kube-probe/1.15+ 127.0.0.1:48128]
I0530 00:16:43.058089       1 scheduling_queue.go:895] About to try and schedule pod volume-5889/gcepd-client
I0530 00:16:43.058115       1 scheduler.go:454] Attempting to schedule pod: volume-5889/gcepd-client
I0530 00:16:43.058353       1 scheduler_binder.go:651] All bound volumes for Pod "volume-5889/gcepd-client" match with Node "e2e-test-peterhornyack-windows-node-group-9q9v"
I0530 00:16:43.058416       1 scheduler_binder.go:651] All bound volumes for Pod "volume-5889/gcepd-client" match with Node "e2e-test-peterhornyack-windows-node-group-1vjk"
I0530 00:16:43.058501       1 scheduler_binder.go:651] All bound volumes for Pod "volume-5889/gcepd-client" match with Node "e2e-test-peterhornyack-windows-node-group-jpxd"
I0530 00:16:43.058668       1 scheduler_binder.go:255] AssumePodVolumes for pod "volume-5889/gcepd-client", node "e2e-test-peterhornyack-windows-node-group-jpxd"
I0530 00:16:43.058677       1 scheduler_binder.go:265] AssumePodVolumes for pod "volume-5889/gcepd-client", node "e2e-test-peterhornyack-windows-node-group-jpxd": all PVCs bound and nothing to do
I0530 00:16:43.058727       1 factory.go:734] Attempting to bind gcepd-client to e2e-test-peterhornyack-windows-node-group-jpxd
I0530 00:16:43.065784       1 scheduler.go:575] pod volume-5889/gcepd-client is bound successfully on node e2e-test-peterhornyack-windows-node-group-jpxd, 6 nodes evaluated, 3 nodes were found feasible
I0530 00:16:51.476865       1 wrap.go:47] GET /healthz: (66.835µs) 200 [kube-probe/1.15+ 127.0.0.1:48160]
I0530 00:17:01.476913       1 wrap.go:47] GET /healthz: (73.365µs) 200 [kube-probe/1.15+ 127.0.0.1:48210]
I0530 00:17:02.821540       1 reflector.go:384] cmd/kube-scheduler/app/server.go:223: Watch close - *v1.Pod total 120 items received
I0530 00:17:11.477006       1 wrap.go:47] GET /healthz: (50.011µs) 200 [kube-probe/1.15+ 127.0.0.1:48244]
I0530 00:17:21.476872       1 wrap.go:47] GET /healthz: (88.205µs) 200 [kube-probe/1.15+ 127.0.0.1:48282]
I0530 00:17:29.623854       1 scheduling_queue.go:895] About to try and schedule pod replication-controller-6223/condition-test-xpfjt
I0530 00:17:29.623876       1 scheduler.go:454] Attempting to schedule pod: replication-controller-6223/condition-test-xpfjt
I0530 00:17:29.627903       1 scheduler_binder.go:255] AssumePodVolumes for pod "replication-controller-6223/condition-test-xpfjt", node "e2e-test-peterhornyack-windows-node-group-jpxd"
I0530 00:17:29.627920       1 scheduler_binder.go:265] AssumePodVolumes for pod "replication-controller-6223/condition-test-xpfjt", node "e2e-test-peterhornyack-windows-node-group-jpxd": all PVCs bound and nothing to do
I0530 00:17:29.630551       1 factory.go:734] Attempting to bind condition-test-xpfjt to e2e-test-peterhornyack-windows-node-group-jpxd
I0530 00:17:29.648908       1 scheduler.go:575] pod replication-controller-6223/condition-test-xpfjt is bound successfully on node e2e-test-peterhornyack-windows-node-group-jpxd, 6 nodes evaluated, 3 nodes were found feasible
I0530 00:17:29.659708       1 scheduling_queue.go:895] About to try and schedule pod replication-controller-6223/condition-test-cqrfj
I0530 00:17:29.659720       1 scheduler.go:454] Attempting to schedule pod: replication-controller-6223/condition-test-cqrfj
I0530 00:17:29.660024       1 scheduler_binder.go:255] AssumePodVolumes for pod "replication-controller-6223/condition-test-cqrfj", node "e2e-test-peterhornyack-windows-node-group-1vjk"
I0530 00:17:29.660034       1 scheduler_binder.go:265] AssumePodVolumes for pod "replication-controller-6223/condition-test-cqrfj", node "e2e-test-peterhornyack-windows-node-group-1vjk": all PVCs bound and nothing to do
I0530 00:17:29.660068       1 factory.go:734] Attempting to bind condition-test-cqrfj to e2e-test-peterhornyack-windows-node-group-1vjk
I0530 00:17:29.681757       1 scheduler.go:575] pod replication-controller-6223/condition-test-cqrfj is bound successfully on node e2e-test-peterhornyack-windows-node-group-1vjk, 6 nodes evaluated, 3 nodes were found feasible
I0530 00:17:31.477926       1 wrap.go:47] GET /healthz: (94.889µs) 200 [kube-probe/1.15+ 127.0.0.1:48316]
I0530 00:17:38.825495       1 scheduling_queue.go:895] About to try and schedule pod hostpath-8011/pod-host-path-test
I0530 00:17:38.825508       1 scheduler.go:454] Attempting to schedule pod: hostpath-8011/pod-host-path-test
I0530 00:17:38.825763       1 scheduler_binder.go:255] AssumePodVolumes for pod "hostpath-8011/pod-host-path-test", node "e2e-test-peterhornyack-windows-node-group-9q9v"
I0530 00:17:38.825788       1 scheduler_binder.go:265] AssumePodVolumes for pod "hostpath-8011/pod-host-path-test", node "e2e-test-peterhornyack-windows-node-group-9q9v": all PVCs bound and nothing to do
I0530 00:17:38.825824       1 factory.go:734] Attempting to bind pod-host-path-test to e2e-test-peterhornyack-windows-node-group-9q9v
I0530 00:17:38.834907       1 scheduler.go:575] pod hostpath-8011/pod-host-path-test is bound successfully on node e2e-test-peterhornyack-windows-node-group-9q9v, 6 nodes evaluated, 3 nodes were found feasible
I0530 00:17:41.477004       1 wrap.go:47] GET /healthz: (86.689µs) 200 [kube-probe/1.15+ 127.0.0.1:48352]
I0530 00:17:45.787328       1 reflector.go:384] k8s.io/client-go/informers/factory.go:133: Watch close - *v1.StorageClass total 0 items received
I0530 00:17:51.476753       1 wrap.go:47] GET /healthz: (67.218µs) 200 [kube-probe/1.15+ 127.0.0.1:48384]
I0530 00:18:01.476564       1 wrap.go:47] GET /healthz: (91.078µs) 200 [kube-probe/1.15+ 127.0.0.1:48432]
I0530 00:18:03.486742       1 scheduling_queue.go:895] About to try and schedule pod windows-volumes-7372/pod-728dbd60-2159-496e-a020-33028e78e61f
I0530 00:18:03.486758       1 scheduler.go:454] Attempting to schedule pod: windows-volumes-7372/pod-728dbd60-2159-496e-a020-33028e78e61f
I0530 00:18:03.487341       1 scheduler_binder.go:255] AssumePodVolumes for pod "windows-volumes-7372/pod-728dbd60-2159-496e-a020-33028e78e61f", node "e2e-test-peterhornyack-windows-node-group-jpxd"
I0530 00:18:03.487355       1 scheduler_binder.go:265] AssumePodVolumes for pod "windows-volumes-7372/pod-728dbd60-2159-496e-a020-33028e78e61f", node "e2e-test-peterhornyack-windows-node-group-jpxd": all PVCs bound and nothing to do
I0530 00:18:03.487414       1 factory.go:734] Attempting to bind pod-728dbd60-2159-496e-a020-33028e78e61f to e2e-test-peterhornyack-windows-node-group-jpxd
I0530 00:18:03.493561       1 scheduler.go:575] pod windows-volumes-7372/pod-728dbd60-2159-496e-a020-33028e78e61f is bound successfully on node e2e-test-peterhornyack-windows-node-group-jpxd, 6 nodes evaluated, 3 nodes were found feasible
I0530 00:18:11.476740       1 wrap.go:47] GET /healthz: (79.053µs) 200 [kube-probe/1.15+ 127.0.0.1:48466]
I0530 00:18:12.052314       1 scheduling_queue.go:895] About to try and schedule pod windows-volumes-7372/pod-a95a2661-ca38-4cf5-8fb6-80fc724e6339
I0530 00:18:12.052326       1 scheduler.go:454] Attempting to schedule pod: windows-volumes-7372/pod-a95a2661-ca38-4cf5-8fb6-80fc724e6339
I0530 00:18:12.052736       1 scheduler_binder.go:255] AssumePodVolumes for pod "windows-volumes-7372/pod-a95a2661-ca38-4cf5-8fb6-80fc724e6339", node "e2e-test-peterhornyack-windows-node-group-jpxd"
I0530 00:18:12.052747       1 scheduler_binder.go:265] AssumePodVolumes for pod "windows-volumes-7372/pod-a95a2661-ca38-4cf5-8fb6-80fc724e6339", node "e2e-test-peterhornyack-windows-node-group-jpxd": all PVCs bound and nothing to do
I0530 00:18:12.053694       1 factory.go:734] Attempting to bind pod-a95a2661-ca38-4cf5-8fb6-80fc724e6339 to e2e-test-peterhornyack-windows-node-group-jpxd
I0530 00:18:12.061391       1 scheduler.go:575] pod windows-volumes-7372/pod-a95a2661-ca38-4cf5-8fb6-80fc724e6339 is bound successfully on node e2e-test-peterhornyack-windows-node-group-jpxd, 6 nodes evaluated, 3 nodes were found feasible
I0530 00:18:21.476641       1 wrap.go:47] GET /healthz: (51.779µs) 200 [kube-probe/1.15+ 127.0.0.1:48510]
I0530 00:18:31.477758       1 wrap.go:47] GET /healthz: (124.556µs) 200 [kube-probe/1.15+ 127.0.0.1:48544]
I0530 00:18:41.476920       1 wrap.go:47] GET /healthz: (49.501µs) 200 [kube-probe/1.15+ 127.0.0.1:48578]
I0530 00:18:45.254517       1 scheduling_queue.go:895] About to try and schedule pod downward-api-7357/downwardapi-volume-bcb76f3c-8fe9-40b0-aa83-cd4e1ee8893f
I0530 00:18:45.254533       1 scheduler.go:454] Attempting to schedule pod: downward-api-7357/downwardapi-volume-bcb76f3c-8fe9-40b0-aa83-cd4e1ee8893f
I0530 00:18:45.254954       1 scheduler_binder.go:255] AssumePodVolumes for pod "downward-api-7357/downwardapi-volume-bcb76f3c-8fe9-40b0-aa83-cd4e1ee8893f", node "e2e-test-peterhornyack-windows-node-group-9q9v"
I0530 00:18:45.254979       1 scheduler_binder.go:265] AssumePodVolumes for pod "downward-api-7357/downwardapi-volume-bcb76f3c-8fe9-40b0-aa83-cd4e1ee8893f", node "e2e-test-peterhornyack-windows-node-group-9q9v": all PVCs bound and nothing to do
I0530 00:18:45.255039       1 factory.go:734] Attempting to bind downwardapi-volume-bcb76f3c-8fe9-40b0-aa83-cd4e1ee8893f to e2e-test-peterhornyack-windows-node-group-9q9v
I0530 00:18:45.262659       1 scheduler.go:575] pod downward-api-7357/downwardapi-volume-bcb76f3c-8fe9-40b0-aa83-cd4e1ee8893f is bound successfully on node e2e-test-peterhornyack-windows-node-group-9q9v, 6 nodes evaluated, 3 nodes were found feasible
I0530 00:18:51.476729       1 wrap.go:47] GET /healthz: (75.632µs) 200 [kube-probe/1.15+ 127.0.0.1:48614]
I0530 00:18:56.804911       1 reflector.go:384] k8s.io/client-go/informers/factory.go:133: Watch close - *v1beta1.PodDisruptionBudget total 0 items received
I0530 00:19:01.477671       1 wrap.go:47] GET /healthz: (74.527µs) 200 [kube-probe/1.15+ 127.0.0.1:48662]
I0530 00:19:01.680136       1 scheduling_queue.go:895] About to try and schedule pod projected-9759/downwardapi-volume-a3222e81-4058-458e-857e-30e373085049
I0530 00:19:01.680915       1 scheduler.go:454] Attempting to schedule pod: projected-9759/downwardapi-volume-a3222e81-4058-458e-857e-30e373085049
I0530 00:19:01.681449       1 scheduler_binder.go:255] AssumePodVolumes for pod "projected-9759/downwardapi-volume-a3222e81-4058-458e-857e-30e373085049", node "e2e-test-peterhornyack-windows-node-group-9q9v"
I0530 00:19:01.681480       1 scheduler_binder.go:265] AssumePodVolumes for pod "projected-9759/downwardapi-volume-a3222e81-4058-458e-857e-30e373085049", node "e2e-test-peterhornyack-windows-node-group-9q9v": all PVCs bound and nothing to do
I0530 00:19:01.681527       1 factory.go:734] Attempting to bind downwardapi-volume-a3222e81-4058-458e-857e-30e373085049 to e2e-test-peterhornyack-windows-node-group-9q9v
I0530 00:19:01.688586       1 scheduler.go:575] pod projected-9759/downwardapi-volume-a3222e81-4058-458e-857e-30e373085049 is bound successfully on node e2e-test-peterhornyack-windows-node-group-9q9v, 6 nodes evaluated, 3 nodes were found feasible
I0530 00:19:11.476800       1 wrap.go:47] GET /healthz: (80.826µs) 200 [kube-probe/1.15+ 127.0.0.1:48696]
I0530 00:19:16.252830       1 scheduling_queue.go:895] About to try and schedule pod svc-latency-1433/svc-latency-rc-7xmtg
I0530 00:19:16.252844       1 scheduler.go:454] Attempting to schedule pod: svc-latency-1433/svc-latency-rc-7xmtg
I0530 00:19:16.253633       1 scheduler_binder.go:255] AssumePodVolumes for pod "svc-latency-1433/svc-latency-rc-7xmtg", node "e2e-test-peterhornyack-windows-node-group-jpxd"
I0530 00:19:16.253646       1 scheduler_binder.go:265] AssumePodVolumes for pod "svc-latency-1433/svc-latency-rc-7xmtg", node "e2e-test-peterhornyack-windows-node-group-jpxd": all PVCs bound and nothing to do
I0530 00:19:16.253689       1 factory.go:734] Attempting to bind svc-latency-rc-7xmtg to e2e-test-peterhornyack-windows-node-group-jpxd
I0530 00:19:16.266754       1 scheduler.go:575] pod svc-latency-1433/svc-latency-rc-7xmtg is bound successfully on node e2e-test-peterhornyack-windows-node-group-jpxd, 6 nodes evaluated, 3 nodes were found feasible
I0530 00:19:21.476722       1 wrap.go:47] GET /healthz: (74.978µs) 200 [kube-probe/1.15+ 127.0.0.1:48732]
I0530 00:19:31.477311       1 wrap.go:47] GET /healthz: (65.491µs) 200 [kube-probe/1.15+ 127.0.0.1:48784]
I0530 00:19:41.477143       1 wrap.go:47] GET /healthz: (68.253µs) 200 [kube-probe/1.15+ 127.0.0.1:48818]
I0530 00:19:51.476801       1 wrap.go:47] GET /healthz: (64.131µs) 200 [kube-probe/1.15+ 127.0.0.1:48852]
I0530 00:19:58.559989       1 scheduling_queue.go:895] About to try and schedule pod services-9045/pod1
I0530 00:19:58.560000       1 scheduler.go:454] Attempting to schedule pod: services-9045/pod1
I0530 00:19:58.563978       1 scheduler_binder.go:255] AssumePodVolumes for pod "services-9045/pod1", node "e2e-test-peterhornyack-windows-node-group-jpxd"
I0530 00:19:58.564004       1 scheduler_binder.go:265] AssumePodVolumes for pod "services-9045/pod1", node "e2e-test-peterhornyack-windows-node-group-jpxd": all PVCs bound and nothing to do
I0530 00:19:58.564054       1 factory.go:734] Attempting to bind pod1 to e2e-test-peterhornyack-windows-node-group-jpxd
I0530 00:19:58.572593       1 scheduler.go:575] pod services-9045/pod1 is bound successfully on node e2e-test-peterhornyack-windows-node-group-jpxd, 6 nodes evaluated, 3 nodes were found feasible
I0530 00:20:01.477069       1 wrap.go:47] GET /healthz: (72.569µs) 200 [kube-probe/1.15+ 127.0.0.1:48902]
I0530 00:20:05.197392       1 scheduling_queue.go:895] About to try and schedule pod services-9045/pod2
I0530 00:20:05.197405       1 scheduler.go:454] Attempting to schedule pod: services-9045/pod2
I0530 00:20:05.197736       1 scheduler_binder.go:255] AssumePodVolumes for pod "services-9045/pod2", node "e2e-test-peterhornyack-windows-node-group-jpxd"
I0530 00:20:05.197745       1 scheduler_binder.go:265] AssumePodVolumes for pod "services-9045/pod2", node "e2e-test-peterhornyack-windows-node-group-jpxd": all PVCs bound and nothing to do
I0530 00:20:05.197787       1 factory.go:734] Attempting to bind pod2 to e2e-test-peterhornyack-windows-node-group-jpxd
I0530 00:20:05.207759       1 scheduler.go:575] pod services-9045/pod2 is bound successfully on node e2e-test-peterhornyack-windows-node-group-jpxd, 6 nodes evaluated, 3 nodes were found feasible
I0530 00:20:11.477400       1 wrap.go:47] GET /healthz: (51.577µs) 200 [kube-probe/1.15+ 127.0.0.1:48938]
I0530 00:20:16.776150       1 reflector.go:384] k8s.io/client-go/informers/factory.go:133: Watch close - *v1.ReplicationController total 19 items received
I0530 00:20:21.476546       1 wrap.go:47] GET /healthz: (97.48µs) 200 [kube-probe/1.15+ 127.0.0.1:48984]
I0530 00:20:31.476858       1 wrap.go:47] GET /healthz: (82.277µs) 200 [kube-probe/1.15+ 127.0.0.1:49018]
I0530 00:20:41.476844       1 wrap.go:47] GET /healthz: (63.456µs) 200 [kube-probe/1.15+ 127.0.0.1:49052]
I0530 00:20:51.308367       1 scheduling_queue.go:895] About to try and schedule pod secrets-1696/pod-secrets-44d74f6f-24bb-4110-826c-87a757a03b3f
I0530 00:20:51.308393       1 scheduler.go:454] Attempting to schedule pod: secrets-1696/pod-secrets-44d74f6f-24bb-4110-826c-87a757a03b3f
I0530 00:20:51.308780       1 scheduler_binder.go:255] AssumePodVolumes for pod "secrets-1696/pod-secrets-44d74f6f-24bb-4110-826c-87a757a03b3f", node "e2e-test-peterhornyack-windows-node-group-9q9v"
I0530 00:20:51.308791       1 scheduler_binder.go:265] AssumePodVolumes for pod "secrets-1696/pod-secrets-44d74f6f-24bb-4110-826c-87a757a03b3f", node "e2e-test-peterhornyack-windows-node-group-9q9v": all PVCs bound and nothing to do
I0530 00:20:51.308854       1 factory.go:734] Attempting to bind pod-secrets-44d74f6f-24bb-4110-826c-87a757a03b3f to e2e-test-peterhornyack-windows-node-group-9q9v
I0530 00:20:51.318629       1 scheduler.go:575] pod secrets-1696/pod-secrets-44d74f6f-24bb-4110-826c-87a757a03b3f is bound successfully on node e2e-test-peterhornyack-windows-node-group-9q9v, 6 nodes evaluated, 3 nodes were found feasible
I0530 00:20:51.476645       1 wrap.go:47] GET /healthz: (117.329µs) 200 [kube-probe/1.15+ 127.0.0.1:49084]
I0530 00:20:59.795197       1 reflector.go:384] k8s.io/client-go/informers/factory.go:133: Watch close - *v1.StatefulSet total 0 items received
I0530 00:21:01.476707       1 wrap.go:47] GET /healthz: (72.846µs) 200 [kube-probe/1.15+ 127.0.0.1:49132]
I0530 00:21:07.748688       1 scheduling_queue.go:895] About to try and schedule pod projected-3835/pod-projected-secrets-72c7df68-3f4b-430e-99ec-a26deef242fb
I0530 00:21:07.748723       1 scheduler.go:454] Attempting to schedule pod: projected-3835/pod-projected-secrets-72c7df68-3f4b-430e-99ec-a26deef242fb
I0530 00:21:07.749285       1 scheduler_binder.go:255] AssumePodVolumes for pod "projected-3835/pod-projected-secrets-72c7df68-3f4b-430e-99ec-a26deef242fb", node "e2e-test-peterhornyack-windows-node-group-9q9v"
I0530 00:21:07.749298       1 scheduler_binder.go:265] AssumePodVolumes for pod "projected-3835/pod-projected-secrets-72c7df68-3f4b-430e-99ec-a26deef242fb", node "e2e-test-peterhornyack-windows-node-group-9q9v": all PVCs bound and nothing to do
I0530 00:21:07.749358       1 factory.go:734] Attempting to bind pod-projected-secrets-72c7df68-3f4b-430e-99ec-a26deef242fb to e2e-test-peterhornyack-windows-node-group-9q9v
I0530 00:21:07.756688       1 scheduler.go:575] pod projected-3835/pod-projected-secrets-72c7df68-3f4b-430e-99ec-a26deef242fb is bound successfully on node e2e-test-peterhornyack-windows-node-group-9q9v, 6 nodes evaluated, 3 nodes were found feasible
I0530 00:21:11.476834       1 wrap.go:47] GET /healthz: (106.032µs) 200 [kube-probe/1.15+ 127.0.0.1:49168]
I0530 00:21:21.476813       1 wrap.go:47] GET /healthz: (75.757µs) 200 [kube-probe/1.15+ 127.0.0.1:49204]
I0530 00:21:31.476430       1 wrap.go:47] GET /healthz: (48.012µs) 200 [kube-probe/1.15+ 127.0.0.1:49238]
I0530 00:21:32.600785       1 scheduling_queue.go:895] About to try and schedule pod kubectl-6774/e2e-test-rm-busybox-job-p9n9r
I0530 00:21:32.600799       1 scheduler.go:454] Attempting to schedule pod: kubectl-6774/e2e-test-rm-busybox-job-p9n9r
I0530 00:21:32.602698       1 scheduler_binder.go:255] AssumePodVolumes for pod "kubectl-6774/e2e-test-rm-busybox-job-p9n9r", node "e2e-test-peterhornyack-windows-node-group-9q9v"
I0530 00:21:32.602725       1 scheduler_binder.go:265] AssumePodVolumes for pod "kubectl-6774/e2e-test-rm-busybox-job-p9n9r", node "e2e-test-peterhornyack-windows-node-group-9q9v": all PVCs bound and nothing to do
I0530 00:21:32.602774       1 factory.go:734] Attempting to bind e2e-test-rm-busybox-job-p9n9r to e2e-test-peterhornyack-windows-node-group-9q9v
I0530 00:21:32.619008       1 scheduler.go:575] pod kubectl-6774/e2e-test-rm-busybox-job-p9n9r is bound successfully on node e2e-test-peterhornyack-windows-node-group-9q9v, 6 nodes evaluated, 3 nodes were found feasible
I0530 00:21:41.476328       1 wrap.go:47] GET /healthz: (63.675µs) 200 [kube-probe/1.15+ 127.0.0.1:49276]
I0530 00:21:42.809750       1 reflector.go:384] k8s.io/client-go/informers/factory.go:133: Watch close - *v1.ReplicaSet total 0 items received
I0530 00:21:51.476797       1 wrap.go:47] GET /healthz: (79.466µs) 200 [kube-probe/1.15+ 127.0.0.1:49308]
I0530 00:21:52.575642       1 scheduling_queue.go:895] About to try and schedule pod projected-2494/pod-projected-secrets-ffff9f30-5702-4b32-8c03-c75d07e875f3
I0530 00:21:52.575655       1 scheduler.go:454] Attempting to schedule pod: projected-2494/pod-projected-secrets-ffff9f30-5702-4b32-8c03-c75d07e875f3
I0530 00:21:52.575985       1 scheduler_binder.go:255] AssumePodVolumes for pod "projected-2494/pod-projected-secrets-ffff9f30-5702-4b32-8c03-c75d07e875f3", node "e2e-test-peterhornyack-windows-node-group-9q9v"
I0530 00:21:52.575997       1 scheduler_binder.go:265] AssumePodVolumes for pod "projected-2494/pod-projected-secrets-ffff9f30-5702-4b32-8c03-c75d07e875f3", node "e2e-test-peterhornyack-windows-node-group-9q9v": all PVCs bound and nothing to do
I0530 00:21:52.576051       1 factory.go:734] Attempting to bind pod-projected-secrets-ffff9f30-5702-4b32-8c03-c75d07e875f3 to e2e-test-peterhornyack-windows-node-group-9q9v
I0530 00:21:52.582519       1 scheduler.go:575] pod projected-2494/pod-projected-secrets-ffff9f30-5702-4b32-8c03-c75d07e875f3 is bound successfully on node e2e-test-peterhornyack-windows-node-group-9q9v, 6 nodes evaluated, 3 nodes were found feasible
I0530 00:22:00.817048       1 reflector.go:384] k8s.io/client-go/informers/factory.go:133: Watch close - *v1.PersistentVolume total 7 items received
I0530 00:22:01.476652       1 wrap.go:47] GET /healthz: (58.11µs) 200 [kube-probe/1.15+ 127.0.0.1:49356]
I0530 00:22:05.768917       1 reflector.go:384] k8s.io/client-go/informers/factory.go:133: Watch close - *v1.Node total 55 items received
I0530 00:22:11.478349       1 wrap.go:47] GET /healthz: (76.506µs) 200 [kube-probe/1.15+ 127.0.0.1:49390]
I0530 00:22:21.476703       1 wrap.go:47] GET /healthz: (80.776µs) 200 [kube-probe/1.15+ 127.0.0.1:49428]
I0530 00:22:31.476911       1 wrap.go:47] GET /healthz: (61.482µs) 200 [kube-probe/1.15+ 127.0.0.1:49462]
I0530 00:22:41.476620       1 wrap.go:47] GET /healthz: (61.59µs) 200 [kube-probe/1.15+ 127.0.0.1:49496]
I0530 00:22:51.477061       1 wrap.go:47] GET /healthz: (78.422µs) 200 [kube-probe/1.15+ 127.0.0.1:49528]
I0530 00:23:01.476835       1 wrap.go:47] GET /healthz: (49.647µs) 200 [kube-probe/1.15+ 127.0.0.1:49576]
I0530 00:23:11.477183       1 wrap.go:47] GET /healthz: (68.278µs) 200 [kube-probe/1.15+ 127.0.0.1:49612]
I0530 00:23:21.476660       1 wrap.go:47] GET /healthz: (73.979µs) 200 [kube-probe/1.15+ 127.0.0.1:49648]
I0530 00:23:31.476819       1 wrap.go:47] GET /healthz: (109.431µs) 200 [kube-probe/1.15+ 127.0.0.1:49684]
I0530 00:23:38.824114       1 reflector.go:384] k8s.io/client-go/informers/factory.go:133: Watch close - *v1.PersistentVolumeClaim total 5 items received
I0530 00:23:41.476865       1 wrap.go:47] GET /healthz: (86.174µs) 200 [kube-probe/1.15+ 127.0.0.1:49718]
I0530 00:23:51.477577       1 wrap.go:47] GET /healthz: (87.469µs) 200 [kube-probe/1.15+ 127.0.0.1:49750]
I0530 00:24:01.476775       1 wrap.go:47] GET /healthz: (83.829µs) 200 [kube-probe/1.15+ 127.0.0.1:49798]
I0530 00:24:11.478742       1 wrap.go:47] GET /healthz: (90.482µs) 200 [kube-probe/1.15+ 127.0.0.1:49832]
I0530 00:24:21.476938       1 wrap.go:47] GET /healthz: (84.367µs) 200 [kube-probe/1.15+ 127.0.0.1:49868]
I0530 00:24:31.476785       1 wrap.go:47] GET /healthz: (76.612µs) 200 [kube-probe/1.15+ 127.0.0.1:49902]
I0530 00:24:33.619752       1 scheduling_queue.go:895] About to try and schedule pod kubectl-9754/redis-master-ndgtz
I0530 00:24:33.619766       1 scheduler.go:454] Attempting to schedule pod: kubectl-9754/redis-master-ndgtz
I0530 00:24:33.622564       1 scheduler_binder.go:255] AssumePodVolumes for pod "kubectl-9754/redis-master-ndgtz", node "e2e-test-peterhornyack-windows-node-group-1vjk"
I0530 00:24:33.622577       1 scheduler_binder.go:265] AssumePodVolumes for pod "kubectl-9754/redis-master-ndgtz", node "e2e-test-peterhornyack-windows-node-group-1vjk": all PVCs bound and nothing to do
I0530 00:24:33.622655       1 factory.go:734] Attempting to bind redis-master-ndgtz to e2e-test-peterhornyack-windows-node-group-1vjk
I0530 00:24:33.634983       1 scheduler.go:575] pod kubectl-9754/redis-master-ndgtz is bound successfully on node e2e-test-peterhornyack-windows-node-group-1vjk, 6 nodes evaluated, 3 nodes were found feasible
I0530 00:24:41.476821       1 wrap.go:47] GET /healthz: (51.617µs) 200 [kube-probe/1.15+ 127.0.0.1:49942]
I0530 00:24:51.477533       1 wrap.go:47] GET /healthz: (80.721µs) 200 [kube-probe/1.15+ 127.0.0.1:49986]
I0530 00:25:01.476522       1 wrap.go:47] GET /healthz: (92.815µs) 200 [kube-probe/1.15+ 127.0.0.1:50034]
I0530 00:25:11.476738       1 wrap.go:47] GET /healthz: (109.31µs) 200 [kube-probe/1.15+ 127.0.0.1:50068]
I0530 00:25:15.766719       1 scheduling_queue.go:895] About to try and schedule pod emptydir-wrapper-3531/pod-secrets-c0093d20-427f-4231-b3da-7a00d4c2ce69
I0530 00:25:15.766732       1 scheduler.go:454] Attempting to schedule pod: emptydir-wrapper-3531/pod-secrets-c0093d20-427f-4231-b3da-7a00d4c2ce69
I0530 00:25:15.767268       1 scheduler_binder.go:255] AssumePodVolumes for pod "emptydir-wrapper-3531/pod-secrets-c0093d20-427f-4231-b3da-7a00d4c2ce69", node "e2e-test-peterhornyack-windows-node-group-jpxd"
I0530 00:25:15.767280       1 scheduler_binder.go:265] AssumePodVolumes for pod "emptydir-wrapper-3531/pod-secrets-c0093d20-427f-4231-b3da-7a00d4c2ce69", node "e2e-test-peterhornyack-windows-node-group-jpxd": all PVCs bound and nothing to do
I0530 00:25:15.767333       1 factory.go:734] Attempting to bind pod-secrets-c0093d20-427f-4231-b3da-7a00d4c2ce69 to e2e-test-peterhornyack-windows-node-group-jpxd
I0530 00:25:15.775645       1 scheduler.go:575] pod emptydir-wrapper-3531/pod-secrets-c0093d20-427f-4231-b3da-7a00d4c2ce69 is bound successfully on node e2e-test-peterhornyack-windows-node-group-jpxd, 6 nodes evaluated, 3 nodes were found feasible
I0530 00:25:16.797537       1 reflector.go:384] k8s.io/client-go/informers/factory.go:133: Watch close - *v1.Service total 406 items received
I0530 00:25:21.476716       1 wrap.go:47] GET /healthz: (105.106µs) 200 [kube-probe/1.15+ 127.0.0.1:50104]
I0530 00:25:30.033607       1 scheduling_queue.go:895] About to try and schedule pod container-probe-4175/liveness-exec
I0530 00:25:30.033620       1 scheduler.go:454] Attempting to schedule pod: container-probe-4175/liveness-exec
I0530 00:25:30.034263       1 scheduler_binder.go:255] AssumePodVolumes for pod "container-probe-4175/liveness-exec", node "e2e-test-peterhornyack-windows-node-group-9q9v"
I0530 00:25:30.034277       1 scheduler_binder.go:265] AssumePodVolumes for pod "container-probe-4175/liveness-exec", node "e2e-test-peterhornyack-windows-node-group-9q9v": all PVCs bound and nothing to do
I0530 00:25:30.034311       1 factory.go:734] Attempting to bind liveness-exec to e2e-test-peterhornyack-windows-node-group-9q9v
I0530 00:25:30.043310       1 scheduler.go:575] pod container-probe-4175/liveness-exec is bound successfully on node e2e-test-peterhornyack-windows-node-group-9q9v, 6 nodes evaluated, 3 nodes were found feasible
I0530 00:25:31.476958       1 wrap.go:47] GET /healthz: (74.786µs) 200 [kube-probe/1.15+ 127.0.0.1:50138]
I0530 00:25:41.476831       1 wrap.go:47] GET /healthz: (73.056µs) 200 [kube-probe/1.15+ 127.0.0.1:50172]
I0530 00:25:51.477381       1 wrap.go:47] GET /healthz: (56.385µs) 200 [kube-probe/1.15+ 127.0.0.1:50206]
I0530 00:26:01.476769       1 wrap.go:47] GET /healthz: (51.156µs) 200 [kube-probe/1.15+ 127.0.0.1:50254]
I0530 00:26:11.477515       1 wrap.go:47] GET /healthz: (89.727µs) 200 [kube-probe/1.15+ 127.0.0.1:50290]
I0530 00:26:17.823873       1 reflector.go:384] cmd/kube-scheduler/app/server.go:223: Watch close - *v1.Pod total 105 items received
I0530 00:26:21.476647       1 wrap.go:47] GET /healthz: (81.156µs) 200 [kube-probe/1.15+ 127.0.0.1:50326]
I0530 00:26:31.477693       1 wrap.go:47] GET /healthz: (83.792µs) 200 [kube-probe/1.15+ 127.0.0.1:50360]
I0530 00:26:41.476730       1 wrap.go:47] GET /healthz: (69.358µs) 200 [kube-probe/1.15+ 127.0.0.1:50394]
I0530 00:26:51.476729       1 wrap.go:47] GET /healthz: (84.402µs) 200 [kube-probe/1.15+ 127.0.0.1:50426]
I0530 00:27:01.476955       1 wrap.go:47] GET /healthz: (89.756µs) 200 [kube-probe/1.15+ 127.0.0.1:50474]
I0530 00:27:11.476777       1 wrap.go:47] GET /healthz: (127.783µs) 200 [kube-probe/1.15+ 127.0.0.1:50510]
I0530 00:27:21.477086       1 wrap.go:47] GET /healthz: (76.615µs) 200 [kube-probe/1.15+ 127.0.0.1:50546]
I0530 00:27:30.789409       1 reflector.go:384] k8s.io/client-go/informers/factory.go:133: Watch close - *v1.StorageClass total 0 items received
I0530 00:27:31.476702       1 wrap.go:47] GET /healthz: (83.683µs) 200 [kube-probe/1.15+ 127.0.0.1:50582]
I0530 00:27:37.806959       1 reflector.go:384] k8s.io/client-go/informers/factory.go:133: Watch close - *v1beta1.PodDisruptionBudget total 0 items received
I0530 00:27:41.476983       1 wrap.go:47] GET /healthz: (80.829µs) 200 [kube-probe/1.15+ 127.0.0.1:50616]
I0530 00:27:45.770796       1 reflector.go:384] k8s.io/client-go/informers/factory.go:133: Watch close - *v1.Node total 44 items received
I0530 00:27:51.476642       1 wrap.go:47] GET /healthz: (65.395µs) 200 [kube-probe/1.15+ 127.0.0.1:50648]
I0530 00:28:01.477276       1 wrap.go:47] GET /healthz: (63.598µs) 200 [kube-probe/1.15+ 127.0.0.1:50696]
I0530 00:28:11.477142       1 wrap.go:47] GET /healthz: (67.638µs) 200 [kube-probe/1.15+ 127.0.0.1:50730]
I0530 00:28:21.476682       1 wrap.go:47] GET /healthz: (62.495µs) 200 [kube-probe/1.15+ 127.0.0.1:50768]
I0530 00:28:31.477293       1 wrap.go:47] GET /healthz: (68.938µs) 200 [kube-probe/1.15+ 127.0.0.1:50802]
I0530 00:28:41.476677       1 wrap.go:47] GET /healthz: (78.665µs) 200 [kube-probe/1.15+ 127.0.0.1:50836]
I0530 00:28:51.476656       1 wrap.go:47] GET /healthz: (64.03µs) 200 [kube-probe/1.15+ 127.0.0.1:50868]
I0530 00:29:01.477203       1 wrap.go:47] GET /healthz: (72.73µs) 200 [kube-probe/1.15+ 127.0.0.1:50918]
I0530 00:29:11.476759       1 wrap.go:47] GET /healthz: (80.677µs) 200 [kube-probe/1.15+ 127.0.0.1:50952]
I0530 00:29:21.476777       1 wrap.go:47] GET /healthz: (77.25µs) 200 [kube-probe/1.15+ 127.0.0.1:50988]
I0530 00:29:31.477078       1 wrap.go:47] GET /healthz: (91.97µs) 200 [kube-probe/1.15+ 127.0.0.1:51024]
I0530 00:29:41.477252       1 wrap.go:47] GET /healthz: (90.107µs) 200 [kube-probe/1.15+ 127.0.0.1:51058]
I0530 00:29:47.312544       1 scheduling_queue.go:895] About to try and schedule pod configmap-9718/pod-configmaps-29cd4f9e-9699-487a-bd9d-ac0159d99d73
I0530 00:29:47.312561       1 scheduler.go:454] Attempting to schedule pod: configmap-9718/pod-configmaps-29cd4f9e-9699-487a-bd9d-ac0159d99d73
I0530 00:29:47.313346       1 scheduler_binder.go:255] AssumePodVolumes for pod "configmap-9718/pod-configmaps-29cd4f9e-9699-487a-bd9d-ac0159d99d73", node "e2e-test-peterhornyack-windows-node-group-9q9v"
I0530 00:29:47.313372       1 scheduler_binder.go:265] AssumePodVolumes for pod "configmap-9718/pod-configmaps-29cd4f9e-9699-487a-bd9d-ac0159d99d73", node "e2e-test-peterhornyack-windows-node-group-9q9v": all PVCs bound and nothing to do
I0530 00:29:47.313417       1 factory.go:734] Attempting to bind pod-configmaps-29cd4f9e-9699-487a-bd9d-ac0159d99d73 to e2e-test-peterhornyack-windows-node-group-9q9v
I0530 00:29:47.319644       1 scheduler.go:575] pod configmap-9718/pod-configmaps-29cd4f9e-9699-487a-bd9d-ac0159d99d73 is bound successfully on node e2e-test-peterhornyack-windows-node-group-9q9v, 6 nodes evaluated, 3 nodes were found feasible
I0530 00:29:49.819225       1 reflector.go:384] k8s.io/client-go/informers/factory.go:133: Watch close - *v1.PersistentVolume total 0 items received
I0530 00:29:50.800236       1 reflector.go:384] k8s.io/client-go/informers/factory.go:133: Watch close - *v1.StatefulSet total 0 items received
I0530 00:29:51.476825       1 wrap.go:47] GET /healthz: (107.768µs) 200 [kube-probe/1.15+ 127.0.0.1:51092]
I0530 00:29:51.779696       1 reflector.go:384] k8s.io/client-go/informers/factory.go:133: Watch close - *v1.ReplicationController total 5 items received
I0530 00:30:01.476904       1 wrap.go:47] GET /healthz: (79.842µs) 200 [kube-probe/1.15+ 127.0.0.1:51140]
I0530 00:30:03.741233       1 scheduling_queue.go:895] About to try and schedule pod container-lifecycle-hook-9470/pod-handle-http-request
I0530 00:30:03.741247       1 scheduler.go:454] Attempting to schedule pod: container-lifecycle-hook-9470/pod-handle-http-request
I0530 00:30:03.742487       1 scheduler_binder.go:255] AssumePodVolumes for pod "container-lifecycle-hook-9470/pod-handle-http-request", node "e2e-test-peterhornyack-windows-node-group-jpxd"
I0530 00:30:03.742500       1 scheduler_binder.go:265] AssumePodVolumes for pod "container-lifecycle-hook-9470/pod-handle-http-request", node "e2e-test-peterhornyack-windows-node-group-jpxd": all PVCs bound and nothing to do
I0530 00:30:03.742563       1 factory.go:734] Attempting to bind pod-handle-http-request to e2e-test-peterhornyack-windows-node-group-jpxd
I0530 00:30:03.748054       1 scheduler.go:575] pod container-lifecycle-hook-9470/pod-handle-http-request is bound successfully on node e2e-test-peterhornyack-windows-node-group-jpxd, 6 nodes evaluated, 3 nodes were found feasible
I0530 00:30:11.476727       1 wrap.go:47] GET /healthz: (70.532µs) 200 [kube-probe/1.15+ 127.0.0.1:51174]
I0530 00:30:11.915312       1 scheduling_queue.go:895] About to try and schedule pod container-lifecycle-hook-9470/pod-with-prestop-exec-hook
I0530 00:30:11.915325       1 scheduler.go:454] Attempting to schedule pod: container-lifecycle-hook-9470/pod-with-prestop-exec-hook
I0530 00:30:11.915640       1 scheduler_binder.go:255] AssumePodVolumes for pod "container-lifecycle-hook-9470/pod-with-prestop-exec-hook", node "e2e-test-peterhornyack-windows-node-group-jpxd"
I0530 00:30:11.915651       1 scheduler_binder.go:265] AssumePodVolumes for pod "container-lifecycle-hook-9470/pod-with-prestop-exec-hook", node "e2e-test-peterhornyack-windows-node-group-jpxd": all PVCs bound and nothing to do
I0530 00:30:11.915702       1 factory.go:734] Attempting to bind pod-with-prestop-exec-hook to e2e-test-peterhornyack-windows-node-group-jpxd
I0530 00:30:11.921717       1 scheduler.go:575] pod container-lifecycle-hook-9470/pod-with-prestop-exec-hook is bound successfully on node e2e-test-peterhornyack-windows-node-group-jpxd, 6 nodes evaluated, 3 nodes were found feasible
I0530 00:30:21.477733       1 wrap.go:47] GET /healthz: (81.778µs) 200 [kube-probe/1.15+ 127.0.0.1:51210]
I0530 00:30:31.476803       1 wrap.go:47] GET /healthz: (89.842µs) 200 [kube-probe/1.15+ 127.0.0.1:51246]
I0530 00:30:41.476539       1 wrap.go:47] GET /healthz: (78.643µs) 200 [kube-probe/1.15+ 127.0.0.1:51282]
I0530 00:30:48.265322       1 scheduling_queue.go:895] About to try and schedule pod downward-api-6276/downwardapi-volume-39858914-a01d-4e8f-bd3a-615baf24b634
I0530 00:30:48.265349       1 scheduler.go:454] Attempting to schedule pod: downward-api-6276/downwardapi-volume-39858914-a01d-4e8f-bd3a-615baf24b634
I0530 00:30:48.265705       1 scheduler_binder.go:255] AssumePodVolumes for pod "downward-api-6276/downwardapi-volume-39858914-a01d-4e8f-bd3a-615baf24b634", node "e2e-test-peterhornyack-windows-node-group-9q9v"
I0530 00:30:48.265716       1 scheduler_binder.go:265] AssumePodVolumes for pod "downward-api-6276/downwardapi-volume-39858914-a01d-4e8f-bd3a-615baf24b634", node "e2e-test-peterhornyack-windows-node-group-9q9v": all PVCs bound and nothing to do
I0530 00:30:48.265787       1 factory.go:734] Attempting to bind downwardapi-volume-39858914-a01d-4e8f-bd3a-615baf24b634 to e2e-test-peterhornyack-windows-node-group-9q9v
I0530 00:30:48.272313       1 scheduler.go:575] pod downward-api-6276/downwardapi-volume-39858914-a01d-4e8f-bd3a-615baf24b634 is bound successfully on node e2e-test-peterhornyack-windows-node-group-9q9v, 6 nodes evaluated, 3 nodes were found feasible
I0530 00:30:51.477117       1 wrap.go:47] GET /healthz: (51.333µs) 200 [kube-probe/1.15+ 127.0.0.1:51314]
I0530 00:31:01.479678       1 wrap.go:47] GET /healthz: (95.203µs) 200 [kube-probe/1.15+ 127.0.0.1:51358]
I0530 00:31:02.678432       1 scheduling_queue.go:895] About to try and schedule pod container-runtime-1047/image-pull-testcc2959b9-0a82-4c46-8139-34c7b103889d
I0530 00:31:02.678446       1 scheduler.go:454] Attempting to schedule pod: container-runtime-1047/image-pull-testcc2959b9-0a82-4c46-8139-34c7b103889d
I0530 00:31:02.680636       1 scheduler_binder.go:255] AssumePodVolumes for pod "container-runtime-1047/image-pull-testcc2959b9-0a82-4c46-8139-34c7b103889d", node "e2e-test-peterhornyack-windows-node-group-1vjk"
I0530 00:31:02.680651       1 scheduler_binder.go:265] AssumePodVolumes for pod "container-runtime-1047/image-pull-testcc2959b9-0a82-4c46-8139-34c7b103889d", node "e2e-test-peterhornyack-windows-node-group-1vjk": all PVCs bound and nothing to do
I0530 00:31:02.680713       1 factory.go:734] Attempting to bind image-pull-testcc2959b9-0a82-4c46-8139-34c7b103889d to e2e-test-peterhornyack-windows-node-group-1vjk
I0530 00:31:02.688662       1 scheduler.go:575] pod container-runtime-1047/image-pull-testcc2959b9-0a82-4c46-8139-34c7b103889d is bound successfully on node e2e-test-peterhornyack-windows-node-group-1vjk, 6 nodes evaluated, 3 nodes were found feasible
I0530 00:31:11.476860       1 wrap.go:47] GET /healthz: (74.305µs) 200 [kube-probe/1.15+ 127.0.0.1:51396]
I0530 00:31:16.811914       1 reflector.go:384] k8s.io/client-go/informers/factory.go:133: Watch close - *v1.ReplicaSet total 0 items received
I0530 00:31:19.818140       1 scheduling_queue.go:895] About to try and schedule pod svcaccounts-4028/pod-service-account-defaultsa
I0530 00:31:19.818155       1 scheduler.go:454] Attempting to schedule pod: svcaccounts-4028/pod-service-account-defaultsa
I0530 00:31:19.819714       1 scheduler_binder.go:255] AssumePodVolumes for pod "svcaccounts-4028/pod-service-account-defaultsa", node "e2e-test-peterhornyack-windows-node-group-9q9v"
I0530 00:31:19.819729       1 scheduler_binder.go:265] AssumePodVolumes for pod "svcaccounts-4028/pod-service-account-defaultsa", node "e2e-test-peterhornyack-windows-node-group-9q9v": all PVCs bound and nothing to do
I0530 00:31:19.819801       1 factory.go:734] Attempting to bind pod-service-account-defaultsa to e2e-test-peterhornyack-windows-node-group-9q9v
I0530 00:31:19.829671       1 scheduler.go:575] pod svcaccounts-4028/pod-service-account-defaultsa is bound successfully on node e2e-test-peterhornyack-windows-node-group-9q9v, 6 nodes evaluated, 3 nodes were found feasible
I0530 00:31:19.865016       1 scheduling_queue.go:895] About to try and schedule pod svcaccounts-4028/pod-service-account-mountsa
I0530 00:31:19.865031       1 scheduler.go:454] Attempting to schedule pod: svcaccounts-4028/pod-service-account-mountsa
I0530 00:31:19.865775       1 scheduler_binder.go:255] AssumePodVolumes for pod "svcaccounts-4028/pod-service-account-mountsa", node "e2e-test-peterhornyack-windows-node-group-9q9v"
I0530 00:31:19.865789       1 scheduler_binder.go:265] AssumePodVolumes for pod "svcaccounts-4028/pod-service-account-mountsa", node "e2e-test-peterhornyack-windows-node-group-9q9v": all PVCs bound and nothing to do
I0530 00:31:19.865842       1 factory.go:734] Attempting to bind pod-service-account-mountsa to e2e-test-peterhornyack-windows-node-group-9q9v
I0530 00:31:19.875419       1 scheduler.go:575] pod svcaccounts-4028/pod-service-account-mountsa is bound successfully on node e2e-test-peterhornyack-windows-node-group-9q9v, 6 nodes evaluated, 3 nodes were found feasible
I0530 00:31:19.909613       1 scheduling_queue.go:895] About to try and schedule pod svcaccounts-4028/pod-service-account-nomountsa
I0530 00:31:19.909642       1 scheduler.go:454] Attempting to schedule pod: svcaccounts-4028/pod-service-account-nomountsa
I0530 00:31:19.910449       1 scheduler_binder.go:255] AssumePodVolumes for pod "svcaccounts-4028/pod-service-account-nomountsa", node "e2e-test-peterhornyack-windows-node-group-9q9v"
I0530 00:31:19.910481       1 scheduler_binder.go:265] AssumePodVolumes for pod "svcaccounts-4028/pod-service-account-nomountsa", node "e2e-test-peterhornyack-windows-node-group-9q9v": all PVCs bound and nothing to do
I0530 00:31:19.910536       1 factory.go:734] Attempting to bind pod-service-account-nomountsa to e2e-test-peterhornyack-windows-node-group-9q9v
I0530 00:31:19.918230       1 scheduler.go:575] pod svcaccounts-4028/pod-service-account-nomountsa is bound successfully on node e2e-test-peterhornyack-windows-node-group-9q9v, 6 nodes evaluated, 3 nodes were found feasible
I0530 00:31:19.953852       1 scheduling_queue.go:895] About to try and schedule pod svcaccounts-4028/pod-service-account-defaultsa-mountspec
I0530 00:31:19.953868       1 scheduler.go:454] Attempting to schedule pod: svcaccounts-4028/pod-service-account-defaultsa-mountspec
I0530 00:31:19.954208       1 scheduler_binder.go:255] AssumePodVolumes for pod "svcaccounts-4028/pod-service-account-defaultsa-mountspec", node "e2e-test-peterhornyack-windows-node-group-9q9v"
I0530 00:31:19.954220       1 scheduler_binder.go:265] AssumePodVolumes for pod "svcaccounts-4028/pod-service-account-defaultsa-mountspec", node "e2e-test-peterhornyack-windows-node-group-9q9v": all PVCs bound and nothing to do
I0530 00:31:19.954273       1 factory.go:734] Attempting to bind pod-service-account-defaultsa-mountspec to e2e-test-peterhornyack-windows-node-group-9q9v
I0530 00:31:19.962687       1 scheduler.go:575] pod svcaccounts-4028/pod-service-account-defaultsa-mountspec is bound successfully on node e2e-test-peterhornyack-windows-node-group-9q9v, 6 nodes evaluated, 3 nodes were found feasible
I0530 00:31:19.998608       1 scheduling_queue.go:895] About to try and schedule pod svcaccounts-4028/pod-service-account-mountsa-mountspec
I0530 00:31:19.998634       1 scheduler.go:454] Attempting to schedule pod: svcaccounts-4028/pod-service-account-mountsa-mountspec
I0530 00:31:19.998987       1 scheduler_binder.go:255] AssumePodVolumes for pod "svcaccounts-4028/pod-service-account-mountsa-mountspec", node "e2e-test-peterhornyack-windows-node-group-9q9v"
I0530 00:31:19.998998       1 scheduler_binder.go:265] AssumePodVolumes for pod "svcaccounts-4028/pod-service-account-mountsa-mountspec", node "e2e-test-peterhornyack-windows-node-group-9q9v": all PVCs bound and nothing to do
I0530 00:31:19.999055       1 factory.go:734] Attempting to bind pod-service-account-mountsa-mountspec to e2e-test-peterhornyack-windows-node-group-9q9v
I0530 00:31:20.005474       1 scheduler.go:575] pod svcaccounts-4028/pod-service-account-mountsa-mountspec is bound successfully on node e2e-test-peterhornyack-windows-node-group-9q9v, 6 nodes evaluated, 3 nodes were found feasible
I0530 00:31:20.042997       1 scheduling_queue.go:895] About to try and schedule pod svcaccounts-4028/pod-service-account-nomountsa-mountspec
I0530 00:31:20.043017       1 scheduler.go:454] Attempting to schedule pod: svcaccounts-4028/pod-service-account-nomountsa-mountspec
I0530 00:31:20.043556       1 scheduler_binder.go:255] AssumePodVolumes for pod "svcaccounts-4028/pod-service-account-nomountsa-mountspec", node "e2e-test-peterhornyack-windows-node-group-9q9v"
I0530 00:31:20.043569       1 scheduler_binder.go:265] AssumePodVolumes for pod "svcaccounts-4028/pod-service-account-nomountsa-mountspec", node "e2e-test-peterhornyack-windows-node-group-9q9v": all PVCs bound and nothing to do
I0530 00:31:20.043607       1 factory.go:734] Attempting to bind pod-service-account-nomountsa-mountspec to e2e-test-peterhornyack-windows-node-group-9q9v
I0530 00:31:20.051887       1 scheduler.go:575] pod svcaccounts-4028/pod-service-account-nomountsa-mountspec is bound successfully on node e2e-test-peterhornyack-windows-node-group-9q9v, 6 nodes evaluated, 3 nodes were found feasible
I0530 00:31:20.088851       1 scheduling_queue.go:895] About to try and schedule pod svcaccounts-4028/pod-service-account-defaultsa-nomountspec
I0530 00:31:20.088866       1 scheduler.go:454] Attempting to schedule pod: svcaccounts-4028/pod-service-account-defaultsa-nomountspec
I0530 00:31:20.090236       1 scheduler_binder.go:255] AssumePodVolumes for pod "svcaccounts-4028/pod-service-account-defaultsa-nomountspec", node "e2e-test-peterhornyack-windows-node-group-9q9v"
I0530 00:31:20.090249       1 scheduler_binder.go:265] AssumePodVolumes for pod "svcaccounts-4028/pod-service-account-defaultsa-nomountspec", node "e2e-test-peterhornyack-windows-node-group-9q9v": all PVCs bound and nothing to do
I0530 00:31:20.090306       1 factory.go:734] Attempting to bind pod-service-account-defaultsa-nomountspec to e2e-test-peterhornyack-windows-node-group-9q9v
I0530 00:31:20.096141       1 scheduler.go:575] pod svcaccounts-4028/pod-service-account-defaultsa-nomountspec is bound successfully on node e2e-test-peterhornyack-windows-node-group-9q9v, 6 nodes evaluated, 3 nodes were found feasible
I0530 00:31:20.137926       1 scheduling_queue.go:895] About to try and schedule pod svcaccounts-4028/pod-service-account-mountsa-nomountspec
I0530 00:31:20.137940       1 scheduler.go:454] Attempting to schedule pod: svcaccounts-4028/pod-service-account-mountsa-nomountspec
I0530 00:31:20.138247       1 scheduler_binder.go:255] AssumePodVolumes for pod "svcaccounts-4028/pod-service-account-mountsa-nomountspec", node "e2e-test-peterhornyack-windows-node-group-9q9v"
I0530 00:31:20.138258       1 scheduler_binder.go:265] AssumePodVolumes for pod "svcaccounts-4028/pod-service-account-mountsa-nomountspec", node "e2e-test-peterhornyack-windows-node-group-9q9v": all PVCs bound and nothing to do
I0530 00:31:20.138306       1 factory.go:734] Attempting to bind pod-service-account-mountsa-nomountspec to e2e-test-peterhornyack-windows-node-group-9q9v
I0530 00:31:20.154619       1 scheduler.go:575] pod svcaccounts-4028/pod-service-account-mountsa-nomountspec is bound successfully on node e2e-test-peterhornyack-windows-node-group-9q9v, 6 nodes evaluated, 3 nodes were found feasible
I0530 00:31:20.178477       1 scheduling_queue.go:895] About to try and schedule pod svcaccounts-4028/pod-service-account-nomountsa-nomountspec
I0530 00:31:20.178492       1 scheduler.go:454] Attempting to schedule pod: svcaccounts-4028/pod-service-account-nomountsa-nomountspec
I0530 00:31:20.178835       1 scheduler_binder.go:255] AssumePodVolumes for pod "svcaccounts-4028/pod-service-account-nomountsa-nomountspec", node "e2e-test-peterhornyack-windows-node-group-9q9v"
I0530 00:31:20.178846       1 scheduler_binder.go:265] AssumePodVolumes for pod "svcaccounts-4028/pod-service-account-nomountsa-nomountspec", node "e2e-test-peterhornyack-windows-node-group-9q9v": all PVCs bound and nothing to do
I0530 00:31:20.178904       1 factory.go:734] Attempting to bind pod-service-account-nomountsa-nomountspec to e2e-test-peterhornyack-windows-node-group-9q9v
I0530 00:31:20.200812       1 scheduler.go:575] pod svcaccounts-4028/pod-service-account-nomountsa-nomountspec is bound successfully on node e2e-test-peterhornyack-windows-node-group-9q9v, 6 nodes evaluated, 3 nodes were found feasible
I0530 00:31:21.476657       1 wrap.go:47] GET /healthz: (73.953µs) 200 [kube-probe/1.15+ 127.0.0.1:51434]
I0530 00:31:21.826312       1 reflector.go:384] k8s.io/client-go/informers/factory.go:133: Watch close - *v1.PersistentVolumeClaim total 0 items received
I0530 00:31:31.477408       1 wrap.go:47] GET /healthz: (84.984µs) 200 [kube-probe/1.15+ 127.0.0.1:51468]
I0530 00:31:41.476489       1 wrap.go:47] GET /healthz: (60.629µs) 200 [kube-probe/1.15+ 127.0.0.1:51502]
I0530 00:31:44.239421       1 scheduling_queue.go:895] About to try and schedule pod containers-3042/client-containers-69c2f39b-4028-4e88-a838-fb99ad5cdccc
I0530 00:31:44.239434       1 scheduler.go:454] Attempting to schedule pod: containers-3042/client-containers-69c2f39b-4028-4e88-a838-fb99ad5cdccc
I0530 00:31:44.239701       1 scheduler_binder.go:255] AssumePodVolumes for pod "containers-3042/client-containers-69c2f39b-4028-4e88-a838-fb99ad5cdccc", node "e2e-test-peterhornyack-windows-node-group-9q9v"
I0530 00:31:44.239712       1 scheduler_binder.go:265] AssumePodVolumes for pod "containers-3042/client-containers-69c2f39b-4028-4e88-a838-fb99ad5cdccc", node "e2e-test-peterhornyack-windows-node-group-9q9v": all PVCs bound and nothing to do
I0530 00:31:44.239795       1 factory.go:734] Attempting to bind client-containers-69c2f39b-4028-4e88-a838-fb99ad5cdccc to e2e-test-peterhornyack-windows-node-group-9q9v
I0530 00:31:44.246244       1 scheduler.go:575] pod containers-3042/client-containers-69c2f39b-4028-4e88-a838-fb99ad5cdccc is bound successfully on node e2e-test-peterhornyack-windows-node-group-9q9v, 6 nodes evaluated, 3 nodes were found feasible
I0530 00:31:51.476505       1 wrap.go:47] GET /healthz: (78.843µs) 200 [kube-probe/1.15+ 127.0.0.1:51536]
I0530 00:31:54.799713       1 reflector.go:384] k8s.io/client-go/informers/factory.go:133: Watch close - *v1.Service total 0 items received
I0530 00:32:01.476676       1 wrap.go:47] GET /healthz: (93.734µs) 200 [kube-probe/1.15+ 127.0.0.1:51586]
I0530 00:32:02.699806       1 scheduling_queue.go:895] About to try and schedule pod container-runtime-5584/image-pull-test05f154b4-9dad-430e-9b52-761fd1a79008
I0530 00:32:02.699821       1 scheduler.go:454] Attempting to schedule pod: container-runtime-5584/image-pull-test05f154b4-9dad-430e-9b52-761fd1a79008
I0530 00:32:02.700376       1 scheduler_binder.go:255] AssumePodVolumes for pod "container-runtime-5584/image-pull-test05f154b4-9dad-430e-9b52-761fd1a79008", node "e2e-test-peterhornyack-windows-node-group-1vjk"
I0530 00:32:02.700390       1 scheduler_binder.go:265] AssumePodVolumes for pod "container-runtime-5584/image-pull-test05f154b4-9dad-430e-9b52-761fd1a79008", node "e2e-test-peterhornyack-windows-node-group-1vjk": all PVCs bound and nothing to do
I0530 00:32:02.700452       1 factory.go:734] Attempting to bind image-pull-test05f154b4-9dad-430e-9b52-761fd1a79008 to e2e-test-peterhornyack-windows-node-group-1vjk
I0530 00:32:02.707192       1 scheduler.go:575] pod container-runtime-5584/image-pull-test05f154b4-9dad-430e-9b52-761fd1a79008 is bound successfully on node e2e-test-peterhornyack-windows-node-group-1vjk, 6 nodes evaluated, 3 nodes were found feasible
I0530 00:32:11.477856       1 wrap.go:47] GET /healthz: (78.658µs) 200 [kube-probe/1.15+ 127.0.0.1:51620]
I0530 00:32:15.448584       1 scheduling_queue.go:895] About to try and schedule pod kubectl-800/redis-master-r7gsh
I0530 00:32:15.448598       1 scheduler.go:454] Attempting to schedule pod: kubectl-800/redis-master-r7gsh
I0530 00:32:15.449016       1 scheduler_binder.go:255] AssumePodVolumes for pod "kubectl-800/redis-master-r7gsh", node "e2e-test-peterhornyack-windows-node-group-1vjk"
I0530 00:32:15.449027       1 scheduler_binder.go:265] AssumePodVolumes for pod "kubectl-800/redis-master-r7gsh", node "e2e-test-peterhornyack-windows-node-group-1vjk": all PVCs bound and nothing to do
I0530 00:32:15.449080       1 factory.go:734] Attempting to bind redis-master-r7gsh to e2e-test-peterhornyack-windows-node-group-1vjk
I0530 00:32:15.463118       1 scheduler.go:575] pod kubectl-800/redis-master-r7gsh is bound successfully on node e2e-test-peterhornyack-windows-node-group-1vjk, 6 nodes evaluated, 3 nodes were found feasible
I0530 00:32:21.476378       1 wrap.go:47] GET /healthz: (74.209µs) 200 [kube-probe/1.15+ 127.0.0.1:51656]
I0530 00:32:31.476567       1 wrap.go:47] GET /healthz: (93.368µs) 200 [kube-probe/1.15+ 127.0.0.1:51690]
I0530 00:32:41.476531       1 wrap.go:47] GET /healthz: (90.699µs) 200 [kube-probe/1.15+ 127.0.0.1:51724]
I0530 00:32:46.926523       1 scheduling_queue.go:895] About to try and schedule pod job-407/foo-47n6f
I0530 00:32:46.926535       1 scheduler.go:454] Attempting to schedule pod: job-407/foo-47n6f
I0530 00:32:46.926874       1 scheduler_binder.go:255] AssumePodVolumes for pod "job-407/foo-47n6f", node "e2e-test-peterhornyack-windows-node-group-9q9v"
I0530 00:32:46.926892       1 scheduler_binder.go:265] AssumePodVolumes for pod "job-407/foo-47n6f", node "e2e-test-peterhornyack-windows-node-group-9q9v": all PVCs bound and nothing to do
I0530 00:32:46.926946       1 factory.go:734] Attempting to bind foo-47n6f to e2e-test-peterhornyack-windows-node-group-9q9v
I0530 00:32:46.935541       1 scheduler.go:575] pod job-407/foo-47n6f is bound successfully on node e2e-test-peterhornyack-windows-node-group-9q9v, 6 nodes evaluated, 3 nodes were found feasible
I0530 00:32:46.935778       1 scheduling_queue.go:895] About to try and schedule pod job-407/foo-prgfm
I0530 00:32:46.935784       1 scheduler.go:454] Attempting to schedule pod: job-407/foo-prgfm
I0530 00:32:46.936027       1 scheduler_binder.go:255] AssumePodVolumes for pod "job-407/foo-prgfm", node "e2e-test-peterhornyack-windows-node-group-1vjk"
I0530 00:32:46.936035       1 scheduler_binder.go:265] AssumePodVolumes for pod "job-407/foo-prgfm", node "e2e-test-peterhornyack-windows-node-group-1vjk": all PVCs bound and nothing to do
I0530 00:32:46.936066       1 factory.go:734] Attempting to bind foo-prgfm to e2e-test-peterhornyack-windows-node-group-1vjk
I0530 00:32:46.948410       1 scheduler.go:575] pod job-407/foo-prgfm is bound successfully on node e2e-test-peterhornyack-windows-node-group-1vjk, 6 nodes evaluated, 3 nodes were found feasible
I0530 00:32:51.476576       1 wrap.go:47] GET /healthz: (95.982µs) 200 [kube-probe/1.15+ 127.0.0.1:51758]
I0530 00:33:01.477154       1 wrap.go:47] GET /healthz: (54.367µs) 200 [kube-probe/1.15+ 127.0.0.1:51808]
I0530 00:33:11.476578       1 wrap.go:47] GET /healthz: (63.995µs) 200 [kube-probe/1.15+ 127.0.0.1:51842]
I0530 00:33:21.476395       1 wrap.go:47] GET /healthz: (53.585µs) 200 [kube-probe/1.15+ 127.0.0.1:51878]
I0530 00:33:24.826159       1 reflector.go:384] cmd/kube-scheduler/app/server.go:223: Watch close - *v1.Pod total 128 items received
I0530 00:33:31.477530       1 wrap.go:47] GET /healthz: (90.031µs) 200 [kube-probe/1.15+ 127.0.0.1:51918]
I0530 00:33:41.476561       1 wrap.go:47] GET /healthz: (88.416µs) 200 [kube-probe/1.15+ 127.0.0.1:51952]
I0530 00:33:45.070316       1 scheduling_queue.go:895] About to try and schedule pod volume-9245/exec-volume-test-gcepd-dynamicpv-dn2s
I0530 00:33:45.070330       1 scheduler.go:454] Attempting to schedule pod: volume-9245/exec-volume-test-gcepd-dynamicpv-dn2s
I0530 00:33:45.070590       1 predicates.go:452] PVC volume-9245/pvc-h6lpb is not bound, assuming PVC matches predicate when counting limits
I0530 00:33:45.070671       1 predicates.go:452] PVC volume-9245/pvc-h6lpb is not bound, assuming PVC matches predicate when counting limits
I0530 00:33:45.070686       1 predicates.go:452] PVC volume-9245/pvc-h6lpb is not bound, assuming PVC matches predicate when counting limits
I0530 00:33:45.070710       1 scheduler_binder.go:683] No matching volumes for Pod "volume-9245/exec-volume-test-gcepd-dynamicpv-dn2s", PVC "volume-9245/pvc-h6lpb" on node "e2e-test-peterhornyack-windows-node-group-9q9v"
I0530 00:33:45.070723       1 scheduler_binder.go:738] Provisioning for claims of pod "volume-9245/exec-volume-test-gcepd-dynamicpv-dn2s" that has no matching volumes on node "e2e-test-peterhornyack-windows-node-group-9q9v" ...
I0530 00:33:45.070770       1 predicates.go:452] PVC volume-9245/pvc-h6lpb is not bound, assuming PVC matches predicate when counting limits
I0530 00:33:45.070787       1 predicates.go:452] PVC volume-9245/pvc-h6lpb is not bound, assuming PVC matches predicate when counting limits
I0530 00:33:45.070794       1 predicates.go:452] PVC volume-9245/pvc-h6lpb is not bound, assuming PVC matches predicate when counting limits
I0530 00:33:45.070804       1 scheduler_binder.go:683] No matching volumes for Pod "volume-9245/exec-volume-test-gcepd-dynamicpv-dn2s", PVC "volume-9245/pvc-h6lpb" on node "e2e-test-peterhornyack-windows-node-group-1vjk"
I0530 00:33:45.070825       1 scheduler_binder.go:738] Provisioning for claims of pod "volume-9245/exec-volume-test-gcepd-dynamicpv-dn2s" that has no matching volumes on node "e2e-test-peterhornyack-windows-node-group-1vjk" ...
I0530 00:33:45.070840       1 predicates.go:452] PVC volume-9245/pvc-h6lpb is not bound, assuming PVC matches predicate when counting limits
I0530 00:33:45.070854       1 predicates.go:452] PVC volume-9245/pvc-h6lpb is not bound, assuming PVC matches predicate when counting limits
I0530 00:33:45.070869       1 predicates.go:452] PVC volume-9245/pvc-h6lpb is not bound, assuming PVC matches predicate when counting limits
I0530 00:33:45.070876       1 scheduler_binder.go:683] No matching volumes for Pod "volume-9245/exec-volume-test-gcepd-dynamicpv-dn2s", PVC "volume-9245/pvc-h6lpb" on node "e2e-test-peterhornyack-windows-node-group-jpxd"
I0530 00:33:45.070884       1 scheduler_binder.go:738] Provisioning for claims of pod "volume-9245/exec-volume-test-gcepd-dynamicpv-dn2s" that has no matching volumes on node "e2e-test-peterhornyack-windows-node-group-jpxd" ...
I0530 00:33:45.071028       1 scheduler_binder.go:255] AssumePodVolumes for pod "volume-9245/exec-volume-test-gcepd-dynamicpv-dn2s", node "e2e-test-peterhornyack-windows-node-group-jpxd"
I0530 00:33:45.071043       1 scheduler_assume_cache.go:319] Assumed v1.PersistentVolumeClaim "volume-9245/pvc-h6lpb", version 15976
I0530 00:33:45.071098       1 scheduler_binder.go:330] BindPodVolumes for pod "volume-9245/exec-volume-test-gcepd-dynamicpv-dn2s", node "e2e-test-peterhornyack-windows-node-group-jpxd"
I0530 00:33:45.387794       1 cache.go:643] Couldn't expire cache for pod volume-9245/exec-volume-test-gcepd-dynamicpv-dn2s. Binding is still in progress.
I0530 00:33:46.387989       1 cache.go:643] Couldn't expire cache for pod volume-9245/exec-volume-test-gcepd-dynamicpv-dn2s. Binding is still in progress.
I0530 00:33:47.388278       1 cache.go:643] Couldn't expire cache for pod volume-9245/exec-volume-test-gcepd-dynamicpv-dn2s. Binding is still in progress.
I0530 00:33:48.077186       1 scheduler_binder.go:545] All PVCs for pod "volume-9245/exec-volume-test-gcepd-dynamicpv-dn2s" are bound
I0530 00:33:48.077223       1 factory.go:734] Attempting to bind exec-volume-test-gcepd-dynamicpv-dn2s to e2e-test-peterhornyack-windows-node-group-jpxd
I0530 00:33:48.087105       1 scheduler.go:575] pod volume-9245/exec-volume-test-gcepd-dynamicpv-dn2s is bound successfully on node e2e-test-peterhornyack-windows-node-group-jpxd, 6 nodes evaluated, 3 nodes were found feasible
I0530 00:33:51.476489       1 wrap.go:47] GET /healthz: (82.456µs) 200 [kube-probe/1.15+ 127.0.0.1:51988]
I0530 00:34:01.476413       1 wrap.go:47] GET /healthz: (48.728µs) 200 [kube-probe/1.15+ 127.0.0.1:52116]
I0530 00:34:11.476620       1 wrap.go:47] GET /healthz: (73.385µs) 200 [kube-probe/1.15+ 127.0.0.1:52152]
I0530 00:34:21.476915       1 wrap.go:47] GET /healthz: (69.096µs) 200 [kube-probe/1.15+ 127.0.0.1:52188]
I0530 00:34:21.809181       1 reflector.go:384] k8s.io/client-go/informers/factory.go:133: Watch close - *v1beta1.PodDisruptionBudget total 0 items received
I0530 00:34:31.476781       1 wrap.go:47] GET /healthz: (119.246µs) 200 [kube-probe/1.15+ 127.0.0.1:52222]
I0530 00:34:31.791391       1 reflector.go:384] k8s.io/client-go/informers/factory.go:133: Watch close - *v1.StorageClass total 2 items received
I0530 00:34:34.449124       1 scheduling_queue.go:895] About to try and schedule pod volume-4600/gcepd-injector-49qx
I0530 00:34:34.449148       1 scheduler.go:454] Attempting to schedule pod: volume-4600/gcepd-injector-49qx
I0530 00:34:34.449427       1 predicates.go:452] PVC volume-4600/pvc-8cfcb is not bound, assuming PVC matches predicate when counting limits
I0530 00:34:34.449513       1 predicates.go:452] PVC volume-4600/pvc-8cfcb is not bound, assuming PVC matches predicate when counting limits
I0530 00:34:34.449527       1 predicates.go:452] PVC volume-4600/pvc-8cfcb is not bound, assuming PVC matches predicate when counting limits
I0530 00:34:34.449561       1 scheduler_binder.go:683] No matching volumes for Pod "volume-4600/gcepd-injector-49qx", PVC "volume-4600/pvc-8cfcb" on node "e2e-test-peterhornyack-windows-node-group-9q9v"
I0530 00:34:34.449582       1 scheduler_binder.go:738] Provisioning for claims of pod "volume-4600/gcepd-injector-49qx" that has no matching volumes on node "e2e-test-peterhornyack-windows-node-group-9q9v" ...
I0530 00:34:34.449613       1 predicates.go:452] PVC volume-4600/pvc-8cfcb is not bound, assuming PVC matches predicate when counting limits
I0530 00:34:34.449647       1 predicates.go:452] PVC volume-4600/pvc-8cfcb is not bound, assuming PVC matches predicate when counting limits
I0530 00:34:34.449655       1 predicates.go:452] PVC volume-4600/pvc-8cfcb is not bound, assuming PVC matches predicate when counting limits
I0530 00:34:34.449663       1 scheduler_binder.go:683] No matching volumes for Pod "volume-4600/gcepd-injector-49qx", PVC "volume-4600/pvc-8cfcb" on node "e2e-test-peterhornyack-windows-node-group-1vjk"
I0530 00:34:34.449670       1 scheduler_binder.go:738] Provisioning for claims of pod "volume-4600/gcepd-injector-49qx" that has no matching volumes on node "e2e-test-peterhornyack-windows-node-group-1vjk" ...
I0530 00:34:34.449686       1 predicates.go:452] PVC volume-4600/pvc-8cfcb is not bound, assuming PVC matches predicate when counting limits
I0530 00:34:34.449700       1 predicates.go:452] PVC volume-4600/pvc-8cfcb is not bound, assuming PVC matches predicate when counting limits
I0530 00:34:34.449747       1 predicates.go:452] PVC volume-4600/pvc-8cfcb is not bound, assuming PVC matches predicate when counting limits
I0530 00:34:34.449754       1 scheduler_binder.go:683] No matching volumes for Pod "volume-4600/gcepd-injector-49qx", PVC "volume-4600/pvc-8cfcb" on node "e2e-test-peterhornyack-windows-node-group-jpxd"
I0530 00:34:34.449762       1 scheduler_binder.go:738] Provisioning for claims of pod "volume-4600/gcepd-injector-49qx" that has no matching volumes on node "e2e-test-peterhornyack-windows-node-group-jpxd" ...
I0530 00:34:34.449936       1 scheduler_binder.go:255] AssumePodVolumes for pod "volume-4600/gcepd-injector-49qx", node "e2e-test-peterhornyack-windows-node-group-jpxd"
I0530 00:34:34.449950       1 scheduler_assume_cache.go:319] Assumed v1.PersistentVolumeClaim "volume-4600/pvc-8cfcb", version 16124
I0530 00:34:34.450000       1 scheduler_binder.go:330] BindPodVolumes for pod "volume-4600/gcepd-injector-49qx", node "e2e-test-peterhornyack-windows-node-group-jpxd"
I0530 00:34:35.407646       1 cache.go:643] Couldn't expire cache for pod volume-4600/gcepd-injector-49qx. Binding is still in progress.
I0530 00:34:35.772932       1 reflector.go:384] k8s.io/client-go/informers/factory.go:133: Watch close - *v1.Node total 59 items received
I0530 00:34:36.408019       1 cache.go:643] Couldn't expire cache for pod volume-4600/gcepd-injector-49qx. Binding is still in progress.
I0530 00:34:37.408575       1 cache.go:643] Couldn't expire cache for pod volume-4600/gcepd-injector-49qx. Binding is still in progress.
I0530 00:34:37.456039       1 scheduler_binder.go:545] All PVCs for pod "volume-4600/gcepd-injector-49qx" are bound
I0530 00:34:37.456067       1 factory.go:734] Attempting to bind gcepd-injector-49qx to e2e-test-peterhornyack-windows-node-group-jpxd
I0530 00:34:37.465772       1 scheduler.go:575] pod volume-4600/gcepd-injector-49qx is bound successfully on node e2e-test-peterhornyack-windows-node-group-jpxd, 6 nodes evaluated, 3 nodes were found feasible
I0530 00:34:41.476611       1 wrap.go:47] GET /healthz: (82.357µs) 200 [kube-probe/1.15+ 127.0.0.1:52256]
I0530 00:34:51.479376       1 wrap.go:47] GET /healthz: (75.505µs) 200 [kube-probe/1.15+ 127.0.0.1:52290]
I0530 00:35:01.476562       1 wrap.go:47] GET /healthz: (96.75µs) 200 [kube-probe/1.15+ 127.0.0.1:52338]
I0530 00:35:07.285478       1 scheduling_queue.go:895] About to try and schedule pod volume-4600/gcepd-client
I0530 00:35:07.285490       1 scheduler.go:454] Attempting to schedule pod: volume-4600/gcepd-client
I0530 00:35:07.287973       1 scheduler_binder.go:651] All bound volumes for Pod "volume-4600/gcepd-client" match with Node "e2e-test-peterhornyack-windows-node-group-9q9v"
I0530 00:35:07.288061       1 scheduler_binder.go:651] All bound volumes for Pod "volume-4600/gcepd-client" match with Node "e2e-test-peterhornyack-windows-node-group-1vjk"
I0530 00:35:07.288111       1 scheduler_binder.go:651] All bound volumes for Pod "volume-4600/gcepd-client" match with Node "e2e-test-peterhornyack-windows-node-group-jpxd"
I0530 00:35:07.288306       1 scheduler_binder.go:255] AssumePodVolumes for pod "volume-4600/gcepd-client", node "e2e-test-peterhornyack-windows-node-group-jpxd"
I0530 00:35:07.288314       1 scheduler_binder.go:265] AssumePodVolumes for pod "volume-4600/gcepd-client", node "e2e-test-peterhornyack-windows-node-group-jpxd": all PVCs bound and nothing to do
I0530 00:35:07.288378       1 factory.go:734] Attempting to bind gcepd-client to e2e-test-peterhornyack-windows-node-group-jpxd
I0530 00:35:07.295782       1 scheduler.go:575] pod volume-4600/gcepd-client is bound successfully on node e2e-test-peterhornyack-windows-node-group-jpxd, 6 nodes evaluated, 3 nodes were found feasible
I0530 00:35:11.476622       1 wrap.go:47] GET /healthz: (93.921µs) 200 [kube-probe/1.15+ 127.0.0.1:52372]
I0530 00:35:21.476424       1 wrap.go:47] GET /healthz: (67.511µs) 200 [kube-probe/1.15+ 127.0.0.1:52410]
I0530 00:35:31.476908       1 wrap.go:47] GET /healthz: (457.078µs) 200 [kube-probe/1.15+ 127.0.0.1:52446]
I0530 00:35:41.476515       1 wrap.go:47] GET /healthz: (87.746µs) 200 [kube-probe/1.15+ 127.0.0.1:52480]
I0530 00:35:51.476633       1 wrap.go:47] GET /healthz: (68.641µs) 200 [kube-probe/1.15+ 127.0.0.1:52512]
I0530 00:35:55.971865       1 scheduling_queue.go:895] About to try and schedule pod kubectl-96/update-demo-nautilus-swf8k
I0530 00:35:55.971878       1 scheduler.go:454] Attempting to schedule pod: kubectl-96/update-demo-nautilus-swf8k
I0530 00:35:55.974863       1 scheduler_binder.go:255] AssumePodVolumes for pod "kubectl-96/update-demo-nautilus-swf8k", node "e2e-test-peterhornyack-windows-node-group-jpxd"
I0530 00:35:55.974876       1 scheduler_binder.go:265] AssumePodVolumes for pod "kubectl-96/update-demo-nautilus-swf8k", node "e2e-test-peterhornyack-windows-node-group-jpxd": all PVCs bound and nothing to do
I0530 00:35:55.974932       1 factory.go:734] Attempting to bind update-demo-nautilus-swf8k to e2e-test-peterhornyack-windows-node-group-jpxd
I0530 00:35:55.982787       1 scheduling_queue.go:895] About to try and schedule pod kubectl-96/update-demo-nautilus-2xkq6
I0530 00:35:55.982798       1 scheduler.go:454] Attempting to schedule pod: kubectl-96/update-demo-nautilus-2xkq6
I0530 00:35:55.983048       1 scheduler_binder.go:255] AssumePodVolumes for pod "kubectl-96/update-demo-nautilus-2xkq6", node "e2e-test-peterhornyack-windows-node-group-9q9v"
I0530 00:35:55.985023       1 scheduler_binder.go:265] AssumePodVolumes for pod "kubectl-96/update-demo-nautilus-2xkq6", node "e2e-test-peterhornyack-windows-node-group-9q9v": all PVCs bound and nothing to do
I0530 00:35:55.985097       1 factory.go:734] Attempting to bind update-demo-nautilus-2xkq6 to e2e-test-peterhornyack-windows-node-group-9q9v
I0530 00:35:55.992483       1 scheduler.go:575] pod kubectl-96/update-demo-nautilus-swf8k is bound successfully on node e2e-test-peterhornyack-windows-node-group-jpxd, 6 nodes evaluated, 3 nodes were found feasible
I0530 00:35:56.004392       1 scheduler.go:575] pod kubectl-96/update-demo-nautilus-2xkq6 is bound successfully on node e2e-test-peterhornyack-windows-node-group-9q9v, 6 nodes evaluated, 3 nodes were found feasible
I0530 00:36:01.476441       1 wrap.go:47] GET /healthz: (63.377µs) 200 [kube-probe/1.15+ 127.0.0.1:52560]
I0530 00:36:09.590329       1 scheduling_queue.go:895] About to try and schedule pod kubectl-96/update-demo-kitten-pmx2f
I0530 00:36:09.590343       1 scheduler.go:454] Attempting to schedule pod: kubectl-96/update-demo-kitten-pmx2f
I0530 00:36:09.594763       1 scheduler_binder.go:255] AssumePodVolumes for pod "kubectl-96/update-demo-kitten-pmx2f", node "e2e-test-peterhornyack-windows-node-group-1vjk"
I0530 00:36:09.594779       1 scheduler_binder.go:265] AssumePodVolumes for pod "kubectl-96/update-demo-kitten-pmx2f", node "e2e-test-peterhornyack-windows-node-group-1vjk": all PVCs bound and nothing to do
I0530 00:36:09.594852       1 factory.go:734] Attempting to bind update-demo-kitten-pmx2f to e2e-test-peterhornyack-windows-node-group-1vjk
I0530 00:36:09.645704       1 scheduler.go:575] pod kubectl-96/update-demo-kitten-pmx2f is bound successfully on node e2e-test-peterhornyack-windows-node-group-1vjk, 6 nodes evaluated, 3 nodes were found feasible
I0530 00:36:11.476537       1 wrap.go:47] GET /healthz: (105.028µs) 200 [kube-probe/1.15+ 127.0.0.1:52598]
I0530 00:36:21.476574       1 wrap.go:47] GET /healthz: (61.366µs) 200 [kube-probe/1.15+ 127.0.0.1:52636]
I0530 00:36:31.476608       1 wrap.go:47] GET /healthz: (74.97µs) 200 [kube-probe/1.15+ 127.0.0.1:52672]
I0530 00:36:34.813995       1 reflector.go:384] k8s.io/client-go/informers/factory.go:133: Watch close - *v1.ReplicaSet total 0 items received
I0530 00:36:41.476795       1 wrap.go:47] GET /healthz: (59.855µs) 200 [kube-probe/1.15+ 127.0.0.1:52706]
I0530 00:36:43.741872       1 scheduling_queue.go:895] About to try and schedule pod kubectl-96/update-demo-kitten-cqmbt
I0530 00:36:43.741885       1 scheduler.go:454] Attempting to schedule pod: kubectl-96/update-demo-kitten-cqmbt
I0530 00:36:43.742282       1 scheduler_binder.go:255] AssumePodVolumes for pod "kubectl-96/update-demo-kitten-cqmbt", node "e2e-test-peterhornyack-windows-node-group-9q9v"
I0530 00:36:43.742293       1 scheduler_binder.go:265] AssumePodVolumes for pod "kubectl-96/update-demo-kitten-cqmbt", node "e2e-test-peterhornyack-windows-node-group-9q9v": all PVCs bound and nothing to do
I0530 00:36:43.746331       1 factory.go:734] Attempting to bind update-demo-kitten-cqmbt to e2e-test-peterhornyack-windows-node-group-9q9v
I0530 00:36:43.757137       1 scheduler.go:575] pod kubectl-96/update-demo-kitten-cqmbt is bound successfully on node e2e-test-peterhornyack-windows-node-group-9q9v, 6 nodes evaluated, 3 nodes were found feasible
I0530 00:36:51.476967       1 wrap.go:47] GET /healthz: (54.181µs) 200 [kube-probe/1.15+ 127.0.0.1:52738]
I0530 00:37:01.476659       1 wrap.go:47] GET /healthz: (54.311µs) 200 [kube-probe/1.15+ 127.0.0.1:52786]
I0530 00:37:11.476573       1 wrap.go:47] GET /healthz: (77.114µs) 200 [kube-probe/1.15+ 127.0.0.1:52820]
I0530 00:37:21.476511       1 wrap.go:47] GET /healthz: (106.328µs) 200 [kube-probe/1.15+ 127.0.0.1:52856]
I0530 00:37:22.821876       1 reflector.go:384] k8s.io/client-go/informers/factory.go:133: Watch close - *v1.PersistentVolume total 10 items received
I0530 00:37:31.476491       1 wrap.go:47] GET /healthz: (68.789µs) 200 [kube-probe/1.15+ 127.0.0.1:52890]
I0530 00:37:41.476715       1 wrap.go:47] GET /healthz: (63.159µs) 200 [kube-probe/1.15+ 127.0.0.1:52926]
I0530 00:37:51.476841       1 wrap.go:47] GET /healthz: (69.078µs) 200 [kube-probe/1.15+ 127.0.0.1:52960]
I0530 00:38:01.498576       1 wrap.go:47] GET /healthz: (75.181µs) 200 [kube-probe/1.15+ 127.0.0.1:53012]
I0530 00:38:11.480413       1 wrap.go:47] GET /healthz: (87.287µs) 200 [kube-probe/1.15+ 127.0.0.1:53046]
I0530 00:38:21.476510       1 wrap.go:47] GET /healthz: (100.168µs) 200 [kube-probe/1.15+ 127.0.0.1:53082]
I0530 00:38:31.476617       1 wrap.go:47] GET /healthz: (77.959µs) 200 [kube-probe/1.15+ 127.0.0.1:53116]
I0530 00:38:37.805963       1 reflector.go:384] k8s.io/client-go/informers/factory.go:133: Watch close - *v1.StatefulSet total 0 items received
I0530 00:38:41.476560       1 wrap.go:47] GET /healthz: (51.702µs) 200 [kube-probe/1.15+ 127.0.0.1:53150]
I0530 00:38:41.782124       1 scheduling_queue.go:895] About to try and schedule pod init-container-9244/pod-init-c0e4d1a8-d4fa-47d8-9667-0898b95a9002
I0530 00:38:41.782137       1 scheduler.go:454] Attempting to schedule pod: init-container-9244/pod-init-c0e4d1a8-d4fa-47d8-9667-0898b95a9002
I0530 00:38:41.782592       1 scheduler_binder.go:255] AssumePodVolumes for pod "init-container-9244/pod-init-c0e4d1a8-d4fa-47d8-9667-0898b95a9002", node "e2e-test-peterhornyack-windows-node-group-jpxd"
I0530 00:38:41.782604       1 scheduler_binder.go:265] AssumePodVolumes for pod "init-container-9244/pod-init-c0e4d1a8-d4fa-47d8-9667-0898b95a9002", node "e2e-test-peterhornyack-windows-node-group-jpxd": all PVCs bound and nothing to do
I0530 00:38:41.784116       1 factory.go:734] Attempting to bind pod-init-c0e4d1a8-d4fa-47d8-9667-0898b95a9002 to e2e-test-peterhornyack-windows-node-group-jpxd
I0530 00:38:41.790988       1 scheduler.go:575] pod init-container-9244/pod-init-c0e4d1a8-d4fa-47d8-9667-0898b95a9002 is bound successfully on node e2e-test-peterhornyack-windows-node-group-jpxd, 6 nodes evaluated, 3 nodes were found feasible
I0530 00:38:51.476841       1 wrap.go:47] GET /healthz: (75.201µs) 200 [kube-probe/1.15+ 127.0.0.1:53182]
I0530 00:39:01.476743       1 wrap.go:47] GET /healthz: (77.503µs) 200 [kube-probe/1.15+ 127.0.0.1:53232]
I0530 00:39:09.781901       1 reflector.go:384] k8s.io/client-go/informers/factory.go:133: Watch close - *v1.ReplicationController total 39 items received
I0530 00:39:11.481171       1 wrap.go:47] GET /healthz: (95.095µs) 200 [kube-probe/1.15+ 127.0.0.1:53266]
I0530 00:39:21.476600       1 wrap.go:47] GET /healthz: (74.865µs) 200 [kube-probe/1.15+ 127.0.0.1:53304]
I0530 00:39:31.483483       1 wrap.go:47] GET /healthz: (78.397µs) 200 [kube-probe/1.15+ 127.0.0.1:53338]
I0530 00:39:41.476764       1 wrap.go:47] GET /healthz: (68.575µs) 200 [kube-probe/1.15+ 127.0.0.1:53372]
I0530 00:39:51.476822       1 wrap.go:47] GET /healthz: (109.75µs) 200 [kube-probe/1.15+ 127.0.0.1:53404]
I0530 00:40:00.710005       1 scheduling_queue.go:895] About to try and schedule pod deployment-3127/test-rolling-update-controller-tq2vs
I0530 00:40:00.710027       1 scheduler.go:454] Attempting to schedule pod: deployment-3127/test-rolling-update-controller-tq2vs
I0530 00:40:00.710444       1 scheduler_binder.go:255] AssumePodVolumes for pod "deployment-3127/test-rolling-update-controller-tq2vs", node "e2e-test-peterhornyack-windows-node-group-1vjk"
I0530 00:40:00.714522       1 scheduler_binder.go:265] AssumePodVolumes for pod "deployment-3127/test-rolling-update-controller-tq2vs", node "e2e-test-peterhornyack-windows-node-group-1vjk": all PVCs bound and nothing to do
I0530 00:40:00.714639       1 factory.go:734] Attempting to bind test-rolling-update-controller-tq2vs to e2e-test-peterhornyack-windows-node-group-1vjk
I0530 00:40:00.742197       1 scheduler.go:575] pod deployment-3127/test-rolling-update-controller-tq2vs is bound successfully on node e2e-test-peterhornyack-windows-node-group-1vjk, 6 nodes evaluated, 3 nodes were found feasible
I0530 00:40:01.477622       1 wrap.go:47] GET /healthz: (63.46µs) 200 [kube-probe/1.15+ 127.0.0.1:53452]
I0530 00:40:08.921780       1 scheduling_queue.go:895] About to try and schedule pod deployment-3127/test-rolling-update-deployment-7fcdf5fb94-nvrbg
I0530 00:40:08.921794       1 scheduler.go:454] Attempting to schedule pod: deployment-3127/test-rolling-update-deployment-7fcdf5fb94-nvrbg
I0530 00:40:08.922217       1 scheduler_binder.go:255] AssumePodVolumes for pod "deployment-3127/test-rolling-update-deployment-7fcdf5fb94-nvrbg", node "e2e-test-peterhornyack-windows-node-group-1vjk"
I0530 00:40:08.922228       1 scheduler_binder.go:265] AssumePodVolumes for pod "deployment-3127/test-rolling-update-deployment-7fcdf5fb94-nvrbg", node "e2e-test-peterhornyack-windows-node-group-1vjk": all PVCs bound and nothing to do
I0530 00:40:08.922275       1 factory.go:734] Attempting to bind test-rolling-update-deployment-7fcdf5fb94-nvrbg to e2e-test-peterhornyack-windows-node-group-1vjk
I0530 00:40:08.954731       1 scheduler.go:575] pod deployment-3127/test-rolling-update-deployment-7fcdf5fb94-nvrbg is bound successfully on node e2e-test-peterhornyack-windows-node-group-1vjk, 6 nodes evaluated, 3 nodes were found feasible
I0530 00:40:11.476732       1 wrap.go:47] GET /healthz: (80.852µs) 200 [kube-probe/1.15+ 127.0.0.1:53488]
I0530 00:40:19.811018       1 reflector.go:384] k8s.io/client-go/informers/factory.go:133: Watch close - *v1beta1.PodDisruptionBudget total 0 items received
I0530 00:40:21.476667       1 wrap.go:47] GET /healthz: (75.536µs) 200 [kube-probe/1.15+ 127.0.0.1:53524]
I0530 00:40:24.801969       1 reflector.go:384] k8s.io/client-go/informers/factory.go:133: Watch close - *v1.Service total 0 items received
I0530 00:40:25.342799       1 scheduling_queue.go:895] About to try and schedule pod replication-controller-5736/pod-release-v7br9
I0530 00:40:25.342826       1 scheduler.go:454] Attempting to schedule pod: replication-controller-5736/pod-release-v7br9
I0530 00:40:25.347058       1 scheduler_binder.go:255] AssumePodVolumes for pod "replication-controller-5736/pod-release-v7br9", node "e2e-test-peterhornyack-windows-node-group-9q9v"
I0530 00:40:25.347076       1 scheduler_binder.go:265] AssumePodVolumes for pod "replication-controller-5736/pod-release-v7br9", node "e2e-test-peterhornyack-windows-node-group-9q9v": all PVCs bound and nothing to do
I0530 00:40:25.347151       1 factory.go:734] Attempting to bind pod-release-v7br9 to e2e-test-peterhornyack-windows-node-group-9q9v
I0530 00:40:25.363080       1 scheduler.go:575] pod replication-controller-5736/pod-release-v7br9 is bound successfully on node e2e-test-peterhornyack-windows-node-group-9q9v, 6 nodes evaluated, 3 nodes were found feasible
I0530 00:40:25.487227       1 scheduling_queue.go:895] About to try and schedule pod replication-controller-5736/pod-release-bxxt8
I0530 00:40:25.487241       1 scheduler.go:454] Attempting to schedule pod: replication-controller-5736/pod-release-bxxt8
I0530 00:40:25.489565       1 scheduler_binder.go:255] AssumePodVolumes for pod "replication-controller-5736/pod-release-bxxt8", node "e2e-test-peterhornyack-windows-node-group-1vjk"
I0530 00:40:25.489581       1 scheduler_binder.go:265] AssumePodVolumes for pod "replication-controller-5736/pod-release-bxxt8", node "e2e-test-peterhornyack-windows-node-group-1vjk": all PVCs bound and nothing to do
I0530 00:40:25.489623       1 factory.go:734] Attempting to bind pod-release-bxxt8 to e2e-test-peterhornyack-windows-node-group-1vjk
I0530 00:40:25.506634       1 scheduler.go:575] pod replication-controller-5736/pod-release-bxxt8 is bound successfully on node e2e-test-peterhornyack-windows-node-group-1vjk, 6 nodes evaluated, 3 nodes were found feasible
I0530 00:40:31.476617       1 wrap.go:47] GET /healthz: (65.077µs) 200 [kube-probe/1.15+ 127.0.0.1:53558]
I0530 00:40:33.515092       1 scheduling_queue.go:895] About to try and schedule pod containers-6631/client-containers-16c35d6b-cf31-4c7f-b584-a0095313a0f3
I0530 00:40:33.515104       1 scheduler.go:454] Attempting to schedule pod: containers-6631/client-containers-16c35d6b-cf31-4c7f-b584-a0095313a0f3
I0530 00:40:33.516644       1 scheduler_binder.go:255] AssumePodVolumes for pod "containers-6631/client-containers-16c35d6b-cf31-4c7f-b584-a0095313a0f3", node "e2e-test-peterhornyack-windows-node-group-9q9v"
I0530 00:40:33.516661       1 scheduler_binder.go:265] AssumePodVolumes for pod "containers-6631/client-containers-16c35d6b-cf31-4c7f-b584-a0095313a0f3", node "e2e-test-peterhornyack-windows-node-group-9q9v": all PVCs bound and nothing to do
I0530 00:40:33.516732       1 factory.go:734] Attempting to bind client-containers-16c35d6b-cf31-4c7f-b584-a0095313a0f3 to e2e-test-peterhornyack-windows-node-group-9q9v
I0530 00:40:33.522163       1 scheduler.go:575] pod containers-6631/client-containers-16c35d6b-cf31-4c7f-b584-a0095313a0f3 is bound successfully on node e2e-test-peterhornyack-windows-node-group-9q9v, 6 nodes evaluated, 3 nodes were found feasible
I0530 00:40:39.828598       1 reflector.go:384] k8s.io/client-go/informers/factory.go:133: Watch close - *v1.PersistentVolumeClaim total 14 items received
I0530 00:40:41.478488       1 wrap.go:47] GET /healthz: (116.443µs) 200 [kube-probe/1.15+ 127.0.0.1:53592]
I0530 00:40:51.479258       1 wrap.go:47] GET /healthz: (66.763µs) 200 [kube-probe/1.15+ 127.0.0.1:53626]
I0530 00:40:54.151140       1 scheduling_queue.go:895] About to try and schedule pod pods-8092/pod-submit-remove-6917c27c-8d26-476d-bf91-4bf42a3af116
I0530 00:40:54.151166       1 scheduler.go:454] Attempting to schedule pod: pods-8092/pod-submit-remove-6917c27c-8d26-476d-bf91-4bf42a3af116
I0530 00:40:54.151501       1 scheduler_binder.go:255] AssumePodVolumes for pod "pods-8092/pod-submit-remove-6917c27c-8d26-476d-bf91-4bf42a3af116", node "e2e-test-peterhornyack-windows-node-group-9q9v"
I0530 00:40:54.151513       1 scheduler_binder.go:265] AssumePodVolumes for pod "pods-8092/pod-submit-remove-6917c27c-8d26-476d-bf91-4bf42a3af116", node "e2e-test-peterhornyack-windows-node-group-9q9v": all PVCs bound and nothing to do
I0530 00:40:54.151555       1 factory.go:734] Attempting to bind pod-submit-remove-6917c27c-8d26-476d-bf91-4bf42a3af116 to e2e-test-peterhornyack-windows-node-group-9q9v
I0530 00:40:54.158386       1 scheduler.go:575] pod pods-8092/pod-submit-remove-6917c27c-8d26-476d-bf91-4bf42a3af116 is bound successfully on node e2e-test-peterhornyack-windows-node-group-9q9v, 6 nodes evaluated, 3 nodes were found feasible
I0530 00:41:01.476611       1 wrap.go:47] GET /healthz: (87.616µs) 200 [kube-probe/1.15+ 127.0.0.1:53674]
I0530 00:41:11.476941       1 wrap.go:47] GET /healthz: (80.415µs) 200 [kube-probe/1.15+ 127.0.0.1:53708]
I0530 00:41:20.696249       1 scheduling_queue.go:895] About to try and schedule pod hostpath-9047/pod-host-path-test
I0530 00:41:20.696262       1 scheduler.go:454] Attempting to schedule pod: hostpath-9047/pod-host-path-test
I0530 00:41:20.698612       1 scheduler_binder.go:255] AssumePodVolumes for pod "hostpath-9047/pod-host-path-test", node "e2e-test-peterhornyack-windows-node-group-9q9v"
I0530 00:41:20.698630       1 scheduler_binder.go:265] AssumePodVolumes for pod "hostpath-9047/pod-host-path-test", node "e2e-test-peterhornyack-windows-node-group-9q9v": all PVCs bound and nothing to do
I0530 00:41:20.698700       1 factory.go:734] Attempting to bind pod-host-path-test to e2e-test-peterhornyack-windows-node-group-9q9v
I0530 00:41:20.708353       1 scheduler.go:575] pod hostpath-9047/pod-host-path-test is bound successfully on node e2e-test-peterhornyack-windows-node-group-9q9v, 6 nodes evaluated, 3 nodes were found feasible
I0530 00:41:21.477370       1 wrap.go:47] GET /healthz: (74.998µs) 200 [kube-probe/1.15+ 127.0.0.1:53746]
I0530 00:41:23.828419       1 reflector.go:384] cmd/kube-scheduler/app/server.go:223: Watch close - *v1.Pod total 114 items received
I0530 00:41:31.476829       1 wrap.go:47] GET /healthz: (50.35µs) 200 [kube-probe/1.15+ 127.0.0.1:53780]
I0530 00:41:41.476696       1 wrap.go:47] GET /healthz: (68.955µs) 200 [kube-probe/1.15+ 127.0.0.1:53814]
I0530 00:41:48.775176       1 reflector.go:384] k8s.io/client-go/informers/factory.go:133: Watch close - *v1.Node total 60 items received
I0530 00:41:51.476801       1 wrap.go:47] GET /healthz: (68.757µs) 200 [kube-probe/1.15+ 127.0.0.1:53846]
I0530 00:41:53.639443       1 scheduling_queue.go:895] About to try and schedule pod pods-5171/back-off-cap
I0530 00:41:53.639469       1 scheduler.go:454] Attempting to schedule pod: pods-5171/back-off-cap
I0530 00:41:53.641431       1 scheduler_binder.go:255] AssumePodVolumes for pod "pods-5171/back-off-cap", node "e2e-test-peterhornyack-windows-node-group-jpxd"
I0530 00:41:53.641453       1 scheduler_binder.go:265] AssumePodVolumes for pod "pods-5171/back-off-cap", node "e2e-test-peterhornyack-windows-node-group-jpxd": all PVCs bound and nothing to do
I0530 00:41:53.641529       1 factory.go:734] Attempting to bind back-off-cap to e2e-test-peterhornyack-windows-node-group-jpxd
I0530 00:41:53.645855       1 scheduler.go:575] pod pods-5171/back-off-cap is bound successfully on node e2e-test-peterhornyack-windows-node-group-jpxd, 6 nodes evaluated, 3 nodes were found feasible
I0530 00:42:01.476631       1 wrap.go:47] GET /healthz: (51.799µs) 200 [kube-probe/1.15+ 127.0.0.1:53894]
I0530 00:42:01.793572       1 reflector.go:384] k8s.io/client-go/informers/factory.go:133: Watch close - *v1.StorageClass total 2 items received
I0530 00:42:11.476637       1 wrap.go:47] GET /healthz: (75.27µs) 200 [kube-probe/1.15+ 127.0.0.1:53930]
I0530 00:42:14.816610       1 reflector.go:384] k8s.io/client-go/informers/factory.go:133: Watch close - *v1.ReplicaSet total 14 items received
I0530 00:42:21.476679       1 wrap.go:47] GET /healthz: (78.708µs) 200 [kube-probe/1.15+ 127.0.0.1:53968]
I0530 00:42:31.476661       1 wrap.go:47] GET /healthz: (127.635µs) 200 [kube-probe/1.15+ 127.0.0.1:54004]
I0530 00:42:41.476575       1 wrap.go:47] GET /healthz: (58.844µs) 200 [kube-probe/1.15+ 127.0.0.1:54038]
I0530 00:42:51.476545       1 wrap.go:47] GET /healthz: (87.157µs) 200 [kube-probe/1.15+ 127.0.0.1:54070]
I0530 00:43:01.481995       1 wrap.go:47] GET /healthz: (74.756µs) 200 [kube-probe/1.15+ 127.0.0.1:54118]
I0530 00:43:11.485759       1 wrap.go:47] GET /healthz: (80.426µs) 200 [kube-probe/1.15+ 127.0.0.1:54152]
I0530 00:43:21.476702       1 wrap.go:47] GET /healthz: (81.144µs) 200 [kube-probe/1.15+ 127.0.0.1:54188]
I0530 00:43:31.476650       1 wrap.go:47] GET /healthz: (91.35µs) 200 [kube-probe/1.15+ 127.0.0.1:54222]
I0530 00:43:41.476590       1 wrap.go:47] GET /healthz: (78.579µs) 200 [kube-probe/1.15+ 127.0.0.1:54260]
I0530 00:43:49.824157       1 reflector.go:384] k8s.io/client-go/informers/factory.go:133: Watch close - *v1.PersistentVolume total 0 items received
I0530 00:43:51.476815       1 wrap.go:47] GET /healthz: (77.938µs) 200 [kube-probe/1.15+ 127.0.0.1:54292]
I0530 00:44:01.477003       1 wrap.go:47] GET /healthz: (81.745µs) 200 [kube-probe/1.15+ 127.0.0.1:54420]
I0530 00:44:11.480873       1 wrap.go:47] GET /healthz: (77.196µs) 200 [kube-probe/1.15+ 127.0.0.1:54454]
I0530 00:44:21.476525       1 wrap.go:47] GET /healthz: (90.054µs) 200 [kube-probe/1.15+ 127.0.0.1:54490]
I0530 00:44:31.476820       1 wrap.go:47] GET /healthz: (61.35µs) 200 [kube-probe/1.15+ 127.0.0.1:54524]
I0530 00:44:41.476722       1 wrap.go:47] GET /healthz: (78.809µs) 200 [kube-probe/1.15+ 127.0.0.1:54558]
I0530 00:44:51.476398       1 wrap.go:47] GET /healthz: (63.377µs) 200 [kube-probe/1.15+ 127.0.0.1:54592]
I0530 00:45:01.476601       1 wrap.go:47] GET /healthz: (119.069µs) 200 [kube-probe/1.15+ 127.0.0.1:54640]
I0530 00:45:11.476760       1 wrap.go:47] GET /healthz: (78.031µs) 200 [kube-probe/1.15+ 127.0.0.1:54676]
I0530 00:45:21.476566       1 wrap.go:47] GET /healthz: (97.112µs) 200 [kube-probe/1.15+ 127.0.0.1:54712]
I0530 00:45:30.783976       1 reflector.go:384] k8s.io/client-go/informers/factory.go:133: Watch close - *v1.ReplicationController total 7 items received
I0530 00:45:31.476437       1 wrap.go:47] GET /healthz: (76.115µs) 200 [kube-probe/1.15+ 127.0.0.1:54746]
I0530 00:45:41.477754       1 wrap.go:47] GET /healthz: (81.992µs) 200 [kube-probe/1.15+ 127.0.0.1:54780]
I0530 00:45:51.476645       1 wrap.go:47] GET /healthz: (52.224µs) 200 [kube-probe/1.15+ 127.0.0.1:54812]
I0530 00:46:01.477062       1 wrap.go:47] GET /healthz: (85.826µs) 200 [kube-probe/1.15+ 127.0.0.1:54862]
I0530 00:46:11.476648       1 wrap.go:47] GET /healthz: (70.472µs) 200 [kube-probe/1.15+ 127.0.0.1:54896]
I0530 00:46:20.808032       1 reflector.go:384] k8s.io/client-go/informers/factory.go:133: Watch close - *v1.StatefulSet total 0 items received
I0530 00:46:21.476877       1 wrap.go:47] GET /healthz: (68.839µs) 200 [kube-probe/1.15+ 127.0.0.1:54932]
I0530 00:46:31.476572       1 wrap.go:47] GET /healthz: (51.233µs) 200 [kube-probe/1.15+ 127.0.0.1:54966]
I0530 00:46:31.804304       1 reflector.go:384] k8s.io/client-go/informers/factory.go:133: Watch close - *v1.Service total 0 items received
I0530 00:46:41.476702       1 wrap.go:47] GET /healthz: (63.407µs) 200 [kube-probe/1.15+ 127.0.0.1:55002]
I0530 00:46:51.477279       1 wrap.go:47] GET /healthz: (86.671µs) 200 [kube-probe/1.15+ 127.0.0.1:55034]
I0530 00:47:01.476607       1 wrap.go:47] GET /healthz: (71.509µs) 200 [kube-probe/1.15+ 127.0.0.1:55082]
I0530 00:47:11.476755       1 wrap.go:47] GET /healthz: (64.833µs) 200 [kube-probe/1.15+ 127.0.0.1:55118]
I0530 00:47:16.812998       1 reflector.go:384] k8s.io/client-go/informers/factory.go:133: Watch close - *v1beta1.PodDisruptionBudget total 0 items received
I0530 00:47:21.477311       1 wrap.go:47] GET /healthz: (49.865µs) 200 [kube-probe/1.15+ 127.0.0.1:55154]
I0530 00:47:31.476622       1 wrap.go:47] GET /healthz: (65.009µs) 200 [kube-probe/1.15+ 127.0.0.1:55188]
I0530 00:47:41.476529       1 wrap.go:47] GET /healthz: (50.889µs) 200 [kube-probe/1.15+ 127.0.0.1:55222]
I0530 00:47:51.476646       1 wrap.go:47] GET /healthz: (69.527µs) 200 [kube-probe/1.15+ 127.0.0.1:55254]
I0530 00:48:01.476582       1 wrap.go:47] GET /healthz: (80.093µs) 200 [kube-probe/1.15+ 127.0.0.1:55302]
I0530 00:48:11.476778       1 wrap.go:47] GET /healthz: (125.85µs) 200 [kube-probe/1.15+ 127.0.0.1:55338]
I0530 00:48:20.830756       1 reflector.go:384] k8s.io/client-go/informers/factory.go:133: Watch close - *v1.PersistentVolumeClaim total 0 items received
I0530 00:48:21.476752       1 wrap.go:47] GET /healthz: (51.905µs) 200 [kube-probe/1.15+ 127.0.0.1:55376]
I0530 00:48:23.777376       1 reflector.go:384] k8s.io/client-go/informers/factory.go:133: Watch close - *v1.Node total 54 items received
I0530 00:48:31.476646       1 wrap.go:47] GET /healthz: (93.041µs) 200 [kube-probe/1.15+ 127.0.0.1:55410]
I0530 00:48:41.476926       1 wrap.go:47] GET /healthz: (78.376µs) 200 [kube-probe/1.15+ 127.0.0.1:55444]
I0530 00:48:49.795754       1 reflector.go:384] k8s.io/client-go/informers/factory.go:133: Watch close - *v1.StorageClass total 0 items received
I0530 00:48:51.476833       1 wrap.go:47] GET /healthz: (79.36µs) 200 [kube-probe/1.15+ 127.0.0.1:55476]
I0530 00:49:01.476597       1 wrap.go:47] GET /healthz: (81.52µs) 200 [kube-probe/1.15+ 127.0.0.1:55524]
I0530 00:49:11.476477       1 wrap.go:47] GET /healthz: (51.228µs) 200 [kube-probe/1.15+ 127.0.0.1:55558]
I0530 00:49:16.830487       1 reflector.go:384] cmd/kube-scheduler/app/server.go:223: Watch close - *v1.Pod total 25 items received
I0530 00:49:21.476569       1 wrap.go:47] GET /healthz: (86.54µs) 200 [kube-probe/1.15+ 127.0.0.1:55594]
I0530 00:49:31.476626       1 wrap.go:47] GET /healthz: (77.442µs) 200 [kube-probe/1.15+ 127.0.0.1:55632]
I0530 00:49:41.476847       1 wrap.go:47] GET /healthz: (82.366µs) 200 [kube-probe/1.15+ 127.0.0.1:55666]
I0530 00:49:51.476848       1 wrap.go:47] GET /healthz: (69.636µs) 200 [kube-probe/1.15+ 127.0.0.1:55698]
I0530 00:50:01.476735       1 wrap.go:47] GET /healthz: (53.364µs) 200 [kube-probe/1.15+ 127.0.0.1:55746]
I0530 00:50:11.476581       1 wrap.go:47] GET /healthz: (76.154µs) 200 [kube-probe/1.15+ 127.0.0.1:55780]
I0530 00:50:21.476909       1 wrap.go:47] GET /healthz: (92.978µs) 200 [kube-probe/1.15+ 127.0.0.1:55816]
I0530 00:50:24.818181       1 reflector.go:384] k8s.io/client-go/informers/factory.go:133: Watch close - *v1.ReplicaSet total 0 items received
I0530 00:50:31.476922       1 wrap.go:47] GET /healthz: (82.514µs) 200 [kube-probe/1.15+ 127.0.0.1:55850]
I0530 00:50:41.476788       1 wrap.go:47] GET /healthz: (60.643µs) 200 [kube-probe/1.15+ 127.0.0.1:55884]
I0530 00:50:51.476651       1 wrap.go:47] GET /healthz: (47.952µs) 200 [kube-probe/1.15+ 127.0.0.1:55918]
I0530 00:51:01.476878       1 wrap.go:47] GET /healthz: (80.347µs) 200 [kube-probe/1.15+ 127.0.0.1:55968]
I0530 00:51:04.787640       1 reflector.go:384] k8s.io/client-go/informers/factory.go:133: Watch close - *v1.ReplicationController total 0 items received
I0530 00:51:11.477200       1 wrap.go:47] GET /healthz: (59.866µs) 200 [kube-probe/1.15+ 127.0.0.1:56002]
I0530 00:51:21.476778       1 wrap.go:47] GET /healthz: (78.957µs) 200 [kube-probe/1.15+ 127.0.0.1:56038]
I0530 00:51:31.476644       1 wrap.go:47] GET /healthz: (75.917µs) 200 [kube-probe/1.15+ 127.0.0.1:56072]
I0530 00:51:41.476665       1 wrap.go:47] GET /healthz: (66.342µs) 200 [kube-probe/1.15+ 127.0.0.1:56106]
I0530 00:51:51.477699       1 wrap.go:47] GET /healthz: (64.378µs) 200 [kube-probe/1.15+ 127.0.0.1:56138]
I0530 00:52:01.477645       1 wrap.go:47] GET /healthz: (83.068µs) 200 [kube-probe/1.15+ 127.0.0.1:56188]
I0530 00:52:11.477227       1 wrap.go:47] GET /healthz: (76.313µs) 200 [kube-probe/1.15+ 127.0.0.1:56222]
I0530 00:52:21.477602       1 wrap.go:47] GET /healthz: (79.364µs) 200 [kube-probe/1.15+ 127.0.0.1:56258]
I0530 00:52:31.477301       1 wrap.go:47] GET /healthz: (72.952µs) 200 [kube-probe/1.15+ 127.0.0.1:56294]
I0530 00:52:41.476533       1 wrap.go:47] GET /healthz: (75.196µs) 200 [kube-probe/1.15+ 127.0.0.1:56328]
I0530 00:52:51.476585       1 wrap.go:47] GET /healthz: (70.689µs) 200 [kube-probe/1.15+ 127.0.0.1:56360]
I0530 00:53:01.477000       1 wrap.go:47] GET /healthz: (89.902µs) 200 [kube-probe/1.15+ 127.0.0.1:56408]
I0530 00:53:11.476617       1 wrap.go:47] GET /healthz: (82.029µs) 200 [kube-probe/1.15+ 127.0.0.1:56444]
I0530 00:53:21.476735       1 wrap.go:47] GET /healthz: (75.61µs) 200 [kube-probe/1.15+ 127.0.0.1:56482]
I0530 00:53:21.832962       1 reflector.go:384] k8s.io/client-go/informers/factory.go:133: Watch close - *v1.PersistentVolumeClaim total 0 items received
I0530 00:53:31.476625       1 wrap.go:47] GET /healthz: (63.33µs) 200 [kube-probe/1.15+ 127.0.0.1:56516]
I0530 00:53:41.476606       1 wrap.go:47] GET /healthz: (68.163µs) 200 [kube-probe/1.15+ 127.0.0.1:56550]
I0530 00:53:41.826366       1 reflector.go:384] k8s.io/client-go/informers/factory.go:133: Watch close - *v1.PersistentVolume total 0 items received
I0530 00:53:51.476917       1 wrap.go:47] GET /healthz: (101.308µs) 200 [kube-probe/1.15+ 127.0.0.1:56582]
I0530 00:53:54.779579       1 reflector.go:384] k8s.io/client-go/informers/factory.go:133: Watch close - *v1.Node total 42 items received
I0530 00:54:01.477428       1 wrap.go:47] GET /healthz: (63.608µs) 200 [kube-probe/1.15+ 127.0.0.1:56696]
I0530 00:54:11.477640       1 wrap.go:47] GET /healthz: (66.212µs) 200 [kube-probe/1.15+ 127.0.0.1:56730]
I0530 00:54:21.477603       1 wrap.go:47] GET /healthz: (78.412µs) 200 [kube-probe/1.15+ 127.0.0.1:56768]
I0530 00:54:31.477749       1 wrap.go:47] GET /healthz: (74.849µs) 200 [kube-probe/1.15+ 127.0.0.1:56802]
I0530 00:54:40.810090       1 reflector.go:384] k8s.io/client-go/informers/factory.go:133: Watch close - *v1.StatefulSet total 0 items received
I0530 00:54:41.476989       1 wrap.go:47] GET /healthz: (67.425µs) 200 [kube-probe/1.15+ 127.0.0.1:56838]
I0530 00:54:51.476892       1 wrap.go:47] GET /healthz: (53.113µs) 200 [kube-probe/1.15+ 127.0.0.1:56870]
I0530 00:55:01.476565       1 wrap.go:47] GET /healthz: (66.216µs) 200 [kube-probe/1.15+ 127.0.0.1:56918]
I0530 00:55:05.806332       1 reflector.go:384] k8s.io/client-go/informers/factory.go:133: Watch close - *v1.Service total 0 items received
I0530 00:55:11.476688       1 wrap.go:47] GET /healthz: (58.951µs) 200 [kube-probe/1.15+ 127.0.0.1:56952]
I0530 00:55:21.477616       1 wrap.go:47] GET /healthz: (65.854µs) 200 [kube-probe/1.15+ 127.0.0.1:56988]
I0530 00:55:25.815170       1 reflector.go:384] k8s.io/client-go/informers/factory.go:133: Watch close - *v1beta1.PodDisruptionBudget total 0 items received
I0530 00:55:31.477220       1 wrap.go:47] GET /healthz: (65.29µs) 200 [kube-probe/1.15+ 127.0.0.1:57026]
I0530 00:55:33.797933       1 reflector.go:384] k8s.io/client-go/informers/factory.go:133: Watch close - *v1.StorageClass total 0 items received
I0530 00:55:41.476535       1 wrap.go:47] GET /healthz: (131.158µs) 200 [kube-probe/1.15+ 127.0.0.1:57060]
I0530 00:55:51.476832       1 wrap.go:47] GET /healthz: (78.037µs) 200 [kube-probe/1.15+ 127.0.0.1:57092]
I0530 00:55:58.820320       1 reflector.go:384] k8s.io/client-go/informers/factory.go:133: Watch close - *v1.ReplicaSet total 0 items received
I0530 00:56:01.476777       1 wrap.go:47] GET /healthz: (185.048µs) 200 [kube-probe/1.15+ 127.0.0.1:57140]
I0530 00:56:11.476820       1 wrap.go:47] GET /healthz: (59.733µs) 200 [kube-probe/1.15+ 127.0.0.1:57176]
I0530 00:56:21.476839       1 wrap.go:47] GET /healthz: (89.261µs) 200 [kube-probe/1.15+ 127.0.0.1:57212]
I0530 00:56:31.476826       1 wrap.go:47] GET /healthz: (71.886µs) 200 [kube-probe/1.15+ 127.0.0.1:57246]
I0530 00:56:41.476834       1 wrap.go:47] GET /healthz: (51.201µs) 200 [kube-probe/1.15+ 127.0.0.1:57282]
I0530 00:56:51.477517       1 wrap.go:47] GET /healthz: (97.059µs) 200 [kube-probe/1.15+ 127.0.0.1:57316]
I0530 00:57:01.476876       1 wrap.go:47] GET /healthz: (66.071µs) 200 [kube-probe/1.15+ 127.0.0.1:57364]
I0530 00:57:11.477073       1 wrap.go:47] GET /healthz: (82.004µs) 200 [kube-probe/1.15+ 127.0.0.1:57398]
I0530 00:57:21.476559       1 wrap.go:47] GET /healthz: (107.182µs) 200 [kube-probe/1.15+ 127.0.0.1:57434]
I0530 00:57:31.476975       1 wrap.go:47] GET /healthz: (83.226µs) 200 [kube-probe/1.15+ 127.0.0.1:57468]
I0530 00:57:41.476699       1 wrap.go:47] GET /healthz: (73.189µs) 200 [kube-probe/1.15+ 127.0.0.1:57502]
I0530 00:57:51.476902       1 wrap.go:47] GET /healthz: (70.62µs) 200 [kube-probe/1.15+ 127.0.0.1:57538]
I0530 00:57:55.789772       1 reflector.go:384] k8s.io/client-go/informers/factory.go:133: Watch close - *v1.ReplicationController total 0 items received
I0530 00:58:01.480983       1 wrap.go:47] GET /healthz: (76.482µs) 200 [kube-probe/1.15+ 127.0.0.1:57586]
I0530 00:58:01.832864       1 reflector.go:384] cmd/kube-scheduler/app/server.go:223: Watch close - *v1.Pod total 3 items received
I0530 00:58:11.476686       1 wrap.go:47] GET /healthz: (72.424µs) 200 [kube-probe/1.15+ 127.0.0.1:57620]
I0530 00:58:21.476915       1 wrap.go:47] GET /healthz: (77.095µs) 200 [kube-probe/1.15+ 127.0.0.1:57658]
I0530 00:58:31.476722       1 wrap.go:47] GET /healthz: (155.444µs) 200 [kube-probe/1.15+ 127.0.0.1:57692]
I0530 00:58:41.476752       1 wrap.go:47] GET /healthz: (61.669µs) 200 [kube-probe/1.15+ 127.0.0.1:57728]
I0530 00:58:51.476668       1 wrap.go:47] GET /healthz: (75.807µs) 200 [kube-probe/1.15+ 127.0.0.1:57760]
I0530 00:59:01.476687       1 wrap.go:47] GET /healthz: (87.942µs) 200 [kube-probe/1.15+ 127.0.0.1:57810]
I0530 00:59:08.835199       1 reflector.go:384] k8s.io/client-go/informers/factory.go:133: Watch close - *v1.PersistentVolumeClaim total 0 items received
I0530 00:59:11.477116       1 wrap.go:47] GET /healthz: (70.766µs) 200 [kube-probe/1.15+ 127.0.0.1:57844]
I0530 00:59:21.476840       1 wrap.go:47] GET /healthz: (52.198µs) 200 [kube-probe/1.15+ 127.0.0.1:57882]
I0530 00:59:31.476880       1 wrap.go:47] GET /healthz: (49.633µs) 200 [kube-probe/1.15+ 127.0.0.1:57916]
I0530 00:59:41.476859       1 wrap.go:47] GET /healthz: (80.761µs) 200 [kube-probe/1.15+ 127.0.0.1:57952]
I0530 00:59:47.812153       1 reflector.go:384] k8s.io/client-go/informers/factory.go:133: Watch close - *v1.StatefulSet total 0 items received
I0530 00:59:51.476865       1 wrap.go:47] GET /healthz: (84.001µs) 200 [kube-probe/1.15+ 127.0.0.1:57986]
I0530 01:00:01.476909       1 wrap.go:47] GET /healthz: (81.086µs) 200 [kube-probe/1.15+ 127.0.0.1:58034]
I0530 01:00:11.476707       1 wrap.go:47] GET /healthz: (69.317µs) 200 [kube-probe/1.15+ 127.0.0.1:58070]
I0530 01:00:21.476536       1 wrap.go:47] GET /healthz: (97.529µs) 200 [kube-probe/1.15+ 127.0.0.1:58106]
I0530 01:00:31.476541       1 wrap.go:47] GET /healthz: (90.207µs) 200 [kube-probe/1.15+ 127.0.0.1:58142]
I0530 01:00:41.476757       1 wrap.go:47] GET /healthz: (80.442µs) 200 [kube-probe/1.15+ 127.0.0.1:58176]
I0530 01:00:51.476754       1 wrap.go:47] GET /healthz: (131.323µs) 200 [kube-probe/1.15+ 127.0.0.1:58216]
I0530 01:01:01.476791       1 wrap.go:47] GET /healthz: (78.736µs) 200 [kube-probe/1.15+ 127.0.0.1:58378]
I0530 01:01:04.800129       1 reflector.go:384] k8s.io/client-go/informers/factory.go:133: Watch close - *v1.StorageClass total 0 items received
I0530 01:01:11.476875       1 wrap.go:47] GET /healthz: (80.221µs) 200 [kube-probe/1.15+ 127.0.0.1:58412]
I0530 01:01:21.476913       1 wrap.go:47] GET /healthz: (89.39µs) 200 [kube-probe/1.15+ 127.0.0.1:58452]
I0530 01:01:29.822573       1 reflector.go:384] k8s.io/client-go/informers/factory.go:133: Watch close - *v1.ReplicaSet total 0 items received
I0530 01:01:31.476600       1 wrap.go:47] GET /healthz: (63.49µs) 200 [kube-probe/1.15+ 127.0.0.1:58494]
I0530 01:01:33.828708       1 reflector.go:384] k8s.io/client-go/informers/factory.go:133: Watch close - *v1.PersistentVolume total 0 items received
I0530 01:01:41.476801       1 wrap.go:47] GET /healthz: (64.788µs) 200 [kube-probe/1.15+ 127.0.0.1:58532]
I0530 01:01:47.781983       1 reflector.go:384] k8s.io/client-go/informers/factory.go:133: Watch close - *v1.Node total 63 items received
I0530 01:01:51.477186       1 wrap.go:47] GET /healthz: (78.449µs) 200 [kube-probe/1.15+ 127.0.0.1:58564]
I0530 01:02:01.477869       1 wrap.go:47] GET /healthz: (85.138µs) 200 [kube-probe/1.15+ 127.0.0.1:58614]
I0530 01:02:11.476705       1 wrap.go:47] GET /healthz: (78.144µs) 200 [kube-probe/1.15+ 127.0.0.1:58650]
I0530 01:02:21.476908       1 wrap.go:47] GET /healthz: (54.036µs) 200 [kube-probe/1.15+ 127.0.0.1:58686]
I0530 01:02:31.476724       1 wrap.go:47] GET /healthz: (75.282µs) 200 [kube-probe/1.15+ 127.0.0.1:58722]
I0530 01:02:41.476677       1 wrap.go:47] GET /healthz: (68.685µs) 200 [kube-probe/1.15+ 127.0.0.1:58758]
I0530 01:02:51.476799       1 wrap.go:47] GET /healthz: (77.249µs) 200 [kube-probe/1.15+ 127.0.0.1:58792]
I0530 01:03:01.476961       1 wrap.go:47] GET /healthz: (76.618µs) 200 [kube-probe/1.15+ 127.0.0.1:58840]
I0530 01:03:11.476838       1 wrap.go:47] GET /healthz: (117.649µs) 200 [kube-probe/1.15+ 127.0.0.1:58874]
I0530 01:03:21.476418       1 wrap.go:47] GET /healthz: (84.345µs) 200 [kube-probe/1.15+ 127.0.0.1:58910]
I0530 01:03:31.476673       1 wrap.go:47] GET /healthz: (81.848µs) 200 [kube-probe/1.15+ 127.0.0.1:58944]
I0530 01:03:41.476684       1 wrap.go:47] GET /healthz: (62.957µs) 200 [kube-probe/1.15+ 127.0.0.1:58978]
I0530 01:03:51.476904       1 wrap.go:47] GET /healthz: (73.485µs) 200 [kube-probe/1.15+ 127.0.0.1:59012]
I0530 01:04:01.476732       1 wrap.go:47] GET /healthz: (52.297µs) 200 [kube-probe/1.15+ 127.0.0.1:59120]
I0530 01:04:11.476566       1 wrap.go:47] GET /healthz: (53.807µs) 200 [kube-probe/1.15+ 127.0.0.1:59156]
I0530 01:04:17.817398       1 reflector.go:384] k8s.io/client-go/informers/factory.go:133: Watch close - *v1beta1.PodDisruptionBudget total 0 items received
I0530 01:04:21.476670       1 wrap.go:47] GET /healthz: (65.345µs) 200 [kube-probe/1.15+ 127.0.0.1:59196]
I0530 01:04:31.476484       1 wrap.go:47] GET /healthz: (73.3µs) 200 [kube-probe/1.15+ 127.0.0.1:59230]
I0530 01:04:41.477049       1 wrap.go:47] GET /healthz: (84.17µs) 200 [kube-probe/1.15+ 127.0.0.1:59264]
I0530 01:04:45.808763       1 reflector.go:384] k8s.io/client-go/informers/factory.go:133: Watch close - *v1.Service total 0 items received
I0530 01:04:51.476699       1 wrap.go:47] GET /healthz: (77.629µs) 200 [kube-probe/1.15+ 127.0.0.1:59296]
I0530 01:05:01.478351       1 wrap.go:47] GET /healthz: (72.521µs) 200 [kube-probe/1.15+ 127.0.0.1:59346]
I0530 01:05:11.476812       1 wrap.go:47] GET /healthz: (76.593µs) 200 [kube-probe/1.15+ 127.0.0.1:59380]
I0530 01:05:18.835191       1 reflector.go:384] cmd/kube-scheduler/app/server.go:223: Watch close - *v1.Pod total 6 items received
I0530 01:05:21.476720       1 wrap.go:47] GET /healthz: (79.07µs) 200 [kube-probe/1.15+ 127.0.0.1:59416]
I0530 01:05:26.791909       1 reflector.go:384] k8s.io/client-go/informers/factory.go:133: Watch close - *v1.ReplicationController total 0 items received
I0530 01:05:31.476748       1 wrap.go:47] GET /healthz: (82.806µs) 200 [kube-probe/1.15+ 127.0.0.1:59450]
I0530 01:05:41.476615       1 wrap.go:47] GET /healthz: (80.749µs) 200 [kube-probe/1.15+ 127.0.0.1:59486]
I0530 01:05:51.476888       1 wrap.go:47] GET /healthz: (77.723µs) 200 [kube-probe/1.15+ 127.0.0.1:59518]
I0530 01:06:01.476952       1 wrap.go:47] GET /healthz: (57.444µs) 200 [kube-probe/1.15+ 127.0.0.1:59578]
I0530 01:06:11.476612       1 wrap.go:47] GET /healthz: (65.965µs) 200 [kube-probe/1.15+ 127.0.0.1:59614]
I0530 01:06:21.476856       1 wrap.go:47] GET /healthz: (77.777µs) 200 [kube-probe/1.15+ 127.0.0.1:59650]
I0530 01:06:31.476912       1 wrap.go:47] GET /healthz: (76.843µs) 200 [kube-probe/1.15+ 127.0.0.1:59684]
I0530 01:06:41.477091       1 wrap.go:47] GET /healthz: (69.014µs) 200 [kube-probe/1.15+ 127.0.0.1:59720]
I0530 01:06:51.477093       1 wrap.go:47] GET /healthz: (47.932µs) 200 [kube-probe/1.15+ 127.0.0.1:59752]
I0530 01:07:01.476852       1 wrap.go:47] GET /healthz: (76.117µs) 200 [kube-probe/1.15+ 127.0.0.1:59800]
I0530 01:07:11.476651       1 wrap.go:47] GET /healthz: (76.103µs) 200 [kube-probe/1.15+ 127.0.0.1:59836]
I0530 01:07:21.477058       1 wrap.go:47] GET /healthz: (76.397µs) 200 [kube-probe/1.15+ 127.0.0.1:59874]
I0530 01:07:31.476870       1 wrap.go:47] GET /healthz: (75.608µs) 200 [kube-probe/1.15+ 127.0.0.1:59908]
I0530 01:07:33.838077       1 reflector.go:384] k8s.io/client-go/informers/factory.go:133: Watch close - *v1.PersistentVolumeClaim total 0 items received
I0530 01:07:41.476635       1 wrap.go:47] GET /healthz: (84.293µs) 200 [kube-probe/1.15+ 127.0.0.1:59942]
I0530 01:07:51.477107       1 wrap.go:47] GET /healthz: (139.671µs) 200 [kube-probe/1.15+ 127.0.0.1:59974]
I0530 01:08:01.476728       1 wrap.go:47] GET /healthz: (71.97µs) 200 [kube-probe/1.15+ 127.0.0.1:60022]
I0530 01:08:11.477172       1 wrap.go:47] GET /healthz: (66.033µs) 200 [kube-probe/1.15+ 127.0.0.1:60056]
I0530 01:08:21.476693       1 wrap.go:47] GET /healthz: (75.801µs) 200 [kube-probe/1.15+ 127.0.0.1:60092]
I0530 01:08:31.476691       1 wrap.go:47] GET /healthz: (75.318µs) 200 [kube-probe/1.15+ 127.0.0.1:60128]
I0530 01:08:41.476784       1 wrap.go:47] GET /healthz: (75.108µs) 200 [kube-probe/1.15+ 127.0.0.1:60164]
I0530 01:08:41.814416       1 reflector.go:384] k8s.io/client-go/informers/factory.go:133: Watch close - *v1.StatefulSet total 0 items received
I0530 01:08:51.476651       1 wrap.go:47] GET /healthz: (51.325µs) 200 [kube-probe/1.15+ 127.0.0.1:60196]
I0530 01:08:57.802405       1 reflector.go:384] k8s.io/client-go/informers/factory.go:133: Watch close - *v1.StorageClass total 0 items received
I0530 01:09:01.476886       1 wrap.go:47] GET /healthz: (85.152µs) 200 [kube-probe/1.15+ 127.0.0.1:60244]
I0530 01:09:11.477233       1 wrap.go:47] GET /healthz: (77.781µs) 200 [kube-probe/1.15+ 127.0.0.1:60278]
I0530 01:09:21.476679       1 wrap.go:47] GET /healthz: (75.29µs) 200 [kube-probe/1.15+ 127.0.0.1:60316]
I0530 01:09:23.824768       1 reflector.go:384] k8s.io/client-go/informers/factory.go:133: Watch close - *v1.ReplicaSet total 0 items received
I0530 01:09:31.476545       1 wrap.go:47] GET /healthz: (48.289µs) 200 [kube-probe/1.15+ 127.0.0.1:60350]
I0530 01:09:41.477536       1 wrap.go:47] GET /healthz: (94.919µs) 200 [kube-probe/1.15+ 127.0.0.1:60386]
I0530 01:09:51.476902       1 wrap.go:47] GET /healthz: (81.37µs) 200 [kube-probe/1.15+ 127.0.0.1:60420]
I0530 01:09:57.542300       1 scheduling_queue.go:895] About to try and schedule pod container-runtime-9301/terminate-cmd-rpaab66049e-ac6a-4a24-8b5f-29e108347b34
I0530 01:09:57.542321       1 scheduler.go:454] Attempting to schedule pod: container-runtime-9301/terminate-cmd-rpaab66049e-ac6a-4a24-8b5f-29e108347b34
I0530 01:09:57.542783       1 scheduler_binder.go:255] AssumePodVolumes for pod "container-runtime-9301/terminate-cmd-rpaab66049e-ac6a-4a24-8b5f-29e108347b34", node "e2e-test-peterhornyack-windows-node-group-9q9v"
I0530 01:09:57.542810       1 scheduler_binder.go:265] AssumePodVolumes for pod "container-runtime-9301/terminate-cmd-rpaab66049e-ac6a-4a24-8b5f-29e108347b34", node "e2e-test-peterhornyack-windows-node-group-9q9v": all PVCs bound and nothing to do
I0530 01:09:57.542859       1 factory.go:734] Attempting to bind terminate-cmd-rpaab66049e-ac6a-4a24-8b5f-29e108347b34 to e2e-test-peterhornyack-windows-node-group-9q9v
I0530 01:09:57.551971       1 scheduler.go:575] pod container-runtime-9301/terminate-cmd-rpaab66049e-ac6a-4a24-8b5f-29e108347b34 is bound successfully on node e2e-test-peterhornyack-windows-node-group-9q9v, 6 nodes evaluated, 3 nodes were found feasible
I0530 01:10:01.476348       1 wrap.go:47] GET /healthz: (64.676µs) 200 [kube-probe/1.15+ 127.0.0.1:60468]
I0530 01:10:11.476719       1 wrap.go:47] GET /healthz: (92.923µs) 200 [kube-probe/1.15+ 127.0.0.1:60504]
I0530 01:10:21.476636       1 wrap.go:47] GET /healthz: (78.662µs) 200 [kube-probe/1.15+ 127.0.0.1:60540]
I0530 01:10:31.200962       1 scheduling_queue.go:895] About to try and schedule pod container-runtime-9301/terminate-cmd-rpof17370f04-8099-4a11-a6d5-6ec690b9dd8b
I0530 01:10:31.200976       1 scheduler.go:454] Attempting to schedule pod: container-runtime-9301/terminate-cmd-rpof17370f04-8099-4a11-a6d5-6ec690b9dd8b
I0530 01:10:31.203497       1 scheduler_binder.go:255] AssumePodVolumes for pod "container-runtime-9301/terminate-cmd-rpof17370f04-8099-4a11-a6d5-6ec690b9dd8b", node "e2e-test-peterhornyack-windows-node-group-1vjk"
I0530 01:10:31.203513       1 scheduler_binder.go:265] AssumePodVolumes for pod "container-runtime-9301/terminate-cmd-rpof17370f04-8099-4a11-a6d5-6ec690b9dd8b", node "e2e-test-peterhornyack-windows-node-group-1vjk": all PVCs bound and nothing to do
I0530 01:10:31.203575       1 factory.go:734] Attempting to bind terminate-cmd-rpof17370f04-8099-4a11-a6d5-6ec690b9dd8b to e2e-test-peterhornyack-windows-node-group-1vjk
I0530 01:10:31.208994       1 scheduler.go:575] pod container-runtime-9301/terminate-cmd-rpof17370f04-8099-4a11-a6d5-6ec690b9dd8b is bound successfully on node e2e-test-peterhornyack-windows-node-group-1vjk, 6 nodes evaluated, 3 nodes were found feasible
I0530 01:10:31.476730       1 wrap.go:47] GET /healthz: (72.772µs) 200 [kube-probe/1.15+ 127.0.0.1:60574]
I0530 01:10:32.784178       1 reflector.go:384] k8s.io/client-go/informers/factory.go:133: Watch close - *v1.Node total 72 items received
I0530 01:10:41.476868       1 wrap.go:47] GET /healthz: (65.652µs) 200 [kube-probe/1.15+ 127.0.0.1:60608]
I0530 01:10:46.112405       1 scheduling_queue.go:895] About to try and schedule pod container-runtime-9301/terminate-cmd-rpn6b125ab5-e4bd-416c-87ac-c995f7cb15c6
I0530 01:10:46.112417       1 scheduler.go:454] Attempting to schedule pod: container-runtime-9301/terminate-cmd-rpn6b125ab5-e4bd-416c-87ac-c995f7cb15c6
I0530 01:10:46.112742       1 scheduler_binder.go:255] AssumePodVolumes for pod "container-runtime-9301/terminate-cmd-rpn6b125ab5-e4bd-416c-87ac-c995f7cb15c6", node "e2e-test-peterhornyack-windows-node-group-jpxd"
I0530 01:10:46.112754       1 scheduler_binder.go:265] AssumePodVolumes for pod "container-runtime-9301/terminate-cmd-rpn6b125ab5-e4bd-416c-87ac-c995f7cb15c6", node "e2e-test-peterhornyack-windows-node-group-jpxd": all PVCs bound and nothing to do
I0530 01:10:46.112798       1 factory.go:734] Attempting to bind terminate-cmd-rpn6b125ab5-e4bd-416c-87ac-c995f7cb15c6 to e2e-test-peterhornyack-windows-node-group-jpxd
I0530 01:10:46.125795       1 scheduler.go:575] pod container-runtime-9301/terminate-cmd-rpn6b125ab5-e4bd-416c-87ac-c995f7cb15c6 is bound successfully on node e2e-test-peterhornyack-windows-node-group-jpxd, 6 nodes evaluated, 3 nodes were found feasible
I0530 01:10:51.476704       1 wrap.go:47] GET /healthz: (62.999µs) 200 [kube-probe/1.15+ 127.0.0.1:60642]
I0530 01:10:58.831251       1 reflector.go:384] k8s.io/client-go/informers/factory.go:133: Watch close - *v1.PersistentVolume total 0 items received
I0530 01:11:01.476628       1 wrap.go:47] GET /healthz: (67.384µs) 200 [kube-probe/1.15+ 127.0.0.1:60690]
I0530 01:11:07.295926       1 scheduling_queue.go:895] About to try and schedule pod kubectl-1090/pause
I0530 01:11:07.295953       1 scheduler.go:454] Attempting to schedule pod: kubectl-1090/pause
I0530 01:11:07.296347       1 scheduler_binder.go:255] AssumePodVolumes for pod "kubectl-1090/pause", node "e2e-test-peterhornyack-windows-node-group-jpxd"
I0530 01:11:07.296358       1 scheduler_binder.go:265] AssumePodVolumes for pod "kubectl-1090/pause", node "e2e-test-peterhornyack-windows-node-group-jpxd": all PVCs bound and nothing to do
I0530 01:11:07.296412       1 factory.go:734] Attempting to bind pause to e2e-test-peterhornyack-windows-node-group-jpxd
I0530 01:11:07.304574       1 scheduler.go:575] pod kubectl-1090/pause is bound successfully on node e2e-test-peterhornyack-windows-node-group-jpxd, 6 nodes evaluated, 3 nodes were found feasible
I0530 01:11:11.476408       1 wrap.go:47] GET /healthz: (50.977µs) 200 [kube-probe/1.15+ 127.0.0.1:60724]
I0530 01:11:21.476620       1 wrap.go:47] GET /healthz: (64.418µs) 200 [kube-probe/1.15+ 127.0.0.1:60760]
I0530 01:11:25.485330       1 scheduling_queue.go:895] About to try and schedule pod replicaset-2637/pod-adoption-release
I0530 01:11:25.485344       1 scheduler.go:454] Attempting to schedule pod: replicaset-2637/pod-adoption-release
I0530 01:11:25.485904       1 scheduler_binder.go:255] AssumePodVolumes for pod "replicaset-2637/pod-adoption-release", node "e2e-test-peterhornyack-windows-node-group-1vjk"
I0530 01:11:25.485916       1 scheduler_binder.go:265] AssumePodVolumes for pod "replicaset-2637/pod-adoption-release", node "e2e-test-peterhornyack-windows-node-group-1vjk": all PVCs bound and nothing to do
I0530 01:11:25.485974       1 factory.go:734] Attempting to bind pod-adoption-release to e2e-test-peterhornyack-windows-node-group-1vjk
I0530 01:11:25.492305       1 scheduler.go:575] pod replicaset-2637/pod-adoption-release is bound successfully on node e2e-test-peterhornyack-windows-node-group-1vjk, 6 nodes evaluated, 3 nodes were found feasible
I0530 01:11:31.476535       1 wrap.go:47] GET /healthz: (84.19µs) 200 [kube-probe/1.15+ 127.0.0.1:60796]
I0530 01:11:33.846752       1 scheduling_queue.go:895] About to try and schedule pod replicaset-2637/pod-adoption-release-79ftq
I0530 01:11:33.846778       1 scheduler.go:454] Attempting to schedule pod: replicaset-2637/pod-adoption-release-79ftq
I0530 01:11:33.847196       1 scheduler_binder.go:255] AssumePodVolumes for pod "replicaset-2637/pod-adoption-release-79ftq", node "e2e-test-peterhornyack-windows-node-group-jpxd"
I0530 01:11:33.847207       1 scheduler_binder.go:265] AssumePodVolumes for pod "replicaset-2637/pod-adoption-release-79ftq", node "e2e-test-peterhornyack-windows-node-group-jpxd": all PVCs bound and nothing to do
I0530 01:11:33.847262       1 factory.go:734] Attempting to bind pod-adoption-release-79ftq to e2e-test-peterhornyack-windows-node-group-jpxd
I0530 01:11:33.861622       1 scheduler.go:575] pod replicaset-2637/pod-adoption-release-79ftq is bound successfully on node e2e-test-peterhornyack-windows-node-group-jpxd, 6 nodes evaluated, 3 nodes were found feasible
I0530 01:11:41.476685       1 wrap.go:47] GET /healthz: (76.012µs) 200 [kube-probe/1.15+ 127.0.0.1:60830]
I0530 01:11:51.477079       1 wrap.go:47] GET /healthz: (84.008µs) 200 [kube-probe/1.15+ 127.0.0.1:60862]
I0530 01:11:57.837576       1 reflector.go:384] cmd/kube-scheduler/app/server.go:223: Watch close - *v1.Pod total 53 items received
I0530 01:12:01.479783       1 wrap.go:47] GET /healthz: (75.383µs) 200 [kube-probe/1.15+ 127.0.0.1:60912]
I0530 01:12:11.477051       1 wrap.go:47] GET /healthz: (79.804µs) 200 [kube-probe/1.15+ 127.0.0.1:60946]
I0530 01:12:21.476681       1 wrap.go:47] GET /healthz: (78.963µs) 200 [kube-probe/1.15+ 127.0.0.1:60982]
I0530 01:12:31.476996       1 wrap.go:47] GET /healthz: (72.446µs) 200 [kube-probe/1.15+ 127.0.0.1:32784]
I0530 01:12:41.476656       1 wrap.go:47] GET /healthz: (53.583µs) 200 [kube-probe/1.15+ 127.0.0.1:32818]
I0530 01:12:51.476908       1 wrap.go:47] GET /healthz: (48.829µs) 200 [kube-probe/1.15+ 127.0.0.1:32850]
I0530 01:12:59.892015       1 scheduling_queue.go:895] About to try and schedule pod pods-4814/pod-back-off-image
I0530 01:12:59.892027       1 scheduler.go:454] Attempting to schedule pod: pods-4814/pod-back-off-image
I0530 01:12:59.892417       1 scheduler_binder.go:255] AssumePodVolumes for pod "pods-4814/pod-back-off-image", node "e2e-test-peterhornyack-windows-node-group-9q9v"
I0530 01:12:59.892427       1 scheduler_binder.go:265] AssumePodVolumes for pod "pods-4814/pod-back-off-image", node "e2e-test-peterhornyack-windows-node-group-9q9v": all PVCs bound and nothing to do
I0530 01:12:59.892486       1 factory.go:734] Attempting to bind pod-back-off-image to e2e-test-peterhornyack-windows-node-group-9q9v
I0530 01:12:59.898357       1 scheduler.go:575] pod pods-4814/pod-back-off-image is bound successfully on node e2e-test-peterhornyack-windows-node-group-9q9v, 6 nodes evaluated, 3 nodes were found feasible
I0530 01:13:01.476894       1 wrap.go:47] GET /healthz: (132.73µs) 200 [kube-probe/1.15+ 127.0.0.1:32900]
I0530 01:13:11.477132       1 wrap.go:47] GET /healthz: (73.028µs) 200 [kube-probe/1.15+ 127.0.0.1:32936]
I0530 01:13:21.476758       1 wrap.go:47] GET /healthz: (47.189µs) 200 [kube-probe/1.15+ 127.0.0.1:32972]
I0530 01:13:27.819448       1 reflector.go:384] k8s.io/client-go/informers/factory.go:133: Watch close - *v1beta1.PodDisruptionBudget total 0 items received
I0530 01:13:31.476713       1 wrap.go:47] GET /healthz: (61.052µs) 200 [kube-probe/1.15+ 127.0.0.1:33006]
I0530 01:13:41.476862       1 wrap.go:47] GET /healthz: (75.999µs) 200 [kube-probe/1.15+ 127.0.0.1:33040]
I0530 01:13:45.810836       1 reflector.go:384] k8s.io/client-go/informers/factory.go:133: Watch close - *v1.Service total 0 items received
I0530 01:13:45.816338       1 reflector.go:384] k8s.io/client-go/informers/factory.go:133: Watch close - *v1.StatefulSet total 0 items received
I0530 01:13:51.476644       1 wrap.go:47] GET /healthz: (85.219µs) 200 [kube-probe/1.15+ 127.0.0.1:33072]
I0530 01:13:58.794104       1 reflector.go:384] k8s.io/client-go/informers/factory.go:133: Watch close - *v1.ReplicationController total 0 items received
I0530 01:14:01.476569       1 wrap.go:47] GET /healthz: (86.798µs) 200 [kube-probe/1.15+ 127.0.0.1:33120]
I0530 01:14:11.476667       1 wrap.go:47] GET /healthz: (81.598µs) 200 [kube-probe/1.15+ 127.0.0.1:33154]
I0530 01:14:21.477596       1 wrap.go:47] GET /healthz: (68.428µs) 200 [kube-probe/1.15+ 127.0.0.1:33190]
I0530 01:14:31.476574       1 wrap.go:47] GET /healthz: (64.229µs) 200 [kube-probe/1.15+ 127.0.0.1:33228]
I0530 01:14:32.840491       1 reflector.go:384] k8s.io/client-go/informers/factory.go:133: Watch close - *v1.PersistentVolumeClaim total 0 items received
I0530 01:14:41.476878       1 wrap.go:47] GET /healthz: (88.437µs) 200 [kube-probe/1.15+ 127.0.0.1:33262]
I0530 01:14:51.476838       1 wrap.go:47] GET /healthz: (56.383µs) 200 [kube-probe/1.15+ 127.0.0.1:33294]
I0530 01:15:01.476753       1 wrap.go:47] GET /healthz: (114.816µs) 200 [kube-probe/1.15+ 127.0.0.1:33342]
I0530 01:15:11.476703       1 wrap.go:47] GET /healthz: (82.963µs) 200 [kube-probe/1.15+ 127.0.0.1:33376]
I0530 01:15:21.476648       1 wrap.go:47] GET /healthz: (77.02µs) 200 [kube-probe/1.15+ 127.0.0.1:33414]
I0530 01:15:31.476818       1 wrap.go:47] GET /healthz: (72.833µs) 200 [kube-probe/1.15+ 127.0.0.1:33448]
I0530 01:15:41.476572       1 wrap.go:47] GET /healthz: (49.717µs) 200 [kube-probe/1.15+ 127.0.0.1:33488]
I0530 01:15:51.476962       1 wrap.go:47] GET /healthz: (82.614µs) 200 [kube-probe/1.15+ 127.0.0.1:33520]
I0530 01:16:01.476668       1 wrap.go:47] GET /healthz: (78.519µs) 200 [kube-probe/1.15+ 127.0.0.1:33570]
I0530 01:16:11.477059       1 wrap.go:47] GET /healthz: (76.289µs) 200 [kube-probe/1.15+ 127.0.0.1:33604]
I0530 01:16:21.476628       1 wrap.go:47] GET /healthz: (67.815µs) 200 [kube-probe/1.15+ 127.0.0.1:33640]
I0530 01:16:31.476589       1 wrap.go:47] GET /healthz: (63.557µs) 200 [kube-probe/1.15+ 127.0.0.1:33674]
I0530 01:16:41.477277       1 wrap.go:47] GET /healthz: (49.208µs) 200 [kube-probe/1.15+ 127.0.0.1:33708]
I0530 01:16:51.476644       1 wrap.go:47] GET /healthz: (75.79µs) 200 [kube-probe/1.15+ 127.0.0.1:33742]
I0530 01:16:54.829450       1 reflector.go:384] k8s.io/client-go/informers/factory.go:133: Watch close - *v1.ReplicaSet total 6 items received
I0530 01:17:01.477006       1 wrap.go:47] GET /healthz: (75.71µs) 200 [kube-probe/1.15+ 127.0.0.1:33790]
I0530 01:17:02.804311       1 reflector.go:384] k8s.io/client-go/informers/factory.go:133: Watch close - *v1.StorageClass total 0 items received
I0530 01:17:11.476933       1 wrap.go:47] GET /healthz: (64.715µs) 200 [kube-probe/1.15+ 127.0.0.1:33824]
I0530 01:17:21.476801       1 wrap.go:47] GET /healthz: (50.065µs) 200 [kube-probe/1.15+ 127.0.0.1:33860]
I0530 01:17:31.476962       1 wrap.go:47] GET /healthz: (66.186µs) 200 [kube-probe/1.15+ 127.0.0.1:33896]
I0530 01:17:41.477675       1 wrap.go:47] GET /healthz: (109.032µs) 200 [kube-probe/1.15+ 127.0.0.1:33930]
I0530 01:17:51.476619       1 wrap.go:47] GET /healthz: (90.479µs) 200 [kube-probe/1.15+ 127.0.0.1:33962]
I0530 01:18:01.476711       1 wrap.go:47] GET /healthz: (91.333µs) 200 [kube-probe/1.15+ 127.0.0.1:34012]
I0530 01:18:11.476916       1 wrap.go:47] GET /healthz: (65.135µs) 200 [kube-probe/1.15+ 127.0.0.1:34046]
I0530 01:18:21.476886       1 wrap.go:47] GET /healthz: (94.942µs) 200 [kube-probe/1.15+ 127.0.0.1:34082]
I0530 01:18:31.476645       1 wrap.go:47] GET /healthz: (76.413µs) 200 [kube-probe/1.15+ 127.0.0.1:34116]
I0530 01:18:41.476715       1 wrap.go:47] GET /healthz: (66.631µs) 200 [kube-probe/1.15+ 127.0.0.1:34150]
I0530 01:18:51.476933       1 wrap.go:47] GET /healthz: (64.595µs) 200 [kube-probe/1.15+ 127.0.0.1:34184]
I0530 01:19:01.476719       1 wrap.go:47] GET /healthz: (48.471µs) 200 [kube-probe/1.15+ 127.0.0.1:34232]
I0530 01:19:11.476799       1 wrap.go:47] GET /healthz: (106.095µs) 200 [kube-probe/1.15+ 127.0.0.1:34268]
I0530 01:19:21.476989       1 wrap.go:47] GET /healthz: (87.206µs) 200 [kube-probe/1.15+ 127.0.0.1:34304]
I0530 01:19:31.476706       1 wrap.go:47] GET /healthz: (70.772µs) 200 [kube-probe/1.15+ 127.0.0.1:34338]
I0530 01:19:41.476597       1 wrap.go:47] GET /healthz: (75.479µs) 200 [kube-probe/1.15+ 127.0.0.1:34372]
I0530 01:19:51.476767       1 wrap.go:47] GET /healthz: (79.44µs) 200 [kube-probe/1.15+ 127.0.0.1:34404]
I0530 01:19:51.833368       1 reflector.go:384] k8s.io/client-go/informers/factory.go:133: Watch close - *v1.PersistentVolume total 0 items received
I0530 01:20:01.476833       1 wrap.go:47] GET /healthz: (53.959µs) 200 [kube-probe/1.15+ 127.0.0.1:34454]
I0530 01:20:11.476509       1 wrap.go:47] GET /healthz: (81.869µs) 200 [kube-probe/1.15+ 127.0.0.1:34490]
I0530 01:20:17.528289       1 scheduling_queue.go:895] About to try and schedule pod secrets-3084/pod-secrets-d9630e5f-4ca6-44eb-807f-61b06b0beffe
I0530 01:20:17.528301       1 scheduler.go:454] Attempting to schedule pod: secrets-3084/pod-secrets-d9630e5f-4ca6-44eb-807f-61b06b0beffe
I0530 01:20:17.529697       1 scheduler_binder.go:255] AssumePodVolumes for pod "secrets-3084/pod-secrets-d9630e5f-4ca6-44eb-807f-61b06b0beffe", node "e2e-test-peterhornyack-windows-node-group-9q9v"
I0530 01:20:17.529719       1 scheduler_binder.go:265] AssumePodVolumes for pod "secrets-3084/pod-secrets-d9630e5f-4ca6-44eb-807f-61b06b0beffe", node "e2e-test-peterhornyack-windows-node-group-9q9v": all PVCs bound and nothing to do
I0530 01:20:17.531056       1 factory.go:734] Attempting to bind pod-secrets-d9630e5f-4ca6-44eb-807f-61b06b0beffe to e2e-test-peterhornyack-windows-node-group-9q9v
I0530 01:20:17.538601       1 scheduler.go:575] pod secrets-3084/pod-secrets-d9630e5f-4ca6-44eb-807f-61b06b0beffe is bound successfully on node e2e-test-peterhornyack-windows-node-group-9q9v, 6 nodes evaluated, 3 nodes were found feasible
I0530 01:20:19.813900       1 reflector.go:384] k8s.io/client-go/informers/factory.go:133: Watch close - *v1.Service total 0 items received
I0530 01:20:21.476888       1 wrap.go:47] GET /healthz: (62.751µs) 200 [kube-probe/1.15+ 127.0.0.1:34530]
I0530 01:20:24.839682       1 reflector.go:384] cmd/kube-scheduler/app/server.go:223: Watch close - *v1.Pod total 41 items received
I0530 01:20:28.786489       1 reflector.go:384] k8s.io/client-go/informers/factory.go:133: Watch close - *v1.Node total 80 items received
I0530 01:20:31.476656       1 wrap.go:47] GET /healthz: (71.19µs) 200 [kube-probe/1.15+ 127.0.0.1:34564]
I0530 01:20:41.477514       1 wrap.go:47] GET /healthz: (91.067µs) 200 [kube-probe/1.15+ 127.0.0.1:34598]
I0530 01:20:47.779597       1 scheduling_queue.go:895] About to try and schedule pod downward-api-411/downwardapi-volume-d9236ad3-8a05-48c6-a3ea-1e3a2e894314
I0530 01:20:47.779608       1 scheduler.go:454] Attempting to schedule pod: downward-api-411/downwardapi-volume-d9236ad3-8a05-48c6-a3ea-1e3a2e894314
I0530 01:20:47.779931       1 scheduler_binder.go:255] AssumePodVolumes for pod "downward-api-411/downwardapi-volume-d9236ad3-8a05-48c6-a3ea-1e3a2e894314", node "e2e-test-peterhornyack-windows-node-group-9q9v"
I0530 01:20:47.779942       1 scheduler_binder.go:265] AssumePodVolumes for pod "downward-api-411/downwardapi-volume-d9236ad3-8a05-48c6-a3ea-1e3a2e894314", node "e2e-test-peterhornyack-windows-node-group-9q9v": all PVCs bound and nothing to do
I0530 01:20:47.779994       1 factory.go:734] Attempting to bind downwardapi-volume-d9236ad3-8a05-48c6-a3ea-1e3a2e894314 to e2e-test-peterhornyack-windows-node-group-9q9v
I0530 01:20:47.786427       1 scheduler.go:575] pod downward-api-411/downwardapi-volume-d9236ad3-8a05-48c6-a3ea-1e3a2e894314 is bound successfully on node e2e-test-peterhornyack-windows-node-group-9q9v, 6 nodes evaluated, 3 nodes were found feasible
I0530 01:20:51.476592       1 wrap.go:47] GET /healthz: (61.835µs) 200 [kube-probe/1.15+ 127.0.0.1:34630]
I0530 01:21:01.476673       1 wrap.go:47] GET /healthz: (74.848µs) 200 [kube-probe/1.15+ 127.0.0.1:34678]
I0530 01:21:02.199274       1 scheduling_queue.go:895] About to try and schedule pod containers-4955/client-containers-754d037c-2a27-4639-ac6e-5d7015f40286
I0530 01:21:02.199289       1 scheduler.go:454] Attempting to schedule pod: containers-4955/client-containers-754d037c-2a27-4639-ac6e-5d7015f40286
I0530 01:21:02.199607       1 scheduler_binder.go:255] AssumePodVolumes for pod "containers-4955/client-containers-754d037c-2a27-4639-ac6e-5d7015f40286", node "e2e-test-peterhornyack-windows-node-group-9q9v"
I0530 01:21:02.199783       1 scheduler_binder.go:265] AssumePodVolumes for pod "containers-4955/client-containers-754d037c-2a27-4639-ac6e-5d7015f40286", node "e2e-test-peterhornyack-windows-node-group-9q9v": all PVCs bound and nothing to do
I0530 01:21:02.199852       1 factory.go:734] Attempting to bind client-containers-754d037c-2a27-4639-ac6e-5d7015f40286 to e2e-test-peterhornyack-windows-node-group-9q9v
I0530 01:21:02.206674       1 scheduler.go:575] pod containers-4955/client-containers-754d037c-2a27-4639-ac6e-5d7015f40286 is bound successfully on node e2e-test-peterhornyack-windows-node-group-9q9v, 6 nodes evaluated, 3 nodes were found feasible
I0530 01:21:11.476888       1 wrap.go:47] GET /healthz: (76.762µs) 200 [kube-probe/1.15+ 127.0.0.1:34712]
I0530 01:21:16.629618       1 scheduling_queue.go:895] About to try and schedule pod pods-2264/pod-logs-websocket-fcdb3b9c-3819-47a7-8aae-b6bae7821a0d
I0530 01:21:16.629644       1 scheduler.go:454] Attempting to schedule pod: pods-2264/pod-logs-websocket-fcdb3b9c-3819-47a7-8aae-b6bae7821a0d
I0530 01:21:16.630081       1 scheduler_binder.go:255] AssumePodVolumes for pod "pods-2264/pod-logs-websocket-fcdb3b9c-3819-47a7-8aae-b6bae7821a0d", node "e2e-test-peterhornyack-windows-node-group-1vjk"
I0530 01:21:16.630093       1 scheduler_binder.go:265] AssumePodVolumes for pod "pods-2264/pod-logs-websocket-fcdb3b9c-3819-47a7-8aae-b6bae7821a0d", node "e2e-test-peterhornyack-windows-node-group-1vjk": all PVCs bound and nothing to do
I0530 01:21:16.630172       1 factory.go:734] Attempting to bind pod-logs-websocket-fcdb3b9c-3819-47a7-8aae-b6bae7821a0d to e2e-test-peterhornyack-windows-node-group-1vjk
I0530 01:21:16.635556       1 scheduler.go:575] pod pods-2264/pod-logs-websocket-fcdb3b9c-3819-47a7-8aae-b6bae7821a0d is bound successfully on node e2e-test-peterhornyack-windows-node-group-1vjk, 6 nodes evaluated, 3 nodes were found feasible
I0530 01:21:21.476582       1 wrap.go:47] GET /healthz: (84.407µs) 200 [kube-probe/1.15+ 127.0.0.1:34748]
I0530 01:21:31.476517       1 wrap.go:47] GET /healthz: (86.799µs) 200 [kube-probe/1.15+ 127.0.0.1:34784]
I0530 01:21:41.476603       1 wrap.go:47] GET /healthz: (74.66µs) 200 [kube-probe/1.15+ 127.0.0.1:34818]
I0530 01:21:48.971443       1 scheduling_queue.go:895] About to try and schedule pod projected-925/pod-projected-configmaps-8c97c3ac-47cf-4720-8735-0fa1b142a4a3
I0530 01:21:48.972246       1 scheduler.go:454] Attempting to schedule pod: projected-925/pod-projected-configmaps-8c97c3ac-47cf-4720-8735-0fa1b142a4a3
I0530 01:21:48.973588       1 scheduler_binder.go:255] AssumePodVolumes for pod "projected-925/pod-projected-configmaps-8c97c3ac-47cf-4720-8735-0fa1b142a4a3", node "e2e-test-peterhornyack-windows-node-group-9q9v"
I0530 01:21:48.973603       1 scheduler_binder.go:265] AssumePodVolumes for pod "projected-925/pod-projected-configmaps-8c97c3ac-47cf-4720-8735-0fa1b142a4a3", node "e2e-test-peterhornyack-windows-node-group-9q9v": all PVCs bound and nothing to do
I0530 01:21:48.973651       1 factory.go:734] Attempting to bind pod-projected-configmaps-8c97c3ac-47cf-4720-8735-0fa1b142a4a3 to e2e-test-peterhornyack-windows-node-group-9q9v
I0530 01:21:48.982721       1 scheduler.go:575] pod projected-925/pod-projected-configmaps-8c97c3ac-47cf-4720-8735-0fa1b142a4a3 is bound successfully on node e2e-test-peterhornyack-windows-node-group-9q9v, 6 nodes evaluated, 3 nodes were found feasible
I0530 01:21:51.476594       1 wrap.go:47] GET /healthz: (66.424µs) 200 [kube-probe/1.15+ 127.0.0.1:34852]
I0530 01:21:56.842628       1 reflector.go:384] k8s.io/client-go/informers/factory.go:133: Watch close - *v1.PersistentVolumeClaim total 0 items received
I0530 01:22:01.476536       1 wrap.go:47] GET /healthz: (87.016µs) 200 [kube-probe/1.15+ 127.0.0.1:34900]
I0530 01:22:11.476564       1 wrap.go:47] GET /healthz: (96.452µs) 200 [kube-probe/1.15+ 127.0.0.1:34934]
I0530 01:22:11.522787       1 scheduling_queue.go:895] About to try and schedule pod prestop-6646/server
I0530 01:22:11.522801       1 scheduler.go:454] Attempting to schedule pod: prestop-6646/server
I0530 01:22:11.523376       1 scheduler_binder.go:255] AssumePodVolumes for pod "prestop-6646/server", node "e2e-test-peterhornyack-windows-node-group-jpxd"
I0530 01:22:11.523388       1 scheduler_binder.go:265] AssumePodVolumes for pod "prestop-6646/server", node "e2e-test-peterhornyack-windows-node-group-jpxd": all PVCs bound and nothing to do
I0530 01:22:11.523447       1 factory.go:734] Attempting to bind server to e2e-test-peterhornyack-windows-node-group-jpxd
I0530 01:22:11.537955       1 scheduler.go:575] pod prestop-6646/server is bound successfully on node e2e-test-peterhornyack-windows-node-group-jpxd, 6 nodes evaluated, 3 nodes were found feasible
I0530 01:22:19.698013       1 scheduling_queue.go:895] About to try and schedule pod prestop-6646/tester
I0530 01:22:19.698027       1 scheduler.go:454] Attempting to schedule pod: prestop-6646/tester
I0530 01:22:19.699788       1 scheduler_binder.go:255] AssumePodVolumes for pod "prestop-6646/tester", node "e2e-test-peterhornyack-windows-node-group-1vjk"
I0530 01:22:19.699802       1 scheduler_binder.go:265] AssumePodVolumes for pod "prestop-6646/tester", node "e2e-test-peterhornyack-windows-node-group-1vjk": all PVCs bound and nothing to do
I0530 01:22:19.700151       1 factory.go:734] Attempting to bind tester to e2e-test-peterhornyack-windows-node-group-1vjk
I0530 01:22:19.707763       1 scheduler.go:575] pod prestop-6646/tester is bound successfully on node e2e-test-peterhornyack-windows-node-group-1vjk, 6 nodes evaluated, 3 nodes were found feasible
I0530 01:22:21.476668       1 wrap.go:47] GET /healthz: (56.108µs) 200 [kube-probe/1.15+ 127.0.0.1:34970]
I0530 01:22:31.476648       1 wrap.go:47] GET /healthz: (80.896µs) 200 [kube-probe/1.15+ 127.0.0.1:35004]
I0530 01:22:41.481281       1 wrap.go:47] GET /healthz: (74.913µs) 200 [kube-probe/1.15+ 127.0.0.1:35042]
I0530 01:22:44.796383       1 reflector.go:384] k8s.io/client-go/informers/factory.go:133: Watch close - *v1.ReplicationController total 0 items received
I0530 01:22:49.078778       1 scheduling_queue.go:895] About to try and schedule pod configmap-8999/pod-configmaps-dbc2a425-50b7-4424-a0f9-ac0cb98f8bcf
I0530 01:22:49.078798       1 scheduler.go:454] Attempting to schedule pod: configmap-8999/pod-configmaps-dbc2a425-50b7-4424-a0f9-ac0cb98f8bcf
I0530 01:22:49.079921       1 scheduler_binder.go:255] AssumePodVolumes for pod "configmap-8999/pod-configmaps-dbc2a425-50b7-4424-a0f9-ac0cb98f8bcf", node "e2e-test-peterhornyack-windows-node-group-jpxd"
I0530 01:22:49.079936       1 scheduler_binder.go:265] AssumePodVolumes for pod "configmap-8999/pod-configmaps-dbc2a425-50b7-4424-a0f9-ac0cb98f8bcf", node "e2e-test-peterhornyack-windows-node-group-jpxd": all PVCs bound and nothing to do
I0530 01:22:49.080003       1 factory.go:734] Attempting to bind pod-configmaps-dbc2a425-50b7-4424-a0f9-ac0cb98f8bcf to e2e-test-peterhornyack-windows-node-group-jpxd
I0530 01:22:49.088680       1 scheduler.go:575] pod configmap-8999/pod-configmaps-dbc2a425-50b7-4424-a0f9-ac0cb98f8bcf is bound successfully on node e2e-test-peterhornyack-windows-node-group-jpxd, 6 nodes evaluated, 3 nodes were found feasible
I0530 01:22:51.476805       1 wrap.go:47] GET /healthz: (80.343µs) 200 [kube-probe/1.15+ 127.0.0.1:35074]
I0530 01:23:01.477563       1 wrap.go:47] GET /healthz: (99.897µs) 200 [kube-probe/1.15+ 127.0.0.1:35122]
I0530 01:23:11.478585       1 wrap.go:47] GET /healthz: (71.536µs) 200 [kube-probe/1.15+ 127.0.0.1:35156]
I0530 01:23:14.823871       1 reflector.go:384] k8s.io/client-go/informers/factory.go:133: Watch close - *v1beta1.PodDisruptionBudget total 0 items received
I0530 01:23:21.476589       1 wrap.go:47] GET /healthz: (73.241µs) 200 [kube-probe/1.15+ 127.0.0.1:35194]
I0530 01:23:31.476324       1 wrap.go:47] GET /healthz: (71.277µs) 200 [kube-probe/1.15+ 127.0.0.1:35228]
I0530 01:23:37.818922       1 reflector.go:384] k8s.io/client-go/informers/factory.go:133: Watch close - *v1.StatefulSet total 0 items received
I0530 01:23:41.478446       1 wrap.go:47] GET /healthz: (90.088µs) 200 [kube-probe/1.15+ 127.0.0.1:35262]
I0530 01:23:51.476757       1 wrap.go:47] GET /healthz: (66.857µs) 200 [kube-probe/1.15+ 127.0.0.1:35296]
I0530 01:24:01.483683       1 wrap.go:47] GET /healthz: (79.413µs) 200 [kube-probe/1.15+ 127.0.0.1:35344]
I0530 01:24:09.340112       1 scheduling_queue.go:895] About to try and schedule pod configmap-8050/pod-configmaps-bb2d7920-afa9-48ff-916f-e8b0db6bf685
I0530 01:24:09.340125       1 scheduler.go:454] Attempting to schedule pod: configmap-8050/pod-configmaps-bb2d7920-afa9-48ff-916f-e8b0db6bf685
I0530 01:24:09.340503       1 scheduler_binder.go:255] AssumePodVolumes for pod "configmap-8050/pod-configmaps-bb2d7920-afa9-48ff-916f-e8b0db6bf685", node "e2e-test-peterhornyack-windows-node-group-9q9v"
I0530 01:24:09.340515       1 scheduler_binder.go:265] AssumePodVolumes for pod "configmap-8050/pod-configmaps-bb2d7920-afa9-48ff-916f-e8b0db6bf685", node "e2e-test-peterhornyack-windows-node-group-9q9v": all PVCs bound and nothing to do
I0530 01:24:09.340570       1 factory.go:734] Attempting to bind pod-configmaps-bb2d7920-afa9-48ff-916f-e8b0db6bf685 to e2e-test-peterhornyack-windows-node-group-9q9v
I0530 01:24:09.346204       1 scheduler.go:575] pod configmap-8050/pod-configmaps-bb2d7920-afa9-48ff-916f-e8b0db6bf685 is bound successfully on node e2e-test-peterhornyack-windows-node-group-9q9v, 6 nodes evaluated, 3 nodes were found feasible
I0530 01:24:11.476909       1 wrap.go:47] GET /healthz: (79.823µs) 200 [kube-probe/1.15+ 127.0.0.1:35378]
I0530 01:24:21.476851       1 wrap.go:47] GET /healthz: (54.416µs) 200 [kube-probe/1.15+ 127.0.0.1:35414]
I0530 01:24:23.760419       1 scheduling_queue.go:895] About to try and schedule pod projected-6253/pod-projected-configmaps-d6e2178e-f908-47f7-ab7b-f10cb53b60f9
I0530 01:24:23.760431       1 scheduler.go:454] Attempting to schedule pod: projected-6253/pod-projected-configmaps-d6e2178e-f908-47f7-ab7b-f10cb53b60f9
I0530 01:24:23.762118       1 scheduler_binder.go:255] AssumePodVolumes for pod "projected-6253/pod-projected-configmaps-d6e2178e-f908-47f7-ab7b-f10cb53b60f9", node "e2e-test-peterhornyack-windows-node-group-9q9v"
I0530 01:24:23.762145       1 scheduler_binder.go:265] AssumePodVolumes for pod "projected-6253/pod-projected-configmaps-d6e2178e-f908-47f7-ab7b-f10cb53b60f9", node "e2e-test-peterhornyack-windows-node-group-9q9v": all PVCs bound and nothing to do
I0530 01:24:23.762188       1 factory.go:734] Attempting to bind pod-projected-configmaps-d6e2178e-f908-47f7-ab7b-f10cb53b60f9 to e2e-test-peterhornyack-windows-node-group-9q9v
I0530 01:24:23.767708       1 scheduler.go:575] pod projected-6253/pod-projected-configmaps-d6e2178e-f908-47f7-ab7b-f10cb53b60f9 is bound successfully on node e2e-test-peterhornyack-windows-node-group-9q9v, 6 nodes evaluated, 3 nodes were found feasible
I0530 01:24:31.476485       1 wrap.go:47] GET /healthz: (81.449µs) 200 [kube-probe/1.15+ 127.0.0.1:35448]
I0530 01:24:38.140548       1 scheduling_queue.go:895] About to try and schedule pod security-context-test-1480/busybox-readonly-false-0ef2ff97-4141-42fd-a34f-47d6fd8f7d5f
I0530 01:24:38.140562       1 scheduler.go:454] Attempting to schedule pod: security-context-test-1480/busybox-readonly-false-0ef2ff97-4141-42fd-a34f-47d6fd8f7d5f
I0530 01:24:38.140822       1 scheduler_binder.go:255] AssumePodVolumes for pod "security-context-test-1480/busybox-readonly-false-0ef2ff97-4141-42fd-a34f-47d6fd8f7d5f", node "e2e-test-peterhornyack-windows-node-group-jpxd"
I0530 01:24:38.140833       1 scheduler_binder.go:265] AssumePodVolumes for pod "security-context-test-1480/busybox-readonly-false-0ef2ff97-4141-42fd-a34f-47d6fd8f7d5f", node "e2e-test-peterhornyack-windows-node-group-jpxd": all PVCs bound and nothing to do
I0530 01:24:38.140881       1 factory.go:734] Attempting to bind busybox-readonly-false-0ef2ff97-4141-42fd-a34f-47d6fd8f7d5f to e2e-test-peterhornyack-windows-node-group-jpxd
I0530 01:24:38.150251       1 scheduler.go:575] pod security-context-test-1480/busybox-readonly-false-0ef2ff97-4141-42fd-a34f-47d6fd8f7d5f is bound successfully on node e2e-test-peterhornyack-windows-node-group-jpxd, 6 nodes evaluated, 3 nodes were found feasible
I0530 01:24:41.476892       1 wrap.go:47] GET /healthz: (73.224µs) 200 [kube-probe/1.15+ 127.0.0.1:35482]
I0530 01:24:51.477027       1 wrap.go:47] GET /healthz: (82.342µs) 200 [kube-probe/1.15+ 127.0.0.1:35516]
I0530 01:25:01.477951       1 wrap.go:47] GET /healthz: (77.381µs) 200 [kube-probe/1.15+ 127.0.0.1:35564]
I0530 01:25:01.807606       1 reflector.go:384] k8s.io/client-go/informers/factory.go:133: Watch close - *v1.StorageClass total 0 items received
I0530 01:25:03.129891       1 scheduling_queue.go:895] About to try and schedule pod kubelet-test-9136/bin-false6d8a242c-531d-4eb8-a85f-87a87601f233
I0530 01:25:03.129904       1 scheduler.go:454] Attempting to schedule pod: kubelet-test-9136/bin-false6d8a242c-531d-4eb8-a85f-87a87601f233
I0530 01:25:03.130382       1 scheduler_binder.go:255] AssumePodVolumes for pod "kubelet-test-9136/bin-false6d8a242c-531d-4eb8-a85f-87a87601f233", node "e2e-test-peterhornyack-windows-node-group-9q9v"
I0530 01:25:03.130399       1 scheduler_binder.go:265] AssumePodVolumes for pod "kubelet-test-9136/bin-false6d8a242c-531d-4eb8-a85f-87a87601f233", node "e2e-test-peterhornyack-windows-node-group-9q9v": all PVCs bound and nothing to do
I0530 01:25:03.130477       1 factory.go:734] Attempting to bind bin-false6d8a242c-531d-4eb8-a85f-87a87601f233 to e2e-test-peterhornyack-windows-node-group-9q9v
I0530 01:25:03.137626       1 scheduler.go:575] pod kubelet-test-9136/bin-false6d8a242c-531d-4eb8-a85f-87a87601f233 is bound successfully on node e2e-test-peterhornyack-windows-node-group-9q9v, 6 nodes evaluated, 3 nodes were found feasible
I0530 01:25:11.337512       1 scheduling_queue.go:895] About to try and schedule pod secrets-208/pod-secrets-d2128228-862a-4e52-8183-1c1b39efa9db
I0530 01:25:11.337530       1 scheduler.go:454] Attempting to schedule pod: secrets-208/pod-secrets-d2128228-862a-4e52-8183-1c1b39efa9db
I0530 01:25:11.337868       1 scheduler_binder.go:255] AssumePodVolumes for pod "secrets-208/pod-secrets-d2128228-862a-4e52-8183-1c1b39efa9db", node "e2e-test-peterhornyack-windows-node-group-jpxd"
I0530 01:25:11.337879       1 scheduler_binder.go:265] AssumePodVolumes for pod "secrets-208/pod-secrets-d2128228-862a-4e52-8183-1c1b39efa9db", node "e2e-test-peterhornyack-windows-node-group-jpxd": all PVCs bound and nothing to do
I0530 01:25:11.337931       1 factory.go:734] Attempting to bind pod-secrets-d2128228-862a-4e52-8183-1c1b39efa9db to e2e-test-peterhornyack-windows-node-group-jpxd
I0530 01:25:11.342591       1 scheduler.go:575] pod secrets-208/pod-secrets-d2128228-862a-4e52-8183-1c1b39efa9db is bound successfully on node e2e-test-peterhornyack-windows-node-group-jpxd, 6 nodes evaluated, 3 nodes were found feasible
I0530 01:25:11.476544       1 wrap.go:47] GET /healthz: (86.295µs) 200 [kube-probe/1.15+ 127.0.0.1:35600]
I0530 01:25:21.476874       1 wrap.go:47] GET /healthz: (63.717µs) 200 [kube-probe/1.15+ 127.0.0.1:35636]
I0530 01:25:31.476605       1 wrap.go:47] GET /healthz: (70.164µs) 200 [kube-probe/1.15+ 127.0.0.1:35670]
I0530 01:25:33.871865       1 scheduling_queue.go:895] About to try and schedule pod downward-api-5777/downwardapi-volume-53e02ba5-fbab-484a-b6fb-3dd006a6ff27
I0530 01:25:33.871878       1 scheduler.go:454] Attempting to schedule pod: downward-api-5777/downwardapi-volume-53e02ba5-fbab-484a-b6fb-3dd006a6ff27
I0530 01:25:33.872193       1 scheduler_binder.go:255] AssumePodVolumes for pod "downward-api-5777/downwardapi-volume-53e02ba5-fbab-484a-b6fb-3dd006a6ff27", node "e2e-test-peterhornyack-windows-node-group-9q9v"
I0530 01:25:33.872204       1 scheduler_binder.go:265] AssumePodVolumes for pod "downward-api-5777/downwardapi-volume-53e02ba5-fbab-484a-b6fb-3dd006a6ff27", node "e2e-test-peterhornyack-windows-node-group-9q9v": all PVCs bound and nothing to do
I0530 01:25:33.872256       1 factory.go:734] Attempting to bind downwardapi-volume-53e02ba5-fbab-484a-b6fb-3dd006a6ff27 to e2e-test-peterhornyack-windows-node-group-9q9v
I0530 01:25:33.878652       1 scheduler.go:575] pod downward-api-5777/downwardapi-volume-53e02ba5-fbab-484a-b6fb-3dd006a6ff27 is bound successfully on node e2e-test-peterhornyack-windows-node-group-9q9v, 6 nodes evaluated, 3 nodes were found feasible
I0530 01:25:41.476509       1 wrap.go:47] GET /healthz: (88.63µs) 200 [kube-probe/1.15+ 127.0.0.1:35704]
I0530 01:25:48.213349       1 scheduling_queue.go:895] About to try and schedule pod dns-7660/dns-test-a2d867b5-2d07-41c3-89db-b5776fd04ad2
I0530 01:25:48.213382       1 scheduler.go:454] Attempting to schedule pod: dns-7660/dns-test-a2d867b5-2d07-41c3-89db-b5776fd04ad2
I0530 01:25:48.215505       1 scheduler_binder.go:255] AssumePodVolumes for pod "dns-7660/dns-test-a2d867b5-2d07-41c3-89db-b5776fd04ad2", node "e2e-test-peterhornyack-windows-node-group-jpxd"
I0530 01:25:48.215522       1 scheduler_binder.go:265] AssumePodVolumes for pod "dns-7660/dns-test-a2d867b5-2d07-41c3-89db-b5776fd04ad2", node "e2e-test-peterhornyack-windows-node-group-jpxd": all PVCs bound and nothing to do
I0530 01:25:48.215576       1 factory.go:734] Attempting to bind dns-test-a2d867b5-2d07-41c3-89db-b5776fd04ad2 to e2e-test-peterhornyack-windows-node-group-jpxd
I0530 01:25:48.221880       1 scheduler.go:575] pod dns-7660/dns-test-a2d867b5-2d07-41c3-89db-b5776fd04ad2 is bound successfully on node e2e-test-peterhornyack-windows-node-group-jpxd, 6 nodes evaluated, 3 nodes were found feasible
I0530 01:25:51.476957       1 wrap.go:47] GET /healthz: (51.458µs) 200 [kube-probe/1.15+ 127.0.0.1:35736]
I0530 01:25:55.831452       1 reflector.go:384] k8s.io/client-go/informers/factory.go:133: Watch close - *v1.ReplicaSet total 0 items received
I0530 01:26:01.476814       1 wrap.go:47] GET /healthz: (75.45µs) 200 [kube-probe/1.15+ 127.0.0.1:35786]
I0530 01:26:11.477819       1 wrap.go:47] GET /healthz: (81.661µs) 200 [kube-probe/1.15+ 127.0.0.1:35822]
I0530 01:26:14.693816       1 scheduling_queue.go:895] About to try and schedule pod var-expansion-6944/var-expansion-9b778d94-283b-495c-ae9e-784c9bed6ba3
I0530 01:26:14.693829       1 scheduler.go:454] Attempting to schedule pod: var-expansion-6944/var-expansion-9b778d94-283b-495c-ae9e-784c9bed6ba3
I0530 01:26:14.694265       1 scheduler_binder.go:255] AssumePodVolumes for pod "var-expansion-6944/var-expansion-9b778d94-283b-495c-ae9e-784c9bed6ba3", node "e2e-test-peterhornyack-windows-node-group-1vjk"
I0530 01:26:14.694275       1 scheduler_binder.go:265] AssumePodVolumes for pod "var-expansion-6944/var-expansion-9b778d94-283b-495c-ae9e-784c9bed6ba3", node "e2e-test-peterhornyack-windows-node-group-1vjk": all PVCs bound and nothing to do
I0530 01:26:14.694329       1 factory.go:734] Attempting to bind var-expansion-9b778d94-283b-495c-ae9e-784c9bed6ba3 to e2e-test-peterhornyack-windows-node-group-1vjk
I0530 01:26:14.702313       1 scheduler.go:575] pod var-expansion-6944/var-expansion-9b778d94-283b-495c-ae9e-784c9bed6ba3 is bound successfully on node e2e-test-peterhornyack-windows-node-group-1vjk, 6 nodes evaluated, 3 nodes were found feasible
I0530 01:26:21.476602       1 wrap.go:47] GET /healthz: (90.928µs) 200 [kube-probe/1.15+ 127.0.0.1:35862]
I0530 01:26:29.134083       1 scheduling_queue.go:895] About to try and schedule pod secrets-7539/pod-configmaps-ab9c535a-b17f-4aaf-a9b4-290055144bc9
I0530 01:26:29.134096       1 scheduler.go:454] Attempting to schedule pod: secrets-7539/pod-configmaps-ab9c535a-b17f-4aaf-a9b4-290055144bc9
I0530 01:26:29.134358       1 scheduler_binder.go:255] AssumePodVolumes for pod "secrets-7539/pod-configmaps-ab9c535a-b17f-4aaf-a9b4-290055144bc9", node "e2e-test-peterhornyack-windows-node-group-jpxd"
I0530 01:26:29.134367       1 scheduler_binder.go:265] AssumePodVolumes for pod "secrets-7539/pod-configmaps-ab9c535a-b17f-4aaf-a9b4-290055144bc9", node "e2e-test-peterhornyack-windows-node-group-jpxd": all PVCs bound and nothing to do
I0530 01:26:29.134477       1 factory.go:734] Attempting to bind pod-configmaps-ab9c535a-b17f-4aaf-a9b4-290055144bc9 to e2e-test-peterhornyack-windows-node-group-jpxd
I0530 01:26:29.140381       1 scheduler.go:575] pod secrets-7539/pod-configmaps-ab9c535a-b17f-4aaf-a9b4-290055144bc9 is bound successfully on node e2e-test-peterhornyack-windows-node-group-jpxd, 6 nodes evaluated, 3 nodes were found feasible
I0530 01:26:31.476575       1 wrap.go:47] GET /healthz: (92.16µs) 200 [kube-probe/1.15+ 127.0.0.1:35896]
I0530 01:26:41.476846       1 wrap.go:47] GET /healthz: (66.299µs) 200 [kube-probe/1.15+ 127.0.0.1:35930]
I0530 01:26:51.476832       1 wrap.go:47] GET /healthz: (61.437µs) 200 [kube-probe/1.15+ 127.0.0.1:35962]
I0530 01:27:01.476880       1 wrap.go:47] GET /healthz: (79.811µs) 200 [kube-probe/1.15+ 127.0.0.1:36010]
I0530 01:27:02.835516       1 reflector.go:384] k8s.io/client-go/informers/factory.go:133: Watch close - *v1.PersistentVolume total 0 items received
I0530 01:27:11.476615       1 wrap.go:47] GET /healthz: (83.737µs) 200 [kube-probe/1.15+ 127.0.0.1:36044]
I0530 01:27:21.476847       1 wrap.go:47] GET /healthz: (49.71µs) 200 [kube-probe/1.15+ 127.0.0.1:36080]
I0530 01:27:31.477058       1 wrap.go:47] GET /healthz: (53.47µs) 200 [kube-probe/1.15+ 127.0.0.1:36116]
I0530 01:27:41.476751       1 wrap.go:47] GET /healthz: (76.797µs) 200 [kube-probe/1.15+ 127.0.0.1:36152]
I0530 01:27:51.476831       1 wrap.go:47] GET /healthz: (128.33µs) 200 [kube-probe/1.15+ 127.0.0.1:36184]
I0530 01:28:01.477001       1 wrap.go:47] GET /healthz: (83.536µs) 200 [kube-probe/1.15+ 127.0.0.1:36232]
I0530 01:28:11.476575       1 wrap.go:47] GET /healthz: (86.516µs) 200 [kube-probe/1.15+ 127.0.0.1:36266]
I0530 01:28:17.842827       1 reflector.go:384] cmd/kube-scheduler/app/server.go:223: Watch close - *v1.Pod total 86 items received
I0530 01:28:21.476547       1 wrap.go:47] GET /healthz: (88.941µs) 200 [kube-probe/1.15+ 127.0.0.1:36302]
I0530 01:28:23.788831       1 reflector.go:384] k8s.io/client-go/informers/factory.go:133: Watch close - *v1.Node total 61 items received
I0530 01:28:24.844810       1 reflector.go:384] k8s.io/client-go/informers/factory.go:133: Watch close - *v1.PersistentVolumeClaim total 0 items received
I0530 01:28:31.477020       1 wrap.go:47] GET /healthz: (79µs) 200 [kube-probe/1.15+ 127.0.0.1:36336]
I0530 01:28:33.815833       1 reflector.go:384] k8s.io/client-go/informers/factory.go:133: Watch close - *v1.Service total 0 items received
I0530 01:28:41.476650       1 wrap.go:47] GET /healthz: (81.972µs) 200 [kube-probe/1.15+ 127.0.0.1:36372]
I0530 01:28:51.476626       1 wrap.go:47] GET /healthz: (73.386µs) 200 [kube-probe/1.15+ 127.0.0.1:36404]
I0530 01:29:01.486409       1 wrap.go:47] GET /healthz: (47.679µs) 200 [kube-probe/1.15+ 127.0.0.1:36452]
I0530 01:29:11.483682       1 wrap.go:47] GET /healthz: (81.81µs) 200 [kube-probe/1.15+ 127.0.0.1:36488]
I0530 01:29:21.476751       1 wrap.go:47] GET /healthz: (107.121µs) 200 [kube-probe/1.15+ 127.0.0.1:36524]
I0530 01:29:31.476590       1 wrap.go:47] GET /healthz: (60.827µs) 200 [kube-probe/1.15+ 127.0.0.1:36558]
I0530 01:29:41.476696       1 wrap.go:47] GET /healthz: (71.244µs) 200 [kube-probe/1.15+ 127.0.0.1:36592]
I0530 01:29:51.476542       1 wrap.go:47] GET /healthz: (78.996µs) 200 [kube-probe/1.15+ 127.0.0.1:36626]
I0530 01:30:01.477239       1 wrap.go:47] GET /healthz: (80.216µs) 200 [kube-probe/1.15+ 127.0.0.1:36674]
I0530 01:30:11.480859       1 wrap.go:47] GET /healthz: (75.44µs) 200 [kube-probe/1.15+ 127.0.0.1:36708]
I0530 01:30:17.933616       1 scheduling_queue.go:895] About to try and schedule pod pods-8527/pod-update-82c8f952-8b60-4daa-bb7a-62973920d456
I0530 01:30:17.933648       1 scheduler.go:454] Attempting to schedule pod: pods-8527/pod-update-82c8f952-8b60-4daa-bb7a-62973920d456
I0530 01:30:17.933955       1 scheduler_binder.go:255] AssumePodVolumes for pod "pods-8527/pod-update-82c8f952-8b60-4daa-bb7a-62973920d456", node "e2e-test-peterhornyack-windows-node-group-9q9v"
I0530 01:30:17.933965       1 scheduler_binder.go:265] AssumePodVolumes for pod "pods-8527/pod-update-82c8f952-8b60-4daa-bb7a-62973920d456", node "e2e-test-peterhornyack-windows-node-group-9q9v": all PVCs bound and nothing to do
I0530 01:30:17.935731       1 factory.go:734] Attempting to bind pod-update-82c8f952-8b60-4daa-bb7a-62973920d456 to e2e-test-peterhornyack-windows-node-group-9q9v
I0530 01:30:17.944706       1 scheduler.go:575] pod pods-8527/pod-update-82c8f952-8b60-4daa-bb7a-62973920d456 is bound successfully on node e2e-test-peterhornyack-windows-node-group-9q9v, 6 nodes evaluated, 3 nodes were found feasible
I0530 01:30:21.476581       1 wrap.go:47] GET /healthz: (62.272µs) 200 [kube-probe/1.15+ 127.0.0.1:36744]
I0530 01:30:31.476718       1 wrap.go:47] GET /healthz: (104.809µs) 200 [kube-probe/1.15+ 127.0.0.1:36778]
I0530 01:30:33.829822       1 reflector.go:384] k8s.io/client-go/informers/factory.go:133: Watch close - *v1beta1.PodDisruptionBudget total 0 items received
I0530 01:30:41.476943       1 wrap.go:47] GET /healthz: (76.507µs) 200 [kube-probe/1.15+ 127.0.0.1:36814]
I0530 01:30:51.476922       1 wrap.go:47] GET /healthz: (73.903µs) 200 [kube-probe/1.15+ 127.0.0.1:36846]
I0530 01:30:59.809727       1 reflector.go:384] k8s.io/client-go/informers/factory.go:133: Watch close - *v1.StorageClass total 0 items received
I0530 01:31:01.476709       1 wrap.go:47] GET /healthz: (84.073µs) 200 [kube-probe/1.15+ 127.0.0.1:36896]
I0530 01:31:08.820973       1 reflector.go:384] k8s.io/client-go/informers/factory.go:133: Watch close - *v1.StatefulSet total 0 items received
I0530 01:31:11.477244       1 wrap.go:47] GET /healthz: (59.508µs) 200 [kube-probe/1.15+ 127.0.0.1:36930]
I0530 01:31:17.833757       1 reflector.go:384] k8s.io/client-go/informers/factory.go:133: Watch close - *v1.ReplicaSet total 0 items received
I0530 01:31:21.476769       1 wrap.go:47] GET /healthz: (77.768µs) 200 [kube-probe/1.15+ 127.0.0.1:36972]
I0530 01:31:30.938660       1 scheduling_queue.go:895] About to try and schedule pod configmap-3076/pod-configmaps-22761ffc-3a59-4225-a342-8fca568a835e
I0530 01:31:30.938775       1 scheduler.go:454] Attempting to schedule pod: configmap-3076/pod-configmaps-22761ffc-3a59-4225-a342-8fca568a835e
I0530 01:31:30.939125       1 scheduler_binder.go:255] AssumePodVolumes for pod "configmap-3076/pod-configmaps-22761ffc-3a59-4225-a342-8fca568a835e", node "e2e-test-peterhornyack-windows-node-group-9q9v"
I0530 01:31:30.939580       1 scheduler_binder.go:265] AssumePodVolumes for pod "configmap-3076/pod-configmaps-22761ffc-3a59-4225-a342-8fca568a835e", node "e2e-test-peterhornyack-windows-node-group-9q9v": all PVCs bound and nothing to do
I0530 01:31:30.939702       1 factory.go:734] Attempting to bind pod-configmaps-22761ffc-3a59-4225-a342-8fca568a835e to e2e-test-peterhornyack-windows-node-group-9q9v
I0530 01:31:30.947769       1 scheduler.go:575] pod configmap-3076/pod-configmaps-22761ffc-3a59-4225-a342-8fca568a835e is bound successfully on node e2e-test-peterhornyack-windows-node-group-9q9v, 6 nodes evaluated, 2 nodes were found feasible
I0530 01:31:31.477051       1 wrap.go:47] GET /healthz: (75.254µs) 200 [kube-probe/1.15+ 127.0.0.1:37006]
I0530 01:31:36.799060       1 reflector.go:384] k8s.io/client-go/informers/factory.go:133: Watch close - *v1.ReplicationController total 0 items received
I0530 01:31:41.476766       1 wrap.go:47] GET /healthz: (50.93µs) 200 [kube-probe/1.15+ 127.0.0.1:37040]
I0530 01:31:51.476683       1 wrap.go:47] GET /healthz: (80.112µs) 200 [kube-probe/1.15+ 127.0.0.1:37072]
I0530 01:32:01.476567       1 wrap.go:47] GET /healthz: (98.649µs) 200 [kube-probe/1.15+ 127.0.0.1:37120]
I0530 01:32:11.476533       1 wrap.go:47] GET /healthz: (94.399µs) 200 [kube-probe/1.15+ 127.0.0.1:37158]
I0530 01:32:21.476719       1 wrap.go:47] GET /healthz: (75.786µs) 200 [kube-probe/1.15+ 127.0.0.1:37196]
I0530 01:32:31.478227       1 wrap.go:47] GET /healthz: (128.787µs) 200 [kube-probe/1.15+ 127.0.0.1:37230]
I0530 01:32:31.837919       1 reflector.go:384] k8s.io/client-go/informers/factory.go:133: Watch close - *v1.PersistentVolume total 0 items received
I0530 01:32:41.477829       1 wrap.go:47] GET /healthz: (64.636µs) 200 [kube-probe/1.15+ 127.0.0.1:37264]
I0530 01:32:51.476676       1 wrap.go:47] GET /healthz: (70.195µs) 200 [kube-probe/1.15+ 127.0.0.1:37296]
I0530 01:33:01.476776       1 wrap.go:47] GET /healthz: (173.673µs) 200 [kube-probe/1.15+ 127.0.0.1:37344]
I0530 01:33:11.476535       1 wrap.go:47] GET /healthz: (79.883µs) 200 [kube-probe/1.15+ 127.0.0.1:37382]
I0530 01:33:21.476646       1 wrap.go:47] GET /healthz: (51.083µs) 200 [kube-probe/1.15+ 127.0.0.1:37422]
I0530 01:33:23.410412       1 scheduling_queue.go:895] About to try and schedule pod replication-controller-217/pod-adoption
I0530 01:33:23.410436       1 scheduler.go:454] Attempting to schedule pod: replication-controller-217/pod-adoption
I0530 01:33:23.411159       1 scheduler_binder.go:255] AssumePodVolumes for pod "replication-controller-217/pod-adoption", node "e2e-test-peterhornyack-windows-node-group-jpxd"
I0530 01:33:23.411173       1 scheduler_binder.go:265] AssumePodVolumes for pod "replication-controller-217/pod-adoption", node "e2e-test-peterhornyack-windows-node-group-jpxd": all PVCs bound and nothing to do
I0530 01:33:23.411240       1 factory.go:734] Attempting to bind pod-adoption to e2e-test-peterhornyack-windows-node-group-jpxd
I0530 01:33:23.417607       1 scheduler.go:575] pod replication-controller-217/pod-adoption is bound successfully on node e2e-test-peterhornyack-windows-node-group-jpxd, 6 nodes evaluated, 3 nodes were found feasible
I0530 01:33:31.476601       1 wrap.go:47] GET /healthz: (64.239µs) 200 [kube-probe/1.15+ 127.0.0.1:37456]
I0530 01:33:41.476664       1 wrap.go:47] GET /healthz: (52.667µs) 200 [kube-probe/1.15+ 127.0.0.1:37492]
I0530 01:33:51.477226       1 wrap.go:47] GET /healthz: (79.55µs) 200 [kube-probe/1.15+ 127.0.0.1:37524]
I0530 01:34:01.477778       1 wrap.go:47] GET /healthz: (50.446µs) 200 [kube-probe/1.15+ 127.0.0.1:37572]
I0530 01:34:11.476593       1 wrap.go:47] GET /healthz: (77.27µs) 200 [kube-probe/1.15+ 127.0.0.1:37606]
I0530 01:34:21.476598       1 wrap.go:47] GET /healthz: (73.59µs) 200 [kube-probe/1.15+ 127.0.0.1:37642]
I0530 01:34:31.476761       1 wrap.go:47] GET /healthz: (49.136µs) 200 [kube-probe/1.15+ 127.0.0.1:37678]
I0530 01:34:41.476655       1 wrap.go:47] GET /healthz: (77.145µs) 200 [kube-probe/1.15+ 127.0.0.1:37712]
I0530 01:34:48.791064       1 reflector.go:384] k8s.io/client-go/informers/factory.go:133: Watch close - *v1.Node total 60 items received
I0530 01:34:51.476898       1 wrap.go:47] GET /healthz: (74.094µs) 200 [kube-probe/1.15+ 127.0.0.1:37744]
I0530 01:35:01.476576       1 wrap.go:47] GET /healthz: (65.495µs) 200 [kube-probe/1.15+ 127.0.0.1:37934]
I0530 01:35:10.844963       1 reflector.go:384] cmd/kube-scheduler/app/server.go:223: Watch close - *v1.Pod total 20 items received
I0530 01:35:11.478011       1 wrap.go:47] GET /healthz: (57.993µs) 200 [kube-probe/1.15+ 127.0.0.1:37972]
I0530 01:35:21.476526       1 wrap.go:47] GET /healthz: (75.286µs) 200 [kube-probe/1.15+ 127.0.0.1:38010]
I0530 01:35:31.476596       1 wrap.go:47] GET /healthz: (72.545µs) 200 [kube-probe/1.15+ 127.0.0.1:38044]
I0530 01:35:41.476776       1 wrap.go:47] GET /healthz: (65.125µs) 200 [kube-probe/1.15+ 127.0.0.1:38080]
I0530 01:35:51.476596       1 wrap.go:47] GET /healthz: (72.91µs) 200 [kube-probe/1.15+ 127.0.0.1:38112]
I0530 01:36:01.476727       1 wrap.go:47] GET /healthz: (56.785µs) 200 [kube-probe/1.15+ 127.0.0.1:38160]
I0530 01:36:03.819254       1 reflector.go:384] k8s.io/client-go/informers/factory.go:133: Watch close - *v1.Service total 0 items received
I0530 01:36:11.476888       1 wrap.go:47] GET /healthz: (64.604µs) 200 [kube-probe/1.15+ 127.0.0.1:38194]
I0530 01:36:21.476677       1 wrap.go:47] GET /healthz: (78.31µs) 200 [kube-probe/1.15+ 127.0.0.1:38230]
I0530 01:36:21.823104       1 reflector.go:384] k8s.io/client-go/informers/factory.go:133: Watch close - *v1.StatefulSet total 0 items received
I0530 01:36:31.476589       1 wrap.go:47] GET /healthz: (64.753µs) 200 [kube-probe/1.15+ 127.0.0.1:38266]
I0530 01:36:41.476601       1 wrap.go:47] GET /healthz: (87.188µs) 200 [kube-probe/1.15+ 127.0.0.1:38300]
I0530 01:36:51.476799       1 wrap.go:47] GET /healthz: (49.497µs) 200 [kube-probe/1.15+ 127.0.0.1:38332]
I0530 01:36:57.835745       1 reflector.go:384] k8s.io/client-go/informers/factory.go:133: Watch close - *v1.ReplicaSet total 0 items received
I0530 01:37:01.476767       1 wrap.go:47] GET /healthz: (60.795µs) 200 [kube-probe/1.15+ 127.0.0.1:38382]
I0530 01:37:11.476640       1 wrap.go:47] GET /healthz: (75.049µs) 200 [kube-probe/1.15+ 127.0.0.1:38416]
I0530 01:37:20.831893       1 reflector.go:384] k8s.io/client-go/informers/factory.go:133: Watch close - *v1beta1.PodDisruptionBudget total 0 items received
I0530 01:37:21.476982       1 wrap.go:47] GET /healthz: (76.371µs) 200 [kube-probe/1.15+ 127.0.0.1:38454]
I0530 01:37:31.476752       1 wrap.go:47] GET /healthz: (69.652µs) 200 [kube-probe/1.15+ 127.0.0.1:38488]
I0530 01:37:41.476703       1 wrap.go:47] GET /healthz: (61.529µs) 200 [kube-probe/1.15+ 127.0.0.1:38522]
I0530 01:37:51.477018       1 wrap.go:47] GET /healthz: (122.67µs) 200 [kube-probe/1.15+ 127.0.0.1:38554]
I0530 01:38:01.476570       1 wrap.go:47] GET /healthz: (109.756µs) 200 [kube-probe/1.15+ 127.0.0.1:38604]
I0530 01:38:08.847084       1 reflector.go:384] k8s.io/client-go/informers/factory.go:133: Watch close - *v1.PersistentVolumeClaim total 0 items received
I0530 01:38:11.476735       1 wrap.go:47] GET /healthz: (120.641µs) 200 [kube-probe/1.15+ 127.0.0.1:38640]
I0530 01:38:11.811903       1 reflector.go:384] k8s.io/client-go/informers/factory.go:133: Watch close - *v1.StorageClass total 0 items received
I0530 01:38:21.476843       1 wrap.go:47] GET /healthz: (80.454µs) 200 [kube-probe/1.15+ 127.0.0.1:38676]
I0530 01:38:31.476619       1 wrap.go:47] GET /healthz: (77.887µs) 200 [kube-probe/1.15+ 127.0.0.1:38710]
I0530 01:38:41.476825       1 wrap.go:47] GET /healthz: (64.036µs) 200 [kube-probe/1.15+ 127.0.0.1:38744]
I0530 01:38:51.476483       1 wrap.go:47] GET /healthz: (51.08µs) 200 [kube-probe/1.15+ 127.0.0.1:38776]
I0530 01:38:53.840169       1 reflector.go:384] k8s.io/client-go/informers/factory.go:133: Watch close - *v1.PersistentVolume total 0 items received
I0530 01:39:01.476809       1 wrap.go:47] GET /healthz: (56.077µs) 200 [kube-probe/1.15+ 127.0.0.1:38824]
I0530 01:39:11.476665       1 wrap.go:47] GET /healthz: (72.454µs) 200 [kube-probe/1.15+ 127.0.0.1:38858]
I0530 01:39:21.477425       1 wrap.go:47] GET /healthz: (68.976µs) 200 [kube-probe/1.15+ 127.0.0.1:38896]
I0530 01:39:31.476705       1 wrap.go:47] GET /healthz: (118.741µs) 200 [kube-probe/1.15+ 127.0.0.1:38934]
I0530 01:39:41.476797       1 wrap.go:47] GET /healthz: (85.201µs) 200 [kube-probe/1.15+ 127.0.0.1:38968]
I0530 01:39:51.476760       1 wrap.go:47] GET /healthz: (109.052µs) 200 [kube-probe/1.15+ 127.0.0.1:39000]
I0530 01:40:01.477510       1 wrap.go:47] GET /healthz: (97.486µs) 200 [kube-probe/1.15+ 127.0.0.1:39048]
I0530 01:40:11.476869       1 wrap.go:47] GET /healthz: (75.662µs) 200 [kube-probe/1.15+ 127.0.0.1:39082]
I0530 01:40:17.847029       1 reflector.go:384] cmd/kube-scheduler/app/server.go:223: Watch close - *v1.Pod total 3 items received
I0530 01:40:21.476766       1 wrap.go:47] GET /healthz: (72.331µs) 200 [kube-probe/1.15+ 127.0.0.1:39122]
I0530 01:40:31.476799       1 wrap.go:47] GET /healthz: (52.508µs) 200 [kube-probe/1.15+ 127.0.0.1:39158]
I0530 01:40:41.476526       1 wrap.go:47] GET /healthz: (72.875µs) 200 [kube-probe/1.15+ 127.0.0.1:39192]
I0530 01:40:51.476768       1 wrap.go:47] GET /healthz: (62.735µs) 200 [kube-probe/1.15+ 127.0.0.1:39224]
I0530 01:41:01.476879       1 wrap.go:47] GET /healthz: (77.54µs) 200 [kube-probe/1.15+ 127.0.0.1:39274]
I0530 01:41:11.476658       1 wrap.go:47] GET /healthz: (63.473µs) 200 [kube-probe/1.15+ 127.0.0.1:39308]
I0530 01:41:21.477008       1 wrap.go:47] GET /healthz: (76.189µs) 200 [kube-probe/1.15+ 127.0.0.1:39346]
I0530 01:41:31.476508       1 wrap.go:47] GET /healthz: (101.104µs) 200 [kube-probe/1.15+ 127.0.0.1:39380]
I0530 01:41:35.800896       1 reflector.go:384] k8s.io/client-go/informers/factory.go:133: Watch close - *v1.ReplicationController total 4 items received
I0530 01:41:41.476794       1 wrap.go:47] GET /healthz: (54.425µs) 200 [kube-probe/1.15+ 127.0.0.1:39416]
I0530 01:41:51.476942       1 wrap.go:47] GET /healthz: (66.434µs) 200 [kube-probe/1.15+ 127.0.0.1:39452]
I0530 01:42:01.476508       1 wrap.go:47] GET /healthz: (98.273µs) 200 [kube-probe/1.15+ 127.0.0.1:39500]
I0530 01:42:11.476711       1 wrap.go:47] GET /healthz: (73.373µs) 200 [kube-probe/1.15+ 127.0.0.1:39534]
I0530 01:42:21.476748       1 wrap.go:47] GET /healthz: (76.106µs) 200 [kube-probe/1.15+ 127.0.0.1:39572]
I0530 01:42:31.476835       1 wrap.go:47] GET /healthz: (61.72µs) 200 [kube-probe/1.15+ 127.0.0.1:39606]
I0530 01:42:41.476667       1 wrap.go:47] GET /healthz: (71.991µs) 200 [kube-probe/1.15+ 127.0.0.1:39640]
I0530 01:42:51.476613       1 wrap.go:47] GET /healthz: (82.499µs) 200 [kube-probe/1.15+ 127.0.0.1:39674]
I0530 01:43:01.476763       1 wrap.go:47] GET /healthz: (80.439µs) 200 [kube-probe/1.15+ 127.0.0.1:39722]
I0530 01:43:03.834127       1 reflector.go:384] k8s.io/client-go/informers/factory.go:133: Watch close - *v1beta1.PodDisruptionBudget total 0 items received
I0530 01:43:11.476401       1 wrap.go:47] GET /healthz: (57.981µs) 200 [kube-probe/1.15+ 127.0.0.1:39756]
I0530 01:43:21.476644       1 wrap.go:47] GET /healthz: (77.946µs) 200 [kube-probe/1.15+ 127.0.0.1:39794]
I0530 01:43:24.822874       1 reflector.go:384] k8s.io/client-go/informers/factory.go:133: Watch close - *v1.Service total 0 items received
I0530 01:43:31.476794       1 wrap.go:47] GET /healthz: (85.308µs) 200 [kube-probe/1.15+ 127.0.0.1:39828]
I0530 01:43:41.477533       1 wrap.go:47] GET /healthz: (105.257µs) 200 [kube-probe/1.15+ 127.0.0.1:39862]
I0530 01:43:51.479283       1 wrap.go:47] GET /healthz: (57.416µs) 200 [kube-probe/1.15+ 127.0.0.1:39896]
I0530 01:43:55.825297       1 reflector.go:384] k8s.io/client-go/informers/factory.go:133: Watch close - *v1.StatefulSet total 0 items received
I0530 01:44:01.476430       1 wrap.go:47] GET /healthz: (61.588µs) 200 [kube-probe/1.15+ 127.0.0.1:39946]
I0530 01:44:11.476646       1 wrap.go:47] GET /healthz: (67.345µs) 200 [kube-probe/1.15+ 127.0.0.1:39980]
I0530 01:44:21.476627       1 wrap.go:47] GET /healthz: (71.601µs) 200 [kube-probe/1.15+ 127.0.0.1:40016]
I0530 01:44:31.475962       1 wrap.go:47] GET /healthz: (76.077µs) 200 [kube-probe/1.15+ 127.0.0.1:40050]
I0530 01:44:41.476429       1 wrap.go:47] GET /healthz: (96.73µs) 200 [kube-probe/1.15+ 127.0.0.1:40084]
I0530 01:44:46.793423       1 reflector.go:384] k8s.io/client-go/informers/factory.go:133: Watch close - *v1.Node total 107 items received
I0530 01:44:51.476842       1 wrap.go:47] GET /healthz: (60.392µs) 200 [kube-probe/1.15+ 127.0.0.1:40118]
I0530 01:45:01.476682       1 wrap.go:47] GET /healthz: (72.789µs) 200 [kube-probe/1.15+ 127.0.0.1:40162]
I0530 01:45:11.476636       1 wrap.go:47] GET /healthz: (68.361µs) 200 [kube-probe/1.15+ 127.0.0.1:40202]
I0530 01:45:20.814035       1 reflector.go:384] k8s.io/client-go/informers/factory.go:133: Watch close - *v1.StorageClass total 0 items received
I0530 01:45:21.476793       1 wrap.go:47] GET /healthz: (75.187µs) 200 [kube-probe/1.15+ 127.0.0.1:40244]
I0530 01:45:31.476705       1 wrap.go:47] GET /healthz: (72.478µs) 200 [kube-probe/1.15+ 127.0.0.1:40278]
I0530 01:45:35.842332       1 reflector.go:384] k8s.io/client-go/informers/factory.go:133: Watch close - *v1.PersistentVolume total 0 items received
I0530 01:45:41.476827       1 wrap.go:47] GET /healthz: (71.355µs) 200 [kube-probe/1.15+ 127.0.0.1:40312]
I0530 01:45:51.477405       1 wrap.go:47] GET /healthz: (77.427µs) 200 [kube-probe/1.15+ 127.0.0.1:40344]
I0530 01:46:00.837821       1 reflector.go:384] k8s.io/client-go/informers/factory.go:133: Watch close - *v1.ReplicaSet total 0 items received
I0530 01:46:01.476890       1 wrap.go:47] GET /healthz: (76.945µs) 200 [kube-probe/1.15+ 127.0.0.1:40392]
I0530 01:46:11.477748       1 wrap.go:47] GET /healthz: (78.006µs) 200 [kube-probe/1.15+ 127.0.0.1:40426]
I0530 01:46:15.787809       1 scheduling_queue.go:895] About to try and schedule pod downward-api-1603/downward-api-6535621f-5cf4-4ed9-84aa-56dcaad1764a
I0530 01:46:15.787833       1 scheduler.go:454] Attempting to schedule pod: downward-api-1603/downward-api-6535621f-5cf4-4ed9-84aa-56dcaad1764a
I0530 01:46:15.788187       1 scheduler_binder.go:255] AssumePodVolumes for pod "downward-api-1603/downward-api-6535621f-5cf4-4ed9-84aa-56dcaad1764a", node "e2e-test-peterhornyack-windows-node-group-9q9v"
I0530 01:46:15.788197       1 scheduler_binder.go:265] AssumePodVolumes for pod "downward-api-1603/downward-api-6535621f-5cf4-4ed9-84aa-56dcaad1764a", node "e2e-test-peterhornyack-windows-node-group-9q9v": all PVCs bound and nothing to do
I0530 01:46:15.788252       1 factory.go:734] Attempting to bind downward-api-6535621f-5cf4-4ed9-84aa-56dcaad1764a to e2e-test-peterhornyack-windows-node-group-9q9v
I0530 01:46:15.794095       1 scheduler.go:575] pod downward-api-1603/downward-api-6535621f-5cf4-4ed9-84aa-56dcaad1764a is bound successfully on node e2e-test-peterhornyack-windows-node-group-9q9v, 6 nodes evaluated, 3 nodes were found feasible
I0530 01:46:21.476636       1 wrap.go:47] GET /healthz: (72.495µs) 200 [kube-probe/1.15+ 127.0.0.1:40464]
I0530 01:46:31.476567       1 wrap.go:47] GET /healthz: (73.52µs) 200 [kube-probe/1.15+ 127.0.0.1:40498]
I0530 01:46:32.221308       1 scheduling_queue.go:895] About to try and schedule pod deployment-8098/nginx-deployment-56d49d846f-hmthd
I0530 01:46:32.221319       1 scheduler.go:454] Attempting to schedule pod: deployment-8098/nginx-deployment-56d49d846f-hmthd
I0530 01:46:32.221732       1 scheduler_binder.go:255] AssumePodVolumes for pod "deployment-8098/nginx-deployment-56d49d846f-hmthd", node "e2e-test-peterhornyack-windows-node-group-1vjk"
I0530 01:46:32.221743       1 scheduler_binder.go:265] AssumePodVolumes for pod "deployment-8098/nginx-deployment-56d49d846f-hmthd", node "e2e-test-peterhornyack-windows-node-group-1vjk": all PVCs bound and nothing to do
I0530 01:46:32.221784       1 factory.go:734] Attempting to bind nginx-deployment-56d49d846f-hmthd to e2e-test-peterhornyack-windows-node-group-1vjk
I0530 01:46:32.231872       1 scheduler.go:575] pod deployment-8098/nginx-deployment-56d49d846f-hmthd is bound successfully on node e2e-test-peterhornyack-windows-node-group-1vjk, 6 nodes evaluated, 3 nodes were found feasible
I0530 01:46:32.247296       1 scheduling_queue.go:895] About to try and schedule pod deployment-8098/nginx-deployment-56d49d846f-q5bj2
I0530 01:46:32.247319       1 scheduler.go:454] Attempting to schedule pod: deployment-8098/nginx-deployment-56d49d846f-q5bj2
I0530 01:46:32.247892       1 scheduler_binder.go:255] AssumePodVolumes for pod "deployment-8098/nginx-deployment-56d49d846f-q5bj2", node "e2e-test-peterhornyack-windows-node-group-jpxd"
I0530 01:46:32.247904       1 scheduler_binder.go:265] AssumePodVolumes for pod "deployment-8098/nginx-deployment-56d49d846f-q5bj2", node "e2e-test-peterhornyack-windows-node-group-jpxd": all PVCs bound and nothing to do
I0530 01:46:32.251259       1 factory.go:734] Attempting to bind nginx-deployment-56d49d846f-q5bj2 to e2e-test-peterhornyack-windows-node-group-jpxd
I0530 01:46:32.251594       1 scheduling_queue.go:895] About to try and schedule pod deployment-8098/nginx-deployment-56d49d846f-c9bfj
I0530 01:46:32.251600       1 scheduler.go:454] Attempting to schedule pod: deployment-8098/nginx-deployment-56d49d846f-c9bfj
I0530 01:46:32.251835       1 scheduler_binder.go:255] AssumePodVolumes for pod "deployment-8098/nginx-deployment-56d49d846f-c9bfj", node "e2e-test-peterhornyack-windows-node-group-9q9v"
I0530 01:46:32.251844       1 scheduler_binder.go:265] AssumePodVolumes for pod "deployment-8098/nginx-deployment-56d49d846f-c9bfj", node "e2e-test-peterhornyack-windows-node-group-9q9v": all PVCs bound and nothing to do
I0530 01:46:32.251890       1 factory.go:734] Attempting to bind nginx-deployment-56d49d846f-c9bfj to e2e-test-peterhornyack-windows-node-group-9q9v
I0530 01:46:32.264186       1 scheduling_queue.go:895] About to try and schedule pod deployment-8098/nginx-deployment-56d49d846f-jntv7
I0530 01:46:32.264197       1 scheduler.go:454] Attempting to schedule pod: deployment-8098/nginx-deployment-56d49d846f-jntv7
I0530 01:46:32.264532       1 scheduler_binder.go:255] AssumePodVolumes for pod "deployment-8098/nginx-deployment-56d49d846f-jntv7", node "e2e-test-peterhornyack-windows-node-group-1vjk"
I0530 01:46:32.264555       1 scheduler_binder.go:265] AssumePodVolumes for pod "deployment-8098/nginx-deployment-56d49d846f-jntv7", node "e2e-test-peterhornyack-windows-node-group-1vjk": all PVCs bound and nothing to do
I0530 01:46:32.264584       1 factory.go:734] Attempting to bind nginx-deployment-56d49d846f-jntv7 to e2e-test-peterhornyack-windows-node-group-1vjk
I0530 01:46:32.276903       1 scheduler.go:575] pod deployment-8098/nginx-deployment-56d49d846f-q5bj2 is bound successfully on node e2e-test-peterhornyack-windows-node-group-jpxd, 6 nodes evaluated, 3 nodes were found feasible
I0530 01:46:32.279782       1 scheduler.go:575] pod deployment-8098/nginx-deployment-56d49d846f-c9bfj is bound successfully on node e2e-test-peterhornyack-windows-node-group-9q9v, 6 nodes evaluated, 3 nodes were found feasible
I0530 01:46:32.280374       1 scheduling_queue.go:895] About to try and schedule pod deployment-8098/nginx-deployment-56d49d846f-nbwf5
I0530 01:46:32.280382       1 scheduler.go:454] Attempting to schedule pod: deployment-8098/nginx-deployment-56d49d846f-nbwf5
I0530 01:46:32.280759       1 scheduler_binder.go:255] AssumePodVolumes for pod "deployment-8098/nginx-deployment-56d49d846f-nbwf5", node "e2e-test-peterhornyack-windows-node-group-9q9v"
I0530 01:46:32.284765       1 scheduler_binder.go:265] AssumePodVolumes for pod "deployment-8098/nginx-deployment-56d49d846f-nbwf5", node "e2e-test-peterhornyack-windows-node-group-9q9v": all PVCs bound and nothing to do
I0530 01:46:32.284839       1 factory.go:734] Attempting to bind nginx-deployment-56d49d846f-nbwf5 to e2e-test-peterhornyack-windows-node-group-9q9v
I0530 01:46:32.285078       1 scheduling_queue.go:895] About to try and schedule pod deployment-8098/nginx-deployment-56d49d846f-9v69d
I0530 01:46:32.285083       1 scheduler.go:454] Attempting to schedule pod: deployment-8098/nginx-deployment-56d49d846f-9v69d
I0530 01:46:32.287607       1 scheduler_binder.go:255] AssumePodVolumes for pod "deployment-8098/nginx-deployment-56d49d846f-9v69d", node "e2e-test-peterhornyack-windows-node-group-jpxd"
I0530 01:46:32.287618       1 scheduler_binder.go:265] AssumePodVolumes for pod "deployment-8098/nginx-deployment-56d49d846f-9v69d", node "e2e-test-peterhornyack-windows-node-group-jpxd": all PVCs bound and nothing to do
I0530 01:46:32.287665       1 factory.go:734] Attempting to bind nginx-deployment-56d49d846f-9v69d to e2e-test-peterhornyack-windows-node-group-jpxd
I0530 01:46:32.290229       1 scheduler.go:575] pod deployment-8098/nginx-deployment-56d49d846f-jntv7 is bound successfully on node e2e-test-peterhornyack-windows-node-group-1vjk, 6 nodes evaluated, 3 nodes were found feasible
I0530 01:46:32.293670       1 scheduling_queue.go:895] About to try and schedule pod deployment-8098/nginx-deployment-56d49d846f-mv9sq
I0530 01:46:32.293678       1 scheduler.go:454] Attempting to schedule pod: deployment-8098/nginx-deployment-56d49d846f-mv9sq
I0530 01:46:32.293903       1 scheduler_binder.go:255] AssumePodVolumes for pod "deployment-8098/nginx-deployment-56d49d846f-mv9sq", node "e2e-test-peterhornyack-windows-node-group-1vjk"
I0530 01:46:32.293911       1 scheduler_binder.go:265] AssumePodVolumes for pod "deployment-8098/nginx-deployment-56d49d846f-mv9sq", node "e2e-test-peterhornyack-windows-node-group-1vjk": all PVCs bound and nothing to do
I0530 01:46:32.293932       1 factory.go:734] Attempting to bind nginx-deployment-56d49d846f-mv9sq to e2e-test-peterhornyack-windows-node-group-1vjk
I0530 01:46:32.315521       1 scheduler.go:575] pod deployment-8098/nginx-deployment-56d49d846f-nbwf5 is bound successfully on node e2e-test-peterhornyack-windows-node-group-9q9v, 6 nodes evaluated, 3 nodes were found feasible
I0530 01:46:32.315899       1 scheduler.go:575] pod deployment-8098/nginx-deployment-56d49d846f-9v69d is bound successfully on node e2e-test-peterhornyack-windows-node-group-jpxd, 6 nodes evaluated, 3 nodes were found feasible
I0530 01:46:32.315987       1 scheduling_queue.go:895] About to try and schedule pod deployment-8098/nginx-deployment-56d49d846f-6wqpl
I0530 01:46:32.315993       1 scheduler.go:454] Attempting to schedule pod: deployment-8098/nginx-deployment-56d49d846f-6wqpl
I0530 01:46:32.316290       1 scheduler_binder.go:255] AssumePodVolumes for pod "deployment-8098/nginx-deployment-56d49d846f-6wqpl", node "e2e-test-peterhornyack-windows-node-group-jpxd"
I0530 01:46:32.316299       1 scheduler_binder.go:265] AssumePodVolumes for pod "deployment-8098/nginx-deployment-56d49d846f-6wqpl", node "e2e-test-peterhornyack-windows-node-group-jpxd": all PVCs bound and nothing to do
I0530 01:46:32.316798       1 factory.go:734] Attempting to bind nginx-deployment-56d49d846f-6wqpl to e2e-test-peterhornyack-windows-node-group-jpxd
I0530 01:46:32.323806       1 scheduler.go:575] pod deployment-8098/nginx-deployment-56d49d846f-mv9sq is bound successfully on node e2e-test-peterhornyack-windows-node-group-1vjk, 6 nodes evaluated, 3 nodes were found feasible
I0530 01:46:32.323851       1 scheduling_queue.go:895] About to try and schedule pod deployment-8098/nginx-deployment-56d49d846f-qgzps
I0530 01:46:32.323856       1 scheduler.go:454] Attempting to schedule pod: deployment-8098/nginx-deployment-56d49d846f-qgzps
I0530 01:46:32.324165       1 scheduler_binder.go:255] AssumePodVolumes for pod "deployment-8098/nginx-deployment-56d49d846f-qgzps", node "e2e-test-peterhornyack-windows-node-group-9q9v"
I0530 01:46:32.324174       1 scheduler_binder.go:265] AssumePodVolumes for pod "deployment-8098/nginx-deployment-56d49d846f-qgzps", node "e2e-test-peterhornyack-windows-node-group-9q9v": all PVCs bound and nothing to do
I0530 01:46:32.324211       1 factory.go:734] Attempting to bind nginx-deployment-56d49d846f-qgzps to e2e-test-peterhornyack-windows-node-group-9q9v
I0530 01:46:32.326949       1 scheduling_queue.go:895] About to try and schedule pod deployment-8098/nginx-deployment-56d49d846f-rsjpt
I0530 01:46:32.326957       1 scheduler.go:454] Attempting to schedule pod: deployment-8098/nginx-deployment-56d49d846f-rsjpt
I0530 01:46:32.327172       1 scheduler_binder.go:255] AssumePodVolumes for pod "deployment-8098/nginx-deployment-56d49d846f-rsjpt", node "e2e-test-peterhornyack-windows-node-group-1vjk"
I0530 01:46:32.327181       1 scheduler_binder.go:265] AssumePodVolumes for pod "deployment-8098/nginx-deployment-56d49d846f-rsjpt", node "e2e-test-peterhornyack-windows-node-group-1vjk": all PVCs bound and nothing to do
I0530 01:46:32.327203       1 factory.go:734] Attempting to bind nginx-deployment-56d49d846f-rsjpt to e2e-test-peterhornyack-windows-node-group-1vjk
I0530 01:46:32.375177       1 scheduler.go:575] pod deployment-8098/nginx-deployment-56d49d846f-qgzps is bound successfully on node e2e-test-peterhornyack-windows-node-group-9q9v, 6 nodes evaluated, 3 nodes were found feasible
I0530 01:46:32.375218       1 scheduler.go:575] pod deployment-8098/nginx-deployment-56d49d846f-6wqpl is bound successfully on node e2e-test-peterhornyack-windows-node-group-jpxd, 6 nodes evaluated, 3 nodes were found feasible
I0530 01:46:32.375263       1 scheduler.go:575] pod deployment-8098/nginx-deployment-56d49d846f-rsjpt is bound successfully on node e2e-test-peterhornyack-windows-node-group-1vjk, 6 nodes evaluated, 3 nodes were found feasible
I0530 01:46:41.476749       1 wrap.go:47] GET /healthz: (67.124µs) 200 [kube-probe/1.15+ 127.0.0.1:40532]
I0530 01:46:43.849522       1 reflector.go:384] k8s.io/client-go/informers/factory.go:133: Watch close - *v1.PersistentVolumeClaim total 0 items received
I0530 01:46:51.476670       1 wrap.go:47] GET /healthz: (75.795µs) 200 [kube-probe/1.15+ 127.0.0.1:40566]
I0530 01:47:01.476581       1 wrap.go:47] GET /healthz: (63.362µs) 200 [kube-probe/1.15+ 127.0.0.1:40614]
I0530 01:47:08.849086       1 reflector.go:384] cmd/kube-scheduler/app/server.go:223: Watch close - *v1.Pod total 41 items received
I0530 01:47:11.476633       1 wrap.go:47] GET /healthz: (125.774µs) 200 [kube-probe/1.15+ 127.0.0.1:40648]
I0530 01:47:21.476627       1 wrap.go:47] GET /healthz: (72.019µs) 200 [kube-probe/1.15+ 127.0.0.1:40684]
I0530 01:47:31.476678       1 wrap.go:47] GET /healthz: (61.595µs) 200 [kube-probe/1.15+ 127.0.0.1:40722]
I0530 01:47:41.476625       1 wrap.go:47] GET /healthz: (49.977µs) 200 [kube-probe/1.15+ 127.0.0.1:40756]
I0530 01:47:51.476737       1 wrap.go:47] GET /healthz: (68.587µs) 200 [kube-probe/1.15+ 127.0.0.1:40788]
I0530 01:48:01.476950       1 wrap.go:47] GET /healthz: (76.12µs) 200 [kube-probe/1.15+ 127.0.0.1:40836]
I0530 01:48:11.477171       1 wrap.go:47] GET /healthz: (73.26µs) 200 [kube-probe/1.15+ 127.0.0.1:40870]
I0530 01:48:21.477598       1 wrap.go:47] GET /healthz: (106.958µs) 200 [kube-probe/1.15+ 127.0.0.1:40910]
I0530 01:48:31.477597       1 wrap.go:47] GET /healthz: (62.406µs) 200 [kube-probe/1.15+ 127.0.0.1:40946]
I0530 01:48:41.476856       1 wrap.go:47] GET /healthz: (65.274µs) 200 [kube-probe/1.15+ 127.0.0.1:40980]
I0530 01:48:51.477039       1 wrap.go:47] GET /healthz: (67.134µs) 200 [kube-probe/1.15+ 127.0.0.1:41014]
I0530 01:49:01.476724       1 wrap.go:47] GET /healthz: (62.884µs) 200 [kube-probe/1.15+ 127.0.0.1:41062]
I0530 01:49:11.481308       1 wrap.go:47] GET /healthz: (76.304µs) 200 [kube-probe/1.15+ 127.0.0.1:41096]
I0530 01:49:21.476759       1 wrap.go:47] GET /healthz: (80.309µs) 200 [kube-probe/1.15+ 127.0.0.1:41132]
I0530 01:49:28.804380       1 reflector.go:384] k8s.io/client-go/informers/factory.go:133: Watch close - *v1.ReplicationController total 0 items received
I0530 01:49:31.476870       1 wrap.go:47] GET /healthz: (65.778µs) 200 [kube-probe/1.15+ 127.0.0.1:41166]
I0530 01:49:41.476796       1 wrap.go:47] GET /healthz: (73.56µs) 200 [kube-probe/1.15+ 127.0.0.1:41202]
I0530 01:49:51.476752       1 wrap.go:47] GET /healthz: (74.863µs) 200 [kube-probe/1.15+ 127.0.0.1:41234]
I0530 01:50:01.476977       1 wrap.go:47] GET /healthz: (66.696µs) 200 [kube-probe/1.15+ 127.0.0.1:41284]
I0530 01:50:11.476910       1 wrap.go:47] GET /healthz: (67.987µs) 200 [kube-probe/1.15+ 127.0.0.1:41318]
I0530 01:50:16.662737       1 scheduling_queue.go:895] About to try and schedule pod deployment-8098/nginx-deployment-5f9595f595-qs4tw
I0530 01:50:16.662749       1 scheduler.go:454] Attempting to schedule pod: deployment-8098/nginx-deployment-5f9595f595-qs4tw
I0530 01:50:16.663139       1 scheduler_binder.go:255] AssumePodVolumes for pod "deployment-8098/nginx-deployment-5f9595f595-qs4tw", node "e2e-test-peterhornyack-windows-node-group-9q9v"
I0530 01:50:16.663161       1 scheduler_binder.go:265] AssumePodVolumes for pod "deployment-8098/nginx-deployment-5f9595f595-qs4tw", node "e2e-test-peterhornyack-windows-node-group-9q9v": all PVCs bound and nothing to do
I0530 01:50:16.663198       1 factory.go:734] Attempting to bind nginx-deployment-5f9595f595-qs4tw to e2e-test-peterhornyack-windows-node-group-9q9v
I0530 01:50:16.676335       1 scheduler.go:575] pod deployment-8098/nginx-deployment-5f9595f595-qs4tw is bound successfully on node e2e-test-peterhornyack-windows-node-group-9q9v, 6 nodes evaluated, 3 nodes were found feasible
I0530 01:50:16.688507       1 scheduling_queue.go:895] About to try and schedule pod deployment-8098/nginx-deployment-5f9595f595-88xwg
I0530 01:50:16.688518       1 scheduler.go:454] Attempting to schedule pod: deployment-8098/nginx-deployment-5f9595f595-88xwg
I0530 01:50:16.689696       1 scheduler_binder.go:255] AssumePodVolumes for pod "deployment-8098/nginx-deployment-5f9595f595-88xwg", node "e2e-test-peterhornyack-windows-node-group-jpxd"
I0530 01:50:16.689708       1 scheduler_binder.go:265] AssumePodVolumes for pod "deployment-8098/nginx-deployment-5f9595f595-88xwg", node "e2e-test-peterhornyack-windows-node-group-jpxd": all PVCs bound and nothing to do
I0530 01:50:16.689754       1 factory.go:734] Attempting to bind nginx-deployment-5f9595f595-88xwg to e2e-test-peterhornyack-windows-node-group-jpxd
I0530 01:50:16.694954       1 scheduling_queue.go:895] About to try and schedule pod deployment-8098/nginx-deployment-5f9595f595-rqzfh
I0530 01:50:16.694965       1 scheduler.go:454] Attempting to schedule pod: deployment-8098/nginx-deployment-5f9595f595-rqzfh
I0530 01:50:16.697492       1 scheduler_binder.go:255] AssumePodVolumes for pod "deployment-8098/nginx-deployment-5f9595f595-rqzfh", node "e2e-test-peterhornyack-windows-node-group-1vjk"
I0530 01:50:16.697505       1 scheduler_binder.go:265] AssumePodVolumes for pod "deployment-8098/nginx-deployment-5f9595f595-rqzfh", node "e2e-test-peterhornyack-windows-node-group-1vjk": all PVCs bound and nothing to do
I0530 01:50:16.697538       1 factory.go:734] Attempting to bind nginx-deployment-5f9595f595-rqzfh to e2e-test-peterhornyack-windows-node-group-1vjk
I0530 01:50:16.732331       1 scheduler.go:575] pod deployment-8098/nginx-deployment-5f9595f595-rqzfh is bound successfully on node e2e-test-peterhornyack-windows-node-group-1vjk, 6 nodes evaluated, 3 nodes were found feasible
I0530 01:50:16.737587       1 scheduler.go:575] pod deployment-8098/nginx-deployment-5f9595f595-88xwg is bound successfully on node e2e-test-peterhornyack-windows-node-group-jpxd, 6 nodes evaluated, 3 nodes were found feasible
I0530 01:50:16.827794       1 scheduling_queue.go:895] About to try and schedule pod deployment-8098/nginx-deployment-5f9595f595-s22bz
I0530 01:50:16.827807       1 scheduler.go:454] Attempting to schedule pod: deployment-8098/nginx-deployment-5f9595f595-s22bz
I0530 01:50:16.828176       1 scheduler_binder.go:255] AssumePodVolumes for pod "deployment-8098/nginx-deployment-5f9595f595-s22bz", node "e2e-test-peterhornyack-windows-node-group-jpxd"
I0530 01:50:16.828186       1 scheduler_binder.go:265] AssumePodVolumes for pod "deployment-8098/nginx-deployment-5f9595f595-s22bz", node "e2e-test-peterhornyack-windows-node-group-jpxd": all PVCs bound and nothing to do
I0530 01:50:16.828225       1 factory.go:734] Attempting to bind nginx-deployment-5f9595f595-s22bz to e2e-test-peterhornyack-windows-node-group-jpxd
I0530 01:50:16.839722       1 scheduler.go:575] pod deployment-8098/nginx-deployment-5f9595f595-s22bz is bound successfully on node e2e-test-peterhornyack-windows-node-group-jpxd, 6 nodes evaluated, 3 nodes were found feasible
I0530 01:50:16.841878       1 scheduling_queue.go:895] About to try and schedule pod deployment-8098/nginx-deployment-5f9595f595-bvgkr
I0530 01:50:16.841887       1 scheduler.go:454] Attempting to schedule pod: deployment-8098/nginx-deployment-5f9595f595-bvgkr
I0530 01:50:16.845069       1 scheduler_binder.go:255] AssumePodVolumes for pod "deployment-8098/nginx-deployment-5f9595f595-bvgkr", node "e2e-test-peterhornyack-windows-node-group-9q9v"
I0530 01:50:16.845083       1 scheduler_binder.go:265] AssumePodVolumes for pod "deployment-8098/nginx-deployment-5f9595f595-bvgkr", node "e2e-test-peterhornyack-windows-node-group-9q9v": all PVCs bound and nothing to do
I0530 01:50:16.846772       1 factory.go:734] Attempting to bind nginx-deployment-5f9595f595-bvgkr to e2e-test-peterhornyack-windows-node-group-9q9v
I0530 01:50:16.865266       1 scheduler.go:575] pod deployment-8098/nginx-deployment-5f9595f595-bvgkr is bound successfully on node e2e-test-peterhornyack-windows-node-group-9q9v, 6 nodes evaluated, 3 nodes were found feasible
I0530 01:50:19.190218       1 scheduling_queue.go:895] About to try and schedule pod deployment-8098/nginx-deployment-56d49d846f-rk69f
I0530 01:50:19.190246       1 scheduler.go:454] Attempting to schedule pod: deployment-8098/nginx-deployment-56d49d846f-rk69f
I0530 01:50:19.190785       1 scheduler_binder.go:255] AssumePodVolumes for pod "deployment-8098/nginx-deployment-56d49d846f-rk69f", node "e2e-test-peterhornyack-windows-node-group-jpxd"
I0530 01:50:19.190797       1 scheduler_binder.go:265] AssumePodVolumes for pod "deployment-8098/nginx-deployment-56d49d846f-rk69f", node "e2e-test-peterhornyack-windows-node-group-jpxd": all PVCs bound and nothing to do
I0530 01:50:19.193572       1 factory.go:734] Attempting to bind nginx-deployment-56d49d846f-rk69f to e2e-test-peterhornyack-windows-node-group-jpxd
I0530 01:50:19.213736       1 scheduler.go:575] pod deployment-8098/nginx-deployment-56d49d846f-rk69f is bound successfully on node e2e-test-peterhornyack-windows-node-group-jpxd, 6 nodes evaluated, 3 nodes were found feasible
I0530 01:50:19.227427       1 scheduling_queue.go:895] About to try and schedule pod deployment-8098/nginx-deployment-5f9595f595-p58q7
I0530 01:50:19.227439       1 scheduler.go:454] Attempting to schedule pod: deployment-8098/nginx-deployment-5f9595f595-p58q7
I0530 01:50:19.233689       1 scheduler_binder.go:255] AssumePodVolumes for pod "deployment-8098/nginx-deployment-5f9595f595-p58q7", node "e2e-test-peterhornyack-windows-node-group-1vjk"
I0530 01:50:19.233706       1 scheduler_binder.go:265] AssumePodVolumes for pod "deployment-8098/nginx-deployment-5f9595f595-p58q7", node "e2e-test-peterhornyack-windows-node-group-1vjk": all PVCs bound and nothing to do
I0530 01:50:19.233766       1 factory.go:734] Attempting to bind nginx-deployment-5f9595f595-p58q7 to e2e-test-peterhornyack-windows-node-group-1vjk
I0530 01:50:19.234041       1 scheduling_queue.go:895] About to try and schedule pod deployment-8098/nginx-deployment-56d49d846f-vpckk
I0530 01:50:19.234047       1 scheduler.go:454] Attempting to schedule pod: deployment-8098/nginx-deployment-56d49d846f-vpckk
I0530 01:50:19.234338       1 scheduler_binder.go:255] AssumePodVolumes for pod "deployment-8098/nginx-deployment-56d49d846f-vpckk", node "e2e-test-peterhornyack-windows-node-group-jpxd"
I0530 01:50:19.234346       1 scheduler_binder.go:265] AssumePodVolumes for pod "deployment-8098/nginx-deployment-56d49d846f-vpckk", node "e2e-test-peterhornyack-windows-node-group-jpxd": all PVCs bound and nothing to do
I0530 01:50:19.234362       1 factory.go:734] Attempting to bind nginx-deployment-56d49d846f-vpckk to e2e-test-peterhornyack-windows-node-group-jpxd
I0530 01:50:19.240294       1 scheduling_queue.go:895] About to try and schedule pod deployment-8098/nginx-deployment-56d49d846f-ng7qv
I0530 01:50:19.240307       1 scheduler.go:454] Attempting to schedule pod: deployment-8098/nginx-deployment-56d49d846f-ng7qv
I0530 01:50:19.240677       1 scheduler_binder.go:255] AssumePodVolumes for pod "deployment-8098/nginx-deployment-56d49d846f-ng7qv", node "e2e-test-peterhornyack-windows-node-group-1vjk"
I0530 01:50:19.240687       1 scheduler_binder.go:265] AssumePodVolumes for pod "deployment-8098/nginx-deployment-56d49d846f-ng7qv", node "e2e-test-peterhornyack-windows-node-group-1vjk": all PVCs bound and nothing to do
I0530 01:50:19.240713       1 factory.go:734] Attempting to bind nginx-deployment-56d49d846f-ng7qv to e2e-test-peterhornyack-windows-node-group-1vjk
I0530 01:50:19.254318       1 scheduling_queue.go:895] About to try and schedule pod deployment-8098/nginx-deployment-56d49d846f-nnnwr
I0530 01:50:19.254331       1 scheduler.go:454] Attempting to schedule pod: deployment-8098/nginx-deployment-56d49d846f-nnnwr
I0530 01:50:19.256211       1 scheduler_binder.go:255] AssumePodVolumes for pod "deployment-8098/nginx-deployment-56d49d846f-nnnwr", node "e2e-test-peterhornyack-windows-node-group-jpxd"
I0530 01:50:19.256224       1 scheduler_binder.go:265] AssumePodVolumes for pod "deployment-8098/nginx-deployment-56d49d846f-nnnwr", node "e2e-test-peterhornyack-windows-node-group-jpxd": all PVCs bound and nothing to do
I0530 01:50:19.257829       1 factory.go:734] Attempting to bind nginx-deployment-56d49d846f-nnnwr to e2e-test-peterhornyack-windows-node-group-jpxd
I0530 01:50:19.263531       1 scheduler.go:575] pod deployment-8098/nginx-deployment-56d49d846f-ng7qv is bound successfully on node e2e-test-peterhornyack-windows-node-group-1vjk, 6 nodes evaluated, 3 nodes were found feasible
I0530 01:50:19.269784       1 scheduler.go:575] pod deployment-8098/nginx-deployment-5f9595f595-p58q7 is bound successfully on node e2e-test-peterhornyack-windows-node-group-1vjk, 6 nodes evaluated, 3 nodes were found feasible
I0530 01:50:19.269843       1 scheduler.go:575] pod deployment-8098/nginx-deployment-56d49d846f-vpckk is bound successfully on node e2e-test-peterhornyack-windows-node-group-jpxd, 6 nodes evaluated, 3 nodes were found feasible
I0530 01:50:19.269897       1 scheduling_queue.go:895] About to try and schedule pod deployment-8098/nginx-deployment-56d49d846f-rbz8x
I0530 01:50:19.269902       1 scheduler.go:454] Attempting to schedule pod: deployment-8098/nginx-deployment-56d49d846f-rbz8x
I0530 01:50:19.270256       1 scheduler_binder.go:255] AssumePodVolumes for pod "deployment-8098/nginx-deployment-56d49d846f-rbz8x", node "e2e-test-peterhornyack-windows-node-group-9q9v"
I0530 01:50:19.270266       1 scheduler_binder.go:265] AssumePodVolumes for pod "deployment-8098/nginx-deployment-56d49d846f-rbz8x", node "e2e-test-peterhornyack-windows-node-group-9q9v": all PVCs bound and nothing to do
I0530 01:50:19.270325       1 factory.go:734] Attempting to bind nginx-deployment-56d49d846f-rbz8x to e2e-test-peterhornyack-windows-node-group-9q9v
I0530 01:50:19.275868       1 scheduling_queue.go:895] About to try and schedule pod deployment-8098/nginx-deployment-5f9595f595-rzdlx
I0530 01:50:19.275878       1 scheduler.go:454] Attempting to schedule pod: deployment-8098/nginx-deployment-5f9595f595-rzdlx
I0530 01:50:19.276391       1 scheduler_binder.go:255] AssumePodVolumes for pod "deployment-8098/nginx-deployment-5f9595f595-rzdlx", node "e2e-test-peterhornyack-windows-node-group-9q9v"
I0530 01:50:19.276401       1 scheduler_binder.go:265] AssumePodVolumes for pod "deployment-8098/nginx-deployment-5f9595f595-rzdlx", node "e2e-test-peterhornyack-windows-node-group-9q9v": all PVCs bound and nothing to do
I0530 01:50:19.276426       1 factory.go:734] Attempting to bind nginx-deployment-5f9595f595-rzdlx to e2e-test-peterhornyack-windows-node-group-9q9v
I0530 01:50:19.282912       1 scheduling_queue.go:895] About to try and schedule pod deployment-8098/nginx-deployment-5f9595f595-jg62p
I0530 01:50:19.282921       1 scheduler.go:454] Attempting to schedule pod: deployment-8098/nginx-deployment-5f9595f595-jg62p
I0530 01:50:19.283245       1 scheduler_binder.go:255] AssumePodVolumes for pod "deployment-8098/nginx-deployment-5f9595f595-jg62p", node "e2e-test-peterhornyack-windows-node-group-1vjk"
I0530 01:50:19.283255       1 scheduler_binder.go:265] AssumePodVolumes for pod "deployment-8098/nginx-deployment-5f9595f595-jg62p", node "e2e-test-peterhornyack-windows-node-group-1vjk": all PVCs bound and nothing to do
I0530 01:50:19.283281       1 factory.go:734] Attempting to bind nginx-deployment-5f9595f595-jg62p to e2e-test-peterhornyack-windows-node-group-1vjk
I0530 01:50:19.288394       1 scheduling_queue.go:895] About to try and schedule pod deployment-8098/nginx-deployment-56d49d846f-nbjw6
I0530 01:50:19.288408       1 scheduler.go:454] Attempting to schedule pod: deployment-8098/nginx-deployment-56d49d846f-nbjw6
I0530 01:50:19.288757       1 scheduler_binder.go:255] AssumePodVolumes for pod "deployment-8098/nginx-deployment-56d49d846f-nbjw6", node "e2e-test-peterhornyack-windows-node-group-jpxd"
I0530 01:50:19.288773       1 scheduler_binder.go:265] AssumePodVolumes for pod "deployment-8098/nginx-deployment-56d49d846f-nbjw6", node "e2e-test-peterhornyack-windows-node-group-jpxd": all PVCs bound and nothing to do
I0530 01:50:19.288807       1 factory.go:734] Attempting to bind nginx-deployment-56d49d846f-nbjw6 to e2e-test-peterhornyack-windows-node-group-jpxd
I0530 01:50:19.291180       1 scheduling_queue.go:895] About to try and schedule pod deployment-8098/nginx-deployment-56d49d846f-wxrtq
I0530 01:50:19.291191       1 scheduler.go:454] Attempting to schedule pod: deployment-8098/nginx-deployment-56d49d846f-wxrtq
I0530 01:50:19.292151       1 scheduler_binder.go:255] AssumePodVolumes for pod "deployment-8098/nginx-deployment-56d49d846f-wxrtq", node "e2e-test-peterhornyack-windows-node-group-9q9v"
I0530 01:50:19.292173       1 scheduler_binder.go:265] AssumePodVolumes for pod "deployment-8098/nginx-deployment-56d49d846f-wxrtq", node "e2e-test-peterhornyack-windows-node-group-9q9v": all PVCs bound and nothing to do
I0530 01:50:19.292207       1 factory.go:734] Attempting to bind nginx-deployment-56d49d846f-wxrtq to e2e-test-peterhornyack-windows-node-group-9q9v
I0530 01:50:19.322757       1 scheduler.go:575] pod deployment-8098/nginx-deployment-56d49d846f-nnnwr is bound successfully on node e2e-test-peterhornyack-windows-node-group-jpxd, 6 nodes evaluated, 3 nodes were found feasible
I0530 01:50:19.323141       1 scheduling_queue.go:895] About to try and schedule pod deployment-8098/nginx-deployment-5f9595f595-7vch4
I0530 01:50:19.323148       1 scheduler.go:454] Attempting to schedule pod: deployment-8098/nginx-deployment-5f9595f595-7vch4
I0530 01:50:19.323563       1 scheduler_binder.go:255] AssumePodVolumes for pod "deployment-8098/nginx-deployment-5f9595f595-7vch4", node "e2e-test-peterhornyack-windows-node-group-jpxd"
I0530 01:50:19.323573       1 scheduler_binder.go:265] AssumePodVolumes for pod "deployment-8098/nginx-deployment-5f9595f595-7vch4", node "e2e-test-peterhornyack-windows-node-group-jpxd": all PVCs bound and nothing to do
I0530 01:50:19.323602       1 factory.go:734] Attempting to bind nginx-deployment-5f9595f595-7vch4 to e2e-test-peterhornyack-windows-node-group-jpxd
I0530 01:50:19.326708       1 scheduling_queue.go:895] About to try and schedule pod deployment-8098/nginx-deployment-56d49d846f-jb85c
I0530 01:50:19.326729       1 scheduler.go:454] Attempting to schedule pod: deployment-8098/nginx-deployment-56d49d846f-jb85c
I0530 01:50:19.327029       1 scheduler_binder.go:255] AssumePodVolumes for pod "deployment-8098/nginx-deployment-56d49d846f-jb85c", node "e2e-test-peterhornyack-windows-node-group-9q9v"
I0530 01:50:19.327051       1 scheduler_binder.go:265] AssumePodVolumes for pod "deployment-8098/nginx-deployment-56d49d846f-jb85c", node "e2e-test-peterhornyack-windows-node-group-9q9v": all PVCs bound and nothing to do
I0530 01:50:19.327075       1 factory.go:734] Attempting to bind nginx-deployment-56d49d846f-jb85c to e2e-test-peterhornyack-windows-node-group-9q9v
I0530 01:50:19.327259       1 scheduling_queue.go:895] About to try and schedule pod deployment-8098/nginx-deployment-5f9595f595-svtp8
I0530 01:50:19.327264       1 scheduler.go:454] Attempting to schedule pod: deployment-8098/nginx-deployment-5f9595f595-svtp8
I0530 01:50:19.336616       1 scheduler_binder.go:255] AssumePodVolumes for pod "deployment-8098/nginx-deployment-5f9595f595-svtp8", node "e2e-test-peterhornyack-windows-node-group-1vjk"
I0530 01:50:19.336633       1 scheduler_binder.go:265] AssumePodVolumes for pod "deployment-8098/nginx-deployment-5f9595f595-svtp8", node "e2e-test-peterhornyack-windows-node-group-1vjk": all PVCs bound and nothing to do
I0530 01:50:19.336699       1 factory.go:734] Attempting to bind nginx-deployment-5f9595f595-svtp8 to e2e-test-peterhornyack-windows-node-group-1vjk
I0530 01:50:19.337742       1 scheduling_queue.go:895] About to try and schedule pod deployment-8098/nginx-deployment-5f9595f595-85hs7
I0530 01:50:19.337750       1 scheduler.go:454] Attempting to schedule pod: deployment-8098/nginx-deployment-5f9595f595-85hs7
I0530 01:50:19.343096       1 scheduler_binder.go:255] AssumePodVolumes for pod "deployment-8098/nginx-deployment-5f9595f595-85hs7", node "e2e-test-peterhornyack-windows-node-group-jpxd"
I0530 01:50:19.343107       1 scheduler_binder.go:265] AssumePodVolumes for pod "deployment-8098/nginx-deployment-5f9595f595-85hs7", node "e2e-test-peterhornyack-windows-node-group-jpxd": all PVCs bound and nothing to do
I0530 01:50:19.343143       1 factory.go:734] Attempting to bind nginx-deployment-5f9595f595-85hs7 to e2e-test-peterhornyack-windows-node-group-jpxd
I0530 01:50:19.343348       1 scheduling_queue.go:895] About to try and schedule pod deployment-8098/nginx-deployment-56d49d846f-7r6nf
I0530 01:50:19.343354       1 scheduler.go:454] Attempting to schedule pod: deployment-8098/nginx-deployment-56d49d846f-7r6nf
I0530 01:50:19.343591       1 scheduler_binder.go:255] AssumePodVolumes for pod "deployment-8098/nginx-deployment-56d49d846f-7r6nf", node "e2e-test-peterhornyack-windows-node-group-1vjk"
I0530 01:50:19.343599       1 scheduler_binder.go:265] AssumePodVolumes for pod "deployment-8098/nginx-deployment-56d49d846f-7r6nf", node "e2e-test-peterhornyack-windows-node-group-1vjk": all PVCs bound and nothing to do
I0530 01:50:19.343623       1 factory.go:734] Attempting to bind nginx-deployment-56d49d846f-7r6nf to e2e-test-peterhornyack-windows-node-group-1vjk
I0530 01:50:19.343877       1 scheduler.go:575] pod deployment-8098/nginx-deployment-5f9595f595-jg62p is bound successfully on node e2e-test-peterhornyack-windows-node-group-1vjk, 6 nodes evaluated, 3 nodes were found feasible
I0530 01:50:19.354866       1 scheduling_queue.go:895] About to try and schedule pod deployment-8098/nginx-deployment-56d49d846f-gdvgw
I0530 01:50:19.354891       1 scheduler.go:454] Attempting to schedule pod: deployment-8098/nginx-deployment-56d49d846f-gdvgw
I0530 01:50:19.355240       1 scheduler_binder.go:255] AssumePodVolumes for pod "deployment-8098/nginx-deployment-56d49d846f-gdvgw", node "e2e-test-peterhornyack-windows-node-group-9q9v"
I0530 01:50:19.355249       1 scheduler_binder.go:265] AssumePodVolumes for pod "deployment-8098/nginx-deployment-56d49d846f-gdvgw", node "e2e-test-peterhornyack-windows-node-group-9q9v": all PVCs bound and nothing to do
I0530 01:50:19.355284       1 factory.go:734] Attempting to bind nginx-deployment-56d49d846f-gdvgw to e2e-test-peterhornyack-windows-node-group-9q9v
I0530 01:50:19.370064       1 scheduler.go:575] pod deployment-8098/nginx-deployment-56d49d846f-rbz8x is bound successfully on node e2e-test-peterhornyack-windows-node-group-9q9v, 6 nodes evaluated, 3 nodes were found feasible
I0530 01:50:19.377336       1 scheduler.go:575] pod deployment-8098/nginx-deployment-56d49d846f-nbjw6 is bound successfully on node e2e-test-peterhornyack-windows-node-group-jpxd, 6 nodes evaluated, 3 nodes were found feasible
I0530 01:50:19.377380       1 scheduler.go:575] pod deployment-8098/nginx-deployment-56d49d846f-wxrtq is bound successfully on node e2e-test-peterhornyack-windows-node-group-9q9v, 6 nodes evaluated, 3 nodes were found feasible
I0530 01:50:19.377415       1 scheduler.go:575] pod deployment-8098/nginx-deployment-5f9595f595-rzdlx is bound successfully on node e2e-test-peterhornyack-windows-node-group-9q9v, 6 nodes evaluated, 3 nodes were found feasible
I0530 01:50:19.388206       1 scheduling_queue.go:895] About to try and schedule pod deployment-8098/nginx-deployment-56d49d846f-cr4g7
I0530 01:50:19.388339       1 scheduler.go:454] Attempting to schedule pod: deployment-8098/nginx-deployment-56d49d846f-cr4g7
I0530 01:50:19.391043       1 scheduler_binder.go:255] AssumePodVolumes for pod "deployment-8098/nginx-deployment-56d49d846f-cr4g7", node "e2e-test-peterhornyack-windows-node-group-jpxd"
I0530 01:50:19.391063       1 scheduler_binder.go:265] AssumePodVolumes for pod "deployment-8098/nginx-deployment-56d49d846f-cr4g7", node "e2e-test-peterhornyack-windows-node-group-jpxd": all PVCs bound and nothing to do
I0530 01:50:19.391100       1 factory.go:734] Attempting to bind nginx-deployment-56d49d846f-cr4g7 to e2e-test-peterhornyack-windows-node-group-jpxd
I0530 01:50:19.394311       1 scheduling_queue.go:895] About to try and schedule pod deployment-8098/nginx-deployment-56d49d846f-478tn
I0530 01:50:19.394321       1 scheduler.go:454] Attempting to schedule pod: deployment-8098/nginx-deployment-56d49d846f-478tn
I0530 01:50:19.394943       1 scheduler_binder.go:255] AssumePodVolumes for pod "deployment-8098/nginx-deployment-56d49d846f-478tn", node "e2e-test-peterhornyack-windows-node-group-9q9v"
I0530 01:50:19.394955       1 scheduler_binder.go:265] AssumePodVolumes for pod "deployment-8098/nginx-deployment-56d49d846f-478tn", node "e2e-test-peterhornyack-windows-node-group-9q9v": all PVCs bound and nothing to do
I0530 01:50:19.394988       1 factory.go:734] Attempting to bind nginx-deployment-56d49d846f-478tn to e2e-test-peterhornyack-windows-node-group-9q9v
I0530 01:50:19.398400       1 scheduling_queue.go:895] About to try and schedule pod deployment-8098/nginx-deployment-5f9595f595-nrg2l
I0530 01:50:19.398410       1 scheduler.go:454] Attempting to schedule pod: deployment-8098/nginx-deployment-5f9595f595-nrg2l
I0530 01:50:19.398711       1 scheduler_binder.go:255] AssumePodVolumes for pod "deployment-8098/nginx-deployment-5f9595f595-nrg2l", node "e2e-test-peterhornyack-windows-node-group-1vjk"
I0530 01:50:19.398721       1 scheduler_binder.go:265] AssumePodVolumes for pod "deployment-8098/nginx-deployment-5f9595f595-nrg2l", node "e2e-test-peterhornyack-windows-node-group-1vjk": all PVCs bound and nothing to do
I0530 01:50:19.398748       1 factory.go:734] Attempting to bind nginx-deployment-5f9595f595-nrg2l to e2e-test-peterhornyack-windows-node-group-1vjk
I0530 01:50:19.417838       1 scheduler.go:575] pod deployment-8098/nginx-deployment-56d49d846f-7r6nf is bound successfully on node e2e-test-peterhornyack-windows-node-group-1vjk, 6 nodes evaluated, 3 nodes were found feasible
I0530 01:50:19.421951       1 scheduler.go:575] pod deployment-8098/nginx-deployment-5f9595f595-7vch4 is bound successfully on node e2e-test-peterhornyack-windows-node-group-jpxd, 6 nodes evaluated, 3 nodes were found feasible
I0530 01:50:19.422230       1 scheduler.go:575] pod deployment-8098/nginx-deployment-56d49d846f-jb85c is bound successfully on node e2e-test-peterhornyack-windows-node-group-9q9v, 6 nodes evaluated, 3 nodes were found feasible
I0530 01:50:19.422281       1 scheduler.go:575] pod deployment-8098/nginx-deployment-5f9595f595-svtp8 is bound successfully on node e2e-test-peterhornyack-windows-node-group-1vjk, 6 nodes evaluated, 3 nodes were found feasible
I0530 01:50:19.425560       1 scheduling_queue.go:895] About to try and schedule pod deployment-8098/nginx-deployment-5f9595f595-7sb27
I0530 01:50:19.425572       1 scheduler.go:454] Attempting to schedule pod: deployment-8098/nginx-deployment-5f9595f595-7sb27
I0530 01:50:19.429944       1 scheduler_binder.go:255] AssumePodVolumes for pod "deployment-8098/nginx-deployment-5f9595f595-7sb27", node "e2e-test-peterhornyack-windows-node-group-9q9v"
I0530 01:50:19.429971       1 scheduler_binder.go:265] AssumePodVolumes for pod "deployment-8098/nginx-deployment-5f9595f595-7sb27", node "e2e-test-peterhornyack-windows-node-group-9q9v": all PVCs bound and nothing to do
I0530 01:50:19.430014       1 factory.go:734] Attempting to bind nginx-deployment-5f9595f595-7sb27 to e2e-test-peterhornyack-windows-node-group-9q9v
I0530 01:50:19.434588       1 scheduler.go:575] pod deployment-8098/nginx-deployment-56d49d846f-gdvgw is bound successfully on node e2e-test-peterhornyack-windows-node-group-9q9v, 6 nodes evaluated, 3 nodes were found feasible
I0530 01:50:19.438346       1 scheduler.go:575] pod deployment-8098/nginx-deployment-5f9595f595-85hs7 is bound successfully on node e2e-test-peterhornyack-windows-node-group-jpxd, 6 nodes evaluated, 3 nodes were found feasible
I0530 01:50:19.463858       1 scheduler.go:575] pod deployment-8098/nginx-deployment-56d49d846f-cr4g7 is bound successfully on node e2e-test-peterhornyack-windows-node-group-jpxd, 6 nodes evaluated, 3 nodes were found feasible
I0530 01:50:19.470333       1 scheduler.go:575] pod deployment-8098/nginx-deployment-56d49d846f-478tn is bound successfully on node e2e-test-peterhornyack-windows-node-group-9q9v, 6 nodes evaluated, 3 nodes were found feasible
I0530 01:50:19.470602       1 scheduler.go:575] pod deployment-8098/nginx-deployment-5f9595f595-nrg2l is bound successfully on node e2e-test-peterhornyack-windows-node-group-1vjk, 6 nodes evaluated, 3 nodes were found feasible
I0530 01:50:19.506728       1 scheduler.go:575] pod deployment-8098/nginx-deployment-5f9595f595-7sb27 is bound successfully on node e2e-test-peterhornyack-windows-node-group-9q9v, 6 nodes evaluated, 3 nodes were found feasible
I0530 01:50:21.476792       1 wrap.go:47] GET /healthz: (93.064µs) 200 [kube-probe/1.15+ 127.0.0.1:41354]
I0530 01:50:31.477025       1 wrap.go:47] GET /healthz: (76.538µs) 200 [kube-probe/1.15+ 127.0.0.1:41388]
I0530 01:50:32.016064       1 scheduling_queue.go:895] About to try and schedule pod kubectl-876/e2e-test-nginx-pod
I0530 01:50:32.016076       1 scheduler.go:454] Attempting to schedule pod: kubectl-876/e2e-test-nginx-pod
I0530 01:50:32.017711       1 scheduler_binder.go:255] AssumePodVolumes for pod "kubectl-876/e2e-test-nginx-pod", node "e2e-test-peterhornyack-windows-node-group-9q9v"
I0530 01:50:32.017725       1 scheduler_binder.go:265] AssumePodVolumes for pod "kubectl-876/e2e-test-nginx-pod", node "e2e-test-peterhornyack-windows-node-group-9q9v": all PVCs bound and nothing to do
I0530 01:50:32.017781       1 factory.go:734] Attempting to bind e2e-test-nginx-pod to e2e-test-peterhornyack-windows-node-group-9q9v
I0530 01:50:32.025042       1 scheduler.go:575] pod kubectl-876/e2e-test-nginx-pod is bound successfully on node e2e-test-peterhornyack-windows-node-group-9q9v, 6 nodes evaluated, 3 nodes were found feasible
I0530 01:50:41.476879       1 wrap.go:47] GET /healthz: (49.72µs) 200 [kube-probe/1.15+ 127.0.0.1:41422]
I0530 01:50:51.477016       1 wrap.go:47] GET /healthz: (50.294µs) 200 [kube-probe/1.15+ 127.0.0.1:41454]
I0530 01:50:53.827589       1 reflector.go:384] k8s.io/client-go/informers/factory.go:133: Watch close - *v1.StatefulSet total 0 items received
I0530 01:50:57.816205       1 reflector.go:384] k8s.io/client-go/informers/factory.go:133: Watch close - *v1.StorageClass total 0 items received
I0530 01:51:01.476552       1 wrap.go:47] GET /healthz: (107.628µs) 200 [kube-probe/1.15+ 127.0.0.1:41502]
I0530 01:51:01.507661       1 scheduling_queue.go:895] About to try and schedule pod downward-api-9185/downwardapi-volume-a9992912-b313-4e58-81da-e7a2c0f5ecae
I0530 01:51:01.507674       1 scheduler.go:454] Attempting to schedule pod: downward-api-9185/downwardapi-volume-a9992912-b313-4e58-81da-e7a2c0f5ecae
I0530 01:51:01.508092       1 scheduler_binder.go:255] AssumePodVolumes for pod "downward-api-9185/downwardapi-volume-a9992912-b313-4e58-81da-e7a2c0f5ecae", node "e2e-test-peterhornyack-windows-node-group-9q9v"
I0530 01:51:01.508103       1 scheduler_binder.go:265] AssumePodVolumes for pod "downward-api-9185/downwardapi-volume-a9992912-b313-4e58-81da-e7a2c0f5ecae", node "e2e-test-peterhornyack-windows-node-group-9q9v": all PVCs bound and nothing to do
I0530 01:51:01.508195       1 factory.go:734] Attempting to bind downwardapi-volume-a9992912-b313-4e58-81da-e7a2c0f5ecae to e2e-test-peterhornyack-windows-node-group-9q9v
I0530 01:51:01.534699       1 scheduler.go:575] pod downward-api-9185/downwardapi-volume-a9992912-b313-4e58-81da-e7a2c0f5ecae is bound successfully on node e2e-test-peterhornyack-windows-node-group-9q9v, 6 nodes evaluated, 3 nodes were found feasible
I0530 01:51:11.476678       1 wrap.go:47] GET /healthz: (83.246µs) 200 [kube-probe/1.15+ 127.0.0.1:41540]
I0530 01:51:19.999305       1 scheduling_queue.go:895] About to try and schedule pod container-runtime-127/image-pull-testb0d00ee3-d5e0-4228-bdc6-f9f685791bc4
I0530 01:51:19.999319       1 scheduler.go:454] Attempting to schedule pod: container-runtime-127/image-pull-testb0d00ee3-d5e0-4228-bdc6-f9f685791bc4
I0530 01:51:19.999795       1 scheduler_binder.go:255] AssumePodVolumes for pod "container-runtime-127/image-pull-testb0d00ee3-d5e0-4228-bdc6-f9f685791bc4", node "e2e-test-peterhornyack-windows-node-group-jpxd"
I0530 01:51:19.999820       1 scheduler_binder.go:265] AssumePodVolumes for pod "container-runtime-127/image-pull-testb0d00ee3-d5e0-4228-bdc6-f9f685791bc4", node "e2e-test-peterhornyack-windows-node-group-jpxd": all PVCs bound and nothing to do
I0530 01:51:19.999866       1 factory.go:734] Attempting to bind image-pull-testb0d00ee3-d5e0-4228-bdc6-f9f685791bc4 to e2e-test-peterhornyack-windows-node-group-jpxd
I0530 01:51:20.005618       1 scheduler.go:575] pod container-runtime-127/image-pull-testb0d00ee3-d5e0-4228-bdc6-f9f685791bc4 is bound successfully on node e2e-test-peterhornyack-windows-node-group-jpxd, 6 nodes evaluated, 3 nodes were found feasible
I0530 01:51:21.478903       1 wrap.go:47] GET /healthz: (160.59µs) 200 [kube-probe/1.15+ 127.0.0.1:41576]
I0530 01:51:28.825904       1 reflector.go:384] k8s.io/client-go/informers/factory.go:133: Watch close - *v1.Service total 0 items received
I0530 01:51:31.476606       1 wrap.go:47] GET /healthz: (100.351µs) 200 [kube-probe/1.15+ 127.0.0.1:41612]
I0530 01:51:41.476974       1 wrap.go:47] GET /healthz: (73.524µs) 200 [kube-probe/1.15+ 127.0.0.1:41646]
I0530 01:51:51.476976       1 wrap.go:47] GET /healthz: (65.121µs) 200 [kube-probe/1.15+ 127.0.0.1:41678]
I0530 01:52:01.476640       1 wrap.go:47] GET /healthz: (80.338µs) 200 [kube-probe/1.15+ 127.0.0.1:41726]
I0530 01:52:11.477447       1 wrap.go:47] GET /healthz: (71.59µs) 200 [kube-probe/1.15+ 127.0.0.1:41760]
I0530 01:52:21.479292       1 wrap.go:47] GET /healthz: (2.347359ms) 200 [kube-probe/1.15+ 127.0.0.1:41798]
I0530 01:52:25.836643       1 reflector.go:384] k8s.io/client-go/informers/factory.go:133: Watch close - *v1beta1.PodDisruptionBudget total 0 items received
I0530 01:52:31.476690       1 wrap.go:47] GET /healthz: (74.818µs) 200 [kube-probe/1.15+ 127.0.0.1:41832]
I0530 01:52:41.476808       1 wrap.go:47] GET /healthz: (88.589µs) 200 [kube-probe/1.15+ 127.0.0.1:41870]
I0530 01:52:51.476871       1 wrap.go:47] GET /healthz: (64.859µs) 200 [kube-probe/1.15+ 127.0.0.1:41902]
I0530 01:52:56.851339       1 reflector.go:384] k8s.io/client-go/informers/factory.go:133: Watch close - *v1.PersistentVolumeClaim total 0 items received
I0530 01:53:01.476708       1 wrap.go:47] GET /healthz: (75.028µs) 200 [kube-probe/1.15+ 127.0.0.1:41950]
I0530 01:53:11.476832       1 wrap.go:47] GET /healthz: (99.341µs) 200 [kube-probe/1.15+ 127.0.0.1:41984]
I0530 01:53:18.839619       1 reflector.go:384] k8s.io/client-go/informers/factory.go:133: Watch close - *v1.ReplicaSet total 44 items received
I0530 01:53:21.476654       1 wrap.go:47] GET /healthz: (51.367µs) 200 [kube-probe/1.15+ 127.0.0.1:42020]
I0530 01:53:31.477113       1 wrap.go:47] GET /healthz: (77.78µs) 200 [kube-probe/1.15+ 127.0.0.1:42056]
I0530 01:53:41.476819       1 wrap.go:47] GET /healthz: (76.215µs) 200 [kube-probe/1.15+ 127.0.0.1:42090]
I0530 01:53:45.795530       1 reflector.go:384] k8s.io/client-go/informers/factory.go:133: Watch close - *v1.Node total 90 items received
I0530 01:53:51.476881       1 wrap.go:47] GET /healthz: (89.69µs) 200 [kube-probe/1.15+ 127.0.0.1:42122]
I0530 01:54:01.476672       1 wrap.go:47] GET /healthz: (76.35µs) 200 [kube-probe/1.15+ 127.0.0.1:42172]
I0530 01:54:11.476803       1 wrap.go:47] GET /healthz: (78.826µs) 200 [kube-probe/1.15+ 127.0.0.1:42208]
I0530 01:54:17.844406       1 reflector.go:384] k8s.io/client-go/informers/factory.go:133: Watch close - *v1.PersistentVolume total 0 items received
I0530 01:54:21.476704       1 wrap.go:47] GET /healthz: (70.352µs) 200 [kube-probe/1.15+ 127.0.0.1:42244]
I0530 01:54:31.476877       1 wrap.go:47] GET /healthz: (65.42µs) 200 [kube-probe/1.15+ 127.0.0.1:42278]
I0530 01:54:41.477445       1 wrap.go:47] GET /healthz: (116.128µs) 200 [kube-probe/1.15+ 127.0.0.1:42314]
I0530 01:54:51.476858       1 wrap.go:47] GET /healthz: (70.467µs) 200 [kube-probe/1.15+ 127.0.0.1:42346]
I0530 01:54:53.851263       1 reflector.go:384] cmd/kube-scheduler/app/server.go:223: Watch close - *v1.Pod total 168 items received
I0530 01:55:01.476624       1 wrap.go:47] GET /healthz: (72.299µs) 200 [kube-probe/1.15+ 127.0.0.1:42394]
I0530 01:55:11.476731       1 wrap.go:47] GET /healthz: (64.569µs) 200 [kube-probe/1.15+ 127.0.0.1:42428]
I0530 01:55:21.476481       1 wrap.go:47] GET /healthz: (66.633µs) 200 [kube-probe/1.15+ 127.0.0.1:42464]
I0530 01:55:31.476798       1 wrap.go:47] GET /healthz: (64.407µs) 200 [kube-probe/1.15+ 127.0.0.1:42500]
I0530 01:55:41.476613       1 wrap.go:47] GET /healthz: (60.038µs) 200 [kube-probe/1.15+ 127.0.0.1:42536]
I0530 01:55:51.476994       1 wrap.go:47] GET /healthz: (84.043µs) 200 [kube-probe/1.15+ 127.0.0.1:42570]
I0530 01:56:01.476836       1 wrap.go:47] GET /healthz: (67.821µs) 200 [kube-probe/1.15+ 127.0.0.1:42618]
I0530 01:56:07.806611       1 reflector.go:384] k8s.io/client-go/informers/factory.go:133: Watch close - *v1.ReplicationController total 0 items received
I0530 01:56:11.477222       1 wrap.go:47] GET /healthz: (50.155µs) 200 [kube-probe/1.15+ 127.0.0.1:42652]
I0530 01:56:21.476796       1 wrap.go:47] GET /healthz: (62.82µs) 200 [kube-probe/1.15+ 127.0.0.1:42688]
I0530 01:56:27.291643       1 scheduling_queue.go:895] About to try and schedule pod init-container-1524/pod-init-f588ade4-e4ba-4968-9669-f67463de99d0
I0530 01:56:27.291656       1 scheduler.go:454] Attempting to schedule pod: init-container-1524/pod-init-f588ade4-e4ba-4968-9669-f67463de99d0
I0530 01:56:27.292566       1 scheduler_binder.go:255] AssumePodVolumes for pod "init-container-1524/pod-init-f588ade4-e4ba-4968-9669-f67463de99d0", node "e2e-test-peterhornyack-windows-node-group-9q9v"
I0530 01:56:27.292579       1 scheduler_binder.go:265] AssumePodVolumes for pod "init-container-1524/pod-init-f588ade4-e4ba-4968-9669-f67463de99d0", node "e2e-test-peterhornyack-windows-node-group-9q9v": all PVCs bound and nothing to do
I0530 01:56:27.292620       1 factory.go:734] Attempting to bind pod-init-f588ade4-e4ba-4968-9669-f67463de99d0 to e2e-test-peterhornyack-windows-node-group-9q9v
I0530 01:56:27.298917       1 scheduler.go:575] pod init-container-1524/pod-init-f588ade4-e4ba-4968-9669-f67463de99d0 is bound successfully on node e2e-test-peterhornyack-windows-node-group-9q9v, 6 nodes evaluated, 3 nodes were found feasible
I0530 01:56:31.476572       1 wrap.go:47] GET /healthz: (51.601µs) 200 [kube-probe/1.15+ 127.0.0.1:42722]
I0530 01:56:41.484021       1 wrap.go:47] GET /healthz: (76.526µs) 200 [kube-probe/1.15+ 127.0.0.1:42756]
I0530 01:56:51.476682       1 wrap.go:47] GET /healthz: (64.041µs) 200 [kube-probe/1.15+ 127.0.0.1:42790]
I0530 01:56:56.651840       1 scheduling_queue.go:895] About to try and schedule pod container-runtime-4946/image-pull-testb9903c6f-f3a0-453b-bd44-538fa67c7aec
I0530 01:56:56.651870       1 scheduler.go:454] Attempting to schedule pod: container-runtime-4946/image-pull-testb9903c6f-f3a0-453b-bd44-538fa67c7aec
I0530 01:56:56.652567       1 scheduler_binder.go:255] AssumePodVolumes for pod "container-runtime-4946/image-pull-testb9903c6f-f3a0-453b-bd44-538fa67c7aec", node "e2e-test-peterhornyack-windows-node-group-1vjk"
I0530 01:56:56.652580       1 scheduler_binder.go:265] AssumePodVolumes for pod "container-runtime-4946/image-pull-testb9903c6f-f3a0-453b-bd44-538fa67c7aec", node "e2e-test-peterhornyack-windows-node-group-1vjk": all PVCs bound and nothing to do
I0530 01:56:56.652626       1 factory.go:734] Attempting to bind image-pull-testb9903c6f-f3a0-453b-bd44-538fa67c7aec to e2e-test-peterhornyack-windows-node-group-1vjk
I0530 01:56:56.658385       1 scheduler.go:575] pod container-runtime-4946/image-pull-testb9903c6f-f3a0-453b-bd44-538fa67c7aec is bound successfully on node e2e-test-peterhornyack-windows-node-group-1vjk, 6 nodes evaluated, 3 nodes were found feasible
I0530 01:57:01.476530       1 wrap.go:47] GET /healthz: (98.516µs) 200 [kube-probe/1.15+ 127.0.0.1:42842]
I0530 01:57:11.081216       1 scheduling_queue.go:895] About to try and schedule pod container-probe-1431/test-webserver-135f27a9-3c5e-4538-9d07-32b1698384dd
I0530 01:57:11.081230       1 scheduler.go:454] Attempting to schedule pod: container-probe-1431/test-webserver-135f27a9-3c5e-4538-9d07-32b1698384dd
I0530 01:57:11.081532       1 scheduler_binder.go:255] AssumePodVolumes for pod "container-probe-1431/test-webserver-135f27a9-3c5e-4538-9d07-32b1698384dd", node "e2e-test-peterhornyack-windows-node-group-jpxd"
I0530 01:57:11.081558       1 scheduler_binder.go:265] AssumePodVolumes for pod "container-probe-1431/test-webserver-135f27a9-3c5e-4538-9d07-32b1698384dd", node "e2e-test-peterhornyack-windows-node-group-jpxd": all PVCs bound and nothing to do
I0530 01:57:11.081587       1 factory.go:734] Attempting to bind test-webserver-135f27a9-3c5e-4538-9d07-32b1698384dd to e2e-test-peterhornyack-windows-node-group-jpxd
I0530 01:57:11.081862       1 cache.go:643] Couldn't expire cache for pod container-probe-1431/test-webserver-135f27a9-3c5e-4538-9d07-32b1698384dd. Binding is still in progress.
I0530 01:57:11.087153       1 scheduler.go:575] pod container-probe-1431/test-webserver-135f27a9-3c5e-4538-9d07-32b1698384dd is bound successfully on node e2e-test-peterhornyack-windows-node-group-jpxd, 6 nodes evaluated, 3 nodes were found feasible
I0530 01:57:11.476819       1 wrap.go:47] GET /healthz: (71.339µs) 200 [kube-probe/1.15+ 127.0.0.1:42876]
I0530 01:57:21.476847       1 wrap.go:47] GET /healthz: (51.394µs) 200 [kube-probe/1.15+ 127.0.0.1:42912]
I0530 01:57:30.828081       1 reflector.go:384] k8s.io/client-go/informers/factory.go:133: Watch close - *v1.Service total 0 items received
I0530 01:57:31.476660       1 wrap.go:47] GET /healthz: (64.493µs) 200 [kube-probe/1.15+ 127.0.0.1:42946]
I0530 01:57:41.477570       1 wrap.go:47] GET /healthz: (63.631µs) 200 [kube-probe/1.15+ 127.0.0.1:42980]
I0530 01:57:51.476745       1 wrap.go:47] GET /healthz: (83.723µs) 200 [kube-probe/1.15+ 127.0.0.1:43012]
I0530 01:58:01.476823       1 wrap.go:47] GET /healthz: (63.422µs) 200 [kube-probe/1.15+ 127.0.0.1:43060]
I0530 01:58:11.477505       1 wrap.go:47] GET /healthz: (79.017µs) 200 [kube-probe/1.15+ 127.0.0.1:43096]
I0530 01:58:21.477046       1 wrap.go:47] GET /healthz: (88.179µs) 200 [kube-probe/1.15+ 127.0.0.1:43132]
I0530 01:58:31.476865       1 wrap.go:47] GET /healthz: (71.876µs) 200 [kube-probe/1.15+ 127.0.0.1:43168]
I0530 01:58:35.147179       1 scheduling_queue.go:895] About to try and schedule pod downward-api-7812/annotationupdateb44af120-cf01-497b-88f1-4589a4971d27
I0530 01:58:35.147203       1 scheduler.go:454] Attempting to schedule pod: downward-api-7812/annotationupdateb44af120-cf01-497b-88f1-4589a4971d27
I0530 01:58:35.147572       1 scheduler_binder.go:255] AssumePodVolumes for pod "downward-api-7812/annotationupdateb44af120-cf01-497b-88f1-4589a4971d27", node "e2e-test-peterhornyack-windows-node-group-jpxd"
I0530 01:58:35.147585       1 scheduler_binder.go:265] AssumePodVolumes for pod "downward-api-7812/annotationupdateb44af120-cf01-497b-88f1-4589a4971d27", node "e2e-test-peterhornyack-windows-node-group-jpxd": all PVCs bound and nothing to do
I0530 01:58:35.147641       1 factory.go:734] Attempting to bind annotationupdateb44af120-cf01-497b-88f1-4589a4971d27 to e2e-test-peterhornyack-windows-node-group-jpxd
I0530 01:58:35.153596       1 scheduler.go:575] pod downward-api-7812/annotationupdateb44af120-cf01-497b-88f1-4589a4971d27 is bound successfully on node e2e-test-peterhornyack-windows-node-group-jpxd, 6 nodes evaluated, 3 nodes were found feasible
I0530 01:58:41.477634       1 wrap.go:47] GET /healthz: (93.794µs) 200 [kube-probe/1.15+ 127.0.0.1:43202]
I0530 01:58:51.476667       1 wrap.go:47] GET /healthz: (78.559µs) 200 [kube-probe/1.15+ 127.0.0.1:43234]
I0530 01:59:01.477366       1 wrap.go:47] GET /healthz: (66.815µs) 200 [kube-probe/1.15+ 127.0.0.1:43282]
I0530 01:59:10.818258       1 reflector.go:384] k8s.io/client-go/informers/factory.go:133: Watch close - *v1.StorageClass total 0 items received
I0530 01:59:11.476580       1 wrap.go:47] GET /healthz: (67.333µs) 200 [kube-probe/1.15+ 127.0.0.1:43316]
I0530 01:59:21.476640       1 wrap.go:47] GET /healthz: (91.053µs) 200 [kube-probe/1.15+ 127.0.0.1:43354]
I0530 01:59:31.476625       1 wrap.go:47] GET /healthz: (61.983µs) 200 [kube-probe/1.15+ 127.0.0.1:43392]
I0530 01:59:41.476764       1 wrap.go:47] GET /healthz: (77.035µs) 200 [kube-probe/1.15+ 127.0.0.1:43426]
I0530 01:59:51.476706       1 wrap.go:47] GET /healthz: (78.827µs) 200 [kube-probe/1.15+ 127.0.0.1:43458]
I0530 02:00:01.476650       1 wrap.go:47] GET /healthz: (80.27µs) 200 [kube-probe/1.15+ 127.0.0.1:43508]
I0530 02:00:11.476538       1 wrap.go:47] GET /healthz: (81.859µs) 200 [kube-probe/1.15+ 127.0.0.1:43542]
I0530 02:00:16.853445       1 reflector.go:384] cmd/kube-scheduler/app/server.go:223: Watch close - *v1.Pod total 28 items received
I0530 02:00:21.477115       1 wrap.go:47] GET /healthz: (84.741µs) 200 [kube-probe/1.15+ 127.0.0.1:43578]
I0530 02:00:31.477349       1 wrap.go:47] GET /healthz: (57.909µs) 200 [kube-probe/1.15+ 127.0.0.1:43612]
I0530 02:00:40.829863       1 reflector.go:384] k8s.io/client-go/informers/factory.go:133: Watch close - *v1.StatefulSet total 0 items received
I0530 02:00:41.476920       1 wrap.go:47] GET /healthz: (66.764µs) 200 [kube-probe/1.15+ 127.0.0.1:43648]
I0530 02:00:42.838870       1 reflector.go:384] k8s.io/client-go/informers/factory.go:133: Watch close - *v1beta1.PodDisruptionBudget total 0 items received
I0530 02:00:51.476796       1 wrap.go:47] GET /healthz: (72.353µs) 200 [kube-probe/1.15+ 127.0.0.1:43680]
I0530 02:01:01.476593       1 wrap.go:47] GET /healthz: (65.429µs) 200 [kube-probe/1.15+ 127.0.0.1:43728]
I0530 02:01:11.476579       1 wrap.go:47] GET /healthz: (64.056µs) 200 [kube-probe/1.15+ 127.0.0.1:43762]
I0530 02:01:21.476524       1 wrap.go:47] GET /healthz: (86.126µs) 200 [kube-probe/1.15+ 127.0.0.1:43798]
I0530 02:01:31.476980       1 wrap.go:47] GET /healthz: (59.051µs) 200 [kube-probe/1.15+ 127.0.0.1:43840]
I0530 02:01:41.476589       1 wrap.go:47] GET /healthz: (66.325µs) 200 [kube-probe/1.15+ 127.0.0.1:43876]
I0530 02:01:48.798371       1 reflector.go:384] k8s.io/client-go/informers/factory.go:133: Watch close - *v1.Node total 83 items received
I0530 02:01:51.477734       1 wrap.go:47] GET /healthz: (85.795µs) 200 [kube-probe/1.15+ 127.0.0.1:43910]
I0530 02:01:53.846655       1 reflector.go:384] k8s.io/client-go/informers/factory.go:133: Watch close - *v1.PersistentVolume total 0 items received
I0530 02:02:01.476786       1 wrap.go:47] GET /healthz: (78.391µs) 200 [kube-probe/1.15+ 127.0.0.1:43958]
I0530 02:02:11.476576       1 wrap.go:47] GET /healthz: (65.438µs) 200 [kube-probe/1.15+ 127.0.0.1:43992]
I0530 02:02:11.853614       1 reflector.go:384] k8s.io/client-go/informers/factory.go:133: Watch close - *v1.PersistentVolumeClaim total 0 items received
I0530 02:02:21.479587       1 wrap.go:47] GET /healthz: (65.211µs) 200 [kube-probe/1.15+ 127.0.0.1:44028]
I0530 02:02:31.476428       1 wrap.go:47] GET /healthz: (62.874µs) 200 [kube-probe/1.15+ 127.0.0.1:44064]
I0530 02:02:41.479085       1 wrap.go:47] GET /healthz: (76.27µs) 200 [kube-probe/1.15+ 127.0.0.1:44098]
I0530 02:02:51.476589       1 wrap.go:47] GET /healthz: (75.548µs) 200 [kube-probe/1.15+ 127.0.0.1:44130]
I0530 02:03:01.476439       1 wrap.go:47] GET /healthz: (58.578µs) 200 [kube-probe/1.15+ 127.0.0.1:44182]
I0530 02:03:11.476809       1 wrap.go:47] GET /healthz: (78.777µs) 200 [kube-probe/1.15+ 127.0.0.1:44216]
I0530 02:03:12.841714       1 reflector.go:384] k8s.io/client-go/informers/factory.go:133: Watch close - *v1.ReplicaSet total 0 items received
I0530 02:03:21.476214       1 wrap.go:47] GET /healthz: (79.527µs) 200 [kube-probe/1.15+ 127.0.0.1:44252]
I0530 02:03:31.479007       1 wrap.go:47] GET /healthz: (72.291µs) 200 [kube-probe/1.15+ 127.0.0.1:44294]
I0530 02:03:41.476687       1 wrap.go:47] GET /healthz: (59.086µs) 200 [kube-probe/1.15+ 127.0.0.1:44328]
I0530 02:03:46.809510       1 reflector.go:384] k8s.io/client-go/informers/factory.go:133: Watch close - *v1.ReplicationController total 0 items received
I0530 02:03:51.476834       1 wrap.go:47] GET /healthz: (84.657µs) 200 [kube-probe/1.15+ 127.0.0.1:44360]
I0530 02:04:01.476617       1 wrap.go:47] GET /healthz: (71.999µs) 200 [kube-probe/1.15+ 127.0.0.1:44408]
I0530 02:04:11.476726       1 wrap.go:47] GET /healthz: (99.288µs) 200 [kube-probe/1.15+ 127.0.0.1:44444]
I0530 02:04:21.476879       1 wrap.go:47] GET /healthz: (78.228µs) 200 [kube-probe/1.15+ 127.0.0.1:44482]
I0530 02:04:31.476560       1 wrap.go:47] GET /healthz: (83.93µs) 200 [kube-probe/1.15+ 127.0.0.1:44516]
I0530 02:04:41.476533       1 wrap.go:47] GET /healthz: (75.247µs) 200 [kube-probe/1.15+ 127.0.0.1:44550]
I0530 02:04:51.476575       1 wrap.go:47] GET /healthz: (52.107µs) 200 [kube-probe/1.15+ 127.0.0.1:44582]
I0530 02:05:01.482423       1 wrap.go:47] GET /healthz: (87.914µs) 200 [kube-probe/1.15+ 127.0.0.1:44630]
I0530 02:05:11.476488       1 wrap.go:47] GET /healthz: (75.457µs) 200 [kube-probe/1.15+ 127.0.0.1:44664]
I0530 02:05:15.820494       1 reflector.go:384] k8s.io/client-go/informers/factory.go:133: Watch close - *v1.StorageClass total 0 items received
I0530 02:05:21.476911       1 wrap.go:47] GET /healthz: (62.019µs) 200 [kube-probe/1.15+ 127.0.0.1:44702]
I0530 02:05:31.477566       1 wrap.go:47] GET /healthz: (56.58µs) 200 [kube-probe/1.15+ 127.0.0.1:44736]
I0530 02:05:41.476768       1 wrap.go:47] GET /healthz: (84.965µs) 200 [kube-probe/1.15+ 127.0.0.1:44770]
I0530 02:05:51.476896       1 wrap.go:47] GET /healthz: (72.729µs) 200 [kube-probe/1.15+ 127.0.0.1:44804]
I0530 02:06:01.476790       1 wrap.go:47] GET /healthz: (63.71µs) 200 [kube-probe/1.15+ 127.0.0.1:44936]
I0530 02:06:11.476733       1 wrap.go:47] GET /healthz: (65.97µs) 200 [kube-probe/1.15+ 127.0.0.1:44970]
I0530 02:06:21.476733       1 wrap.go:47] GET /healthz: (64.111µs) 200 [kube-probe/1.15+ 127.0.0.1:45006]
I0530 02:06:31.476730       1 wrap.go:47] GET /healthz: (75.342µs) 200 [kube-probe/1.15+ 127.0.0.1:45042]
I0530 02:06:41.476432       1 wrap.go:47] GET /healthz: (77.194µs) 200 [kube-probe/1.15+ 127.0.0.1:45078]
I0530 02:06:42.830116       1 reflector.go:384] k8s.io/client-go/informers/factory.go:133: Watch close - *v1.Service total 0 items received
I0530 02:06:51.476587       1 wrap.go:47] GET /healthz: (72.577µs) 200 [kube-probe/1.15+ 127.0.0.1:45110]
I0530 02:06:51.835104       1 reflector.go:384] k8s.io/client-go/informers/factory.go:133: Watch close - *v1.StatefulSet total 0 items received
I0530 02:07:01.476909       1 wrap.go:47] GET /healthz: (63.519µs) 200 [kube-probe/1.15+ 127.0.0.1:45158]
I0530 02:07:11.477443       1 wrap.go:47] GET /healthz: (48.904µs) 200 [kube-probe/1.15+ 127.0.0.1:45192]
I0530 02:07:21.476757       1 wrap.go:47] GET /healthz: (67.84µs) 200 [kube-probe/1.15+ 127.0.0.1:45230]
I0530 02:07:31.476553       1 wrap.go:47] GET /healthz: (85.18µs) 200 [kube-probe/1.15+ 127.0.0.1:45266]
I0530 02:07:36.841944       1 reflector.go:384] k8s.io/client-go/informers/factory.go:133: Watch close - *v1beta1.PodDisruptionBudget total 0 items received
I0530 02:07:41.476634       1 wrap.go:47] GET /healthz: (60.304µs) 200 [kube-probe/1.15+ 127.0.0.1:45302]
I0530 02:07:51.476890       1 wrap.go:47] GET /healthz: (77.454µs) 200 [kube-probe/1.15+ 127.0.0.1:45334]
I0530 02:08:01.481226       1 wrap.go:47] GET /healthz: (85.75µs) 200 [kube-probe/1.15+ 127.0.0.1:45382]
I0530 02:08:11.476643       1 wrap.go:47] GET /healthz: (52.321µs) 200 [kube-probe/1.15+ 127.0.0.1:45416]
I0530 02:08:21.476791       1 wrap.go:47] GET /healthz: (69.238µs) 200 [kube-probe/1.15+ 127.0.0.1:45452]
I0530 02:08:31.476782       1 wrap.go:47] GET /healthz: (52.343µs) 200 [kube-probe/1.15+ 127.0.0.1:45486]
I0530 02:08:41.478091       1 wrap.go:47] GET /healthz: (58.455µs) 200 [kube-probe/1.15+ 127.0.0.1:45522]
I0530 02:08:51.476614       1 wrap.go:47] GET /healthz: (50.764µs) 200 [kube-probe/1.15+ 127.0.0.1:45558]
I0530 02:08:58.856276       1 reflector.go:384] cmd/kube-scheduler/app/server.go:223: Watch close - *v1.Pod total 4 items received
I0530 02:09:01.476711       1 wrap.go:47] GET /healthz: (62.559µs) 200 [kube-probe/1.15+ 127.0.0.1:45606]
I0530 02:09:11.481308       1 wrap.go:47] GET /healthz: (75.774µs) 200 [kube-probe/1.15+ 127.0.0.1:45640]
I0530 02:09:21.476650       1 wrap.go:47] GET /healthz: (70.869µs) 200 [kube-probe/1.15+ 127.0.0.1:45676]
I0530 02:09:26.850268       1 reflector.go:384] k8s.io/client-go/informers/factory.go:133: Watch close - *v1.PersistentVolume total 0 items received
I0530 02:09:31.476719       1 wrap.go:47] GET /healthz: (61.831µs) 200 [kube-probe/1.15+ 127.0.0.1:45710]
I0530 02:09:41.476592       1 wrap.go:47] GET /healthz: (146.423µs) 200 [kube-probe/1.15+ 127.0.0.1:45744]
I0530 02:09:51.476656       1 wrap.go:47] GET /healthz: (79.901µs) 200 [kube-probe/1.15+ 127.0.0.1:45776]
I0530 02:10:01.476685       1 wrap.go:47] GET /healthz: (65.802µs) 200 [kube-probe/1.15+ 127.0.0.1:45826]
I0530 02:10:11.476664       1 wrap.go:47] GET /healthz: (67.562µs) 200 [kube-probe/1.15+ 127.0.0.1:45860]
I0530 02:10:21.476525       1 wrap.go:47] GET /healthz: (78.149µs) 200 [kube-probe/1.15+ 127.0.0.1:45904]
I0530 02:10:31.476540       1 wrap.go:47] GET /healthz: (84.196µs) 200 [kube-probe/1.15+ 127.0.0.1:45938]
I0530 02:10:31.803732       1 reflector.go:384] k8s.io/client-go/informers/factory.go:133: Watch close - *v1.Node total 88 items received
I0530 02:10:41.476693       1 wrap.go:47] GET /healthz: (77.924µs) 200 [kube-probe/1.15+ 127.0.0.1:45972]
I0530 02:10:49.811754       1 reflector.go:384] k8s.io/client-go/informers/factory.go:133: Watch close - *v1.ReplicationController total 0 items received
I0530 02:10:51.477688       1 wrap.go:47] GET /healthz: (70.235µs) 200 [kube-probe/1.15+ 127.0.0.1:46004]
I0530 02:11:01.476627       1 wrap.go:47] GET /healthz: (50.445µs) 200 [kube-probe/1.15+ 127.0.0.1:46052]
I0530 02:11:11.476676       1 wrap.go:47] GET /healthz: (74.483µs) 200 [kube-probe/1.15+ 127.0.0.1:46086]
I0530 02:11:21.476671       1 wrap.go:47] GET /healthz: (71.934µs) 200 [kube-probe/1.15+ 127.0.0.1:46124]
I0530 02:11:27.855747       1 reflector.go:384] k8s.io/client-go/informers/factory.go:133: Watch close - *v1.PersistentVolumeClaim total 0 items received
I0530 02:11:31.476528       1 wrap.go:47] GET /healthz: (76.343µs) 200 [kube-probe/1.15+ 127.0.0.1:46160]
I0530 02:11:41.476499       1 wrap.go:47] GET /healthz: (69.335µs) 200 [kube-probe/1.15+ 127.0.0.1:46196]
I0530 02:11:51.476598       1 wrap.go:47] GET /healthz: (65.464µs) 200 [kube-probe/1.15+ 127.0.0.1:46228]
I0530 02:12:01.476363       1 wrap.go:47] GET /healthz: (52.709µs) 200 [kube-probe/1.15+ 127.0.0.1:46278]
I0530 02:12:11.476576       1 wrap.go:47] GET /healthz: (53.871µs) 200 [kube-probe/1.15+ 127.0.0.1:46312]
I0530 02:12:21.476560       1 wrap.go:47] GET /healthz: (67.562µs) 200 [kube-probe/1.15+ 127.0.0.1:46348]
I0530 02:12:31.476548       1 wrap.go:47] GET /healthz: (79.658µs) 200 [kube-probe/1.15+ 127.0.0.1:46384]
I0530 02:12:39.839115       1 reflector.go:384] k8s.io/client-go/informers/factory.go:133: Watch close - *v1.StatefulSet total 0 items received
I0530 02:12:41.476731       1 wrap.go:47] GET /healthz: (48.572µs) 200 [kube-probe/1.15+ 127.0.0.1:46418]
I0530 02:12:51.476407       1 wrap.go:47] GET /healthz: (66.959µs) 200 [kube-probe/1.15+ 127.0.0.1:46450]
I0530 02:13:01.481118       1 wrap.go:47] GET /healthz: (75.083µs) 200 [kube-probe/1.15+ 127.0.0.1:46498]
I0530 02:13:04.843828       1 reflector.go:384] k8s.io/client-go/informers/factory.go:133: Watch close - *v1.ReplicaSet total 0 items received
I0530 02:13:11.476657       1 wrap.go:47] GET /healthz: (55.574µs) 200 [kube-probe/1.15+ 127.0.0.1:46534]
I0530 02:13:21.476627       1 wrap.go:47] GET /healthz: (73.478µs) 200 [kube-probe/1.15+ 127.0.0.1:46570]
I0530 02:13:26.008447       1 scheduling_queue.go:895] About to try and schedule pod containers-4264/client-containers-afa55fd3-dfb5-41ee-9051-5b7851cee9a0
I0530 02:13:26.008495       1 scheduler.go:454] Attempting to schedule pod: containers-4264/client-containers-afa55fd3-dfb5-41ee-9051-5b7851cee9a0
I0530 02:13:26.010216       1 scheduler_binder.go:255] AssumePodVolumes for pod "containers-4264/client-containers-afa55fd3-dfb5-41ee-9051-5b7851cee9a0", node "e2e-test-peterhornyack-windows-node-group-9q9v"
I0530 02:13:26.010234       1 scheduler_binder.go:265] AssumePodVolumes for pod "containers-4264/client-containers-afa55fd3-dfb5-41ee-9051-5b7851cee9a0", node "e2e-test-peterhornyack-windows-node-group-9q9v": all PVCs bound and nothing to do
I0530 02:13:26.010309       1 factory.go:734] Attempting to bind client-containers-afa55fd3-dfb5-41ee-9051-5b7851cee9a0 to e2e-test-peterhornyack-windows-node-group-9q9v
I0530 02:13:26.014832       1 scheduler.go:575] pod containers-4264/client-containers-afa55fd3-dfb5-41ee-9051-5b7851cee9a0 is bound successfully on node e2e-test-peterhornyack-windows-node-group-9q9v, 6 nodes evaluated, 3 nodes were found feasible
I0530 02:13:31.476773       1 wrap.go:47] GET /healthz: (74.077µs) 200 [kube-probe/1.15+ 127.0.0.1:46606]
I0530 02:13:41.476523       1 wrap.go:47] GET /healthz: (106.02µs) 200 [kube-probe/1.15+ 127.0.0.1:46642]
I0530 02:13:42.409630       1 scheduling_queue.go:895] About to try and schedule pod container-lifecycle-hook-9969/pod-handle-http-request
I0530 02:13:42.409644       1 scheduler.go:454] Attempting to schedule pod: container-lifecycle-hook-9969/pod-handle-http-request
I0530 02:13:42.409890       1 scheduler_binder.go:255] AssumePodVolumes for pod "container-lifecycle-hook-9969/pod-handle-http-request", node "e2e-test-peterhornyack-windows-node-group-jpxd"
I0530 02:13:42.409900       1 scheduler_binder.go:265] AssumePodVolumes for pod "container-lifecycle-hook-9969/pod-handle-http-request", node "e2e-test-peterhornyack-windows-node-group-jpxd": all PVCs bound and nothing to do
I0530 02:13:42.409936       1 factory.go:734] Attempting to bind pod-handle-http-request to e2e-test-peterhornyack-windows-node-group-jpxd
I0530 02:13:42.418241       1 scheduler.go:575] pod container-lifecycle-hook-9969/pod-handle-http-request is bound successfully on node e2e-test-peterhornyack-windows-node-group-jpxd, 6 nodes evaluated, 3 nodes were found feasible
I0530 02:13:51.476706       1 wrap.go:47] GET /healthz: (81.672µs) 200 [kube-probe/1.15+ 127.0.0.1:46676]
I0530 02:14:01.477082       1 wrap.go:47] GET /healthz: (141.288µs) 200 [kube-probe/1.15+ 127.0.0.1:46724]
I0530 02:14:11.476840       1 wrap.go:47] GET /healthz: (157.277µs) 200 [kube-probe/1.15+ 127.0.0.1:46758]
I0530 02:14:21.491332       1 wrap.go:47] GET /healthz: (77.184µs) 200 [kube-probe/1.15+ 127.0.0.1:46794]
I0530 02:14:31.476605       1 wrap.go:47] GET /healthz: (75.904µs) 200 [kube-probe/1.15+ 127.0.0.1:46828]
I0530 02:14:41.476599       1 wrap.go:47] GET /healthz: (62.785µs) 200 [kube-probe/1.15+ 127.0.0.1:46864]
I0530 02:14:51.476907       1 wrap.go:47] GET /healthz: (65.142µs) 200 [kube-probe/1.15+ 127.0.0.1:46898]
I0530 02:14:52.823014       1 reflector.go:384] k8s.io/client-go/informers/factory.go:133: Watch close - *v1.StorageClass total 0 items received
I0530 02:14:59.844050       1 reflector.go:384] k8s.io/client-go/informers/factory.go:133: Watch close - *v1beta1.PodDisruptionBudget total 0 items received
I0530 02:15:01.477118       1 wrap.go:47] GET /healthz: (65.51µs) 200 [kube-probe/1.15+ 127.0.0.1:46946]
I0530 02:15:11.476795       1 wrap.go:47] GET /healthz: (53.358µs) 200 [kube-probe/1.15+ 127.0.0.1:46980]
I0530 02:15:21.476929       1 wrap.go:47] GET /healthz: (57.465µs) 200 [kube-probe/1.15+ 127.0.0.1:47016]
I0530 02:15:31.476550       1 wrap.go:47] GET /healthz: (105.64µs) 200 [kube-probe/1.15+ 127.0.0.1:47052]
I0530 02:15:40.832235       1 reflector.go:384] k8s.io/client-go/informers/factory.go:133: Watch close - *v1.Service total 0 items received
I0530 02:15:41.476727       1 wrap.go:47] GET /healthz: (58.904µs) 200 [kube-probe/1.15+ 127.0.0.1:47086]
I0530 02:15:50.852522       1 reflector.go:384] k8s.io/client-go/informers/factory.go:133: Watch close - *v1.PersistentVolume total 0 items received
I0530 02:15:51.476821       1 wrap.go:47] GET /healthz: (79.149µs) 200 [kube-probe/1.15+ 127.0.0.1:47118]
I0530 02:16:01.476709       1 wrap.go:47] GET /healthz: (78.729µs) 200 [kube-probe/1.15+ 127.0.0.1:47254]
I0530 02:16:11.476643       1 wrap.go:47] GET /healthz: (73.599µs) 200 [kube-probe/1.15+ 127.0.0.1:47290]
I0530 02:16:21.476747       1 wrap.go:47] GET /healthz: (62.913µs) 200 [kube-probe/1.15+ 127.0.0.1:47326]
I0530 02:16:31.476766       1 wrap.go:47] GET /healthz: (62.82µs) 200 [kube-probe/1.15+ 127.0.0.1:47360]
I0530 02:16:41.476365       1 wrap.go:47] GET /healthz: (69.822µs) 200 [kube-probe/1.15+ 127.0.0.1:47394]
I0530 02:16:49.858938       1 reflector.go:384] cmd/kube-scheduler/app/server.go:223: Watch close - *v1.Pod total 7 items received
I0530 02:16:51.476580       1 wrap.go:47] GET /healthz: (75.163µs) 200 [kube-probe/1.15+ 127.0.0.1:47428]
I0530 02:16:56.857871       1 reflector.go:384] k8s.io/client-go/informers/factory.go:133: Watch close - *v1.PersistentVolumeClaim total 0 items received
I0530 02:17:01.476449       1 wrap.go:47] GET /healthz: (55.838µs) 200 [kube-probe/1.15+ 127.0.0.1:47476]
I0530 02:17:11.476727       1 wrap.go:47] GET /healthz: (72.18µs) 200 [kube-probe/1.15+ 127.0.0.1:47512]
I0530 02:17:21.476528       1 wrap.go:47] GET /healthz: (76.855µs) 200 [kube-probe/1.15+ 127.0.0.1:47548]
I0530 02:17:31.476653       1 wrap.go:47] GET /healthz: (52.988µs) 200 [kube-probe/1.15+ 127.0.0.1:47584]
I0530 02:17:41.476589       1 wrap.go:47] GET /healthz: (61.12µs) 200 [kube-probe/1.15+ 127.0.0.1:47620]
I0530 02:17:51.476680       1 wrap.go:47] GET /healthz: (79.096µs) 200 [kube-probe/1.15+ 127.0.0.1:47652]
I0530 02:18:01.476702       1 wrap.go:47] GET /healthz: (75.026µs) 200 [kube-probe/1.15+ 127.0.0.1:47700]
I0530 02:18:11.476387       1 wrap.go:47] GET /healthz: (72.956µs) 200 [kube-probe/1.15+ 127.0.0.1:47734]
I0530 02:18:21.476752       1 wrap.go:47] GET /healthz: (76.736µs) 200 [kube-probe/1.15+ 127.0.0.1:47772]
I0530 02:18:24.582353       1 scheduling_queue.go:895] About to try and schedule pod container-lifecycle-hook-9969/pod-with-poststart-exec-hook
I0530 02:18:24.582365       1 scheduler.go:454] Attempting to schedule pod: container-lifecycle-hook-9969/pod-with-poststart-exec-hook
I0530 02:18:24.582693       1 scheduler_binder.go:255] AssumePodVolumes for pod "container-lifecycle-hook-9969/pod-with-poststart-exec-hook", node "e2e-test-peterhornyack-windows-node-group-jpxd"
I0530 02:18:24.582719       1 scheduler_binder.go:265] AssumePodVolumes for pod "container-lifecycle-hook-9969/pod-with-poststart-exec-hook", node "e2e-test-peterhornyack-windows-node-group-jpxd": all PVCs bound and nothing to do
I0530 02:18:24.582761       1 factory.go:734] Attempting to bind pod-with-poststart-exec-hook to e2e-test-peterhornyack-windows-node-group-jpxd
I0530 02:18:24.588328       1 scheduler.go:575] pod container-lifecycle-hook-9969/pod-with-poststart-exec-hook is bound successfully on node e2e-test-peterhornyack-windows-node-group-jpxd, 6 nodes evaluated, 3 nodes were found feasible
I0530 02:18:31.476506       1 wrap.go:47] GET /healthz: (92.365µs) 200 [kube-probe/1.15+ 127.0.0.1:47806]
I0530 02:18:41.476390       1 wrap.go:47] GET /healthz: (52.646µs) 200 [kube-probe/1.15+ 127.0.0.1:47840]
I0530 02:18:51.476428       1 wrap.go:47] GET /healthz: (63.214µs) 200 [kube-probe/1.15+ 127.0.0.1:47872]
I0530 02:19:01.483145       1 wrap.go:47] GET /healthz: (76.474µs) 200 [kube-probe/1.15+ 127.0.0.1:47922]
I0530 02:19:11.476642       1 wrap.go:47] GET /healthz: (70.199µs) 200 [kube-probe/1.15+ 127.0.0.1:47956]
I0530 02:19:15.848021       1 reflector.go:384] k8s.io/client-go/informers/factory.go:133: Watch close - *v1.ReplicaSet total 0 items received
I0530 02:19:21.476537       1 wrap.go:47] GET /healthz: (81.532µs) 200 [kube-probe/1.15+ 127.0.0.1:47992]
I0530 02:19:31.479004       1 wrap.go:47] GET /healthz: (68.666µs) 200 [kube-probe/1.15+ 127.0.0.1:48026]
I0530 02:19:41.479236       1 wrap.go:47] GET /healthz: (69.525µs) 200 [kube-probe/1.15+ 127.0.0.1:48062]
I0530 02:19:49.805936       1 reflector.go:384] k8s.io/client-go/informers/factory.go:133: Watch close - *v1.Node total 95 items received
I0530 02:19:51.476830       1 wrap.go:47] GET /healthz: (81.14µs) 200 [kube-probe/1.15+ 127.0.0.1:48094]
I0530 02:20:01.481032       1 wrap.go:47] GET /healthz: (86.402µs) 200 [kube-probe/1.15+ 127.0.0.1:48142]
I0530 02:20:11.515773       1 wrap.go:47] GET /healthz: (91.642µs) 200 [kube-probe/1.15+ 127.0.0.1:48176]
I0530 02:20:21.476654       1 wrap.go:47] GET /healthz: (191.707µs) 200 [kube-probe/1.15+ 127.0.0.1:48212]
I0530 02:20:24.840979       1 reflector.go:384] k8s.io/client-go/informers/factory.go:133: Watch close - *v1.StatefulSet total 0 items received
I0530 02:20:31.476567       1 wrap.go:47] GET /healthz: (47.371µs) 200 [kube-probe/1.15+ 127.0.0.1:48248]
I0530 02:20:41.481862       1 wrap.go:47] GET /healthz: (69.028µs) 200 [kube-probe/1.15+ 127.0.0.1:48284]
I0530 02:20:46.813950       1 reflector.go:384] k8s.io/client-go/informers/factory.go:133: Watch close - *v1.ReplicationController total 0 items received
I0530 02:20:51.476877       1 wrap.go:47] GET /healthz: (62.114µs) 200 [kube-probe/1.15+ 127.0.0.1:48316]
I0530 02:21:01.476632       1 wrap.go:47] GET /healthz: (62.183µs) 200 [kube-probe/1.15+ 127.0.0.1:48364]
I0530 02:21:10.854776       1 reflector.go:384] k8s.io/client-go/informers/factory.go:133: Watch close - *v1.PersistentVolume total 0 items received
I0530 02:21:11.476614       1 wrap.go:47] GET /healthz: (78.7µs) 200 [kube-probe/1.15+ 127.0.0.1:48398]
I0530 02:21:21.476663       1 wrap.go:47] GET /healthz: (79.909µs) 200 [kube-probe/1.15+ 127.0.0.1:48436]
I0530 02:21:31.476691       1 wrap.go:47] GET /healthz: (75.126µs) 200 [kube-probe/1.15+ 127.0.0.1:48470]
I0530 02:21:41.476636       1 wrap.go:47] GET /healthz: (74.232µs) 200 [kube-probe/1.15+ 127.0.0.1:48504]
I0530 02:21:45.825174       1 reflector.go:384] k8s.io/client-go/informers/factory.go:133: Watch close - *v1.StorageClass total 0 items received
I0530 02:21:51.476689       1 wrap.go:47] GET /healthz: (70.835µs) 200 [kube-probe/1.15+ 127.0.0.1:48538]
I0530 02:22:01.476521       1 wrap.go:47] GET /healthz: (99.635µs) 200 [kube-probe/1.15+ 127.0.0.1:48588]
I0530 02:22:11.476611       1 wrap.go:47] GET /healthz: (72.25µs) 200 [kube-probe/1.15+ 127.0.0.1:48622]
I0530 02:22:21.476562       1 wrap.go:47] GET /healthz: (49.983µs) 200 [kube-probe/1.15+ 127.0.0.1:48658]
I0530 02:22:31.476718       1 wrap.go:47] GET /healthz: (50.071µs) 200 [kube-probe/1.15+ 127.0.0.1:48692]
I0530 02:22:41.476557       1 wrap.go:47] GET /healthz: (49.5µs) 200 [kube-probe/1.15+ 127.0.0.1:48726]
I0530 02:22:51.476409       1 wrap.go:47] GET /healthz: (85.247µs) 200 [kube-probe/1.15+ 127.0.0.1:48762]
I0530 02:23:01.476636       1 wrap.go:47] GET /healthz: (59.514µs) 200 [kube-probe/1.15+ 127.0.0.1:48812]
I0530 02:23:11.476938       1 wrap.go:47] GET /healthz: (81.895µs) 200 [kube-probe/1.15+ 127.0.0.1:48848]
I0530 02:23:21.476637       1 wrap.go:47] GET /healthz: (81.735µs) 200 [kube-probe/1.15+ 127.0.0.1:48888]
I0530 02:23:30.834410       1 reflector.go:384] k8s.io/client-go/informers/factory.go:133: Watch close - *v1.Service total 0 items received
I0530 02:23:31.476586       1 wrap.go:47] GET /healthz: (77.182µs) 200 [kube-probe/1.15+ 127.0.0.1:48924]
I0530 02:23:41.476530       1 wrap.go:47] GET /healthz: (85.364µs) 200 [kube-probe/1.15+ 127.0.0.1:48960]
I0530 02:23:51.476768       1 wrap.go:47] GET /healthz: (78.738µs) 200 [kube-probe/1.15+ 127.0.0.1:48992]
I0530 02:24:01.481112       1 wrap.go:47] GET /healthz: (97.325µs) 200 [kube-probe/1.15+ 127.0.0.1:49040]
I0530 02:24:11.476838       1 wrap.go:47] GET /healthz: (73.835µs) 200 [kube-probe/1.15+ 127.0.0.1:49074]
I0530 02:24:16.860103       1 reflector.go:384] k8s.io/client-go/informers/factory.go:133: Watch close - *v1.PersistentVolumeClaim total 0 items received
I0530 02:24:21.476761       1 wrap.go:47] GET /healthz: (74.086µs) 200 [kube-probe/1.15+ 127.0.0.1:49112]
I0530 02:24:31.480799       1 wrap.go:47] GET /healthz: (54.693µs) 200 [kube-probe/1.15+ 127.0.0.1:49146]
I0530 02:24:37.846718       1 reflector.go:384] k8s.io/client-go/informers/factory.go:133: Watch close - *v1beta1.PodDisruptionBudget total 0 items received
I0530 02:24:41.476968       1 wrap.go:47] GET /healthz: (56.594µs) 200 [kube-probe/1.15+ 127.0.0.1:49180]
I0530 02:24:51.476651       1 wrap.go:47] GET /healthz: (78.608µs) 200 [kube-probe/1.15+ 127.0.0.1:49212]
I0530 02:24:51.861187       1 reflector.go:384] cmd/kube-scheduler/app/server.go:223: Watch close - *v1.Pod total 6 items received
I0530 02:24:52.808109       1 reflector.go:384] k8s.io/client-go/informers/factory.go:133: Watch close - *v1.Node total 55 items received
I0530 02:25:01.477120       1 wrap.go:47] GET /healthz: (83.505µs) 200 [kube-probe/1.15+ 127.0.0.1:49262]
I0530 02:25:11.476486       1 wrap.go:47] GET /healthz: (69.764µs) 200 [kube-probe/1.15+ 127.0.0.1:49296]
I0530 02:25:21.476526       1 wrap.go:47] GET /healthz: (76.663µs) 200 [kube-probe/1.15+ 127.0.0.1:49332]
I0530 02:25:31.476757       1 wrap.go:47] GET /healthz: (79.436µs) 200 [kube-probe/1.15+ 127.0.0.1:49368]
I0530 02:25:41.476623       1 wrap.go:47] GET /healthz: (78.996µs) 200 [kube-probe/1.15+ 127.0.0.1:49402]
I0530 02:25:45.843227       1 reflector.go:384] k8s.io/client-go/informers/factory.go:133: Watch close - *v1.StatefulSet total 0 items received
I0530 02:25:51.481593       1 wrap.go:47] GET /healthz: (69.592µs) 200 [kube-probe/1.15+ 127.0.0.1:49434]
I0530 02:26:01.476799       1 wrap.go:47] GET /healthz: (77.17µs) 200 [kube-probe/1.15+ 127.0.0.1:49558]
I0530 02:26:11.476725       1 wrap.go:47] GET /healthz: (78.63µs) 200 [kube-probe/1.15+ 127.0.0.1:49592]
I0530 02:26:21.476790       1 wrap.go:47] GET /healthz: (75.41µs) 200 [kube-probe/1.15+ 127.0.0.1:49632]
I0530 02:26:24.816335       1 reflector.go:384] k8s.io/client-go/informers/factory.go:133: Watch close - *v1.ReplicationController total 0 items received
I0530 02:26:31.476676       1 wrap.go:47] GET /healthz: (77.04µs) 200 [kube-probe/1.15+ 127.0.0.1:49666]
I0530 02:26:40.850290       1 reflector.go:384] k8s.io/client-go/informers/factory.go:133: Watch close - *v1.ReplicaSet total 0 items received
I0530 02:26:41.476706       1 wrap.go:47] GET /healthz: (84.918µs) 200 [kube-probe/1.15+ 127.0.0.1:49702]
I0530 02:26:51.476451       1 wrap.go:47] GET /healthz: (84.624µs) 200 [kube-probe/1.15+ 127.0.0.1:49734]
I0530 02:27:01.476702       1 wrap.go:47] GET /healthz: (64.919µs) 200 [kube-probe/1.15+ 127.0.0.1:49782]
I0530 02:27:11.476682       1 wrap.go:47] GET /healthz: (87.54µs) 200 [kube-probe/1.15+ 127.0.0.1:49816]
I0530 02:27:21.476891       1 wrap.go:47] GET /healthz: (74.193µs) 200 [kube-probe/1.15+ 127.0.0.1:49852]
I0530 02:27:31.476799       1 wrap.go:47] GET /healthz: (66.056µs) 200 [kube-probe/1.15+ 127.0.0.1:49888]
I0530 02:27:41.476906       1 wrap.go:47] GET /healthz: (66.308µs) 200 [kube-probe/1.15+ 127.0.0.1:49924]
I0530 02:27:51.476693       1 wrap.go:47] GET /healthz: (69.005µs) 200 [kube-probe/1.15+ 127.0.0.1:49962]
I0530 02:28:01.476520       1 wrap.go:47] GET /healthz: (82.078µs) 200 [kube-probe/1.15+ 127.0.0.1:50010]
I0530 02:28:11.476505       1 wrap.go:47] GET /healthz: (96.264µs) 200 [kube-probe/1.15+ 127.0.0.1:50044]
I0530 02:28:21.476325       1 wrap.go:47] GET /healthz: (90.03µs) 200 [kube-probe/1.15+ 127.0.0.1:50080]
I0530 02:28:31.476490       1 wrap.go:47] GET /healthz: (105.553µs) 200 [kube-probe/1.15+ 127.0.0.1:50118]
I0530 02:28:39.857009       1 reflector.go:384] k8s.io/client-go/informers/factory.go:133: Watch close - *v1.PersistentVolume total 0 items received
I0530 02:28:41.477222       1 wrap.go:47] GET /healthz: (69.588µs) 200 [kube-probe/1.15+ 127.0.0.1:50154]
I0530 02:28:51.476729       1 wrap.go:47] GET /healthz: (135.129µs) 200 [kube-probe/1.15+ 127.0.0.1:50186]
I0530 02:29:01.477622       1 wrap.go:47] GET /healthz: (82.793µs) 200 [kube-probe/1.15+ 127.0.0.1:50236]
I0530 02:29:11.476506       1 wrap.go:47] GET /healthz: (110.48µs) 200 [kube-probe/1.15+ 127.0.0.1:50270]
I0530 02:29:21.476566       1 wrap.go:47] GET /healthz: (90.331µs) 200 [kube-probe/1.15+ 127.0.0.1:50312]
I0530 02:29:31.476676       1 wrap.go:47] GET /healthz: (80.611µs) 200 [kube-probe/1.15+ 127.0.0.1:50346]
I0530 02:29:41.476731       1 wrap.go:47] GET /healthz: (109.703µs) 200 [kube-probe/1.15+ 127.0.0.1:50380]
I0530 02:29:43.827389       1 reflector.go:384] k8s.io/client-go/informers/factory.go:133: Watch close - *v1.StorageClass total 0 items received
I0530 02:29:51.477041       1 wrap.go:47] GET /healthz: (81.605µs) 200 [kube-probe/1.15+ 127.0.0.1:50412]
I0530 02:30:01.476789       1 wrap.go:47] GET /healthz: (83.483µs) 200 [kube-probe/1.15+ 127.0.0.1:50462]
I0530 02:30:03.863207       1 reflector.go:384] cmd/kube-scheduler/app/server.go:223: Watch close - *v1.Pod total 1 items received
I0530 02:30:11.476484       1 wrap.go:47] GET /healthz: (74.724µs) 200 [kube-probe/1.15+ 127.0.0.1:50498]
I0530 02:30:19.836594       1 reflector.go:384] k8s.io/client-go/informers/factory.go:133: Watch close - *v1.Service total 0 items received
I0530 02:30:21.476876       1 wrap.go:47] GET /healthz: (64.705µs) 200 [kube-probe/1.15+ 127.0.0.1:50534]
I0530 02:30:31.477194       1 wrap.go:47] GET /healthz: (78.497µs) 200 [kube-probe/1.15+ 127.0.0.1:50568]
I0530 02:30:41.476620       1 wrap.go:47] GET /healthz: (71.436µs) 200 [kube-probe/1.15+ 127.0.0.1:50602]
I0530 02:30:51.477886       1 wrap.go:47] GET /healthz: (195.624µs) 200 [kube-probe/1.15+ 127.0.0.1:50636]
I0530 02:31:01.476754       1 wrap.go:47] GET /healthz: (78.507µs) 200 [kube-probe/1.15+ 127.0.0.1:50686]
I0530 02:31:11.476437       1 wrap.go:47] GET /healthz: (67.519µs) 200 [kube-probe/1.15+ 127.0.0.1:50720]
I0530 02:31:21.476790       1 wrap.go:47] GET /healthz: (80.809µs) 200 [kube-probe/1.15+ 127.0.0.1:50758]
I0530 02:31:31.476617       1 wrap.go:47] GET /healthz: (80.487µs) 200 [kube-probe/1.15+ 127.0.0.1:50792]
I0530 02:31:41.477600       1 wrap.go:47] GET /healthz: (67.365µs) 200 [kube-probe/1.15+ 127.0.0.1:50828]
I0530 02:31:51.476693       1 wrap.go:47] GET /healthz: (79.5µs) 200 [kube-probe/1.15+ 127.0.0.1:50860]
I0530 02:32:01.476903       1 wrap.go:47] GET /healthz: (72.354µs) 200 [kube-probe/1.15+ 127.0.0.1:50908]
I0530 02:32:11.476600       1 wrap.go:47] GET /healthz: (64.413µs) 200 [kube-probe/1.15+ 127.0.0.1:50942]
I0530 02:32:15.848838       1 reflector.go:384] k8s.io/client-go/informers/factory.go:133: Watch close - *v1beta1.PodDisruptionBudget total 0 items received
I0530 02:32:21.476647       1 wrap.go:47] GET /healthz: (78.103µs) 200 [kube-probe/1.15+ 127.0.0.1:50982]
I0530 02:32:31.476600       1 wrap.go:47] GET /healthz: (81.994µs) 200 [kube-probe/1.15+ 127.0.0.1:51018]
I0530 02:32:41.476646       1 wrap.go:47] GET /healthz: (75.87µs) 200 [kube-probe/1.15+ 127.0.0.1:51052]
I0530 02:32:51.476808       1 wrap.go:47] GET /healthz: (107.516µs) 200 [kube-probe/1.15+ 127.0.0.1:51084]
I0530 02:33:01.476602       1 wrap.go:47] GET /healthz: (73.881µs) 200 [kube-probe/1.15+ 127.0.0.1:51132]
I0530 02:33:04.852423       1 reflector.go:384] k8s.io/client-go/informers/factory.go:133: Watch close - *v1.ReplicaSet total 0 items received
I0530 02:33:11.476785       1 wrap.go:47] GET /healthz: (58.074µs) 200 [kube-probe/1.15+ 127.0.0.1:51166]
I0530 02:33:21.476439       1 wrap.go:47] GET /healthz: (71.466µs) 200 [kube-probe/1.15+ 127.0.0.1:51202]
I0530 02:33:25.845415       1 reflector.go:384] k8s.io/client-go/informers/factory.go:133: Watch close - *v1.StatefulSet total 0 items received
I0530 02:33:31.476574       1 wrap.go:47] GET /healthz: (105.537µs) 200 [kube-probe/1.15+ 127.0.0.1:51236]
I0530 02:33:41.476754       1 wrap.go:47] GET /healthz: (71.957µs) 200 [kube-probe/1.15+ 127.0.0.1:51274]
I0530 02:33:44.862435       1 reflector.go:384] k8s.io/client-go/informers/factory.go:133: Watch close - *v1.PersistentVolumeClaim total 0 items received
I0530 02:33:51.476849       1 wrap.go:47] GET /healthz: (65.668µs) 200 [kube-probe/1.15+ 127.0.0.1:51306]
I0530 02:34:01.476608       1 wrap.go:47] GET /healthz: (72.929µs) 200 [kube-probe/1.15+ 127.0.0.1:51354]
I0530 02:34:03.810083       1 reflector.go:384] k8s.io/client-go/informers/factory.go:133: Watch close - *v1.Node total 91 items received
I0530 02:34:11.476749       1 wrap.go:47] GET /healthz: (50.397µs) 200 [kube-probe/1.15+ 127.0.0.1:51388]
I0530 02:34:21.476776       1 wrap.go:47] GET /healthz: (50.215µs) 200 [kube-probe/1.15+ 127.0.0.1:51424]
I0530 02:34:31.476957       1 wrap.go:47] GET /healthz: (113.839µs) 200 [kube-probe/1.15+ 127.0.0.1:51458]
I0530 02:34:41.479281       1 wrap.go:47] GET /healthz: (75.351µs) 200 [kube-probe/1.15+ 127.0.0.1:51492]
I0530 02:34:51.476645       1 wrap.go:47] GET /healthz: (113.4µs) 200 [kube-probe/1.15+ 127.0.0.1:51524]
I0530 02:35:01.476699       1 wrap.go:47] GET /healthz: (77.166µs) 200 [kube-probe/1.15+ 127.0.0.1:51574]
I0530 02:35:11.476636       1 wrap.go:47] GET /healthz: (121.068µs) 200 [kube-probe/1.15+ 127.0.0.1:51610]
I0530 02:35:21.476491       1 wrap.go:47] GET /healthz: (73.247µs) 200 [kube-probe/1.15+ 127.0.0.1:51646]
I0530 02:35:31.476648       1 wrap.go:47] GET /healthz: (49.242µs) 200 [kube-probe/1.15+ 127.0.0.1:51680]
I0530 02:35:34.820076       1 reflector.go:384] k8s.io/client-go/informers/factory.go:133: Watch close - *v1.ReplicationController total 0 items received
I0530 02:35:34.963149       1 scheduling_queue.go:895] About to try and schedule pod projected-1207/pod-projected-configmaps-2c6d0556-2cc4-4920-b02d-9bcec46a9d40
I0530 02:35:34.963161       1 scheduler.go:454] Attempting to schedule pod: projected-1207/pod-projected-configmaps-2c6d0556-2cc4-4920-b02d-9bcec46a9d40
I0530 02:35:34.963991       1 scheduler_binder.go:255] AssumePodVolumes for pod "projected-1207/pod-projected-configmaps-2c6d0556-2cc4-4920-b02d-9bcec46a9d40", node "e2e-test-peterhornyack-windows-node-group-9q9v"
I0530 02:35:34.964006       1 scheduler_binder.go:265] AssumePodVolumes for pod "projected-1207/pod-projected-configmaps-2c6d0556-2cc4-4920-b02d-9bcec46a9d40", node "e2e-test-peterhornyack-windows-node-group-9q9v": all PVCs bound and nothing to do
I0530 02:35:34.964052       1 factory.go:734] Attempting to bind pod-projected-configmaps-2c6d0556-2cc4-4920-b02d-9bcec46a9d40 to e2e-test-peterhornyack-windows-node-group-9q9v
I0530 02:35:34.970252       1 scheduler.go:575] pod projected-1207/pod-projected-configmaps-2c6d0556-2cc4-4920-b02d-9bcec46a9d40 is bound successfully on node e2e-test-peterhornyack-windows-node-group-9q9v, 6 nodes evaluated, 3 nodes were found feasible
I0530 02:35:41.476539       1 wrap.go:47] GET /healthz: (84.834µs) 200 [kube-probe/1.15+ 127.0.0.1:51716]
I0530 02:35:51.476886       1 wrap.go:47] GET /healthz: (69.245µs) 200 [kube-probe/1.15+ 127.0.0.1:51748]
I0530 02:35:57.510442       1 scheduling_queue.go:895] About to try and schedule pod downward-api-2368/labelsupdate00558040-9f55-48a3-8504-53ae2df8cbad
I0530 02:35:57.510481       1 scheduler.go:454] Attempting to schedule pod: downward-api-2368/labelsupdate00558040-9f55-48a3-8504-53ae2df8cbad
I0530 02:35:57.510909       1 scheduler_binder.go:255] AssumePodVolumes for pod "downward-api-2368/labelsupdate00558040-9f55-48a3-8504-53ae2df8cbad", node "e2e-test-peterhornyack-windows-node-group-9q9v"
I0530 02:35:57.510920       1 scheduler_binder.go:265] AssumePodVolumes for pod "downward-api-2368/labelsupdate00558040-9f55-48a3-8504-53ae2df8cbad", node "e2e-test-peterhornyack-windows-node-group-9q9v": all PVCs bound and nothing to do
I0530 02:35:57.510961       1 factory.go:734] Attempting to bind labelsupdate00558040-9f55-48a3-8504-53ae2df8cbad to e2e-test-peterhornyack-windows-node-group-9q9v
I0530 02:35:57.516988       1 scheduler.go:575] pod downward-api-2368/labelsupdate00558040-9f55-48a3-8504-53ae2df8cbad is bound successfully on node e2e-test-peterhornyack-windows-node-group-9q9v, 6 nodes evaluated, 2 nodes were found feasible
I0530 02:36:01.476861       1 wrap.go:47] GET /healthz: (82.704µs) 200 [kube-probe/1.15+ 127.0.0.1:51852]
I0530 02:36:11.476740       1 wrap.go:47] GET /healthz: (74.285µs) 200 [kube-probe/1.15+ 127.0.0.1:51888]
I0530 02:36:21.476788       1 wrap.go:47] GET /healthz: (77.571µs) 200 [kube-probe/1.15+ 127.0.0.1:51924]
I0530 02:36:30.599523       1 scheduling_queue.go:895] About to try and schedule pod projected-2571/pod-projected-secrets-d72d3bdb-b190-400d-b7c6-e962618352ae
I0530 02:36:30.599537       1 scheduler.go:454] Attempting to schedule pod: projected-2571/pod-projected-secrets-d72d3bdb-b190-400d-b7c6-e962618352ae
I0530 02:36:30.600756       1 scheduler_binder.go:255] AssumePodVolumes for pod "projected-2571/pod-projected-secrets-d72d3bdb-b190-400d-b7c6-e962618352ae", node "e2e-test-peterhornyack-windows-node-group-9q9v"
I0530 02:36:30.600770       1 scheduler_binder.go:265] AssumePodVolumes for pod "projected-2571/pod-projected-secrets-d72d3bdb-b190-400d-b7c6-e962618352ae", node "e2e-test-peterhornyack-windows-node-group-9q9v": all PVCs bound and nothing to do
I0530 02:36:30.600823       1 factory.go:734] Attempting to bind pod-projected-secrets-d72d3bdb-b190-400d-b7c6-e962618352ae to e2e-test-peterhornyack-windows-node-group-9q9v
I0530 02:36:30.608104       1 scheduler.go:575] pod projected-2571/pod-projected-secrets-d72d3bdb-b190-400d-b7c6-e962618352ae is bound successfully on node e2e-test-peterhornyack-windows-node-group-9q9v, 6 nodes evaluated, 2 nodes were found feasible
I0530 02:36:31.476786       1 wrap.go:47] GET /healthz: (62.449µs) 200 [kube-probe/1.15+ 127.0.0.1:51958]
I0530 02:36:32.866130       1 reflector.go:384] cmd/kube-scheduler/app/server.go:223: Watch close - *v1.Pod total 19 items received
I0530 02:36:41.476652       1 wrap.go:47] GET /healthz: (62.705µs) 200 [kube-probe/1.15+ 127.0.0.1:51994]
I0530 02:36:51.477018       1 wrap.go:47] GET /healthz: (77.39µs) 200 [kube-probe/1.15+ 127.0.0.1:52026]
I0530 02:37:00.957920       1 scheduling_queue.go:895] About to try and schedule pod statefulset-5035/ss-0
I0530 02:37:00.957944       1 scheduler.go:454] Attempting to schedule pod: statefulset-5035/ss-0
I0530 02:37:00.959418       1 scheduler_binder.go:255] AssumePodVolumes for pod "statefulset-5035/ss-0", node "e2e-test-peterhornyack-windows-node-group-1vjk"
I0530 02:37:00.959431       1 scheduler_binder.go:265] AssumePodVolumes for pod "statefulset-5035/ss-0", node "e2e-test-peterhornyack-windows-node-group-1vjk": all PVCs bound and nothing to do
I0530 02:37:00.959515       1 factory.go:734] Attempting to bind ss-0 to e2e-test-peterhornyack-windows-node-group-1vjk
I0530 02:37:00.973634       1 scheduler.go:575] pod statefulset-5035/ss-0 is bound successfully on node e2e-test-peterhornyack-windows-node-group-1vjk, 6 nodes evaluated, 3 nodes were found feasible
I0530 02:37:01.477030       1 wrap.go:47] GET /healthz: (75.036µs) 200 [kube-probe/1.15+ 127.0.0.1:52074]
I0530 02:37:11.476578       1 wrap.go:47] GET /healthz: (110.84µs) 200 [kube-probe/1.15+ 127.0.0.1:52108]
I0530 02:37:14.838589       1 reflector.go:384] k8s.io/client-go/informers/factory.go:133: Watch close - *v1.Service total 1 items received
I0530 02:37:21.476787       1 wrap.go:47] GET /healthz: (70.521µs) 200 [kube-probe/1.15+ 127.0.0.1:52148]
I0530 02:37:31.476776       1 wrap.go:47] GET /healthz: (64.314µs) 200 [kube-probe/1.15+ 127.0.0.1:52182]
I0530 02:37:33.300740       1 scheduling_queue.go:895] About to try and schedule pod statefulset-5035/ss-1
I0530 02:37:33.300753       1 scheduler.go:454] Attempting to schedule pod: statefulset-5035/ss-1
I0530 02:37:33.306001       1 scheduler_binder.go:255] AssumePodVolumes for pod "statefulset-5035/ss-1", node "e2e-test-peterhornyack-windows-node-group-jpxd"
I0530 02:37:33.306018       1 scheduler_binder.go:265] AssumePodVolumes for pod "statefulset-5035/ss-1", node "e2e-test-peterhornyack-windows-node-group-jpxd": all PVCs bound and nothing to do
I0530 02:37:33.306082       1 factory.go:734] Attempting to bind ss-1 to e2e-test-peterhornyack-windows-node-group-jpxd
I0530 02:37:33.319108       1 scheduler.go:575] pod statefulset-5035/ss-1 is bound successfully on node e2e-test-peterhornyack-windows-node-group-jpxd, 6 nodes evaluated, 3 nodes were found feasible
I0530 02:37:41.476535       1 wrap.go:47] GET /healthz: (108.185µs) 200 [kube-probe/1.15+ 127.0.0.1:52218]
I0530 02:37:51.476978       1 wrap.go:47] GET /healthz: (77.952µs) 200 [kube-probe/1.15+ 127.0.0.1:52250]
I0530 02:38:01.476695       1 wrap.go:47] GET /healthz: (74.156µs) 200 [kube-probe/1.15+ 127.0.0.1:52298]
I0530 02:38:11.476668       1 wrap.go:47] GET /healthz: (75.772µs) 200 [kube-probe/1.15+ 127.0.0.1:52334]
I0530 02:38:21.476592       1 wrap.go:47] GET /healthz: (78.207µs) 200 [kube-probe/1.15+ 127.0.0.1:52370]
I0530 02:38:25.829943       1 reflector.go:384] k8s.io/client-go/informers/factory.go:133: Watch close - *v1.StorageClass total 0 items received
I0530 02:38:31.476667       1 wrap.go:47] GET /healthz: (72.156µs) 200 [kube-probe/1.15+ 127.0.0.1:52408]
I0530 02:38:32.859209       1 reflector.go:384] k8s.io/client-go/informers/factory.go:133: Watch close - *v1.PersistentVolume total 0 items received
I0530 02:38:41.476415       1 wrap.go:47] GET /healthz: (62.118µs) 200 [kube-probe/1.15+ 127.0.0.1:52442]
I0530 02:38:51.476589       1 wrap.go:47] GET /healthz: (70.503µs) 200 [kube-probe/1.15+ 127.0.0.1:52474]
I0530 02:39:01.476673       1 wrap.go:47] GET /healthz: (81.397µs) 200 [kube-probe/1.15+ 127.0.0.1:52522]
I0530 02:39:11.476513       1 wrap.go:47] GET /healthz: (83.951µs) 200 [kube-probe/1.15+ 127.0.0.1:52556]
I0530 02:39:21.476626       1 wrap.go:47] GET /healthz: (78.374µs) 200 [kube-probe/1.15+ 127.0.0.1:52592]
I0530 02:39:31.476647       1 wrap.go:47] GET /healthz: (113.076µs) 200 [kube-probe/1.15+ 127.0.0.1:52626]
I0530 02:39:41.481917       1 wrap.go:47] GET /healthz: (69.784µs) 200 [kube-probe/1.15+ 127.0.0.1:52666]
I0530 02:39:51.476958       1 wrap.go:47] GET /healthz: (99.877µs) 200 [kube-probe/1.15+ 127.0.0.1:52698]
I0530 02:40:01.476379       1 wrap.go:47] GET /healthz: (72.585µs) 200 [kube-probe/1.15+ 127.0.0.1:52746]
I0530 02:40:11.476707       1 wrap.go:47] GET /healthz: (79.648µs) 200 [kube-probe/1.15+ 127.0.0.1:52780]
I0530 02:40:21.476591       1 wrap.go:47] GET /healthz: (83.359µs) 200 [kube-probe/1.15+ 127.0.0.1:52816]
I0530 02:40:28.847278       1 reflector.go:384] k8s.io/client-go/informers/factory.go:133: Watch close - *v1.StatefulSet total 7 items received
I0530 02:40:31.476650       1 wrap.go:47] GET /healthz: (48.207µs) 200 [kube-probe/1.15+ 127.0.0.1:52850]
I0530 02:40:31.883393       1 scheduling_queue.go:895] About to try and schedule pod statefulset-5035/ss-2
I0530 02:40:31.883404       1 scheduler.go:454] Attempting to schedule pod: statefulset-5035/ss-2
I0530 02:40:31.883852       1 scheduler_binder.go:255] AssumePodVolumes for pod "statefulset-5035/ss-2", node "e2e-test-peterhornyack-windows-node-group-9q9v"
I0530 02:40:31.883862       1 scheduler_binder.go:265] AssumePodVolumes for pod "statefulset-5035/ss-2", node "e2e-test-peterhornyack-windows-node-group-9q9v": all PVCs bound and nothing to do
I0530 02:40:31.886622       1 factory.go:734] Attempting to bind ss-2 to e2e-test-peterhornyack-windows-node-group-9q9v
I0530 02:40:31.899739       1 scheduler.go:575] pod statefulset-5035/ss-2 is bound successfully on node e2e-test-peterhornyack-windows-node-group-9q9v, 6 nodes evaluated, 2 nodes were found feasible
I0530 02:40:41.476611       1 wrap.go:47] GET /healthz: (87.365µs) 200 [kube-probe/1.15+ 127.0.0.1:52884]
I0530 02:40:51.476723       1 wrap.go:47] GET /healthz: (83.611µs) 200 [kube-probe/1.15+ 127.0.0.1:52924]
I0530 02:40:55.854741       1 reflector.go:384] k8s.io/client-go/informers/factory.go:133: Watch close - *v1.ReplicaSet total 0 items received
I0530 02:41:01.481410       1 wrap.go:47] GET /healthz: (87.847µs) 200 [kube-probe/1.15+ 127.0.0.1:52974]
I0530 02:41:11.476409       1 wrap.go:47] GET /healthz: (63.096µs) 200 [kube-probe/1.15+ 127.0.0.1:53014]
I0530 02:41:14.851005       1 reflector.go:384] k8s.io/client-go/informers/factory.go:133: Watch close - *v1beta1.PodDisruptionBudget total 0 items received
I0530 02:41:21.476757       1 wrap.go:47] GET /healthz: (86.745µs) 200 [kube-probe/1.15+ 127.0.0.1:53050]
I0530 02:41:24.864244       1 reflector.go:384] k8s.io/client-go/informers/factory.go:133: Watch close - *v1.PersistentVolumeClaim total 0 items received
I0530 02:41:31.476754       1 wrap.go:47] GET /healthz: (76.213µs) 200 [kube-probe/1.15+ 127.0.0.1:53084]
I0530 02:41:41.476433       1 wrap.go:47] GET /healthz: (61.228µs) 200 [kube-probe/1.15+ 127.0.0.1:53118]
I0530 02:41:51.476869       1 wrap.go:47] GET /healthz: (54.346µs) 200 [kube-probe/1.15+ 127.0.0.1:53164]
I0530 02:42:01.476631       1 wrap.go:47] GET /healthz: (76.822µs) 200 [kube-probe/1.15+ 127.0.0.1:53214]
I0530 02:42:11.476598       1 wrap.go:47] GET /healthz: (86.41µs) 200 [kube-probe/1.15+ 127.0.0.1:53248]
I0530 02:42:11.812123       1 reflector.go:384] k8s.io/client-go/informers/factory.go:133: Watch close - *v1.Node total 83 items received
I0530 02:42:19.868189       1 reflector.go:384] cmd/kube-scheduler/app/server.go:223: Watch close - *v1.Pod total 33 items received
I0530 02:42:21.476542       1 wrap.go:47] GET /healthz: (85.456µs) 200 [kube-probe/1.15+ 127.0.0.1:53284]
I0530 02:42:31.477481       1 wrap.go:47] GET /healthz: (49.549µs) 200 [kube-probe/1.15+ 127.0.0.1:53320]
I0530 02:42:41.476671       1 wrap.go:47] GET /healthz: (148.921µs) 200 [kube-probe/1.15+ 127.0.0.1:53356]
I0530 02:42:51.476702       1 wrap.go:47] GET /healthz: (49.301µs) 200 [kube-probe/1.15+ 127.0.0.1:53388]
I0530 02:42:55.840826       1 reflector.go:384] k8s.io/client-go/informers/factory.go:133: Watch close - *v1.Service total 0 items received
I0530 02:43:01.476860       1 wrap.go:47] GET /healthz: (52.587µs) 200 [kube-probe/1.15+ 127.0.0.1:53436]
I0530 02:43:11.476508       1 wrap.go:47] GET /healthz: (90.843µs) 200 [kube-probe/1.15+ 127.0.0.1:53472]
I0530 02:43:21.476756       1 wrap.go:47] GET /healthz: (84.282µs) 200 [kube-probe/1.15+ 127.0.0.1:53510]
I0530 02:43:29.832241       1 reflector.go:384] k8s.io/client-go/informers/factory.go:133: Watch close - *v1.StorageClass total 0 items received
I0530 02:43:31.476773       1 wrap.go:47] GET /healthz: (77.715µs) 200 [kube-probe/1.15+ 127.0.0.1:53544]
I0530 02:43:41.476586       1 wrap.go:47] GET /healthz: (76.147µs) 200 [kube-probe/1.15+ 127.0.0.1:53580]
I0530 02:43:51.476671       1 wrap.go:47] GET /healthz: (76.538µs) 200 [kube-probe/1.15+ 127.0.0.1:53612]
I0530 02:44:01.476332       1 wrap.go:47] GET /healthz: (66.264µs) 200 [kube-probe/1.15+ 127.0.0.1:53662]
I0530 02:44:11.476651       1 wrap.go:47] GET /healthz: (74.709µs) 200 [kube-probe/1.15+ 127.0.0.1:53696]
I0530 02:44:15.822911       1 reflector.go:384] k8s.io/client-go/informers/factory.go:133: Watch close - *v1.ReplicationController total 0 items received
I0530 02:44:21.477036       1 wrap.go:47] GET /healthz: (74.395µs) 200 [kube-probe/1.15+ 127.0.0.1:53734]
I0530 02:44:31.477514       1 wrap.go:47] GET /healthz: (90.174µs) 200 [kube-probe/1.15+ 127.0.0.1:53768]
I0530 02:44:41.476605       1 wrap.go:47] GET /healthz: (89.102µs) 200 [kube-probe/1.15+ 127.0.0.1:53802]
I0530 02:44:51.476559       1 wrap.go:47] GET /healthz: (97.637µs) 200 [kube-probe/1.15+ 127.0.0.1:53834]
I0530 02:45:01.476611       1 wrap.go:47] GET /healthz: (84.887µs) 200 [kube-probe/1.15+ 127.0.0.1:53882]
I0530 02:45:11.476987       1 wrap.go:47] GET /healthz: (65.108µs) 200 [kube-probe/1.15+ 127.0.0.1:53916]
I0530 02:45:21.476917       1 wrap.go:47] GET /healthz: (107.363µs) 200 [kube-probe/1.15+ 127.0.0.1:53952]
I0530 02:45:31.476818       1 wrap.go:47] GET /healthz: (78.079µs) 200 [kube-probe/1.15+ 127.0.0.1:53988]
I0530 02:45:41.476515       1 wrap.go:47] GET /healthz: (76.235µs) 200 [kube-probe/1.15+ 127.0.0.1:54024]
I0530 02:45:51.476846       1 wrap.go:47] GET /healthz: (64.484µs) 200 [kube-probe/1.15+ 127.0.0.1:54056]
I0530 02:46:01.477225       1 wrap.go:47] GET /healthz: (50.496µs) 200 [kube-probe/1.15+ 127.0.0.1:54160]
I0530 02:46:11.476408       1 wrap.go:47] GET /healthz: (58.557µs) 200 [kube-probe/1.15+ 127.0.0.1:54194]
I0530 02:46:21.476827       1 wrap.go:47] GET /healthz: (75.876µs) 200 [kube-probe/1.15+ 127.0.0.1:54230]
I0530 02:46:31.476581       1 wrap.go:47] GET /healthz: (85.868µs) 200 [kube-probe/1.15+ 127.0.0.1:54264]
I0530 02:46:41.476692       1 wrap.go:47] GET /healthz: (105.379µs) 200 [kube-probe/1.15+ 127.0.0.1:54298]
I0530 02:46:51.476433       1 wrap.go:47] GET /healthz: (69.187µs) 200 [kube-probe/1.15+ 127.0.0.1:54332]
I0530 02:47:01.477037       1 wrap.go:47] GET /healthz: (68.121µs) 200 [kube-probe/1.15+ 127.0.0.1:54382]
I0530 02:47:07.861159       1 reflector.go:384] k8s.io/client-go/informers/factory.go:133: Watch close - *v1.PersistentVolume total 0 items received
I0530 02:47:11.476776       1 wrap.go:47] GET /healthz: (77.954µs) 200 [kube-probe/1.15+ 127.0.0.1:54416]
I0530 02:47:21.476741       1 wrap.go:47] GET /healthz: (72.565µs) 200 [kube-probe/1.15+ 127.0.0.1:54452]
I0530 02:47:23.856908       1 reflector.go:384] k8s.io/client-go/informers/factory.go:133: Watch close - *v1.ReplicaSet total 0 items received
I0530 02:47:31.476653       1 wrap.go:47] GET /healthz: (71.063µs) 200 [kube-probe/1.15+ 127.0.0.1:54486]
I0530 02:47:41.476488       1 wrap.go:47] GET /healthz: (58.935µs) 200 [kube-probe/1.15+ 127.0.0.1:54522]
I0530 02:47:51.476571       1 wrap.go:47] GET /healthz: (74.85µs) 200 [kube-probe/1.15+ 127.0.0.1:54554]
I0530 02:48:01.476905       1 wrap.go:47] GET /healthz: (85.297µs) 200 [kube-probe/1.15+ 127.0.0.1:54604]
I0530 02:48:11.476918       1 wrap.go:47] GET /healthz: (89.927µs) 200 [kube-probe/1.15+ 127.0.0.1:54638]
I0530 02:48:11.866435       1 reflector.go:384] k8s.io/client-go/informers/factory.go:133: Watch close - *v1.PersistentVolumeClaim total 0 items received
I0530 02:48:13.849452       1 reflector.go:384] k8s.io/client-go/informers/factory.go:133: Watch close - *v1.StatefulSet total 12 items received
I0530 02:48:20.870453       1 reflector.go:384] cmd/kube-scheduler/app/server.go:223: Watch close - *v1.Pod total 2 items received
I0530 02:48:21.477860       1 wrap.go:47] GET /healthz: (77.824µs) 200 [kube-probe/1.15+ 127.0.0.1:54674]
I0530 02:48:31.476737       1 wrap.go:47] GET /healthz: (55.135µs) 200 [kube-probe/1.15+ 127.0.0.1:54710]
I0530 02:48:41.485132       1 wrap.go:47] GET /healthz: (67.583µs) 200 [kube-probe/1.15+ 127.0.0.1:54744]
I0530 02:48:51.476586       1 wrap.go:47] GET /healthz: (89.785µs) 200 [kube-probe/1.15+ 127.0.0.1:54776]
I0530 02:48:51.842989       1 reflector.go:384] k8s.io/client-go/informers/factory.go:133: Watch close - *v1.Service total 0 items received
I0530 02:49:01.476715       1 wrap.go:47] GET /healthz: (84.755µs) 200 [kube-probe/1.15+ 127.0.0.1:54824]
I0530 02:49:11.476803       1 wrap.go:47] GET /healthz: (74.795µs) 200 [kube-probe/1.15+ 127.0.0.1:54860]
I0530 02:49:21.476609       1 wrap.go:47] GET /healthz: (67.873µs) 200 [kube-probe/1.15+ 127.0.0.1:54896]
I0530 02:49:31.476665       1 wrap.go:47] GET /healthz: (63.991µs) 200 [kube-probe/1.15+ 127.0.0.1:54930]
I0530 02:49:41.476653       1 wrap.go:47] GET /healthz: (63.384µs) 200 [kube-probe/1.15+ 127.0.0.1:54964]
I0530 02:49:51.476660       1 wrap.go:47] GET /healthz: (80.391µs) 200 [kube-probe/1.15+ 127.0.0.1:54998]
I0530 02:50:01.477059       1 wrap.go:47] GET /healthz: (77.769µs) 200 [kube-probe/1.15+ 127.0.0.1:55046]
I0530 02:50:04.814313       1 reflector.go:384] k8s.io/client-go/informers/factory.go:133: Watch close - *v1.Node total 81 items received
I0530 02:50:04.853161       1 reflector.go:384] k8s.io/client-go/informers/factory.go:133: Watch close - *v1beta1.PodDisruptionBudget total 0 items received
I0530 02:50:11.476760       1 wrap.go:47] GET /healthz: (52.123µs) 200 [kube-probe/1.15+ 127.0.0.1:55080]
I0530 02:50:17.834244       1 reflector.go:384] k8s.io/client-go/informers/factory.go:133: Watch close - *v1.StorageClass total 0 items received
I0530 02:50:21.476622       1 wrap.go:47] GET /healthz: (76.903µs) 200 [kube-probe/1.15+ 127.0.0.1:55118]
I0530 02:50:31.477426       1 wrap.go:47] GET /healthz: (49.476µs) 200 [kube-probe/1.15+ 127.0.0.1:55152]
I0530 02:50:41.477010       1 wrap.go:47] GET /healthz: (83.382µs) 200 [kube-probe/1.15+ 127.0.0.1:55186]
I0530 02:50:51.476757       1 wrap.go:47] GET /healthz: (78.618µs) 200 [kube-probe/1.15+ 127.0.0.1:55218]
I0530 02:51:01.476799       1 wrap.go:47] GET /healthz: (85.341µs) 200 [kube-probe/1.15+ 127.0.0.1:55266]
I0530 02:51:11.476562       1 wrap.go:47] GET /healthz: (96.494µs) 200 [kube-probe/1.15+ 127.0.0.1:55300]
I0530 02:51:21.477643       1 wrap.go:47] GET /healthz: (75.303µs) 200 [kube-probe/1.15+ 127.0.0.1:55338]
I0530 02:51:31.476421       1 wrap.go:47] GET /healthz: (75.847µs) 200 [kube-probe/1.15+ 127.0.0.1:55374]
I0530 02:51:41.476890       1 wrap.go:47] GET /healthz: (63.514µs) 200 [kube-probe/1.15+ 127.0.0.1:55408]
I0530 02:51:51.476756       1 wrap.go:47] GET /healthz: (83.038µs) 200 [kube-probe/1.15+ 127.0.0.1:55442]
I0530 02:52:01.476790       1 wrap.go:47] GET /healthz: (69.31µs) 200 [kube-probe/1.15+ 127.0.0.1:55490]
I0530 02:52:11.476432       1 wrap.go:47] GET /healthz: (50.27µs) 200 [kube-probe/1.15+ 127.0.0.1:55536]
I0530 02:52:21.476708       1 wrap.go:47] GET /healthz: (88.55µs) 200 [kube-probe/1.15+ 127.0.0.1:55572]
I0530 02:52:31.478254       1 wrap.go:47] GET /healthz: (79.255µs) 200 [kube-probe/1.15+ 127.0.0.1:55606]
I0530 02:52:41.478015       1 wrap.go:47] GET /healthz: (48.724µs) 200 [kube-probe/1.15+ 127.0.0.1:55642]
I0530 02:52:50.825233       1 reflector.go:384] k8s.io/client-go/informers/factory.go:133: Watch close - *v1.ReplicationController total 0 items received
I0530 02:52:51.476551       1 wrap.go:47] GET /healthz: (79.038µs) 200 [kube-probe/1.15+ 127.0.0.1:55676]
I0530 02:53:01.477372       1 wrap.go:47] GET /healthz: (65.058µs) 200 [kube-probe/1.15+ 127.0.0.1:55724]
I0530 02:53:11.476665       1 wrap.go:47] GET /healthz: (70.937µs) 200 [kube-probe/1.15+ 127.0.0.1:55758]
I0530 02:53:11.859101       1 reflector.go:384] k8s.io/client-go/informers/factory.go:133: Watch close - *v1.ReplicaSet total 0 items received
I0530 02:53:21.476922       1 wrap.go:47] GET /healthz: (57.857µs) 200 [kube-probe/1.15+ 127.0.0.1:55794]
I0530 02:53:31.476620       1 wrap.go:47] GET /healthz: (72.275µs) 200 [kube-probe/1.15+ 127.0.0.1:55828]
I0530 02:53:41.476672       1 wrap.go:47] GET /healthz: (75.018µs) 200 [kube-probe/1.15+ 127.0.0.1:55862]
I0530 02:53:51.482142       1 wrap.go:47] GET /healthz: (78.253µs) 200 [kube-probe/1.15+ 127.0.0.1:55896]
I0530 02:54:01.476731       1 wrap.go:47] GET /healthz: (84.323µs) 200 [kube-probe/1.15+ 127.0.0.1:55944]
I0530 02:54:09.851731       1 reflector.go:384] k8s.io/client-go/informers/factory.go:133: Watch close - *v1.StatefulSet total 1 items received
I0530 02:54:11.476506       1 wrap.go:47] GET /healthz: (91.197µs) 200 [kube-probe/1.15+ 127.0.0.1:55978]
I0530 02:54:21.476801       1 wrap.go:47] GET /healthz: (79.633µs) 200 [kube-probe/1.15+ 127.0.0.1:56018]
I0530 02:54:31.476666       1 wrap.go:47] GET /healthz: (75.639µs) 200 [kube-probe/1.15+ 127.0.0.1:56052]
I0530 02:54:39.872560       1 reflector.go:384] cmd/kube-scheduler/app/server.go:223: Watch close - *v1.Pod total 1 items received
I0530 02:54:41.476733       1 wrap.go:47] GET /healthz: (78.055µs) 200 [kube-probe/1.15+ 127.0.0.1:56086]
I0530 02:54:51.476961       1 wrap.go:47] GET /healthz: (79.494µs) 200 [kube-probe/1.15+ 127.0.0.1:56118]
I0530 02:55:01.476904       1 wrap.go:47] GET /healthz: (76.527µs) 200 [kube-probe/1.15+ 127.0.0.1:56168]
I0530 02:55:11.479989       1 wrap.go:47] GET /healthz: (79.12µs) 200 [kube-probe/1.15+ 127.0.0.1:56202]
I0530 02:55:21.476834       1 wrap.go:47] GET /healthz: (127.85µs) 200 [kube-probe/1.15+ 127.0.0.1:56238]
I0530 02:55:31.476480       1 wrap.go:47] GET /healthz: (47.759µs) 200 [kube-probe/1.15+ 127.0.0.1:56272]
I0530 02:55:37.816256       1 reflector.go:384] k8s.io/client-go/informers/factory.go:133: Watch close - *v1.Node total 57 items received
I0530 02:55:41.476842       1 wrap.go:47] GET /healthz: (76.676µs) 200 [kube-probe/1.15+ 127.0.0.1:56308]
I0530 02:55:51.477305       1 wrap.go:47] GET /healthz: (73.835µs) 200 [kube-probe/1.15+ 127.0.0.1:56342]
I0530 02:56:01.476822       1 wrap.go:47] GET /healthz: (81.33µs) 200 [kube-probe/1.15+ 127.0.0.1:56462]
I0530 02:56:11.476573       1 wrap.go:47] GET /healthz: (87.436µs) 200 [kube-probe/1.15+ 127.0.0.1:56502]
I0530 02:56:21.476735       1 wrap.go:47] GET /healthz: (106.985µs) 200 [kube-probe/1.15+ 127.0.0.1:56538]
I0530 02:56:29.870254       1 reflector.go:384] k8s.io/client-go/informers/factory.go:133: Watch close - *v1.PersistentVolumeClaim total 0 items received
I0530 02:56:31.479698       1 wrap.go:47] GET /healthz: (2.973166ms) 200 [kube-probe/1.15+ 127.0.0.1:56572]
I0530 02:56:41.476487       1 wrap.go:47] GET /healthz: (62.53µs) 200 [kube-probe/1.15+ 127.0.0.1:56606]
I0530 02:56:45.864142       1 reflector.go:384] k8s.io/client-go/informers/factory.go:133: Watch close - *v1.PersistentVolume total 0 items received
I0530 02:56:51.476684       1 wrap.go:47] GET /healthz: (63.296µs) 200 [kube-probe/1.15+ 127.0.0.1:56638]
I0530 02:57:01.476637       1 wrap.go:47] GET /healthz: (97.054µs) 200 [kube-probe/1.15+ 127.0.0.1:56686]
I0530 02:57:11.476773       1 wrap.go:47] GET /healthz: (74.962µs) 200 [kube-probe/1.15+ 127.0.0.1:56722]
I0530 02:57:15.855223       1 reflector.go:384] k8s.io/client-go/informers/factory.go:133: Watch close - *v1beta1.PodDisruptionBudget total 0 items received
I0530 02:57:21.476606       1 wrap.go:47] GET /healthz: (86.082µs) 200 [kube-probe/1.15+ 127.0.0.1:56758]
I0530 02:57:31.476810       1 wrap.go:47] GET /healthz: (136.682µs) 200 [kube-probe/1.15+ 127.0.0.1:56794]
I0530 02:57:41.476514       1 wrap.go:47] GET /healthz: (79.856µs) 200 [kube-probe/1.15+ 127.0.0.1:56828]
I0530 02:57:43.845010       1 reflector.go:384] k8s.io/client-go/informers/factory.go:133: Watch close - *v1.Service total 0 items received
I0530 02:57:50.836571       1 reflector.go:384] k8s.io/client-go/informers/factory.go:133: Watch close - *v1.StorageClass total 0 items received
I0530 02:57:51.476748       1 wrap.go:47] GET /healthz: (75.448µs) 200 [kube-probe/1.15+ 127.0.0.1:56860]
I0530 02:58:01.476866       1 wrap.go:47] GET /healthz: (79.218µs) 200 [kube-probe/1.15+ 127.0.0.1:56908]
I0530 02:58:11.476967       1 wrap.go:47] GET /healthz: (76.152µs) 200 [kube-probe/1.15+ 127.0.0.1:56942]
I0530 02:58:21.476981       1 wrap.go:47] GET /healthz: (93.637µs) 200 [kube-probe/1.15+ 127.0.0.1:56978]
I0530 02:58:31.477246       1 wrap.go:47] GET /healthz: (76.596µs) 200 [kube-probe/1.15+ 127.0.0.1:57012]
I0530 02:58:39.861446       1 reflector.go:384] k8s.io/client-go/informers/factory.go:133: Watch close - *v1.ReplicaSet total 0 items received
I0530 02:58:41.476973       1 wrap.go:47] GET /healthz: (49.284µs) 200 [kube-probe/1.15+ 127.0.0.1:57050]
I0530 02:58:51.476589       1 wrap.go:47] GET /healthz: (72.851µs) 200 [kube-probe/1.15+ 127.0.0.1:57082]
I0530 02:59:01.477631       1 wrap.go:47] GET /healthz: (1.187492ms) 200 [kube-probe/1.15+ 127.0.0.1:57130]
I0530 02:59:11.476584       1 wrap.go:47] GET /healthz: (65.102µs) 200 [kube-probe/1.15+ 127.0.0.1:57164]
I0530 02:59:21.476604       1 wrap.go:47] GET /healthz: (72.711µs) 200 [kube-probe/1.15+ 127.0.0.1:57200]
I0530 02:59:31.476521       1 wrap.go:47] GET /healthz: (72.892µs) 200 [kube-probe/1.15+ 127.0.0.1:57234]
I0530 02:59:41.476509       1 wrap.go:47] GET /healthz: (88.598µs) 200 [kube-probe/1.15+ 127.0.0.1:57268]
I0530 02:59:51.476634       1 wrap.go:47] GET /healthz: (76.338µs) 200 [kube-probe/1.15+ 127.0.0.1:57304]
I0530 03:00:01.476707       1 wrap.go:47] GET /healthz: (74.483µs) 200 [kube-probe/1.15+ 127.0.0.1:57352]
I0530 03:00:11.476802       1 wrap.go:47] GET /healthz: (126.628µs) 200 [kube-probe/1.15+ 127.0.0.1:57388]
I0530 03:00:21.480183       1 wrap.go:47] GET /healthz: (79.424µs) 200 [kube-probe/1.15+ 127.0.0.1:57424]
I0530 03:00:31.479533       1 wrap.go:47] GET /healthz: (93.79µs) 200 [kube-probe/1.15+ 127.0.0.1:57458]
I0530 03:00:41.476541       1 wrap.go:47] GET /healthz: (85.459µs) 200 [kube-probe/1.15+ 127.0.0.1:57492]
I0530 03:00:41.874670       1 reflector.go:384] cmd/kube-scheduler/app/server.go:223: Watch close - *v1.Pod total 5 items received
I0530 03:00:51.477725       1 wrap.go:47] GET /healthz: (65.882µs) 200 [kube-probe/1.15+ 127.0.0.1:57524]
I0530 03:01:01.477551       1 wrap.go:47] GET /healthz: (846.767µs) 200 [kube-probe/1.15+ 127.0.0.1:57574]
I0530 03:01:11.476920       1 wrap.go:47] GET /healthz: (70.802µs) 200 [kube-probe/1.15+ 127.0.0.1:57608]
I0530 03:01:21.476597       1 wrap.go:47] GET /healthz: (74.715µs) 200 [kube-probe/1.15+ 127.0.0.1:57644]
I0530 03:01:31.476814       1 wrap.go:47] GET /healthz: (70.971µs) 200 [kube-probe/1.15+ 127.0.0.1:57684]
I0530 03:01:41.476482       1 wrap.go:47] GET /healthz: (63.481µs) 200 [kube-probe/1.15+ 127.0.0.1:57722]
I0530 03:01:51.476841       1 wrap.go:47] GET /healthz: (67.84µs) 200 [kube-probe/1.15+ 127.0.0.1:57754]
I0530 03:01:53.098375       1 scheduling_queue.go:895] About to try and schedule pod volume-4561/exec-volume-test-gcepd-l7jb
I0530 03:01:53.098389       1 scheduler.go:454] Attempting to schedule pod: volume-4561/exec-volume-test-gcepd-l7jb
I0530 03:01:53.098953       1 scheduler_binder.go:255] AssumePodVolumes for pod "volume-4561/exec-volume-test-gcepd-l7jb", node "e2e-test-peterhornyack-windows-node-group-jpxd"
I0530 03:01:53.098965       1 scheduler_binder.go:265] AssumePodVolumes for pod "volume-4561/exec-volume-test-gcepd-l7jb", node "e2e-test-peterhornyack-windows-node-group-jpxd": all PVCs bound and nothing to do
I0530 03:01:53.098997       1 factory.go:734] Attempting to bind exec-volume-test-gcepd-l7jb to e2e-test-peterhornyack-windows-node-group-jpxd
I0530 03:01:53.106746       1 scheduler.go:575] pod volume-4561/exec-volume-test-gcepd-l7jb is bound successfully on node e2e-test-peterhornyack-windows-node-group-jpxd, 6 nodes evaluated, 3 nodes were found feasible
I0530 03:02:01.477675       1 wrap.go:47] GET /healthz: (79.082µs) 200 [kube-probe/1.15+ 127.0.0.1:57802]
I0530 03:02:06.818629       1 reflector.go:384] k8s.io/client-go/informers/factory.go:133: Watch close - *v1.Node total 68 items received
I0530 03:02:11.479114       1 wrap.go:47] GET /healthz: (72.983µs) 200 [kube-probe/1.15+ 127.0.0.1:57838]
I0530 03:02:21.476625       1 wrap.go:47] GET /healthz: (81.877µs) 200 [kube-probe/1.15+ 127.0.0.1:57874]
I0530 03:02:31.476651       1 wrap.go:47] GET /healthz: (87.204µs) 200 [kube-probe/1.15+ 127.0.0.1:57908]
I0530 03:02:41.476885       1 wrap.go:47] GET /healthz: (69.624µs) 200 [kube-probe/1.15+ 127.0.0.1:57942]
I0530 03:02:47.827337       1 reflector.go:384] k8s.io/client-go/informers/factory.go:133: Watch close - *v1.ReplicationController total 0 items received
I0530 03:02:51.476902       1 wrap.go:47] GET /healthz: (78.947µs) 200 [kube-probe/1.15+ 127.0.0.1:57976]
I0530 03:03:01.476633       1 wrap.go:47] GET /healthz: (86.718µs) 200 [kube-probe/1.15+ 127.0.0.1:58024]
I0530 03:03:11.476722       1 wrap.go:47] GET /healthz: (79.153µs) 200 [kube-probe/1.15+ 127.0.0.1:58060]
I0530 03:03:21.476666       1 wrap.go:47] GET /healthz: (93.817µs) 200 [kube-probe/1.15+ 127.0.0.1:58098]
I0530 03:03:31.476797       1 wrap.go:47] GET /healthz: (78.648µs) 200 [kube-probe/1.15+ 127.0.0.1:58132]
I0530 03:03:41.476475       1 wrap.go:47] GET /healthz: (50.569µs) 200 [kube-probe/1.15+ 127.0.0.1:58166]
I0530 03:03:51.476813       1 wrap.go:47] GET /healthz: (74.357µs) 200 [kube-probe/1.15+ 127.0.0.1:58198]
I0530 03:03:57.853791       1 reflector.go:384] k8s.io/client-go/informers/factory.go:133: Watch close - *v1.StatefulSet total 4 items received
I0530 03:04:01.476517       1 wrap.go:47] GET /healthz: (123.003µs) 200 [kube-probe/1.15+ 127.0.0.1:58374]
I0530 03:04:10.873245       1 reflector.go:384] k8s.io/client-go/informers/factory.go:133: Watch close - *v1.PersistentVolumeClaim total 0 items received
I0530 03:04:11.478105       1 wrap.go:47] GET /healthz: (76.25µs) 200 [kube-probe/1.15+ 127.0.0.1:58408]
I0530 03:04:21.477234       1 wrap.go:47] GET /healthz: (52.42µs) 200 [kube-probe/1.15+ 127.0.0.1:58444]
I0530 03:04:31.477033       1 wrap.go:47] GET /healthz: (83.506µs) 200 [kube-probe/1.15+ 127.0.0.1:58482]
I0530 03:04:41.476603       1 wrap.go:47] GET /healthz: (87.939µs) 200 [kube-probe/1.15+ 127.0.0.1:58516]
I0530 03:04:51.476702       1 wrap.go:47] GET /healthz: (81.778µs) 200 [kube-probe/1.15+ 127.0.0.1:58548]
I0530 03:05:01.476879       1 wrap.go:47] GET /healthz: (81.54µs) 200 [kube-probe/1.15+ 127.0.0.1:58596]
I0530 03:05:11.476584       1 wrap.go:47] GET /healthz: (82.332µs) 200 [kube-probe/1.15+ 127.0.0.1:58630]
I0530 03:05:21.476638       1 wrap.go:47] GET /healthz: (83.69µs) 200 [kube-probe/1.15+ 127.0.0.1:58670]
I0530 03:05:31.481690       1 wrap.go:47] GET /healthz: (66.142µs) 200 [kube-probe/1.15+ 127.0.0.1:58704]
I0530 03:05:41.476658       1 wrap.go:47] GET /healthz: (70.765µs) 200 [kube-probe/1.15+ 127.0.0.1:58740]
I0530 03:05:51.476661       1 wrap.go:47] GET /healthz: (66.537µs) 200 [kube-probe/1.15+ 127.0.0.1:58772]
I0530 03:06:00.857169       1 reflector.go:384] k8s.io/client-go/informers/factory.go:133: Watch close - *v1beta1.PodDisruptionBudget total 0 items received
I0530 03:06:01.476515       1 wrap.go:47] GET /healthz: (84.618µs) 200 [kube-probe/1.15+ 127.0.0.1:58822]
I0530 03:06:01.866684       1 reflector.go:384] k8s.io/client-go/informers/factory.go:133: Watch close - *v1.PersistentVolume total 0 items received
I0530 03:06:11.476800       1 wrap.go:47] GET /healthz: (69.358µs) 200 [kube-probe/1.15+ 127.0.0.1:58858]
I0530 03:06:21.476442       1 wrap.go:47] GET /healthz: (73.766µs) 200 [kube-probe/1.15+ 127.0.0.1:58894]
I0530 03:06:24.838554       1 reflector.go:384] k8s.io/client-go/informers/factory.go:133: Watch close - *v1.StorageClass total 0 items received
I0530 03:06:31.476636       1 wrap.go:47] GET /healthz: (84.42µs) 200 [kube-probe/1.15+ 127.0.0.1:58928]
I0530 03:06:41.477570       1 wrap.go:47] GET /healthz: (122.549µs) 200 [kube-probe/1.15+ 127.0.0.1:58962]
I0530 03:06:51.476685       1 wrap.go:47] GET /healthz: (74.956µs) 200 [kube-probe/1.15+ 127.0.0.1:58998]
I0530 03:07:01.476845       1 wrap.go:47] GET /healthz: (100.867µs) 200 [kube-probe/1.15+ 127.0.0.1:59046]
I0530 03:07:09.863639       1 reflector.go:384] k8s.io/client-go/informers/factory.go:133: Watch close - *v1.ReplicaSet total 0 items received
I0530 03:07:11.476721       1 wrap.go:47] GET /healthz: (76.938µs) 200 [kube-probe/1.15+ 127.0.0.1:59086]
I0530 03:07:14.940801       1 scheduling_queue.go:895] About to try and schedule pod volume-1445/exec-volume-test-gcepd-preprovisionedpv-6bx5
I0530 03:07:14.940830       1 scheduler.go:454] Attempting to schedule pod: volume-1445/exec-volume-test-gcepd-preprovisionedpv-6bx5
I0530 03:07:14.942239       1 scheduler_binder.go:651] All bound volumes for Pod "volume-1445/exec-volume-test-gcepd-preprovisionedpv-6bx5" match with Node "e2e-test-peterhornyack-windows-node-group-9q9v"
I0530 03:07:14.942326       1 scheduler_binder.go:651] All bound volumes for Pod "volume-1445/exec-volume-test-gcepd-preprovisionedpv-6bx5" match with Node "e2e-test-peterhornyack-windows-node-group-1vjk"
I0530 03:07:14.942364       1 scheduler_binder.go:651] All bound volumes for Pod "volume-1445/exec-volume-test-gcepd-preprovisionedpv-6bx5" match with Node "e2e-test-peterhornyack-windows-node-group-jpxd"
I0530 03:07:14.944646       1 scheduler_binder.go:255] AssumePodVolumes for pod "volume-1445/exec-volume-test-gcepd-preprovisionedpv-6bx5", node "e2e-test-peterhornyack-windows-node-group-jpxd"
I0530 03:07:14.944679       1 scheduler_binder.go:265] AssumePodVolumes for pod "volume-1445/exec-volume-test-gcepd-preprovisionedpv-6bx5", node "e2e-test-peterhornyack-windows-node-group-jpxd": all PVCs bound and nothing to do
I0530 03:07:14.944750       1 factory.go:734] Attempting to bind exec-volume-test-gcepd-preprovisionedpv-6bx5 to e2e-test-peterhornyack-windows-node-group-jpxd
I0530 03:07:14.954159       1 scheduler.go:575] pod volume-1445/exec-volume-test-gcepd-preprovisionedpv-6bx5 is bound successfully on node e2e-test-peterhornyack-windows-node-group-jpxd, 6 nodes evaluated, 3 nodes were found feasible
I0530 03:07:17.876932       1 reflector.go:384] cmd/kube-scheduler/app/server.go:223: Watch close - *v1.Pod total 12 items received
I0530 03:07:19.847074       1 reflector.go:384] k8s.io/client-go/informers/factory.go:133: Watch close - *v1.Service total 1 items received
I0530 03:07:21.476757       1 wrap.go:47] GET /healthz: (80.203µs) 200 [kube-probe/1.15+ 127.0.0.1:59122]
I0530 03:07:31.476578       1 wrap.go:47] GET /healthz: (47.541µs) 200 [kube-probe/1.15+ 127.0.0.1:59158]
I0530 03:07:41.477006       1 wrap.go:47] GET /healthz: (66.332µs) 200 [kube-probe/1.15+ 127.0.0.1:59192]
I0530 03:07:51.476425       1 wrap.go:47] GET /healthz: (51.927µs) 200 [kube-probe/1.15+ 127.0.0.1:59224]
I0530 03:08:01.478321       1 wrap.go:47] GET /healthz: (70.371µs) 200 [kube-probe/1.15+ 127.0.0.1:59274]
I0530 03:08:11.476771       1 wrap.go:47] GET /healthz: (77.093µs) 200 [kube-probe/1.15+ 127.0.0.1:59308]
I0530 03:08:21.476705       1 wrap.go:47] GET /healthz: (65.605µs) 200 [kube-probe/1.15+ 127.0.0.1:59344]
I0530 03:08:31.476659       1 wrap.go:47] GET /healthz: (87.809µs) 200 [kube-probe/1.15+ 127.0.0.1:59378]
I0530 03:08:41.476948       1 wrap.go:47] GET /healthz: (91.501µs) 200 [kube-probe/1.15+ 127.0.0.1:59412]
I0530 03:08:51.476707       1 wrap.go:47] GET /healthz: (75.822µs) 200 [kube-probe/1.15+ 127.0.0.1:59444]
I0530 03:09:01.476775       1 wrap.go:47] GET /healthz: (88.071µs) 200 [kube-probe/1.15+ 127.0.0.1:59494]
I0530 03:09:07.855959       1 reflector.go:384] k8s.io/client-go/informers/factory.go:133: Watch close - *v1.StatefulSet total 0 items received
I0530 03:09:09.689602       1 scheduling_queue.go:895] About to try and schedule pod secrets-5024/pod-secrets-b0d9ec09-3ba0-4730-95e1-0e797f720e30
I0530 03:09:09.689618       1 scheduler.go:454] Attempting to schedule pod: secrets-5024/pod-secrets-b0d9ec09-3ba0-4730-95e1-0e797f720e30
I0530 03:09:09.690868       1 scheduler_binder.go:255] AssumePodVolumes for pod "secrets-5024/pod-secrets-b0d9ec09-3ba0-4730-95e1-0e797f720e30", node "e2e-test-peterhornyack-windows-node-group-jpxd"
I0530 03:09:09.690882       1 scheduler_binder.go:265] AssumePodVolumes for pod "secrets-5024/pod-secrets-b0d9ec09-3ba0-4730-95e1-0e797f720e30", node "e2e-test-peterhornyack-windows-node-group-jpxd": all PVCs bound and nothing to do
I0530 03:09:09.690943       1 factory.go:734] Attempting to bind pod-secrets-b0d9ec09-3ba0-4730-95e1-0e797f720e30 to e2e-test-peterhornyack-windows-node-group-jpxd
I0530 03:09:09.699730       1 scheduler.go:575] pod secrets-5024/pod-secrets-b0d9ec09-3ba0-4730-95e1-0e797f720e30 is bound successfully on node e2e-test-peterhornyack-windows-node-group-jpxd, 6 nodes evaluated, 3 nodes were found feasible
I0530 03:09:11.476712       1 wrap.go:47] GET /healthz: (85.973µs) 200 [kube-probe/1.15+ 127.0.0.1:59528]
I0530 03:09:17.821705       1 reflector.go:384] k8s.io/client-go/informers/factory.go:133: Watch close - *v1.Node total 81 items received
I0530 03:09:21.476731       1 wrap.go:47] GET /healthz: (118.889µs) 200 [kube-probe/1.15+ 127.0.0.1:59566]
I0530 03:09:31.476548       1 wrap.go:47] GET /healthz: (49.749µs) 200 [kube-probe/1.15+ 127.0.0.1:59600]
I0530 03:09:41.476887       1 wrap.go:47] GET /healthz: (70.347µs) 200 [kube-probe/1.15+ 127.0.0.1:59634]
I0530 03:09:51.477057       1 wrap.go:47] GET /healthz: (67.069µs) 200 [kube-probe/1.15+ 127.0.0.1:59666]
I0530 03:10:01.476442       1 wrap.go:47] GET /healthz: (51.4µs) 200 [kube-probe/1.15+ 127.0.0.1:59714]
I0530 03:10:11.476572       1 wrap.go:47] GET /healthz: (50.213µs) 200 [kube-probe/1.15+ 127.0.0.1:59748]
I0530 03:10:21.477068       1 wrap.go:47] GET /healthz: (85.466µs) 200 [kube-probe/1.15+ 127.0.0.1:59784]
I0530 03:10:31.477043       1 wrap.go:47] GET /healthz: (71.381µs) 200 [kube-probe/1.15+ 127.0.0.1:59822]
I0530 03:10:41.477535       1 wrap.go:47] GET /healthz: (73.613µs) 200 [kube-probe/1.15+ 127.0.0.1:59856]
I0530 03:10:46.875588       1 reflector.go:384] k8s.io/client-go/informers/factory.go:133: Watch close - *v1.PersistentVolumeClaim total 5 items received
I0530 03:10:51.477083       1 wrap.go:47] GET /healthz: (84.817µs) 200 [kube-probe/1.15+ 127.0.0.1:59888]
I0530 03:11:01.477332       1 wrap.go:47] GET /healthz: (94.142µs) 200 [kube-probe/1.15+ 127.0.0.1:59936]
I0530 03:11:11.476933       1 wrap.go:47] GET /healthz: (76.99µs) 200 [kube-probe/1.15+ 127.0.0.1:59970]
I0530 03:11:21.476718       1 wrap.go:47] GET /healthz: (75.832µs) 200 [kube-probe/1.15+ 127.0.0.1:60008]
I0530 03:11:30.841008       1 reflector.go:384] k8s.io/client-go/informers/factory.go:133: Watch close - *v1.StorageClass total 0 items received
I0530 03:11:31.476665       1 wrap.go:47] GET /healthz: (59.314µs) 200 [kube-probe/1.15+ 127.0.0.1:60042]
I0530 03:11:41.476630       1 wrap.go:47] GET /healthz: (76.119µs) 200 [kube-probe/1.15+ 127.0.0.1:60080]
I0530 03:11:51.476779       1 wrap.go:47] GET /healthz: (58.334µs) 200 [kube-probe/1.15+ 127.0.0.1:60114]
I0530 03:12:00.829430       1 reflector.go:384] k8s.io/client-go/informers/factory.go:133: Watch close - *v1.ReplicationController total 0 items received
I0530 03:12:01.476785       1 wrap.go:47] GET /healthz: (64.209µs) 200 [kube-probe/1.15+ 127.0.0.1:60162]
I0530 03:12:11.476756       1 wrap.go:47] GET /healthz: (52.258µs) 200 [kube-probe/1.15+ 127.0.0.1:60196]
I0530 03:12:11.865877       1 reflector.go:384] k8s.io/client-go/informers/factory.go:133: Watch close - *v1.ReplicaSet total 0 items received
I0530 03:12:21.476448       1 wrap.go:47] GET /healthz: (58.444µs) 200 [kube-probe/1.15+ 127.0.0.1:60232]
I0530 03:12:31.479513       1 wrap.go:47] GET /healthz: (75.615µs) 200 [kube-probe/1.15+ 127.0.0.1:60266]
I0530 03:12:41.476529       1 wrap.go:47] GET /healthz: (77.08µs) 200 [kube-probe/1.15+ 127.0.0.1:60300]
I0530 03:12:51.483313       1 wrap.go:47] GET /healthz: (68.173µs) 200 [kube-probe/1.15+ 127.0.0.1:60334]
I0530 03:13:01.538131       1 wrap.go:47] GET /healthz: (84.5µs) 200 [kube-probe/1.15+ 127.0.0.1:60382]
I0530 03:13:11.476599       1 wrap.go:47] GET /healthz: (82.384µs) 200 [kube-probe/1.15+ 127.0.0.1:60416]
I0530 03:13:20.859284       1 reflector.go:384] k8s.io/client-go/informers/factory.go:133: Watch close - *v1beta1.PodDisruptionBudget total 0 items received
I0530 03:13:21.476929       1 wrap.go:47] GET /healthz: (49.59µs) 200 [kube-probe/1.15+ 127.0.0.1:60454]
I0530 03:13:31.476827       1 wrap.go:47] GET /healthz: (47.4µs) 200 [kube-probe/1.15+ 127.0.0.1:60488]
I0530 03:13:41.476827       1 wrap.go:47] GET /healthz: (64.718µs) 200 [kube-probe/1.15+ 127.0.0.1:60522]
I0530 03:13:51.476910       1 wrap.go:47] GET /healthz: (79.389µs) 200 [kube-probe/1.15+ 127.0.0.1:60554]
I0530 03:14:01.476890       1 wrap.go:47] GET /healthz: (79.41µs) 200 [kube-probe/1.15+ 127.0.0.1:60604]
I0530 03:14:04.869028       1 reflector.go:384] k8s.io/client-go/informers/factory.go:133: Watch close - *v1.PersistentVolume total 7 items received
I0530 03:14:11.476670       1 wrap.go:47] GET /healthz: (50.93µs) 200 [kube-probe/1.15+ 127.0.0.1:60638]
I0530 03:14:21.476613       1 wrap.go:47] GET /healthz: (74.521µs) 200 [kube-probe/1.15+ 127.0.0.1:60674]
I0530 03:14:26.265662       1 scheduling_queue.go:895] About to try and schedule pod statefulset-1120/ss2-0
I0530 03:14:26.265677       1 scheduler.go:454] Attempting to schedule pod: statefulset-1120/ss2-0
I0530 03:14:26.266263       1 scheduler_binder.go:255] AssumePodVolumes for pod "statefulset-1120/ss2-0", node "e2e-test-peterhornyack-windows-node-group-1vjk"
I0530 03:14:26.266275       1 scheduler_binder.go:265] AssumePodVolumes for pod "statefulset-1120/ss2-0", node "e2e-test-peterhornyack-windows-node-group-1vjk": all PVCs bound and nothing to do
I0530 03:14:26.266335       1 factory.go:734] Attempting to bind ss2-0 to e2e-test-peterhornyack-windows-node-group-1vjk
I0530 03:14:26.285917       1 scheduler.go:575] pod statefulset-1120/ss2-0 is bound successfully on node e2e-test-peterhornyack-windows-node-group-1vjk, 6 nodes evaluated, 3 nodes were found feasible
I0530 03:14:31.476907       1 wrap.go:47] GET /healthz: (51.409µs) 200 [kube-probe/1.15+ 127.0.0.1:60710]
I0530 03:14:33.223658       1 scheduling_queue.go:895] About to try and schedule pod statefulset-1120/ss2-1
I0530 03:14:33.223672       1 scheduler.go:454] Attempting to schedule pod: statefulset-1120/ss2-1
I0530 03:14:33.224820       1 scheduler_binder.go:255] AssumePodVolumes for pod "statefulset-1120/ss2-1", node "e2e-test-peterhornyack-windows-node-group-jpxd"
I0530 03:14:33.224832       1 scheduler_binder.go:265] AssumePodVolumes for pod "statefulset-1120/ss2-1", node "e2e-test-peterhornyack-windows-node-group-jpxd": all PVCs bound and nothing to do
I0530 03:14:33.224888       1 factory.go:734] Attempting to bind ss2-1 to e2e-test-peterhornyack-windows-node-group-jpxd
I0530 03:14:33.235582       1 scheduler.go:575] pod statefulset-1120/ss2-1 is bound successfully on node e2e-test-peterhornyack-windows-node-group-jpxd, 6 nodes evaluated, 3 nodes were found feasible
I0530 03:14:40.878987       1 reflector.go:384] cmd/kube-scheduler/app/server.go:223: Watch close - *v1.Pod total 16 items received
I0530 03:14:41.476496       1 wrap.go:47] GET /healthz: (74.296µs) 200 [kube-probe/1.15+ 127.0.0.1:60744]
I0530 03:14:51.476667       1 wrap.go:47] GET /healthz: (69.254µs) 200 [kube-probe/1.15+ 127.0.0.1:60778]
I0530 03:15:01.476622       1 wrap.go:47] GET /healthz: (82.312µs) 200 [kube-probe/1.15+ 127.0.0.1:60826]
I0530 03:15:11.476676       1 wrap.go:47] GET /healthz: (73.172µs) 200 [kube-probe/1.15+ 127.0.0.1:60862]
I0530 03:15:21.477069       1 wrap.go:47] GET /healthz: (68.53µs) 200 [kube-probe/1.15+ 127.0.0.1:60898]
I0530 03:15:28.849318       1 reflector.go:384] k8s.io/client-go/informers/factory.go:133: Watch close - *v1.Service total 1 items received
I0530 03:15:31.476417       1 wrap.go:47] GET /healthz: (75.249µs) 200 [kube-probe/1.15+ 127.0.0.1:60932]
I0530 03:15:41.476749       1 wrap.go:47] GET /healthz: (92.464µs) 200 [kube-probe/1.15+ 127.0.0.1:60966]
I0530 03:15:51.476733       1 wrap.go:47] GET /healthz: (83.307µs) 200 [kube-probe/1.15+ 127.0.0.1:60998]
I0530 03:15:58.827130       1 reflector.go:384] k8s.io/client-go/informers/factory.go:133: Watch close - *v1.Node total 66 items received
I0530 03:16:01.476774       1 wrap.go:47] GET /healthz: (72.681µs) 200 [kube-probe/1.15+ 127.0.0.1:32814]
I0530 03:16:11.476641       1 wrap.go:47] GET /healthz: (90.502µs) 200 [kube-probe/1.15+ 127.0.0.1:32848]
I0530 03:16:21.476625       1 wrap.go:47] GET /healthz: (86.116µs) 200 [kube-probe/1.15+ 127.0.0.1:32890]
I0530 03:16:31.476859       1 wrap.go:47] GET /healthz: (81.666µs) 200 [kube-probe/1.15+ 127.0.0.1:32924]
I0530 03:16:41.476606       1 wrap.go:47] GET /healthz: (76.255µs) 200 [kube-probe/1.15+ 127.0.0.1:32958]
I0530 03:16:42.858276       1 reflector.go:384] k8s.io/client-go/informers/factory.go:133: Watch close - *v1.StatefulSet total 3 items received
I0530 03:16:51.476660       1 wrap.go:47] GET /healthz: (54.923µs) 200 [kube-probe/1.15+ 127.0.0.1:32990]
I0530 03:17:01.476781       1 wrap.go:47] GET /healthz: (79.114µs) 200 [kube-probe/1.15+ 127.0.0.1:33038]
I0530 03:17:11.476689       1 wrap.go:47] GET /healthz: (151.333µs) 200 [kube-probe/1.15+ 127.0.0.1:33072]
I0530 03:17:21.476854       1 wrap.go:47] GET /healthz: (64.014µs) 200 [kube-probe/1.15+ 127.0.0.1:33108]
I0530 03:17:31.476756       1 wrap.go:47] GET /healthz: (49.769µs) 200 [kube-probe/1.15+ 127.0.0.1:33144]
I0530 03:17:41.476977       1 wrap.go:47] GET /healthz: (70.19µs) 200 [kube-probe/1.15+ 127.0.0.1:33178]
I0530 03:17:46.877781       1 reflector.go:384] k8s.io/client-go/informers/factory.go:133: Watch close - *v1.PersistentVolumeClaim total 0 items received
I0530 03:17:51.476612       1 wrap.go:47] GET /healthz: (51.647µs) 200 [kube-probe/1.15+ 127.0.0.1:33212]
I0530 03:18:01.476574       1 wrap.go:47] GET /healthz: (53.536µs) 200 [kube-probe/1.15+ 127.0.0.1:33260]
I0530 03:18:05.867943       1 reflector.go:384] k8s.io/client-go/informers/factory.go:133: Watch close - *v1.ReplicaSet total 0 items received
I0530 03:18:11.476589       1 wrap.go:47] GET /healthz: (77.956µs) 200 [kube-probe/1.15+ 127.0.0.1:33294]
I0530 03:18:21.476532       1 wrap.go:47] GET /healthz: (98.425µs) 200 [kube-probe/1.15+ 127.0.0.1:33330]
I0530 03:18:31.477326       1 wrap.go:47] GET /healthz: (60.65µs) 200 [kube-probe/1.15+ 127.0.0.1:33364]
I0530 03:18:41.477678       1 wrap.go:47] GET /healthz: (62.496µs) 200 [kube-probe/1.15+ 127.0.0.1:33400]
I0530 03:18:42.302360       1 scheduling_queue.go:895] About to try and schedule pod statefulset-1120/ss2-2
I0530 03:18:42.302373       1 scheduler.go:454] Attempting to schedule pod: statefulset-1120/ss2-2
I0530 03:18:42.302908       1 scheduler_binder.go:255] AssumePodVolumes for pod "statefulset-1120/ss2-2", node "e2e-test-peterhornyack-windows-node-group-9q9v"
I0530 03:18:42.302919       1 scheduler_binder.go:265] AssumePodVolumes for pod "statefulset-1120/ss2-2", node "e2e-test-peterhornyack-windows-node-group-9q9v": all PVCs bound and nothing to do
I0530 03:18:42.302981       1 factory.go:734] Attempting to bind ss2-2 to e2e-test-peterhornyack-windows-node-group-9q9v
I0530 03:18:42.313301       1 scheduler.go:575] pod statefulset-1120/ss2-2 is bound successfully on node e2e-test-peterhornyack-windows-node-group-9q9v, 6 nodes evaluated, 3 nodes were found feasible
I0530 03:18:51.476971       1 wrap.go:47] GET /healthz: (87.048µs) 200 [kube-probe/1.15+ 127.0.0.1:33432]
I0530 03:18:57.831716       1 reflector.go:384] k8s.io/client-go/informers/factory.go:133: Watch close - *v1.ReplicationController total 0 items received
I0530 03:19:01.476727       1 wrap.go:47] GET /healthz: (141.076µs) 200 [kube-probe/1.15+ 127.0.0.1:33480]
I0530 03:19:01.843101       1 reflector.go:384] k8s.io/client-go/informers/factory.go:133: Watch close - *v1.StorageClass total 0 items received
I0530 03:19:04.219225       1 scheduling_queue.go:895] About to try and schedule pod statefulset-1120/ss2-2
I0530 03:19:04.219240       1 scheduler.go:454] Attempting to schedule pod: statefulset-1120/ss2-2
I0530 03:19:04.219659       1 scheduler_binder.go:255] AssumePodVolumes for pod "statefulset-1120/ss2-2", node "e2e-test-peterhornyack-windows-node-group-9q9v"
I0530 03:19:04.219669       1 scheduler_binder.go:265] AssumePodVolumes for pod "statefulset-1120/ss2-2", node "e2e-test-peterhornyack-windows-node-group-9q9v": all PVCs bound and nothing to do
I0530 03:19:04.219729       1 factory.go:734] Attempting to bind ss2-2 to e2e-test-peterhornyack-windows-node-group-9q9v
I0530 03:19:04.229716       1 scheduler.go:575] pod statefulset-1120/ss2-2 is bound successfully on node e2e-test-peterhornyack-windows-node-group-9q9v, 6 nodes evaluated, 3 nodes were found feasible
I0530 03:19:06.993012       1 scheduling_queue.go:895] About to try and schedule pod statefulset-1120/ss2-0
I0530 03:19:06.993026       1 scheduler.go:454] Attempting to schedule pod: statefulset-1120/ss2-0
I0530 03:19:06.997115       1 scheduler_binder.go:255] AssumePodVolumes for pod "statefulset-1120/ss2-0", node "e2e-test-peterhornyack-windows-node-group-1vjk"
I0530 03:19:06.997132       1 scheduler_binder.go:265] AssumePodVolumes for pod "statefulset-1120/ss2-0", node "e2e-test-peterhornyack-windows-node-group-1vjk": all PVCs bound and nothing to do
I0530 03:19:06.997204       1 factory.go:734] Attempting to bind ss2-0 to e2e-test-peterhornyack-windows-node-group-1vjk
I0530 03:19:07.008132       1 scheduler.go:575] pod statefulset-1120/ss2-0 is bound successfully on node e2e-test-peterhornyack-windows-node-group-1vjk, 6 nodes evaluated, 3 nodes were found feasible
I0530 03:19:11.476709       1 wrap.go:47] GET /healthz: (78.192µs) 200 [kube-probe/1.15+ 127.0.0.1:33516]
I0530 03:19:13.276142       1 scheduling_queue.go:895] About to try and schedule pod statefulset-1120/ss2-2
I0530 03:19:13.276156       1 scheduler.go:454] Attempting to schedule pod: statefulset-1120/ss2-2
I0530 03:19:13.278770       1 scheduler_binder.go:255] AssumePodVolumes for pod "statefulset-1120/ss2-2", node "e2e-test-peterhornyack-windows-node-group-9q9v"
I0530 03:19:13.278783       1 scheduler_binder.go:265] AssumePodVolumes for pod "statefulset-1120/ss2-2", node "e2e-test-peterhornyack-windows-node-group-9q9v": all PVCs bound and nothing to do
I0530 03:19:13.278849       1 factory.go:734] Attempting to bind ss2-2 to e2e-test-peterhornyack-windows-node-group-9q9v
I0530 03:19:13.292172       1 scheduler.go:575] pod statefulset-1120/ss2-2 is bound successfully on node e2e-test-peterhornyack-windows-node-group-9q9v, 6 nodes evaluated, 3 nodes were found feasible
I0530 03:19:21.476656       1 wrap.go:47] GET /healthz: (80.779µs) 200 [kube-probe/1.15+ 127.0.0.1:33552]
I0530 03:19:31.476892       1 wrap.go:47] GET /healthz: (64.388µs) 200 [kube-probe/1.15+ 127.0.0.1:33586]
I0530 03:19:41.476538       1 wrap.go:47] GET /healthz: (98.698µs) 200 [kube-probe/1.15+ 127.0.0.1:33620]
I0530 03:19:51.477615       1 wrap.go:47] GET /healthz: (77.041µs) 200 [kube-probe/1.15+ 127.0.0.1:33656]
I0530 03:20:01.476586       1 wrap.go:47] GET /healthz: (76.787µs) 200 [kube-probe/1.15+ 127.0.0.1:33704]
I0530 03:20:11.476476       1 wrap.go:47] GET /healthz: (49.873µs) 200 [kube-probe/1.15+ 127.0.0.1:33738]
I0530 03:20:21.476437       1 wrap.go:47] GET /healthz: (69.883µs) 200 [kube-probe/1.15+ 127.0.0.1:33774]
I0530 03:20:31.476593       1 wrap.go:47] GET /healthz: (71.337µs) 200 [kube-probe/1.15+ 127.0.0.1:33820]
I0530 03:20:32.861303       1 reflector.go:384] k8s.io/client-go/informers/factory.go:133: Watch close - *v1beta1.PodDisruptionBudget total 0 items received
I0530 03:20:41.477430       1 wrap.go:47] GET /healthz: (90.787µs) 200 [kube-probe/1.15+ 127.0.0.1:33856]
I0530 03:20:51.476949       1 wrap.go:47] GET /healthz: (73.134µs) 200 [kube-probe/1.15+ 127.0.0.1:33888]
I0530 03:21:01.476714       1 wrap.go:47] GET /healthz: (65.111µs) 200 [kube-probe/1.15+ 127.0.0.1:33936]
I0530 03:21:11.477378       1 wrap.go:47] GET /healthz: (63.588µs) 200 [kube-probe/1.15+ 127.0.0.1:33972]
I0530 03:21:16.881233       1 reflector.go:384] cmd/kube-scheduler/app/server.go:223: Watch close - *v1.Pod total 29 items received
I0530 03:21:21.476757       1 wrap.go:47] GET /healthz: (49.987µs) 200 [kube-probe/1.15+ 127.0.0.1:34008]
I0530 03:21:31.476578       1 wrap.go:47] GET /healthz: (70.831µs) 200 [kube-probe/1.15+ 127.0.0.1:34042]
I0530 03:21:41.481478       1 wrap.go:47] GET /healthz: (64.869µs) 200 [kube-probe/1.15+ 127.0.0.1:34076]
I0530 03:21:51.476733       1 wrap.go:47] GET /healthz: (116.445µs) 200 [kube-probe/1.15+ 127.0.0.1:34108]
I0530 03:21:51.829198       1 reflector.go:384] k8s.io/client-go/informers/factory.go:133: Watch close - *v1.Node total 64 items received
I0530 03:22:01.476944       1 wrap.go:47] GET /healthz: (62.45µs) 200 [kube-probe/1.15+ 127.0.0.1:34156]
I0530 03:22:11.476779       1 wrap.go:47] GET /healthz: (67.129µs) 200 [kube-probe/1.15+ 127.0.0.1:34192]
I0530 03:22:21.476598       1 wrap.go:47] GET /healthz: (84.015µs) 200 [kube-probe/1.15+ 127.0.0.1:34230]
I0530 03:22:31.476881       1 wrap.go:47] GET /healthz: (75.914µs) 200 [kube-probe/1.15+ 127.0.0.1:34264]
I0530 03:22:41.476555       1 wrap.go:47] GET /healthz: (93.932µs) 200 [kube-probe/1.15+ 127.0.0.1:34298]
I0530 03:22:51.477042       1 wrap.go:47] GET /healthz: (71.811µs) 200 [kube-probe/1.15+ 127.0.0.1:34330]
I0530 03:23:01.476580       1 wrap.go:47] GET /healthz: (73.923µs) 200 [kube-probe/1.15+ 127.0.0.1:34378]
I0530 03:23:11.477018       1 wrap.go:47] GET /healthz: (72.97µs) 200 [kube-probe/1.15+ 127.0.0.1:34412]
I0530 03:23:21.476754       1 wrap.go:47] GET /healthz: (74.488µs) 200 [kube-probe/1.15+ 127.0.0.1:34448]
I0530 03:23:21.871445       1 reflector.go:384] k8s.io/client-go/informers/factory.go:133: Watch close - *v1.PersistentVolume total 0 items received
I0530 03:23:21.879764       1 reflector.go:384] k8s.io/client-go/informers/factory.go:133: Watch close - *v1.PersistentVolumeClaim total 0 items received
I0530 03:23:23.860861       1 reflector.go:384] k8s.io/client-go/informers/factory.go:133: Watch close - *v1.StatefulSet total 16 items received
I0530 03:23:31.477033       1 wrap.go:47] GET /healthz: (148.944µs) 200 [kube-probe/1.15+ 127.0.0.1:34484]
I0530 03:23:41.476890       1 wrap.go:47] GET /healthz: (74.825µs) 200 [kube-probe/1.15+ 127.0.0.1:34520]
I0530 03:23:51.476778       1 wrap.go:47] GET /healthz: (60.108µs) 200 [kube-probe/1.15+ 127.0.0.1:34552]
I0530 03:24:01.476736       1 wrap.go:47] GET /healthz: (51.007µs) 200 [kube-probe/1.15+ 127.0.0.1:34602]
I0530 03:24:04.833624       1 reflector.go:384] k8s.io/client-go/informers/factory.go:133: Watch close - *v1.ReplicationController total 0 items received
I0530 03:24:11.476701       1 wrap.go:47] GET /healthz: (66.649µs) 200 [kube-probe/1.15+ 127.0.0.1:34636]
I0530 03:24:21.476704       1 wrap.go:47] GET /healthz: (78.996µs) 200 [kube-probe/1.15+ 127.0.0.1:34672]
I0530 03:24:31.476672       1 wrap.go:47] GET /healthz: (76.909µs) 200 [kube-probe/1.15+ 127.0.0.1:34706]
I0530 03:24:41.476592       1 wrap.go:47] GET /healthz: (87.831µs) 200 [kube-probe/1.15+ 127.0.0.1:34742]
I0530 03:24:51.476866       1 wrap.go:47] GET /healthz: (66.198µs) 200 [kube-probe/1.15+ 127.0.0.1:34774]
I0530 03:25:01.476939       1 wrap.go:47] GET /healthz: (79.457µs) 200 [kube-probe/1.15+ 127.0.0.1:34822]
I0530 03:25:11.476701       1 wrap.go:47] GET /healthz: (68.462µs) 200 [kube-probe/1.15+ 127.0.0.1:34858]
I0530 03:25:12.870119       1 reflector.go:384] k8s.io/client-go/informers/factory.go:133: Watch close - *v1.ReplicaSet total 0 items received
I0530 03:25:15.851666       1 reflector.go:384] k8s.io/client-go/informers/factory.go:133: Watch close - *v1.Service total 0 items received
I0530 03:25:21.476597       1 wrap.go:47] GET /healthz: (80.155µs) 200 [kube-probe/1.15+ 127.0.0.1:34894]
I0530 03:25:31.476579       1 wrap.go:47] GET /healthz: (113.968µs) 200 [kube-probe/1.15+ 127.0.0.1:34928]
I0530 03:25:41.476857       1 wrap.go:47] GET /healthz: (75.496µs) 200 [kube-probe/1.15+ 127.0.0.1:34962]
I0530 03:25:51.476829       1 wrap.go:47] GET /healthz: (73.795µs) 200 [kube-probe/1.15+ 127.0.0.1:34998]
I0530 03:26:01.477595       1 wrap.go:47] GET /healthz: (85.62µs) 200 [kube-probe/1.15+ 127.0.0.1:35046]
I0530 03:26:11.479505       1 wrap.go:47] GET /healthz: (97.703µs) 200 [kube-probe/1.15+ 127.0.0.1:35080]
I0530 03:26:21.476663       1 wrap.go:47] GET /healthz: (130.205µs) 200 [kube-probe/1.15+ 127.0.0.1:35116]
I0530 03:26:31.476806       1 wrap.go:47] GET /healthz: (72.236µs) 200 [kube-probe/1.15+ 127.0.0.1:35152]
I0530 03:26:41.476716       1 wrap.go:47] GET /healthz: (66.345µs) 200 [kube-probe/1.15+ 127.0.0.1:35188]
I0530 03:26:51.477144       1 wrap.go:47] GET /healthz: (102.025µs) 200 [kube-probe/1.15+ 127.0.0.1:35220]
I0530 03:27:01.476852       1 wrap.go:47] GET /healthz: (75.881µs) 200 [kube-probe/1.15+ 127.0.0.1:35414]
I0530 03:27:04.883249       1 reflector.go:384] cmd/kube-scheduler/app/server.go:223: Watch close - *v1.Pod total 0 items received
I0530 03:27:11.477101       1 wrap.go:47] GET /healthz: (73.77µs) 200 [kube-probe/1.15+ 127.0.0.1:35448]
I0530 03:27:16.863336       1 reflector.go:384] k8s.io/client-go/informers/factory.go:133: Watch close - *v1beta1.PodDisruptionBudget total 0 items received
I0530 03:27:21.476756       1 wrap.go:47] GET /healthz: (51.361µs) 200 [kube-probe/1.15+ 127.0.0.1:35488]
I0530 03:27:31.476593       1 wrap.go:47] GET /healthz: (83.381µs) 200 [kube-probe/1.15+ 127.0.0.1:35522]
I0530 03:27:36.845215       1 reflector.go:384] k8s.io/client-go/informers/factory.go:133: Watch close - *v1.StorageClass total 0 items received
I0530 03:27:40.831450       1 reflector.go:384] k8s.io/client-go/informers/factory.go:133: Watch close - *v1.Node total 56 items received
I0530 03:27:41.476694       1 wrap.go:47] GET /healthz: (74.468µs) 200 [kube-probe/1.15+ 127.0.0.1:35556]
I0530 03:27:51.477581       1 wrap.go:47] GET /healthz: (110.25µs) 200 [kube-probe/1.15+ 127.0.0.1:35592]
I0530 03:28:01.476409       1 wrap.go:47] GET /healthz: (51.985µs) 200 [kube-probe/1.15+ 127.0.0.1:35642]
I0530 03:28:11.476639       1 wrap.go:47] GET /healthz: (127.273µs) 200 [kube-probe/1.15+ 127.0.0.1:35678]
I0530 03:28:21.476729       1 wrap.go:47] GET /healthz: (52.574µs) 200 [kube-probe/1.15+ 127.0.0.1:35714]
I0530 03:28:31.476756       1 wrap.go:47] GET /healthz: (53.798µs) 200 [kube-probe/1.15+ 127.0.0.1:35748]
I0530 03:28:41.478337       1 wrap.go:47] GET /healthz: (69.587µs) 200 [kube-probe/1.15+ 127.0.0.1:35782]
I0530 03:28:51.483222       1 wrap.go:47] GET /healthz: (73.434µs) 200 [kube-probe/1.15+ 127.0.0.1:35814]
I0530 03:29:01.477201       1 wrap.go:47] GET /healthz: (76.633µs) 200 [kube-probe/1.15+ 127.0.0.1:35862]
I0530 03:29:11.476664       1 wrap.go:47] GET /healthz: (87.63µs) 200 [kube-probe/1.15+ 127.0.0.1:35896]
I0530 03:29:21.476856       1 wrap.go:47] GET /healthz: (87.697µs) 200 [kube-probe/1.15+ 127.0.0.1:35934]
I0530 03:29:22.863270       1 reflector.go:384] k8s.io/client-go/informers/factory.go:133: Watch close - *v1.StatefulSet total 1 items received
I0530 03:29:31.476562       1 wrap.go:47] GET /healthz: (96.216µs) 200 [kube-probe/1.15+ 127.0.0.1:35970]
I0530 03:29:41.476954       1 wrap.go:47] GET /healthz: (63.872µs) 200 [kube-probe/1.15+ 127.0.0.1:36004]
I0530 03:29:51.476500       1 wrap.go:47] GET /healthz: (83.886µs) 200 [kube-probe/1.15+ 127.0.0.1:36036]
I0530 03:30:01.476780       1 wrap.go:47] GET /healthz: (75.611µs) 200 [kube-probe/1.15+ 127.0.0.1:36088]
I0530 03:30:11.476986       1 wrap.go:47] GET /healthz: (92.845µs) 200 [kube-probe/1.15+ 127.0.0.1:36122]
I0530 03:30:21.476681       1 wrap.go:47] GET /healthz: (123.731µs) 200 [kube-probe/1.15+ 127.0.0.1:36158]
I0530 03:30:31.476601       1 wrap.go:47] GET /healthz: (85.814µs) 200 [kube-probe/1.15+ 127.0.0.1:36194]
I0530 03:30:41.476423       1 wrap.go:47] GET /healthz: (72.363µs) 200 [kube-probe/1.15+ 127.0.0.1:36228]
I0530 03:30:51.476706       1 wrap.go:47] GET /healthz: (75.885µs) 200 [kube-probe/1.15+ 127.0.0.1:36260]
I0530 03:31:01.476785       1 wrap.go:47] GET /healthz: (74.441µs) 200 [kube-probe/1.15+ 127.0.0.1:36310]
I0530 03:31:11.476238       1 wrap.go:47] GET /healthz: (67.699µs) 200 [kube-probe/1.15+ 127.0.0.1:36344]
I0530 03:31:21.476607       1 wrap.go:47] GET /healthz: (86.567µs) 200 [kube-probe/1.15+ 127.0.0.1:36380]
I0530 03:31:31.477108       1 wrap.go:47] GET /healthz: (103.299µs) 200 [kube-probe/1.15+ 127.0.0.1:36414]
I0530 03:31:41.476911       1 wrap.go:47] GET /healthz: (86.056µs) 200 [kube-probe/1.15+ 127.0.0.1:36450]
I0530 03:31:51.476854       1 wrap.go:47] GET /healthz: (62.891µs) 200 [kube-probe/1.15+ 127.0.0.1:36482]
I0530 03:31:59.836114       1 reflector.go:384] k8s.io/client-go/informers/factory.go:133: Watch close - *v1.ReplicationController total 0 items received
I0530 03:32:01.477040       1 wrap.go:47] GET /healthz: (56.237µs) 200 [kube-probe/1.15+ 127.0.0.1:36532]
I0530 03:32:03.873599       1 reflector.go:384] k8s.io/client-go/informers/factory.go:133: Watch close - *v1.PersistentVolume total 0 items received
I0530 03:32:11.476722       1 wrap.go:47] GET /healthz: (70.735µs) 200 [kube-probe/1.15+ 127.0.0.1:36566]
I0530 03:32:17.853957       1 reflector.go:384] k8s.io/client-go/informers/factory.go:133: Watch close - *v1.Service total 0 items received
I0530 03:32:21.476396       1 wrap.go:47] GET /healthz: (48.065µs) 200 [kube-probe/1.15+ 127.0.0.1:36602]
I0530 03:32:31.476452       1 wrap.go:47] GET /healthz: (60.738µs) 200 [kube-probe/1.15+ 127.0.0.1:36638]
I0530 03:32:32.883232       1 reflector.go:384] k8s.io/client-go/informers/factory.go:133: Watch close - *v1.PersistentVolumeClaim total 0 items received
I0530 03:32:41.476623       1 wrap.go:47] GET /healthz: (95.641µs) 200 [kube-probe/1.15+ 127.0.0.1:36672]
I0530 03:32:51.476706       1 wrap.go:47] GET /healthz: (80.29µs) 200 [kube-probe/1.15+ 127.0.0.1:36704]
I0530 03:32:58.886258       1 reflector.go:384] cmd/kube-scheduler/app/server.go:223: Watch close - *v1.Pod total 9 items received
I0530 03:33:01.479161       1 wrap.go:47] GET /healthz: (96.235µs) 200 [kube-probe/1.15+ 127.0.0.1:36754]
I0530 03:33:11.476627       1 wrap.go:47] GET /healthz: (83.543µs) 200 [kube-probe/1.15+ 127.0.0.1:36788]
I0530 03:33:21.476666       1 wrap.go:47] GET /healthz: (48.795µs) 200 [kube-probe/1.15+ 127.0.0.1:36824]
I0530 03:33:31.476890       1 wrap.go:47] GET /healthz: (76.053µs) 200 [kube-probe/1.15+ 127.0.0.1:36858]
I0530 03:33:31.872272       1 reflector.go:384] k8s.io/client-go/informers/factory.go:133: Watch close - *v1.ReplicaSet total 0 items received
I0530 03:33:41.477915       1 wrap.go:47] GET /healthz: (81.47µs) 200 [kube-probe/1.15+ 127.0.0.1:36892]
I0530 03:33:51.476512       1 wrap.go:47] GET /healthz: (77.427µs) 200 [kube-probe/1.15+ 127.0.0.1:36926]
I0530 03:34:01.476796       1 wrap.go:47] GET /healthz: (64.086µs) 200 [kube-probe/1.15+ 127.0.0.1:36974]
I0530 03:34:11.476985       1 wrap.go:47] GET /healthz: (64.132µs) 200 [kube-probe/1.15+ 127.0.0.1:37010]
I0530 03:34:21.476546       1 wrap.go:47] GET /healthz: (98.987µs) 200 [kube-probe/1.15+ 127.0.0.1:37046]
I0530 03:34:31.477647       1 wrap.go:47] GET /healthz: (89.361µs) 200 [kube-probe/1.15+ 127.0.0.1:37080]
I0530 03:34:41.476848       1 wrap.go:47] GET /healthz: (71.196µs) 200 [kube-probe/1.15+ 127.0.0.1:37114]
I0530 03:34:51.476879       1 wrap.go:47] GET /healthz: (62.841µs) 200 [kube-probe/1.15+ 127.0.0.1:37146]
I0530 03:35:01.476673       1 wrap.go:47] GET /healthz: (85.393µs) 200 [kube-probe/1.15+ 127.0.0.1:37194]
I0530 03:35:11.476872       1 wrap.go:47] GET /healthz: (78.006µs) 200 [kube-probe/1.15+ 127.0.0.1:37228]
I0530 03:35:21.476697       1 wrap.go:47] GET /healthz: (72.949µs) 200 [kube-probe/1.15+ 127.0.0.1:37268]
I0530 03:35:31.476761       1 wrap.go:47] GET /healthz: (79.759µs) 200 [kube-probe/1.15+ 127.0.0.1:37302]
I0530 03:35:33.865450       1 reflector.go:384] k8s.io/client-go/informers/factory.go:133: Watch close - *v1beta1.PodDisruptionBudget total 0 items received
I0530 03:35:41.476837       1 wrap.go:47] GET /healthz: (72.097µs) 200 [kube-probe/1.15+ 127.0.0.1:37336]
I0530 03:35:41.865567       1 reflector.go:384] k8s.io/client-go/informers/factory.go:133: Watch close - *v1.StatefulSet total 4 items received
I0530 03:35:50.847326       1 reflector.go:384] k8s.io/client-go/informers/factory.go:133: Watch close - *v1.StorageClass total 0 items received
I0530 03:35:51.476822       1 wrap.go:47] GET /healthz: (72.951µs) 200 [kube-probe/1.15+ 127.0.0.1:37368]
I0530 03:36:01.476778       1 wrap.go:47] GET /healthz: (66.305µs) 200 [kube-probe/1.15+ 127.0.0.1:37418]
I0530 03:36:11.476757       1 wrap.go:47] GET /healthz: (80.764µs) 200 [kube-probe/1.15+ 127.0.0.1:37452]
I0530 03:36:21.476507       1 wrap.go:47] GET /healthz: (87.186µs) 200 [kube-probe/1.15+ 127.0.0.1:37488]
I0530 03:36:31.476611       1 wrap.go:47] GET /healthz: (71.007µs) 200 [kube-probe/1.15+ 127.0.0.1:37524]
I0530 03:36:41.482265       1 wrap.go:47] GET /healthz: (70.569µs) 200 [kube-probe/1.15+ 127.0.0.1:37558]
I0530 03:36:51.476568       1 wrap.go:47] GET /healthz: (51.028µs) 200 [kube-probe/1.15+ 127.0.0.1:37592]
I0530 03:36:54.833537       1 reflector.go:384] k8s.io/client-go/informers/factory.go:133: Watch close - *v1.Node total 99 items received
I0530 03:37:01.476686       1 wrap.go:47] GET /healthz: (85.54µs) 200 [kube-probe/1.15+ 127.0.0.1:37780]
I0530 03:37:02.838640       1 reflector.go:384] k8s.io/client-go/informers/factory.go:133: Watch close - *v1.ReplicationController total 0 items received
I0530 03:37:11.476579       1 wrap.go:47] GET /healthz: (69.895µs) 200 [kube-probe/1.15+ 127.0.0.1:37818]
I0530 03:37:21.476673       1 wrap.go:47] GET /healthz: (113.444µs) 200 [kube-probe/1.15+ 127.0.0.1:37854]
I0530 03:37:31.476530       1 wrap.go:47] GET /healthz: (78.953µs) 200 [kube-probe/1.15+ 127.0.0.1:37888]
I0530 03:37:39.885432       1 reflector.go:384] k8s.io/client-go/informers/factory.go:133: Watch close - *v1.PersistentVolumeClaim total 0 items received
I0530 03:37:41.477267       1 wrap.go:47] GET /healthz: (63.684µs) 200 [kube-probe/1.15+ 127.0.0.1:37924]
I0530 03:37:51.476819       1 wrap.go:47] GET /healthz: (119.598µs) 200 [kube-probe/1.15+ 127.0.0.1:37956]
I0530 03:38:00.591839       1 scheduling_queue.go:895] About to try and schedule pod provisioning-427/pvc-volume-tester-writer-dk95k
I0530 03:38:00.591851       1 scheduler.go:454] Attempting to schedule pod: provisioning-427/pvc-volume-tester-writer-dk95k
I0530 03:38:00.592036       1 predicates.go:452] PVC provisioning-427/pvc-qqlcq is not bound, assuming PVC matches predicate when counting limits
I0530 03:38:00.593940       1 predicates.go:452] PVC provisioning-427/pvc-qqlcq is not bound, assuming PVC matches predicate when counting limits
I0530 03:38:00.593979       1 predicates.go:452] PVC provisioning-427/pvc-qqlcq is not bound, assuming PVC matches predicate when counting limits
I0530 03:38:00.594027       1 scheduler_binder.go:683] No matching volumes for Pod "provisioning-427/pvc-volume-tester-writer-dk95k", PVC "provisioning-427/pvc-qqlcq" on node "e2e-test-peterhornyack-windows-node-group-9q9v"
I0530 03:38:00.594039       1 scheduler_binder.go:738] Provisioning for claims of pod "provisioning-427/pvc-volume-tester-writer-dk95k" that has no matching volumes on node "e2e-test-peterhornyack-windows-node-group-9q9v" ...
I0530 03:38:00.594091       1 predicates.go:452] PVC provisioning-427/pvc-qqlcq is not bound, assuming PVC matches predicate when counting limits
I0530 03:38:00.594121       1 predicates.go:452] PVC provisioning-427/pvc-qqlcq is not bound, assuming PVC matches predicate when counting limits
I0530 03:38:00.594131       1 predicates.go:452] PVC provisioning-427/pvc-qqlcq is not bound, assuming PVC matches predicate when counting limits
I0530 03:38:00.594140       1 scheduler_binder.go:683] No matching volumes for Pod "provisioning-427/pvc-volume-tester-writer-dk95k", PVC "provisioning-427/pvc-qqlcq" on node "e2e-test-peterhornyack-windows-node-group-1vjk"
I0530 03:38:00.594148       1 scheduler_binder.go:738] Provisioning for claims of pod "provisioning-427/pvc-volume-tester-writer-dk95k" that has no matching volumes on node "e2e-test-peterhornyack-windows-node-group-1vjk" ...
I0530 03:38:00.594184       1 predicates.go:452] PVC provisioning-427/pvc-qqlcq is not bound, assuming PVC matches predicate when counting limits
I0530 03:38:00.594202       1 predicates.go:452] PVC provisioning-427/pvc-qqlcq is not bound, assuming PVC matches predicate when counting limits
I0530 03:38:00.594210       1 predicates.go:452] PVC provisioning-427/pvc-qqlcq is not bound, assuming PVC matches predicate when counting limits
I0530 03:38:00.594217       1 scheduler_binder.go:683] No matching volumes for Pod "provisioning-427/pvc-volume-tester-writer-dk95k", PVC "provisioning-427/pvc-qqlcq" on node "e2e-test-peterhornyack-windows-node-group-jpxd"
I0530 03:38:00.594226       1 scheduler_binder.go:738] Provisioning for claims of pod "provisioning-427/pvc-volume-tester-writer-dk95k" that has no matching volumes on node "e2e-test-peterhornyack-windows-node-group-jpxd" ...
I0530 03:38:00.594431       1 scheduler_binder.go:255] AssumePodVolumes for pod "provisioning-427/pvc-volume-tester-writer-dk95k", node "e2e-test-peterhornyack-windows-node-group-jpxd"
I0530 03:38:00.594447       1 scheduler_assume_cache.go:319] Assumed v1.PersistentVolumeClaim "provisioning-427/pvc-qqlcq", version 43723
I0530 03:38:00.594504       1 scheduler_binder.go:330] BindPodVolumes for pod "provisioning-427/pvc-volume-tester-writer-dk95k", node "e2e-test-peterhornyack-windows-node-group-jpxd"
I0530 03:38:00.932575       1 cache.go:643] Couldn't expire cache for pod provisioning-427/pvc-volume-tester-writer-dk95k. Binding is still in progress.
I0530 03:38:01.476603       1 wrap.go:47] GET /healthz: (49.307µs) 200 [kube-probe/1.15+ 127.0.0.1:38004]
I0530 03:38:01.933129       1 cache.go:643] Couldn't expire cache for pod provisioning-427/pvc-volume-tester-writer-dk95k. Binding is still in progress.
I0530 03:38:02.936329       1 cache.go:643] Couldn't expire cache for pod provisioning-427/pvc-volume-tester-writer-dk95k. Binding is still in progress.
I0530 03:38:03.605264       1 scheduler_binder.go:545] All PVCs for pod "provisioning-427/pvc-volume-tester-writer-dk95k" are bound
I0530 03:38:03.605301       1 factory.go:734] Attempting to bind pvc-volume-tester-writer-dk95k to e2e-test-peterhornyack-windows-node-group-jpxd
I0530 03:38:03.613207       1 scheduler.go:575] pod provisioning-427/pvc-volume-tester-writer-dk95k is bound successfully on node e2e-test-peterhornyack-windows-node-group-jpxd, 6 nodes evaluated, 3 nodes were found feasible
I0530 03:38:11.476671       1 wrap.go:47] GET /healthz: (83.696µs) 200 [kube-probe/1.15+ 127.0.0.1:38040]
I0530 03:38:21.476725       1 wrap.go:47] GET /healthz: (60.184µs) 200 [kube-probe/1.15+ 127.0.0.1:38080]
I0530 03:38:31.476802       1 wrap.go:47] GET /healthz: (76.668µs) 200 [kube-probe/1.15+ 127.0.0.1:38114]
I0530 03:38:41.476687       1 wrap.go:47] GET /healthz: (86.956µs) 200 [kube-probe/1.15+ 127.0.0.1:38148]
I0530 03:38:41.888507       1 reflector.go:384] cmd/kube-scheduler/app/server.go:223: Watch close - *v1.Pod total 12 items received
I0530 03:38:47.856243       1 reflector.go:384] k8s.io/client-go/informers/factory.go:133: Watch close - *v1.Service total 1 items received
I0530 03:38:51.476744       1 wrap.go:47] GET /healthz: (78.952µs) 200 [kube-probe/1.15+ 127.0.0.1:38182]
I0530 03:39:01.476792       1 wrap.go:47] GET /healthz: (77.78µs) 200 [kube-probe/1.15+ 127.0.0.1:38230]
I0530 03:39:11.477257       1 wrap.go:47] GET /healthz: (79.763µs) 200 [kube-probe/1.15+ 127.0.0.1:38264]
I0530 03:39:21.476512       1 wrap.go:47] GET /healthz: (88.674µs) 200 [kube-probe/1.15+ 127.0.0.1:38304]
I0530 03:39:23.875747       1 reflector.go:384] k8s.io/client-go/informers/factory.go:133: Watch close - *v1.PersistentVolume total 2 items received
I0530 03:39:31.476531       1 wrap.go:47] GET /healthz: (72.796µs) 200 [kube-probe/1.15+ 127.0.0.1:38338]
I0530 03:39:41.476815       1 wrap.go:47] GET /healthz: (72.044µs) 200 [kube-probe/1.15+ 127.0.0.1:38372]
I0530 03:39:42.874493       1 reflector.go:384] k8s.io/client-go/informers/factory.go:133: Watch close - *v1.ReplicaSet total 0 items received
I0530 03:39:51.476906       1 wrap.go:47] GET /healthz: (80.418µs) 200 [kube-probe/1.15+ 127.0.0.1:38406]
I0530 03:40:01.476795       1 wrap.go:47] GET /healthz: (77.103µs) 200 [kube-probe/1.15+ 127.0.0.1:38456]
I0530 03:40:11.477059       1 wrap.go:47] GET /healthz: (76.025µs) 200 [kube-probe/1.15+ 127.0.0.1:38490]
I0530 03:40:21.476844       1 wrap.go:47] GET /healthz: (81.87µs) 200 [kube-probe/1.15+ 127.0.0.1:38526]
I0530 03:40:31.476606       1 wrap.go:47] GET /healthz: (58.366µs) 200 [kube-probe/1.15+ 127.0.0.1:38560]
I0530 03:40:41.481665       1 wrap.go:47] GET /healthz: (70.406µs) 200 [kube-probe/1.15+ 127.0.0.1:38594]
I0530 03:40:51.476979       1 wrap.go:47] GET /healthz: (74.532µs) 200 [kube-probe/1.15+ 127.0.0.1:38630]
I0530 03:41:01.476839       1 wrap.go:47] GET /healthz: (105.308µs) 200 [kube-probe/1.15+ 127.0.0.1:38678]
I0530 03:41:11.476891       1 wrap.go:47] GET /healthz: (77.954µs) 200 [kube-probe/1.15+ 127.0.0.1:38716]
I0530 03:41:21.476691       1 wrap.go:47] GET /healthz: (86.822µs) 200 [kube-probe/1.15+ 127.0.0.1:38752]
I0530 03:41:31.476596       1 wrap.go:47] GET /healthz: (69.397µs) 200 [kube-probe/1.15+ 127.0.0.1:38786]
I0530 03:41:41.476434       1 wrap.go:47] GET /healthz: (46.535µs) 200 [kube-probe/1.15+ 127.0.0.1:38820]
I0530 03:41:51.476730       1 wrap.go:47] GET /healthz: (87.754µs) 200 [kube-probe/1.15+ 127.0.0.1:38852]
I0530 03:42:01.476812       1 wrap.go:47] GET /healthz: (72.59µs) 200 [kube-probe/1.15+ 127.0.0.1:38900]
I0530 03:42:11.476565       1 wrap.go:47] GET /healthz: (56.934µs) 200 [kube-probe/1.15+ 127.0.0.1:38934]
I0530 03:42:21.476418       1 wrap.go:47] GET /healthz: (61.844µs) 200 [kube-probe/1.15+ 127.0.0.1:38972]
I0530 03:42:31.476857       1 wrap.go:47] GET /healthz: (63.545µs) 200 [kube-probe/1.15+ 127.0.0.1:39006]
I0530 03:42:36.868593       1 reflector.go:384] k8s.io/client-go/informers/factory.go:133: Watch close - *v1.StatefulSet total 4 items received
I0530 03:42:41.477611       1 wrap.go:47] GET /healthz: (78.501µs) 200 [kube-probe/1.15+ 127.0.0.1:39042]
I0530 03:42:44.867451       1 reflector.go:384] k8s.io/client-go/informers/factory.go:133: Watch close - *v1beta1.PodDisruptionBudget total 0 items received
I0530 03:42:51.476737       1 wrap.go:47] GET /healthz: (85.322µs) 200 [kube-probe/1.15+ 127.0.0.1:39074]
I0530 03:43:01.477136       1 wrap.go:47] GET /healthz: (63.761µs) 200 [kube-probe/1.15+ 127.0.0.1:39126]
I0530 03:43:11.485392       1 wrap.go:47] GET /healthz: (63.93µs) 200 [kube-probe/1.15+ 127.0.0.1:39160]
I0530 03:43:21.476451       1 wrap.go:47] GET /healthz: (48.896µs) 200 [kube-probe/1.15+ 127.0.0.1:39196]
I0530 03:43:31.476829       1 wrap.go:47] GET /healthz: (70.617µs) 200 [kube-probe/1.15+ 127.0.0.1:39230]
I0530 03:43:41.476587       1 wrap.go:47] GET /healthz: (66.236µs) 200 [kube-probe/1.15+ 127.0.0.1:39266]
I0530 03:43:51.476442       1 wrap.go:47] GET /healthz: (56.017µs) 200 [kube-probe/1.15+ 127.0.0.1:39298]
I0530 03:43:54.849609       1 reflector.go:384] k8s.io/client-go/informers/factory.go:133: Watch close - *v1.StorageClass total 1 items received
I0530 03:44:01.478321       1 wrap.go:47] GET /healthz: (153.48µs) 200 [kube-probe/1.15+ 127.0.0.1:39346]
I0530 03:44:11.476590       1 wrap.go:47] GET /healthz: (78.835µs) 200 [kube-probe/1.15+ 127.0.0.1:39382]
I0530 03:44:21.476612       1 wrap.go:47] GET /healthz: (83.876µs) 200 [kube-probe/1.15+ 127.0.0.1:39418]
I0530 03:44:30.887505       1 reflector.go:384] k8s.io/client-go/informers/factory.go:133: Watch close - *v1.PersistentVolumeClaim total 5 items received
I0530 03:44:31.476654       1 wrap.go:47] GET /healthz: (69.809µs) 200 [kube-probe/1.15+ 127.0.0.1:39452]
I0530 03:44:41.476429       1 wrap.go:47] GET /healthz: (60.927µs) 200 [kube-probe/1.15+ 127.0.0.1:39486]
I0530 03:44:51.476788       1 wrap.go:47] GET /healthz: (90.257µs) 200 [kube-probe/1.15+ 127.0.0.1:39520]
I0530 03:45:01.476865       1 wrap.go:47] GET /healthz: (98.389µs) 200 [kube-probe/1.15+ 127.0.0.1:39568]
I0530 03:45:11.476858       1 wrap.go:47] GET /healthz: (79.665µs) 200 [kube-probe/1.15+ 127.0.0.1:39602]
I0530 03:45:21.476746       1 wrap.go:47] GET /healthz: (78.681µs) 200 [kube-probe/1.15+ 127.0.0.1:39638]
I0530 03:45:31.476823       1 wrap.go:47] GET /healthz: (80.337µs) 200 [kube-probe/1.15+ 127.0.0.1:39672]
I0530 03:45:41.476844       1 wrap.go:47] GET /healthz: (99.307µs) 200 [kube-probe/1.15+ 127.0.0.1:39708]
I0530 03:45:44.876613       1 reflector.go:384] k8s.io/client-go/informers/factory.go:133: Watch close - *v1.ReplicaSet total 0 items received
I0530 03:45:51.475866       1 wrap.go:47] GET /healthz: (71.889µs) 200 [kube-probe/1.15+ 127.0.0.1:39740]
I0530 03:46:01.476694       1 wrap.go:47] GET /healthz: (94.23µs) 200 [kube-probe/1.15+ 127.0.0.1:39790]
I0530 03:46:05.877850       1 reflector.go:384] k8s.io/client-go/informers/factory.go:133: Watch close - *v1.PersistentVolume total 0 items received
I0530 03:46:11.476601       1 wrap.go:47] GET /healthz: (77.674µs) 200 [kube-probe/1.15+ 127.0.0.1:39824]
I0530 03:46:12.835511       1 reflector.go:384] k8s.io/client-go/informers/factory.go:133: Watch close - *v1.Node total 94 items received
I0530 03:46:20.840621       1 reflector.go:384] k8s.io/client-go/informers/factory.go:133: Watch close - *v1.ReplicationController total 0 items received
I0530 03:46:21.476690       1 wrap.go:47] GET /healthz: (79.42µs) 200 [kube-probe/1.15+ 127.0.0.1:39860]
I0530 03:46:31.476551       1 wrap.go:47] GET /healthz: (60.824µs) 200 [kube-probe/1.15+ 127.0.0.1:39894]
I0530 03:46:40.890672       1 reflector.go:384] cmd/kube-scheduler/app/server.go:223: Watch close - *v1.Pod total 3 items received
I0530 03:46:41.476610       1 wrap.go:47] GET /healthz: (65.165µs) 200 [kube-probe/1.15+ 127.0.0.1:39928]
I0530 03:46:51.476681       1 wrap.go:47] GET /healthz: (63.327µs) 200 [kube-probe/1.15+ 127.0.0.1:39960]
I0530 03:47:01.477670       1 wrap.go:47] GET /healthz: (72.023µs) 200 [kube-probe/1.15+ 127.0.0.1:40008]
I0530 03:47:11.476519       1 wrap.go:47] GET /healthz: (87.19µs) 200 [kube-probe/1.15+ 127.0.0.1:40050]
I0530 03:47:13.498874       1 scheduling_queue.go:895] About to try and schedule pod replicaset-5192/my-hostname-basic-856d4ba0-d339-4fb9-ae24-e0447c7a6f62-zv7vv
I0530 03:47:13.498901       1 scheduler.go:454] Attempting to schedule pod: replicaset-5192/my-hostname-basic-856d4ba0-d339-4fb9-ae24-e0447c7a6f62-zv7vv
I0530 03:47:13.500993       1 scheduler_binder.go:255] AssumePodVolumes for pod "replicaset-5192/my-hostname-basic-856d4ba0-d339-4fb9-ae24-e0447c7a6f62-zv7vv", node "e2e-test-peterhornyack-windows-node-group-jpxd"
I0530 03:47:13.501015       1 scheduler_binder.go:265] AssumePodVolumes for pod "replicaset-5192/my-hostname-basic-856d4ba0-d339-4fb9-ae24-e0447c7a6f62-zv7vv", node "e2e-test-peterhornyack-windows-node-group-jpxd": all PVCs bound and nothing to do
I0530 03:47:13.503519       1 factory.go:734] Attempting to bind my-hostname-basic-856d4ba0-d339-4fb9-ae24-e0447c7a6f62-zv7vv to e2e-test-peterhornyack-windows-node-group-jpxd
I0530 03:47:13.526521       1 scheduler.go:575] pod replicaset-5192/my-hostname-basic-856d4ba0-d339-4fb9-ae24-e0447c7a6f62-zv7vv is bound successfully on node e2e-test-peterhornyack-windows-node-group-jpxd, 6 nodes evaluated, 3 nodes were found feasible
I0530 03:47:17.858527       1 reflector.go:384] k8s.io/client-go/informers/factory.go:133: Watch close - *v1.Service total 0 items received
I0530 03:47:21.476385       1 wrap.go:47] GET /healthz: (61.694µs) 200 [kube-probe/1.15+ 127.0.0.1:40086]
I0530 03:47:31.476451       1 wrap.go:47] GET /healthz: (59.684µs) 200 [kube-probe/1.15+ 127.0.0.1:40120]
I0530 03:47:41.477040       1 wrap.go:47] GET /healthz: (83.573µs) 200 [kube-probe/1.15+ 127.0.0.1:40154]
I0530 03:47:51.476635       1 wrap.go:47] GET /healthz: (81.952µs) 200 [kube-probe/1.15+ 127.0.0.1:40186]
I0530 03:48:01.476569       1 wrap.go:47] GET /healthz: (58.711µs) 200 [kube-probe/1.15+ 127.0.0.1:40234]
I0530 03:48:11.476486       1 wrap.go:47] GET /healthz: (50.749µs) 200 [kube-probe/1.15+ 127.0.0.1:40268]
I0530 03:48:21.476624       1 wrap.go:47] GET /healthz: (46.934µs) 200 [kube-probe/1.15+ 127.0.0.1:40306]
I0530 03:48:31.476869       1 wrap.go:47] GET /healthz: (61.537µs) 200 [kube-probe/1.15+ 127.0.0.1:40342]
I0530 03:48:41.476671       1 wrap.go:47] GET /healthz: (49.6µs) 200 [kube-probe/1.15+ 127.0.0.1:40376]
I0530 03:48:47.870734       1 reflector.go:384] k8s.io/client-go/informers/factory.go:133: Watch close - *v1.StatefulSet total 0 items received
I0530 03:48:51.477282       1 wrap.go:47] GET /healthz: (56.466µs) 200 [kube-probe/1.15+ 127.0.0.1:40408]
I0530 03:49:01.476815       1 wrap.go:47] GET /healthz: (71.531µs) 200 [kube-probe/1.15+ 127.0.0.1:40456]
I0530 03:49:11.476675       1 wrap.go:47] GET /healthz: (86.008µs) 200 [kube-probe/1.15+ 127.0.0.1:40490]
I0530 03:49:21.476731       1 wrap.go:47] GET /healthz: (89.851µs) 200 [kube-probe/1.15+ 127.0.0.1:40528]
I0530 03:49:31.477167       1 wrap.go:47] GET /healthz: (76.775µs) 200 [kube-probe/1.15+ 127.0.0.1:40564]
I0530 03:49:41.476521       1 wrap.go:47] GET /healthz: (85.689µs) 200 [kube-probe/1.15+ 127.0.0.1:40598]
I0530 03:49:51.477003       1 wrap.go:47] GET /healthz: (78.368µs) 200 [kube-probe/1.15+ 127.0.0.1:40630]
I0530 03:49:52.892805       1 reflector.go:384] k8s.io/client-go/informers/factory.go:133: Watch close - *v1.PersistentVolumeClaim total 2 items received
I0530 03:50:01.476930       1 wrap.go:47] GET /healthz: (76.259µs) 200 [kube-probe/1.15+ 127.0.0.1:40680]
I0530 03:50:11.476615       1 wrap.go:47] GET /healthz: (71.514µs) 200 [kube-probe/1.15+ 127.0.0.1:40714]
I0530 03:50:21.476675       1 wrap.go:47] GET /healthz: (73.744µs) 200 [kube-probe/1.15+ 127.0.0.1:40750]
I0530 03:50:31.476693       1 wrap.go:47] GET /healthz: (75.29µs) 200 [kube-probe/1.15+ 127.0.0.1:40784]
