Log file created at: 2019/04/16 21:02:58
Running on machine: e2e-test-peterhornyack-master
Binary: Built with gc go1.12.1 for linux/amd64
Log line format: [IWEF]mmdd hh:mm:ss.uuuuuu threadid file:line] msg
I0416 21:02:58.789694       1 flags.go:33] FLAG: --address="0.0.0.0"
I0416 21:02:58.789803       1 flags.go:33] FLAG: --algorithm-provider=""
I0416 21:02:58.789808       1 flags.go:33] FLAG: --alsologtostderr="false"
I0416 21:02:58.789812       1 flags.go:33] FLAG: --authentication-kubeconfig=""
I0416 21:02:58.789821       1 flags.go:33] FLAG: --authentication-skip-lookup="false"
I0416 21:02:58.789826       1 flags.go:33] FLAG: --authentication-token-webhook-cache-ttl="10s"
I0416 21:02:58.789830       1 flags.go:33] FLAG: --authentication-tolerate-lookup-failure="true"
I0416 21:02:58.789833       1 flags.go:33] FLAG: --authorization-always-allow-paths="[/healthz]"
I0416 21:02:58.789852       1 flags.go:33] FLAG: --authorization-kubeconfig=""
I0416 21:02:58.789855       1 flags.go:33] FLAG: --authorization-webhook-cache-authorized-ttl="10s"
I0416 21:02:58.789857       1 flags.go:33] FLAG: --authorization-webhook-cache-unauthorized-ttl="10s"
I0416 21:02:58.789863       1 flags.go:33] FLAG: --bind-address="0.0.0.0"
I0416 21:02:58.789869       1 flags.go:33] FLAG: --cert-dir=""
I0416 21:02:58.789871       1 flags.go:33] FLAG: --client-ca-file=""
I0416 21:02:58.789873       1 flags.go:33] FLAG: --config=""
I0416 21:02:58.789875       1 flags.go:33] FLAG: --contention-profiling="false"
I0416 21:02:58.789878       1 flags.go:33] FLAG: --feature-gates="ExperimentalCriticalPodAnnotation=true"
I0416 21:02:58.789891       1 flags.go:33] FLAG: --hard-pod-affinity-symmetric-weight="1"
I0416 21:02:58.789896       1 flags.go:33] FLAG: --help="false"
I0416 21:02:58.789898       1 flags.go:33] FLAG: --http2-max-streams-per-connection="0"
I0416 21:02:58.789902       1 flags.go:33] FLAG: --kube-api-burst="100"
I0416 21:02:58.789905       1 flags.go:33] FLAG: --kube-api-content-type="application/vnd.kubernetes.protobuf"
I0416 21:02:58.789908       1 flags.go:33] FLAG: --kube-api-qps="50"
I0416 21:02:58.789918       1 flags.go:33] FLAG: --kubeconfig="/etc/srv/kubernetes/kube-scheduler/kubeconfig"
I0416 21:02:58.789922       1 flags.go:33] FLAG: --leader-elect="true"
I0416 21:02:58.789925       1 flags.go:33] FLAG: --leader-elect-lease-duration="15s"
I0416 21:02:58.789928       1 flags.go:33] FLAG: --leader-elect-renew-deadline="10s"
I0416 21:02:58.789934       1 flags.go:33] FLAG: --leader-elect-resource-lock="endpoints"
I0416 21:02:58.789937       1 flags.go:33] FLAG: --leader-elect-retry-period="2s"
I0416 21:02:58.789939       1 flags.go:33] FLAG: --lock-object-name="kube-scheduler"
I0416 21:02:58.789945       1 flags.go:33] FLAG: --lock-object-namespace="kube-system"
I0416 21:02:58.789948       1 flags.go:33] FLAG: --log-backtrace-at=":0"
I0416 21:02:58.789952       1 flags.go:33] FLAG: --log-dir=""
I0416 21:02:58.789954       1 flags.go:33] FLAG: --log-file="/var/log/kube-scheduler.log"
I0416 21:02:58.789957       1 flags.go:33] FLAG: --log-flush-frequency="5s"
I0416 21:02:58.789959       1 flags.go:33] FLAG: --logtostderr="false"
I0416 21:02:58.789962       1 flags.go:33] FLAG: --master=""
I0416 21:02:58.789968       1 flags.go:33] FLAG: --policy-config-file=""
I0416 21:02:58.789970       1 flags.go:33] FLAG: --policy-configmap=""
I0416 21:02:58.789973       1 flags.go:33] FLAG: --policy-configmap-namespace="kube-system"
I0416 21:02:58.789975       1 flags.go:33] FLAG: --port="10251"
I0416 21:02:58.789978       1 flags.go:33] FLAG: --profiling="false"
I0416 21:02:58.789980       1 flags.go:33] FLAG: --requestheader-allowed-names="[]"
I0416 21:02:58.789986       1 flags.go:33] FLAG: --requestheader-client-ca-file=""
I0416 21:02:58.789992       1 flags.go:33] FLAG: --requestheader-extra-headers-prefix="[x-remote-extra-]"
I0416 21:02:58.789999       1 flags.go:33] FLAG: --requestheader-group-headers="[x-remote-group]"
I0416 21:02:58.790007       1 flags.go:33] FLAG: --requestheader-username-headers="[x-remote-user]"
I0416 21:02:58.790015       1 flags.go:33] FLAG: --scheduler-name="default-scheduler"
I0416 21:02:58.790017       1 flags.go:33] FLAG: --secure-port="10259"
I0416 21:02:58.790020       1 flags.go:33] FLAG: --skip-headers="false"
I0416 21:02:58.790030       1 flags.go:33] FLAG: --stderrthreshold="2"
I0416 21:02:58.790037       1 flags.go:33] FLAG: --tls-cert-file=""
I0416 21:02:58.790039       1 flags.go:33] FLAG: --tls-cipher-suites="[]"
I0416 21:02:58.790046       1 flags.go:33] FLAG: --tls-min-version=""
I0416 21:02:58.790049       1 flags.go:33] FLAG: --tls-private-key-file=""
I0416 21:02:58.790051       1 flags.go:33] FLAG: --tls-sni-cert-key="[]"
I0416 21:02:58.790056       1 flags.go:33] FLAG: --use-legacy-policy-config="false"
I0416 21:02:58.790061       1 flags.go:33] FLAG: --v="4"
I0416 21:02:58.790064       1 flags.go:33] FLAG: --version="false"
I0416 21:02:58.790069       1 flags.go:33] FLAG: --vmodule=""
I0416 21:02:58.790072       1 flags.go:33] FLAG: --write-config-to=""
I0416 21:03:02.679391       1 serving.go:319] Generated self-signed cert in-memory
Log file created at: 2019/04/16 21:03:05
Running on machine: e2e-test-peterhornyack-master
Binary: Built with gc go1.12.1 for linux/amd64
Log line format: [IWEF]mmdd hh:mm:ss.uuuuuu threadid file:line] msg
W0416 21:03:05.631899       1 authentication.go:249] No authentication-kubeconfig provided in order to lookup client-ca-file in configmap/extension-apiserver-authentication in kube-system, so client certificate authentication won't work.
W0416 21:03:05.632034       1 authentication.go:252] No authentication-kubeconfig provided in order to lookup requestheader-client-ca-file in configmap/extension-apiserver-authentication in kube-system, so request-header client certificate authentication won't work.
W0416 21:03:05.632049       1 authorization.go:146] No authorization-kubeconfig provided, so SubjectAccessReview of authorization tokens won't work.
W0416 21:03:05.640570       1 authorization.go:47] Authorization is disabled
W0416 21:03:05.640578       1 authentication.go:55] Authentication is disabled
W0416 21:03:05.631899       1 authentication.go:249] No authentication-kubeconfig provided in order to lookup client-ca-file in configmap/extension-apiserver-authentication in kube-system, so client certificate authentication won't work.
W0416 21:03:05.632034       1 authentication.go:252] No authentication-kubeconfig provided in order to lookup requestheader-client-ca-file in configmap/extension-apiserver-authentication in kube-system, so request-header client certificate authentication won't work.
W0416 21:03:05.632049       1 authorization.go:146] No authorization-kubeconfig provided, so SubjectAccessReview of authorization tokens won't work.
I0416 21:03:05.636147       1 server.go:142] Version: v1.15.0-alpha.0.1887+bae0630ef897d6-dirty
I0416 21:03:05.636199       1 defaults.go:87] TaintNodesByCondition is enabled, PodToleratesNodeTaints predicate is mandatory
I0416 21:03:05.636208       1 server.go:161] Starting Kubernetes Scheduler version v1.15.0-alpha.0.1887+bae0630ef897d6-dirty
I0416 21:03:05.637125       1 factory.go:332] Creating scheduler from algorithm provider 'DefaultProvider'
I0416 21:03:05.637138       1 factory.go:413] Creating scheduler with fit predicates 'map[CheckNodeUnschedulable:{} CheckVolumeBinding:{} GeneralPredicates:{} MatchInterPodAffinity:{} MaxAzureDiskVolumeCount:{} MaxCSIVolumeCountPred:{} MaxEBSVolumeCount:{} MaxGCEPDVolumeCount:{} NoDiskConflict:{} NoVolumeZoneConflict:{} PodToleratesNodeTaints:{}]' and priority functions 'map[BalancedResourceAllocation:{} ImageLocalityPriority:{} InterPodAffinityPriority:{} LeastRequestedPriority:{} NodeAffinityPriority:{} NodePreferAvoidPodsPriority:{} SelectorSpreadPriority:{} TaintTolerationPriority:{}]'
W0416 21:03:05.640570       1 authorization.go:47] Authorization is disabled
W0416 21:03:05.640578       1 authentication.go:55] Authentication is disabled
I0416 21:03:05.640590       1 deprecated_insecure_serving.go:49] Serving healthz insecurely on [::]:10251
I0416 21:03:05.643483       1 secure_serving.go:116] Serving securely on [::]:10259
I0416 21:03:05.644746       1 reflector.go:128] Starting reflector *v1.Pod (0s) from cmd/kube-scheduler/app/server.go:223
I0416 21:03:05.644763       1 reflector.go:166] Listing and watching *v1.Pod from cmd/kube-scheduler/app/server.go:223
I0416 21:03:05.648369       1 reflector.go:128] Starting reflector *v1.Node (0s) from k8s.io/client-go/informers/factory.go:133
I0416 21:03:05.648381       1 reflector.go:166] Listing and watching *v1.Node from k8s.io/client-go/informers/factory.go:133
I0416 21:03:05.648677       1 reflector.go:128] Starting reflector *v1.PersistentVolume (0s) from k8s.io/client-go/informers/factory.go:133
I0416 21:03:05.648683       1 reflector.go:166] Listing and watching *v1.PersistentVolume from k8s.io/client-go/informers/factory.go:133
I0416 21:03:05.648895       1 reflector.go:128] Starting reflector *v1beta1.PodDisruptionBudget (0s) from k8s.io/client-go/informers/factory.go:133
I0416 21:03:05.648900       1 reflector.go:166] Listing and watching *v1beta1.PodDisruptionBudget from k8s.io/client-go/informers/factory.go:133
I0416 21:03:05.649076       1 reflector.go:128] Starting reflector *v1.StorageClass (0s) from k8s.io/client-go/informers/factory.go:133
I0416 21:03:05.649081       1 reflector.go:166] Listing and watching *v1.StorageClass from k8s.io/client-go/informers/factory.go:133
I0416 21:03:05.651286       1 reflector.go:128] Starting reflector *v1.Service (0s) from k8s.io/client-go/informers/factory.go:133
I0416 21:03:05.651299       1 reflector.go:166] Listing and watching *v1.Service from k8s.io/client-go/informers/factory.go:133
I0416 21:03:05.651584       1 reflector.go:128] Starting reflector *v1.ReplicationController (0s) from k8s.io/client-go/informers/factory.go:133
I0416 21:03:05.651590       1 reflector.go:166] Listing and watching *v1.ReplicationController from k8s.io/client-go/informers/factory.go:133
I0416 21:03:05.651768       1 reflector.go:128] Starting reflector *v1.ReplicaSet (0s) from k8s.io/client-go/informers/factory.go:133
I0416 21:03:05.651772       1 reflector.go:166] Listing and watching *v1.ReplicaSet from k8s.io/client-go/informers/factory.go:133
I0416 21:03:05.651960       1 reflector.go:128] Starting reflector *v1.StatefulSet (0s) from k8s.io/client-go/informers/factory.go:133
I0416 21:03:05.651964       1 reflector.go:166] Listing and watching *v1.StatefulSet from k8s.io/client-go/informers/factory.go:133
I0416 21:03:05.652115       1 reflector.go:128] Starting reflector *v1.PersistentVolumeClaim (0s) from k8s.io/client-go/informers/factory.go:133
I0416 21:03:05.652119       1 reflector.go:166] Listing and watching *v1.PersistentVolumeClaim from k8s.io/client-go/informers/factory.go:133
Log file created at: 2019/04/16 21:03:15
Running on machine: e2e-test-peterhornyack-master
Binary: Built with gc go1.12.1 for linux/amd64
Log line format: [IWEF]mmdd hh:mm:ss.uuuuuu threadid file:line] msg
E0416 21:03:15.656306       1 reflector.go:131] k8s.io/client-go/informers/factory.go:133: Failed to list *v1.ReplicaSet: Get https://localhost:443/apis/apps/v1/replicasets?limit=500&resourceVersion=0: net/http: TLS handshake timeout
E0416 21:03:15.656535       1 reflector.go:131] k8s.io/client-go/informers/factory.go:133: Failed to list *v1.StatefulSet: Get https://localhost:443/apis/apps/v1/statefulsets?limit=500&resourceVersion=0: net/http: TLS handshake timeout
E0416 21:03:15.656788       1 reflector.go:131] k8s.io/client-go/informers/factory.go:133: Failed to list *v1.PersistentVolumeClaim: Get https://localhost:443/api/v1/persistentvolumeclaims?limit=500&resourceVersion=0: net/http: TLS handshake timeout
E0416 21:03:15.656909       1 reflector.go:131] k8s.io/client-go/informers/factory.go:133: Failed to list *v1.ReplicationController: Get https://localhost:443/api/v1/replicationcontrollers?limit=500&resourceVersion=0: net/http: TLS handshake timeout
E0416 21:03:15.657001       1 reflector.go:131] k8s.io/client-go/informers/factory.go:133: Failed to list *v1.Service: Get https://localhost:443/api/v1/services?limit=500&resourceVersion=0: net/http: TLS handshake timeout
E0416 21:03:15.657078       1 reflector.go:131] k8s.io/client-go/informers/factory.go:133: Failed to list *v1.StorageClass: Get https://localhost:443/apis/storage.k8s.io/v1/storageclasses?limit=500&resourceVersion=0: net/http: TLS handshake timeout
E0416 21:03:15.657157       1 reflector.go:131] k8s.io/client-go/informers/factory.go:133: Failed to list *v1beta1.PodDisruptionBudget: Get https://localhost:443/apis/policy/v1beta1/poddisruptionbudgets?limit=500&resourceVersion=0: net/http: TLS handshake timeout
E0416 21:03:15.657269       1 reflector.go:131] k8s.io/client-go/informers/factory.go:133: Failed to list *v1.PersistentVolume: Get https://localhost:443/api/v1/persistentvolumes?limit=500&resourceVersion=0: net/http: TLS handshake timeout
E0416 21:03:15.657364       1 reflector.go:131] k8s.io/client-go/informers/factory.go:133: Failed to list *v1.Node: Get https://localhost:443/api/v1/nodes?limit=500&resourceVersion=0: net/http: TLS handshake timeout
E0416 21:03:15.657486       1 reflector.go:131] cmd/kube-scheduler/app/server.go:223: Failed to list *v1.Pod: Get https://localhost:443/api/v1/pods?fieldSelector=status.phase%21%3DFailed%2Cstatus.phase%21%3DSucceeded&limit=500&resourceVersion=0: net/http: TLS handshake timeout
E0416 21:03:15.656306       1 reflector.go:131] k8s.io/client-go/informers/factory.go:133: Failed to list *v1.ReplicaSet: Get https://localhost:443/apis/apps/v1/replicasets?limit=500&resourceVersion=0: net/http: TLS handshake timeout
E0416 21:03:15.656535       1 reflector.go:131] k8s.io/client-go/informers/factory.go:133: Failed to list *v1.StatefulSet: Get https://localhost:443/apis/apps/v1/statefulsets?limit=500&resourceVersion=0: net/http: TLS handshake timeout
E0416 21:03:15.656788       1 reflector.go:131] k8s.io/client-go/informers/factory.go:133: Failed to list *v1.PersistentVolumeClaim: Get https://localhost:443/api/v1/persistentvolumeclaims?limit=500&resourceVersion=0: net/http: TLS handshake timeout
E0416 21:03:15.656909       1 reflector.go:131] k8s.io/client-go/informers/factory.go:133: Failed to list *v1.ReplicationController: Get https://localhost:443/api/v1/replicationcontrollers?limit=500&resourceVersion=0: net/http: TLS handshake timeout
E0416 21:03:15.657001       1 reflector.go:131] k8s.io/client-go/informers/factory.go:133: Failed to list *v1.Service: Get https://localhost:443/api/v1/services?limit=500&resourceVersion=0: net/http: TLS handshake timeout
E0416 21:03:15.657078       1 reflector.go:131] k8s.io/client-go/informers/factory.go:133: Failed to list *v1.StorageClass: Get https://localhost:443/apis/storage.k8s.io/v1/storageclasses?limit=500&resourceVersion=0: net/http: TLS handshake timeout
E0416 21:03:15.657157       1 reflector.go:131] k8s.io/client-go/informers/factory.go:133: Failed to list *v1beta1.PodDisruptionBudget: Get https://localhost:443/apis/policy/v1beta1/poddisruptionbudgets?limit=500&resourceVersion=0: net/http: TLS handshake timeout
E0416 21:03:15.657269       1 reflector.go:131] k8s.io/client-go/informers/factory.go:133: Failed to list *v1.PersistentVolume: Get https://localhost:443/api/v1/persistentvolumes?limit=500&resourceVersion=0: net/http: TLS handshake timeout
E0416 21:03:15.657364       1 reflector.go:131] k8s.io/client-go/informers/factory.go:133: Failed to list *v1.Node: Get https://localhost:443/api/v1/nodes?limit=500&resourceVersion=0: net/http: TLS handshake timeout
E0416 21:03:15.657486       1 reflector.go:131] cmd/kube-scheduler/app/server.go:223: Failed to list *v1.Pod: Get https://localhost:443/api/v1/pods?fieldSelector=status.phase%21%3DFailed%2Cstatus.phase%21%3DSucceeded&limit=500&resourceVersion=0: net/http: TLS handshake timeout
I0416 21:03:15.656296       1 trace.go:81] Trace[647142704]: "Reflector k8s.io/client-go/informers/factory.go:133 ListAndWatch" (started: 2019-04-16 21:03:05.651774533 +0000 UTC m=+7.271186035) (total time: 10.004476615s):
Trace[647142704]: [10.004476615s] [10.004476615s] END
E0416 21:03:15.656306       1 reflector.go:131] k8s.io/client-go/informers/factory.go:133: Failed to list *v1.ReplicaSet: Get https://localhost:443/apis/apps/v1/replicasets?limit=500&resourceVersion=0: net/http: TLS handshake timeout
I0416 21:03:15.656532       1 trace.go:81] Trace[355084483]: "Reflector k8s.io/client-go/informers/factory.go:133 ListAndWatch" (started: 2019-04-16 21:03:05.65196568 +0000 UTC m=+7.271377168) (total time: 10.004536755s):
Trace[355084483]: [10.004536755s] [10.004536755s] END
E0416 21:03:15.656535       1 reflector.go:131] k8s.io/client-go/informers/factory.go:133: Failed to list *v1.StatefulSet: Get https://localhost:443/apis/apps/v1/statefulsets?limit=500&resourceVersion=0: net/http: TLS handshake timeout
I0416 21:03:15.656785       1 trace.go:81] Trace[866203980]: "Reflector k8s.io/client-go/informers/factory.go:133 ListAndWatch" (started: 2019-04-16 21:03:05.652120602 +0000 UTC m=+7.271532090) (total time: 10.004638985s):
Trace[866203980]: [10.004638985s] [10.004638985s] END
E0416 21:03:15.656788       1 reflector.go:131] k8s.io/client-go/informers/factory.go:133: Failed to list *v1.PersistentVolumeClaim: Get https://localhost:443/api/v1/persistentvolumeclaims?limit=500&resourceVersion=0: net/http: TLS handshake timeout
I0416 21:03:15.656906       1 trace.go:81] Trace[2046389567]: "Reflector k8s.io/client-go/informers/factory.go:133 ListAndWatch" (started: 2019-04-16 21:03:05.651591655 +0000 UTC m=+7.271003160) (total time: 10.005290858s):
Trace[2046389567]: [10.005290858s] [10.005290858s] END
E0416 21:03:15.656909       1 reflector.go:131] k8s.io/client-go/informers/factory.go:133: Failed to list *v1.ReplicationController: Get https://localhost:443/api/v1/replicationcontrollers?limit=500&resourceVersion=0: net/http: TLS handshake timeout
I0416 21:03:15.656999       1 trace.go:81] Trace[1531133016]: "Reflector k8s.io/client-go/informers/factory.go:133 ListAndWatch" (started: 2019-04-16 21:03:05.651301651 +0000 UTC m=+7.270713153) (total time: 10.005679119s):
Trace[1531133016]: [10.005679119s] [10.005679119s] END
E0416 21:03:15.657001       1 reflector.go:131] k8s.io/client-go/informers/factory.go:133: Failed to list *v1.Service: Get https://localhost:443/api/v1/services?limit=500&resourceVersion=0: net/http: TLS handshake timeout
I0416 21:03:15.657076       1 trace.go:81] Trace[1820501444]: "Reflector k8s.io/client-go/informers/factory.go:133 ListAndWatch" (started: 2019-04-16 21:03:05.649082552 +0000 UTC m=+7.268494054) (total time: 10.007976922s):
Trace[1820501444]: [10.007976922s] [10.007976922s] END
E0416 21:03:15.657078       1 reflector.go:131] k8s.io/client-go/informers/factory.go:133: Failed to list *v1.StorageClass: Get https://localhost:443/apis/storage.k8s.io/v1/storageclasses?limit=500&resourceVersion=0: net/http: TLS handshake timeout
I0416 21:03:15.657155       1 trace.go:81] Trace[1378246638]: "Reflector k8s.io/client-go/informers/factory.go:133 ListAndWatch" (started: 2019-04-16 21:03:05.648901896 +0000 UTC m=+7.268313384) (total time: 10.008236501s):
Trace[1378246638]: [10.008236501s] [10.008236501s] END
E0416 21:03:15.657157       1 reflector.go:131] k8s.io/client-go/informers/factory.go:133: Failed to list *v1beta1.PodDisruptionBudget: Get https://localhost:443/apis/policy/v1beta1/poddisruptionbudgets?limit=500&resourceVersion=0: net/http: TLS handshake timeout
I0416 21:03:15.657264       1 trace.go:81] Trace[1028526246]: "Reflector k8s.io/client-go/informers/factory.go:133 ListAndWatch" (started: 2019-04-16 21:03:05.64868539 +0000 UTC m=+7.268096892) (total time: 10.008528846s):
Trace[1028526246]: [10.008528846s] [10.008528846s] END
E0416 21:03:15.657269       1 reflector.go:131] k8s.io/client-go/informers/factory.go:133: Failed to list *v1.PersistentVolume: Get https://localhost:443/api/v1/persistentvolumes?limit=500&resourceVersion=0: net/http: TLS handshake timeout
I0416 21:03:15.657362       1 trace.go:81] Trace[1338411073]: "Reflector k8s.io/client-go/informers/factory.go:133 ListAndWatch" (started: 2019-04-16 21:03:05.64838491 +0000 UTC m=+7.267796406) (total time: 10.008959533s):
Trace[1338411073]: [10.008959533s] [10.008959533s] END
E0416 21:03:15.657364       1 reflector.go:131] k8s.io/client-go/informers/factory.go:133: Failed to list *v1.Node: Get https://localhost:443/api/v1/nodes?limit=500&resourceVersion=0: net/http: TLS handshake timeout
I0416 21:03:15.657479       1 trace.go:81] Trace[247273078]: "Reflector cmd/kube-scheduler/app/server.go:223 ListAndWatch" (started: 2019-04-16 21:03:05.644766842 +0000 UTC m=+7.264178346) (total time: 10.012680743s):
Trace[247273078]: [10.012680743s] [10.012680743s] END
E0416 21:03:15.657486       1 reflector.go:131] cmd/kube-scheduler/app/server.go:223: Failed to list *v1.Pod: Get https://localhost:443/api/v1/pods?fieldSelector=status.phase%21%3DFailed%2Cstatus.phase%21%3DSucceeded&limit=500&resourceVersion=0: net/http: TLS handshake timeout
I0416 21:03:16.467971       1 wrap.go:47] GET /healthz: (100.16µs) 200 [kube-probe/1.15+ 127.0.0.1:52176]
I0416 21:03:16.656663       1 reflector.go:166] Listing and watching *v1.ReplicaSet from k8s.io/client-go/informers/factory.go:133
I0416 21:03:16.659489       1 reflector.go:166] Listing and watching *v1.PersistentVolumeClaim from k8s.io/client-go/informers/factory.go:133
I0416 21:03:16.660280       1 reflector.go:166] Listing and watching *v1.StatefulSet from k8s.io/client-go/informers/factory.go:133
I0416 21:03:16.660766       1 reflector.go:166] Listing and watching *v1.ReplicationController from k8s.io/client-go/informers/factory.go:133
I0416 21:03:16.662345       1 reflector.go:166] Listing and watching *v1.Service from k8s.io/client-go/informers/factory.go:133
I0416 21:03:16.663488       1 reflector.go:166] Listing and watching *v1.StorageClass from k8s.io/client-go/informers/factory.go:133
I0416 21:03:16.664763       1 reflector.go:166] Listing and watching *v1beta1.PodDisruptionBudget from k8s.io/client-go/informers/factory.go:133
I0416 21:03:16.665958       1 reflector.go:166] Listing and watching *v1.PersistentVolume from k8s.io/client-go/informers/factory.go:133
I0416 21:03:16.667132       1 reflector.go:166] Listing and watching *v1.Node from k8s.io/client-go/informers/factory.go:133
I0416 21:03:16.670736       1 reflector.go:166] Listing and watching *v1.Pod from cmd/kube-scheduler/app/server.go:223
E0416 21:03:25.256016       1 reflector.go:131] k8s.io/client-go/informers/factory.go:133: Failed to list *v1.ReplicationController: replicationcontrollers is forbidden: User "system:kube-scheduler" cannot list resource "replicationcontrollers" in API group "" at the cluster scope
E0416 21:03:25.256110       1 reflector.go:131] k8s.io/client-go/informers/factory.go:133: Failed to list *v1.Service: services is forbidden: User "system:kube-scheduler" cannot list resource "services" in API group "" at the cluster scope
E0416 21:03:25.256184       1 reflector.go:131] k8s.io/client-go/informers/factory.go:133: Failed to list *v1.PersistentVolumeClaim: persistentvolumeclaims is forbidden: User "system:kube-scheduler" cannot list resource "persistentvolumeclaims" in API group "" at the cluster scope
E0416 21:03:25.256366       1 reflector.go:131] k8s.io/client-go/informers/factory.go:133: Failed to list *v1.ReplicaSet: replicasets.apps is forbidden: User "system:kube-scheduler" cannot list resource "replicasets" in API group "apps" at the cluster scope
E0416 21:03:25.256427       1 reflector.go:131] k8s.io/client-go/informers/factory.go:133: Failed to list *v1.StatefulSet: statefulsets.apps is forbidden: User "system:kube-scheduler" cannot list resource "statefulsets" in API group "apps" at the cluster scope
E0416 21:03:25.256497       1 reflector.go:131] cmd/kube-scheduler/app/server.go:223: Failed to list *v1.Pod: pods is forbidden: User "system:kube-scheduler" cannot list resource "pods" in API group "" at the cluster scope
E0416 21:03:25.256536       1 reflector.go:131] k8s.io/client-go/informers/factory.go:133: Failed to list *v1beta1.PodDisruptionBudget: poddisruptionbudgets.policy is forbidden: User "system:kube-scheduler" cannot list resource "poddisruptionbudgets" in API group "policy" at the cluster scope
E0416 21:03:25.256580       1 reflector.go:131] k8s.io/client-go/informers/factory.go:133: Failed to list *v1.PersistentVolume: persistentvolumes is forbidden: User "system:kube-scheduler" cannot list resource "persistentvolumes" in API group "" at the cluster scope
E0416 21:03:25.256613       1 reflector.go:131] k8s.io/client-go/informers/factory.go:133: Failed to list *v1.Node: nodes is forbidden: User "system:kube-scheduler" cannot list resource "nodes" in API group "" at the cluster scope
E0416 21:03:25.259020       1 reflector.go:131] k8s.io/client-go/informers/factory.go:133: Failed to list *v1.StorageClass: storageclasses.storage.k8s.io is forbidden: User "system:kube-scheduler" cannot list resource "storageclasses" in API group "storage.k8s.io" at the cluster scope
E0416 21:03:26.261562       1 reflector.go:131] k8s.io/client-go/informers/factory.go:133: Failed to list *v1.ReplicationController: replicationcontrollers is forbidden: User "system:kube-scheduler" cannot list resource "replicationcontrollers" in API group "" at the cluster scope
E0416 21:03:26.280011       1 reflector.go:131] k8s.io/client-go/informers/factory.go:133: Failed to list *v1.Service: services is forbidden: User "system:kube-scheduler" cannot list resource "services" in API group "" at the cluster scope
E0416 21:03:26.280097       1 reflector.go:131] k8s.io/client-go/informers/factory.go:133: Failed to list *v1.PersistentVolumeClaim: persistentvolumeclaims is forbidden: User "system:kube-scheduler" cannot list resource "persistentvolumeclaims" in API group "" at the cluster scope
E0416 21:03:26.280142       1 reflector.go:131] k8s.io/client-go/informers/factory.go:133: Failed to list *v1.ReplicaSet: replicasets.apps is forbidden: User "system:kube-scheduler" cannot list resource "replicasets" in API group "apps" at the cluster scope
E0416 21:03:26.313994       1 reflector.go:131] k8s.io/client-go/informers/factory.go:133: Failed to list *v1beta1.PodDisruptionBudget: poddisruptionbudgets.policy is forbidden: User "system:kube-scheduler" cannot list resource "poddisruptionbudgets" in API group "policy" at the cluster scope
E0416 21:03:26.326171       1 reflector.go:131] k8s.io/client-go/informers/factory.go:133: Failed to list *v1.StorageClass: storageclasses.storage.k8s.io is forbidden: User "system:kube-scheduler" cannot list resource "storageclasses" in API group "storage.k8s.io" at the cluster scope
E0416 21:03:26.326353       1 reflector.go:131] k8s.io/client-go/informers/factory.go:133: Failed to list *v1.StatefulSet: statefulsets.apps is forbidden: User "system:kube-scheduler" cannot list resource "statefulsets" in API group "apps" at the cluster scope
E0416 21:03:26.326423       1 reflector.go:131] cmd/kube-scheduler/app/server.go:223: Failed to list *v1.Pod: pods is forbidden: User "system:kube-scheduler" cannot list resource "pods" in API group "" at the cluster scope
E0416 21:03:26.335426       1 reflector.go:131] k8s.io/client-go/informers/factory.go:133: Failed to list *v1.Node: nodes is forbidden: User "system:kube-scheduler" cannot list resource "nodes" in API group "" at the cluster scope
E0416 21:03:26.335821       1 reflector.go:131] k8s.io/client-go/informers/factory.go:133: Failed to list *v1.PersistentVolume: persistentvolumes is forbidden: User "system:kube-scheduler" cannot list resource "persistentvolumes" in API group "" at the cluster scope
E0416 21:03:25.256016       1 reflector.go:131] k8s.io/client-go/informers/factory.go:133: Failed to list *v1.ReplicationController: replicationcontrollers is forbidden: User "system:kube-scheduler" cannot list resource "replicationcontrollers" in API group "" at the cluster scope
E0416 21:03:25.256110       1 reflector.go:131] k8s.io/client-go/informers/factory.go:133: Failed to list *v1.Service: services is forbidden: User "system:kube-scheduler" cannot list resource "services" in API group "" at the cluster scope
E0416 21:03:25.256184       1 reflector.go:131] k8s.io/client-go/informers/factory.go:133: Failed to list *v1.PersistentVolumeClaim: persistentvolumeclaims is forbidden: User "system:kube-scheduler" cannot list resource "persistentvolumeclaims" in API group "" at the cluster scope
E0416 21:03:25.256366       1 reflector.go:131] k8s.io/client-go/informers/factory.go:133: Failed to list *v1.ReplicaSet: replicasets.apps is forbidden: User "system:kube-scheduler" cannot list resource "replicasets" in API group "apps" at the cluster scope
E0416 21:03:25.256427       1 reflector.go:131] k8s.io/client-go/informers/factory.go:133: Failed to list *v1.StatefulSet: statefulsets.apps is forbidden: User "system:kube-scheduler" cannot list resource "statefulsets" in API group "apps" at the cluster scope
E0416 21:03:25.256497       1 reflector.go:131] cmd/kube-scheduler/app/server.go:223: Failed to list *v1.Pod: pods is forbidden: User "system:kube-scheduler" cannot list resource "pods" in API group "" at the cluster scope
E0416 21:03:25.256536       1 reflector.go:131] k8s.io/client-go/informers/factory.go:133: Failed to list *v1beta1.PodDisruptionBudget: poddisruptionbudgets.policy is forbidden: User "system:kube-scheduler" cannot list resource "poddisruptionbudgets" in API group "policy" at the cluster scope
E0416 21:03:25.256580       1 reflector.go:131] k8s.io/client-go/informers/factory.go:133: Failed to list *v1.PersistentVolume: persistentvolumes is forbidden: User "system:kube-scheduler" cannot list resource "persistentvolumes" in API group "" at the cluster scope
E0416 21:03:25.256613       1 reflector.go:131] k8s.io/client-go/informers/factory.go:133: Failed to list *v1.Node: nodes is forbidden: User "system:kube-scheduler" cannot list resource "nodes" in API group "" at the cluster scope
E0416 21:03:25.259020       1 reflector.go:131] k8s.io/client-go/informers/factory.go:133: Failed to list *v1.StorageClass: storageclasses.storage.k8s.io is forbidden: User "system:kube-scheduler" cannot list resource "storageclasses" in API group "storage.k8s.io" at the cluster scope
E0416 21:03:26.261562       1 reflector.go:131] k8s.io/client-go/informers/factory.go:133: Failed to list *v1.ReplicationController: replicationcontrollers is forbidden: User "system:kube-scheduler" cannot list resource "replicationcontrollers" in API group "" at the cluster scope
E0416 21:03:26.280011       1 reflector.go:131] k8s.io/client-go/informers/factory.go:133: Failed to list *v1.Service: services is forbidden: User "system:kube-scheduler" cannot list resource "services" in API group "" at the cluster scope
E0416 21:03:26.280097       1 reflector.go:131] k8s.io/client-go/informers/factory.go:133: Failed to list *v1.PersistentVolumeClaim: persistentvolumeclaims is forbidden: User "system:kube-scheduler" cannot list resource "persistentvolumeclaims" in API group "" at the cluster scope
E0416 21:03:26.280142       1 reflector.go:131] k8s.io/client-go/informers/factory.go:133: Failed to list *v1.ReplicaSet: replicasets.apps is forbidden: User "system:kube-scheduler" cannot list resource "replicasets" in API group "apps" at the cluster scope
E0416 21:03:26.313994       1 reflector.go:131] k8s.io/client-go/informers/factory.go:133: Failed to list *v1beta1.PodDisruptionBudget: poddisruptionbudgets.policy is forbidden: User "system:kube-scheduler" cannot list resource "poddisruptionbudgets" in API group "policy" at the cluster scope
E0416 21:03:26.326171       1 reflector.go:131] k8s.io/client-go/informers/factory.go:133: Failed to list *v1.StorageClass: storageclasses.storage.k8s.io is forbidden: User "system:kube-scheduler" cannot list resource "storageclasses" in API group "storage.k8s.io" at the cluster scope
E0416 21:03:26.326353       1 reflector.go:131] k8s.io/client-go/informers/factory.go:133: Failed to list *v1.StatefulSet: statefulsets.apps is forbidden: User "system:kube-scheduler" cannot list resource "statefulsets" in API group "apps" at the cluster scope
E0416 21:03:26.326423       1 reflector.go:131] cmd/kube-scheduler/app/server.go:223: Failed to list *v1.Pod: pods is forbidden: User "system:kube-scheduler" cannot list resource "pods" in API group "" at the cluster scope
E0416 21:03:26.335426       1 reflector.go:131] k8s.io/client-go/informers/factory.go:133: Failed to list *v1.Node: nodes is forbidden: User "system:kube-scheduler" cannot list resource "nodes" in API group "" at the cluster scope
E0416 21:03:26.335821       1 reflector.go:131] k8s.io/client-go/informers/factory.go:133: Failed to list *v1.PersistentVolume: persistentvolumes is forbidden: User "system:kube-scheduler" cannot list resource "persistentvolumes" in API group "" at the cluster scope
E0416 21:03:25.256016       1 reflector.go:131] k8s.io/client-go/informers/factory.go:133: Failed to list *v1.ReplicationController: replicationcontrollers is forbidden: User "system:kube-scheduler" cannot list resource "replicationcontrollers" in API group "" at the cluster scope
E0416 21:03:25.256110       1 reflector.go:131] k8s.io/client-go/informers/factory.go:133: Failed to list *v1.Service: services is forbidden: User "system:kube-scheduler" cannot list resource "services" in API group "" at the cluster scope
E0416 21:03:25.256184       1 reflector.go:131] k8s.io/client-go/informers/factory.go:133: Failed to list *v1.PersistentVolumeClaim: persistentvolumeclaims is forbidden: User "system:kube-scheduler" cannot list resource "persistentvolumeclaims" in API group "" at the cluster scope
E0416 21:03:25.256366       1 reflector.go:131] k8s.io/client-go/informers/factory.go:133: Failed to list *v1.ReplicaSet: replicasets.apps is forbidden: User "system:kube-scheduler" cannot list resource "replicasets" in API group "apps" at the cluster scope
E0416 21:03:25.256427       1 reflector.go:131] k8s.io/client-go/informers/factory.go:133: Failed to list *v1.StatefulSet: statefulsets.apps is forbidden: User "system:kube-scheduler" cannot list resource "statefulsets" in API group "apps" at the cluster scope
E0416 21:03:25.256497       1 reflector.go:131] cmd/kube-scheduler/app/server.go:223: Failed to list *v1.Pod: pods is forbidden: User "system:kube-scheduler" cannot list resource "pods" in API group "" at the cluster scope
E0416 21:03:25.256536       1 reflector.go:131] k8s.io/client-go/informers/factory.go:133: Failed to list *v1beta1.PodDisruptionBudget: poddisruptionbudgets.policy is forbidden: User "system:kube-scheduler" cannot list resource "poddisruptionbudgets" in API group "policy" at the cluster scope
E0416 21:03:25.256580       1 reflector.go:131] k8s.io/client-go/informers/factory.go:133: Failed to list *v1.PersistentVolume: persistentvolumes is forbidden: User "system:kube-scheduler" cannot list resource "persistentvolumes" in API group "" at the cluster scope
E0416 21:03:25.256613       1 reflector.go:131] k8s.io/client-go/informers/factory.go:133: Failed to list *v1.Node: nodes is forbidden: User "system:kube-scheduler" cannot list resource "nodes" in API group "" at the cluster scope
E0416 21:03:25.259020       1 reflector.go:131] k8s.io/client-go/informers/factory.go:133: Failed to list *v1.StorageClass: storageclasses.storage.k8s.io is forbidden: User "system:kube-scheduler" cannot list resource "storageclasses" in API group "storage.k8s.io" at the cluster scope
I0416 21:03:26.257579       1 reflector.go:166] Listing and watching *v1.ReplicationController from k8s.io/client-go/informers/factory.go:133
E0416 21:03:26.261562       1 reflector.go:131] k8s.io/client-go/informers/factory.go:133: Failed to list *v1.ReplicationController: replicationcontrollers is forbidden: User "system:kube-scheduler" cannot list resource "replicationcontrollers" in API group "" at the cluster scope
I0416 21:03:26.267602       1 reflector.go:166] Listing and watching *v1.ReplicaSet from k8s.io/client-go/informers/factory.go:133
I0416 21:03:26.267944       1 reflector.go:166] Listing and watching *v1.Service from k8s.io/client-go/informers/factory.go:133
I0416 21:03:26.268038       1 reflector.go:166] Listing and watching *v1.PersistentVolumeClaim from k8s.io/client-go/informers/factory.go:133
E0416 21:03:26.280011       1 reflector.go:131] k8s.io/client-go/informers/factory.go:133: Failed to list *v1.Service: services is forbidden: User "system:kube-scheduler" cannot list resource "services" in API group "" at the cluster scope
E0416 21:03:26.280097       1 reflector.go:131] k8s.io/client-go/informers/factory.go:133: Failed to list *v1.PersistentVolumeClaim: persistentvolumeclaims is forbidden: User "system:kube-scheduler" cannot list resource "persistentvolumeclaims" in API group "" at the cluster scope
E0416 21:03:26.280142       1 reflector.go:131] k8s.io/client-go/informers/factory.go:133: Failed to list *v1.ReplicaSet: replicasets.apps is forbidden: User "system:kube-scheduler" cannot list resource "replicasets" in API group "apps" at the cluster scope
I0416 21:03:26.285811       1 reflector.go:166] Listing and watching *v1.StorageClass from k8s.io/client-go/informers/factory.go:133
I0416 21:03:26.286152       1 reflector.go:166] Listing and watching *v1.StatefulSet from k8s.io/client-go/informers/factory.go:133
I0416 21:03:26.288453       1 reflector.go:166] Listing and watching *v1.Pod from cmd/kube-scheduler/app/server.go:223
I0416 21:03:26.288713       1 reflector.go:166] Listing and watching *v1beta1.PodDisruptionBudget from k8s.io/client-go/informers/factory.go:133
I0416 21:03:26.298291       1 reflector.go:166] Listing and watching *v1.PersistentVolume from k8s.io/client-go/informers/factory.go:133
I0416 21:03:26.298598       1 reflector.go:166] Listing and watching *v1.Node from k8s.io/client-go/informers/factory.go:133
E0416 21:03:26.313994       1 reflector.go:131] k8s.io/client-go/informers/factory.go:133: Failed to list *v1beta1.PodDisruptionBudget: poddisruptionbudgets.policy is forbidden: User "system:kube-scheduler" cannot list resource "poddisruptionbudgets" in API group "policy" at the cluster scope
E0416 21:03:26.326171       1 reflector.go:131] k8s.io/client-go/informers/factory.go:133: Failed to list *v1.StorageClass: storageclasses.storage.k8s.io is forbidden: User "system:kube-scheduler" cannot list resource "storageclasses" in API group "storage.k8s.io" at the cluster scope
E0416 21:03:26.326353       1 reflector.go:131] k8s.io/client-go/informers/factory.go:133: Failed to list *v1.StatefulSet: statefulsets.apps is forbidden: User "system:kube-scheduler" cannot list resource "statefulsets" in API group "apps" at the cluster scope
E0416 21:03:26.326423       1 reflector.go:131] cmd/kube-scheduler/app/server.go:223: Failed to list *v1.Pod: pods is forbidden: User "system:kube-scheduler" cannot list resource "pods" in API group "" at the cluster scope
E0416 21:03:26.335426       1 reflector.go:131] k8s.io/client-go/informers/factory.go:133: Failed to list *v1.Node: nodes is forbidden: User "system:kube-scheduler" cannot list resource "nodes" in API group "" at the cluster scope
E0416 21:03:26.335821       1 reflector.go:131] k8s.io/client-go/informers/factory.go:133: Failed to list *v1.PersistentVolume: persistentvolumes is forbidden: User "system:kube-scheduler" cannot list resource "persistentvolumes" in API group "" at the cluster scope
I0416 21:03:26.474560       1 wrap.go:47] GET /healthz: (73.734µs) 200 [kube-probe/1.15+ 127.0.0.1:52988]
I0416 21:03:27.265572       1 reflector.go:166] Listing and watching *v1.ReplicationController from k8s.io/client-go/informers/factory.go:133
I0416 21:03:27.280434       1 reflector.go:166] Listing and watching *v1.Service from k8s.io/client-go/informers/factory.go:133
I0416 21:03:27.299024       1 reflector.go:166] Listing and watching *v1.PersistentVolumeClaim from k8s.io/client-go/informers/factory.go:133
I0416 21:03:27.326726       1 reflector.go:166] Listing and watching *v1.ReplicaSet from k8s.io/client-go/informers/factory.go:133
I0416 21:03:27.328709       1 reflector.go:166] Listing and watching *v1beta1.PodDisruptionBudget from k8s.io/client-go/informers/factory.go:133
I0416 21:03:27.336159       1 reflector.go:166] Listing and watching *v1.StorageClass from k8s.io/client-go/informers/factory.go:133
I0416 21:03:27.348486       1 reflector.go:166] Listing and watching *v1.StatefulSet from k8s.io/client-go/informers/factory.go:133
I0416 21:03:27.363272       1 reflector.go:166] Listing and watching *v1.Node from k8s.io/client-go/informers/factory.go:133
I0416 21:03:27.363581       1 reflector.go:166] Listing and watching *v1.Pod from cmd/kube-scheduler/app/server.go:223
I0416 21:03:27.363789       1 reflector.go:166] Listing and watching *v1.PersistentVolume from k8s.io/client-go/informers/factory.go:133
I0416 21:03:27.444318       1 shared_informer.go:123] caches populated
I0416 21:03:27.544523       1 shared_informer.go:123] caches populated
I0416 21:03:27.644631       1 shared_informer.go:123] caches populated
I0416 21:03:27.744996       1 shared_informer.go:123] caches populated
I0416 21:03:27.845173       1 shared_informer.go:123] caches populated
I0416 21:03:27.945314       1 shared_informer.go:123] caches populated
I0416 21:03:28.046350       1 shared_informer.go:123] caches populated
I0416 21:03:28.146511       1 shared_informer.go:123] caches populated
I0416 21:03:28.246611       1 shared_informer.go:123] caches populated
I0416 21:03:28.246647       1 controller_utils.go:1028] Waiting for caches to sync for scheduler controller
I0416 21:03:28.346817       1 shared_informer.go:123] caches populated
I0416 21:03:28.346834       1 controller_utils.go:1035] Caches are synced for scheduler controller
I0416 21:03:28.346964       1 leaderelection.go:217] attempting to acquire leader lease  kube-system/kube-scheduler...
I0416 21:03:28.356041       1 leaderelection.go:227] successfully acquired lease kube-system/kube-scheduler
I0416 21:03:28.461445       1 shared_informer.go:123] caches populated
I0416 21:03:36.468513       1 wrap.go:47] GET /healthz: (109.465µs) 200 [kube-probe/1.15+ 127.0.0.1:53146]
E0416 21:03:44.531893       1 scheduler.go:482] error selecting node for pod: no nodes available to schedule pods
E0416 21:03:44.681331       1 scheduler.go:482] error selecting node for pod: no nodes available to schedule pods
E0416 21:03:44.869635       1 scheduler.go:482] error selecting node for pod: no nodes available to schedule pods
E0416 21:03:45.358002       1 scheduler.go:482] error selecting node for pod: no nodes available to schedule pods
E0416 21:03:45.358422       1 scheduler.go:482] error selecting node for pod: no nodes available to schedule pods
E0416 21:03:45.681488       1 scheduler.go:482] error selecting node for pod: no nodes available to schedule pods
E0416 21:03:45.685454       1 scheduler.go:482] error selecting node for pod: no nodes available to schedule pods
E0416 21:03:46.682481       1 scheduler.go:482] error selecting node for pod: no nodes available to schedule pods
E0416 21:03:46.879705       1 scheduler.go:482] error selecting node for pod: no nodes available to schedule pods
E0416 21:03:46.880147       1 scheduler.go:482] error selecting node for pod: no nodes available to schedule pods
E0416 21:03:47.059819       1 scheduler.go:482] error selecting node for pod: no nodes available to schedule pods
E0416 21:03:44.531893       1 scheduler.go:482] error selecting node for pod: no nodes available to schedule pods
E0416 21:03:44.681331       1 scheduler.go:482] error selecting node for pod: no nodes available to schedule pods
E0416 21:03:44.869635       1 scheduler.go:482] error selecting node for pod: no nodes available to schedule pods
E0416 21:03:45.358002       1 scheduler.go:482] error selecting node for pod: no nodes available to schedule pods
E0416 21:03:45.358422       1 scheduler.go:482] error selecting node for pod: no nodes available to schedule pods
E0416 21:03:45.681488       1 scheduler.go:482] error selecting node for pod: no nodes available to schedule pods
E0416 21:03:45.685454       1 scheduler.go:482] error selecting node for pod: no nodes available to schedule pods
E0416 21:03:46.682481       1 scheduler.go:482] error selecting node for pod: no nodes available to schedule pods
E0416 21:03:46.879705       1 scheduler.go:482] error selecting node for pod: no nodes available to schedule pods
E0416 21:03:46.880147       1 scheduler.go:482] error selecting node for pod: no nodes available to schedule pods
E0416 21:03:47.059819       1 scheduler.go:482] error selecting node for pod: no nodes available to schedule pods
I0416 21:03:44.504334       1 scheduling_queue.go:895] About to try and schedule pod kube-system/coredns-5b969f4c88-zcdpb
I0416 21:03:44.504347       1 scheduler.go:454] Attempting to schedule pod: kube-system/coredns-5b969f4c88-zcdpb
I0416 21:03:44.504389       1 factory.go:645] Unable to schedule kube-system/coredns-5b969f4c88-zcdpb: no nodes are registered to the cluster; waiting
I0416 21:03:44.504430       1 factory.go:743] Updating pod condition for kube-system/coredns-5b969f4c88-zcdpb to (PodScheduled==False, Reason=Unschedulable)
E0416 21:03:44.531893       1 scheduler.go:482] error selecting node for pod: no nodes available to schedule pods
I0416 21:03:44.617890       1 scheduling_queue.go:895] About to try and schedule pod kube-system/l7-default-backend-8f479dd9-wbtkw
I0416 21:03:44.617903       1 scheduler.go:454] Attempting to schedule pod: kube-system/l7-default-backend-8f479dd9-wbtkw
I0416 21:03:44.617947       1 factory.go:645] Unable to schedule kube-system/l7-default-backend-8f479dd9-wbtkw: no nodes are registered to the cluster; waiting
I0416 21:03:44.617974       1 factory.go:743] Updating pod condition for kube-system/l7-default-backend-8f479dd9-wbtkw to (PodScheduled==False, Reason=Unschedulable)
E0416 21:03:44.681331       1 scheduler.go:482] error selecting node for pod: no nodes available to schedule pods
I0416 21:03:44.836737       1 scheduling_queue.go:895] About to try and schedule pod kube-system/heapster-v1.6.0-beta.1-5858bf5485-5td9x
I0416 21:03:44.836776       1 scheduler.go:454] Attempting to schedule pod: kube-system/heapster-v1.6.0-beta.1-5858bf5485-5td9x
I0416 21:03:44.836843       1 factory.go:645] Unable to schedule kube-system/heapster-v1.6.0-beta.1-5858bf5485-5td9x: no nodes are registered to the cluster; waiting
I0416 21:03:44.836876       1 factory.go:743] Updating pod condition for kube-system/heapster-v1.6.0-beta.1-5858bf5485-5td9x to (PodScheduled==False, Reason=Unschedulable)
E0416 21:03:44.869635       1 scheduler.go:482] error selecting node for pod: no nodes available to schedule pods
I0416 21:03:45.330637       1 scheduling_queue.go:895] About to try and schedule pod kube-system/event-exporter-v0.2.4-65d8d98768-n6vvr
I0416 21:03:45.332273       1 scheduler.go:454] Attempting to schedule pod: kube-system/event-exporter-v0.2.4-65d8d98768-n6vvr
I0416 21:03:45.332358       1 factory.go:645] Unable to schedule kube-system/event-exporter-v0.2.4-65d8d98768-n6vvr: no nodes are registered to the cluster; waiting
I0416 21:03:45.332404       1 factory.go:743] Updating pod condition for kube-system/event-exporter-v0.2.4-65d8d98768-n6vvr to (PodScheduled==False, Reason=Unschedulable)
E0416 21:03:45.358002       1 scheduler.go:482] error selecting node for pod: no nodes available to schedule pods
I0416 21:03:45.358317       1 scheduling_queue.go:895] About to try and schedule pod kube-system/event-exporter-v0.2.4-65d8d98768-n6vvr
I0416 21:03:45.358349       1 scheduler.go:454] Attempting to schedule pod: kube-system/event-exporter-v0.2.4-65d8d98768-n6vvr
I0416 21:03:45.358381       1 factory.go:645] Unable to schedule kube-system/event-exporter-v0.2.4-65d8d98768-n6vvr: no nodes are registered to the cluster; waiting
I0416 21:03:45.358405       1 factory.go:743] Updating pod condition for kube-system/event-exporter-v0.2.4-65d8d98768-n6vvr to (PodScheduled==False, Reason=Unschedulable)
E0416 21:03:45.358422       1 scheduler.go:482] error selecting node for pod: no nodes available to schedule pods
I0416 21:03:45.681381       1 scheduling_queue.go:895] About to try and schedule pod kube-system/coredns-5b969f4c88-zcdpb
I0416 21:03:45.681394       1 scheduler.go:454] Attempting to schedule pod: kube-system/coredns-5b969f4c88-zcdpb
I0416 21:03:45.681445       1 factory.go:645] Unable to schedule kube-system/coredns-5b969f4c88-zcdpb: no nodes are registered to the cluster; waiting
I0416 21:03:45.681478       1 factory.go:743] Updating pod condition for kube-system/coredns-5b969f4c88-zcdpb to (PodScheduled==False, Reason=Unschedulable)
E0416 21:03:45.681488       1 scheduler.go:482] error selecting node for pod: no nodes available to schedule pods
I0416 21:03:45.685338       1 scheduling_queue.go:895] About to try and schedule pod kube-system/l7-default-backend-8f479dd9-wbtkw
I0416 21:03:45.685362       1 scheduler.go:454] Attempting to schedule pod: kube-system/l7-default-backend-8f479dd9-wbtkw
I0416 21:03:45.685414       1 factory.go:645] Unable to schedule kube-system/l7-default-backend-8f479dd9-wbtkw: no nodes are registered to the cluster; waiting
I0416 21:03:45.685445       1 factory.go:743] Updating pod condition for kube-system/l7-default-backend-8f479dd9-wbtkw to (PodScheduled==False, Reason=Unschedulable)
E0416 21:03:45.685454       1 scheduler.go:482] error selecting node for pod: no nodes available to schedule pods
I0416 21:03:45.810671       1 backoff_utils.go:79] Backing off 2s
I0416 21:03:45.810797       1 backoff_utils.go:79] Backing off 2s
I0416 21:03:46.471630       1 wrap.go:47] GET /healthz: (80.1µs) 200 [kube-probe/1.15+ 127.0.0.1:53260]
I0416 21:03:46.682346       1 scheduling_queue.go:895] About to try and schedule pod kube-system/heapster-v1.6.0-beta.1-5858bf5485-5td9x
I0416 21:03:46.682358       1 scheduler.go:454] Attempting to schedule pod: kube-system/heapster-v1.6.0-beta.1-5858bf5485-5td9x
I0416 21:03:46.682437       1 factory.go:645] Unable to schedule kube-system/heapster-v1.6.0-beta.1-5858bf5485-5td9x: no nodes are registered to the cluster; waiting
I0416 21:03:46.682472       1 factory.go:743] Updating pod condition for kube-system/heapster-v1.6.0-beta.1-5858bf5485-5td9x to (PodScheduled==False, Reason=Unschedulable)
E0416 21:03:46.682481       1 scheduler.go:482] error selecting node for pod: no nodes available to schedule pods
I0416 21:03:46.777000       1 backoff_utils.go:79] Backing off 2s
I0416 21:03:46.806810       1 scheduling_queue.go:895] About to try and schedule pod kube-system/metrics-server-v0.3.1-677c578bdf-xl48c
I0416 21:03:46.806841       1 scheduler.go:454] Attempting to schedule pod: kube-system/metrics-server-v0.3.1-677c578bdf-xl48c
I0416 21:03:46.806877       1 factory.go:645] Unable to schedule kube-system/metrics-server-v0.3.1-677c578bdf-xl48c: no nodes are registered to the cluster; waiting
I0416 21:03:46.806920       1 factory.go:743] Updating pod condition for kube-system/metrics-server-v0.3.1-677c578bdf-xl48c to (PodScheduled==False, Reason=Unschedulable)
E0416 21:03:46.879705       1 scheduler.go:482] error selecting node for pod: no nodes available to schedule pods
I0416 21:03:46.880032       1 scheduling_queue.go:895] About to try and schedule pod kube-system/metrics-server-v0.3.1-677c578bdf-xl48c
I0416 21:03:46.880041       1 scheduler.go:454] Attempting to schedule pod: kube-system/metrics-server-v0.3.1-677c578bdf-xl48c
I0416 21:03:46.880094       1 factory.go:645] Unable to schedule kube-system/metrics-server-v0.3.1-677c578bdf-xl48c: no nodes are registered to the cluster; waiting
I0416 21:03:46.880136       1 factory.go:743] Updating pod condition for kube-system/metrics-server-v0.3.1-677c578bdf-xl48c to (PodScheduled==False, Reason=Unschedulable)
E0416 21:03:46.880147       1 scheduler.go:482] error selecting node for pod: no nodes available to schedule pods
I0416 21:03:47.059702       1 scheduling_queue.go:895] About to try and schedule pod kube-system/event-exporter-v0.2.4-65d8d98768-n6vvr
I0416 21:03:47.059713       1 scheduler.go:454] Attempting to schedule pod: kube-system/event-exporter-v0.2.4-65d8d98768-n6vvr
I0416 21:03:47.059769       1 factory.go:645] Unable to schedule kube-system/event-exporter-v0.2.4-65d8d98768-n6vvr: no nodes are registered to the cluster; waiting
I0416 21:03:47.059795       1 factory.go:743] Updating pod condition for kube-system/event-exporter-v0.2.4-65d8d98768-n6vvr to (PodScheduled==False, Reason=Unschedulable)
E0416 21:03:47.059819       1 scheduler.go:482] error selecting node for pod: no nodes available to schedule pods
I0416 21:03:47.074936       1 backoff_utils.go:79] Backing off 2s
E0416 21:03:48.683164       1 scheduler.go:482] error selecting node for pod: no nodes available to schedule pods
E0416 21:03:48.691041       1 scheduler.go:482] error selecting node for pod: no nodes available to schedule pods
E0416 21:03:48.697551       1 scheduler.go:482] error selecting node for pod: no nodes available to schedule pods
E0416 21:03:49.000656       1 scheduler.go:482] error selecting node for pod: no nodes available to schedule pods
E0416 21:03:49.002093       1 scheduler.go:482] error selecting node for pod: no nodes available to schedule pods
E0416 21:03:49.683387       1 scheduler.go:482] error selecting node for pod: no nodes available to schedule pods
E0416 21:03:50.657614       1 scheduler.go:482] error selecting node for pod: no nodes available to schedule pods
E0416 21:03:50.657787       1 scheduler.go:482] error selecting node for pod: no nodes available to schedule pods
E0416 21:03:50.761422       1 scheduler.go:482] error selecting node for pod: no nodes available to schedule pods
E0416 21:03:50.762586       1 scheduler.go:482] error selecting node for pod: no nodes available to schedule pods
E0416 21:03:48.683164       1 scheduler.go:482] error selecting node for pod: no nodes available to schedule pods
E0416 21:03:48.691041       1 scheduler.go:482] error selecting node for pod: no nodes available to schedule pods
E0416 21:03:48.697551       1 scheduler.go:482] error selecting node for pod: no nodes available to schedule pods
E0416 21:03:49.000656       1 scheduler.go:482] error selecting node for pod: no nodes available to schedule pods
E0416 21:03:49.002093       1 scheduler.go:482] error selecting node for pod: no nodes available to schedule pods
E0416 21:03:49.683387       1 scheduler.go:482] error selecting node for pod: no nodes available to schedule pods
E0416 21:03:50.657614       1 scheduler.go:482] error selecting node for pod: no nodes available to schedule pods
E0416 21:03:50.657787       1 scheduler.go:482] error selecting node for pod: no nodes available to schedule pods
E0416 21:03:50.761422       1 scheduler.go:482] error selecting node for pod: no nodes available to schedule pods
E0416 21:03:50.762586       1 scheduler.go:482] error selecting node for pod: no nodes available to schedule pods
I0416 21:03:48.683030       1 scheduling_queue.go:895] About to try and schedule pod kube-system/coredns-5b969f4c88-zcdpb
I0416 21:03:48.683043       1 scheduler.go:454] Attempting to schedule pod: kube-system/coredns-5b969f4c88-zcdpb
I0416 21:03:48.683119       1 factory.go:645] Unable to schedule kube-system/coredns-5b969f4c88-zcdpb: no nodes are registered to the cluster; waiting
I0416 21:03:48.683155       1 factory.go:743] Updating pod condition for kube-system/coredns-5b969f4c88-zcdpb to (PodScheduled==False, Reason=Unschedulable)
E0416 21:03:48.683164       1 scheduler.go:482] error selecting node for pod: no nodes available to schedule pods
I0416 21:03:48.689804       1 backoff_utils.go:79] Backing off 4s
I0416 21:03:48.690863       1 scheduling_queue.go:895] About to try and schedule pod kube-system/metrics-server-v0.3.1-677c578bdf-xl48c
I0416 21:03:48.690876       1 scheduler.go:454] Attempting to schedule pod: kube-system/metrics-server-v0.3.1-677c578bdf-xl48c
I0416 21:03:48.690970       1 factory.go:645] Unable to schedule kube-system/metrics-server-v0.3.1-677c578bdf-xl48c: no nodes are registered to the cluster; waiting
I0416 21:03:48.691031       1 factory.go:743] Updating pod condition for kube-system/metrics-server-v0.3.1-677c578bdf-xl48c to (PodScheduled==False, Reason=Unschedulable)
E0416 21:03:48.691041       1 scheduler.go:482] error selecting node for pod: no nodes available to schedule pods
I0416 21:03:48.697436       1 scheduling_queue.go:895] About to try and schedule pod kube-system/l7-default-backend-8f479dd9-wbtkw
I0416 21:03:48.697460       1 scheduler.go:454] Attempting to schedule pod: kube-system/l7-default-backend-8f479dd9-wbtkw
I0416 21:03:48.697508       1 factory.go:645] Unable to schedule kube-system/l7-default-backend-8f479dd9-wbtkw: no nodes are registered to the cluster; waiting
I0416 21:03:48.697541       1 factory.go:743] Updating pod condition for kube-system/l7-default-backend-8f479dd9-wbtkw to (PodScheduled==False, Reason=Unschedulable)
E0416 21:03:48.697551       1 scheduler.go:482] error selecting node for pod: no nodes available to schedule pods
I0416 21:03:48.699885       1 backoff_utils.go:79] Backing off 2s
I0416 21:03:48.705388       1 backoff_utils.go:79] Backing off 4s
I0416 21:03:48.977697       1 scheduling_queue.go:895] About to try and schedule pod kube-system/fluentd-gcp-scaler-7db4984bf4-26sjq
I0416 21:03:48.977723       1 scheduler.go:454] Attempting to schedule pod: kube-system/fluentd-gcp-scaler-7db4984bf4-26sjq
I0416 21:03:48.977748       1 factory.go:645] Unable to schedule kube-system/fluentd-gcp-scaler-7db4984bf4-26sjq: no nodes are registered to the cluster; waiting
I0416 21:03:48.977785       1 factory.go:743] Updating pod condition for kube-system/fluentd-gcp-scaler-7db4984bf4-26sjq to (PodScheduled==False, Reason=Unschedulable)
E0416 21:03:49.000656       1 scheduler.go:482] error selecting node for pod: no nodes available to schedule pods
I0416 21:03:49.000922       1 scheduling_queue.go:895] About to try and schedule pod kube-system/fluentd-gcp-scaler-7db4984bf4-26sjq
I0416 21:03:49.000929       1 scheduler.go:454] Attempting to schedule pod: kube-system/fluentd-gcp-scaler-7db4984bf4-26sjq
I0416 21:03:49.000989       1 factory.go:645] Unable to schedule kube-system/fluentd-gcp-scaler-7db4984bf4-26sjq: no nodes are registered to the cluster; waiting
I0416 21:03:49.002074       1 factory.go:743] Updating pod condition for kube-system/fluentd-gcp-scaler-7db4984bf4-26sjq to (PodScheduled==False, Reason=Unschedulable)
E0416 21:03:49.002093       1 scheduler.go:482] error selecting node for pod: no nodes available to schedule pods
I0416 21:03:49.683214       1 scheduling_queue.go:895] About to try and schedule pod kube-system/heapster-v1.6.0-beta.1-5858bf5485-5td9x
I0416 21:03:49.683241       1 scheduler.go:454] Attempting to schedule pod: kube-system/heapster-v1.6.0-beta.1-5858bf5485-5td9x
I0416 21:03:49.683302       1 factory.go:645] Unable to schedule kube-system/heapster-v1.6.0-beta.1-5858bf5485-5td9x: no nodes are registered to the cluster; waiting
I0416 21:03:49.683378       1 factory.go:743] Updating pod condition for kube-system/heapster-v1.6.0-beta.1-5858bf5485-5td9x to (PodScheduled==False, Reason=Unschedulable)
E0416 21:03:49.683387       1 scheduler.go:482] error selecting node for pod: no nodes available to schedule pods
I0416 21:03:49.689140       1 backoff_utils.go:79] Backing off 4s
I0416 21:03:50.635022       1 scheduling_queue.go:895] About to try and schedule pod kube-system/kubernetes-dashboard-85bcf5dbf8-t5nl6
I0416 21:03:50.635049       1 scheduler.go:454] Attempting to schedule pod: kube-system/kubernetes-dashboard-85bcf5dbf8-t5nl6
I0416 21:03:50.635084       1 factory.go:645] Unable to schedule kube-system/kubernetes-dashboard-85bcf5dbf8-t5nl6: no nodes are registered to the cluster; waiting
I0416 21:03:50.636965       1 factory.go:743] Updating pod condition for kube-system/kubernetes-dashboard-85bcf5dbf8-t5nl6 to (PodScheduled==False, Reason=Unschedulable)
E0416 21:03:50.657614       1 scheduler.go:482] error selecting node for pod: no nodes available to schedule pods
I0416 21:03:50.657689       1 scheduling_queue.go:895] About to try and schedule pod kube-system/kubernetes-dashboard-85bcf5dbf8-t5nl6
I0416 21:03:50.657694       1 scheduler.go:454] Attempting to schedule pod: kube-system/kubernetes-dashboard-85bcf5dbf8-t5nl6
I0416 21:03:50.657750       1 factory.go:645] Unable to schedule kube-system/kubernetes-dashboard-85bcf5dbf8-t5nl6: no nodes are registered to the cluster; waiting
I0416 21:03:50.657777       1 factory.go:743] Updating pod condition for kube-system/kubernetes-dashboard-85bcf5dbf8-t5nl6 to (PodScheduled==False, Reason=Unschedulable)
E0416 21:03:50.657787       1 scheduler.go:482] error selecting node for pod: no nodes available to schedule pods
I0416 21:03:50.729609       1 scheduling_queue.go:895] About to try and schedule pod kube-system/kube-dns-autoscaler-97df449df-4ggmd
I0416 21:03:50.729623       1 scheduler.go:454] Attempting to schedule pod: kube-system/kube-dns-autoscaler-97df449df-4ggmd
I0416 21:03:50.729658       1 factory.go:645] Unable to schedule kube-system/kube-dns-autoscaler-97df449df-4ggmd: no nodes are registered to the cluster; waiting
I0416 21:03:50.729701       1 factory.go:743] Updating pod condition for kube-system/kube-dns-autoscaler-97df449df-4ggmd to (PodScheduled==False, Reason=Unschedulable)
E0416 21:03:50.761422       1 scheduler.go:482] error selecting node for pod: no nodes available to schedule pods
I0416 21:03:50.762454       1 scheduling_queue.go:895] About to try and schedule pod kube-system/kube-dns-autoscaler-97df449df-4ggmd
I0416 21:03:50.762473       1 scheduler.go:454] Attempting to schedule pod: kube-system/kube-dns-autoscaler-97df449df-4ggmd
I0416 21:03:50.762540       1 factory.go:645] Unable to schedule kube-system/kube-dns-autoscaler-97df449df-4ggmd: no nodes are registered to the cluster; waiting
I0416 21:03:50.762576       1 factory.go:743] Updating pod condition for kube-system/kube-dns-autoscaler-97df449df-4ggmd to (PodScheduled==False, Reason=Unschedulable)
E0416 21:03:50.762586       1 scheduler.go:482] error selecting node for pod: no nodes available to schedule pods
I0416 21:03:54.023947       1 scheduling_queue.go:895] About to try and schedule pod kube-system/coredns-5b969f4c88-zcdpb
I0416 21:03:54.023958       1 scheduler.go:454] Attempting to schedule pod: kube-system/coredns-5b969f4c88-zcdpb
I0416 21:03:54.024072       1 factory.go:648] Unable to schedule kube-system/coredns-5b969f4c88-zcdpb: no fit: 0/1 nodes are available: 1 node(s) were unschedulable.; waiting
I0416 21:03:54.024104       1 factory.go:743] Updating pod condition for kube-system/coredns-5b969f4c88-zcdpb to (PodScheduled==False, Reason=Unschedulable)
I0416 21:03:54.105139       1 generic_scheduler.go:308] Preemption will not help schedule pod kube-system/coredns-5b969f4c88-zcdpb on any node.
I0416 21:03:54.117775       1 scheduling_queue.go:895] About to try and schedule pod kube-system/fluentd-gcp-v3.2.0-vqwbk
I0416 21:03:54.117816       1 scheduler.go:454] Attempting to schedule pod: kube-system/fluentd-gcp-v3.2.0-vqwbk
I0416 21:03:54.123721       1 scheduler_binder.go:255] AssumePodVolumes for pod "kube-system/fluentd-gcp-v3.2.0-vqwbk", node "e2e-test-peterhornyack-master"
I0416 21:03:54.123741       1 scheduler_binder.go:265] AssumePodVolumes for pod "kube-system/fluentd-gcp-v3.2.0-vqwbk", node "e2e-test-peterhornyack-master": all PVCs bound and nothing to do
I0416 21:03:54.123844       1 factory.go:734] Attempting to bind fluentd-gcp-v3.2.0-vqwbk to e2e-test-peterhornyack-master
I0416 21:03:54.147585       1 scheduling_queue.go:895] About to try and schedule pod kube-system/metadata-proxy-v0.1-ll5kc
I0416 21:03:54.147604       1 scheduler.go:454] Attempting to schedule pod: kube-system/metadata-proxy-v0.1-ll5kc
I0416 21:03:54.147894       1 scheduler_binder.go:255] AssumePodVolumes for pod "kube-system/metadata-proxy-v0.1-ll5kc", node "e2e-test-peterhornyack-master"
I0416 21:03:54.147906       1 scheduler_binder.go:265] AssumePodVolumes for pod "kube-system/metadata-proxy-v0.1-ll5kc", node "e2e-test-peterhornyack-master": all PVCs bound and nothing to do
I0416 21:03:54.147947       1 factory.go:734] Attempting to bind metadata-proxy-v0.1-ll5kc to e2e-test-peterhornyack-master
I0416 21:03:54.183785       1 scheduler.go:575] pod kube-system/fluentd-gcp-v3.2.0-vqwbk is bound successfully on node e2e-test-peterhornyack-master, 1 nodes evaluated, 1 nodes were found feasible
I0416 21:03:54.192680       1 scheduling_queue.go:895] About to try and schedule pod kube-system/metrics-server-v0.3.1-677c578bdf-xl48c
I0416 21:03:54.192699       1 scheduler.go:454] Attempting to schedule pod: kube-system/metrics-server-v0.3.1-677c578bdf-xl48c
I0416 21:03:54.219844       1 factory.go:648] Unable to schedule kube-system/metrics-server-v0.3.1-677c578bdf-xl48c: no fit: 0/1 nodes are available: 1 node(s) were unschedulable.; waiting
I0416 21:03:54.219896       1 factory.go:743] Updating pod condition for kube-system/metrics-server-v0.3.1-677c578bdf-xl48c to (PodScheduled==False, Reason=Unschedulable)
I0416 21:03:54.230112       1 scheduler.go:575] pod kube-system/metadata-proxy-v0.1-ll5kc is bound successfully on node e2e-test-peterhornyack-master, 1 nodes evaluated, 1 nodes were found feasible
I0416 21:03:54.397772       1 generic_scheduler.go:308] Preemption will not help schedule pod kube-system/metrics-server-v0.3.1-677c578bdf-xl48c on any node.
I0416 21:03:54.397920       1 scheduling_queue.go:895] About to try and schedule pod kube-system/heapster-v1.6.0-beta.1-5858bf5485-5td9x
I0416 21:03:54.397927       1 scheduler.go:454] Attempting to schedule pod: kube-system/heapster-v1.6.0-beta.1-5858bf5485-5td9x
I0416 21:03:54.398026       1 factory.go:648] Unable to schedule kube-system/heapster-v1.6.0-beta.1-5858bf5485-5td9x: no fit: 0/1 nodes are available: 1 node(s) were unschedulable.; waiting
I0416 21:03:54.398052       1 factory.go:743] Updating pod condition for kube-system/heapster-v1.6.0-beta.1-5858bf5485-5td9x to (PodScheduled==False, Reason=Unschedulable)
I0416 21:03:54.424595       1 generic_scheduler.go:308] Preemption will not help schedule pod kube-system/heapster-v1.6.0-beta.1-5858bf5485-5td9x on any node.
I0416 21:03:54.426102       1 scheduling_queue.go:895] About to try and schedule pod kube-system/kubernetes-dashboard-85bcf5dbf8-t5nl6
I0416 21:03:54.426126       1 scheduler.go:454] Attempting to schedule pod: kube-system/kubernetes-dashboard-85bcf5dbf8-t5nl6
I0416 21:03:54.426283       1 factory.go:648] Unable to schedule kube-system/kubernetes-dashboard-85bcf5dbf8-t5nl6: no fit: 0/1 nodes are available: 1 node(s) were unschedulable.; waiting
I0416 21:03:54.426318       1 factory.go:743] Updating pod condition for kube-system/kubernetes-dashboard-85bcf5dbf8-t5nl6 to (PodScheduled==False, Reason=Unschedulable)
I0416 21:03:54.459840       1 generic_scheduler.go:308] Preemption will not help schedule pod kube-system/kubernetes-dashboard-85bcf5dbf8-t5nl6 on any node.
I0416 21:03:54.459927       1 scheduling_queue.go:895] About to try and schedule pod kube-system/kube-dns-autoscaler-97df449df-4ggmd
I0416 21:03:54.459934       1 scheduler.go:454] Attempting to schedule pod: kube-system/kube-dns-autoscaler-97df449df-4ggmd
I0416 21:03:54.460161       1 factory.go:648] Unable to schedule kube-system/kube-dns-autoscaler-97df449df-4ggmd: no fit: 0/1 nodes are available: 1 node(s) were unschedulable.; waiting
I0416 21:03:54.460202       1 factory.go:743] Updating pod condition for kube-system/kube-dns-autoscaler-97df449df-4ggmd to (PodScheduled==False, Reason=Unschedulable)
I0416 21:03:54.474317       1 generic_scheduler.go:308] Preemption will not help schedule pod kube-system/kube-dns-autoscaler-97df449df-4ggmd on any node.
I0416 21:03:54.474732       1 scheduling_queue.go:895] About to try and schedule pod kube-system/coredns-5b969f4c88-zcdpb
I0416 21:03:54.474748       1 scheduler.go:454] Attempting to schedule pod: kube-system/coredns-5b969f4c88-zcdpb
I0416 21:03:54.474886       1 factory.go:648] Unable to schedule kube-system/coredns-5b969f4c88-zcdpb: no fit: 0/1 nodes are available: 1 node(s) were unschedulable.; waiting
I0416 21:03:54.474913       1 factory.go:743] Updating pod condition for kube-system/coredns-5b969f4c88-zcdpb to (PodScheduled==False, Reason=Unschedulable)
I0416 21:03:54.478812       1 generic_scheduler.go:308] Preemption will not help schedule pod kube-system/coredns-5b969f4c88-zcdpb on any node.
I0416 21:03:54.478876       1 scheduling_queue.go:895] About to try and schedule pod kube-system/metrics-server-v0.3.1-677c578bdf-xl48c
I0416 21:03:54.478884       1 scheduler.go:454] Attempting to schedule pod: kube-system/metrics-server-v0.3.1-677c578bdf-xl48c
I0416 21:03:54.478973       1 factory.go:648] Unable to schedule kube-system/metrics-server-v0.3.1-677c578bdf-xl48c: no fit: 0/1 nodes are available: 1 node(s) were unschedulable.; waiting
I0416 21:03:54.478994       1 factory.go:743] Updating pod condition for kube-system/metrics-server-v0.3.1-677c578bdf-xl48c to (PodScheduled==False, Reason=Unschedulable)
I0416 21:03:54.487592       1 generic_scheduler.go:308] Preemption will not help schedule pod kube-system/metrics-server-v0.3.1-677c578bdf-xl48c on any node.
I0416 21:03:54.487812       1 backoff_utils.go:79] Backing off 8s
I0416 21:03:54.488831       1 backoff_utils.go:79] Backing off 4s
I0416 21:03:54.488862       1 scheduling_queue.go:895] About to try and schedule pod kube-system/heapster-v1.6.0-beta.1-5858bf5485-5td9x
I0416 21:03:54.488870       1 scheduler.go:454] Attempting to schedule pod: kube-system/heapster-v1.6.0-beta.1-5858bf5485-5td9x
I0416 21:03:54.489346       1 factory.go:648] Unable to schedule kube-system/heapster-v1.6.0-beta.1-5858bf5485-5td9x: no fit: 0/1 nodes are available: 1 node(s) were unschedulable.; waiting
I0416 21:03:54.489374       1 factory.go:743] Updating pod condition for kube-system/heapster-v1.6.0-beta.1-5858bf5485-5td9x to (PodScheduled==False, Reason=Unschedulable)
I0416 21:03:54.493347       1 generic_scheduler.go:308] Preemption will not help schedule pod kube-system/heapster-v1.6.0-beta.1-5858bf5485-5td9x on any node.
I0416 21:03:54.497048       1 backoff_utils.go:79] Backing off 8s
I0416 21:03:54.497093       1 scheduling_queue.go:895] About to try and schedule pod kube-system/kubernetes-dashboard-85bcf5dbf8-t5nl6
I0416 21:03:54.497118       1 scheduler.go:454] Attempting to schedule pod: kube-system/kubernetes-dashboard-85bcf5dbf8-t5nl6
I0416 21:03:54.497208       1 factory.go:648] Unable to schedule kube-system/kubernetes-dashboard-85bcf5dbf8-t5nl6: no fit: 0/1 nodes are available: 1 node(s) were unschedulable.; waiting
I0416 21:03:54.497247       1 factory.go:743] Updating pod condition for kube-system/kubernetes-dashboard-85bcf5dbf8-t5nl6 to (PodScheduled==False, Reason=Unschedulable)
I0416 21:03:54.501609       1 generic_scheduler.go:308] Preemption will not help schedule pod kube-system/kubernetes-dashboard-85bcf5dbf8-t5nl6 on any node.
I0416 21:03:54.501673       1 scheduling_queue.go:895] About to try and schedule pod kube-system/kube-dns-autoscaler-97df449df-4ggmd
I0416 21:03:54.501679       1 scheduler.go:454] Attempting to schedule pod: kube-system/kube-dns-autoscaler-97df449df-4ggmd
I0416 21:03:54.501757       1 factory.go:648] Unable to schedule kube-system/kube-dns-autoscaler-97df449df-4ggmd: no fit: 0/1 nodes are available: 1 node(s) were unschedulable.; waiting
I0416 21:03:54.501780       1 factory.go:743] Updating pod condition for kube-system/kube-dns-autoscaler-97df449df-4ggmd to (PodScheduled==False, Reason=Unschedulable)
I0416 21:03:54.508191       1 backoff_utils.go:79] Backing off 2s
I0416 21:03:54.514685       1 generic_scheduler.go:308] Preemption will not help schedule pod kube-system/kube-dns-autoscaler-97df449df-4ggmd on any node.
I0416 21:03:54.518817       1 backoff_utils.go:79] Backing off 2s
I0416 21:03:54.518877       1 scheduling_queue.go:895] About to try and schedule pod kube-system/event-exporter-v0.2.4-65d8d98768-n6vvr
I0416 21:03:54.518884       1 scheduler.go:454] Attempting to schedule pod: kube-system/event-exporter-v0.2.4-65d8d98768-n6vvr
I0416 21:03:54.518991       1 factory.go:648] Unable to schedule kube-system/event-exporter-v0.2.4-65d8d98768-n6vvr: no fit: 0/1 nodes are available: 1 node(s) were unschedulable.; waiting
I0416 21:03:54.519050       1 factory.go:743] Updating pod condition for kube-system/event-exporter-v0.2.4-65d8d98768-n6vvr to (PodScheduled==False, Reason=Unschedulable)
I0416 21:03:54.615159       1 generic_scheduler.go:308] Preemption will not help schedule pod kube-system/event-exporter-v0.2.4-65d8d98768-n6vvr on any node.
I0416 21:03:54.621335       1 scheduling_queue.go:895] About to try and schedule pod kube-system/l7-default-backend-8f479dd9-wbtkw
I0416 21:03:54.621354       1 scheduler.go:454] Attempting to schedule pod: kube-system/l7-default-backend-8f479dd9-wbtkw
I0416 21:03:54.621458       1 factory.go:648] Unable to schedule kube-system/l7-default-backend-8f479dd9-wbtkw: no fit: 0/1 nodes are available: 1 node(s) were unschedulable.; waiting
I0416 21:03:54.621497       1 factory.go:743] Updating pod condition for kube-system/l7-default-backend-8f479dd9-wbtkw to (PodScheduled==False, Reason=Unschedulable)
I0416 21:03:54.738908       1 generic_scheduler.go:308] Preemption will not help schedule pod kube-system/l7-default-backend-8f479dd9-wbtkw on any node.
I0416 21:03:54.738978       1 scheduling_queue.go:895] About to try and schedule pod kube-system/fluentd-gcp-scaler-7db4984bf4-26sjq
I0416 21:03:54.738984       1 scheduler.go:454] Attempting to schedule pod: kube-system/fluentd-gcp-scaler-7db4984bf4-26sjq
I0416 21:03:54.739060       1 factory.go:648] Unable to schedule kube-system/fluentd-gcp-scaler-7db4984bf4-26sjq: no fit: 0/1 nodes are available: 1 node(s) were unschedulable.; waiting
I0416 21:03:54.739085       1 factory.go:743] Updating pod condition for kube-system/fluentd-gcp-scaler-7db4984bf4-26sjq to (PodScheduled==False, Reason=Unschedulable)
I0416 21:03:54.831613       1 generic_scheduler.go:308] Preemption will not help schedule pod kube-system/fluentd-gcp-scaler-7db4984bf4-26sjq on any node.
I0416 21:03:54.832260       1 scheduling_queue.go:895] About to try and schedule pod kube-system/event-exporter-v0.2.4-65d8d98768-n6vvr
I0416 21:03:54.832270       1 scheduler.go:454] Attempting to schedule pod: kube-system/event-exporter-v0.2.4-65d8d98768-n6vvr
I0416 21:03:54.832373       1 factory.go:648] Unable to schedule kube-system/event-exporter-v0.2.4-65d8d98768-n6vvr: no fit: 0/1 nodes are available: 1 node(s) were unschedulable.; waiting
I0416 21:03:54.832401       1 factory.go:743] Updating pod condition for kube-system/event-exporter-v0.2.4-65d8d98768-n6vvr to (PodScheduled==False, Reason=Unschedulable)
I0416 21:03:54.848630       1 generic_scheduler.go:308] Preemption will not help schedule pod kube-system/event-exporter-v0.2.4-65d8d98768-n6vvr on any node.
I0416 21:03:54.848761       1 backoff_utils.go:79] Backing off 4s
I0416 21:03:54.854776       1 scheduling_queue.go:895] About to try and schedule pod kube-system/l7-default-backend-8f479dd9-wbtkw
I0416 21:03:54.854792       1 scheduler.go:454] Attempting to schedule pod: kube-system/l7-default-backend-8f479dd9-wbtkw
I0416 21:03:54.854899       1 factory.go:648] Unable to schedule kube-system/l7-default-backend-8f479dd9-wbtkw: no fit: 0/1 nodes are available: 1 node(s) were unschedulable.; waiting
I0416 21:03:54.854939       1 factory.go:743] Updating pod condition for kube-system/l7-default-backend-8f479dd9-wbtkw to (PodScheduled==False, Reason=Unschedulable)
I0416 21:03:54.877086       1 backoff_utils.go:79] Backing off 8s
I0416 21:03:54.885041       1 generic_scheduler.go:308] Preemption will not help schedule pod kube-system/l7-default-backend-8f479dd9-wbtkw on any node.
I0416 21:03:54.885115       1 scheduling_queue.go:895] About to try and schedule pod kube-system/fluentd-gcp-scaler-7db4984bf4-26sjq
I0416 21:03:54.885121       1 scheduler.go:454] Attempting to schedule pod: kube-system/fluentd-gcp-scaler-7db4984bf4-26sjq
I0416 21:03:54.885197       1 factory.go:648] Unable to schedule kube-system/fluentd-gcp-scaler-7db4984bf4-26sjq: no fit: 0/1 nodes are available: 1 node(s) were unschedulable.; waiting
I0416 21:03:54.885224       1 factory.go:743] Updating pod condition for kube-system/fluentd-gcp-scaler-7db4984bf4-26sjq to (PodScheduled==False, Reason=Unschedulable)
I0416 21:03:54.945865       1 backoff_utils.go:79] Backing off 2s
I0416 21:03:54.945978       1 generic_scheduler.go:308] Preemption will not help schedule pod kube-system/fluentd-gcp-scaler-7db4984bf4-26sjq on any node.
I0416 21:03:56.470574       1 wrap.go:47] GET /healthz: (76.777µs) 200 [kube-probe/1.15+ 127.0.0.1:53336]
I0416 21:03:56.702727       1 scheduling_queue.go:895] About to try and schedule pod kube-system/kube-dns-autoscaler-97df449df-4ggmd
I0416 21:03:56.702744       1 scheduler.go:454] Attempting to schedule pod: kube-system/kube-dns-autoscaler-97df449df-4ggmd
I0416 21:03:56.702854       1 factory.go:648] Unable to schedule kube-system/kube-dns-autoscaler-97df449df-4ggmd: no fit: 0/1 nodes are available: 1 node(s) were unschedulable.; waiting
I0416 21:03:56.702890       1 factory.go:743] Updating pod condition for kube-system/kube-dns-autoscaler-97df449df-4ggmd to (PodScheduled==False, Reason=Unschedulable)
I0416 21:03:56.718562       1 generic_scheduler.go:308] Preemption will not help schedule pod kube-system/kube-dns-autoscaler-97df449df-4ggmd on any node.
I0416 21:03:56.718671       1 scheduling_queue.go:895] About to try and schedule pod kube-system/kubernetes-dashboard-85bcf5dbf8-t5nl6
I0416 21:03:56.718678       1 scheduler.go:454] Attempting to schedule pod: kube-system/kubernetes-dashboard-85bcf5dbf8-t5nl6
I0416 21:03:56.718760       1 factory.go:648] Unable to schedule kube-system/kubernetes-dashboard-85bcf5dbf8-t5nl6: no fit: 0/1 nodes are available: 1 node(s) were unschedulable.; waiting
I0416 21:03:56.718790       1 factory.go:743] Updating pod condition for kube-system/kubernetes-dashboard-85bcf5dbf8-t5nl6 to (PodScheduled==False, Reason=Unschedulable)
I0416 21:03:56.731935       1 backoff_utils.go:79] Backing off 4s
I0416 21:03:56.739039       1 backoff_utils.go:79] Backing off 4s
I0416 21:03:56.739146       1 generic_scheduler.go:308] Preemption will not help schedule pod kube-system/kubernetes-dashboard-85bcf5dbf8-t5nl6 on any node.
I0416 21:03:57.702865       1 scheduling_queue.go:895] About to try and schedule pod kube-system/fluentd-gcp-scaler-7db4984bf4-26sjq
I0416 21:03:58.984366       1 scheduler.go:454] Attempting to schedule pod: kube-system/fluentd-gcp-scaler-7db4984bf4-26sjq
I0416 21:03:58.984511       1 factory.go:648] Unable to schedule kube-system/fluentd-gcp-scaler-7db4984bf4-26sjq: no fit: 0/1 nodes are available: 1 node(s) were unschedulable.; waiting
I0416 21:03:58.984555       1 factory.go:743] Updating pod condition for kube-system/fluentd-gcp-scaler-7db4984bf4-26sjq to (PodScheduled==False, Reason=Unschedulable)
I0416 21:03:59.004168       1 generic_scheduler.go:308] Preemption will not help schedule pod kube-system/fluentd-gcp-scaler-7db4984bf4-26sjq on any node.
I0416 21:03:59.004292       1 backoff_utils.go:79] Backing off 4s
I0416 21:03:59.078144       1 scheduling_queue.go:895] About to try and schedule pod kube-system/metrics-server-v0.3.1-677c578bdf-xl48c
I0416 21:03:59.078159       1 scheduler.go:454] Attempting to schedule pod: kube-system/metrics-server-v0.3.1-677c578bdf-xl48c
I0416 21:03:59.078310       1 factory.go:648] Unable to schedule kube-system/metrics-server-v0.3.1-677c578bdf-xl48c: no fit: 0/1 nodes are available: 1 node(s) were unschedulable.; waiting
I0416 21:03:59.078368       1 factory.go:743] Updating pod condition for kube-system/metrics-server-v0.3.1-677c578bdf-xl48c to (PodScheduled==False, Reason=Unschedulable)
I0416 21:03:59.093564       1 generic_scheduler.go:308] Preemption will not help schedule pod kube-system/metrics-server-v0.3.1-677c578bdf-xl48c on any node.
I0416 21:03:59.125424       1 backoff_utils.go:79] Backing off 8s
I0416 21:03:59.703249       1 scheduling_queue.go:895] About to try and schedule pod kube-system/event-exporter-v0.2.4-65d8d98768-n6vvr
I0416 21:03:59.703263       1 scheduler.go:454] Attempting to schedule pod: kube-system/event-exporter-v0.2.4-65d8d98768-n6vvr
I0416 21:03:59.703375       1 factory.go:648] Unable to schedule kube-system/event-exporter-v0.2.4-65d8d98768-n6vvr: no fit: 0/1 nodes are available: 1 node(s) were unschedulable.; waiting
I0416 21:03:59.703432       1 factory.go:743] Updating pod condition for kube-system/event-exporter-v0.2.4-65d8d98768-n6vvr to (PodScheduled==False, Reason=Unschedulable)
I0416 21:03:59.718804       1 generic_scheduler.go:308] Preemption will not help schedule pod kube-system/event-exporter-v0.2.4-65d8d98768-n6vvr on any node.
I0416 21:03:59.726169       1 backoff_utils.go:79] Backing off 8s
I0416 21:04:02.704332       1 scheduling_queue.go:895] About to try and schedule pod kube-system/coredns-5b969f4c88-zcdpb
I0416 21:04:02.704346       1 scheduler.go:454] Attempting to schedule pod: kube-system/coredns-5b969f4c88-zcdpb
I0416 21:04:02.704461       1 factory.go:648] Unable to schedule kube-system/coredns-5b969f4c88-zcdpb: no fit: 0/1 nodes are available: 1 node(s) were unschedulable.; waiting
I0416 21:04:02.704499       1 factory.go:743] Updating pod condition for kube-system/coredns-5b969f4c88-zcdpb to (PodScheduled==False, Reason=Unschedulable)
I0416 21:04:02.716209       1 generic_scheduler.go:308] Preemption will not help schedule pod kube-system/coredns-5b969f4c88-zcdpb on any node.
I0416 21:04:02.721337       1 backoff_utils.go:79] Backing off 10s
I0416 21:04:02.721409       1 scheduling_queue.go:895] About to try and schedule pod kube-system/heapster-v1.6.0-beta.1-5858bf5485-5td9x
I0416 21:04:02.721416       1 scheduler.go:454] Attempting to schedule pod: kube-system/heapster-v1.6.0-beta.1-5858bf5485-5td9x
I0416 21:04:02.721536       1 factory.go:648] Unable to schedule kube-system/heapster-v1.6.0-beta.1-5858bf5485-5td9x: no fit: 0/1 nodes are available: 1 node(s) were unschedulable.; waiting
I0416 21:04:02.721585       1 factory.go:743] Updating pod condition for kube-system/heapster-v1.6.0-beta.1-5858bf5485-5td9x to (PodScheduled==False, Reason=Unschedulable)
I0416 21:04:02.728049       1 generic_scheduler.go:308] Preemption will not help schedule pod kube-system/heapster-v1.6.0-beta.1-5858bf5485-5td9x on any node.
I0416 21:04:02.738552       1 backoff_utils.go:79] Backing off 10s
I0416 21:04:03.704802       1 scheduling_queue.go:895] About to try and schedule pod kube-system/l7-default-backend-8f479dd9-wbtkw
I0416 21:04:04.249715       1 scheduler.go:454] Attempting to schedule pod: kube-system/l7-default-backend-8f479dd9-wbtkw
I0416 21:04:04.249877       1 factory.go:648] Unable to schedule kube-system/l7-default-backend-8f479dd9-wbtkw: no fit: 0/1 nodes are available: 1 node(s) were unschedulable.; waiting
I0416 21:04:04.249930       1 factory.go:743] Updating pod condition for kube-system/l7-default-backend-8f479dd9-wbtkw to (PodScheduled==False, Reason=Unschedulable)
I0416 21:04:04.268722       1 generic_scheduler.go:308] Preemption will not help schedule pod kube-system/l7-default-backend-8f479dd9-wbtkw on any node.
I0416 21:04:04.272439       1 backoff_utils.go:79] Backing off 10s
I0416 21:04:06.470595       1 wrap.go:47] GET /healthz: (74.156µs) 200 [kube-probe/1.15+ 127.0.0.1:53386]
I0416 21:04:16.468474       1 wrap.go:47] GET /healthz: (84.167µs) 200 [kube-probe/1.15+ 127.0.0.1:53508]
I0416 21:04:26.468624       1 wrap.go:47] GET /healthz: (100.791µs) 200 [kube-probe/1.15+ 127.0.0.1:53542]
I0416 21:04:36.468672       1 wrap.go:47] GET /healthz: (95.301µs) 200 [kube-probe/1.15+ 127.0.0.1:53574]
I0416 21:04:46.468803       1 wrap.go:47] GET /healthz: (72.34µs) 200 [kube-probe/1.15+ 127.0.0.1:53620]
I0416 21:04:56.468678       1 wrap.go:47] GET /healthz: (71.914µs) 200 [kube-probe/1.15+ 127.0.0.1:53656]
I0416 21:05:05.644844       1 scheduling_queue.go:895] About to try and schedule pod kube-system/kube-dns-autoscaler-97df449df-4ggmd
I0416 21:05:05.644861       1 scheduler.go:454] Attempting to schedule pod: kube-system/kube-dns-autoscaler-97df449df-4ggmd
I0416 21:05:05.645012       1 factory.go:648] Unable to schedule kube-system/kube-dns-autoscaler-97df449df-4ggmd: no fit: 0/1 nodes are available: 1 node(s) were unschedulable.; waiting
I0416 21:05:05.645058       1 factory.go:743] Updating pod condition for kube-system/kube-dns-autoscaler-97df449df-4ggmd to (PodScheduled==False, Reason=Unschedulable)
I0416 21:05:05.653612       1 generic_scheduler.go:308] Preemption will not help schedule pod kube-system/kube-dns-autoscaler-97df449df-4ggmd on any node.
I0416 21:05:05.653874       1 scheduling_queue.go:895] About to try and schedule pod kube-system/kubernetes-dashboard-85bcf5dbf8-t5nl6
I0416 21:05:05.653881       1 scheduler.go:454] Attempting to schedule pod: kube-system/kubernetes-dashboard-85bcf5dbf8-t5nl6
I0416 21:05:05.653974       1 factory.go:648] Unable to schedule kube-system/kubernetes-dashboard-85bcf5dbf8-t5nl6: no fit: 0/1 nodes are available: 1 node(s) were unschedulable.; waiting
I0416 21:05:05.654004       1 factory.go:743] Updating pod condition for kube-system/kubernetes-dashboard-85bcf5dbf8-t5nl6 to (PodScheduled==False, Reason=Unschedulable)
I0416 21:05:05.663414       1 generic_scheduler.go:308] Preemption will not help schedule pod kube-system/kubernetes-dashboard-85bcf5dbf8-t5nl6 on any node.
I0416 21:05:05.665579       1 scheduling_queue.go:895] About to try and schedule pod kube-system/metrics-server-v0.3.1-677c578bdf-xl48c
I0416 21:05:05.665591       1 scheduler.go:454] Attempting to schedule pod: kube-system/metrics-server-v0.3.1-677c578bdf-xl48c
I0416 21:05:05.665686       1 factory.go:648] Unable to schedule kube-system/metrics-server-v0.3.1-677c578bdf-xl48c: no fit: 0/1 nodes are available: 1 node(s) were unschedulable.; waiting
I0416 21:05:05.665715       1 factory.go:743] Updating pod condition for kube-system/metrics-server-v0.3.1-677c578bdf-xl48c to (PodScheduled==False, Reason=Unschedulable)
I0416 21:05:05.675656       1 generic_scheduler.go:308] Preemption will not help schedule pod kube-system/metrics-server-v0.3.1-677c578bdf-xl48c on any node.
I0416 21:05:05.676911       1 scheduling_queue.go:895] About to try and schedule pod kube-system/coredns-5b969f4c88-zcdpb
I0416 21:05:05.676921       1 scheduler.go:454] Attempting to schedule pod: kube-system/coredns-5b969f4c88-zcdpb
I0416 21:05:05.676997       1 factory.go:648] Unable to schedule kube-system/coredns-5b969f4c88-zcdpb: no fit: 0/1 nodes are available: 1 node(s) were unschedulable.; waiting
I0416 21:05:05.677021       1 factory.go:743] Updating pod condition for kube-system/coredns-5b969f4c88-zcdpb to (PodScheduled==False, Reason=Unschedulable)
I0416 21:05:05.684548       1 generic_scheduler.go:308] Preemption will not help schedule pod kube-system/coredns-5b969f4c88-zcdpb on any node.
I0416 21:05:05.685192       1 scheduling_queue.go:895] About to try and schedule pod kube-system/heapster-v1.6.0-beta.1-5858bf5485-5td9x
I0416 21:05:05.685201       1 scheduler.go:454] Attempting to schedule pod: kube-system/heapster-v1.6.0-beta.1-5858bf5485-5td9x
I0416 21:05:05.686796       1 factory.go:648] Unable to schedule kube-system/heapster-v1.6.0-beta.1-5858bf5485-5td9x: no fit: 0/1 nodes are available: 1 node(s) were unschedulable.; waiting
I0416 21:05:05.686830       1 factory.go:743] Updating pod condition for kube-system/heapster-v1.6.0-beta.1-5858bf5485-5td9x to (PodScheduled==False, Reason=Unschedulable)
I0416 21:05:05.695188       1 generic_scheduler.go:308] Preemption will not help schedule pod kube-system/heapster-v1.6.0-beta.1-5858bf5485-5td9x on any node.
I0416 21:05:05.698268       1 scheduling_queue.go:895] About to try and schedule pod kube-system/fluentd-gcp-scaler-7db4984bf4-26sjq
I0416 21:05:05.698277       1 scheduler.go:454] Attempting to schedule pod: kube-system/fluentd-gcp-scaler-7db4984bf4-26sjq
I0416 21:05:05.698379       1 factory.go:648] Unable to schedule kube-system/fluentd-gcp-scaler-7db4984bf4-26sjq: no fit: 0/1 nodes are available: 1 node(s) were unschedulable.; waiting
I0416 21:05:05.698428       1 factory.go:743] Updating pod condition for kube-system/fluentd-gcp-scaler-7db4984bf4-26sjq to (PodScheduled==False, Reason=Unschedulable)
I0416 21:05:05.706721       1 generic_scheduler.go:308] Preemption will not help schedule pod kube-system/fluentd-gcp-scaler-7db4984bf4-26sjq on any node.
I0416 21:05:05.709814       1 scheduling_queue.go:895] About to try and schedule pod kube-system/event-exporter-v0.2.4-65d8d98768-n6vvr
I0416 21:05:05.709825       1 scheduler.go:454] Attempting to schedule pod: kube-system/event-exporter-v0.2.4-65d8d98768-n6vvr
I0416 21:05:05.709933       1 factory.go:648] Unable to schedule kube-system/event-exporter-v0.2.4-65d8d98768-n6vvr: no fit: 0/1 nodes are available: 1 node(s) were unschedulable.; waiting
I0416 21:05:05.709964       1 factory.go:743] Updating pod condition for kube-system/event-exporter-v0.2.4-65d8d98768-n6vvr to (PodScheduled==False, Reason=Unschedulable)
I0416 21:05:05.714679       1 generic_scheduler.go:308] Preemption will not help schedule pod kube-system/event-exporter-v0.2.4-65d8d98768-n6vvr on any node.
I0416 21:05:05.715012       1 scheduling_queue.go:895] About to try and schedule pod kube-system/l7-default-backend-8f479dd9-wbtkw
I0416 21:05:05.715022       1 scheduler.go:454] Attempting to schedule pod: kube-system/l7-default-backend-8f479dd9-wbtkw
I0416 21:05:05.715128       1 factory.go:648] Unable to schedule kube-system/l7-default-backend-8f479dd9-wbtkw: no fit: 0/1 nodes are available: 1 node(s) were unschedulable.; waiting
I0416 21:05:05.715155       1 factory.go:743] Updating pod condition for kube-system/l7-default-backend-8f479dd9-wbtkw to (PodScheduled==False, Reason=Unschedulable)
I0416 21:05:05.721489       1 generic_scheduler.go:308] Preemption will not help schedule pod kube-system/l7-default-backend-8f479dd9-wbtkw on any node.
I0416 21:05:06.469477       1 wrap.go:47] GET /healthz: (83.278µs) 200 [kube-probe/1.15+ 127.0.0.1:53690]
I0416 21:05:16.468785       1 wrap.go:47] GET /healthz: (63.062µs) 200 [kube-probe/1.15+ 127.0.0.1:53738]
I0416 21:05:26.468806       1 wrap.go:47] GET /healthz: (74.873µs) 200 [kube-probe/1.15+ 127.0.0.1:53770]
I0416 21:05:36.468913       1 wrap.go:47] GET /healthz: (149.644µs) 200 [kube-probe/1.15+ 127.0.0.1:53804]
I0416 21:05:46.469131       1 wrap.go:47] GET /healthz: (77.116µs) 200 [kube-probe/1.15+ 127.0.0.1:53852]
I0416 21:05:56.468747       1 wrap.go:47] GET /healthz: (74.526µs) 200 [kube-probe/1.15+ 127.0.0.1:53888]
I0416 21:06:06.468933       1 wrap.go:47] GET /healthz: (146.346µs) 200 [kube-probe/1.15+ 127.0.0.1:53922]
I0416 21:06:16.469617       1 wrap.go:47] GET /healthz: (97.136µs) 200 [kube-probe/1.15+ 127.0.0.1:53960]
I0416 21:06:26.468918       1 wrap.go:47] GET /healthz: (84.036µs) 200 [kube-probe/1.15+ 127.0.0.1:53992]
I0416 21:06:35.645571       1 scheduling_queue.go:895] About to try and schedule pod kube-system/kube-dns-autoscaler-97df449df-4ggmd
I0416 21:06:35.645585       1 scheduler.go:454] Attempting to schedule pod: kube-system/kube-dns-autoscaler-97df449df-4ggmd
I0416 21:06:35.645722       1 factory.go:648] Unable to schedule kube-system/kube-dns-autoscaler-97df449df-4ggmd: no fit: 0/1 nodes are available: 1 node(s) were unschedulable.; waiting
I0416 21:06:35.645760       1 factory.go:743] Updating pod condition for kube-system/kube-dns-autoscaler-97df449df-4ggmd to (PodScheduled==False, Reason=Unschedulable)
I0416 21:06:35.653297       1 generic_scheduler.go:308] Preemption will not help schedule pod kube-system/kube-dns-autoscaler-97df449df-4ggmd on any node.
I0416 21:06:35.655079       1 scheduling_queue.go:895] About to try and schedule pod kube-system/kubernetes-dashboard-85bcf5dbf8-t5nl6
I0416 21:06:35.655094       1 scheduler.go:454] Attempting to schedule pod: kube-system/kubernetes-dashboard-85bcf5dbf8-t5nl6
I0416 21:06:35.655199       1 factory.go:648] Unable to schedule kube-system/kubernetes-dashboard-85bcf5dbf8-t5nl6: no fit: 0/1 nodes are available: 1 node(s) were unschedulable.; waiting
I0416 21:06:35.655251       1 factory.go:743] Updating pod condition for kube-system/kubernetes-dashboard-85bcf5dbf8-t5nl6 to (PodScheduled==False, Reason=Unschedulable)
I0416 21:06:35.660596       1 generic_scheduler.go:308] Preemption will not help schedule pod kube-system/kubernetes-dashboard-85bcf5dbf8-t5nl6 on any node.
I0416 21:06:35.663644       1 scheduling_queue.go:895] About to try and schedule pod kube-system/metrics-server-v0.3.1-677c578bdf-xl48c
I0416 21:06:35.663655       1 scheduler.go:454] Attempting to schedule pod: kube-system/metrics-server-v0.3.1-677c578bdf-xl48c
I0416 21:06:35.663748       1 factory.go:648] Unable to schedule kube-system/metrics-server-v0.3.1-677c578bdf-xl48c: no fit: 0/1 nodes are available: 1 node(s) were unschedulable.; waiting
I0416 21:06:35.663775       1 factory.go:743] Updating pod condition for kube-system/metrics-server-v0.3.1-677c578bdf-xl48c to (PodScheduled==False, Reason=Unschedulable)
I0416 21:06:35.667926       1 generic_scheduler.go:308] Preemption will not help schedule pod kube-system/metrics-server-v0.3.1-677c578bdf-xl48c on any node.
I0416 21:06:35.668000       1 scheduling_queue.go:895] About to try and schedule pod kube-system/coredns-5b969f4c88-zcdpb
I0416 21:06:35.668008       1 scheduler.go:454] Attempting to schedule pod: kube-system/coredns-5b969f4c88-zcdpb
I0416 21:06:35.668105       1 factory.go:648] Unable to schedule kube-system/coredns-5b969f4c88-zcdpb: no fit: 0/1 nodes are available: 1 node(s) were unschedulable.; waiting
I0416 21:06:35.668128       1 factory.go:743] Updating pod condition for kube-system/coredns-5b969f4c88-zcdpb to (PodScheduled==False, Reason=Unschedulable)
I0416 21:06:35.675949       1 generic_scheduler.go:308] Preemption will not help schedule pod kube-system/coredns-5b969f4c88-zcdpb on any node.
I0416 21:06:35.679295       1 scheduling_queue.go:895] About to try and schedule pod kube-system/heapster-v1.6.0-beta.1-5858bf5485-5td9x
I0416 21:06:35.679305       1 scheduler.go:454] Attempting to schedule pod: kube-system/heapster-v1.6.0-beta.1-5858bf5485-5td9x
I0416 21:06:35.679421       1 factory.go:648] Unable to schedule kube-system/heapster-v1.6.0-beta.1-5858bf5485-5td9x: no fit: 0/1 nodes are available: 1 node(s) were unschedulable.; waiting
I0416 21:06:35.679455       1 factory.go:743] Updating pod condition for kube-system/heapster-v1.6.0-beta.1-5858bf5485-5td9x to (PodScheduled==False, Reason=Unschedulable)
I0416 21:06:35.689014       1 generic_scheduler.go:308] Preemption will not help schedule pod kube-system/heapster-v1.6.0-beta.1-5858bf5485-5td9x on any node.
I0416 21:06:35.689086       1 scheduling_queue.go:895] About to try and schedule pod kube-system/fluentd-gcp-scaler-7db4984bf4-26sjq
I0416 21:06:35.689093       1 scheduler.go:454] Attempting to schedule pod: kube-system/fluentd-gcp-scaler-7db4984bf4-26sjq
I0416 21:06:35.689161       1 factory.go:648] Unable to schedule kube-system/fluentd-gcp-scaler-7db4984bf4-26sjq: no fit: 0/1 nodes are available: 1 node(s) were unschedulable.; waiting
I0416 21:06:35.689186       1 factory.go:743] Updating pod condition for kube-system/fluentd-gcp-scaler-7db4984bf4-26sjq to (PodScheduled==False, Reason=Unschedulable)
I0416 21:06:35.703840       1 generic_scheduler.go:308] Preemption will not help schedule pod kube-system/fluentd-gcp-scaler-7db4984bf4-26sjq on any node.
I0416 21:06:35.708401       1 scheduling_queue.go:895] About to try and schedule pod kube-system/event-exporter-v0.2.4-65d8d98768-n6vvr
I0416 21:06:35.708414       1 scheduler.go:454] Attempting to schedule pod: kube-system/event-exporter-v0.2.4-65d8d98768-n6vvr
I0416 21:06:35.708486       1 factory.go:648] Unable to schedule kube-system/event-exporter-v0.2.4-65d8d98768-n6vvr: no fit: 0/1 nodes are available: 1 node(s) were unschedulable.; waiting
I0416 21:06:35.708512       1 factory.go:743] Updating pod condition for kube-system/event-exporter-v0.2.4-65d8d98768-n6vvr to (PodScheduled==False, Reason=Unschedulable)
I0416 21:06:35.715324       1 generic_scheduler.go:308] Preemption will not help schedule pod kube-system/event-exporter-v0.2.4-65d8d98768-n6vvr on any node.
I0416 21:06:35.718633       1 scheduling_queue.go:895] About to try and schedule pod kube-system/l7-default-backend-8f479dd9-wbtkw
I0416 21:06:35.718651       1 scheduler.go:454] Attempting to schedule pod: kube-system/l7-default-backend-8f479dd9-wbtkw
I0416 21:06:35.718734       1 factory.go:648] Unable to schedule kube-system/l7-default-backend-8f479dd9-wbtkw: no fit: 0/1 nodes are available: 1 node(s) were unschedulable.; waiting
I0416 21:06:35.718759       1 factory.go:743] Updating pod condition for kube-system/l7-default-backend-8f479dd9-wbtkw to (PodScheduled==False, Reason=Unschedulable)
I0416 21:06:35.723093       1 generic_scheduler.go:308] Preemption will not help schedule pod kube-system/l7-default-backend-8f479dd9-wbtkw on any node.
I0416 21:06:36.468980       1 wrap.go:47] GET /healthz: (84.287µs) 200 [kube-probe/1.15+ 127.0.0.1:54026]
I0416 21:06:46.469884       1 wrap.go:47] GET /healthz: (67.322µs) 200 [kube-probe/1.15+ 127.0.0.1:54074]
I0416 21:06:52.679724       1 scheduling_queue.go:895] About to try and schedule pod kube-system/kube-dns-autoscaler-97df449df-4ggmd
I0416 21:06:52.679748       1 scheduler.go:454] Attempting to schedule pod: kube-system/kube-dns-autoscaler-97df449df-4ggmd
I0416 21:06:52.679961       1 scheduler_binder.go:255] AssumePodVolumes for pod "kube-system/kube-dns-autoscaler-97df449df-4ggmd", node "e2e-test-peterhornyack-minion-group-06gd"
I0416 21:06:52.679972       1 scheduler_binder.go:265] AssumePodVolumes for pod "kube-system/kube-dns-autoscaler-97df449df-4ggmd", node "e2e-test-peterhornyack-minion-group-06gd": all PVCs bound and nothing to do
I0416 21:06:52.680037       1 factory.go:734] Attempting to bind kube-dns-autoscaler-97df449df-4ggmd to e2e-test-peterhornyack-minion-group-06gd
I0416 21:06:52.682538       1 scheduling_queue.go:895] About to try and schedule pod kube-system/kubernetes-dashboard-85bcf5dbf8-t5nl6
I0416 21:06:52.682552       1 scheduler.go:454] Attempting to schedule pod: kube-system/kubernetes-dashboard-85bcf5dbf8-t5nl6
I0416 21:06:52.682685       1 scheduler_binder.go:255] AssumePodVolumes for pod "kube-system/kubernetes-dashboard-85bcf5dbf8-t5nl6", node "e2e-test-peterhornyack-minion-group-06gd"
I0416 21:06:52.682695       1 scheduler_binder.go:265] AssumePodVolumes for pod "kube-system/kubernetes-dashboard-85bcf5dbf8-t5nl6", node "e2e-test-peterhornyack-minion-group-06gd": all PVCs bound and nothing to do
I0416 21:06:52.682726       1 factory.go:734] Attempting to bind kubernetes-dashboard-85bcf5dbf8-t5nl6 to e2e-test-peterhornyack-minion-group-06gd
I0416 21:06:52.691184       1 scheduling_queue.go:895] About to try and schedule pod kube-system/metrics-server-v0.3.1-677c578bdf-xl48c
I0416 21:06:52.691203       1 scheduler.go:454] Attempting to schedule pod: kube-system/metrics-server-v0.3.1-677c578bdf-xl48c
I0416 21:06:52.691424       1 scheduler_binder.go:255] AssumePodVolumes for pod "kube-system/metrics-server-v0.3.1-677c578bdf-xl48c", node "e2e-test-peterhornyack-minion-group-06gd"
I0416 21:06:52.691435       1 scheduler_binder.go:265] AssumePodVolumes for pod "kube-system/metrics-server-v0.3.1-677c578bdf-xl48c", node "e2e-test-peterhornyack-minion-group-06gd": all PVCs bound and nothing to do
I0416 21:06:52.691483       1 factory.go:734] Attempting to bind metrics-server-v0.3.1-677c578bdf-xl48c to e2e-test-peterhornyack-minion-group-06gd
I0416 21:06:52.693601       1 scheduling_queue.go:895] About to try and schedule pod kube-system/coredns-5b969f4c88-zcdpb
I0416 21:06:52.693614       1 scheduler.go:454] Attempting to schedule pod: kube-system/coredns-5b969f4c88-zcdpb
I0416 21:06:52.696627       1 scheduler_binder.go:255] AssumePodVolumes for pod "kube-system/coredns-5b969f4c88-zcdpb", node "e2e-test-peterhornyack-minion-group-06gd"
I0416 21:06:52.696649       1 scheduler_binder.go:265] AssumePodVolumes for pod "kube-system/coredns-5b969f4c88-zcdpb", node "e2e-test-peterhornyack-minion-group-06gd": all PVCs bound and nothing to do
I0416 21:06:52.696739       1 factory.go:734] Attempting to bind coredns-5b969f4c88-zcdpb to e2e-test-peterhornyack-minion-group-06gd
I0416 21:06:52.701286       1 scheduling_queue.go:895] About to try and schedule pod kube-system/heapster-v1.6.0-beta.1-5858bf5485-5td9x
I0416 21:06:52.701303       1 scheduler.go:454] Attempting to schedule pod: kube-system/heapster-v1.6.0-beta.1-5858bf5485-5td9x
I0416 21:06:52.703422       1 scheduler_binder.go:255] AssumePodVolumes for pod "kube-system/heapster-v1.6.0-beta.1-5858bf5485-5td9x", node "e2e-test-peterhornyack-minion-group-06gd"
I0416 21:06:52.703440       1 scheduler_binder.go:265] AssumePodVolumes for pod "kube-system/heapster-v1.6.0-beta.1-5858bf5485-5td9x", node "e2e-test-peterhornyack-minion-group-06gd": all PVCs bound and nothing to do
I0416 21:06:52.703499       1 factory.go:734] Attempting to bind heapster-v1.6.0-beta.1-5858bf5485-5td9x to e2e-test-peterhornyack-minion-group-06gd
I0416 21:06:52.709159       1 scheduling_queue.go:895] About to try and schedule pod kube-system/fluentd-gcp-scaler-7db4984bf4-26sjq
I0416 21:06:52.709170       1 scheduler.go:454] Attempting to schedule pod: kube-system/fluentd-gcp-scaler-7db4984bf4-26sjq
I0416 21:06:52.709330       1 scheduler_binder.go:255] AssumePodVolumes for pod "kube-system/fluentd-gcp-scaler-7db4984bf4-26sjq", node "e2e-test-peterhornyack-minion-group-06gd"
I0416 21:06:52.709341       1 scheduler_binder.go:265] AssumePodVolumes for pod "kube-system/fluentd-gcp-scaler-7db4984bf4-26sjq", node "e2e-test-peterhornyack-minion-group-06gd": all PVCs bound and nothing to do
I0416 21:06:52.709370       1 factory.go:734] Attempting to bind fluentd-gcp-scaler-7db4984bf4-26sjq to e2e-test-peterhornyack-minion-group-06gd
I0416 21:06:52.709601       1 scheduling_queue.go:895] About to try and schedule pod kube-system/event-exporter-v0.2.4-65d8d98768-n6vvr
I0416 21:06:52.709606       1 scheduler.go:454] Attempting to schedule pod: kube-system/event-exporter-v0.2.4-65d8d98768-n6vvr
I0416 21:06:52.709696       1 scheduler_binder.go:255] AssumePodVolumes for pod "kube-system/event-exporter-v0.2.4-65d8d98768-n6vvr", node "e2e-test-peterhornyack-minion-group-06gd"
I0416 21:06:52.709703       1 scheduler_binder.go:265] AssumePodVolumes for pod "kube-system/event-exporter-v0.2.4-65d8d98768-n6vvr", node "e2e-test-peterhornyack-minion-group-06gd": all PVCs bound and nothing to do
I0416 21:06:52.709719       1 factory.go:734] Attempting to bind event-exporter-v0.2.4-65d8d98768-n6vvr to e2e-test-peterhornyack-minion-group-06gd
I0416 21:06:52.716795       1 scheduling_queue.go:895] About to try and schedule pod kube-system/l7-default-backend-8f479dd9-wbtkw
I0416 21:06:52.716813       1 scheduler.go:454] Attempting to schedule pod: kube-system/l7-default-backend-8f479dd9-wbtkw
I0416 21:06:52.716972       1 scheduler_binder.go:255] AssumePodVolumes for pod "kube-system/l7-default-backend-8f479dd9-wbtkw", node "e2e-test-peterhornyack-minion-group-06gd"
I0416 21:06:52.716982       1 scheduler_binder.go:265] AssumePodVolumes for pod "kube-system/l7-default-backend-8f479dd9-wbtkw", node "e2e-test-peterhornyack-minion-group-06gd": all PVCs bound and nothing to do
I0416 21:06:52.717013       1 factory.go:734] Attempting to bind l7-default-backend-8f479dd9-wbtkw to e2e-test-peterhornyack-minion-group-06gd
I0416 21:06:52.723486       1 scheduler.go:575] pod kube-system/metrics-server-v0.3.1-677c578bdf-xl48c is bound successfully on node e2e-test-peterhornyack-minion-group-06gd, 2 nodes evaluated, 1 nodes were found feasible
I0416 21:06:52.727637       1 scheduler.go:575] pod kube-system/kubernetes-dashboard-85bcf5dbf8-t5nl6 is bound successfully on node e2e-test-peterhornyack-minion-group-06gd, 2 nodes evaluated, 1 nodes were found feasible
I0416 21:06:52.727677       1 scheduler.go:575] pod kube-system/kube-dns-autoscaler-97df449df-4ggmd is bound successfully on node e2e-test-peterhornyack-minion-group-06gd, 2 nodes evaluated, 1 nodes were found feasible
I0416 21:06:52.746242       1 scheduler.go:575] pod kube-system/coredns-5b969f4c88-zcdpb is bound successfully on node e2e-test-peterhornyack-minion-group-06gd, 2 nodes evaluated, 1 nodes were found feasible
I0416 21:06:52.748839       1 scheduler.go:575] pod kube-system/event-exporter-v0.2.4-65d8d98768-n6vvr is bound successfully on node e2e-test-peterhornyack-minion-group-06gd, 2 nodes evaluated, 1 nodes were found feasible
I0416 21:06:52.752037       1 scheduler.go:575] pod kube-system/heapster-v1.6.0-beta.1-5858bf5485-5td9x is bound successfully on node e2e-test-peterhornyack-minion-group-06gd, 2 nodes evaluated, 1 nodes were found feasible
I0416 21:06:52.752115       1 scheduler.go:575] pod kube-system/fluentd-gcp-scaler-7db4984bf4-26sjq is bound successfully on node e2e-test-peterhornyack-minion-group-06gd, 2 nodes evaluated, 1 nodes were found feasible
I0416 21:06:52.770101       1 scheduler.go:575] pod kube-system/l7-default-backend-8f479dd9-wbtkw is bound successfully on node e2e-test-peterhornyack-minion-group-06gd, 2 nodes evaluated, 1 nodes were found feasible
I0416 21:06:52.775792       1 scheduling_queue.go:895] About to try and schedule pod kube-system/fluentd-gcp-v3.2.0-4tl8c
I0416 21:06:52.775816       1 scheduler.go:454] Attempting to schedule pod: kube-system/fluentd-gcp-v3.2.0-4tl8c
I0416 21:06:52.779800       1 scheduler_binder.go:255] AssumePodVolumes for pod "kube-system/fluentd-gcp-v3.2.0-4tl8c", node "e2e-test-peterhornyack-minion-group-06gd"
I0416 21:06:52.779823       1 scheduler_binder.go:265] AssumePodVolumes for pod "kube-system/fluentd-gcp-v3.2.0-4tl8c", node "e2e-test-peterhornyack-minion-group-06gd": all PVCs bound and nothing to do
I0416 21:06:52.779861       1 factory.go:734] Attempting to bind fluentd-gcp-v3.2.0-4tl8c to e2e-test-peterhornyack-minion-group-06gd
I0416 21:06:52.782514       1 cache.go:643] Couldn't expire cache for pod kube-system/fluentd-gcp-v3.2.0-4tl8c. Binding is still in progress.
I0416 21:06:52.794608       1 scheduling_queue.go:895] About to try and schedule pod kube-system/metadata-proxy-v0.1-m4h7x
I0416 21:06:52.794621       1 scheduler.go:454] Attempting to schedule pod: kube-system/metadata-proxy-v0.1-m4h7x
I0416 21:06:52.794884       1 scheduler_binder.go:255] AssumePodVolumes for pod "kube-system/metadata-proxy-v0.1-m4h7x", node "e2e-test-peterhornyack-minion-group-06gd"
I0416 21:06:52.794895       1 scheduler_binder.go:265] AssumePodVolumes for pod "kube-system/metadata-proxy-v0.1-m4h7x", node "e2e-test-peterhornyack-minion-group-06gd": all PVCs bound and nothing to do
I0416 21:06:52.794951       1 factory.go:734] Attempting to bind metadata-proxy-v0.1-m4h7x to e2e-test-peterhornyack-minion-group-06gd
I0416 21:06:52.827310       1 scheduler.go:575] pod kube-system/fluentd-gcp-v3.2.0-4tl8c is bound successfully on node e2e-test-peterhornyack-minion-group-06gd, 2 nodes evaluated, 1 nodes were found feasible
I0416 21:06:52.835540       1 scheduler.go:575] pod kube-system/metadata-proxy-v0.1-m4h7x is bound successfully on node e2e-test-peterhornyack-minion-group-06gd, 2 nodes evaluated, 1 nodes were found feasible
I0416 21:06:56.468754       1 wrap.go:47] GET /healthz: (71.179µs) 200 [kube-probe/1.15+ 127.0.0.1:54112]
I0416 21:07:06.469117       1 wrap.go:47] GET /healthz: (81.346µs) 200 [kube-probe/1.15+ 127.0.0.1:54146]
I0416 21:07:14.189370       1 scheduling_queue.go:895] About to try and schedule pod kube-system/metrics-server-v0.3.1-7d9cf58c5c-xrmt9
I0416 21:07:14.189387       1 scheduler.go:454] Attempting to schedule pod: kube-system/metrics-server-v0.3.1-7d9cf58c5c-xrmt9
I0416 21:07:14.191779       1 scheduler_binder.go:255] AssumePodVolumes for pod "kube-system/metrics-server-v0.3.1-7d9cf58c5c-xrmt9", node "e2e-test-peterhornyack-minion-group-06gd"
I0416 21:07:14.191811       1 scheduler_binder.go:265] AssumePodVolumes for pod "kube-system/metrics-server-v0.3.1-7d9cf58c5c-xrmt9", node "e2e-test-peterhornyack-minion-group-06gd": all PVCs bound and nothing to do
I0416 21:07:14.191865       1 factory.go:734] Attempting to bind metrics-server-v0.3.1-7d9cf58c5c-xrmt9 to e2e-test-peterhornyack-minion-group-06gd
I0416 21:07:14.212662       1 scheduler.go:575] pod kube-system/metrics-server-v0.3.1-7d9cf58c5c-xrmt9 is bound successfully on node e2e-test-peterhornyack-minion-group-06gd, 2 nodes evaluated, 1 nodes were found feasible
I0416 21:07:17.110913       1 wrap.go:47] GET /healthz: (88.902µs) 200 [kube-probe/1.15+ 127.0.0.1:54186]
I0416 21:07:17.585003       1 scheduling_queue.go:895] About to try and schedule pod kube-system/heapster-v1.6.0-beta.1-77858557dc-gwsdj
I0416 21:07:17.585016       1 scheduler.go:454] Attempting to schedule pod: kube-system/heapster-v1.6.0-beta.1-77858557dc-gwsdj
I0416 21:07:17.585209       1 scheduler_binder.go:255] AssumePodVolumes for pod "kube-system/heapster-v1.6.0-beta.1-77858557dc-gwsdj", node "e2e-test-peterhornyack-minion-group-06gd"
I0416 21:07:17.585223       1 scheduler_binder.go:265] AssumePodVolumes for pod "kube-system/heapster-v1.6.0-beta.1-77858557dc-gwsdj", node "e2e-test-peterhornyack-minion-group-06gd": all PVCs bound and nothing to do
I0416 21:07:17.585291       1 factory.go:734] Attempting to bind heapster-v1.6.0-beta.1-77858557dc-gwsdj to e2e-test-peterhornyack-minion-group-06gd
I0416 21:07:17.607649       1 scheduler.go:575] pod kube-system/heapster-v1.6.0-beta.1-77858557dc-gwsdj is bound successfully on node e2e-test-peterhornyack-minion-group-06gd, 2 nodes evaluated, 1 nodes were found feasible
I0416 21:07:24.301659       1 scheduling_queue.go:895] About to try and schedule pod kube-system/fluentd-gcp-v3.2.0-n97bf
I0416 21:07:24.301672       1 scheduler.go:454] Attempting to schedule pod: kube-system/fluentd-gcp-v3.2.0-n97bf
I0416 21:07:24.301979       1 scheduler_binder.go:255] AssumePodVolumes for pod "kube-system/fluentd-gcp-v3.2.0-n97bf", node "e2e-test-peterhornyack-minion-group-06gd"
I0416 21:07:24.301989       1 scheduler_binder.go:265] AssumePodVolumes for pod "kube-system/fluentd-gcp-v3.2.0-n97bf", node "e2e-test-peterhornyack-minion-group-06gd": all PVCs bound and nothing to do
I0416 21:07:24.302044       1 factory.go:734] Attempting to bind fluentd-gcp-v3.2.0-n97bf to e2e-test-peterhornyack-minion-group-06gd
I0416 21:07:24.312188       1 scheduler.go:575] pod kube-system/fluentd-gcp-v3.2.0-n97bf is bound successfully on node e2e-test-peterhornyack-minion-group-06gd, 2 nodes evaluated, 1 nodes were found feasible
I0416 21:07:26.469050       1 wrap.go:47] GET /healthz: (79.443µs) 200 [kube-probe/1.15+ 127.0.0.1:54246]
I0416 21:07:36.468738       1 wrap.go:47] GET /healthz: (96.075µs) 200 [kube-probe/1.15+ 127.0.0.1:54282]
I0416 21:07:41.172634       1 scheduling_queue.go:895] About to try and schedule pod kube-system/fluentd-gcp-v3.2.0-xtf58
I0416 21:07:41.172649       1 scheduler.go:454] Attempting to schedule pod: kube-system/fluentd-gcp-v3.2.0-xtf58
I0416 21:07:41.172910       1 scheduler_binder.go:255] AssumePodVolumes for pod "kube-system/fluentd-gcp-v3.2.0-xtf58", node "e2e-test-peterhornyack-master"
I0416 21:07:41.172921       1 scheduler_binder.go:265] AssumePodVolumes for pod "kube-system/fluentd-gcp-v3.2.0-xtf58", node "e2e-test-peterhornyack-master": all PVCs bound and nothing to do
I0416 21:07:41.172984       1 factory.go:734] Attempting to bind fluentd-gcp-v3.2.0-xtf58 to e2e-test-peterhornyack-master
I0416 21:07:41.217499       1 scheduler.go:575] pod kube-system/fluentd-gcp-v3.2.0-xtf58 is bound successfully on node e2e-test-peterhornyack-master, 2 nodes evaluated, 1 nodes were found feasible
I0416 21:07:46.470591       1 wrap.go:47] GET /healthz: (81.577µs) 200 [kube-probe/1.15+ 127.0.0.1:54408]
I0416 21:07:56.468652       1 wrap.go:47] GET /healthz: (78.877µs) 200 [kube-probe/1.15+ 127.0.0.1:54458]
I0416 21:08:06.468882       1 wrap.go:47] GET /healthz: (97.55µs) 200 [kube-probe/1.15+ 127.0.0.1:54492]
I0416 21:08:16.471609       1 wrap.go:47] GET /healthz: (85.854µs) 200 [kube-probe/1.15+ 127.0.0.1:54524]
I0416 21:08:26.468627       1 wrap.go:47] GET /healthz: (72.935µs) 200 [kube-probe/1.15+ 127.0.0.1:54558]
I0416 21:08:36.468683       1 wrap.go:47] GET /healthz: (72.194µs) 200 [kube-probe/1.15+ 127.0.0.1:54592]
I0416 21:08:40.384484       1 reflector.go:384] k8s.io/client-go/informers/factory.go:133: Watch close - *v1.StorageClass total 1 items received
I0416 21:08:46.468683       1 wrap.go:47] GET /healthz: (62.987µs) 200 [kube-probe/1.15+ 127.0.0.1:54648]
I0416 21:08:56.468584       1 wrap.go:47] GET /healthz: (57.305µs) 200 [kube-probe/1.15+ 127.0.0.1:54684]
I0416 21:08:57.372048       1 reflector.go:384] k8s.io/client-go/informers/factory.go:133: Watch close - *v1.ReplicaSet total 48 items received
I0416 21:09:06.468661       1 wrap.go:47] GET /healthz: (72.034µs) 200 [kube-probe/1.15+ 127.0.0.1:54718]
I0416 21:09:16.468674       1 wrap.go:47] GET /healthz: (75.051µs) 200 [kube-probe/1.15+ 127.0.0.1:54750]
I0416 21:09:26.387451       1 reflector.go:384] cmd/kube-scheduler/app/server.go:223: Watch close - *v1.Pod total 115 items received
I0416 21:09:26.468802       1 wrap.go:47] GET /healthz: (72.999µs) 200 [kube-probe/1.15+ 127.0.0.1:54784]
I0416 21:09:36.468921       1 wrap.go:47] GET /healthz: (73.965µs) 200 [kube-probe/1.15+ 127.0.0.1:54818]
I0416 21:09:42.385220       1 reflector.go:384] k8s.io/client-go/informers/factory.go:133: Watch close - *v1.StatefulSet total 0 items received
I0416 21:09:46.471638       1 wrap.go:47] GET /healthz: (74.865µs) 200 [kube-probe/1.15+ 127.0.0.1:54870]
I0416 21:09:55.673841       1 scheduling_queue.go:895] About to try and schedule pod kube-system/coredns-5b969f4c88-6mpws
I0416 21:09:55.673855       1 scheduler.go:454] Attempting to schedule pod: kube-system/coredns-5b969f4c88-6mpws
I0416 21:09:55.676602       1 scheduler_binder.go:255] AssumePodVolumes for pod "kube-system/coredns-5b969f4c88-6mpws", node "e2e-test-peterhornyack-minion-group-06gd"
I0416 21:09:55.676619       1 scheduler_binder.go:265] AssumePodVolumes for pod "kube-system/coredns-5b969f4c88-6mpws", node "e2e-test-peterhornyack-minion-group-06gd": all PVCs bound and nothing to do
I0416 21:09:55.676683       1 factory.go:734] Attempting to bind coredns-5b969f4c88-6mpws to e2e-test-peterhornyack-minion-group-06gd
I0416 21:09:55.688484       1 scheduler.go:575] pod kube-system/coredns-5b969f4c88-6mpws is bound successfully on node e2e-test-peterhornyack-minion-group-06gd, 3 nodes evaluated, 1 nodes were found feasible
I0416 21:09:56.469071       1 wrap.go:47] GET /healthz: (84.072µs) 200 [kube-probe/1.15+ 127.0.0.1:54908]
I0416 21:09:57.270272       1 reflector.go:384] k8s.io/client-go/informers/factory.go:133: Watch close - *v1.ReplicationController total 0 items received
I0416 21:10:02.524299       1 wrap.go:47] GET /healthz: (100.063µs) 200 [kube-probe/1.15+ 127.0.0.1:54934]
I0416 21:10:02.844759       1 wrap.go:47] GET /healthz: (100.182µs) 200 [kube-probe/1.15+ 127.0.0.1:54944]
I0416 21:10:06.468898       1 wrap.go:47] GET /healthz: (88.126µs) 200 [kube-probe/1.15+ 127.0.0.1:54958]
I0416 21:10:09.380633       1 reflector.go:384] k8s.io/client-go/informers/factory.go:133: Watch close - *v1beta1.PodDisruptionBudget total 0 items received
I0416 21:10:13.284671       1 reflector.go:384] k8s.io/client-go/informers/factory.go:133: Watch close - *v1.Service total 6 items received
I0416 21:10:16.468708       1 wrap.go:47] GET /healthz: (57.537µs) 200 [kube-probe/1.15+ 127.0.0.1:54990]
I0416 21:10:26.469069       1 wrap.go:47] GET /healthz: (75.593µs) 200 [kube-probe/1.15+ 127.0.0.1:55024]
I0416 21:10:36.468697       1 wrap.go:47] GET /healthz: (76.916µs) 200 [kube-probe/1.15+ 127.0.0.1:55058]
I0416 21:10:46.468778       1 wrap.go:47] GET /healthz: (73.183µs) 200 [kube-probe/1.15+ 127.0.0.1:55110]
I0416 21:10:56.468971       1 wrap.go:47] GET /healthz: (77.845µs) 200 [kube-probe/1.15+ 127.0.0.1:55146]
I0416 21:11:06.468616       1 wrap.go:47] GET /healthz: (87.651µs) 200 [kube-probe/1.15+ 127.0.0.1:55180]
I0416 21:11:16.468837       1 wrap.go:47] GET /healthz: (73.98µs) 200 [kube-probe/1.15+ 127.0.0.1:55212]
I0416 21:11:26.468710       1 wrap.go:47] GET /healthz: (71.404µs) 200 [kube-probe/1.15+ 127.0.0.1:55246]
I0416 21:11:36.468854       1 wrap.go:47] GET /healthz: (77.228µs) 200 [kube-probe/1.15+ 127.0.0.1:55280]
I0416 21:11:46.468614       1 wrap.go:47] GET /healthz: (93.804µs) 200 [kube-probe/1.15+ 127.0.0.1:55332]
I0416 21:11:56.468354       1 wrap.go:47] GET /healthz: (117.658µs) 200 [kube-probe/1.15+ 127.0.0.1:55368]
I0416 21:12:06.469723       1 wrap.go:47] GET /healthz: (77.266µs) 200 [kube-probe/1.15+ 127.0.0.1:55402]
I0416 21:12:16.468614       1 wrap.go:47] GET /healthz: (80.128µs) 200 [kube-probe/1.15+ 127.0.0.1:55434]
I0416 21:12:19.371056       1 reflector.go:384] k8s.io/client-go/informers/factory.go:133: Watch close - *v1.PersistentVolumeClaim total 0 items received
I0416 21:12:26.469060       1 wrap.go:47] GET /healthz: (80.366µs) 200 [kube-probe/1.15+ 127.0.0.1:55468]
I0416 21:12:36.470026       1 wrap.go:47] GET /healthz: (71.917µs) 200 [kube-probe/1.15+ 127.0.0.1:55502]
I0416 21:12:37.369603       1 reflector.go:384] k8s.io/client-go/informers/factory.go:133: Watch close - *v1.PersistentVolume total 0 items received
I0416 21:12:46.468636       1 wrap.go:47] GET /healthz: (74.655µs) 200 [kube-probe/1.15+ 127.0.0.1:55554]
I0416 21:12:56.471286       1 wrap.go:47] GET /healthz: (113.976µs) 200 [kube-probe/1.15+ 127.0.0.1:55590]
I0416 21:13:06.468770       1 wrap.go:47] GET /healthz: (65.927µs) 200 [kube-probe/1.15+ 127.0.0.1:55624]
I0416 21:13:16.468697       1 wrap.go:47] GET /healthz: (68.155µs) 200 [kube-probe/1.15+ 127.0.0.1:55656]
I0416 21:13:18.386608       1 reflector.go:384] k8s.io/client-go/informers/factory.go:133: Watch close - *v1.Node total 54 items received
I0416 21:13:26.468568       1 wrap.go:47] GET /healthz: (77.429µs) 200 [kube-probe/1.15+ 127.0.0.1:55688]
I0416 21:13:36.468604       1 wrap.go:47] GET /healthz: (74.863µs) 200 [kube-probe/1.15+ 127.0.0.1:55724]
I0416 21:13:46.468625       1 wrap.go:47] GET /healthz: (73.68µs) 200 [kube-probe/1.15+ 127.0.0.1:55776]
I0416 21:13:56.468741       1 wrap.go:47] GET /healthz: (64.943µs) 200 [kube-probe/1.15+ 127.0.0.1:55812]
I0416 21:13:59.373921       1 reflector.go:384] k8s.io/client-go/informers/factory.go:133: Watch close - *v1.ReplicaSet total 4 items received
I0416 21:14:06.468806       1 wrap.go:47] GET /healthz: (69.885µs) 200 [kube-probe/1.15+ 127.0.0.1:55846]
I0416 21:14:16.469344       1 wrap.go:47] GET /healthz: (98.945µs) 200 [kube-probe/1.15+ 127.0.0.1:55878]
I0416 21:14:26.469063       1 wrap.go:47] GET /healthz: (78.563µs) 200 [kube-probe/1.15+ 127.0.0.1:55910]
I0416 21:14:36.468579       1 wrap.go:47] GET /healthz: (75.3µs) 200 [kube-probe/1.15+ 127.0.0.1:55946]
I0416 21:14:46.468860       1 wrap.go:47] GET /healthz: (69.443µs) 200 [kube-probe/1.15+ 127.0.0.1:55998]
I0416 21:14:55.387564       1 reflector.go:384] k8s.io/client-go/informers/factory.go:133: Watch close - *v1.StatefulSet total 0 items received
I0416 21:14:56.468734       1 wrap.go:47] GET /healthz: (86.288µs) 200 [kube-probe/1.15+ 127.0.0.1:56034]
I0416 21:15:06.272740       1 reflector.go:384] k8s.io/client-go/informers/factory.go:133: Watch close - *v1.ReplicationController total 0 items received
I0416 21:15:06.468570       1 wrap.go:47] GET /healthz: (86.583µs) 200 [kube-probe/1.15+ 127.0.0.1:56068]
I0416 21:15:16.468594       1 wrap.go:47] GET /healthz: (76.573µs) 200 [kube-probe/1.15+ 127.0.0.1:56100]
I0416 21:15:26.468829       1 wrap.go:47] GET /healthz: (95.242µs) 200 [kube-probe/1.15+ 127.0.0.1:56132]
I0416 21:15:36.468818       1 wrap.go:47] GET /healthz: (71.048µs) 200 [kube-probe/1.15+ 127.0.0.1:56168]
I0416 21:15:46.468849       1 wrap.go:47] GET /healthz: (77.425µs) 200 [kube-probe/1.15+ 127.0.0.1:56220]
I0416 21:15:56.469038       1 wrap.go:47] GET /healthz: (74.273µs) 200 [kube-probe/1.15+ 127.0.0.1:56256]
I0416 21:16:01.383149       1 reflector.go:384] k8s.io/client-go/informers/factory.go:133: Watch close - *v1beta1.PodDisruptionBudget total 0 items received
I0416 21:16:06.469282       1 wrap.go:47] GET /healthz: (112.597µs) 200 [kube-probe/1.15+ 127.0.0.1:56290]
I0416 21:16:16.468606       1 wrap.go:47] GET /healthz: (71.671µs) 200 [kube-probe/1.15+ 127.0.0.1:56324]
I0416 21:16:26.469090       1 wrap.go:47] GET /healthz: (71.559µs) 200 [kube-probe/1.15+ 127.0.0.1:56356]
I0416 21:16:36.469038       1 wrap.go:47] GET /healthz: (92.008µs) 200 [kube-probe/1.15+ 127.0.0.1:56392]
I0416 21:16:40.387017       1 reflector.go:384] k8s.io/client-go/informers/factory.go:133: Watch close - *v1.StorageClass total 0 items received
I0416 21:16:46.468782       1 wrap.go:47] GET /healthz: (75.559µs) 200 [kube-probe/1.15+ 127.0.0.1:56444]
I0416 21:16:56.468888       1 wrap.go:47] GET /healthz: (74.023µs) 200 [kube-probe/1.15+ 127.0.0.1:56480]
I0416 21:17:06.469361       1 wrap.go:47] GET /healthz: (76.975µs) 200 [kube-probe/1.15+ 127.0.0.1:56514]
I0416 21:17:16.469610       1 wrap.go:47] GET /healthz: (79.717µs) 200 [kube-probe/1.15+ 127.0.0.1:56546]
I0416 21:17:26.469071       1 wrap.go:47] GET /healthz: (130.496µs) 200 [kube-probe/1.15+ 127.0.0.1:56578]
I0416 21:17:36.468792       1 wrap.go:47] GET /healthz: (88.407µs) 200 [kube-probe/1.15+ 127.0.0.1:56614]
I0416 21:17:46.470572       1 wrap.go:47] GET /healthz: (79.434µs) 200 [kube-probe/1.15+ 127.0.0.1:56666]
I0416 21:17:56.468601       1 wrap.go:47] GET /healthz: (71.081µs) 200 [kube-probe/1.15+ 127.0.0.1:56702]
I0416 21:18:06.286964       1 reflector.go:384] k8s.io/client-go/informers/factory.go:133: Watch close - *v1.Service total 0 items received
I0416 21:18:06.468604       1 wrap.go:47] GET /healthz: (77.517µs) 200 [kube-probe/1.15+ 127.0.0.1:56740]
I0416 21:18:16.468906       1 wrap.go:47] GET /healthz: (73.948µs) 200 [kube-probe/1.15+ 127.0.0.1:56772]
I0416 21:18:26.468671       1 wrap.go:47] GET /healthz: (98.133µs) 200 [kube-probe/1.15+ 127.0.0.1:56804]
I0416 21:18:36.389773       1 reflector.go:384] cmd/kube-scheduler/app/server.go:223: Watch close - *v1.Pod total 5 items received
I0416 21:18:36.469526       1 wrap.go:47] GET /healthz: (77.983µs) 200 [kube-probe/1.15+ 127.0.0.1:56838]
I0416 21:18:46.468836       1 wrap.go:47] GET /healthz: (75.881µs) 200 [kube-probe/1.15+ 127.0.0.1:56892]
I0416 21:18:56.468673       1 wrap.go:47] GET /healthz: (70.497µs) 200 [kube-probe/1.15+ 127.0.0.1:56928]
I0416 21:19:06.468875       1 wrap.go:47] GET /healthz: (62.921µs) 200 [kube-probe/1.15+ 127.0.0.1:56962]
I0416 21:19:16.468562       1 wrap.go:47] GET /healthz: (71.976µs) 200 [kube-probe/1.15+ 127.0.0.1:56994]
I0416 21:19:26.468587       1 wrap.go:47] GET /healthz: (91.04µs) 200 [kube-probe/1.15+ 127.0.0.1:57026]
I0416 21:19:36.469543       1 wrap.go:47] GET /healthz: (71.762µs) 200 [kube-probe/1.15+ 127.0.0.1:57060]
I0416 21:19:46.468774       1 wrap.go:47] GET /healthz: (73.003µs) 200 [kube-probe/1.15+ 127.0.0.1:57114]
I0416 21:19:56.468617       1 wrap.go:47] GET /healthz: (76.246µs) 200 [kube-probe/1.15+ 127.0.0.1:57150]
I0416 21:20:06.468732       1 wrap.go:47] GET /healthz: (73.276µs) 200 [kube-probe/1.15+ 127.0.0.1:57184]
I0416 21:20:16.468700       1 wrap.go:47] GET /healthz: (78.86µs) 200 [kube-probe/1.15+ 127.0.0.1:57216]
I0416 21:20:22.373210       1 reflector.go:384] k8s.io/client-go/informers/factory.go:133: Watch close - *v1.PersistentVolumeClaim total 0 items received
I0416 21:20:26.468372       1 wrap.go:47] GET /healthz: (74.219µs) 200 [kube-probe/1.15+ 127.0.0.1:57248]
I0416 21:20:36.468673       1 wrap.go:47] GET /healthz: (72.724µs) 200 [kube-probe/1.15+ 127.0.0.1:57282]
I0416 21:20:46.468872       1 wrap.go:47] GET /healthz: (95.232µs) 200 [kube-probe/1.15+ 127.0.0.1:57336]
I0416 21:20:48.371902       1 reflector.go:384] k8s.io/client-go/informers/factory.go:133: Watch close - *v1.PersistentVolume total 0 items received
I0416 21:20:56.468784       1 wrap.go:47] GET /healthz: (72.67µs) 200 [kube-probe/1.15+ 127.0.0.1:57372]
I0416 21:21:06.469081       1 wrap.go:47] GET /healthz: (85.14µs) 200 [kube-probe/1.15+ 127.0.0.1:57406]
I0416 21:21:16.468966       1 wrap.go:47] GET /healthz: (78.006µs) 200 [kube-probe/1.15+ 127.0.0.1:57438]
I0416 21:21:26.468580       1 wrap.go:47] GET /healthz: (74.794µs) 200 [kube-probe/1.15+ 127.0.0.1:57470]
I0416 21:21:36.468672       1 wrap.go:47] GET /healthz: (78.928µs) 200 [kube-probe/1.15+ 127.0.0.1:57504]
I0416 21:21:46.470053       1 wrap.go:47] GET /healthz: (72.022µs) 200 [kube-probe/1.15+ 127.0.0.1:57558]
I0416 21:21:56.470621       1 wrap.go:47] GET /healthz: (73.026µs) 200 [kube-probe/1.15+ 127.0.0.1:57594]
I0416 21:22:01.275097       1 reflector.go:384] k8s.io/client-go/informers/factory.go:133: Watch close - *v1.ReplicationController total 0 items received
I0416 21:22:06.470689       1 wrap.go:47] GET /healthz: (84.413µs) 200 [kube-probe/1.15+ 127.0.0.1:57628]
I0416 21:22:16.469877       1 wrap.go:47] GET /healthz: (77.865µs) 200 [kube-probe/1.15+ 127.0.0.1:57660]
I0416 21:22:26.470682       1 wrap.go:47] GET /healthz: (70.293µs) 200 [kube-probe/1.15+ 127.0.0.1:57692]
I0416 21:22:36.470612       1 wrap.go:47] GET /healthz: (86.593µs) 200 [kube-probe/1.15+ 127.0.0.1:57726]
I0416 21:22:46.475556       1 wrap.go:47] GET /healthz: (80.651µs) 200 [kube-probe/1.15+ 127.0.0.1:57778]
I0416 21:22:55.385449       1 reflector.go:384] k8s.io/client-go/informers/factory.go:133: Watch close - *v1beta1.PodDisruptionBudget total 0 items received
I0416 21:22:56.469403       1 wrap.go:47] GET /healthz: (74.514µs) 200 [kube-probe/1.15+ 127.0.0.1:57816]
I0416 21:22:59.376040       1 reflector.go:384] k8s.io/client-go/informers/factory.go:133: Watch close - *v1.ReplicaSet total 0 items received
I0416 21:23:06.469582       1 wrap.go:47] GET /healthz: (87.516µs) 200 [kube-probe/1.15+ 127.0.0.1:57850]
I0416 21:23:11.389101       1 reflector.go:384] k8s.io/client-go/informers/factory.go:133: Watch close - *v1.Node total 40 items received
I0416 21:23:16.468945       1 wrap.go:47] GET /healthz: (162.542µs) 200 [kube-probe/1.15+ 127.0.0.1:57882]
I0416 21:23:26.469581       1 wrap.go:47] GET /healthz: (80.565µs) 200 [kube-probe/1.15+ 127.0.0.1:57914]
I0416 21:23:36.469547       1 wrap.go:47] GET /healthz: (74.668µs) 200 [kube-probe/1.15+ 127.0.0.1:57948]
I0416 21:23:46.470500       1 wrap.go:47] GET /healthz: (190.136µs) 200 [kube-probe/1.15+ 127.0.0.1:58000]
I0416 21:23:56.473437       1 wrap.go:47] GET /healthz: (75.448µs) 200 [kube-probe/1.15+ 127.0.0.1:58038]
I0416 21:24:06.469289       1 wrap.go:47] GET /healthz: (102.265µs) 200 [kube-probe/1.15+ 127.0.0.1:58072]
I0416 21:24:16.491388       1 wrap.go:47] GET /healthz: (100.132µs) 200 [kube-probe/1.15+ 127.0.0.1:58104]
I0416 21:24:26.468656       1 wrap.go:47] GET /healthz: (68.912µs) 200 [kube-probe/1.15+ 127.0.0.1:58136]
I0416 21:24:36.468713       1 wrap.go:47] GET /healthz: (75.236µs) 200 [kube-probe/1.15+ 127.0.0.1:58170]
I0416 21:24:46.468478       1 wrap.go:47] GET /healthz: (71.669µs) 200 [kube-probe/1.15+ 127.0.0.1:58224]
I0416 21:24:49.389772       1 reflector.go:384] k8s.io/client-go/informers/factory.go:133: Watch close - *v1.StatefulSet total 0 items received
I0416 21:24:56.468688       1 wrap.go:47] GET /healthz: (77.105µs) 200 [kube-probe/1.15+ 127.0.0.1:58266]
I0416 21:25:06.490358       1 wrap.go:47] GET /healthz: (96.53µs) 200 [kube-probe/1.15+ 127.0.0.1:58300]
I0416 21:25:07.389207       1 reflector.go:384] k8s.io/client-go/informers/factory.go:133: Watch close - *v1.StorageClass total 0 items received
I0416 21:25:16.470587       1 wrap.go:47] GET /healthz: (75.881µs) 200 [kube-probe/1.15+ 127.0.0.1:58332]
I0416 21:25:26.470587       1 wrap.go:47] GET /healthz: (72.983µs) 200 [kube-probe/1.15+ 127.0.0.1:58364]
I0416 21:25:36.468922       1 wrap.go:47] GET /healthz: (71.349µs) 200 [kube-probe/1.15+ 127.0.0.1:58398]
I0416 21:25:37.375824       1 reflector.go:384] k8s.io/client-go/informers/factory.go:133: Watch close - *v1.PersistentVolumeClaim total 0 items received
I0416 21:25:46.468805       1 wrap.go:47] GET /healthz: (161.037µs) 200 [kube-probe/1.15+ 127.0.0.1:58450]
I0416 21:25:56.468899       1 wrap.go:47] GET /healthz: (78.867µs) 200 [kube-probe/1.15+ 127.0.0.1:58488]
I0416 21:26:06.468731       1 wrap.go:47] GET /healthz: (75.224µs) 200 [kube-probe/1.15+ 127.0.0.1:58522]
I0416 21:26:09.289466       1 reflector.go:384] k8s.io/client-go/informers/factory.go:133: Watch close - *v1.Service total 0 items received
I0416 21:26:16.468624       1 wrap.go:47] GET /healthz: (81.418µs) 200 [kube-probe/1.15+ 127.0.0.1:58554]
I0416 21:26:24.392182       1 reflector.go:384] cmd/kube-scheduler/app/server.go:223: Watch close - *v1.Pod total 0 items received
I0416 21:26:26.468955       1 wrap.go:47] GET /healthz: (70.266µs) 200 [kube-probe/1.15+ 127.0.0.1:58586]
I0416 21:26:36.468847       1 wrap.go:47] GET /healthz: (81.152µs) 200 [kube-probe/1.15+ 127.0.0.1:58620]
I0416 21:26:39.019978       1 scheduling_queue.go:895] About to try and schedule pod default/linux-nginx-7c4f9bd84f-vsbts
I0416 21:26:39.019991       1 scheduler.go:454] Attempting to schedule pod: default/linux-nginx-7c4f9bd84f-vsbts
I0416 21:26:39.022262       1 scheduler_binder.go:255] AssumePodVolumes for pod "default/linux-nginx-7c4f9bd84f-vsbts", node "e2e-test-peterhornyack-minion-group-06gd"
I0416 21:26:39.022280       1 scheduler_binder.go:265] AssumePodVolumes for pod "default/linux-nginx-7c4f9bd84f-vsbts", node "e2e-test-peterhornyack-minion-group-06gd": all PVCs bound and nothing to do
I0416 21:26:39.022361       1 factory.go:734] Attempting to bind linux-nginx-7c4f9bd84f-vsbts to e2e-test-peterhornyack-minion-group-06gd
I0416 21:26:39.036125       1 scheduler.go:575] pod default/linux-nginx-7c4f9bd84f-vsbts is bound successfully on node e2e-test-peterhornyack-minion-group-06gd, 3 nodes evaluated, 1 nodes were found feasible
I0416 21:26:46.468854       1 wrap.go:47] GET /healthz: (80.923µs) 200 [kube-probe/1.15+ 127.0.0.1:58672]
I0416 21:26:49.935590       1 scheduling_queue.go:895] About to try and schedule pod default/linux-ubuntu-5dbcdfff9d-xmpzc
I0416 21:26:49.935604       1 scheduler.go:454] Attempting to schedule pod: default/linux-ubuntu-5dbcdfff9d-xmpzc
I0416 21:26:49.937864       1 scheduler_binder.go:255] AssumePodVolumes for pod "default/linux-ubuntu-5dbcdfff9d-xmpzc", node "e2e-test-peterhornyack-minion-group-06gd"
I0416 21:26:49.937880       1 scheduler_binder.go:265] AssumePodVolumes for pod "default/linux-ubuntu-5dbcdfff9d-xmpzc", node "e2e-test-peterhornyack-minion-group-06gd": all PVCs bound and nothing to do
I0416 21:26:49.937954       1 factory.go:734] Attempting to bind linux-ubuntu-5dbcdfff9d-xmpzc to e2e-test-peterhornyack-minion-group-06gd
I0416 21:26:49.957387       1 scheduler.go:575] pod default/linux-ubuntu-5dbcdfff9d-xmpzc is bound successfully on node e2e-test-peterhornyack-minion-group-06gd, 3 nodes evaluated, 1 nodes were found feasible
I0416 21:26:56.471567       1 wrap.go:47] GET /healthz: (74.478µs) 200 [kube-probe/1.15+ 127.0.0.1:58710]
I0416 21:27:00.823962       1 scheduling_queue.go:895] About to try and schedule pod default/windows-nettest-944bd6d8d-rfhxl
I0416 21:27:00.823976       1 scheduler.go:454] Attempting to schedule pod: default/windows-nettest-944bd6d8d-rfhxl
I0416 21:27:00.824206       1 scheduler_binder.go:255] AssumePodVolumes for pod "default/windows-nettest-944bd6d8d-rfhxl", node "e2e-test-peterhornyack-windows-node-group-31ht"
I0416 21:27:00.824215       1 scheduler_binder.go:265] AssumePodVolumes for pod "default/windows-nettest-944bd6d8d-rfhxl", node "e2e-test-peterhornyack-windows-node-group-31ht": all PVCs bound and nothing to do
I0416 21:27:00.826942       1 factory.go:734] Attempting to bind windows-nettest-944bd6d8d-rfhxl to e2e-test-peterhornyack-windows-node-group-31ht
I0416 21:27:00.847728       1 scheduler.go:575] pod default/windows-nettest-944bd6d8d-rfhxl is bound successfully on node e2e-test-peterhornyack-windows-node-group-31ht, 3 nodes evaluated, 1 nodes were found feasible
I0416 21:27:06.468754       1 wrap.go:47] GET /healthz: (75.091µs) 200 [kube-probe/1.15+ 127.0.0.1:58744]
I0416 21:27:16.468696       1 wrap.go:47] GET /healthz: (76.219µs) 200 [kube-probe/1.15+ 127.0.0.1:58778]
I0416 21:27:26.470630       1 wrap.go:47] GET /healthz: (75.838µs) 200 [kube-probe/1.15+ 127.0.0.1:58810]
I0416 21:27:36.468761       1 wrap.go:47] GET /healthz: (75.093µs) 200 [kube-probe/1.15+ 127.0.0.1:58844]
I0416 21:27:46.468990       1 wrap.go:47] GET /healthz: (71.06µs) 200 [kube-probe/1.15+ 127.0.0.1:58896]
I0416 21:27:56.469314       1 wrap.go:47] GET /healthz: (172.36µs) 200 [kube-probe/1.15+ 127.0.0.1:58932]
I0416 21:28:06.470560       1 wrap.go:47] GET /healthz: (1.649025ms) 200 [kube-probe/1.15+ 127.0.0.1:58968]
I0416 21:28:16.468696       1 wrap.go:47] GET /healthz: (82.833µs) 200 [kube-probe/1.15+ 127.0.0.1:59000]
I0416 21:28:26.468732       1 wrap.go:47] GET /healthz: (83.511µs) 200 [kube-probe/1.15+ 127.0.0.1:59032]
I0416 21:28:36.469145       1 wrap.go:47] GET /healthz: (58.113µs) 200 [kube-probe/1.15+ 127.0.0.1:59066]
I0416 21:28:46.468866       1 wrap.go:47] GET /healthz: (77.706µs) 200 [kube-probe/1.15+ 127.0.0.1:59118]
I0416 21:28:56.468977       1 wrap.go:47] GET /healthz: (79.707µs) 200 [kube-probe/1.15+ 127.0.0.1:59154]
I0416 21:29:06.469014       1 wrap.go:47] GET /healthz: (95.556µs) 200 [kube-probe/1.15+ 127.0.0.1:59190]
I0416 21:29:13.391388       1 reflector.go:384] k8s.io/client-go/informers/factory.go:133: Watch close - *v1.Node total 25 items received
I0416 21:29:16.468904       1 wrap.go:47] GET /healthz: (86.135µs) 200 [kube-probe/1.15+ 127.0.0.1:59222]
I0416 21:29:22.374168       1 reflector.go:384] k8s.io/client-go/informers/factory.go:133: Watch close - *v1.PersistentVolume total 0 items received
I0416 21:29:26.468918       1 wrap.go:47] GET /healthz: (72.717µs) 200 [kube-probe/1.15+ 127.0.0.1:59254]
I0416 21:29:36.468602       1 wrap.go:47] GET /healthz: (70.421µs) 200 [kube-probe/1.15+ 127.0.0.1:59288]
I0416 21:29:46.468790       1 wrap.go:47] GET /healthz: (80.134µs) 200 [kube-probe/1.15+ 127.0.0.1:59352]
I0416 21:29:56.468701       1 wrap.go:47] GET /healthz: (90.05µs) 200 [kube-probe/1.15+ 127.0.0.1:59388]
I0416 21:30:06.469894       1 wrap.go:47] GET /healthz: (74.225µs) 200 [kube-probe/1.15+ 127.0.0.1:59424]
I0416 21:30:16.468931       1 wrap.go:47] GET /healthz: (71.902µs) 200 [kube-probe/1.15+ 127.0.0.1:59456]
I0416 21:30:18.277607       1 reflector.go:384] k8s.io/client-go/informers/factory.go:133: Watch close - *v1.ReplicationController total 0 items received
I0416 21:30:26.468860       1 wrap.go:47] GET /healthz: (79.321µs) 200 [kube-probe/1.15+ 127.0.0.1:59488]
I0416 21:30:36.470784       1 wrap.go:47] GET /healthz: (85.047µs) 200 [kube-probe/1.15+ 127.0.0.1:59522]
I0416 21:30:46.468842       1 wrap.go:47] GET /healthz: (86.539µs) 200 [kube-probe/1.15+ 127.0.0.1:59574]
I0416 21:30:56.468870       1 wrap.go:47] GET /healthz: (74.433µs) 200 [kube-probe/1.15+ 127.0.0.1:59610]
I0416 21:31:03.392213       1 reflector.go:384] k8s.io/client-go/informers/factory.go:133: Watch close - *v1.StatefulSet total 0 items received
I0416 21:31:06.391132       1 reflector.go:384] k8s.io/client-go/informers/factory.go:133: Watch close - *v1.StorageClass total 0 items received
I0416 21:31:06.468741       1 wrap.go:47] GET /healthz: (76.976µs) 200 [kube-probe/1.15+ 127.0.0.1:59646]
I0416 21:31:16.468590       1 wrap.go:47] GET /healthz: (66.677µs) 200 [kube-probe/1.15+ 127.0.0.1:59678]
I0416 21:31:26.468791       1 wrap.go:47] GET /healthz: (81.855µs) 200 [kube-probe/1.15+ 127.0.0.1:59710]
I0416 21:31:29.394930       1 reflector.go:384] cmd/kube-scheduler/app/server.go:223: Watch close - *v1.Pod total 23 items received
I0416 21:31:36.470279       1 wrap.go:47] GET /healthz: (990.015µs) 200 [kube-probe/1.15+ 127.0.0.1:59744]
I0416 21:31:46.469356       1 wrap.go:47] GET /healthz: (84.691µs) 200 [kube-probe/1.15+ 127.0.0.1:59796]
I0416 21:31:56.468917       1 wrap.go:47] GET /healthz: (65.793µs) 200 [kube-probe/1.15+ 127.0.0.1:59832]
I0416 21:32:06.471796       1 wrap.go:47] GET /healthz: (422.849µs) 200 [kube-probe/1.15+ 127.0.0.1:59868]
I0416 21:32:16.469195       1 wrap.go:47] GET /healthz: (98.064µs) 200 [kube-probe/1.15+ 127.0.0.1:59900]
I0416 21:32:17.291977       1 reflector.go:384] k8s.io/client-go/informers/factory.go:133: Watch close - *v1.Service total 0 items received
I0416 21:32:23.378366       1 reflector.go:384] k8s.io/client-go/informers/factory.go:133: Watch close - *v1.ReplicaSet total 14 items received
I0416 21:32:24.388914       1 reflector.go:384] k8s.io/client-go/informers/factory.go:133: Watch close - *v1beta1.PodDisruptionBudget total 0 items received
I0416 21:32:26.468761       1 wrap.go:47] GET /healthz: (76.162µs) 200 [kube-probe/1.15+ 127.0.0.1:59932]
I0416 21:32:36.469151       1 wrap.go:47] GET /healthz: (75.733µs) 200 [kube-probe/1.15+ 127.0.0.1:59966]
I0416 21:32:46.468821       1 wrap.go:47] GET /healthz: (74.064µs) 200 [kube-probe/1.15+ 127.0.0.1:60018]
I0416 21:32:56.469429       1 wrap.go:47] GET /healthz: (88.442µs) 200 [kube-probe/1.15+ 127.0.0.1:60054]
I0416 21:33:06.470103       1 wrap.go:47] GET /healthz: (83.687µs) 200 [kube-probe/1.15+ 127.0.0.1:60088]
I0416 21:33:16.468717       1 wrap.go:47] GET /healthz: (73.998µs) 200 [kube-probe/1.15+ 127.0.0.1:60122]
I0416 21:33:26.468981       1 wrap.go:47] GET /healthz: (73.45µs) 200 [kube-probe/1.15+ 127.0.0.1:60154]
I0416 21:33:36.468747       1 wrap.go:47] GET /healthz: (76.964µs) 200 [kube-probe/1.15+ 127.0.0.1:60188]
I0416 21:33:46.469901       1 wrap.go:47] GET /healthz: (73.463µs) 200 [kube-probe/1.15+ 127.0.0.1:60240]
I0416 21:33:56.468770       1 wrap.go:47] GET /healthz: (88.264µs) 200 [kube-probe/1.15+ 127.0.0.1:60276]
I0416 21:34:00.378049       1 reflector.go:384] k8s.io/client-go/informers/factory.go:133: Watch close - *v1.PersistentVolumeClaim total 0 items received
I0416 21:34:06.470044       1 wrap.go:47] GET /healthz: (75.885µs) 200 [kube-probe/1.15+ 127.0.0.1:60310]
I0416 21:34:16.468971       1 wrap.go:47] GET /healthz: (80.188µs) 200 [kube-probe/1.15+ 127.0.0.1:60344]
I0416 21:34:26.468792       1 wrap.go:47] GET /healthz: (80.762µs) 200 [kube-probe/1.15+ 127.0.0.1:60376]
I0416 21:34:36.468893       1 wrap.go:47] GET /healthz: (75.357µs) 200 [kube-probe/1.15+ 127.0.0.1:60410]
I0416 21:34:46.468959       1 wrap.go:47] GET /healthz: (80.852µs) 200 [kube-probe/1.15+ 127.0.0.1:60462]
I0416 21:34:56.468833       1 wrap.go:47] GET /healthz: (75.63µs) 200 [kube-probe/1.15+ 127.0.0.1:60498]
I0416 21:35:06.468862       1 wrap.go:47] GET /healthz: (59.583µs) 200 [kube-probe/1.15+ 127.0.0.1:60532]
I0416 21:35:16.468772       1 wrap.go:47] GET /healthz: (76.051µs) 200 [kube-probe/1.15+ 127.0.0.1:60566]
I0416 21:35:26.469385       1 wrap.go:47] GET /healthz: (79.728µs) 200 [kube-probe/1.15+ 127.0.0.1:60598]
I0416 21:35:33.279895       1 reflector.go:384] k8s.io/client-go/informers/factory.go:133: Watch close - *v1.ReplicationController total 0 items received
I0416 21:35:36.468693       1 wrap.go:47] GET /healthz: (77.131µs) 200 [kube-probe/1.15+ 127.0.0.1:60632]
I0416 21:35:46.470566       1 wrap.go:47] GET /healthz: (114.324µs) 200 [kube-probe/1.15+ 127.0.0.1:60684]
I0416 21:35:52.807577       1 scheduling_queue.go:895] About to try and schedule pod default/linux-nginx-7c4f9bd84f-bp2kn
I0416 21:35:52.807594       1 scheduler.go:454] Attempting to schedule pod: default/linux-nginx-7c4f9bd84f-bp2kn
I0416 21:35:52.810461       1 scheduler_binder.go:255] AssumePodVolumes for pod "default/linux-nginx-7c4f9bd84f-bp2kn", node "e2e-test-peterhornyack-minion-group-06gd"
I0416 21:35:52.810477       1 scheduler_binder.go:265] AssumePodVolumes for pod "default/linux-nginx-7c4f9bd84f-bp2kn", node "e2e-test-peterhornyack-minion-group-06gd": all PVCs bound and nothing to do
I0416 21:35:52.811220       1 factory.go:734] Attempting to bind linux-nginx-7c4f9bd84f-bp2kn to e2e-test-peterhornyack-minion-group-06gd
I0416 21:35:52.827656       1 scheduler.go:575] pod default/linux-nginx-7c4f9bd84f-bp2kn is bound successfully on node e2e-test-peterhornyack-minion-group-06gd, 3 nodes evaluated, 1 nodes were found feasible
I0416 21:35:56.468661       1 wrap.go:47] GET /healthz: (85.768µs) 200 [kube-probe/1.15+ 127.0.0.1:60732]
I0416 21:36:00.376562       1 reflector.go:384] k8s.io/client-go/informers/factory.go:133: Watch close - *v1.PersistentVolume total 0 items received
I0416 21:36:03.709067       1 scheduling_queue.go:895] About to try and schedule pod default/linux-ubuntu-5dbcdfff9d-zl2vx
I0416 21:36:03.709093       1 scheduler.go:454] Attempting to schedule pod: default/linux-ubuntu-5dbcdfff9d-zl2vx
I0416 21:36:03.713285       1 scheduler_binder.go:255] AssumePodVolumes for pod "default/linux-ubuntu-5dbcdfff9d-zl2vx", node "e2e-test-peterhornyack-minion-group-06gd"
I0416 21:36:03.713305       1 scheduler_binder.go:265] AssumePodVolumes for pod "default/linux-ubuntu-5dbcdfff9d-zl2vx", node "e2e-test-peterhornyack-minion-group-06gd": all PVCs bound and nothing to do
I0416 21:36:03.713389       1 factory.go:734] Attempting to bind linux-ubuntu-5dbcdfff9d-zl2vx to e2e-test-peterhornyack-minion-group-06gd
I0416 21:36:03.733449       1 cache.go:643] Couldn't expire cache for pod default/linux-ubuntu-5dbcdfff9d-zl2vx. Binding is still in progress.
I0416 21:36:03.737619       1 scheduler.go:575] pod default/linux-ubuntu-5dbcdfff9d-zl2vx is bound successfully on node e2e-test-peterhornyack-minion-group-06gd, 3 nodes evaluated, 1 nodes were found feasible
I0416 21:36:06.470580       1 wrap.go:47] GET /healthz: (75.451µs) 200 [kube-probe/1.15+ 127.0.0.1:60766]
I0416 21:36:14.611632       1 scheduling_queue.go:895] About to try and schedule pod default/windows-nettest-944bd6d8d-x7mcl
I0416 21:36:14.611646       1 scheduler.go:454] Attempting to schedule pod: default/windows-nettest-944bd6d8d-x7mcl
I0416 21:36:14.612959       1 scheduler_binder.go:255] AssumePodVolumes for pod "default/windows-nettest-944bd6d8d-x7mcl", node "e2e-test-peterhornyack-windows-node-group-31ht"
I0416 21:36:14.612987       1 scheduler_binder.go:265] AssumePodVolumes for pod "default/windows-nettest-944bd6d8d-x7mcl", node "e2e-test-peterhornyack-windows-node-group-31ht": all PVCs bound and nothing to do
I0416 21:36:14.613038       1 factory.go:734] Attempting to bind windows-nettest-944bd6d8d-x7mcl to e2e-test-peterhornyack-windows-node-group-31ht
I0416 21:36:14.635774       1 scheduler.go:575] pod default/windows-nettest-944bd6d8d-x7mcl is bound successfully on node e2e-test-peterhornyack-windows-node-group-31ht, 3 nodes evaluated, 1 nodes were found feasible
I0416 21:36:16.471470       1 wrap.go:47] GET /healthz: (80.883µs) 200 [kube-probe/1.15+ 127.0.0.1:60800]
I0416 21:36:25.562341       1 scheduling_queue.go:895] About to try and schedule pod default/windows-powershell-7c9878bbfd-fwlj7
I0416 21:36:25.562354       1 scheduler.go:454] Attempting to schedule pod: default/windows-powershell-7c9878bbfd-fwlj7
I0416 21:36:25.562582       1 scheduler_binder.go:255] AssumePodVolumes for pod "default/windows-powershell-7c9878bbfd-fwlj7", node "e2e-test-peterhornyack-windows-node-group-31ht"
I0416 21:36:25.562593       1 scheduler_binder.go:265] AssumePodVolumes for pod "default/windows-powershell-7c9878bbfd-fwlj7", node "e2e-test-peterhornyack-windows-node-group-31ht": all PVCs bound and nothing to do
I0416 21:36:25.562657       1 factory.go:734] Attempting to bind windows-powershell-7c9878bbfd-fwlj7 to e2e-test-peterhornyack-windows-node-group-31ht
I0416 21:36:25.578510       1 scheduler.go:575] pod default/windows-powershell-7c9878bbfd-fwlj7 is bound successfully on node e2e-test-peterhornyack-windows-node-group-31ht, 3 nodes evaluated, 1 nodes were found feasible
I0416 21:36:26.471491       1 wrap.go:47] GET /healthz: (197.097µs) 200 [kube-probe/1.15+ 127.0.0.1:60832]
I0416 21:36:36.468943       1 wrap.go:47] GET /healthz: (81.082µs) 200 [kube-probe/1.15+ 127.0.0.1:60866]
I0416 21:36:46.468637       1 wrap.go:47] GET /healthz: (73.721µs) 200 [kube-probe/1.15+ 127.0.0.1:60918]
I0416 21:36:49.393985       1 reflector.go:384] k8s.io/client-go/informers/factory.go:133: Watch close - *v1.Node total 31 items received
I0416 21:36:56.470044       1 wrap.go:47] GET /healthz: (75.674µs) 200 [kube-probe/1.15+ 127.0.0.1:60954]
I0416 21:37:06.468661       1 wrap.go:47] GET /healthz: (77.313µs) 200 [kube-probe/1.15+ 127.0.0.1:60992]
I0416 21:37:16.468735       1 wrap.go:47] GET /healthz: (85.364µs) 200 [kube-probe/1.15+ 127.0.0.1:32798]
I0416 21:37:26.469062       1 wrap.go:47] GET /healthz: (71.842µs) 200 [kube-probe/1.15+ 127.0.0.1:32834]
I0416 21:37:36.468718       1 wrap.go:47] GET /healthz: (94.346µs) 200 [kube-probe/1.15+ 127.0.0.1:32872]
I0416 21:37:46.469045       1 wrap.go:47] GET /healthz: (73.005µs) 200 [kube-probe/1.15+ 127.0.0.1:32928]
I0416 21:37:56.468854       1 wrap.go:47] GET /healthz: (70.53µs) 200 [kube-probe/1.15+ 127.0.0.1:32966]
I0416 21:38:06.468802       1 wrap.go:47] GET /healthz: (78.461µs) 200 [kube-probe/1.15+ 127.0.0.1:33000]
I0416 21:38:16.469034       1 wrap.go:47] GET /healthz: (102.131µs) 200 [kube-probe/1.15+ 127.0.0.1:33034]
I0416 21:38:26.468790       1 wrap.go:47] GET /healthz: (87.73µs) 200 [kube-probe/1.15+ 127.0.0.1:33068]
I0416 21:38:31.396442       1 reflector.go:384] k8s.io/client-go/informers/factory.go:133: Watch close - *v1.StatefulSet total 0 items received
I0416 21:38:36.468940       1 wrap.go:47] GET /healthz: (124.965µs) 200 [kube-probe/1.15+ 127.0.0.1:33102]
I0416 21:38:46.468651       1 wrap.go:47] GET /healthz: (87.228µs) 200 [kube-probe/1.15+ 127.0.0.1:33154]
I0416 21:38:56.468929       1 wrap.go:47] GET /healthz: (74.491µs) 200 [kube-probe/1.15+ 127.0.0.1:33190]
I0416 21:39:06.468940       1 wrap.go:47] GET /healthz: (75.741µs) 200 [kube-probe/1.15+ 127.0.0.1:33224]
I0416 21:39:16.468787       1 wrap.go:47] GET /healthz: (77.61µs) 200 [kube-probe/1.15+ 127.0.0.1:33256]
I0416 21:39:26.468831       1 wrap.go:47] GET /healthz: (75.166µs) 200 [kube-probe/1.15+ 127.0.0.1:33290]
I0416 21:39:35.391958       1 reflector.go:384] k8s.io/client-go/informers/factory.go:133: Watch close - *v1beta1.PodDisruptionBudget total 0 items received
I0416 21:39:36.468633       1 wrap.go:47] GET /healthz: (69.867µs) 200 [kube-probe/1.15+ 127.0.0.1:33324]
I0416 21:39:46.471661       1 wrap.go:47] GET /healthz: (78.546µs) 200 [kube-probe/1.15+ 127.0.0.1:33376]
I0416 21:39:56.468831       1 wrap.go:47] GET /healthz: (72.598µs) 200 [kube-probe/1.15+ 127.0.0.1:33412]
I0416 21:39:58.393420       1 reflector.go:384] k8s.io/client-go/informers/factory.go:133: Watch close - *v1.StorageClass total 0 items received
I0416 21:40:06.397435       1 reflector.go:384] cmd/kube-scheduler/app/server.go:223: Watch close - *v1.Pod total 32 items received
I0416 21:40:06.468859       1 wrap.go:47] GET /healthz: (72.254µs) 200 [kube-probe/1.15+ 127.0.0.1:33446]
I0416 21:40:16.469174       1 wrap.go:47] GET /healthz: (73.275µs) 200 [kube-probe/1.15+ 127.0.0.1:33478]
I0416 21:40:26.469283       1 wrap.go:47] GET /healthz: (88.516µs) 200 [kube-probe/1.15+ 127.0.0.1:33512]
I0416 21:40:36.468746       1 wrap.go:47] GET /healthz: (70.377µs) 200 [kube-probe/1.15+ 127.0.0.1:33546]
I0416 21:40:46.468866       1 wrap.go:47] GET /healthz: (74.552µs) 200 [kube-probe/1.15+ 127.0.0.1:33598]
I0416 21:40:56.468697       1 wrap.go:47] GET /healthz: (63.32µs) 200 [kube-probe/1.15+ 127.0.0.1:33634]
I0416 21:41:06.468878       1 wrap.go:47] GET /healthz: (73.904µs) 200 [kube-probe/1.15+ 127.0.0.1:33668]
I0416 21:41:16.468797       1 wrap.go:47] GET /healthz: (70.281µs) 200 [kube-probe/1.15+ 127.0.0.1:33700]
I0416 21:41:26.468732       1 wrap.go:47] GET /healthz: (66.256µs) 200 [kube-probe/1.15+ 127.0.0.1:33734]
I0416 21:41:29.380593       1 reflector.go:384] k8s.io/client-go/informers/factory.go:133: Watch close - *v1.ReplicaSet total 20 items received
I0416 21:41:36.468875       1 wrap.go:47] GET /healthz: (70.448µs) 200 [kube-probe/1.15+ 127.0.0.1:33768]
I0416 21:41:46.468850       1 wrap.go:47] GET /healthz: (72.88µs) 200 [kube-probe/1.15+ 127.0.0.1:33820]
I0416 21:41:51.294468       1 reflector.go:384] k8s.io/client-go/informers/factory.go:133: Watch close - *v1.Service total 0 items received
I0416 21:41:56.473307       1 wrap.go:47] GET /healthz: (90.639µs) 200 [kube-probe/1.15+ 127.0.0.1:33856]
I0416 21:42:06.469672       1 wrap.go:47] GET /healthz: (71.83µs) 200 [kube-probe/1.15+ 127.0.0.1:33894]
I0416 21:42:16.469650       1 wrap.go:47] GET /healthz: (71.936µs) 200 [kube-probe/1.15+ 127.0.0.1:33926]
I0416 21:42:26.468842       1 wrap.go:47] GET /healthz: (77.356µs) 200 [kube-probe/1.15+ 127.0.0.1:33960]
I0416 21:42:36.468772       1 wrap.go:47] GET /healthz: (73.557µs) 200 [kube-probe/1.15+ 127.0.0.1:33994]
I0416 21:42:46.468714       1 wrap.go:47] GET /healthz: (80.692µs) 200 [kube-probe/1.15+ 127.0.0.1:34046]
I0416 21:42:56.468915       1 wrap.go:47] GET /healthz: (63.515µs) 200 [kube-probe/1.15+ 127.0.0.1:34082]
I0416 21:43:06.468724       1 wrap.go:47] GET /healthz: (71.208µs) 200 [kube-probe/1.15+ 127.0.0.1:34116]
I0416 21:43:11.380854       1 reflector.go:384] k8s.io/client-go/informers/factory.go:133: Watch close - *v1.PersistentVolumeClaim total 0 items received
I0416 21:43:16.468786       1 wrap.go:47] GET /healthz: (78.009µs) 200 [kube-probe/1.15+ 127.0.0.1:34148]
I0416 21:43:26.468914       1 wrap.go:47] GET /healthz: (74.301µs) 200 [kube-probe/1.15+ 127.0.0.1:34180]
I0416 21:43:36.468658       1 wrap.go:47] GET /healthz: (77.419µs) 200 [kube-probe/1.15+ 127.0.0.1:34216]
I0416 21:43:46.469062       1 wrap.go:47] GET /healthz: (77.783µs) 200 [kube-probe/1.15+ 127.0.0.1:34268]
I0416 21:43:56.470565       1 wrap.go:47] GET /healthz: (74.446µs) 200 [kube-probe/1.15+ 127.0.0.1:34304]
I0416 21:44:01.285716       1 reflector.go:384] k8s.io/client-go/informers/factory.go:133: Watch close - *v1.ReplicationController total 0 items received
I0416 21:44:06.469307       1 wrap.go:47] GET /healthz: (86.724µs) 200 [kube-probe/1.15+ 127.0.0.1:34338]
I0416 21:44:16.468739       1 wrap.go:47] GET /healthz: (77.994µs) 200 [kube-probe/1.15+ 127.0.0.1:34370]
I0416 21:44:26.468788       1 wrap.go:47] GET /healthz: (93.076µs) 200 [kube-probe/1.15+ 127.0.0.1:34402]
I0416 21:44:36.468812       1 wrap.go:47] GET /healthz: (78.071µs) 200 [kube-probe/1.15+ 127.0.0.1:34438]
I0416 21:44:46.468885       1 wrap.go:47] GET /healthz: (83.152µs) 200 [kube-probe/1.15+ 127.0.0.1:34634]
I0416 21:44:56.468943       1 wrap.go:47] GET /healthz: (129.232µs) 200 [kube-probe/1.15+ 127.0.0.1:34670]
I0416 21:45:06.470586       1 wrap.go:47] GET /healthz: (71.345µs) 200 [kube-probe/1.15+ 127.0.0.1:34704]
I0416 21:45:16.469608       1 wrap.go:47] GET /healthz: (88.667µs) 200 [kube-probe/1.15+ 127.0.0.1:34736]
I0416 21:45:26.468823       1 wrap.go:47] GET /healthz: (74.385µs) 200 [kube-probe/1.15+ 127.0.0.1:34768]
I0416 21:45:36.468870       1 wrap.go:47] GET /healthz: (75.04µs) 200 [kube-probe/1.15+ 127.0.0.1:34804]
I0416 21:45:46.468747       1 wrap.go:47] GET /healthz: (70.707µs) 200 [kube-probe/1.15+ 127.0.0.1:34856]
I0416 21:45:52.379031       1 reflector.go:384] k8s.io/client-go/informers/factory.go:133: Watch close - *v1.PersistentVolume total 0 items received
I0416 21:45:56.469290       1 wrap.go:47] GET /healthz: (103.604µs) 200 [kube-probe/1.15+ 127.0.0.1:34892]
I0416 21:46:05.396477       1 reflector.go:384] k8s.io/client-go/informers/factory.go:133: Watch close - *v1.Node total 36 items received
I0416 21:46:06.468704       1 wrap.go:47] GET /healthz: (79.805µs) 200 [kube-probe/1.15+ 127.0.0.1:34926]
I0416 21:46:16.468674       1 wrap.go:47] GET /healthz: (79.879µs) 200 [kube-probe/1.15+ 127.0.0.1:34958]
I0416 21:46:26.468677       1 wrap.go:47] GET /healthz: (81.531µs) 200 [kube-probe/1.15+ 127.0.0.1:34990]
I0416 21:46:30.382815       1 reflector.go:384] k8s.io/client-go/informers/factory.go:133: Watch close - *v1.ReplicaSet total 0 items received
I0416 21:46:36.468736       1 wrap.go:47] GET /healthz: (73.767µs) 200 [kube-probe/1.15+ 127.0.0.1:35026]
I0416 21:46:46.468946       1 wrap.go:47] GET /healthz: (74.667µs) 200 [kube-probe/1.15+ 127.0.0.1:35078]
I0416 21:46:56.469045       1 wrap.go:47] GET /healthz: (69.285µs) 200 [kube-probe/1.15+ 127.0.0.1:35114]
I0416 21:47:06.468768       1 wrap.go:47] GET /healthz: (75.371µs) 200 [kube-probe/1.15+ 127.0.0.1:35148]
I0416 21:47:16.468740       1 wrap.go:47] GET /healthz: (70.669µs) 200 [kube-probe/1.15+ 127.0.0.1:35180]
I0416 21:47:26.468786       1 wrap.go:47] GET /healthz: (65.302µs) 200 [kube-probe/1.15+ 127.0.0.1:35212]
I0416 21:47:27.398662       1 reflector.go:384] k8s.io/client-go/informers/factory.go:133: Watch close - *v1.StatefulSet total 0 items received
I0416 21:47:34.296924       1 reflector.go:384] k8s.io/client-go/informers/factory.go:133: Watch close - *v1.Service total 0 items received
I0416 21:47:36.468729       1 wrap.go:47] GET /healthz: (77.124µs) 200 [kube-probe/1.15+ 127.0.0.1:35248]
I0416 21:47:46.468959       1 wrap.go:47] GET /healthz: (76.733µs) 200 [kube-probe/1.15+ 127.0.0.1:35300]
I0416 21:47:56.468737       1 wrap.go:47] GET /healthz: (75.91µs) 200 [kube-probe/1.15+ 127.0.0.1:35336]
I0416 21:47:59.395674       1 reflector.go:384] k8s.io/client-go/informers/factory.go:133: Watch close - *v1.StorageClass total 0 items received
I0416 21:48:06.468541       1 wrap.go:47] GET /healthz: (75.73µs) 200 [kube-probe/1.15+ 127.0.0.1:35370]
I0416 21:48:15.399839       1 reflector.go:384] cmd/kube-scheduler/app/server.go:223: Watch close - *v1.Pod total 0 items received
I0416 21:48:16.470073       1 wrap.go:47] GET /healthz: (77.532µs) 200 [kube-probe/1.15+ 127.0.0.1:35402]
I0416 21:48:26.469678       1 wrap.go:47] GET /healthz: (73.879µs) 200 [kube-probe/1.15+ 127.0.0.1:35438]
I0416 21:48:36.468975       1 wrap.go:47] GET /healthz: (74.051µs) 200 [kube-probe/1.15+ 127.0.0.1:35472]
I0416 21:48:46.471464       1 wrap.go:47] GET /healthz: (75.365µs) 200 [kube-probe/1.15+ 127.0.0.1:35526]
I0416 21:48:52.394526       1 reflector.go:384] k8s.io/client-go/informers/factory.go:133: Watch close - *v1beta1.PodDisruptionBudget total 0 items received
I0416 21:48:56.468813       1 wrap.go:47] GET /healthz: (74.088µs) 200 [kube-probe/1.15+ 127.0.0.1:35562]
I0416 21:49:06.470047       1 wrap.go:47] GET /healthz: (73.71µs) 200 [kube-probe/1.15+ 127.0.0.1:35596]
I0416 21:49:16.469696       1 wrap.go:47] GET /healthz: (77.662µs) 200 [kube-probe/1.15+ 127.0.0.1:35630]
I0416 21:49:26.469066       1 wrap.go:47] GET /healthz: (75.011µs) 200 [kube-probe/1.15+ 127.0.0.1:35662]
I0416 21:49:36.468672       1 wrap.go:47] GET /healthz: (74.616µs) 200 [kube-probe/1.15+ 127.0.0.1:35696]
I0416 21:49:46.468667       1 wrap.go:47] GET /healthz: (75.647µs) 200 [kube-probe/1.15+ 127.0.0.1:35750]
I0416 21:49:56.468843       1 wrap.go:47] GET /healthz: (81.169µs) 200 [kube-probe/1.15+ 127.0.0.1:35786]
I0416 21:50:06.469545       1 wrap.go:47] GET /healthz: (74.74µs) 200 [kube-probe/1.15+ 127.0.0.1:35820]
I0416 21:50:16.474478       1 wrap.go:47] GET /healthz: (97.403µs) 200 [kube-probe/1.15+ 127.0.0.1:35852]
I0416 21:50:26.469024       1 wrap.go:47] GET /healthz: (74.319µs) 200 [kube-probe/1.15+ 127.0.0.1:35884]
I0416 21:50:36.468822       1 wrap.go:47] GET /healthz: (74.054µs) 200 [kube-probe/1.15+ 127.0.0.1:35918]
I0416 21:50:46.469554       1 wrap.go:47] GET /healthz: (75.028µs) 200 [kube-probe/1.15+ 127.0.0.1:35972]
I0416 21:50:56.468708       1 wrap.go:47] GET /healthz: (58.585µs) 200 [kube-probe/1.15+ 127.0.0.1:36008]
I0416 21:51:06.468836       1 wrap.go:47] GET /healthz: (90.528µs) 200 [kube-probe/1.15+ 127.0.0.1:36042]
I0416 21:51:07.297699       1 reflector.go:384] k8s.io/client-go/informers/factory.go:133: Watch close - *v1.ReplicationController total 0 items received
I0416 21:51:07.383388       1 reflector.go:384] k8s.io/client-go/informers/factory.go:133: Watch close - *v1.PersistentVolumeClaim total 0 items received
I0416 21:51:16.468664       1 wrap.go:47] GET /healthz: (77.599µs) 200 [kube-probe/1.15+ 127.0.0.1:36074]
I0416 21:51:26.469205       1 wrap.go:47] GET /healthz: (76.565µs) 200 [kube-probe/1.15+ 127.0.0.1:36106]
I0416 21:51:36.468625       1 wrap.go:47] GET /healthz: (77.055µs) 200 [kube-probe/1.15+ 127.0.0.1:36140]
I0416 21:51:46.468669       1 wrap.go:47] GET /healthz: (74.269µs) 200 [kube-probe/1.15+ 127.0.0.1:36194]
I0416 21:51:52.383421       1 reflector.go:384] k8s.io/client-go/informers/factory.go:133: Watch close - *v1.PersistentVolume total 0 items received
I0416 21:51:56.468847       1 wrap.go:47] GET /healthz: (78.213µs) 200 [kube-probe/1.15+ 127.0.0.1:36230]
I0416 21:52:06.472043       1 wrap.go:47] GET /healthz: (70.661µs) 200 [kube-probe/1.15+ 127.0.0.1:36264]
I0416 21:52:16.468591       1 wrap.go:47] GET /healthz: (69.488µs) 200 [kube-probe/1.15+ 127.0.0.1:36296]
I0416 21:52:26.468843       1 wrap.go:47] GET /healthz: (98.863µs) 200 [kube-probe/1.15+ 127.0.0.1:36330]
I0416 21:52:36.468822       1 wrap.go:47] GET /healthz: (72.607µs) 200 [kube-probe/1.15+ 127.0.0.1:36364]
I0416 21:52:46.469978       1 wrap.go:47] GET /healthz: (75.942µs) 200 [kube-probe/1.15+ 127.0.0.1:36418]
I0416 21:52:56.469336       1 wrap.go:47] GET /healthz: (114.566µs) 200 [kube-probe/1.15+ 127.0.0.1:36454]
I0416 21:53:06.468952       1 wrap.go:47] GET /healthz: (92.838µs) 200 [kube-probe/1.15+ 127.0.0.1:36488]
I0416 21:53:16.469019       1 wrap.go:47] GET /healthz: (76.974µs) 200 [kube-probe/1.15+ 127.0.0.1:36520]
I0416 21:53:26.470601       1 wrap.go:47] GET /healthz: (74.424µs) 200 [kube-probe/1.15+ 127.0.0.1:36552]
I0416 21:53:36.468862       1 wrap.go:47] GET /healthz: (58.183µs) 200 [kube-probe/1.15+ 127.0.0.1:36586]
I0416 21:53:46.469571       1 wrap.go:47] GET /healthz: (78.404µs) 200 [kube-probe/1.15+ 127.0.0.1:36638]
I0416 21:53:56.469054       1 wrap.go:47] GET /healthz: (79.36µs) 200 [kube-probe/1.15+ 127.0.0.1:36676]
I0416 21:54:06.469524       1 wrap.go:47] GET /healthz: (75.902µs) 200 [kube-probe/1.15+ 127.0.0.1:36710]
I0416 21:54:16.468908       1 wrap.go:47] GET /healthz: (83.537µs) 200 [kube-probe/1.15+ 127.0.0.1:36742]
I0416 21:54:26.468587       1 wrap.go:47] GET /healthz: (84.156µs) 200 [kube-probe/1.15+ 127.0.0.1:36774]
I0416 21:54:27.401076       1 reflector.go:384] k8s.io/client-go/informers/factory.go:133: Watch close - *v1.StatefulSet total 0 items received
I0416 21:54:30.385138       1 reflector.go:384] k8s.io/client-go/informers/factory.go:133: Watch close - *v1.ReplicaSet total 0 items received
I0416 21:54:36.469006       1 wrap.go:47] GET /healthz: (81.855µs) 200 [kube-probe/1.15+ 127.0.0.1:36808]
I0416 21:54:38.401987       1 reflector.go:384] cmd/kube-scheduler/app/server.go:223: Watch close - *v1.Pod total 0 items received
I0416 21:54:46.468754       1 wrap.go:47] GET /healthz: (93.724µs) 200 [kube-probe/1.15+ 127.0.0.1:36860]
I0416 21:54:47.401465       1 reflector.go:384] k8s.io/client-go/informers/factory.go:133: Watch close - *v1.Node total 36 items received
I0416 21:54:56.470005       1 wrap.go:47] GET /healthz: (71.869µs) 200 [kube-probe/1.15+ 127.0.0.1:36898]
I0416 21:55:06.468655       1 wrap.go:47] GET /healthz: (75.358µs) 200 [kube-probe/1.15+ 127.0.0.1:36932]
I0416 21:55:16.468654       1 wrap.go:47] GET /healthz: (89.255µs) 200 [kube-probe/1.15+ 127.0.0.1:36964]
I0416 21:55:26.468346       1 wrap.go:47] GET /healthz: (104.024µs) 200 [kube-probe/1.15+ 127.0.0.1:36996]
I0416 21:55:36.468691       1 wrap.go:47] GET /healthz: (73.505µs) 200 [kube-probe/1.15+ 127.0.0.1:37030]
I0416 21:55:46.468948       1 wrap.go:47] GET /healthz: (74.278µs) 200 [kube-probe/1.15+ 127.0.0.1:37082]
I0416 21:55:56.469605       1 wrap.go:47] GET /healthz: (68.501µs) 200 [kube-probe/1.15+ 127.0.0.1:37120]
I0416 21:56:06.468702       1 wrap.go:47] GET /healthz: (81.866µs) 200 [kube-probe/1.15+ 127.0.0.1:37154]
I0416 21:56:16.468588       1 wrap.go:47] GET /healthz: (61.756µs) 200 [kube-probe/1.15+ 127.0.0.1:37186]
I0416 21:56:26.469874       1 wrap.go:47] GET /healthz: (70.068µs) 200 [kube-probe/1.15+ 127.0.0.1:37218]
I0416 21:56:36.468578       1 wrap.go:47] GET /healthz: (68.655µs) 200 [kube-probe/1.15+ 127.0.0.1:37252]
I0416 21:56:46.469039       1 wrap.go:47] GET /healthz: (72.894µs) 200 [kube-probe/1.15+ 127.0.0.1:37306]
I0416 21:56:56.468755       1 wrap.go:47] GET /healthz: (65.234µs) 200 [kube-probe/1.15+ 127.0.0.1:37344]
I0416 21:57:06.468922       1 wrap.go:47] GET /healthz: (81.22µs) 200 [kube-probe/1.15+ 127.0.0.1:37378]
I0416 21:57:16.468964       1 wrap.go:47] GET /healthz: (71.599µs) 200 [kube-probe/1.15+ 127.0.0.1:37410]
I0416 21:57:26.469383       1 wrap.go:47] GET /healthz: (83.803µs) 200 [kube-probe/1.15+ 127.0.0.1:37442]
I0416 21:57:29.299567       1 reflector.go:384] k8s.io/client-go/informers/factory.go:133: Watch close - *v1.Service total 0 items received
I0416 21:57:30.397135       1 reflector.go:384] k8s.io/client-go/informers/factory.go:133: Watch close - *v1beta1.PodDisruptionBudget total 0 items received
I0416 21:57:33.300013       1 reflector.go:384] k8s.io/client-go/informers/factory.go:133: Watch close - *v1.ReplicationController total 0 items received
I0416 21:57:36.468613       1 wrap.go:47] GET /healthz: (76.364µs) 200 [kube-probe/1.15+ 127.0.0.1:37476]
I0416 21:57:46.468962       1 wrap.go:47] GET /healthz: (78.205µs) 200 [kube-probe/1.15+ 127.0.0.1:37528]
I0416 21:57:50.399506       1 reflector.go:384] k8s.io/client-go/informers/factory.go:133: Watch close - *v1.StorageClass total 0 items received
I0416 21:57:56.468642       1 wrap.go:47] GET /healthz: (61.223µs) 200 [kube-probe/1.15+ 127.0.0.1:37566]
I0416 21:58:06.468759       1 wrap.go:47] GET /healthz: (83.391µs) 200 [kube-probe/1.15+ 127.0.0.1:37600]
I0416 21:58:16.468751       1 wrap.go:47] GET /healthz: (80.639µs) 200 [kube-probe/1.15+ 127.0.0.1:37632]
I0416 21:58:26.469410       1 wrap.go:47] GET /healthz: (99.81µs) 200 [kube-probe/1.15+ 127.0.0.1:37664]
I0416 21:58:36.468759       1 wrap.go:47] GET /healthz: (74.547µs) 200 [kube-probe/1.15+ 127.0.0.1:37698]
I0416 21:58:42.385618       1 reflector.go:384] k8s.io/client-go/informers/factory.go:133: Watch close - *v1.PersistentVolume total 0 items received
I0416 21:58:46.468877       1 wrap.go:47] GET /healthz: (87.443µs) 200 [kube-probe/1.15+ 127.0.0.1:37750]
I0416 21:58:56.468723       1 wrap.go:47] GET /healthz: (62.859µs) 200 [kube-probe/1.15+ 127.0.0.1:37786]
I0416 21:59:06.468750       1 wrap.go:47] GET /healthz: (74.323µs) 200 [kube-probe/1.15+ 127.0.0.1:37822]
I0416 21:59:16.468677       1 wrap.go:47] GET /healthz: (78.032µs) 200 [kube-probe/1.15+ 127.0.0.1:37856]
I0416 21:59:26.468692       1 wrap.go:47] GET /healthz: (77.96µs) 200 [kube-probe/1.15+ 127.0.0.1:37888]
I0416 21:59:35.385685       1 reflector.go:384] k8s.io/client-go/informers/factory.go:133: Watch close - *v1.PersistentVolumeClaim total 0 items received
I0416 21:59:36.468910       1 wrap.go:47] GET /healthz: (71.875µs) 200 [kube-probe/1.15+ 127.0.0.1:37922]
I0416 21:59:46.468733       1 wrap.go:47] GET /healthz: (73.165µs) 200 [kube-probe/1.15+ 127.0.0.1:37974]
I0416 21:59:56.468854       1 wrap.go:47] GET /healthz: (79.114µs) 200 [kube-probe/1.15+ 127.0.0.1:38010]
I0416 22:00:06.468825       1 wrap.go:47] GET /healthz: (61.273µs) 200 [kube-probe/1.15+ 127.0.0.1:38050]
I0416 22:00:16.469681       1 wrap.go:47] GET /healthz: (74.242µs) 200 [kube-probe/1.15+ 127.0.0.1:38084]
I0416 22:00:21.404394       1 reflector.go:384] cmd/kube-scheduler/app/server.go:223: Watch close - *v1.Pod total 0 items received
I0416 22:00:26.469756       1 wrap.go:47] GET /healthz: (87.44µs) 200 [kube-probe/1.15+ 127.0.0.1:38116]
I0416 22:00:36.469038       1 wrap.go:47] GET /healthz: (86.826µs) 200 [kube-probe/1.15+ 127.0.0.1:38150]
I0416 22:00:46.469597       1 wrap.go:47] GET /healthz: (964.178µs) 200 [kube-probe/1.15+ 127.0.0.1:38202]
I0416 22:00:52.387400       1 reflector.go:384] k8s.io/client-go/informers/factory.go:133: Watch close - *v1.ReplicaSet total 0 items received
I0416 22:00:56.468518       1 wrap.go:47] GET /healthz: (77.27µs) 200 [kube-probe/1.15+ 127.0.0.1:38238]
I0416 22:01:06.468689       1 wrap.go:47] GET /healthz: (74.364µs) 200 [kube-probe/1.15+ 127.0.0.1:38276]
I0416 22:01:08.403298       1 reflector.go:384] k8s.io/client-go/informers/factory.go:133: Watch close - *v1.StatefulSet total 0 items received
I0416 22:01:16.469342       1 wrap.go:47] GET /healthz: (166.301µs) 200 [kube-probe/1.15+ 127.0.0.1:38308]
I0416 22:01:26.468592       1 wrap.go:47] GET /healthz: (63.481µs) 200 [kube-probe/1.15+ 127.0.0.1:38340]
I0416 22:01:36.468988       1 wrap.go:47] GET /healthz: (78.571µs) 200 [kube-probe/1.15+ 127.0.0.1:38374]
I0416 22:01:46.468669       1 wrap.go:47] GET /healthz: (74.085µs) 200 [kube-probe/1.15+ 127.0.0.1:38428]
I0416 22:01:56.468766       1 wrap.go:47] GET /healthz: (81.536µs) 200 [kube-probe/1.15+ 127.0.0.1:38480]
I0416 22:02:02.404696       1 reflector.go:384] k8s.io/client-go/informers/factory.go:133: Watch close - *v1.Node total 28 items received
I0416 22:02:06.468672       1 wrap.go:47] GET /healthz: (68.93µs) 200 [kube-probe/1.15+ 127.0.0.1:38516]
I0416 22:02:16.468594       1 wrap.go:47] GET /healthz: (93.258µs) 200 [kube-probe/1.15+ 127.0.0.1:38548]
I0416 22:02:26.468989       1 wrap.go:47] GET /healthz: (73.172µs) 200 [kube-probe/1.15+ 127.0.0.1:38580]
I0416 22:02:36.468570       1 wrap.go:47] GET /healthz: (68.336µs) 200 [kube-probe/1.15+ 127.0.0.1:38614]
I0416 22:02:46.470760       1 wrap.go:47] GET /healthz: (80.233µs) 200 [kube-probe/1.15+ 127.0.0.1:38666]
I0416 22:02:56.468917       1 wrap.go:47] GET /healthz: (70.733µs) 200 [kube-probe/1.15+ 127.0.0.1:38702]
I0416 22:03:06.468707       1 wrap.go:47] GET /healthz: (72.71µs) 200 [kube-probe/1.15+ 127.0.0.1:38738]
I0416 22:03:16.468572       1 wrap.go:47] GET /healthz: (169.697µs) 200 [kube-probe/1.15+ 127.0.0.1:38776]
I0416 22:03:26.468655       1 wrap.go:47] GET /healthz: (159.27µs) 200 [kube-probe/1.15+ 127.0.0.1:38812]
I0416 22:03:36.469082       1 wrap.go:47] GET /healthz: (80.701µs) 200 [kube-probe/1.15+ 127.0.0.1:38848]
I0416 22:03:46.468762       1 wrap.go:47] GET /healthz: (114.808µs) 200 [kube-probe/1.15+ 127.0.0.1:38900]
I0416 22:03:56.469349       1 wrap.go:47] GET /healthz: (71.244µs) 200 [kube-probe/1.15+ 127.0.0.1:38936]
I0416 22:04:06.468767       1 wrap.go:47] GET /healthz: (84.504µs) 200 [kube-probe/1.15+ 127.0.0.1:38970]
I0416 22:04:16.470309       1 wrap.go:47] GET /healthz: (84.273µs) 200 [kube-probe/1.15+ 127.0.0.1:39006]
I0416 22:04:26.468522       1 wrap.go:47] GET /healthz: (106.037µs) 200 [kube-probe/1.15+ 127.0.0.1:39038]
I0416 22:04:36.470498       1 wrap.go:47] GET /healthz: (74.765µs) 200 [kube-probe/1.15+ 127.0.0.1:39072]
I0416 22:04:46.469578       1 wrap.go:47] GET /healthz: (75.531µs) 200 [kube-probe/1.15+ 127.0.0.1:39124]
I0416 22:04:56.400689       1 reflector.go:384] k8s.io/client-go/informers/factory.go:133: Watch close - *v1beta1.PodDisruptionBudget total 0 items received
I0416 22:04:56.469561       1 wrap.go:47] GET /healthz: (67.635µs) 200 [kube-probe/1.15+ 127.0.0.1:39160]
I0416 22:05:06.468914       1 wrap.go:47] GET /healthz: (62.835µs) 200 [kube-probe/1.15+ 127.0.0.1:39194]
I0416 22:05:14.301704       1 reflector.go:384] k8s.io/client-go/informers/factory.go:133: Watch close - *v1.Service total 0 items received
I0416 22:05:16.468588       1 wrap.go:47] GET /healthz: (81.748µs) 200 [kube-probe/1.15+ 127.0.0.1:39228]
I0416 22:05:26.468623       1 wrap.go:47] GET /healthz: (71.398µs) 200 [kube-probe/1.15+ 127.0.0.1:39260]
I0416 22:05:36.468689       1 wrap.go:47] GET /healthz: (73.732µs) 200 [kube-probe/1.15+ 127.0.0.1:39294]
I0416 22:05:46.468649       1 wrap.go:47] GET /healthz: (64.812µs) 200 [kube-probe/1.15+ 127.0.0.1:39346]
I0416 22:05:56.468957       1 wrap.go:47] GET /healthz: (95.566µs) 200 [kube-probe/1.15+ 127.0.0.1:39382]
I0416 22:06:06.468711       1 wrap.go:47] GET /healthz: (78.042µs) 200 [kube-probe/1.15+ 127.0.0.1:39416]
I0416 22:06:15.302610       1 reflector.go:384] k8s.io/client-go/informers/factory.go:133: Watch close - *v1.ReplicationController total 0 items received
I0416 22:06:16.468918       1 wrap.go:47] GET /healthz: (73.603µs) 200 [kube-probe/1.15+ 127.0.0.1:39450]
I0416 22:06:26.468802       1 wrap.go:47] GET /healthz: (86.175µs) 200 [kube-probe/1.15+ 127.0.0.1:39482]
I0416 22:06:36.387625       1 reflector.go:384] k8s.io/client-go/informers/factory.go:133: Watch close - *v1.PersistentVolumeClaim total 0 items received
I0416 22:06:36.468804       1 wrap.go:47] GET /healthz: (67.965µs) 200 [kube-probe/1.15+ 127.0.0.1:39516]
I0416 22:06:44.409082       1 reflector.go:384] k8s.io/client-go/informers/factory.go:133: Watch close - *v1.StorageClass total 0 items received
I0416 22:06:46.468646       1 wrap.go:47] GET /healthz: (57.131µs) 200 [kube-probe/1.15+ 127.0.0.1:39568]
I0416 22:06:56.468710       1 wrap.go:47] GET /healthz: (84.486µs) 200 [kube-probe/1.15+ 127.0.0.1:39604]
I0416 22:07:06.480615       1 wrap.go:47] GET /healthz: (77.664µs) 200 [kube-probe/1.15+ 127.0.0.1:39638]
I0416 22:07:16.468691       1 wrap.go:47] GET /healthz: (85.655µs) 200 [kube-probe/1.15+ 127.0.0.1:39672]
I0416 22:07:26.470152       1 wrap.go:47] GET /healthz: (190.933µs) 200 [kube-probe/1.15+ 127.0.0.1:39704]
I0416 22:07:36.468503       1 wrap.go:47] GET /healthz: (71.519µs) 200 [kube-probe/1.15+ 127.0.0.1:39738]
I0416 22:07:46.468620       1 wrap.go:47] GET /healthz: (73.246µs) 200 [kube-probe/1.15+ 127.0.0.1:39790]
I0416 22:07:47.387846       1 reflector.go:384] k8s.io/client-go/informers/factory.go:133: Watch close - *v1.PersistentVolume total 0 items received
I0416 22:07:56.468741       1 wrap.go:47] GET /healthz: (81.983µs) 200 [kube-probe/1.15+ 127.0.0.1:39828]
I0416 22:07:59.407141       1 reflector.go:384] k8s.io/client-go/informers/factory.go:133: Watch close - *v1.Node total 26 items received
I0416 22:08:06.468812       1 wrap.go:47] GET /healthz: (72.075µs) 200 [kube-probe/1.15+ 127.0.0.1:39862]
I0416 22:08:16.471863       1 wrap.go:47] GET /healthz: (72.792µs) 200 [kube-probe/1.15+ 127.0.0.1:39900]
I0416 22:08:26.468751       1 wrap.go:47] GET /healthz: (75.004µs) 200 [kube-probe/1.15+ 127.0.0.1:39932]
I0416 22:08:30.406384       1 reflector.go:384] cmd/kube-scheduler/app/server.go:223: Watch close - *v1.Pod total 0 items received
I0416 22:08:36.468745       1 wrap.go:47] GET /healthz: (75.591µs) 200 [kube-probe/1.15+ 127.0.0.1:39966]
I0416 22:08:46.468538       1 wrap.go:47] GET /healthz: (72.992µs) 200 [kube-probe/1.15+ 127.0.0.1:40018]
I0416 22:08:56.468786       1 wrap.go:47] GET /healthz: (72.362µs) 200 [kube-probe/1.15+ 127.0.0.1:40054]
I0416 22:09:06.469764       1 wrap.go:47] GET /healthz: (70.535µs) 200 [kube-probe/1.15+ 127.0.0.1:40088]
I0416 22:09:10.389655       1 reflector.go:384] k8s.io/client-go/informers/factory.go:133: Watch close - *v1.ReplicaSet total 0 items received
I0416 22:09:16.468696       1 wrap.go:47] GET /healthz: (84.288µs) 200 [kube-probe/1.15+ 127.0.0.1:40120]
I0416 22:09:26.469305       1 wrap.go:47] GET /healthz: (87.94µs) 200 [kube-probe/1.15+ 127.0.0.1:40154]
I0416 22:09:36.503482       1 wrap.go:47] GET /healthz: (85.846µs) 200 [kube-probe/1.15+ 127.0.0.1:40188]
I0416 22:09:42.012078       1 scheduling_queue.go:895] About to try and schedule pod services-1982/pod1
I0416 22:09:42.013099       1 scheduler.go:454] Attempting to schedule pod: services-1982/pod1
I0416 22:09:42.013368       1 scheduler_binder.go:255] AssumePodVolumes for pod "services-1982/pod1", node "e2e-test-peterhornyack-windows-node-group-31ht"
I0416 22:09:42.013385       1 scheduler_binder.go:265] AssumePodVolumes for pod "services-1982/pod1", node "e2e-test-peterhornyack-windows-node-group-31ht": all PVCs bound and nothing to do
I0416 22:09:42.013447       1 factory.go:734] Attempting to bind pod1 to e2e-test-peterhornyack-windows-node-group-31ht
I0416 22:09:42.020111       1 scheduler.go:575] pod services-1982/pod1 is bound successfully on node e2e-test-peterhornyack-windows-node-group-31ht, 3 nodes evaluated, 1 nodes were found feasible
I0416 22:09:44.405624       1 reflector.go:384] k8s.io/client-go/informers/factory.go:133: Watch close - *v1.StatefulSet total 0 items received
I0416 22:09:46.468732       1 wrap.go:47] GET /healthz: (68.936µs) 200 [kube-probe/1.15+ 127.0.0.1:40246]
I0416 22:09:51.890922       1 scheduling_queue.go:895] About to try and schedule pod services-1982/pod2
I0416 22:09:51.890936       1 scheduler.go:454] Attempting to schedule pod: services-1982/pod2
I0416 22:09:51.891100       1 scheduler_binder.go:255] AssumePodVolumes for pod "services-1982/pod2", node "e2e-test-peterhornyack-windows-node-group-31ht"
I0416 22:09:51.891110       1 scheduler_binder.go:265] AssumePodVolumes for pod "services-1982/pod2", node "e2e-test-peterhornyack-windows-node-group-31ht": all PVCs bound and nothing to do
I0416 22:09:51.891163       1 factory.go:734] Attempting to bind pod2 to e2e-test-peterhornyack-windows-node-group-31ht
I0416 22:09:51.899765       1 scheduler.go:575] pod services-1982/pod2 is bound successfully on node e2e-test-peterhornyack-windows-node-group-31ht, 3 nodes evaluated, 1 nodes were found feasible
I0416 22:09:56.469276       1 wrap.go:47] GET /healthz: (109.087µs) 200 [kube-probe/1.15+ 127.0.0.1:40282]
I0416 22:10:06.468976       1 wrap.go:47] GET /healthz: (141.414µs) 200 [kube-probe/1.15+ 127.0.0.1:40316]
I0416 22:10:16.468982       1 wrap.go:47] GET /healthz: (72.038µs) 200 [kube-probe/1.15+ 127.0.0.1:40348]
I0416 22:10:26.468688       1 wrap.go:47] GET /healthz: (65.336µs) 200 [kube-probe/1.15+ 127.0.0.1:40382]
I0416 22:10:36.469531       1 wrap.go:47] GET /healthz: (80.033µs) 200 [kube-probe/1.15+ 127.0.0.1:40416]
I0416 22:10:46.468797       1 wrap.go:47] GET /healthz: (66.964µs) 200 [kube-probe/1.15+ 127.0.0.1:40468]
I0416 22:10:56.468635       1 wrap.go:47] GET /healthz: (54.018µs) 200 [kube-probe/1.15+ 127.0.0.1:40506]
I0416 22:11:06.468572       1 wrap.go:47] GET /healthz: (67.991µs) 200 [kube-probe/1.15+ 127.0.0.1:40540]
I0416 22:11:16.468832       1 wrap.go:47] GET /healthz: (79.786µs) 200 [kube-probe/1.15+ 127.0.0.1:40576]
I0416 22:11:26.468657       1 wrap.go:47] GET /healthz: (73.489µs) 200 [kube-probe/1.15+ 127.0.0.1:40610]
I0416 22:11:36.468531       1 wrap.go:47] GET /healthz: (73.524µs) 200 [kube-probe/1.15+ 127.0.0.1:40644]
I0416 22:11:42.389854       1 reflector.go:384] k8s.io/client-go/informers/factory.go:133: Watch close - *v1.PersistentVolumeClaim total 0 items received
I0416 22:11:46.468628       1 wrap.go:47] GET /healthz: (99.445µs) 200 [kube-probe/1.15+ 127.0.0.1:40696]
I0416 22:11:56.468930       1 wrap.go:47] GET /healthz: (73.966µs) 200 [kube-probe/1.15+ 127.0.0.1:40732]
I0416 22:12:06.468652       1 wrap.go:47] GET /healthz: (87.262µs) 200 [kube-probe/1.15+ 127.0.0.1:40766]
I0416 22:12:16.468827       1 wrap.go:47] GET /healthz: (73.314µs) 200 [kube-probe/1.15+ 127.0.0.1:40798]
I0416 22:12:19.304844       1 reflector.go:384] k8s.io/client-go/informers/factory.go:133: Watch close - *v1.ReplicationController total 0 items received
I0416 22:12:26.468594       1 wrap.go:47] GET /healthz: (84.418µs) 200 [kube-probe/1.15+ 127.0.0.1:40832]
I0416 22:12:36.468665       1 wrap.go:47] GET /healthz: (74.356µs) 200 [kube-probe/1.15+ 127.0.0.1:40866]
I0416 22:12:46.468683       1 wrap.go:47] GET /healthz: (83.549µs) 200 [kube-probe/1.15+ 127.0.0.1:40918]
I0416 22:12:56.474131       1 wrap.go:47] GET /healthz: (63.269µs) 200 [kube-probe/1.15+ 127.0.0.1:40954]
I0416 22:13:06.468553       1 wrap.go:47] GET /healthz: (71.924µs) 200 [kube-probe/1.15+ 127.0.0.1:40988]
I0416 22:13:16.303982       1 reflector.go:384] k8s.io/client-go/informers/factory.go:133: Watch close - *v1.Service total 2 items received
I0416 22:13:16.468665       1 wrap.go:47] GET /healthz: (75.9µs) 200 [kube-probe/1.15+ 127.0.0.1:41020]
I0416 22:13:26.468783       1 wrap.go:47] GET /healthz: (75.252µs) 200 [kube-probe/1.15+ 127.0.0.1:41054]
I0416 22:13:36.469564       1 wrap.go:47] GET /healthz: (76.977µs) 200 [kube-probe/1.15+ 127.0.0.1:41088]
I0416 22:13:43.408946       1 reflector.go:384] cmd/kube-scheduler/app/server.go:223: Watch close - *v1.Pod total 10 items received
I0416 22:13:46.468884       1 wrap.go:47] GET /healthz: (69.389µs) 200 [kube-probe/1.15+ 127.0.0.1:41140]
I0416 22:13:53.409488       1 reflector.go:384] k8s.io/client-go/informers/factory.go:133: Watch close - *v1.Node total 24 items received
I0416 22:13:56.468906       1 wrap.go:47] GET /healthz: (80.704µs) 200 [kube-probe/1.15+ 127.0.0.1:41176]
I0416 22:14:00.402868       1 reflector.go:384] k8s.io/client-go/informers/factory.go:133: Watch close - *v1beta1.PodDisruptionBudget total 0 items received
I0416 22:14:06.468598       1 wrap.go:47] GET /healthz: (71.072µs) 200 [kube-probe/1.15+ 127.0.0.1:41210]
I0416 22:14:16.468690       1 wrap.go:47] GET /healthz: (82.435µs) 200 [kube-probe/1.15+ 127.0.0.1:41242]
I0416 22:14:26.468967       1 wrap.go:47] GET /healthz: (74.454µs) 200 [kube-probe/1.15+ 127.0.0.1:41274]
I0416 22:14:36.468962       1 wrap.go:47] GET /healthz: (82.327µs) 200 [kube-probe/1.15+ 127.0.0.1:41310]
I0416 22:14:41.392448       1 reflector.go:384] k8s.io/client-go/informers/factory.go:133: Watch close - *v1.ReplicaSet total 0 items received
I0416 22:14:46.468986       1 wrap.go:47] GET /healthz: (95.42µs) 200 [kube-probe/1.15+ 127.0.0.1:41362]
I0416 22:14:56.468804       1 wrap.go:47] GET /healthz: (68.164µs) 200 [kube-probe/1.15+ 127.0.0.1:41398]
I0416 22:15:04.411467       1 reflector.go:384] k8s.io/client-go/informers/factory.go:133: Watch close - *v1.StorageClass total 0 items received
I0416 22:15:06.468741       1 wrap.go:47] GET /healthz: (68.112µs) 200 [kube-probe/1.15+ 127.0.0.1:41432]
I0416 22:15:16.468801       1 wrap.go:47] GET /healthz: (55.074µs) 200 [kube-probe/1.15+ 127.0.0.1:41464]
I0416 22:15:26.468639       1 wrap.go:47] GET /healthz: (73.758µs) 200 [kube-probe/1.15+ 127.0.0.1:41498]
I0416 22:15:36.476171       1 wrap.go:47] GET /healthz: (1.25031ms) 200 [kube-probe/1.15+ 127.0.0.1:41534]
I0416 22:15:46.468966       1 wrap.go:47] GET /healthz: (87.644µs) 200 [kube-probe/1.15+ 127.0.0.1:41586]
I0416 22:15:56.468824       1 wrap.go:47] GET /healthz: (76.57µs) 200 [kube-probe/1.15+ 127.0.0.1:41622]
I0416 22:16:06.468739       1 wrap.go:47] GET /healthz: (59.32µs) 200 [kube-probe/1.15+ 127.0.0.1:41668]
I0416 22:16:16.469166       1 wrap.go:47] GET /healthz: (67.667µs) 200 [kube-probe/1.15+ 127.0.0.1:41700]
I0416 22:16:26.469464       1 wrap.go:47] GET /healthz: (63.764µs) 200 [kube-probe/1.15+ 127.0.0.1:41732]
I0416 22:16:36.469531       1 wrap.go:47] GET /healthz: (84.853µs) 200 [kube-probe/1.15+ 127.0.0.1:41768]
I0416 22:16:46.468661       1 wrap.go:47] GET /healthz: (89.222µs) 200 [kube-probe/1.15+ 127.0.0.1:41820]
I0416 22:16:56.469104       1 wrap.go:47] GET /healthz: (63.612µs) 200 [kube-probe/1.15+ 127.0.0.1:41856]
I0416 22:17:06.468577       1 wrap.go:47] GET /healthz: (67.445µs) 200 [kube-probe/1.15+ 127.0.0.1:41890]
I0416 22:17:12.391962       1 reflector.go:384] k8s.io/client-go/informers/factory.go:133: Watch close - *v1.PersistentVolumeClaim total 0 items received
I0416 22:17:16.468516       1 wrap.go:47] GET /healthz: (68.576µs) 200 [kube-probe/1.15+ 127.0.0.1:41922]
I0416 22:17:26.468806       1 wrap.go:47] GET /healthz: (66.474µs) 200 [kube-probe/1.15+ 127.0.0.1:41954]
I0416 22:17:36.469134       1 wrap.go:47] GET /healthz: (133.814µs) 200 [kube-probe/1.15+ 127.0.0.1:41990]
I0416 22:17:42.390052       1 reflector.go:384] k8s.io/client-go/informers/factory.go:133: Watch close - *v1.PersistentVolume total 0 items received
I0416 22:17:46.468577       1 wrap.go:47] GET /healthz: (74.271µs) 200 [kube-probe/1.15+ 127.0.0.1:42042]
I0416 22:17:49.407859       1 reflector.go:384] k8s.io/client-go/informers/factory.go:133: Watch close - *v1.StatefulSet total 0 items received
I0416 22:17:56.471137       1 wrap.go:47] GET /healthz: (74.008µs) 200 [kube-probe/1.15+ 127.0.0.1:42078]
I0416 22:18:06.468670       1 wrap.go:47] GET /healthz: (90.663µs) 200 [kube-probe/1.15+ 127.0.0.1:42112]
I0416 22:18:16.468837       1 wrap.go:47] GET /healthz: (75.557µs) 200 [kube-probe/1.15+ 127.0.0.1:42144]
I0416 22:18:26.469709       1 wrap.go:47] GET /healthz: (1.106255ms) 200 [kube-probe/1.15+ 127.0.0.1:42176]
I0416 22:18:36.468930       1 wrap.go:47] GET /healthz: (68.216µs) 200 [kube-probe/1.15+ 127.0.0.1:42210]
I0416 22:18:46.468653       1 wrap.go:47] GET /healthz: (75.427µs) 200 [kube-probe/1.15+ 127.0.0.1:42264]
I0416 22:18:56.468829       1 wrap.go:47] GET /healthz: (68.383µs) 200 [kube-probe/1.15+ 127.0.0.1:42300]
I0416 22:19:06.468802       1 wrap.go:47] GET /healthz: (108.913µs) 200 [kube-probe/1.15+ 127.0.0.1:42334]
I0416 22:19:16.468870       1 wrap.go:47] GET /healthz: (72.33µs) 200 [kube-probe/1.15+ 127.0.0.1:42366]
I0416 22:19:26.469170       1 wrap.go:47] GET /healthz: (76.201µs) 200 [kube-probe/1.15+ 127.0.0.1:42400]
I0416 22:19:36.469031       1 wrap.go:47] GET /healthz: (81.649µs) 200 [kube-probe/1.15+ 127.0.0.1:42434]
I0416 22:19:46.469167       1 wrap.go:47] GET /healthz: (77.514µs) 200 [kube-probe/1.15+ 127.0.0.1:42488]
I0416 22:19:56.468971       1 wrap.go:47] GET /healthz: (76.562µs) 200 [kube-probe/1.15+ 127.0.0.1:42524]
I0416 22:20:06.468947       1 wrap.go:47] GET /healthz: (79.498µs) 200 [kube-probe/1.15+ 127.0.0.1:42558]
I0416 22:20:09.411013       1 reflector.go:384] cmd/kube-scheduler/app/server.go:223: Watch close - *v1.Pod total 0 items received
I0416 22:20:16.469558       1 wrap.go:47] GET /healthz: (70.419µs) 200 [kube-probe/1.15+ 127.0.0.1:42590]
I0416 22:20:23.411804       1 reflector.go:384] k8s.io/client-go/informers/factory.go:133: Watch close - *v1.Node total 43 items received
I0416 22:20:26.468774       1 wrap.go:47] GET /healthz: (73.722µs) 200 [kube-probe/1.15+ 127.0.0.1:42622]
I0416 22:20:36.468502       1 wrap.go:47] GET /healthz: (55.036µs) 200 [kube-probe/1.15+ 127.0.0.1:42656]
I0416 22:20:46.468994       1 wrap.go:47] GET /healthz: (77.099µs) 200 [kube-probe/1.15+ 127.0.0.1:42710]
I0416 22:20:47.306475       1 reflector.go:384] k8s.io/client-go/informers/factory.go:133: Watch close - *v1.Service total 0 items received
I0416 22:20:49.307328       1 reflector.go:384] k8s.io/client-go/informers/factory.go:133: Watch close - *v1.ReplicationController total 0 items received
I0416 22:20:56.468699       1 wrap.go:47] GET /healthz: (152.897µs) 200 [kube-probe/1.15+ 127.0.0.1:42746]
I0416 22:21:06.469026       1 wrap.go:47] GET /healthz: (83.19µs) 200 [kube-probe/1.15+ 127.0.0.1:42780]
