I0319 16:42:48.061746       1 feature_gate.go:226] feature gates: &{map[ExperimentalCriticalPodAnnotation:true]}
I0319 16:42:48.061909       1 flags.go:33] FLAG: --address="0.0.0.0"
I0319 16:42:48.061940       1 flags.go:33] FLAG: --algorithm-provider=""
I0319 16:42:48.061951       1 flags.go:33] FLAG: --alsologtostderr="false"
I0319 16:42:48.061958       1 flags.go:33] FLAG: --authentication-kubeconfig=""
I0319 16:42:48.061963       1 flags.go:33] FLAG: --authentication-skip-lookup="false"
I0319 16:42:48.061972       1 flags.go:33] FLAG: --authentication-token-webhook-cache-ttl="10s"
I0319 16:42:48.061979       1 flags.go:33] FLAG: --authentication-tolerate-lookup-failure="true"
I0319 16:42:48.061984       1 flags.go:33] FLAG: --authorization-always-allow-paths="[/healthz]"
I0319 16:42:48.062000       1 flags.go:33] FLAG: --authorization-kubeconfig=""
I0319 16:42:48.062005       1 flags.go:33] FLAG: --authorization-webhook-cache-authorized-ttl="10s"
I0319 16:42:48.062010       1 flags.go:33] FLAG: --authorization-webhook-cache-unauthorized-ttl="10s"
I0319 16:42:48.062015       1 flags.go:33] FLAG: --bind-address="0.0.0.0"
I0319 16:42:48.062054       1 flags.go:33] FLAG: --cert-dir=""
I0319 16:42:48.062069       1 flags.go:33] FLAG: --client-ca-file=""
I0319 16:42:48.062077       1 flags.go:33] FLAG: --config=""
I0319 16:42:48.062082       1 flags.go:33] FLAG: --contention-profiling="false"
I0319 16:42:48.062087       1 flags.go:33] FLAG: --failure-domains="kubernetes.io/hostname,failure-domain.beta.kubernetes.io/zone,failure-domain.beta.kubernetes.io/region"
I0319 16:42:48.062096       1 flags.go:33] FLAG: --feature-gates="ExperimentalCriticalPodAnnotation=true"
I0319 16:42:48.062112       1 flags.go:33] FLAG: --hard-pod-affinity-symmetric-weight="1"
I0319 16:42:48.062118       1 flags.go:33] FLAG: --help="false"
I0319 16:42:48.062123       1 flags.go:33] FLAG: --http2-max-streams-per-connection="0"
I0319 16:42:48.062130       1 flags.go:33] FLAG: --kube-api-burst="100"
I0319 16:42:48.062135       1 flags.go:33] FLAG: --kube-api-content-type="application/vnd.kubernetes.protobuf"
I0319 16:42:48.062145       1 flags.go:33] FLAG: --kube-api-qps="50"
I0319 16:42:48.062153       1 flags.go:33] FLAG: --kubeconfig="/etc/srv/kubernetes/kube-scheduler/kubeconfig"
I0319 16:42:48.062158       1 flags.go:33] FLAG: --leader-elect="true"
I0319 16:42:48.062164       1 flags.go:33] FLAG: --leader-elect-lease-duration="15s"
I0319 16:42:48.062169       1 flags.go:33] FLAG: --leader-elect-renew-deadline="10s"
I0319 16:42:48.062174       1 flags.go:33] FLAG: --leader-elect-resource-lock="endpoints"
I0319 16:42:48.062182       1 flags.go:33] FLAG: --leader-elect-retry-period="2s"
I0319 16:42:48.062188       1 flags.go:33] FLAG: --lock-object-name="kube-scheduler"
I0319 16:42:48.062193       1 flags.go:33] FLAG: --lock-object-namespace="kube-system"
I0319 16:42:48.062198       1 flags.go:33] FLAG: --log-backtrace-at=":0"
I0319 16:42:48.062206       1 flags.go:33] FLAG: --log-dir=""
I0319 16:42:48.062216       1 flags.go:33] FLAG: --log-file=""
I0319 16:42:48.062221       1 flags.go:33] FLAG: --log-flush-frequency="5s"
I0319 16:42:48.062230       1 flags.go:33] FLAG: --logtostderr="true"
I0319 16:42:48.062236       1 flags.go:33] FLAG: --master=""
I0319 16:42:48.062241       1 flags.go:33] FLAG: --policy-config-file=""
I0319 16:42:48.062245       1 flags.go:33] FLAG: --policy-configmap=""
I0319 16:42:48.062253       1 flags.go:33] FLAG: --policy-configmap-namespace="kube-system"
I0319 16:42:48.062259       1 flags.go:33] FLAG: --port="10251"
I0319 16:42:48.062264       1 flags.go:33] FLAG: --profiling="false"
I0319 16:42:48.062269       1 flags.go:33] FLAG: --requestheader-allowed-names="[]"
I0319 16:42:48.062275       1 flags.go:33] FLAG: --requestheader-client-ca-file=""
I0319 16:42:48.062280       1 flags.go:33] FLAG: --requestheader-extra-headers-prefix="[x-remote-extra-]"
I0319 16:42:48.062293       1 flags.go:33] FLAG: --requestheader-group-headers="[x-remote-group]"
I0319 16:42:48.062300       1 flags.go:33] FLAG: --requestheader-username-headers="[x-remote-user]"
I0319 16:42:48.062340       1 flags.go:33] FLAG: --scheduler-name="default-scheduler"
I0319 16:42:48.062346       1 flags.go:33] FLAG: --secure-port="10259"
I0319 16:42:48.062351       1 flags.go:33] FLAG: --skip-headers="false"
I0319 16:42:48.062356       1 flags.go:33] FLAG: --stderrthreshold="2"
I0319 16:42:48.062364       1 flags.go:33] FLAG: --tls-cert-file=""
I0319 16:42:48.062369       1 flags.go:33] FLAG: --tls-cipher-suites="[]"
I0319 16:42:48.062375       1 flags.go:33] FLAG: --tls-min-version=""
I0319 16:42:48.062380       1 flags.go:33] FLAG: --tls-private-key-file=""
I0319 16:42:48.062385       1 flags.go:33] FLAG: --tls-sni-cert-key="[]"
I0319 16:42:48.062397       1 flags.go:33] FLAG: --use-legacy-policy-config="false"
I0319 16:42:48.062402       1 flags.go:33] FLAG: --v="4"
I0319 16:42:48.062407       1 flags.go:33] FLAG: --version="false"
I0319 16:42:48.062415       1 flags.go:33] FLAG: --vmodule=""
I0319 16:42:48.062420       1 flags.go:33] FLAG: --write-config-to=""
I0319 16:42:49.180666       1 serving.go:319] Generated self-signed cert in-memory
W0319 16:42:53.336846       1 authentication.go:249] No authentication-kubeconfig provided in order to lookup client-ca-file in configmap/extension-apiserver-authentication in kube-system, so client certificate authentication won't work.
W0319 16:42:53.336877       1 authentication.go:252] No authentication-kubeconfig provided in order to lookup requestheader-client-ca-file in configmap/extension-apiserver-authentication in kube-system, so request-header client certificate authentication won't work.
W0319 16:42:53.336895       1 authorization.go:146] No authorization-kubeconfig provided, so SubjectAccessReview of authorization tokens won't work.
I0319 16:42:53.386494       1 server.go:142] Version: v1.15.0-alpha.0.1217+13f77e8589cd67-dirty
I0319 16:42:53.386609       1 defaults.go:87] TaintNodesByCondition is enabled, PodToleratesNodeTaints predicate is mandatory
I0319 16:42:53.386622       1 server.go:161] Starting Kubernetes Scheduler version v1.15.0-alpha.0.1217+13f77e8589cd67-dirty
I0319 16:42:53.418285       1 factory.go:331] Creating scheduler from algorithm provider 'DefaultProvider'
I0319 16:42:53.418314       1 factory.go:412] Creating scheduler with fit predicates 'map[CheckNodeUnschedulable:{} CheckVolumeBinding:{} GeneralPredicates:{} MatchInterPodAffinity:{} MaxAzureDiskVolumeCount:{} MaxCSIVolumeCountPred:{} MaxEBSVolumeCount:{} MaxGCEPDVolumeCount:{} NoDiskConflict:{} NoVolumeZoneConflict:{} PodToleratesNodeTaints:{}]' and priority functions 'map[BalancedResourceAllocation:{} ImageLocalityPriority:{} InterPodAffinityPriority:{} LeastRequestedPriority:{} NodeAffinityPriority:{} NodePreferAvoidPodsPriority:{} SelectorSpreadPriority:{} TaintTolerationPriority:{}]'
W0319 16:42:53.433737       1 authorization.go:47] Authorization is disabled
W0319 16:42:53.433836       1 authentication.go:55] Authentication is disabled
I0319 16:42:53.433850       1 deprecated_insecure_serving.go:49] Serving healthz insecurely on [::]:10251
I0319 16:42:53.469335       1 secure_serving.go:116] Serving securely on [::]:10259
I0319 16:42:53.469685       1 reflector.go:123] Starting reflector *v1.Pod (0s) from k8s.io/kubernetes/cmd/kube-scheduler/app/server.go:223
I0319 16:42:53.469704       1 reflector.go:161] Listing and watching *v1.Pod from k8s.io/kubernetes/cmd/kube-scheduler/app/server.go:223
I0319 16:42:53.489939       1 reflector.go:123] Starting reflector *v1.StorageClass (0s) from k8s.io/client-go/informers/factory.go:133
I0319 16:42:53.489968       1 reflector.go:161] Listing and watching *v1.StorageClass from k8s.io/client-go/informers/factory.go:133
I0319 16:42:53.507504       1 reflector.go:123] Starting reflector *v1.PersistentVolume (0s) from k8s.io/client-go/informers/factory.go:133
I0319 16:42:53.507539       1 reflector.go:161] Listing and watching *v1.PersistentVolume from k8s.io/client-go/informers/factory.go:133
I0319 16:42:53.522152       1 reflector.go:123] Starting reflector *v1.PersistentVolumeClaim (0s) from k8s.io/client-go/informers/factory.go:133
I0319 16:42:53.522201       1 reflector.go:161] Listing and watching *v1.PersistentVolumeClaim from k8s.io/client-go/informers/factory.go:133
I0319 16:42:53.522828       1 reflector.go:123] Starting reflector *v1.Service (0s) from k8s.io/client-go/informers/factory.go:133
I0319 16:42:53.522851       1 reflector.go:161] Listing and watching *v1.Service from k8s.io/client-go/informers/factory.go:133
I0319 16:42:53.534606       1 reflector.go:123] Starting reflector *v1.ReplicationController (0s) from k8s.io/client-go/informers/factory.go:133
I0319 16:42:53.534642       1 reflector.go:161] Listing and watching *v1.ReplicationController from k8s.io/client-go/informers/factory.go:133
I0319 16:42:53.550117       1 reflector.go:123] Starting reflector *v1beta1.PodDisruptionBudget (0s) from k8s.io/client-go/informers/factory.go:133
I0319 16:42:53.550152       1 reflector.go:161] Listing and watching *v1beta1.PodDisruptionBudget from k8s.io/client-go/informers/factory.go:133
I0319 16:42:53.550831       1 reflector.go:123] Starting reflector *v1.Node (0s) from k8s.io/client-go/informers/factory.go:133
I0319 16:42:53.550849       1 reflector.go:161] Listing and watching *v1.Node from k8s.io/client-go/informers/factory.go:133
I0319 16:42:53.564695       1 reflector.go:123] Starting reflector *v1.ReplicaSet (0s) from k8s.io/client-go/informers/factory.go:133
I0319 16:42:53.564724       1 reflector.go:161] Listing and watching *v1.ReplicaSet from k8s.io/client-go/informers/factory.go:133
I0319 16:42:53.577547       1 reflector.go:123] Starting reflector *v1.StatefulSet (0s) from k8s.io/client-go/informers/factory.go:133
I0319 16:42:53.577581       1 reflector.go:161] Listing and watching *v1.StatefulSet from k8s.io/client-go/informers/factory.go:133
I0319 16:43:03.589882       1 trace.go:81] Trace[2056655333]: "Reflector k8s.io/kubernetes/cmd/kube-scheduler/app/server.go:223 ListAndWatch" (started: 2019-03-19 16:42:53.469710664 +0000 UTC m=+5.498215548) (total time: 10.120124175s):
Trace[2056655333]: [10.120124175s] [10.120124175s] END
E0319 16:43:03.589915       1 reflector.go:126] k8s.io/kubernetes/cmd/kube-scheduler/app/server.go:223: Failed to list *v1.Pod: Get https://localhost:443/api/v1/pods?fieldSelector=status.phase%21%3DFailed%2Cstatus.phase%21%3DSucceeded&limit=500&resourceVersion=0: net/http: TLS handshake timeout
I0319 16:43:03.590221       1 trace.go:81] Trace[865918817]: "Reflector k8s.io/client-go/informers/factory.go:133 ListAndWatch" (started: 2019-03-19 16:42:53.564730717 +0000 UTC m=+5.593235596) (total time: 10.025472694s):
Trace[865918817]: [10.025472694s] [10.025472694s] END
E0319 16:43:03.590235       1 reflector.go:126] k8s.io/client-go/informers/factory.go:133: Failed to list *v1.ReplicaSet: Get https://localhost:443/apis/apps/v1/replicasets?limit=500&resourceVersion=0: net/http: TLS handshake timeout
I0319 16:43:03.590326       1 trace.go:81] Trace[937873569]: "Reflector k8s.io/client-go/informers/factory.go:133 ListAndWatch" (started: 2019-03-19 16:42:53.507544047 +0000 UTC m=+5.536048927) (total time: 10.082757397s):
Trace[937873569]: [10.082757397s] [10.082757397s] END
E0319 16:43:03.590333       1 reflector.go:126] k8s.io/client-go/informers/factory.go:133: Failed to list *v1.PersistentVolume: Get https://localhost:443/api/v1/persistentvolumes?limit=500&resourceVersion=0: net/http: TLS handshake timeout
I0319 16:43:03.590408       1 trace.go:81] Trace[90363704]: "Reflector k8s.io/client-go/informers/factory.go:133 ListAndWatch" (started: 2019-03-19 16:42:53.489973831 +0000 UTC m=+5.518478707) (total time: 10.100416757s):
Trace[90363704]: [10.100416757s] [10.100416757s] END
E0319 16:43:03.590414       1 reflector.go:126] k8s.io/client-go/informers/factory.go:133: Failed to list *v1.StorageClass: Get https://localhost:443/apis/storage.k8s.io/v1/storageclasses?limit=500&resourceVersion=0: net/http: TLS handshake timeout
I0319 16:43:03.590485       1 trace.go:81] Trace[508434910]: "Reflector k8s.io/client-go/informers/factory.go:133 ListAndWatch" (started: 2019-03-19 16:42:53.522207522 +0000 UTC m=+5.550712402) (total time: 10.068260701s):
Trace[508434910]: [10.068260701s] [10.068260701s] END
E0319 16:43:03.590501       1 reflector.go:126] k8s.io/client-go/informers/factory.go:133: Failed to list *v1.PersistentVolumeClaim: Get https://localhost:443/api/v1/persistentvolumeclaims?limit=500&resourceVersion=0: net/http: TLS handshake timeout
I0319 16:43:03.590585       1 trace.go:81] Trace[1237132237]: "Reflector k8s.io/client-go/informers/factory.go:133 ListAndWatch" (started: 2019-03-19 16:42:53.534658214 +0000 UTC m=+5.563163243) (total time: 10.055896817s):
Trace[1237132237]: [10.055896817s] [10.055896817s] END
E0319 16:43:03.590592       1 reflector.go:126] k8s.io/client-go/informers/factory.go:133: Failed to list *v1.ReplicationController: Get https://localhost:443/api/v1/replicationcontrollers?limit=500&resourceVersion=0: net/http: TLS handshake timeout
I0319 16:43:03.590668       1 trace.go:81] Trace[109308190]: "Reflector k8s.io/client-go/informers/factory.go:133 ListAndWatch" (started: 2019-03-19 16:42:53.522855881 +0000 UTC m=+5.551360758) (total time: 10.067795654s):
Trace[109308190]: [10.067795654s] [10.067795654s] END
E0319 16:43:03.590678       1 reflector.go:126] k8s.io/client-go/informers/factory.go:133: Failed to list *v1.Service: Get https://localhost:443/api/v1/services?limit=500&resourceVersion=0: net/http: TLS handshake timeout
I0319 16:43:03.590769       1 trace.go:81] Trace[1922260818]: "Reflector k8s.io/client-go/informers/factory.go:133 ListAndWatch" (started: 2019-03-19 16:42:53.550157934 +0000 UTC m=+5.578662810) (total time: 10.040593326s):
Trace[1922260818]: [10.040593326s] [10.040593326s] END
E0319 16:43:03.590776       1 reflector.go:126] k8s.io/client-go/informers/factory.go:133: Failed to list *v1beta1.PodDisruptionBudget: Get https://localhost:443/apis/policy/v1beta1/poddisruptionbudgets?limit=500&resourceVersion=0: net/http: TLS handshake timeout
I0319 16:43:03.590846       1 trace.go:81] Trace[1765218525]: "Reflector k8s.io/client-go/informers/factory.go:133 ListAndWatch" (started: 2019-03-19 16:42:53.550853724 +0000 UTC m=+5.579358601) (total time: 10.039977101s):
Trace[1765218525]: [10.039977101s] [10.039977101s] END
E0319 16:43:03.590853       1 reflector.go:126] k8s.io/client-go/informers/factory.go:133: Failed to list *v1.Node: Get https://localhost:443/api/v1/nodes?limit=500&resourceVersion=0: net/http: TLS handshake timeout
I0319 16:43:03.590919       1 trace.go:81] Trace[2005418907]: "Reflector k8s.io/client-go/informers/factory.go:133 ListAndWatch" (started: 2019-03-19 16:42:53.577586377 +0000 UTC m=+5.606091255) (total time: 10.013318133s):
Trace[2005418907]: [10.013318133s] [10.013318133s] END
E0319 16:43:03.590925       1 reflector.go:126] k8s.io/client-go/informers/factory.go:133: Failed to list *v1.StatefulSet: Get https://localhost:443/apis/apps/v1/statefulsets?limit=500&resourceVersion=0: net/http: TLS handshake timeout
I0319 16:43:04.590125       1 reflector.go:161] Listing and watching *v1.Pod from k8s.io/kubernetes/cmd/kube-scheduler/app/server.go:223
I0319 16:43:04.591997       1 reflector.go:161] Listing and watching *v1.ReplicaSet from k8s.io/client-go/informers/factory.go:133
I0319 16:43:04.592732       1 reflector.go:161] Listing and watching *v1.PersistentVolume from k8s.io/client-go/informers/factory.go:133
I0319 16:43:04.593268       1 reflector.go:161] Listing and watching *v1.StorageClass from k8s.io/client-go/informers/factory.go:133
I0319 16:43:04.594373       1 reflector.go:161] Listing and watching *v1.PersistentVolumeClaim from k8s.io/client-go/informers/factory.go:133
I0319 16:43:04.595467       1 reflector.go:161] Listing and watching *v1.ReplicationController from k8s.io/client-go/informers/factory.go:133
I0319 16:43:04.596615       1 reflector.go:161] Listing and watching *v1.Service from k8s.io/client-go/informers/factory.go:133
I0319 16:43:04.597654       1 reflector.go:161] Listing and watching *v1beta1.PodDisruptionBudget from k8s.io/client-go/informers/factory.go:133
I0319 16:43:04.598768       1 reflector.go:161] Listing and watching *v1.Node from k8s.io/client-go/informers/factory.go:133
I0319 16:43:04.599846       1 reflector.go:161] Listing and watching *v1.StatefulSet from k8s.io/client-go/informers/factory.go:133
I0319 16:43:10.117639       1 wrap.go:47] GET /healthz: (76.346µs) 200 [kube-probe/1.15+ 127.0.0.1:47618]
E0319 16:43:13.010383       1 reflector.go:126] k8s.io/client-go/informers/factory.go:133: Failed to list *v1.StatefulSet: statefulsets.apps is forbidden: User "system:kube-scheduler" cannot list resource "statefulsets" in API group "apps" at the cluster scope
E0319 16:43:13.010447       1 reflector.go:126] k8s.io/client-go/informers/factory.go:133: Failed to list *v1.PersistentVolume: persistentvolumes is forbidden: User "system:kube-scheduler" cannot list resource "persistentvolumes" in API group "" at the cluster scope
E0319 16:43:13.011482       1 reflector.go:126] k8s.io/kubernetes/cmd/kube-scheduler/app/server.go:223: Failed to list *v1.Pod: pods is forbidden: User "system:kube-scheduler" cannot list resource "pods" in API group "" at the cluster scope
E0319 16:43:13.011540       1 reflector.go:126] k8s.io/client-go/informers/factory.go:133: Failed to list *v1.ReplicaSet: replicasets.apps is forbidden: User "system:kube-scheduler" cannot list resource "replicasets" in API group "apps" at the cluster scope
E0319 16:43:13.011600       1 reflector.go:126] k8s.io/client-go/informers/factory.go:133: Failed to list *v1beta1.PodDisruptionBudget: poddisruptionbudgets.policy is forbidden: User "system:kube-scheduler" cannot list resource "poddisruptionbudgets" in API group "policy" at the cluster scope
E0319 16:43:13.011637       1 reflector.go:126] k8s.io/client-go/informers/factory.go:133: Failed to list *v1.Node: nodes is forbidden: User "system:kube-scheduler" cannot list resource "nodes" in API group "" at the cluster scope
E0319 16:43:13.011699       1 reflector.go:126] k8s.io/client-go/informers/factory.go:133: Failed to list *v1.PersistentVolumeClaim: persistentvolumeclaims is forbidden: User "system:kube-scheduler" cannot list resource "persistentvolumeclaims" in API group "" at the cluster scope
E0319 16:43:13.011739       1 reflector.go:126] k8s.io/client-go/informers/factory.go:133: Failed to list *v1.ReplicationController: replicationcontrollers is forbidden: User "system:kube-scheduler" cannot list resource "replicationcontrollers" in API group "" at the cluster scope
E0319 16:43:13.011787       1 reflector.go:126] k8s.io/client-go/informers/factory.go:133: Failed to list *v1.Service: services is forbidden: User "system:kube-scheduler" cannot list resource "services" in API group "" at the cluster scope
E0319 16:43:13.011855       1 reflector.go:126] k8s.io/client-go/informers/factory.go:133: Failed to list *v1.StorageClass: storageclasses.storage.k8s.io is forbidden: User "system:kube-scheduler" cannot list resource "storageclasses" in API group "storage.k8s.io" at the cluster scope
I0319 16:43:14.010600       1 reflector.go:161] Listing and watching *v1.StatefulSet from k8s.io/client-go/informers/factory.go:133
E0319 16:43:14.016381       1 reflector.go:126] k8s.io/client-go/informers/factory.go:133: Failed to list *v1.StatefulSet: statefulsets.apps is forbidden: User "system:kube-scheduler" cannot list resource "statefulsets" in API group "apps" at the cluster scope
I0319 16:43:14.016459       1 reflector.go:161] Listing and watching *v1.Pod from k8s.io/kubernetes/cmd/kube-scheduler/app/server.go:223
I0319 16:43:14.016664       1 reflector.go:161] Listing and watching *v1.PersistentVolume from k8s.io/client-go/informers/factory.go:133
E0319 16:43:14.024263       1 reflector.go:126] k8s.io/kubernetes/cmd/kube-scheduler/app/server.go:223: Failed to list *v1.Pod: pods is forbidden: User "system:kube-scheduler" cannot list resource "pods" in API group "" at the cluster scope
E0319 16:43:14.024340       1 reflector.go:126] k8s.io/client-go/informers/factory.go:133: Failed to list *v1.PersistentVolume: persistentvolumes is forbidden: User "system:kube-scheduler" cannot list resource "persistentvolumes" in API group "" at the cluster scope
I0319 16:43:14.024396       1 reflector.go:161] Listing and watching *v1beta1.PodDisruptionBudget from k8s.io/client-go/informers/factory.go:133
I0319 16:43:14.024583       1 reflector.go:161] Listing and watching *v1.ReplicaSet from k8s.io/client-go/informers/factory.go:133
E0319 16:43:14.030472       1 reflector.go:126] k8s.io/client-go/informers/factory.go:133: Failed to list *v1.ReplicaSet: replicasets.apps is forbidden: User "system:kube-scheduler" cannot list resource "replicasets" in API group "apps" at the cluster scope
E0319 16:43:14.030543       1 reflector.go:126] k8s.io/client-go/informers/factory.go:133: Failed to list *v1beta1.PodDisruptionBudget: poddisruptionbudgets.policy is forbidden: User "system:kube-scheduler" cannot list resource "poddisruptionbudgets" in API group "policy" at the cluster scope
I0319 16:43:14.030595       1 reflector.go:161] Listing and watching *v1.PersistentVolumeClaim from k8s.io/client-go/informers/factory.go:133
I0319 16:43:14.030805       1 reflector.go:161] Listing and watching *v1.Node from k8s.io/client-go/informers/factory.go:133
E0319 16:43:14.041786       1 reflector.go:126] k8s.io/client-go/informers/factory.go:133: Failed to list *v1.Node: nodes is forbidden: User "system:kube-scheduler" cannot list resource "nodes" in API group "" at the cluster scope
E0319 16:43:14.041871       1 reflector.go:126] k8s.io/client-go/informers/factory.go:133: Failed to list *v1.PersistentVolumeClaim: persistentvolumeclaims is forbidden: User "system:kube-scheduler" cannot list resource "persistentvolumeclaims" in API group "" at the cluster scope
I0319 16:43:14.042099       1 reflector.go:161] Listing and watching *v1.StorageClass from k8s.io/client-go/informers/factory.go:133
I0319 16:43:14.044104       1 reflector.go:161] Listing and watching *v1.ReplicationController from k8s.io/client-go/informers/factory.go:133
I0319 16:43:14.044421       1 reflector.go:161] Listing and watching *v1.Service from k8s.io/client-go/informers/factory.go:133
E0319 16:43:14.045109       1 reflector.go:126] k8s.io/client-go/informers/factory.go:133: Failed to list *v1.StorageClass: storageclasses.storage.k8s.io is forbidden: User "system:kube-scheduler" cannot list resource "storageclasses" in API group "storage.k8s.io" at the cluster scope
E0319 16:43:14.059413       1 reflector.go:126] k8s.io/client-go/informers/factory.go:133: Failed to list *v1.Service: services is forbidden: User "system:kube-scheduler" cannot list resource "services" in API group "" at the cluster scope
E0319 16:43:14.059617       1 reflector.go:126] k8s.io/client-go/informers/factory.go:133: Failed to list *v1.ReplicationController: replicationcontrollers is forbidden: User "system:kube-scheduler" cannot list resource "replicationcontrollers" in API group "" at the cluster scope
I0319 16:43:15.017418       1 reflector.go:161] Listing and watching *v1.StatefulSet from k8s.io/client-go/informers/factory.go:133
I0319 16:43:15.024894       1 reflector.go:161] Listing and watching *v1.Pod from k8s.io/kubernetes/cmd/kube-scheduler/app/server.go:223
I0319 16:43:15.031597       1 reflector.go:161] Listing and watching *v1.PersistentVolume from k8s.io/client-go/informers/factory.go:133
I0319 16:43:15.044278       1 reflector.go:161] Listing and watching *v1.ReplicaSet from k8s.io/client-go/informers/factory.go:133
I0319 16:43:15.053808       1 reflector.go:161] Listing and watching *v1beta1.PodDisruptionBudget from k8s.io/client-go/informers/factory.go:133
I0319 16:43:15.059844       1 reflector.go:161] Listing and watching *v1.Node from k8s.io/client-go/informers/factory.go:133
I0319 16:43:15.062595       1 reflector.go:161] Listing and watching *v1.PersistentVolumeClaim from k8s.io/client-go/informers/factory.go:133
I0319 16:43:15.065863       1 reflector.go:161] Listing and watching *v1.StorageClass from k8s.io/client-go/informers/factory.go:133
I0319 16:43:15.075689       1 reflector.go:161] Listing and watching *v1.Service from k8s.io/client-go/informers/factory.go:133
I0319 16:43:15.078750       1 reflector.go:161] Listing and watching *v1.ReplicationController from k8s.io/client-go/informers/factory.go:133
I0319 16:43:15.170131       1 shared_informer.go:123] caches populated
I0319 16:43:15.271539       1 shared_informer.go:123] caches populated
I0319 16:43:15.373193       1 shared_informer.go:123] caches populated
I0319 16:43:15.473435       1 shared_informer.go:123] caches populated
I0319 16:43:15.574174       1 shared_informer.go:123] caches populated
I0319 16:43:15.674686       1 shared_informer.go:123] caches populated
I0319 16:43:15.774992       1 shared_informer.go:123] caches populated
I0319 16:43:15.876008       1 shared_informer.go:123] caches populated
I0319 16:43:15.976302       1 shared_informer.go:123] caches populated
I0319 16:43:15.976353       1 controller_utils.go:1027] Waiting for caches to sync for scheduler controller
I0319 16:43:16.077294       1 shared_informer.go:123] caches populated
I0319 16:43:16.077338       1 controller_utils.go:1034] Caches are synced for scheduler controller
I0319 16:43:16.077423       1 leaderelection.go:217] attempting to acquire leader lease  kube-system/kube-scheduler...
I0319 16:43:16.104707       1 leaderelection.go:227] successfully acquired lease kube-system/kube-scheduler
I0319 16:43:16.207795       1 shared_informer.go:123] caches populated
I0319 16:43:20.119149       1 wrap.go:47] GET /healthz: (58.26µs) 200 [kube-probe/1.15+ 127.0.0.1:48314]
I0319 16:43:30.117957       1 wrap.go:47] GET /healthz: (74.258µs) 200 [kube-probe/1.15+ 127.0.0.1:48406]
I0319 16:43:34.238541       1 scheduling_queue.go:908] About to try and schedule pod kube-system/coredns-5b969f4c88-sn584
I0319 16:43:34.238591       1 scheduler.go:453] Attempting to schedule pod: kube-system/coredns-5b969f4c88-sn584
I0319 16:43:34.238640       1 factory.go:644] Unable to schedule kube-system/coredns-5b969f4c88-sn584: no nodes are registered to the cluster; waiting
I0319 16:43:34.238689       1 factory.go:742] Updating pod condition for kube-system/coredns-5b969f4c88-sn584 to (PodScheduled==False, Reason=Unschedulable)
E0319 16:43:34.262501       1 scheduler.go:481] error selecting node for pod: no nodes available to schedule pods
I0319 16:43:34.262659       1 scheduling_queue.go:908] About to try and schedule pod kube-system/coredns-5b969f4c88-sn584
I0319 16:43:34.262670       1 scheduler.go:453] Attempting to schedule pod: kube-system/coredns-5b969f4c88-sn584
I0319 16:43:34.262713       1 factory.go:644] Unable to schedule kube-system/coredns-5b969f4c88-sn584: no nodes are registered to the cluster; waiting
I0319 16:43:34.262738       1 factory.go:742] Updating pod condition for kube-system/coredns-5b969f4c88-sn584 to (PodScheduled==False, Reason=Unschedulable)
E0319 16:43:34.262750       1 scheduler.go:481] error selecting node for pod: no nodes available to schedule pods
I0319 16:43:34.339384       1 scheduling_queue.go:908] About to try and schedule pod kube-system/l7-default-backend-8f479dd9-5qggn
I0319 16:43:34.339431       1 scheduler.go:453] Attempting to schedule pod: kube-system/l7-default-backend-8f479dd9-5qggn
I0319 16:43:34.339467       1 factory.go:644] Unable to schedule kube-system/l7-default-backend-8f479dd9-5qggn: no nodes are registered to the cluster; waiting
I0319 16:43:34.339495       1 factory.go:742] Updating pod condition for kube-system/l7-default-backend-8f479dd9-5qggn to (PodScheduled==False, Reason=Unschedulable)
E0319 16:43:34.359138       1 scheduler.go:481] error selecting node for pod: no nodes available to schedule pods
I0319 16:43:34.542570       1 scheduling_queue.go:908] About to try and schedule pod kube-system/heapster-v1.6.0-beta.1-b9947ddcf-dn54v
I0319 16:43:34.542603       1 scheduler.go:453] Attempting to schedule pod: kube-system/heapster-v1.6.0-beta.1-b9947ddcf-dn54v
I0319 16:43:34.542664       1 factory.go:644] Unable to schedule kube-system/heapster-v1.6.0-beta.1-b9947ddcf-dn54v: no nodes are registered to the cluster; waiting
I0319 16:43:34.542696       1 factory.go:742] Updating pod condition for kube-system/heapster-v1.6.0-beta.1-b9947ddcf-dn54v to (PodScheduled==False, Reason=Unschedulable)
E0319 16:43:34.586933       1 scheduler.go:481] error selecting node for pod: no nodes available to schedule pods
I0319 16:43:34.587137       1 scheduling_queue.go:908] About to try and schedule pod kube-system/heapster-v1.6.0-beta.1-b9947ddcf-dn54v
I0319 16:43:34.587153       1 scheduler.go:453] Attempting to schedule pod: kube-system/heapster-v1.6.0-beta.1-b9947ddcf-dn54v
I0319 16:43:34.587211       1 factory.go:644] Unable to schedule kube-system/heapster-v1.6.0-beta.1-b9947ddcf-dn54v: no nodes are registered to the cluster; waiting
I0319 16:43:34.587241       1 factory.go:742] Updating pod condition for kube-system/heapster-v1.6.0-beta.1-b9947ddcf-dn54v to (PodScheduled==False, Reason=Unschedulable)
E0319 16:43:34.587275       1 scheduler.go:481] error selecting node for pod: no nodes available to schedule pods
I0319 16:43:35.091439       1 scheduling_queue.go:908] About to try and schedule pod kube-system/event-exporter-v0.2.3-77f59d4b59-mdcvl
I0319 16:43:35.091463       1 scheduler.go:453] Attempting to schedule pod: kube-system/event-exporter-v0.2.3-77f59d4b59-mdcvl
I0319 16:43:35.091510       1 factory.go:644] Unable to schedule kube-system/event-exporter-v0.2.3-77f59d4b59-mdcvl: no nodes are registered to the cluster; waiting
I0319 16:43:35.091541       1 factory.go:742] Updating pod condition for kube-system/event-exporter-v0.2.3-77f59d4b59-mdcvl to (PodScheduled==False, Reason=Unschedulable)
E0319 16:43:35.110679       1 scheduler.go:481] error selecting node for pod: no nodes available to schedule pods
I0319 16:43:35.110751       1 scheduling_queue.go:908] About to try and schedule pod kube-system/event-exporter-v0.2.3-77f59d4b59-mdcvl
I0319 16:43:35.110760       1 scheduler.go:453] Attempting to schedule pod: kube-system/event-exporter-v0.2.3-77f59d4b59-mdcvl
I0319 16:43:35.110800       1 factory.go:644] Unable to schedule kube-system/event-exporter-v0.2.3-77f59d4b59-mdcvl: no nodes are registered to the cluster; waiting
I0319 16:43:35.110825       1 factory.go:742] Updating pod condition for kube-system/event-exporter-v0.2.3-77f59d4b59-mdcvl to (PodScheduled==False, Reason=Unschedulable)
E0319 16:43:35.110837       1 scheduler.go:481] error selecting node for pod: no nodes available to schedule pods
I0319 16:43:35.505413       1 scheduling_queue.go:908] About to try and schedule pod kube-system/coredns-5b969f4c88-sn584
I0319 16:43:35.505453       1 scheduler.go:453] Attempting to schedule pod: kube-system/coredns-5b969f4c88-sn584
I0319 16:43:35.505518       1 factory.go:644] Unable to schedule kube-system/coredns-5b969f4c88-sn584: no nodes are registered to the cluster; waiting
I0319 16:43:35.505553       1 factory.go:742] Updating pod condition for kube-system/coredns-5b969f4c88-sn584 to (PodScheduled==False, Reason=Unschedulable)
E0319 16:43:35.505566       1 scheduler.go:481] error selecting node for pod: no nodes available to schedule pods
I0319 16:43:35.508760       1 scheduling_queue.go:908] About to try and schedule pod kube-system/l7-default-backend-8f479dd9-5qggn
I0319 16:43:35.508798       1 scheduler.go:453] Attempting to schedule pod: kube-system/l7-default-backend-8f479dd9-5qggn
I0319 16:43:35.508842       1 factory.go:644] Unable to schedule kube-system/l7-default-backend-8f479dd9-5qggn: no nodes are registered to the cluster; waiting
I0319 16:43:35.508869       1 factory.go:742] Updating pod condition for kube-system/l7-default-backend-8f479dd9-5qggn to (PodScheduled==False, Reason=Unschedulable)
E0319 16:43:35.508882       1 scheduler.go:481] error selecting node for pod: no nodes available to schedule pods
I0319 16:43:35.611393       1 backoff_utils.go:79] Backing off 2s
I0319 16:43:35.611517       1 backoff_utils.go:79] Backing off 2s
I0319 16:43:36.296061       1 scheduling_queue.go:908] About to try and schedule pod kube-system/metrics-server-v0.3.1-677c578bdf-zvr7g
I0319 16:43:36.296087       1 scheduler.go:453] Attempting to schedule pod: kube-system/metrics-server-v0.3.1-677c578bdf-zvr7g
I0319 16:43:36.296139       1 factory.go:644] Unable to schedule kube-system/metrics-server-v0.3.1-677c578bdf-zvr7g: no nodes are registered to the cluster; waiting
I0319 16:43:36.296199       1 factory.go:742] Updating pod condition for kube-system/metrics-server-v0.3.1-677c578bdf-zvr7g to (PodScheduled==False, Reason=Unschedulable)
E0319 16:43:36.374732       1 scheduler.go:481] error selecting node for pod: no nodes available to schedule pods
I0319 16:43:36.374925       1 scheduling_queue.go:908] About to try and schedule pod kube-system/metrics-server-v0.3.1-677c578bdf-zvr7g
I0319 16:43:36.374937       1 scheduler.go:453] Attempting to schedule pod: kube-system/metrics-server-v0.3.1-677c578bdf-zvr7g
I0319 16:43:36.374989       1 factory.go:644] Unable to schedule kube-system/metrics-server-v0.3.1-677c578bdf-zvr7g: no nodes are registered to the cluster; waiting
I0319 16:43:36.375017       1 factory.go:742] Updating pod condition for kube-system/metrics-server-v0.3.1-677c578bdf-zvr7g to (PodScheduled==False, Reason=Unschedulable)
E0319 16:43:36.375042       1 scheduler.go:481] error selecting node for pod: no nodes available to schedule pods
I0319 16:43:36.509581       1 scheduling_queue.go:908] About to try and schedule pod kube-system/heapster-v1.6.0-beta.1-b9947ddcf-dn54v
I0319 16:43:36.509612       1 scheduler.go:453] Attempting to schedule pod: kube-system/heapster-v1.6.0-beta.1-b9947ddcf-dn54v
I0319 16:43:36.509680       1 factory.go:644] Unable to schedule kube-system/heapster-v1.6.0-beta.1-b9947ddcf-dn54v: no nodes are registered to the cluster; waiting
I0319 16:43:36.509713       1 factory.go:742] Updating pod condition for kube-system/heapster-v1.6.0-beta.1-b9947ddcf-dn54v to (PodScheduled==False, Reason=Unschedulable)
E0319 16:43:36.509726       1 scheduler.go:481] error selecting node for pod: no nodes available to schedule pods
I0319 16:43:36.541808       1 backoff_utils.go:79] Backing off 2s
I0319 16:43:36.590981       1 scheduling_queue.go:908] About to try and schedule pod kube-system/event-exporter-v0.2.3-77f59d4b59-mdcvl
I0319 16:43:36.591014       1 scheduler.go:453] Attempting to schedule pod: kube-system/event-exporter-v0.2.3-77f59d4b59-mdcvl
I0319 16:43:36.591064       1 factory.go:644] Unable to schedule kube-system/event-exporter-v0.2.3-77f59d4b59-mdcvl: no nodes are registered to the cluster; waiting
I0319 16:43:36.591218       1 factory.go:742] Updating pod condition for kube-system/event-exporter-v0.2.3-77f59d4b59-mdcvl to (PodScheduled==False, Reason=Unschedulable)
E0319 16:43:36.591234       1 scheduler.go:481] error selecting node for pod: no nodes available to schedule pods
I0319 16:43:36.606017       1 backoff_utils.go:79] Backing off 2s
I0319 16:43:37.509857       1 scheduling_queue.go:908] About to try and schedule pod kube-system/metrics-server-v0.3.1-677c578bdf-zvr7g
I0319 16:43:37.509914       1 scheduler.go:453] Attempting to schedule pod: kube-system/metrics-server-v0.3.1-677c578bdf-zvr7g
I0319 16:43:37.509985       1 factory.go:644] Unable to schedule kube-system/metrics-server-v0.3.1-677c578bdf-zvr7g: no nodes are registered to the cluster; waiting
I0319 16:43:37.510038       1 factory.go:742] Updating pod condition for kube-system/metrics-server-v0.3.1-677c578bdf-zvr7g to (PodScheduled==False, Reason=Unschedulable)
E0319 16:43:37.510053       1 scheduler.go:481] error selecting node for pod: no nodes available to schedule pods
I0319 16:43:37.516418       1 backoff_utils.go:79] Backing off 2s
I0319 16:43:38.476367       1 scheduling_queue.go:908] About to try and schedule pod kube-system/fluentd-gcp-scaler-85cdd7d7c5-7lm6p
I0319 16:43:38.476393       1 scheduler.go:453] Attempting to schedule pod: kube-system/fluentd-gcp-scaler-85cdd7d7c5-7lm6p
I0319 16:43:38.476440       1 factory.go:644] Unable to schedule kube-system/fluentd-gcp-scaler-85cdd7d7c5-7lm6p: no nodes are registered to the cluster; waiting
I0319 16:43:38.476474       1 factory.go:742] Updating pod condition for kube-system/fluentd-gcp-scaler-85cdd7d7c5-7lm6p to (PodScheduled==False, Reason=Unschedulable)
E0319 16:43:38.505441       1 scheduler.go:481] error selecting node for pod: no nodes available to schedule pods
I0319 16:43:38.506291       1 scheduling_queue.go:908] About to try and schedule pod kube-system/fluentd-gcp-scaler-85cdd7d7c5-7lm6p
I0319 16:43:38.506322       1 scheduler.go:453] Attempting to schedule pod: kube-system/fluentd-gcp-scaler-85cdd7d7c5-7lm6p
I0319 16:43:38.506360       1 factory.go:644] Unable to schedule kube-system/fluentd-gcp-scaler-85cdd7d7c5-7lm6p: no nodes are registered to the cluster; waiting
I0319 16:43:38.506391       1 factory.go:742] Updating pod condition for kube-system/fluentd-gcp-scaler-85cdd7d7c5-7lm6p to (PodScheduled==False, Reason=Unschedulable)
E0319 16:43:38.506403       1 scheduler.go:481] error selecting node for pod: no nodes available to schedule pods
I0319 16:43:38.517449       1 scheduling_queue.go:908] About to try and schedule pod kube-system/coredns-5b969f4c88-sn584
I0319 16:43:38.517471       1 scheduler.go:453] Attempting to schedule pod: kube-system/coredns-5b969f4c88-sn584
I0319 16:43:38.517514       1 factory.go:644] Unable to schedule kube-system/coredns-5b969f4c88-sn584: no nodes are registered to the cluster; waiting
I0319 16:43:38.517539       1 factory.go:742] Updating pod condition for kube-system/coredns-5b969f4c88-sn584 to (PodScheduled==False, Reason=Unschedulable)
E0319 16:43:38.517552       1 scheduler.go:481] error selecting node for pod: no nodes available to schedule pods
I0319 16:43:38.524568       1 scheduling_queue.go:908] About to try and schedule pod kube-system/l7-default-backend-8f479dd9-5qggn
I0319 16:43:38.524601       1 scheduler.go:453] Attempting to schedule pod: kube-system/l7-default-backend-8f479dd9-5qggn
I0319 16:43:38.524634       1 factory.go:644] Unable to schedule kube-system/l7-default-backend-8f479dd9-5qggn: no nodes are registered to the cluster; waiting
I0319 16:43:38.524666       1 factory.go:742] Updating pod condition for kube-system/l7-default-backend-8f479dd9-5qggn to (PodScheduled==False, Reason=Unschedulable)
E0319 16:43:38.524679       1 scheduler.go:481] error selecting node for pod: no nodes available to schedule pods
I0319 16:43:38.558563       1 backoff_utils.go:79] Backing off 4s
I0319 16:43:38.562949       1 backoff_utils.go:79] Backing off 4s
I0319 16:43:39.517921       1 scheduling_queue.go:908] About to try and schedule pod kube-system/heapster-v1.6.0-beta.1-b9947ddcf-dn54v
I0319 16:43:39.517975       1 scheduler.go:453] Attempting to schedule pod: kube-system/heapster-v1.6.0-beta.1-b9947ddcf-dn54v
I0319 16:43:39.518082       1 factory.go:644] Unable to schedule kube-system/heapster-v1.6.0-beta.1-b9947ddcf-dn54v: no nodes are registered to the cluster; waiting
I0319 16:43:39.518133       1 factory.go:742] Updating pod condition for kube-system/heapster-v1.6.0-beta.1-b9947ddcf-dn54v to (PodScheduled==False, Reason=Unschedulable)
E0319 16:43:39.518148       1 scheduler.go:481] error selecting node for pod: no nodes available to schedule pods
I0319 16:43:39.525807       1 backoff_utils.go:79] Backing off 4s
I0319 16:43:40.118086       1 wrap.go:47] GET /healthz: (452.824µs) 200 [kube-probe/1.15+ 127.0.0.1:48504]
I0319 16:43:40.286316       1 scheduling_queue.go:908] About to try and schedule pod kube-system/kubernetes-dashboard-85bcf5dbf8-p8g76
I0319 16:43:40.286354       1 scheduler.go:453] Attempting to schedule pod: kube-system/kubernetes-dashboard-85bcf5dbf8-p8g76
I0319 16:43:40.286411       1 factory.go:644] Unable to schedule kube-system/kubernetes-dashboard-85bcf5dbf8-p8g76: no nodes are registered to the cluster; waiting
I0319 16:43:40.286441       1 factory.go:742] Updating pod condition for kube-system/kubernetes-dashboard-85bcf5dbf8-p8g76 to (PodScheduled==False, Reason=Unschedulable)
E0319 16:43:40.309435       1 scheduler.go:481] error selecting node for pod: no nodes available to schedule pods
I0319 16:43:40.309508       1 scheduling_queue.go:908] About to try and schedule pod kube-system/kubernetes-dashboard-85bcf5dbf8-p8g76
I0319 16:43:40.309523       1 scheduler.go:453] Attempting to schedule pod: kube-system/kubernetes-dashboard-85bcf5dbf8-p8g76
I0319 16:43:40.309579       1 factory.go:644] Unable to schedule kube-system/kubernetes-dashboard-85bcf5dbf8-p8g76: no nodes are registered to the cluster; waiting
I0319 16:43:40.309605       1 factory.go:742] Updating pod condition for kube-system/kubernetes-dashboard-85bcf5dbf8-p8g76 to (PodScheduled==False, Reason=Unschedulable)
E0319 16:43:40.309617       1 scheduler.go:481] error selecting node for pod: no nodes available to schedule pods
I0319 16:43:40.360684       1 scheduling_queue.go:908] About to try and schedule pod kube-system/kube-dns-autoscaler-97df449df-fnkn6
I0319 16:43:40.385147       1 scheduler.go:453] Attempting to schedule pod: kube-system/kube-dns-autoscaler-97df449df-fnkn6
I0319 16:43:40.385298       1 factory.go:644] Unable to schedule kube-system/kube-dns-autoscaler-97df449df-fnkn6: no nodes are registered to the cluster; waiting
I0319 16:43:40.385359       1 factory.go:742] Updating pod condition for kube-system/kube-dns-autoscaler-97df449df-fnkn6 to (PodScheduled==False, Reason=Unschedulable)
E0319 16:43:40.399766       1 scheduler.go:481] error selecting node for pod: no nodes available to schedule pods
I0319 16:43:40.400284       1 scheduling_queue.go:908] About to try and schedule pod kube-system/kube-dns-autoscaler-97df449df-fnkn6
I0319 16:43:40.400303       1 scheduler.go:453] Attempting to schedule pod: kube-system/kube-dns-autoscaler-97df449df-fnkn6
I0319 16:43:40.400334       1 factory.go:644] Unable to schedule kube-system/kube-dns-autoscaler-97df449df-fnkn6: no nodes are registered to the cluster; waiting
I0319 16:43:40.400358       1 factory.go:742] Updating pod condition for kube-system/kube-dns-autoscaler-97df449df-fnkn6 to (PodScheduled==False, Reason=Unschedulable)
E0319 16:43:40.400370       1 scheduler.go:481] error selecting node for pod: no nodes available to schedule pods
I0319 16:43:41.901813       1 scheduling_queue.go:908] About to try and schedule pod kube-system/metrics-server-v0.3.1-677c578bdf-zvr7g
I0319 16:43:41.901841       1 scheduler.go:453] Attempting to schedule pod: kube-system/metrics-server-v0.3.1-677c578bdf-zvr7g
I0319 16:43:41.903195       1 factory.go:647] Unable to schedule kube-system/metrics-server-v0.3.1-677c578bdf-zvr7g: no fit: 0/1 nodes are available: 1 node(s) were unschedulable.; waiting
I0319 16:43:41.903267       1 factory.go:742] Updating pod condition for kube-system/metrics-server-v0.3.1-677c578bdf-zvr7g to (PodScheduled==False, Reason=Unschedulable)
I0319 16:43:41.935932       1 backoff_utils.go:79] Backing off 4s
I0319 16:43:41.977517       1 generic_scheduler.go:308] Preemption will not help schedule pod kube-system/metrics-server-v0.3.1-677c578bdf-zvr7g on any node.
I0319 16:43:41.977666       1 scheduling_queue.go:908] About to try and schedule pod kube-system/fluentd-gcp-v3.2.0-t7wjl
I0319 16:43:41.977677       1 scheduler.go:453] Attempting to schedule pod: kube-system/fluentd-gcp-v3.2.0-t7wjl
I0319 16:43:41.978011       1 scheduler_binder.go:269] AssumePodVolumes for pod "kube-system/fluentd-gcp-v3.2.0-t7wjl", node "e2e-test-peterhornyack-master"
I0319 16:43:41.980108       1 scheduler_binder.go:279] AssumePodVolumes for pod "kube-system/fluentd-gcp-v3.2.0-t7wjl", node "e2e-test-peterhornyack-master": all PVCs bound and nothing to do
I0319 16:43:41.983252       1 factory.go:733] Attempting to bind fluentd-gcp-v3.2.0-t7wjl to e2e-test-peterhornyack-master
I0319 16:43:41.983737       1 scheduling_queue.go:908] About to try and schedule pod kube-system/metadata-proxy-v0.1-t99fq
I0319 16:43:41.983753       1 scheduler.go:453] Attempting to schedule pod: kube-system/metadata-proxy-v0.1-t99fq
I0319 16:43:41.983910       1 scheduler_binder.go:269] AssumePodVolumes for pod "kube-system/metadata-proxy-v0.1-t99fq", node "e2e-test-peterhornyack-master"
I0319 16:43:41.983922       1 scheduler_binder.go:279] AssumePodVolumes for pod "kube-system/metadata-proxy-v0.1-t99fq", node "e2e-test-peterhornyack-master": all PVCs bound and nothing to do
I0319 16:43:41.983957       1 factory.go:733] Attempting to bind metadata-proxy-v0.1-t99fq to e2e-test-peterhornyack-master
I0319 16:43:41.992337       1 scheduling_queue.go:908] About to try and schedule pod kube-system/kubernetes-dashboard-85bcf5dbf8-p8g76
I0319 16:43:41.992362       1 scheduler.go:453] Attempting to schedule pod: kube-system/kubernetes-dashboard-85bcf5dbf8-p8g76
I0319 16:43:41.992903       1 factory.go:647] Unable to schedule kube-system/kubernetes-dashboard-85bcf5dbf8-p8g76: no fit: 0/1 nodes are available: 1 node(s) were unschedulable.; waiting
I0319 16:43:41.992970       1 factory.go:742] Updating pod condition for kube-system/kubernetes-dashboard-85bcf5dbf8-p8g76 to (PodScheduled==False, Reason=Unschedulable)
I0319 16:43:42.023684       1 scheduler.go:572] pod kube-system/fluentd-gcp-v3.2.0-t7wjl is bound successfully on node e2e-test-peterhornyack-master, 1 nodes evaluated, 1 nodes were found feasible
I0319 16:43:42.050351       1 scheduler.go:572] pod kube-system/metadata-proxy-v0.1-t99fq is bound successfully on node e2e-test-peterhornyack-master, 1 nodes evaluated, 1 nodes were found feasible
I0319 16:43:42.096613       1 generic_scheduler.go:308] Preemption will not help schedule pod kube-system/kubernetes-dashboard-85bcf5dbf8-p8g76 on any node.
I0319 16:43:42.097719       1 scheduling_queue.go:908] About to try and schedule pod kube-system/kube-dns-autoscaler-97df449df-fnkn6
I0319 16:43:42.097756       1 scheduler.go:453] Attempting to schedule pod: kube-system/kube-dns-autoscaler-97df449df-fnkn6
I0319 16:43:42.097866       1 factory.go:647] Unable to schedule kube-system/kube-dns-autoscaler-97df449df-fnkn6: no fit: 0/1 nodes are available: 1 node(s) were unschedulable.; waiting
I0319 16:43:42.098519       1 factory.go:742] Updating pod condition for kube-system/kube-dns-autoscaler-97df449df-fnkn6 to (PodScheduled==False, Reason=Unschedulable)
I0319 16:43:42.153239       1 backoff_utils.go:79] Backing off 2s
I0319 16:43:42.171274       1 generic_scheduler.go:308] Preemption will not help schedule pod kube-system/kube-dns-autoscaler-97df449df-fnkn6 on any node.
I0319 16:43:42.171356       1 scheduling_queue.go:908] About to try and schedule pod kube-system/kubernetes-dashboard-85bcf5dbf8-p8g76
I0319 16:43:42.171366       1 scheduler.go:453] Attempting to schedule pod: kube-system/kubernetes-dashboard-85bcf5dbf8-p8g76
I0319 16:43:42.171460       1 factory.go:647] Unable to schedule kube-system/kubernetes-dashboard-85bcf5dbf8-p8g76: no fit: 0/1 nodes are available: 1 node(s) were unschedulable.; waiting
I0319 16:43:42.171492       1 factory.go:742] Updating pod condition for kube-system/kubernetes-dashboard-85bcf5dbf8-p8g76 to (PodScheduled==False, Reason=Unschedulable)
I0319 16:43:42.193818       1 backoff_utils.go:79] Backing off 2s
I0319 16:43:42.194718       1 generic_scheduler.go:308] Preemption will not help schedule pod kube-system/kubernetes-dashboard-85bcf5dbf8-p8g76 on any node.
I0319 16:43:42.198773       1 scheduling_queue.go:908] About to try and schedule pod kube-system/kube-dns-autoscaler-97df449df-fnkn6
I0319 16:43:42.198796       1 scheduler.go:453] Attempting to schedule pod: kube-system/kube-dns-autoscaler-97df449df-fnkn6
I0319 16:43:42.198880       1 factory.go:647] Unable to schedule kube-system/kube-dns-autoscaler-97df449df-fnkn6: no fit: 0/1 nodes are available: 1 node(s) were unschedulable.; waiting
I0319 16:43:42.198910       1 factory.go:742] Updating pod condition for kube-system/kube-dns-autoscaler-97df449df-fnkn6 to (PodScheduled==False, Reason=Unschedulable)
I0319 16:43:42.204804       1 generic_scheduler.go:308] Preemption will not help schedule pod kube-system/kube-dns-autoscaler-97df449df-fnkn6 on any node.
I0319 16:43:42.205475       1 scheduling_queue.go:908] About to try and schedule pod kube-system/event-exporter-v0.2.3-77f59d4b59-mdcvl
I0319 16:43:42.205500       1 scheduler.go:453] Attempting to schedule pod: kube-system/event-exporter-v0.2.3-77f59d4b59-mdcvl
I0319 16:43:42.205568       1 factory.go:647] Unable to schedule kube-system/event-exporter-v0.2.3-77f59d4b59-mdcvl: no fit: 0/1 nodes are available: 1 node(s) were unschedulable.; waiting
I0319 16:43:42.205594       1 factory.go:742] Updating pod condition for kube-system/event-exporter-v0.2.3-77f59d4b59-mdcvl to (PodScheduled==False, Reason=Unschedulable)
I0319 16:43:42.222314       1 generic_scheduler.go:308] Preemption will not help schedule pod kube-system/event-exporter-v0.2.3-77f59d4b59-mdcvl on any node.
I0319 16:43:42.222391       1 scheduling_queue.go:908] About to try and schedule pod kube-system/fluentd-gcp-scaler-85cdd7d7c5-7lm6p
I0319 16:43:42.222402       1 scheduler.go:453] Attempting to schedule pod: kube-system/fluentd-gcp-scaler-85cdd7d7c5-7lm6p
I0319 16:43:42.222478       1 factory.go:647] Unable to schedule kube-system/fluentd-gcp-scaler-85cdd7d7c5-7lm6p: no fit: 0/1 nodes are available: 1 node(s) were unschedulable.; waiting
I0319 16:43:42.222505       1 factory.go:742] Updating pod condition for kube-system/fluentd-gcp-scaler-85cdd7d7c5-7lm6p to (PodScheduled==False, Reason=Unschedulable)
I0319 16:43:42.282919       1 backoff_utils.go:79] Backing off 2s
I0319 16:43:42.304829       1 generic_scheduler.go:308] Preemption will not help schedule pod kube-system/fluentd-gcp-scaler-85cdd7d7c5-7lm6p on any node.
I0319 16:43:42.304915       1 scheduling_queue.go:908] About to try and schedule pod kube-system/event-exporter-v0.2.3-77f59d4b59-mdcvl
I0319 16:43:42.304926       1 scheduler.go:453] Attempting to schedule pod: kube-system/event-exporter-v0.2.3-77f59d4b59-mdcvl
I0319 16:43:42.313405       1 factory.go:647] Unable to schedule kube-system/event-exporter-v0.2.3-77f59d4b59-mdcvl: no fit: 0/1 nodes are available: 1 node(s) were unschedulable.; waiting
I0319 16:43:42.313485       1 factory.go:742] Updating pod condition for kube-system/event-exporter-v0.2.3-77f59d4b59-mdcvl to (PodScheduled==False, Reason=Unschedulable)
I0319 16:43:42.347843       1 generic_scheduler.go:308] Preemption will not help schedule pod kube-system/event-exporter-v0.2.3-77f59d4b59-mdcvl on any node.
I0319 16:43:42.352546       1 backoff_utils.go:79] Backing off 4s
I0319 16:43:43.521984       1 scheduling_queue.go:908] About to try and schedule pod kube-system/coredns-5b969f4c88-sn584
I0319 16:43:43.522017       1 scheduler.go:453] Attempting to schedule pod: kube-system/coredns-5b969f4c88-sn584
I0319 16:43:43.522164       1 factory.go:647] Unable to schedule kube-system/coredns-5b969f4c88-sn584: no fit: 0/1 nodes are available: 1 node(s) were unschedulable.; waiting
I0319 16:43:43.522205       1 factory.go:742] Updating pod condition for kube-system/coredns-5b969f4c88-sn584 to (PodScheduled==False, Reason=Unschedulable)
I0319 16:43:43.547695       1 backoff_utils.go:79] Backing off 8s
I0319 16:43:43.559689       1 generic_scheduler.go:308] Preemption will not help schedule pod kube-system/coredns-5b969f4c88-sn584 on any node.
I0319 16:43:43.559831       1 scheduling_queue.go:908] About to try and schedule pod kube-system/l7-default-backend-8f479dd9-5qggn
I0319 16:43:43.559844       1 scheduler.go:453] Attempting to schedule pod: kube-system/l7-default-backend-8f479dd9-5qggn
I0319 16:43:43.559930       1 factory.go:647] Unable to schedule kube-system/l7-default-backend-8f479dd9-5qggn: no fit: 0/1 nodes are available: 1 node(s) were unschedulable.; waiting
I0319 16:43:43.559963       1 factory.go:742] Updating pod condition for kube-system/l7-default-backend-8f479dd9-5qggn to (PodScheduled==False, Reason=Unschedulable)
I0319 16:43:43.576853       1 backoff_utils.go:79] Backing off 8s
I0319 16:43:43.586089       1 generic_scheduler.go:308] Preemption will not help schedule pod kube-system/l7-default-backend-8f479dd9-5qggn on any node.
I0319 16:43:44.522206       1 scheduling_queue.go:908] About to try and schedule pod kube-system/heapster-v1.6.0-beta.1-b9947ddcf-dn54v
I0319 16:43:44.522252       1 scheduler.go:453] Attempting to schedule pod: kube-system/heapster-v1.6.0-beta.1-b9947ddcf-dn54v
I0319 16:43:44.522401       1 factory.go:647] Unable to schedule kube-system/heapster-v1.6.0-beta.1-b9947ddcf-dn54v: no fit: 0/1 nodes are available: 1 node(s) were unschedulable.; waiting
I0319 16:43:44.522468       1 factory.go:742] Updating pod condition for kube-system/heapster-v1.6.0-beta.1-b9947ddcf-dn54v to (PodScheduled==False, Reason=Unschedulable)
I0319 16:43:44.560394       1 generic_scheduler.go:308] Preemption will not help schedule pod kube-system/heapster-v1.6.0-beta.1-b9947ddcf-dn54v on any node.
I0319 16:43:44.560546       1 scheduling_queue.go:908] About to try and schedule pod kube-system/kubernetes-dashboard-85bcf5dbf8-p8g76
I0319 16:43:44.560566       1 scheduler.go:453] Attempting to schedule pod: kube-system/kubernetes-dashboard-85bcf5dbf8-p8g76
I0319 16:43:44.560678       1 factory.go:647] Unable to schedule kube-system/kubernetes-dashboard-85bcf5dbf8-p8g76: no fit: 0/1 nodes are available: 1 node(s) were unschedulable.; waiting
I0319 16:43:44.560709       1 factory.go:742] Updating pod condition for kube-system/kubernetes-dashboard-85bcf5dbf8-p8g76 to (PodScheduled==False, Reason=Unschedulable)
I0319 16:43:44.571338       1 generic_scheduler.go:308] Preemption will not help schedule pod kube-system/kubernetes-dashboard-85bcf5dbf8-p8g76 on any node.
I0319 16:43:44.577423       1 backoff_utils.go:79] Backing off 4s
I0319 16:43:44.577818       1 scheduling_queue.go:908] About to try and schedule pod kube-system/kube-dns-autoscaler-97df449df-fnkn6
I0319 16:43:44.577836       1 scheduler.go:453] Attempting to schedule pod: kube-system/kube-dns-autoscaler-97df449df-fnkn6
I0319 16:43:44.577926       1 factory.go:647] Unable to schedule kube-system/kube-dns-autoscaler-97df449df-fnkn6: no fit: 0/1 nodes are available: 1 node(s) were unschedulable.; waiting
I0319 16:43:44.577972       1 factory.go:742] Updating pod condition for kube-system/kube-dns-autoscaler-97df449df-fnkn6 to (PodScheduled==False, Reason=Unschedulable)
I0319 16:43:44.595839       1 generic_scheduler.go:308] Preemption will not help schedule pod kube-system/kube-dns-autoscaler-97df449df-fnkn6 on any node.
I0319 16:43:44.601099       1 backoff_utils.go:79] Backing off 4s
I0319 16:43:44.601165       1 scheduling_queue.go:908] About to try and schedule pod kube-system/heapster-v1.6.0-beta.1-b9947ddcf-dn54v
I0319 16:43:44.601176       1 scheduler.go:453] Attempting to schedule pod: kube-system/heapster-v1.6.0-beta.1-b9947ddcf-dn54v
I0319 16:43:44.601305       1 factory.go:647] Unable to schedule kube-system/heapster-v1.6.0-beta.1-b9947ddcf-dn54v: no fit: 0/1 nodes are available: 1 node(s) were unschedulable.; waiting
I0319 16:43:44.601338       1 factory.go:742] Updating pod condition for kube-system/heapster-v1.6.0-beta.1-b9947ddcf-dn54v to (PodScheduled==False, Reason=Unschedulable)
I0319 16:43:44.619583       1 backoff_utils.go:79] Backing off 8s
I0319 16:43:44.619673       1 generic_scheduler.go:308] Preemption will not help schedule pod kube-system/heapster-v1.6.0-beta.1-b9947ddcf-dn54v on any node.
I0319 16:43:44.637559       1 scheduling_queue.go:908] About to try and schedule pod kube-system/fluentd-gcp-scaler-85cdd7d7c5-7lm6p
I0319 16:43:44.637584       1 scheduler.go:453] Attempting to schedule pod: kube-system/fluentd-gcp-scaler-85cdd7d7c5-7lm6p
I0319 16:43:44.640327       1 factory.go:647] Unable to schedule kube-system/fluentd-gcp-scaler-85cdd7d7c5-7lm6p: no fit: 0/1 nodes are available: 1 node(s) were unschedulable.; waiting
I0319 16:43:44.640398       1 factory.go:742] Updating pod condition for kube-system/fluentd-gcp-scaler-85cdd7d7c5-7lm6p to (PodScheduled==False, Reason=Unschedulable)
I0319 16:43:44.661300       1 generic_scheduler.go:308] Preemption will not help schedule pod kube-system/fluentd-gcp-scaler-85cdd7d7c5-7lm6p on any node.
I0319 16:43:44.661498       1 backoff_utils.go:79] Backing off 4s
I0319 16:43:46.522619       1 scheduling_queue.go:908] About to try and schedule pod kube-system/metrics-server-v0.3.1-677c578bdf-zvr7g
I0319 16:43:46.522683       1 scheduler.go:453] Attempting to schedule pod: kube-system/metrics-server-v0.3.1-677c578bdf-zvr7g
I0319 16:43:46.522811       1 factory.go:647] Unable to schedule kube-system/metrics-server-v0.3.1-677c578bdf-zvr7g: no fit: 0/1 nodes are available: 1 node(s) were unschedulable.; waiting
I0319 16:43:46.522864       1 factory.go:742] Updating pod condition for kube-system/metrics-server-v0.3.1-677c578bdf-zvr7g to (PodScheduled==False, Reason=Unschedulable)
I0319 16:43:46.691666       1 backoff_utils.go:79] Backing off 8s
I0319 16:43:46.691763       1 generic_scheduler.go:308] Preemption will not help schedule pod kube-system/metrics-server-v0.3.1-677c578bdf-zvr7g on any node.
I0319 16:43:46.691826       1 scheduling_queue.go:908] About to try and schedule pod kube-system/event-exporter-v0.2.3-77f59d4b59-mdcvl
I0319 16:43:46.691836       1 scheduler.go:453] Attempting to schedule pod: kube-system/event-exporter-v0.2.3-77f59d4b59-mdcvl
I0319 16:43:46.691907       1 factory.go:647] Unable to schedule kube-system/event-exporter-v0.2.3-77f59d4b59-mdcvl: no fit: 0/1 nodes are available: 1 node(s) were unschedulable.; waiting
I0319 16:43:46.691938       1 factory.go:742] Updating pod condition for kube-system/event-exporter-v0.2.3-77f59d4b59-mdcvl to (PodScheduled==False, Reason=Unschedulable)
I0319 16:43:46.695346       1 generic_scheduler.go:308] Preemption will not help schedule pod kube-system/event-exporter-v0.2.3-77f59d4b59-mdcvl on any node.
I0319 16:43:46.699760       1 backoff_utils.go:79] Backing off 8s
I0319 16:43:49.523512       1 scheduling_queue.go:908] About to try and schedule pod kube-system/kubernetes-dashboard-85bcf5dbf8-p8g76
I0319 16:43:49.523546       1 scheduler.go:453] Attempting to schedule pod: kube-system/kubernetes-dashboard-85bcf5dbf8-p8g76
I0319 16:43:49.523683       1 factory.go:647] Unable to schedule kube-system/kubernetes-dashboard-85bcf5dbf8-p8g76: no fit: 0/1 nodes are available: 1 node(s) were unschedulable.; waiting
I0319 16:43:49.523725       1 factory.go:742] Updating pod condition for kube-system/kubernetes-dashboard-85bcf5dbf8-p8g76 to (PodScheduled==False, Reason=Unschedulable)
I0319 16:43:49.538700       1 generic_scheduler.go:308] Preemption will not help schedule pod kube-system/kubernetes-dashboard-85bcf5dbf8-p8g76 on any node.
I0319 16:43:49.542441       1 backoff_utils.go:79] Backing off 8s
I0319 16:43:49.542513       1 scheduling_queue.go:908] About to try and schedule pod kube-system/kube-dns-autoscaler-97df449df-fnkn6
I0319 16:43:49.542539       1 scheduler.go:453] Attempting to schedule pod: kube-system/kube-dns-autoscaler-97df449df-fnkn6
I0319 16:43:49.542680       1 factory.go:647] Unable to schedule kube-system/kube-dns-autoscaler-97df449df-fnkn6: no fit: 0/1 nodes are available: 1 node(s) were unschedulable.; waiting
I0319 16:43:49.542729       1 factory.go:742] Updating pod condition for kube-system/kube-dns-autoscaler-97df449df-fnkn6 to (PodScheduled==False, Reason=Unschedulable)
I0319 16:43:49.563603       1 generic_scheduler.go:308] Preemption will not help schedule pod kube-system/kube-dns-autoscaler-97df449df-fnkn6 on any node.
I0319 16:43:49.563715       1 scheduling_queue.go:908] About to try and schedule pod kube-system/fluentd-gcp-scaler-85cdd7d7c5-7lm6p
I0319 16:43:49.563727       1 scheduler.go:453] Attempting to schedule pod: kube-system/fluentd-gcp-scaler-85cdd7d7c5-7lm6p
I0319 16:43:49.563807       1 factory.go:647] Unable to schedule kube-system/fluentd-gcp-scaler-85cdd7d7c5-7lm6p: no fit: 0/1 nodes are available: 1 node(s) were unschedulable.; waiting
I0319 16:43:49.563841       1 factory.go:742] Updating pod condition for kube-system/fluentd-gcp-scaler-85cdd7d7c5-7lm6p to (PodScheduled==False, Reason=Unschedulable)
I0319 16:43:49.576849       1 generic_scheduler.go:308] Preemption will not help schedule pod kube-system/fluentd-gcp-scaler-85cdd7d7c5-7lm6p on any node.
I0319 16:43:49.581223       1 backoff_utils.go:79] Backing off 8s
I0319 16:43:49.585409       1 backoff_utils.go:79] Backing off 8s
I0319 16:43:50.117770       1 wrap.go:47] GET /healthz: (102.644µs) 200 [kube-probe/1.15+ 127.0.0.1:48596]
I0319 16:43:52.524088       1 scheduling_queue.go:908] About to try and schedule pod kube-system/coredns-5b969f4c88-sn584
I0319 16:43:52.524117       1 scheduler.go:453] Attempting to schedule pod: kube-system/coredns-5b969f4c88-sn584
I0319 16:43:52.524239       1 factory.go:647] Unable to schedule kube-system/coredns-5b969f4c88-sn584: no fit: 0/1 nodes are available: 1 node(s) were unschedulable.; waiting
I0319 16:43:52.524288       1 factory.go:742] Updating pod condition for kube-system/coredns-5b969f4c88-sn584 to (PodScheduled==False, Reason=Unschedulable)
I0319 16:43:52.542490       1 backoff_utils.go:79] Backing off 10s
I0319 16:43:52.542589       1 generic_scheduler.go:308] Preemption will not help schedule pod kube-system/coredns-5b969f4c88-sn584 on any node.
I0319 16:43:52.542654       1 scheduling_queue.go:908] About to try and schedule pod kube-system/l7-default-backend-8f479dd9-5qggn
I0319 16:43:52.542666       1 scheduler.go:453] Attempting to schedule pod: kube-system/l7-default-backend-8f479dd9-5qggn
I0319 16:43:52.542748       1 factory.go:647] Unable to schedule kube-system/l7-default-backend-8f479dd9-5qggn: no fit: 0/1 nodes are available: 1 node(s) were unschedulable.; waiting
I0319 16:43:52.542777       1 factory.go:742] Updating pod condition for kube-system/l7-default-backend-8f479dd9-5qggn to (PodScheduled==False, Reason=Unschedulable)
I0319 16:43:52.554449       1 generic_scheduler.go:308] Preemption will not help schedule pod kube-system/l7-default-backend-8f479dd9-5qggn on any node.
I0319 16:43:52.565308       1 backoff_utils.go:79] Backing off 10s
I0319 16:43:53.524286       1 scheduling_queue.go:908] About to try and schedule pod kube-system/heapster-v1.6.0-beta.1-b9947ddcf-dn54v
I0319 16:43:53.524322       1 scheduler.go:453] Attempting to schedule pod: kube-system/heapster-v1.6.0-beta.1-b9947ddcf-dn54v
I0319 16:43:53.524462       1 factory.go:647] Unable to schedule kube-system/heapster-v1.6.0-beta.1-b9947ddcf-dn54v: no fit: 0/1 nodes are available: 1 node(s) were unschedulable.; waiting
I0319 16:43:53.524519       1 factory.go:742] Updating pod condition for kube-system/heapster-v1.6.0-beta.1-b9947ddcf-dn54v to (PodScheduled==False, Reason=Unschedulable)
I0319 16:43:53.550631       1 backoff_utils.go:79] Backing off 10s
I0319 16:43:53.550758       1 generic_scheduler.go:308] Preemption will not help schedule pod kube-system/heapster-v1.6.0-beta.1-b9947ddcf-dn54v on any node.
I0319 16:43:55.524720       1 scheduling_queue.go:908] About to try and schedule pod kube-system/metrics-server-v0.3.1-677c578bdf-zvr7g
I0319 16:43:55.524749       1 scheduler.go:453] Attempting to schedule pod: kube-system/metrics-server-v0.3.1-677c578bdf-zvr7g
I0319 16:43:55.524904       1 factory.go:647] Unable to schedule kube-system/metrics-server-v0.3.1-677c578bdf-zvr7g: no fit: 0/1 nodes are available: 1 node(s) were unschedulable.; waiting
I0319 16:43:55.524962       1 factory.go:742] Updating pod condition for kube-system/metrics-server-v0.3.1-677c578bdf-zvr7g to (PodScheduled==False, Reason=Unschedulable)
I0319 16:43:55.540411       1 generic_scheduler.go:308] Preemption will not help schedule pod kube-system/metrics-server-v0.3.1-677c578bdf-zvr7g on any node.
I0319 16:43:55.540507       1 scheduling_queue.go:908] About to try and schedule pod kube-system/event-exporter-v0.2.3-77f59d4b59-mdcvl
I0319 16:43:55.540517       1 scheduler.go:453] Attempting to schedule pod: kube-system/event-exporter-v0.2.3-77f59d4b59-mdcvl
I0319 16:43:55.540601       1 factory.go:647] Unable to schedule kube-system/event-exporter-v0.2.3-77f59d4b59-mdcvl: no fit: 0/1 nodes are available: 1 node(s) were unschedulable.; waiting
I0319 16:43:55.540646       1 factory.go:742] Updating pod condition for kube-system/event-exporter-v0.2.3-77f59d4b59-mdcvl to (PodScheduled==False, Reason=Unschedulable)
I0319 16:43:55.558069       1 generic_scheduler.go:308] Preemption will not help schedule pod kube-system/event-exporter-v0.2.3-77f59d4b59-mdcvl on any node.
I0319 16:43:55.565565       1 backoff_utils.go:79] Backing off 10s
I0319 16:43:55.565774       1 backoff_utils.go:79] Backing off 10s
I0319 16:44:00.137898       1 wrap.go:47] GET /healthz: (77.129µs) 200 [kube-probe/1.15+ 127.0.0.1:48628]
I0319 16:44:10.118184       1 wrap.go:47] GET /healthz: (77.316µs) 200 [kube-probe/1.15+ 127.0.0.1:48754]
I0319 16:44:20.117986       1 wrap.go:47] GET /healthz: (63.208µs) 200 [kube-probe/1.15+ 127.0.0.1:48784]
I0319 16:44:30.117884       1 wrap.go:47] GET /healthz: (71.184µs) 200 [kube-probe/1.15+ 127.0.0.1:48816]
I0319 16:44:40.118089       1 wrap.go:47] GET /healthz: (103.364µs) 200 [kube-probe/1.15+ 127.0.0.1:48862]
I0319 16:44:50.117957       1 wrap.go:47] GET /healthz: (82.244µs) 200 [kube-probe/1.15+ 127.0.0.1:48896]
I0319 16:44:53.462322       1 scheduling_queue.go:908] About to try and schedule pod kube-system/kubernetes-dashboard-85bcf5dbf8-p8g76
I0319 16:44:53.462421       1 scheduler.go:453] Attempting to schedule pod: kube-system/kubernetes-dashboard-85bcf5dbf8-p8g76
I0319 16:44:53.462614       1 factory.go:647] Unable to schedule kube-system/kubernetes-dashboard-85bcf5dbf8-p8g76: no fit: 0/1 nodes are available: 1 node(s) were unschedulable.; waiting
I0319 16:44:53.462672       1 factory.go:742] Updating pod condition for kube-system/kubernetes-dashboard-85bcf5dbf8-p8g76 to (PodScheduled==False, Reason=Unschedulable)
I0319 16:44:53.473259       1 generic_scheduler.go:308] Preemption will not help schedule pod kube-system/kubernetes-dashboard-85bcf5dbf8-p8g76 on any node.
I0319 16:44:53.473354       1 scheduling_queue.go:908] About to try and schedule pod kube-system/kube-dns-autoscaler-97df449df-fnkn6
I0319 16:44:53.473366       1 scheduler.go:453] Attempting to schedule pod: kube-system/kube-dns-autoscaler-97df449df-fnkn6
I0319 16:44:53.473467       1 factory.go:647] Unable to schedule kube-system/kube-dns-autoscaler-97df449df-fnkn6: no fit: 0/1 nodes are available: 1 node(s) were unschedulable.; waiting
I0319 16:44:53.473500       1 factory.go:742] Updating pod condition for kube-system/kube-dns-autoscaler-97df449df-fnkn6 to (PodScheduled==False, Reason=Unschedulable)
I0319 16:44:53.476722       1 generic_scheduler.go:308] Preemption will not help schedule pod kube-system/kube-dns-autoscaler-97df449df-fnkn6 on any node.
I0319 16:44:53.482657       1 scheduling_queue.go:908] About to try and schedule pod kube-system/coredns-5b969f4c88-sn584
I0319 16:44:53.482684       1 scheduler.go:453] Attempting to schedule pod: kube-system/coredns-5b969f4c88-sn584
I0319 16:44:53.482833       1 factory.go:647] Unable to schedule kube-system/coredns-5b969f4c88-sn584: no fit: 0/1 nodes are available: 1 node(s) were unschedulable.; waiting
I0319 16:44:53.482868       1 factory.go:742] Updating pod condition for kube-system/coredns-5b969f4c88-sn584 to (PodScheduled==False, Reason=Unschedulable)
I0319 16:44:53.489201       1 generic_scheduler.go:308] Preemption will not help schedule pod kube-system/coredns-5b969f4c88-sn584 on any node.
I0319 16:44:53.489575       1 scheduling_queue.go:908] About to try and schedule pod kube-system/fluentd-gcp-scaler-85cdd7d7c5-7lm6p
I0319 16:44:53.489607       1 scheduler.go:453] Attempting to schedule pod: kube-system/fluentd-gcp-scaler-85cdd7d7c5-7lm6p
I0319 16:44:53.489697       1 factory.go:647] Unable to schedule kube-system/fluentd-gcp-scaler-85cdd7d7c5-7lm6p: no fit: 0/1 nodes are available: 1 node(s) were unschedulable.; waiting
I0319 16:44:53.489727       1 factory.go:742] Updating pod condition for kube-system/fluentd-gcp-scaler-85cdd7d7c5-7lm6p to (PodScheduled==False, Reason=Unschedulable)
I0319 16:44:53.495407       1 generic_scheduler.go:308] Preemption will not help schedule pod kube-system/fluentd-gcp-scaler-85cdd7d7c5-7lm6p on any node.
I0319 16:44:53.497395       1 scheduling_queue.go:908] About to try and schedule pod kube-system/l7-default-backend-8f479dd9-5qggn
I0319 16:44:53.497440       1 scheduler.go:453] Attempting to schedule pod: kube-system/l7-default-backend-8f479dd9-5qggn
I0319 16:44:53.497549       1 factory.go:647] Unable to schedule kube-system/l7-default-backend-8f479dd9-5qggn: no fit: 0/1 nodes are available: 1 node(s) were unschedulable.; waiting
I0319 16:44:53.497577       1 factory.go:742] Updating pod condition for kube-system/l7-default-backend-8f479dd9-5qggn to (PodScheduled==False, Reason=Unschedulable)
I0319 16:44:53.503644       1 generic_scheduler.go:308] Preemption will not help schedule pod kube-system/l7-default-backend-8f479dd9-5qggn on any node.
I0319 16:45:00.120288       1 wrap.go:47] GET /healthz: (127.28µs) 200 [kube-probe/1.15+ 127.0.0.1:48930]
I0319 16:45:10.118059       1 wrap.go:47] GET /healthz: (98.091µs) 200 [kube-probe/1.15+ 127.0.0.1:48976]
I0319 16:45:20.118075       1 wrap.go:47] GET /healthz: (112.564µs) 200 [kube-probe/1.15+ 127.0.0.1:49012]
I0319 16:45:23.462534       1 scheduling_queue.go:908] About to try and schedule pod kube-system/heapster-v1.6.0-beta.1-b9947ddcf-dn54v
I0319 16:45:23.462594       1 scheduler.go:453] Attempting to schedule pod: kube-system/heapster-v1.6.0-beta.1-b9947ddcf-dn54v
I0319 16:45:23.462782       1 factory.go:647] Unable to schedule kube-system/heapster-v1.6.0-beta.1-b9947ddcf-dn54v: no fit: 0/1 nodes are available: 1 node(s) were unschedulable.; waiting
I0319 16:45:23.462839       1 factory.go:742] Updating pod condition for kube-system/heapster-v1.6.0-beta.1-b9947ddcf-dn54v to (PodScheduled==False, Reason=Unschedulable)
I0319 16:45:23.470765       1 generic_scheduler.go:308] Preemption will not help schedule pod kube-system/heapster-v1.6.0-beta.1-b9947ddcf-dn54v on any node.
I0319 16:45:23.470975       1 scheduling_queue.go:908] About to try and schedule pod kube-system/metrics-server-v0.3.1-677c578bdf-zvr7g
I0319 16:45:23.470987       1 scheduler.go:453] Attempting to schedule pod: kube-system/metrics-server-v0.3.1-677c578bdf-zvr7g
I0319 16:45:23.471096       1 factory.go:647] Unable to schedule kube-system/metrics-server-v0.3.1-677c578bdf-zvr7g: no fit: 0/1 nodes are available: 1 node(s) were unschedulable.; waiting
I0319 16:45:23.471155       1 factory.go:742] Updating pod condition for kube-system/metrics-server-v0.3.1-677c578bdf-zvr7g to (PodScheduled==False, Reason=Unschedulable)
I0319 16:45:23.474613       1 generic_scheduler.go:308] Preemption will not help schedule pod kube-system/metrics-server-v0.3.1-677c578bdf-zvr7g on any node.
I0319 16:45:23.476806       1 scheduling_queue.go:908] About to try and schedule pod kube-system/event-exporter-v0.2.3-77f59d4b59-mdcvl
I0319 16:45:23.476828       1 scheduler.go:453] Attempting to schedule pod: kube-system/event-exporter-v0.2.3-77f59d4b59-mdcvl
I0319 16:45:23.476913       1 factory.go:647] Unable to schedule kube-system/event-exporter-v0.2.3-77f59d4b59-mdcvl: no fit: 0/1 nodes are available: 1 node(s) were unschedulable.; waiting
I0319 16:45:23.476942       1 factory.go:742] Updating pod condition for kube-system/event-exporter-v0.2.3-77f59d4b59-mdcvl to (PodScheduled==False, Reason=Unschedulable)
I0319 16:45:23.483068       1 generic_scheduler.go:308] Preemption will not help schedule pod kube-system/event-exporter-v0.2.3-77f59d4b59-mdcvl on any node.
I0319 16:45:30.118260       1 wrap.go:47] GET /healthz: (74.168µs) 200 [kube-probe/1.15+ 127.0.0.1:49046]
I0319 16:45:40.117909       1 wrap.go:47] GET /healthz: (82.222µs) 200 [kube-probe/1.15+ 127.0.0.1:49094]
I0319 16:45:50.117936       1 wrap.go:47] GET /healthz: (74.935µs) 200 [kube-probe/1.15+ 127.0.0.1:49126]
I0319 16:46:00.117902       1 wrap.go:47] GET /healthz: (70.308µs) 200 [kube-probe/1.15+ 127.0.0.1:49162]
I0319 16:46:10.117756       1 wrap.go:47] GET /healthz: (78.216µs) 200 [kube-probe/1.15+ 127.0.0.1:49200]
I0319 16:46:20.118661       1 wrap.go:47] GET /healthz: (79.207µs) 200 [kube-probe/1.15+ 127.0.0.1:49232]
I0319 16:46:23.462965       1 scheduling_queue.go:908] About to try and schedule pod kube-system/kubernetes-dashboard-85bcf5dbf8-p8g76
I0319 16:46:23.463059       1 scheduler.go:453] Attempting to schedule pod: kube-system/kubernetes-dashboard-85bcf5dbf8-p8g76
I0319 16:46:23.463221       1 factory.go:647] Unable to schedule kube-system/kubernetes-dashboard-85bcf5dbf8-p8g76: no fit: 0/1 nodes are available: 1 node(s) were unschedulable.; waiting
I0319 16:46:23.463265       1 factory.go:742] Updating pod condition for kube-system/kubernetes-dashboard-85bcf5dbf8-p8g76 to (PodScheduled==False, Reason=Unschedulable)
I0319 16:46:23.470970       1 generic_scheduler.go:308] Preemption will not help schedule pod kube-system/kubernetes-dashboard-85bcf5dbf8-p8g76 on any node.
I0319 16:46:23.471145       1 scheduling_queue.go:908] About to try and schedule pod kube-system/kube-dns-autoscaler-97df449df-fnkn6
I0319 16:46:23.471174       1 scheduler.go:453] Attempting to schedule pod: kube-system/kube-dns-autoscaler-97df449df-fnkn6
I0319 16:46:23.471268       1 factory.go:647] Unable to schedule kube-system/kube-dns-autoscaler-97df449df-fnkn6: no fit: 0/1 nodes are available: 1 node(s) were unschedulable.; waiting
I0319 16:46:23.471306       1 factory.go:742] Updating pod condition for kube-system/kube-dns-autoscaler-97df449df-fnkn6 to (PodScheduled==False, Reason=Unschedulable)
I0319 16:46:23.482735       1 generic_scheduler.go:308] Preemption will not help schedule pod kube-system/kube-dns-autoscaler-97df449df-fnkn6 on any node.
I0319 16:46:23.484363       1 scheduling_queue.go:908] About to try and schedule pod kube-system/coredns-5b969f4c88-sn584
I0319 16:46:23.484388       1 scheduler.go:453] Attempting to schedule pod: kube-system/coredns-5b969f4c88-sn584
I0319 16:46:23.484491       1 factory.go:647] Unable to schedule kube-system/coredns-5b969f4c88-sn584: no fit: 0/1 nodes are available: 1 node(s) were unschedulable.; waiting
I0319 16:46:23.484525       1 factory.go:742] Updating pod condition for kube-system/coredns-5b969f4c88-sn584 to (PodScheduled==False, Reason=Unschedulable)
I0319 16:46:23.494100       1 generic_scheduler.go:308] Preemption will not help schedule pod kube-system/coredns-5b969f4c88-sn584 on any node.
I0319 16:46:23.495093       1 scheduling_queue.go:908] About to try and schedule pod kube-system/fluentd-gcp-scaler-85cdd7d7c5-7lm6p
I0319 16:46:23.495134       1 scheduler.go:453] Attempting to schedule pod: kube-system/fluentd-gcp-scaler-85cdd7d7c5-7lm6p
I0319 16:46:23.495258       1 factory.go:647] Unable to schedule kube-system/fluentd-gcp-scaler-85cdd7d7c5-7lm6p: no fit: 0/1 nodes are available: 1 node(s) were unschedulable.; waiting
I0319 16:46:23.495316       1 factory.go:742] Updating pod condition for kube-system/fluentd-gcp-scaler-85cdd7d7c5-7lm6p to (PodScheduled==False, Reason=Unschedulable)
I0319 16:46:23.504758       1 generic_scheduler.go:308] Preemption will not help schedule pod kube-system/fluentd-gcp-scaler-85cdd7d7c5-7lm6p on any node.
I0319 16:46:23.504861       1 scheduling_queue.go:908] About to try and schedule pod kube-system/l7-default-backend-8f479dd9-5qggn
I0319 16:46:23.504888       1 scheduler.go:453] Attempting to schedule pod: kube-system/l7-default-backend-8f479dd9-5qggn
I0319 16:46:23.504985       1 factory.go:647] Unable to schedule kube-system/l7-default-backend-8f479dd9-5qggn: no fit: 0/1 nodes are available: 1 node(s) were unschedulable.; waiting
I0319 16:46:23.505039       1 factory.go:742] Updating pod condition for kube-system/l7-default-backend-8f479dd9-5qggn to (PodScheduled==False, Reason=Unschedulable)
I0319 16:46:23.513616       1 generic_scheduler.go:308] Preemption will not help schedule pod kube-system/l7-default-backend-8f479dd9-5qggn on any node.
I0319 16:46:30.118013       1 wrap.go:47] GET /healthz: (70.858µs) 200 [kube-probe/1.15+ 127.0.0.1:49266]
I0319 16:46:40.118154       1 wrap.go:47] GET /healthz: (83.027µs) 200 [kube-probe/1.15+ 127.0.0.1:49316]
I0319 16:46:50.118171       1 wrap.go:47] GET /healthz: (74.948µs) 200 [kube-probe/1.15+ 127.0.0.1:49348]
I0319 16:46:53.463214       1 scheduling_queue.go:908] About to try and schedule pod kube-system/heapster-v1.6.0-beta.1-b9947ddcf-dn54v
I0319 16:46:53.463273       1 scheduler.go:453] Attempting to schedule pod: kube-system/heapster-v1.6.0-beta.1-b9947ddcf-dn54v
I0319 16:46:53.463414       1 factory.go:647] Unable to schedule kube-system/heapster-v1.6.0-beta.1-b9947ddcf-dn54v: no fit: 0/1 nodes are available: 1 node(s) were unschedulable.; waiting
I0319 16:46:53.463459       1 factory.go:742] Updating pod condition for kube-system/heapster-v1.6.0-beta.1-b9947ddcf-dn54v to (PodScheduled==False, Reason=Unschedulable)
I0319 16:46:53.469848       1 generic_scheduler.go:308] Preemption will not help schedule pod kube-system/heapster-v1.6.0-beta.1-b9947ddcf-dn54v on any node.
I0319 16:46:53.469969       1 scheduling_queue.go:908] About to try and schedule pod kube-system/metrics-server-v0.3.1-677c578bdf-zvr7g
I0319 16:46:53.469980       1 scheduler.go:453] Attempting to schedule pod: kube-system/metrics-server-v0.3.1-677c578bdf-zvr7g
I0319 16:46:53.470069       1 factory.go:647] Unable to schedule kube-system/metrics-server-v0.3.1-677c578bdf-zvr7g: no fit: 0/1 nodes are available: 1 node(s) were unschedulable.; waiting
I0319 16:46:53.470104       1 factory.go:742] Updating pod condition for kube-system/metrics-server-v0.3.1-677c578bdf-zvr7g to (PodScheduled==False, Reason=Unschedulable)
I0319 16:46:53.480378       1 generic_scheduler.go:308] Preemption will not help schedule pod kube-system/metrics-server-v0.3.1-677c578bdf-zvr7g on any node.
I0319 16:46:53.480537       1 scheduling_queue.go:908] About to try and schedule pod kube-system/event-exporter-v0.2.3-77f59d4b59-mdcvl
I0319 16:46:53.480550       1 scheduler.go:453] Attempting to schedule pod: kube-system/event-exporter-v0.2.3-77f59d4b59-mdcvl
I0319 16:46:53.480646       1 factory.go:647] Unable to schedule kube-system/event-exporter-v0.2.3-77f59d4b59-mdcvl: no fit: 0/1 nodes are available: 1 node(s) were unschedulable.; waiting
I0319 16:46:53.480685       1 factory.go:742] Updating pod condition for kube-system/event-exporter-v0.2.3-77f59d4b59-mdcvl to (PodScheduled==False, Reason=Unschedulable)
I0319 16:46:53.486561       1 generic_scheduler.go:308] Preemption will not help schedule pod kube-system/event-exporter-v0.2.3-77f59d4b59-mdcvl on any node.
I0319 16:47:00.117894       1 wrap.go:47] GET /healthz: (78.715µs) 200 [kube-probe/1.15+ 127.0.0.1:49382]
I0319 16:47:10.117934       1 wrap.go:47] GET /healthz: (73.255µs) 200 [kube-probe/1.15+ 127.0.0.1:49422]
I0319 16:47:13.515479       1 scheduling_queue.go:908] About to try and schedule pod kube-system/kubernetes-dashboard-85bcf5dbf8-p8g76
I0319 16:47:13.515516       1 scheduler.go:453] Attempting to schedule pod: kube-system/kubernetes-dashboard-85bcf5dbf8-p8g76
I0319 16:47:13.515680       1 scheduler_binder.go:269] AssumePodVolumes for pod "kube-system/kubernetes-dashboard-85bcf5dbf8-p8g76", node "e2e-test-peterhornyack-minion-group-413w"
I0319 16:47:13.515696       1 scheduler_binder.go:279] AssumePodVolumes for pod "kube-system/kubernetes-dashboard-85bcf5dbf8-p8g76", node "e2e-test-peterhornyack-minion-group-413w": all PVCs bound and nothing to do
I0319 16:47:13.515777       1 factory.go:733] Attempting to bind kubernetes-dashboard-85bcf5dbf8-p8g76 to e2e-test-peterhornyack-minion-group-413w
I0319 16:47:13.519301       1 scheduling_queue.go:908] About to try and schedule pod kube-system/kube-dns-autoscaler-97df449df-fnkn6
I0319 16:47:13.519330       1 scheduler.go:453] Attempting to schedule pod: kube-system/kube-dns-autoscaler-97df449df-fnkn6
I0319 16:47:13.519485       1 scheduler_binder.go:269] AssumePodVolumes for pod "kube-system/kube-dns-autoscaler-97df449df-fnkn6", node "e2e-test-peterhornyack-minion-group-413w"
I0319 16:47:13.519498       1 scheduler_binder.go:279] AssumePodVolumes for pod "kube-system/kube-dns-autoscaler-97df449df-fnkn6", node "e2e-test-peterhornyack-minion-group-413w": all PVCs bound and nothing to do
I0319 16:47:13.519530       1 factory.go:733] Attempting to bind kube-dns-autoscaler-97df449df-fnkn6 to e2e-test-peterhornyack-minion-group-413w
I0319 16:47:13.527012       1 scheduling_queue.go:908] About to try and schedule pod kube-system/coredns-5b969f4c88-sn584
I0319 16:47:13.527075       1 scheduler.go:453] Attempting to schedule pod: kube-system/coredns-5b969f4c88-sn584
I0319 16:47:13.527388       1 scheduler_binder.go:269] AssumePodVolumes for pod "kube-system/coredns-5b969f4c88-sn584", node "e2e-test-peterhornyack-minion-group-413w"
I0319 16:47:13.527402       1 scheduler_binder.go:279] AssumePodVolumes for pod "kube-system/coredns-5b969f4c88-sn584", node "e2e-test-peterhornyack-minion-group-413w": all PVCs bound and nothing to do
I0319 16:47:13.528172       1 factory.go:733] Attempting to bind coredns-5b969f4c88-sn584 to e2e-test-peterhornyack-minion-group-413w
I0319 16:47:13.532157       1 scheduling_queue.go:908] About to try and schedule pod kube-system/heapster-v1.6.0-beta.1-b9947ddcf-dn54v
I0319 16:47:13.532181       1 scheduler.go:453] Attempting to schedule pod: kube-system/heapster-v1.6.0-beta.1-b9947ddcf-dn54v
I0319 16:47:13.532333       1 scheduler_binder.go:269] AssumePodVolumes for pod "kube-system/heapster-v1.6.0-beta.1-b9947ddcf-dn54v", node "e2e-test-peterhornyack-minion-group-413w"
I0319 16:47:13.532347       1 scheduler_binder.go:279] AssumePodVolumes for pod "kube-system/heapster-v1.6.0-beta.1-b9947ddcf-dn54v", node "e2e-test-peterhornyack-minion-group-413w": all PVCs bound and nothing to do
I0319 16:47:13.532384       1 factory.go:733] Attempting to bind heapster-v1.6.0-beta.1-b9947ddcf-dn54v to e2e-test-peterhornyack-minion-group-413w
I0319 16:47:13.539188       1 scheduling_queue.go:908] About to try and schedule pod kube-system/metrics-server-v0.3.1-677c578bdf-zvr7g
I0319 16:47:13.539215       1 scheduler.go:453] Attempting to schedule pod: kube-system/metrics-server-v0.3.1-677c578bdf-zvr7g
I0319 16:47:13.539361       1 scheduler_binder.go:269] AssumePodVolumes for pod "kube-system/metrics-server-v0.3.1-677c578bdf-zvr7g", node "e2e-test-peterhornyack-minion-group-413w"
I0319 16:47:13.539376       1 scheduler_binder.go:279] AssumePodVolumes for pod "kube-system/metrics-server-v0.3.1-677c578bdf-zvr7g", node "e2e-test-peterhornyack-minion-group-413w": all PVCs bound and nothing to do
I0319 16:47:13.539421       1 factory.go:733] Attempting to bind metrics-server-v0.3.1-677c578bdf-zvr7g to e2e-test-peterhornyack-minion-group-413w
I0319 16:47:13.540489       1 scheduling_queue.go:908] About to try and schedule pod kube-system/fluentd-gcp-scaler-85cdd7d7c5-7lm6p
I0319 16:47:13.540511       1 scheduler.go:453] Attempting to schedule pod: kube-system/fluentd-gcp-scaler-85cdd7d7c5-7lm6p
I0319 16:47:13.540799       1 scheduler_binder.go:269] AssumePodVolumes for pod "kube-system/fluentd-gcp-scaler-85cdd7d7c5-7lm6p", node "e2e-test-peterhornyack-minion-group-413w"
I0319 16:47:13.540818       1 scheduler_binder.go:279] AssumePodVolumes for pod "kube-system/fluentd-gcp-scaler-85cdd7d7c5-7lm6p", node "e2e-test-peterhornyack-minion-group-413w": all PVCs bound and nothing to do
I0319 16:47:13.540846       1 factory.go:733] Attempting to bind fluentd-gcp-scaler-85cdd7d7c5-7lm6p to e2e-test-peterhornyack-minion-group-413w
I0319 16:47:13.541084       1 scheduling_queue.go:908] About to try and schedule pod kube-system/l7-default-backend-8f479dd9-5qggn
I0319 16:47:13.541097       1 scheduler.go:453] Attempting to schedule pod: kube-system/l7-default-backend-8f479dd9-5qggn
I0319 16:47:13.541180       1 scheduler_binder.go:269] AssumePodVolumes for pod "kube-system/l7-default-backend-8f479dd9-5qggn", node "e2e-test-peterhornyack-minion-group-413w"
I0319 16:47:13.541206       1 scheduler_binder.go:279] AssumePodVolumes for pod "kube-system/l7-default-backend-8f479dd9-5qggn", node "e2e-test-peterhornyack-minion-group-413w": all PVCs bound and nothing to do
I0319 16:47:13.541225       1 factory.go:733] Attempting to bind l7-default-backend-8f479dd9-5qggn to e2e-test-peterhornyack-minion-group-413w
I0319 16:47:13.544406       1 cache.go:643] Couldn't expire cache for pod kube-system/fluentd-gcp-scaler-85cdd7d7c5-7lm6p. Binding is still in progress.
I0319 16:47:13.544850       1 cache.go:643] Couldn't expire cache for pod kube-system/l7-default-backend-8f479dd9-5qggn. Binding is still in progress.
I0319 16:47:13.544875       1 cache.go:643] Couldn't expire cache for pod kube-system/kubernetes-dashboard-85bcf5dbf8-p8g76. Binding is still in progress.
I0319 16:47:13.544881       1 cache.go:643] Couldn't expire cache for pod kube-system/kube-dns-autoscaler-97df449df-fnkn6. Binding is still in progress.
I0319 16:47:13.544888       1 cache.go:643] Couldn't expire cache for pod kube-system/coredns-5b969f4c88-sn584. Binding is still in progress.
I0319 16:47:13.544894       1 cache.go:643] Couldn't expire cache for pod kube-system/heapster-v1.6.0-beta.1-b9947ddcf-dn54v. Binding is still in progress.
I0319 16:47:13.544911       1 cache.go:643] Couldn't expire cache for pod kube-system/metrics-server-v0.3.1-677c578bdf-zvr7g. Binding is still in progress.
I0319 16:47:13.544935       1 scheduling_queue.go:908] About to try and schedule pod kube-system/event-exporter-v0.2.3-77f59d4b59-mdcvl
I0319 16:47:13.544955       1 scheduler.go:453] Attempting to schedule pod: kube-system/event-exporter-v0.2.3-77f59d4b59-mdcvl
I0319 16:47:13.546156       1 scheduler_binder.go:269] AssumePodVolumes for pod "kube-system/event-exporter-v0.2.3-77f59d4b59-mdcvl", node "e2e-test-peterhornyack-minion-group-413w"
I0319 16:47:13.546194       1 scheduler_binder.go:279] AssumePodVolumes for pod "kube-system/event-exporter-v0.2.3-77f59d4b59-mdcvl", node "e2e-test-peterhornyack-minion-group-413w": all PVCs bound and nothing to do
I0319 16:47:13.546226       1 factory.go:733] Attempting to bind event-exporter-v0.2.3-77f59d4b59-mdcvl to e2e-test-peterhornyack-minion-group-413w
I0319 16:47:13.561283       1 scheduler.go:572] pod kube-system/kube-dns-autoscaler-97df449df-fnkn6 is bound successfully on node e2e-test-peterhornyack-minion-group-413w, 2 nodes evaluated, 1 nodes were found feasible
I0319 16:47:13.563578       1 scheduler.go:572] pod kube-system/kubernetes-dashboard-85bcf5dbf8-p8g76 is bound successfully on node e2e-test-peterhornyack-minion-group-413w, 2 nodes evaluated, 1 nodes were found feasible
I0319 16:47:13.563636       1 scheduler.go:572] pod kube-system/coredns-5b969f4c88-sn584 is bound successfully on node e2e-test-peterhornyack-minion-group-413w, 2 nodes evaluated, 1 nodes were found feasible
I0319 16:47:13.563669       1 scheduler.go:572] pod kube-system/heapster-v1.6.0-beta.1-b9947ddcf-dn54v is bound successfully on node e2e-test-peterhornyack-minion-group-413w, 2 nodes evaluated, 1 nodes were found feasible
I0319 16:47:13.584657       1 scheduler.go:572] pod kube-system/fluentd-gcp-scaler-85cdd7d7c5-7lm6p is bound successfully on node e2e-test-peterhornyack-minion-group-413w, 2 nodes evaluated, 1 nodes were found feasible
I0319 16:47:13.584804       1 scheduler.go:572] pod kube-system/metrics-server-v0.3.1-677c578bdf-zvr7g is bound successfully on node e2e-test-peterhornyack-minion-group-413w, 2 nodes evaluated, 1 nodes were found feasible
I0319 16:47:13.584846       1 scheduler.go:572] pod kube-system/event-exporter-v0.2.3-77f59d4b59-mdcvl is bound successfully on node e2e-test-peterhornyack-minion-group-413w, 2 nodes evaluated, 1 nodes were found feasible
I0319 16:47:13.584901       1 scheduler.go:572] pod kube-system/l7-default-backend-8f479dd9-5qggn is bound successfully on node e2e-test-peterhornyack-minion-group-413w, 2 nodes evaluated, 1 nodes were found feasible
I0319 16:47:13.603286       1 scheduling_queue.go:908] About to try and schedule pod kube-system/fluentd-gcp-v3.2.0-6njnw
I0319 16:47:13.603314       1 scheduler.go:453] Attempting to schedule pod: kube-system/fluentd-gcp-v3.2.0-6njnw
I0319 16:47:13.606337       1 scheduler_binder.go:269] AssumePodVolumes for pod "kube-system/fluentd-gcp-v3.2.0-6njnw", node "e2e-test-peterhornyack-minion-group-413w"
I0319 16:47:13.606383       1 scheduler_binder.go:279] AssumePodVolumes for pod "kube-system/fluentd-gcp-v3.2.0-6njnw", node "e2e-test-peterhornyack-minion-group-413w": all PVCs bound and nothing to do
I0319 16:47:13.609462       1 factory.go:733] Attempting to bind fluentd-gcp-v3.2.0-6njnw to e2e-test-peterhornyack-minion-group-413w
I0319 16:47:13.617169       1 scheduling_queue.go:908] About to try and schedule pod kube-system/metadata-proxy-v0.1-mhd5d
I0319 16:47:13.617210       1 scheduler.go:453] Attempting to schedule pod: kube-system/metadata-proxy-v0.1-mhd5d
I0319 16:47:13.617579       1 scheduler_binder.go:269] AssumePodVolumes for pod "kube-system/metadata-proxy-v0.1-mhd5d", node "e2e-test-peterhornyack-minion-group-413w"
I0319 16:47:13.617598       1 scheduler_binder.go:279] AssumePodVolumes for pod "kube-system/metadata-proxy-v0.1-mhd5d", node "e2e-test-peterhornyack-minion-group-413w": all PVCs bound and nothing to do
I0319 16:47:13.617676       1 factory.go:733] Attempting to bind metadata-proxy-v0.1-mhd5d to e2e-test-peterhornyack-minion-group-413w
I0319 16:47:13.636252       1 scheduler.go:572] pod kube-system/fluentd-gcp-v3.2.0-6njnw is bound successfully on node e2e-test-peterhornyack-minion-group-413w, 2 nodes evaluated, 1 nodes were found feasible
I0319 16:47:13.647184       1 scheduler.go:572] pod kube-system/metadata-proxy-v0.1-mhd5d is bound successfully on node e2e-test-peterhornyack-minion-group-413w, 2 nodes evaluated, 1 nodes were found feasible
I0319 16:47:16.174229       1 scheduling_queue.go:908] About to try and schedule pod kube-system/metadata-proxy-v0.1-mx4wk
I0319 16:47:16.174278       1 scheduler.go:453] Attempting to schedule pod: kube-system/metadata-proxy-v0.1-mx4wk
I0319 16:47:16.174603       1 scheduler_binder.go:269] AssumePodVolumes for pod "kube-system/metadata-proxy-v0.1-mx4wk", node "e2e-test-peterhornyack-minion-group-b97j"
I0319 16:47:16.174633       1 scheduler_binder.go:279] AssumePodVolumes for pod "kube-system/metadata-proxy-v0.1-mx4wk", node "e2e-test-peterhornyack-minion-group-b97j": all PVCs bound and nothing to do
I0319 16:47:16.174690       1 factory.go:733] Attempting to bind metadata-proxy-v0.1-mx4wk to e2e-test-peterhornyack-minion-group-b97j
I0319 16:47:16.183733       1 scheduling_queue.go:908] About to try and schedule pod kube-system/fluentd-gcp-v3.2.0-jf6gd
I0319 16:47:16.183758       1 scheduler.go:453] Attempting to schedule pod: kube-system/fluentd-gcp-v3.2.0-jf6gd
I0319 16:47:16.183942       1 scheduler_binder.go:269] AssumePodVolumes for pod "kube-system/fluentd-gcp-v3.2.0-jf6gd", node "e2e-test-peterhornyack-minion-group-b97j"
I0319 16:47:16.183957       1 scheduler_binder.go:279] AssumePodVolumes for pod "kube-system/fluentd-gcp-v3.2.0-jf6gd", node "e2e-test-peterhornyack-minion-group-b97j": all PVCs bound and nothing to do
I0319 16:47:16.184004       1 factory.go:733] Attempting to bind fluentd-gcp-v3.2.0-jf6gd to e2e-test-peterhornyack-minion-group-b97j
I0319 16:47:16.207012       1 scheduler.go:572] pod kube-system/fluentd-gcp-v3.2.0-jf6gd is bound successfully on node e2e-test-peterhornyack-minion-group-b97j, 3 nodes evaluated, 1 nodes were found feasible
I0319 16:47:16.215269       1 scheduler.go:572] pod kube-system/metadata-proxy-v0.1-mx4wk is bound successfully on node e2e-test-peterhornyack-minion-group-b97j, 3 nodes evaluated, 1 nodes were found feasible
I0319 16:47:20.117927       1 wrap.go:47] GET /healthz: (74.199µs) 200 [kube-probe/1.15+ 127.0.0.1:49456]
I0319 16:47:27.751821       1 scheduling_queue.go:908] About to try and schedule pod kube-system/coredns-5b969f4c88-8wcmf
I0319 16:47:27.751858       1 scheduler.go:453] Attempting to schedule pod: kube-system/coredns-5b969f4c88-8wcmf
I0319 16:47:27.753907       1 scheduler_binder.go:269] AssumePodVolumes for pod "kube-system/coredns-5b969f4c88-8wcmf", node "e2e-test-peterhornyack-minion-group-b97j"
I0319 16:47:27.753941       1 scheduler_binder.go:279] AssumePodVolumes for pod "kube-system/coredns-5b969f4c88-8wcmf", node "e2e-test-peterhornyack-minion-group-b97j": all PVCs bound and nothing to do
I0319 16:47:27.756182       1 factory.go:733] Attempting to bind coredns-5b969f4c88-8wcmf to e2e-test-peterhornyack-minion-group-b97j
I0319 16:47:27.780047       1 scheduler.go:572] pod kube-system/coredns-5b969f4c88-8wcmf is bound successfully on node e2e-test-peterhornyack-minion-group-b97j, 3 nodes evaluated, 2 nodes were found feasible
I0319 16:47:30.117921       1 wrap.go:47] GET /healthz: (78.578µs) 200 [kube-probe/1.15+ 127.0.0.1:49490]
I0319 16:47:35.397566       1 scheduling_queue.go:908] About to try and schedule pod kube-system/metrics-server-v0.3.1-7d9cf58c5c-2wbtj
I0319 16:47:35.397989       1 scheduler.go:453] Attempting to schedule pod: kube-system/metrics-server-v0.3.1-7d9cf58c5c-2wbtj
I0319 16:47:35.402699       1 scheduler_binder.go:269] AssumePodVolumes for pod "kube-system/metrics-server-v0.3.1-7d9cf58c5c-2wbtj", node "e2e-test-peterhornyack-minion-group-b97j"
I0319 16:47:35.402740       1 scheduler_binder.go:279] AssumePodVolumes for pod "kube-system/metrics-server-v0.3.1-7d9cf58c5c-2wbtj", node "e2e-test-peterhornyack-minion-group-b97j": all PVCs bound and nothing to do
I0319 16:47:35.402834       1 factory.go:733] Attempting to bind metrics-server-v0.3.1-7d9cf58c5c-2wbtj to e2e-test-peterhornyack-minion-group-b97j
I0319 16:47:35.434946       1 scheduler.go:572] pod kube-system/metrics-server-v0.3.1-7d9cf58c5c-2wbtj is bound successfully on node e2e-test-peterhornyack-minion-group-b97j, 3 nodes evaluated, 2 nodes were found feasible
I0319 16:47:36.050009       1 scheduling_queue.go:908] About to try and schedule pod kube-system/heapster-v1.6.0-beta.1-6796bf47bf-vtxtn
I0319 16:47:36.050715       1 scheduler.go:453] Attempting to schedule pod: kube-system/heapster-v1.6.0-beta.1-6796bf47bf-vtxtn
I0319 16:47:36.056293       1 scheduler_binder.go:269] AssumePodVolumes for pod "kube-system/heapster-v1.6.0-beta.1-6796bf47bf-vtxtn", node "e2e-test-peterhornyack-minion-group-b97j"
I0319 16:47:36.056327       1 scheduler_binder.go:279] AssumePodVolumes for pod "kube-system/heapster-v1.6.0-beta.1-6796bf47bf-vtxtn", node "e2e-test-peterhornyack-minion-group-b97j": all PVCs bound and nothing to do
I0319 16:47:36.056411       1 factory.go:733] Attempting to bind heapster-v1.6.0-beta.1-6796bf47bf-vtxtn to e2e-test-peterhornyack-minion-group-b97j
I0319 16:47:36.088777       1 scheduler.go:572] pod kube-system/heapster-v1.6.0-beta.1-6796bf47bf-vtxtn is bound successfully on node e2e-test-peterhornyack-minion-group-b97j, 3 nodes evaluated, 2 nodes were found feasible
I0319 16:47:40.118107       1 wrap.go:47] GET /healthz: (92.099µs) 200 [kube-probe/1.15+ 127.0.0.1:49542]
I0319 16:47:43.062485       1 scheduling_queue.go:908] About to try and schedule pod kube-system/fluentd-gcp-v3.2.0-dhczm
I0319 16:47:43.062516       1 scheduler.go:453] Attempting to schedule pod: kube-system/fluentd-gcp-v3.2.0-dhczm
I0319 16:47:43.066346       1 scheduler_binder.go:269] AssumePodVolumes for pod "kube-system/fluentd-gcp-v3.2.0-dhczm", node "e2e-test-peterhornyack-minion-group-413w"
I0319 16:47:43.066399       1 scheduler_binder.go:279] AssumePodVolumes for pod "kube-system/fluentd-gcp-v3.2.0-dhczm", node "e2e-test-peterhornyack-minion-group-413w": all PVCs bound and nothing to do
I0319 16:47:43.066474       1 factory.go:733] Attempting to bind fluentd-gcp-v3.2.0-dhczm to e2e-test-peterhornyack-minion-group-413w
I0319 16:47:43.087338       1 scheduler.go:572] pod kube-system/fluentd-gcp-v3.2.0-dhczm is bound successfully on node e2e-test-peterhornyack-minion-group-413w, 3 nodes evaluated, 1 nodes were found feasible
I0319 16:47:50.117873       1 wrap.go:47] GET /healthz: (85.788µs) 200 [kube-probe/1.15+ 127.0.0.1:49600]
I0319 16:47:55.988305       1 scheduling_queue.go:908] About to try and schedule pod kube-system/fluentd-gcp-v3.2.0-cjzwp
I0319 16:47:55.988339       1 scheduler.go:453] Attempting to schedule pod: kube-system/fluentd-gcp-v3.2.0-cjzwp
I0319 16:47:55.990155       1 scheduler_binder.go:269] AssumePodVolumes for pod "kube-system/fluentd-gcp-v3.2.0-cjzwp", node "e2e-test-peterhornyack-minion-group-b97j"
I0319 16:47:55.990202       1 scheduler_binder.go:279] AssumePodVolumes for pod "kube-system/fluentd-gcp-v3.2.0-cjzwp", node "e2e-test-peterhornyack-minion-group-b97j": all PVCs bound and nothing to do
I0319 16:47:55.990286       1 factory.go:733] Attempting to bind fluentd-gcp-v3.2.0-cjzwp to e2e-test-peterhornyack-minion-group-b97j
I0319 16:47:56.017768       1 scheduler.go:572] pod kube-system/fluentd-gcp-v3.2.0-cjzwp is bound successfully on node e2e-test-peterhornyack-minion-group-b97j, 3 nodes evaluated, 1 nodes were found feasible
I0319 16:48:00.118225       1 wrap.go:47] GET /healthz: (90.677µs) 200 [kube-probe/1.15+ 127.0.0.1:49640]
I0319 16:48:05.733403       1 scheduling_queue.go:908] About to try and schedule pod kube-system/fluentd-gcp-v3.2.0-hzdmn
I0319 16:48:05.733433       1 scheduler.go:453] Attempting to schedule pod: kube-system/fluentd-gcp-v3.2.0-hzdmn
I0319 16:48:05.733840       1 scheduler_binder.go:269] AssumePodVolumes for pod "kube-system/fluentd-gcp-v3.2.0-hzdmn", node "e2e-test-peterhornyack-master"
I0319 16:48:05.733857       1 scheduler_binder.go:279] AssumePodVolumes for pod "kube-system/fluentd-gcp-v3.2.0-hzdmn", node "e2e-test-peterhornyack-master": all PVCs bound and nothing to do
I0319 16:48:05.733923       1 factory.go:733] Attempting to bind fluentd-gcp-v3.2.0-hzdmn to e2e-test-peterhornyack-master
I0319 16:48:05.751690       1 scheduler.go:572] pod kube-system/fluentd-gcp-v3.2.0-hzdmn is bound successfully on node e2e-test-peterhornyack-master, 3 nodes evaluated, 1 nodes were found feasible
I0319 16:48:10.118387       1 wrap.go:47] GET /healthz: (81.003µs) 200 [kube-probe/1.15+ 127.0.0.1:49756]
I0319 16:48:20.118215       1 wrap.go:47] GET /healthz: (75.322µs) 200 [kube-probe/1.15+ 127.0.0.1:49798]
I0319 16:48:26.022337       1 reflector.go:370] k8s.io/client-go/informers/factory.go:133: Watch close - *v1.StatefulSet total 0 items received
I0319 16:48:30.090823       1 reflector.go:370] k8s.io/client-go/informers/factory.go:133: Watch close - *v1.ReplicationController total 0 items received
I0319 16:48:30.117952       1 wrap.go:47] GET /healthz: (73.356µs) 200 [kube-probe/1.15+ 127.0.0.1:49834]
I0319 16:48:40.117927       1 wrap.go:47] GET /healthz: (81.306µs) 200 [kube-probe/1.15+ 127.0.0.1:49882]
I0319 16:48:50.118100       1 wrap.go:47] GET /healthz: (89.344µs) 200 [kube-probe/1.15+ 127.0.0.1:49916]
I0319 16:49:00.117826       1 wrap.go:47] GET /healthz: (132.499µs) 200 [kube-probe/1.15+ 127.0.0.1:49954]
I0319 16:49:10.118107       1 wrap.go:47] GET /healthz: (92.593µs) 200 [kube-probe/1.15+ 127.0.0.1:49996]
I0319 16:49:20.118259       1 wrap.go:47] GET /healthz: (73.742µs) 200 [kube-probe/1.15+ 127.0.0.1:50028]
I0319 16:49:30.035735       1 reflector.go:370] k8s.io/client-go/informers/factory.go:133: Watch close - *v1.PersistentVolume total 0 items received
I0319 16:49:30.119271       1 wrap.go:47] GET /healthz: (136.952µs) 200 [kube-probe/1.15+ 127.0.0.1:50064]
I0319 16:49:40.118110       1 wrap.go:47] GET /healthz: (110.72µs) 200 [kube-probe/1.15+ 127.0.0.1:50114]
I0319 16:49:50.117834       1 wrap.go:47] GET /healthz: (72.457µs) 200 [kube-probe/1.15+ 127.0.0.1:50146]
I0319 16:49:57.083207       1 reflector.go:370] k8s.io/client-go/informers/factory.go:133: Watch close - *v1.Service total 6 items received
I0319 16:50:00.117822       1 wrap.go:47] GET /healthz: (58.872µs) 200 [kube-probe/1.15+ 127.0.0.1:50180]
I0319 16:50:10.118243       1 wrap.go:47] GET /healthz: (78.129µs) 200 [kube-probe/1.15+ 127.0.0.1:50218]
I0319 16:50:20.117993       1 wrap.go:47] GET /healthz: (74.1µs) 200 [kube-probe/1.15+ 127.0.0.1:50252]
I0319 16:50:24.078429       1 wrap.go:47] GET /healthz: (88.776µs) 200 [kube-probe/1.15+ 127.0.0.1:50270]
I0319 16:50:24.434316       1 wrap.go:47] GET /healthz: (93.187µs) 200 [kube-probe/1.15+ 127.0.0.1:50278]
I0319 16:50:30.118284       1 wrap.go:47] GET /healthz: (74.421µs) 200 [kube-probe/1.15+ 127.0.0.1:50302]
I0319 16:50:38.070403       1 reflector.go:370] k8s.io/client-go/informers/factory.go:133: Watch close - *v1.StorageClass total 1 items received
I0319 16:50:40.117920       1 wrap.go:47] GET /healthz: (79.887µs) 200 [kube-probe/1.15+ 127.0.0.1:50350]
I0319 16:50:42.029381       1 reflector.go:370] k8s.io/kubernetes/cmd/kube-scheduler/app/server.go:223: Watch close - *v1.Pod total 137 items received
I0319 16:50:43.058282       1 reflector.go:370] k8s.io/client-go/informers/factory.go:133: Watch close - *v1beta1.PodDisruptionBudget total 0 items received
I0319 16:50:50.118329       1 wrap.go:47] GET /healthz: (76.167µs) 200 [kube-probe/1.15+ 127.0.0.1:50386]
I0319 16:51:00.118048       1 wrap.go:47] GET /healthz: (77.606µs) 200 [kube-probe/1.15+ 127.0.0.1:50420]
I0319 16:51:01.067805       1 reflector.go:370] k8s.io/client-go/informers/factory.go:133: Watch close - *v1.PersistentVolumeClaim total 0 items received
I0319 16:51:10.117767       1 wrap.go:47] GET /healthz: (87.103µs) 200 [kube-probe/1.15+ 127.0.0.1:50458]
I0319 16:51:20.118098       1 wrap.go:47] GET /healthz: (91.63µs) 200 [kube-probe/1.15+ 127.0.0.1:50490]
I0319 16:51:28.064276       1 reflector.go:370] k8s.io/client-go/informers/factory.go:133: Watch close - *v1.Node total 72 items received
I0319 16:51:30.117783       1 wrap.go:47] GET /healthz: (76.293µs) 200 [kube-probe/1.15+ 127.0.0.1:50524]
I0319 16:51:40.118283       1 wrap.go:47] GET /healthz: (72.858µs) 200 [kube-probe/1.15+ 127.0.0.1:50572]
I0319 16:51:50.117839       1 wrap.go:47] GET /healthz: (88.141µs) 200 [kube-probe/1.15+ 127.0.0.1:50604]
I0319 16:52:00.118341       1 wrap.go:47] GET /healthz: (81.984µs) 200 [kube-probe/1.15+ 127.0.0.1:50638]
I0319 16:52:10.118125       1 wrap.go:47] GET /healthz: (160.255µs) 200 [kube-probe/1.15+ 127.0.0.1:50680]
I0319 16:52:20.118223       1 wrap.go:47] GET /healthz: (75.433µs) 200 [kube-probe/1.15+ 127.0.0.1:50712]
I0319 16:52:30.117942       1 wrap.go:47] GET /healthz: (65.101µs) 200 [kube-probe/1.15+ 127.0.0.1:50746]
I0319 16:52:40.049804       1 reflector.go:370] k8s.io/client-go/informers/factory.go:133: Watch close - *v1.ReplicaSet total 52 items received
I0319 16:52:40.118139       1 wrap.go:47] GET /healthz: (60.632µs) 200 [kube-probe/1.15+ 127.0.0.1:50794]
I0319 16:52:50.118100       1 wrap.go:47] GET /healthz: (106.246µs) 200 [kube-probe/1.15+ 127.0.0.1:50826]
I0319 16:53:00.117851       1 wrap.go:47] GET /healthz: (74.886µs) 200 [kube-probe/1.15+ 127.0.0.1:50860]
I0319 16:53:10.118756       1 wrap.go:47] GET /healthz: (68.967µs) 200 [kube-probe/1.15+ 127.0.0.1:50898]
I0319 16:53:18.166762       1 scheduling_queue.go:908] About to try and schedule pod default/linux-nginx-7c4f9bd84f-dmsh6
I0319 16:53:18.166822       1 scheduler.go:453] Attempting to schedule pod: default/linux-nginx-7c4f9bd84f-dmsh6
I0319 16:53:18.172215       1 scheduler_binder.go:269] AssumePodVolumes for pod "default/linux-nginx-7c4f9bd84f-dmsh6", node "e2e-test-peterhornyack-minion-group-b97j"
I0319 16:53:18.172573       1 scheduler_binder.go:279] AssumePodVolumes for pod "default/linux-nginx-7c4f9bd84f-dmsh6", node "e2e-test-peterhornyack-minion-group-b97j": all PVCs bound and nothing to do
I0319 16:53:18.172653       1 factory.go:733] Attempting to bind linux-nginx-7c4f9bd84f-dmsh6 to e2e-test-peterhornyack-minion-group-b97j
I0319 16:53:18.197549       1 scheduler.go:572] pod default/linux-nginx-7c4f9bd84f-dmsh6 is bound successfully on node e2e-test-peterhornyack-minion-group-b97j, 5 nodes evaluated, 2 nodes were found feasible
I0319 16:53:20.117934       1 wrap.go:47] GET /healthz: (88.014µs) 200 [kube-probe/1.15+ 127.0.0.1:50932]
I0319 16:53:29.029266       1 reflector.go:370] k8s.io/client-go/informers/factory.go:133: Watch close - *v1.StatefulSet total 0 items received
I0319 16:53:29.057518       1 scheduling_queue.go:908] About to try and schedule pod default/linux-ubuntu-5dbcdfff9d-slgzc
I0319 16:53:29.057563       1 scheduler.go:453] Attempting to schedule pod: default/linux-ubuntu-5dbcdfff9d-slgzc
I0319 16:53:29.063078       1 scheduler_binder.go:269] AssumePodVolumes for pod "default/linux-ubuntu-5dbcdfff9d-slgzc", node "e2e-test-peterhornyack-minion-group-b97j"
I0319 16:53:29.063128       1 scheduler_binder.go:279] AssumePodVolumes for pod "default/linux-ubuntu-5dbcdfff9d-slgzc", node "e2e-test-peterhornyack-minion-group-b97j": all PVCs bound and nothing to do
I0319 16:53:29.064085       1 factory.go:733] Attempting to bind linux-ubuntu-5dbcdfff9d-slgzc to e2e-test-peterhornyack-minion-group-b97j
I0319 16:53:29.102345       1 scheduler.go:572] pod default/linux-ubuntu-5dbcdfff9d-slgzc is bound successfully on node e2e-test-peterhornyack-minion-group-b97j, 5 nodes evaluated, 2 nodes were found feasible
I0319 16:53:30.118057       1 wrap.go:47] GET /healthz: (76.723µs) 200 [kube-probe/1.15+ 127.0.0.1:50966]
I0319 16:53:39.974357       1 scheduling_queue.go:908] About to try and schedule pod default/windows-nettest-944bd6d8d-bgrvz
I0319 16:53:39.974403       1 scheduler.go:453] Attempting to schedule pod: default/windows-nettest-944bd6d8d-bgrvz
I0319 16:53:39.974818       1 scheduler_binder.go:269] AssumePodVolumes for pod "default/windows-nettest-944bd6d8d-bgrvz", node "e2e-test-peterhornyack-windows-node-group-dp2r"
I0319 16:53:39.974834       1 scheduler_binder.go:279] AssumePodVolumes for pod "default/windows-nettest-944bd6d8d-bgrvz", node "e2e-test-peterhornyack-windows-node-group-dp2r": all PVCs bound and nothing to do
I0319 16:53:39.974890       1 factory.go:733] Attempting to bind windows-nettest-944bd6d8d-bgrvz to e2e-test-peterhornyack-windows-node-group-dp2r
I0319 16:53:40.005369       1 scheduler.go:572] pod default/windows-nettest-944bd6d8d-bgrvz is bound successfully on node e2e-test-peterhornyack-windows-node-group-dp2r, 5 nodes evaluated, 2 nodes were found feasible
I0319 16:53:40.117817       1 wrap.go:47] GET /healthz: (80.58µs) 200 [kube-probe/1.15+ 127.0.0.1:51016]
I0319 16:53:50.117933       1 wrap.go:47] GET /healthz: (75.215µs) 200 [kube-probe/1.15+ 127.0.0.1:51048]
I0319 16:54:00.118241       1 wrap.go:47] GET /healthz: (98.493µs) 200 [kube-probe/1.15+ 127.0.0.1:51082]
I0319 16:54:01.151398       1 scheduling_queue.go:908] About to try and schedule pod default/windows-powershell-7c9878bbfd-c6j66
I0319 16:54:01.151435       1 scheduler.go:453] Attempting to schedule pod: default/windows-powershell-7c9878bbfd-c6j66
I0319 16:54:01.158098       1 scheduler_binder.go:269] AssumePodVolumes for pod "default/windows-powershell-7c9878bbfd-c6j66", node "e2e-test-peterhornyack-windows-node-group-dp2r"
I0319 16:54:01.158163       1 scheduler_binder.go:279] AssumePodVolumes for pod "default/windows-powershell-7c9878bbfd-c6j66", node "e2e-test-peterhornyack-windows-node-group-dp2r": all PVCs bound and nothing to do
I0319 16:54:01.158247       1 factory.go:733] Attempting to bind windows-powershell-7c9878bbfd-c6j66 to e2e-test-peterhornyack-windows-node-group-dp2r
I0319 16:54:01.177664       1 scheduler.go:572] pod default/windows-powershell-7c9878bbfd-c6j66 is bound successfully on node e2e-test-peterhornyack-windows-node-group-dp2r, 5 nodes evaluated, 2 nodes were found feasible
I0319 16:54:10.118057       1 wrap.go:47] GET /healthz: (94.137µs) 200 [kube-probe/1.15+ 127.0.0.1:51120]
I0319 16:54:20.117900       1 wrap.go:47] GET /healthz: (79.022µs) 200 [kube-probe/1.15+ 127.0.0.1:51156]
I0319 16:54:30.118104       1 wrap.go:47] GET /healthz: (90.782µs) 200 [kube-probe/1.15+ 127.0.0.1:51194]
I0319 16:54:40.118395       1 wrap.go:47] GET /healthz: (104.606µs) 200 [kube-probe/1.15+ 127.0.0.1:51248]
I0319 16:54:50.118003       1 wrap.go:47] GET /healthz: (76.824µs) 200 [kube-probe/1.15+ 127.0.0.1:51284]
I0319 16:55:00.118100       1 wrap.go:47] GET /healthz: (126.035µs) 200 [kube-probe/1.15+ 127.0.0.1:51324]
I0319 16:55:10.118140       1 wrap.go:47] GET /healthz: (81.754µs) 200 [kube-probe/1.15+ 127.0.0.1:51364]
I0319 16:55:20.118047       1 wrap.go:47] GET /healthz: (57.436µs) 200 [kube-probe/1.15+ 127.0.0.1:51396]
I0319 16:55:30.117970       1 wrap.go:47] GET /healthz: (71.59µs) 200 [kube-probe/1.15+ 127.0.0.1:51430]
I0319 16:55:40.118389       1 wrap.go:47] GET /healthz: (73.946µs) 200 [kube-probe/1.15+ 127.0.0.1:51478]
I0319 16:55:46.094398       1 reflector.go:370] k8s.io/client-go/informers/factory.go:133: Watch close - *v1.ReplicationController total 0 items received
I0319 16:55:50.118252       1 wrap.go:47] GET /healthz: (80.484µs) 200 [kube-probe/1.15+ 127.0.0.1:51512]
I0319 16:56:00.117996       1 wrap.go:47] GET /healthz: (89.322µs) 200 [kube-probe/1.15+ 127.0.0.1:51550]
I0319 16:56:10.118000       1 wrap.go:47] GET /healthz: (78.441µs) 200 [kube-probe/1.15+ 127.0.0.1:51590]
I0319 16:56:11.508346       1 scheduling_queue.go:908] About to try and schedule pod proxy-1378/proxy-service-nbdhs-qxjss
I0319 16:56:11.508395       1 scheduler.go:453] Attempting to schedule pod: proxy-1378/proxy-service-nbdhs-qxjss
I0319 16:56:11.508888       1 scheduler_binder.go:269] AssumePodVolumes for pod "proxy-1378/proxy-service-nbdhs-qxjss", node "e2e-test-peterhornyack-windows-node-group-dp2r"
I0319 16:56:11.508908       1 scheduler_binder.go:279] AssumePodVolumes for pod "proxy-1378/proxy-service-nbdhs-qxjss", node "e2e-test-peterhornyack-windows-node-group-dp2r": all PVCs bound and nothing to do
I0319 16:56:11.508986       1 factory.go:733] Attempting to bind proxy-service-nbdhs-qxjss to e2e-test-peterhornyack-windows-node-group-dp2r
I0319 16:56:11.524642       1 scheduler.go:572] pod proxy-1378/proxy-service-nbdhs-qxjss is bound successfully on node e2e-test-peterhornyack-windows-node-group-dp2r, 5 nodes evaluated, 2 nodes were found feasible
I0319 16:56:20.117935       1 wrap.go:47] GET /healthz: (82.003µs) 200 [kube-probe/1.15+ 127.0.0.1:51626]
I0319 16:56:30.118487       1 wrap.go:47] GET /healthz: (72.629µs) 200 [kube-probe/1.15+ 127.0.0.1:51660]
I0319 16:56:40.117822       1 wrap.go:47] GET /healthz: (85.359µs) 200 [kube-probe/1.15+ 127.0.0.1:51798]
I0319 16:56:44.034095       1 reflector.go:370] k8s.io/kubernetes/cmd/kube-scheduler/app/server.go:223: Watch close - *v1.Pod total 41 items received
I0319 16:56:50.117817       1 wrap.go:47] GET /healthz: (70.879µs) 200 [kube-probe/1.15+ 127.0.0.1:51830]
I0319 16:57:00.118148       1 wrap.go:47] GET /healthz: (100.07µs) 200 [kube-probe/1.15+ 127.0.0.1:51866]
I0319 16:57:10.117803       1 wrap.go:47] GET /healthz: (73.344µs) 200 [kube-probe/1.15+ 127.0.0.1:51904]
I0319 16:57:20.118225       1 wrap.go:47] GET /healthz: (80.013µs) 200 [kube-probe/1.15+ 127.0.0.1:51936]
I0319 16:57:27.073407       1 reflector.go:370] k8s.io/client-go/informers/factory.go:133: Watch close - *v1.StorageClass total 0 items received
I0319 16:57:30.118649       1 wrap.go:47] GET /healthz: (74.555µs) 200 [kube-probe/1.15+ 127.0.0.1:51970]
I0319 16:57:40.118385       1 wrap.go:47] GET /healthz: (73.082µs) 200 [kube-probe/1.15+ 127.0.0.1:52020]
I0319 16:57:50.118216       1 wrap.go:47] GET /healthz: (84.208µs) 200 [kube-probe/1.15+ 127.0.0.1:52052]
I0319 16:57:52.067159       1 reflector.go:370] k8s.io/client-go/informers/factory.go:133: Watch close - *v1.Node total 55 items received
I0319 16:58:00.120095       1 wrap.go:47] GET /healthz: (102.337µs) 200 [kube-probe/1.15+ 127.0.0.1:52086]
I0319 16:58:10.117973       1 wrap.go:47] GET /healthz: (106.665µs) 200 [kube-probe/1.15+ 127.0.0.1:52126]
I0319 16:58:20.117928       1 wrap.go:47] GET /healthz: (77.242µs) 200 [kube-probe/1.15+ 127.0.0.1:52158]
I0319 16:58:30.118932       1 wrap.go:47] GET /healthz: (73.257µs) 200 [kube-probe/1.15+ 127.0.0.1:52192]
I0319 16:58:32.051986       1 reflector.go:370] k8s.io/client-go/informers/factory.go:133: Watch close - *v1.ReplicaSet total 20 items received
I0319 16:58:39.074172       1 reflector.go:370] k8s.io/client-go/informers/factory.go:133: Watch close - *v1.PersistentVolumeClaim total 0 items received
I0319 16:58:40.118265       1 wrap.go:47] GET /healthz: (81.029µs) 200 [kube-probe/1.15+ 127.0.0.1:52240]
I0319 16:58:50.118897       1 wrap.go:47] GET /healthz: (82.152µs) 200 [kube-probe/1.15+ 127.0.0.1:52272]
I0319 16:59:00.118151       1 wrap.go:47] GET /healthz: (73.748µs) 200 [kube-probe/1.15+ 127.0.0.1:52306]
I0319 16:59:06.039176       1 reflector.go:370] k8s.io/client-go/informers/factory.go:133: Watch close - *v1.PersistentVolume total 0 items received
I0319 16:59:10.118822       1 wrap.go:47] GET /healthz: (75.907µs) 200 [kube-probe/1.15+ 127.0.0.1:52346]
I0319 16:59:20.118871       1 wrap.go:47] GET /healthz: (71.712µs) 200 [kube-probe/1.15+ 127.0.0.1:52390]
I0319 16:59:30.125511       1 wrap.go:47] GET /healthz: (72.244µs) 200 [kube-probe/1.15+ 127.0.0.1:52426]
I0319 16:59:40.118259       1 wrap.go:47] GET /healthz: (57.413µs) 200 [kube-probe/1.15+ 127.0.0.1:52474]
I0319 16:59:50.118935       1 wrap.go:47] GET /healthz: (91.461µs) 200 [kube-probe/1.15+ 127.0.0.1:52506]
I0319 16:59:51.086752       1 reflector.go:370] k8s.io/client-go/informers/factory.go:133: Watch close - *v1.Service total 2 items received
I0319 17:00:00.117933       1 wrap.go:47] GET /healthz: (76.681µs) 200 [kube-probe/1.15+ 127.0.0.1:52540]
I0319 17:00:10.117976       1 wrap.go:47] GET /healthz: (61.252µs) 200 [kube-probe/1.15+ 127.0.0.1:52578]
I0319 17:00:19.061215       1 reflector.go:370] k8s.io/client-go/informers/factory.go:133: Watch close - *v1beta1.PodDisruptionBudget total 0 items received
I0319 17:00:20.118280       1 wrap.go:47] GET /healthz: (79.592µs) 200 [kube-probe/1.15+ 127.0.0.1:52610]
I0319 17:00:21.541382       1 scheduling_queue.go:908] About to try and schedule pod projected-8843/pod-projected-configmaps-7b2fffa3-4a68-11e9-af5d-a08cfde32bdd
I0319 17:00:21.542906       1 scheduler.go:453] Attempting to schedule pod: projected-8843/pod-projected-configmaps-7b2fffa3-4a68-11e9-af5d-a08cfde32bdd
I0319 17:00:21.543375       1 scheduler_binder.go:269] AssumePodVolumes for pod "projected-8843/pod-projected-configmaps-7b2fffa3-4a68-11e9-af5d-a08cfde32bdd", node "e2e-test-peterhornyack-windows-node-group-7n03"
I0319 17:00:21.543398       1 scheduler_binder.go:279] AssumePodVolumes for pod "projected-8843/pod-projected-configmaps-7b2fffa3-4a68-11e9-af5d-a08cfde32bdd", node "e2e-test-peterhornyack-windows-node-group-7n03": all PVCs bound and nothing to do
I0319 17:00:21.543464       1 factory.go:733] Attempting to bind pod-projected-configmaps-7b2fffa3-4a68-11e9-af5d-a08cfde32bdd to e2e-test-peterhornyack-windows-node-group-7n03
I0319 17:00:21.550209       1 scheduler.go:572] pod projected-8843/pod-projected-configmaps-7b2fffa3-4a68-11e9-af5d-a08cfde32bdd is bound successfully on node e2e-test-peterhornyack-windows-node-group-7n03, 5 nodes evaluated, 2 nodes were found feasible
I0319 17:00:30.118151       1 wrap.go:47] GET /healthz: (76.278µs) 200 [kube-probe/1.15+ 127.0.0.1:52646]
I0319 17:00:40.117970       1 wrap.go:47] GET /healthz: (83.662µs) 200 [kube-probe/1.15+ 127.0.0.1:52696]
I0319 17:00:50.118784       1 wrap.go:47] GET /healthz: (69.637µs) 200 [kube-probe/1.15+ 127.0.0.1:52728]
I0319 17:00:58.407081       1 scheduling_queue.go:908] About to try and schedule pod container-runtime-3131/image-pull-test9129122c-4a68-11e9-af5d-a08cfde32bdd
I0319 17:00:58.407113       1 scheduler.go:453] Attempting to schedule pod: container-runtime-3131/image-pull-test9129122c-4a68-11e9-af5d-a08cfde32bdd
I0319 17:00:58.409216       1 scheduler_binder.go:269] AssumePodVolumes for pod "container-runtime-3131/image-pull-test9129122c-4a68-11e9-af5d-a08cfde32bdd", node "e2e-test-peterhornyack-windows-node-group-dp2r"
I0319 17:00:58.409262       1 scheduler_binder.go:279] AssumePodVolumes for pod "container-runtime-3131/image-pull-test9129122c-4a68-11e9-af5d-a08cfde32bdd", node "e2e-test-peterhornyack-windows-node-group-dp2r": all PVCs bound and nothing to do
I0319 17:00:58.410127       1 factory.go:733] Attempting to bind image-pull-test9129122c-4a68-11e9-af5d-a08cfde32bdd to e2e-test-peterhornyack-windows-node-group-dp2r
I0319 17:00:58.417799       1 scheduler.go:572] pod container-runtime-3131/image-pull-test9129122c-4a68-11e9-af5d-a08cfde32bdd is bound successfully on node e2e-test-peterhornyack-windows-node-group-dp2r, 5 nodes evaluated, 2 nodes were found feasible
I0319 17:01:00.117902       1 wrap.go:47] GET /healthz: (69.467µs) 200 [kube-probe/1.15+ 127.0.0.1:52764]
I0319 17:01:10.117883       1 wrap.go:47] GET /healthz: (79.326µs) 200 [kube-probe/1.15+ 127.0.0.1:52802]
I0319 17:01:11.841045       1 scheduling_queue.go:908] About to try and schedule pod statefulset-6320/ss2-0
I0319 17:01:11.841078       1 scheduler.go:453] Attempting to schedule pod: statefulset-6320/ss2-0
I0319 17:01:11.844001       1 scheduler_binder.go:269] AssumePodVolumes for pod "statefulset-6320/ss2-0", node "e2e-test-peterhornyack-windows-node-group-7n03"
I0319 17:01:11.844063       1 scheduler_binder.go:279] AssumePodVolumes for pod "statefulset-6320/ss2-0", node "e2e-test-peterhornyack-windows-node-group-7n03": all PVCs bound and nothing to do
I0319 17:01:11.844133       1 factory.go:733] Attempting to bind ss2-0 to e2e-test-peterhornyack-windows-node-group-7n03
I0319 17:01:11.857186       1 scheduler.go:572] pod statefulset-6320/ss2-0 is bound successfully on node e2e-test-peterhornyack-windows-node-group-7n03, 5 nodes evaluated, 2 nodes were found feasible
I0319 17:01:13.033268       1 reflector.go:370] k8s.io/client-go/informers/factory.go:133: Watch close - *v1.StatefulSet total 2 items received
I0319 17:01:16.097457       1 reflector.go:370] k8s.io/client-go/informers/factory.go:133: Watch close - *v1.ReplicationController total 5 items received
I0319 17:01:20.118382       1 wrap.go:47] GET /healthz: (75.03µs) 200 [kube-probe/1.15+ 127.0.0.1:52836]
I0319 17:01:30.118053       1 wrap.go:47] GET /healthz: (72.124µs) 200 [kube-probe/1.15+ 127.0.0.1:52870]
I0319 17:01:40.117877       1 wrap.go:47] GET /healthz: (77.733µs) 200 [kube-probe/1.15+ 127.0.0.1:52918]
I0319 17:01:50.117776       1 wrap.go:47] GET /healthz: (77.718µs) 200 [kube-probe/1.15+ 127.0.0.1:52954]
I0319 17:01:50.602697       1 scheduling_queue.go:908] About to try and schedule pod statefulset-6320/ss2-1
I0319 17:01:50.602876       1 scheduler.go:453] Attempting to schedule pod: statefulset-6320/ss2-1
I0319 17:01:50.604416       1 scheduler_binder.go:269] AssumePodVolumes for pod "statefulset-6320/ss2-1", node "e2e-test-peterhornyack-windows-node-group-7n03"
I0319 17:01:50.606226       1 scheduler_binder.go:279] AssumePodVolumes for pod "statefulset-6320/ss2-1", node "e2e-test-peterhornyack-windows-node-group-7n03": all PVCs bound and nothing to do
I0319 17:01:50.606328       1 factory.go:733] Attempting to bind ss2-1 to e2e-test-peterhornyack-windows-node-group-7n03
I0319 17:01:50.624847       1 scheduler.go:572] pod statefulset-6320/ss2-1 is bound successfully on node e2e-test-peterhornyack-windows-node-group-7n03, 5 nodes evaluated, 2 nodes were found feasible
I0319 17:01:59.270402       1 scheduling_queue.go:908] About to try and schedule pod statefulset-6320/ss2-2
I0319 17:01:59.270448       1 scheduler.go:453] Attempting to schedule pod: statefulset-6320/ss2-2
I0319 17:01:59.271508       1 scheduler_binder.go:269] AssumePodVolumes for pod "statefulset-6320/ss2-2", node "e2e-test-peterhornyack-windows-node-group-7n03"
I0319 17:01:59.274100       1 scheduler_binder.go:279] AssumePodVolumes for pod "statefulset-6320/ss2-2", node "e2e-test-peterhornyack-windows-node-group-7n03": all PVCs bound and nothing to do
I0319 17:01:59.274192       1 factory.go:733] Attempting to bind ss2-2 to e2e-test-peterhornyack-windows-node-group-7n03
I0319 17:01:59.288585       1 scheduler.go:572] pod statefulset-6320/ss2-2 is bound successfully on node e2e-test-peterhornyack-windows-node-group-7n03, 5 nodes evaluated, 2 nodes were found feasible
I0319 17:02:00.118115       1 wrap.go:47] GET /healthz: (114.346µs) 200 [kube-probe/1.15+ 127.0.0.1:52988]
I0319 17:02:10.118088       1 wrap.go:47] GET /healthz: (112.971µs) 200 [kube-probe/1.15+ 127.0.0.1:53026]
I0319 17:02:20.118565       1 wrap.go:47] GET /healthz: (101.939µs) 200 [kube-probe/1.15+ 127.0.0.1:53058]
I0319 17:02:21.507267       1 scheduling_queue.go:908] About to try and schedule pod statefulset-6320/ss2-2
I0319 17:02:21.507299       1 scheduler.go:453] Attempting to schedule pod: statefulset-6320/ss2-2
I0319 17:02:21.507793       1 scheduler_binder.go:269] AssumePodVolumes for pod "statefulset-6320/ss2-2", node "e2e-test-peterhornyack-windows-node-group-dp2r"
I0319 17:02:21.507829       1 scheduler_binder.go:279] AssumePodVolumes for pod "statefulset-6320/ss2-2", node "e2e-test-peterhornyack-windows-node-group-dp2r": all PVCs bound and nothing to do
I0319 17:02:21.507880       1 factory.go:733] Attempting to bind ss2-2 to e2e-test-peterhornyack-windows-node-group-dp2r
I0319 17:02:21.524166       1 scheduler.go:572] pod statefulset-6320/ss2-2 is bound successfully on node e2e-test-peterhornyack-windows-node-group-dp2r, 5 nodes evaluated, 2 nodes were found feasible
I0319 17:02:22.620101       1 scheduling_queue.go:908] About to try and schedule pod statefulset-6320/ss2-0
I0319 17:02:22.620150       1 scheduler.go:453] Attempting to schedule pod: statefulset-6320/ss2-0
I0319 17:02:22.620523       1 scheduler_binder.go:269] AssumePodVolumes for pod "statefulset-6320/ss2-0", node "e2e-test-peterhornyack-windows-node-group-7n03"
I0319 17:02:22.620539       1 scheduler_binder.go:279] AssumePodVolumes for pod "statefulset-6320/ss2-0", node "e2e-test-peterhornyack-windows-node-group-7n03": all PVCs bound and nothing to do
I0319 17:02:22.620620       1 factory.go:733] Attempting to bind ss2-0 to e2e-test-peterhornyack-windows-node-group-7n03
I0319 17:02:22.653344       1 scheduler.go:572] pod statefulset-6320/ss2-0 is bound successfully on node e2e-test-peterhornyack-windows-node-group-7n03, 5 nodes evaluated, 2 nodes were found feasible
I0319 17:02:30.119057       1 wrap.go:47] GET /healthz: (76.302µs) 200 [kube-probe/1.15+ 127.0.0.1:53092]
I0319 17:02:30.720841       1 scheduling_queue.go:908] About to try and schedule pod statefulset-6320/ss2-2
I0319 17:02:30.720869       1 scheduler.go:453] Attempting to schedule pod: statefulset-6320/ss2-2
I0319 17:02:30.724811       1 scheduler_binder.go:269] AssumePodVolumes for pod "statefulset-6320/ss2-2", node "e2e-test-peterhornyack-windows-node-group-dp2r"
I0319 17:02:30.724857       1 scheduler_binder.go:279] AssumePodVolumes for pod "statefulset-6320/ss2-2", node "e2e-test-peterhornyack-windows-node-group-dp2r": all PVCs bound and nothing to do
I0319 17:02:30.724910       1 factory.go:733] Attempting to bind ss2-2 to e2e-test-peterhornyack-windows-node-group-dp2r
I0319 17:02:30.735402       1 scheduler.go:572] pod statefulset-6320/ss2-2 is bound successfully on node e2e-test-peterhornyack-windows-node-group-dp2r, 5 nodes evaluated, 2 nodes were found feasible
I0319 17:02:40.118107       1 wrap.go:47] GET /healthz: (95.015µs) 200 [kube-probe/1.15+ 127.0.0.1:53140]
I0319 17:02:50.117958       1 wrap.go:47] GET /healthz: (73.651µs) 200 [kube-probe/1.15+ 127.0.0.1:53172]
I0319 17:03:00.118061       1 wrap.go:47] GET /healthz: (107.746µs) 200 [kube-probe/1.15+ 127.0.0.1:53208]
I0319 17:03:10.118306       1 wrap.go:47] GET /healthz: (74.576µs) 200 [kube-probe/1.15+ 127.0.0.1:53246]
I0319 17:03:20.118266       1 wrap.go:47] GET /healthz: (84.009µs) 200 [kube-probe/1.15+ 127.0.0.1:53280]
I0319 17:03:30.118126       1 wrap.go:47] GET /healthz: (100.04µs) 200 [kube-probe/1.15+ 127.0.0.1:53314]
I0319 17:03:40.118224       1 wrap.go:47] GET /healthz: (89.832µs) 200 [kube-probe/1.15+ 127.0.0.1:53362]
I0319 17:03:50.118197       1 wrap.go:47] GET /healthz: (87.902µs) 200 [kube-probe/1.15+ 127.0.0.1:53394]
I0319 17:04:00.118167       1 wrap.go:47] GET /healthz: (85.779µs) 200 [kube-probe/1.15+ 127.0.0.1:53428]
I0319 17:04:04.056071       1 reflector.go:370] k8s.io/client-go/informers/factory.go:133: Watch close - *v1.ReplicaSet total 0 items received
I0319 17:04:10.117860       1 wrap.go:47] GET /healthz: (71.386µs) 200 [kube-probe/1.15+ 127.0.0.1:53466]
I0319 17:04:18.732168       1 scheduling_queue.go:908] About to try and schedule pod statefulset-6320/ss2-1
I0319 17:04:18.732351       1 scheduler.go:453] Attempting to schedule pod: statefulset-6320/ss2-1
I0319 17:04:18.737443       1 scheduler_binder.go:269] AssumePodVolumes for pod "statefulset-6320/ss2-1", node "e2e-test-peterhornyack-windows-node-group-dp2r"
I0319 17:04:18.737484       1 scheduler_binder.go:279] AssumePodVolumes for pod "statefulset-6320/ss2-1", node "e2e-test-peterhornyack-windows-node-group-dp2r": all PVCs bound and nothing to do
I0319 17:04:18.737561       1 factory.go:733] Attempting to bind ss2-1 to e2e-test-peterhornyack-windows-node-group-dp2r
I0319 17:04:18.757885       1 scheduler.go:572] pod statefulset-6320/ss2-1 is bound successfully on node e2e-test-peterhornyack-windows-node-group-dp2r, 5 nodes evaluated, 2 nodes were found feasible
I0319 17:04:20.117813       1 wrap.go:47] GET /healthz: (84.994µs) 200 [kube-probe/1.15+ 127.0.0.1:53500]
I0319 17:04:30.118128       1 wrap.go:47] GET /healthz: (121.764µs) 200 [kube-probe/1.15+ 127.0.0.1:53534]
I0319 17:04:40.118230       1 wrap.go:47] GET /healthz: (80.168µs) 200 [kube-probe/1.15+ 127.0.0.1:53584]
I0319 17:04:50.118336       1 wrap.go:47] GET /healthz: (74.942µs) 200 [kube-probe/1.15+ 127.0.0.1:53616]
I0319 17:05:00.118437       1 wrap.go:47] GET /healthz: (82.307µs) 200 [kube-probe/1.15+ 127.0.0.1:53650]
I0319 17:05:10.118241       1 wrap.go:47] GET /healthz: (73.722µs) 200 [kube-probe/1.15+ 127.0.0.1:53688]
I0319 17:05:19.662155       1 scheduling_queue.go:908] About to try and schedule pod statefulset-6320/ss2-0
I0319 17:05:19.662187       1 scheduler.go:453] Attempting to schedule pod: statefulset-6320/ss2-0
I0319 17:05:19.664634       1 scheduler_binder.go:269] AssumePodVolumes for pod "statefulset-6320/ss2-0", node "e2e-test-peterhornyack-windows-node-group-dp2r"
I0319 17:05:19.664663       1 scheduler_binder.go:279] AssumePodVolumes for pod "statefulset-6320/ss2-0", node "e2e-test-peterhornyack-windows-node-group-dp2r": all PVCs bound and nothing to do
I0319 17:05:19.668175       1 factory.go:733] Attempting to bind ss2-0 to e2e-test-peterhornyack-windows-node-group-dp2r
I0319 17:05:19.685858       1 scheduler.go:572] pod statefulset-6320/ss2-0 is bound successfully on node e2e-test-peterhornyack-windows-node-group-dp2r, 5 nodes evaluated, 2 nodes were found feasible
I0319 17:05:20.117916       1 wrap.go:47] GET /healthz: (86.424µs) 200 [kube-probe/1.15+ 127.0.0.1:53720]
I0319 17:05:30.117934       1 wrap.go:47] GET /healthz: (76.328µs) 200 [kube-probe/1.15+ 127.0.0.1:53756]
I0319 17:05:40.090389       1 reflector.go:370] k8s.io/client-go/informers/factory.go:133: Watch close - *v1.Service total 1 items received
I0319 17:05:40.118102       1 wrap.go:47] GET /healthz: (123.601µs) 200 [kube-probe/1.15+ 127.0.0.1:53804]
I0319 17:05:50.118067       1 wrap.go:47] GET /healthz: (82.194µs) 200 [kube-probe/1.15+ 127.0.0.1:53836]
I0319 17:06:00.117800       1 wrap.go:47] GET /healthz: (71.466µs) 200 [kube-probe/1.15+ 127.0.0.1:53872]
I0319 17:06:07.071512       1 reflector.go:370] k8s.io/client-go/informers/factory.go:133: Watch close - *v1.Node total 57 items received
I0319 17:06:10.117824       1 wrap.go:47] GET /healthz: (76.024µs) 200 [kube-probe/1.15+ 127.0.0.1:53910]
I0319 17:06:20.118256       1 wrap.go:47] GET /healthz: (71.557µs) 200 [kube-probe/1.15+ 127.0.0.1:53942]
I0319 17:06:26.076597       1 reflector.go:370] k8s.io/client-go/informers/factory.go:133: Watch close - *v1.StorageClass total 0 items received
I0319 17:06:30.118498       1 wrap.go:47] GET /healthz: (88.473µs) 200 [kube-probe/1.15+ 127.0.0.1:53976]
I0319 17:06:36.038349       1 reflector.go:370] k8s.io/kubernetes/cmd/kube-scheduler/app/server.go:223: Watch close - *v1.Pod total 83 items received
I0319 17:06:40.117833       1 wrap.go:47] GET /healthz: (77.453µs) 200 [kube-probe/1.15+ 127.0.0.1:54026]
I0319 17:06:50.118619       1 wrap.go:47] GET /healthz: (81.828µs) 200 [kube-probe/1.15+ 127.0.0.1:54058]
I0319 17:06:52.076454       1 reflector.go:370] k8s.io/client-go/informers/factory.go:133: Watch close - *v1.PersistentVolumeClaim total 0 items received
I0319 17:07:00.118238       1 wrap.go:47] GET /healthz: (75.904µs) 200 [kube-probe/1.15+ 127.0.0.1:54092]
I0319 17:07:10.118084       1 wrap.go:47] GET /healthz: (93.842µs) 200 [kube-probe/1.15+ 127.0.0.1:54132]
I0319 17:07:12.064186       1 reflector.go:370] k8s.io/client-go/informers/factory.go:133: Watch close - *v1beta1.PodDisruptionBudget total 0 items received
I0319 17:07:20.117894       1 wrap.go:47] GET /healthz: (59.515µs) 200 [kube-probe/1.15+ 127.0.0.1:54164]
I0319 17:07:23.036199       1 reflector.go:370] k8s.io/client-go/informers/factory.go:133: Watch close - *v1.StatefulSet total 30 items received
I0319 17:07:30.118348       1 wrap.go:47] GET /healthz: (76.183µs) 200 [kube-probe/1.15+ 127.0.0.1:54200]
I0319 17:07:40.118287       1 wrap.go:47] GET /healthz: (69.288µs) 200 [kube-probe/1.15+ 127.0.0.1:54260]
I0319 17:07:50.117895       1 wrap.go:47] GET /healthz: (77.858µs) 200 [kube-probe/1.15+ 127.0.0.1:54294]
I0319 17:08:00.118207       1 wrap.go:47] GET /healthz: (90.753µs) 200 [kube-probe/1.15+ 127.0.0.1:54330]
I0319 17:08:10.118555       1 wrap.go:47] GET /healthz: (88.798µs) 200 [kube-probe/1.15+ 127.0.0.1:54368]
I0319 17:08:20.118937       1 wrap.go:47] GET /healthz: (124.584µs) 200 [kube-probe/1.15+ 127.0.0.1:54400]
I0319 17:08:21.100711       1 reflector.go:370] k8s.io/client-go/informers/factory.go:133: Watch close - *v1.ReplicationController total 0 items received
I0319 17:08:30.118266       1 wrap.go:47] GET /healthz: (76.09µs) 200 [kube-probe/1.15+ 127.0.0.1:54434]
I0319 17:08:40.118102       1 wrap.go:47] GET /healthz: (91.748µs) 200 [kube-probe/1.15+ 127.0.0.1:54488]
I0319 17:08:45.042854       1 reflector.go:370] k8s.io/client-go/informers/factory.go:133: Watch close - *v1.PersistentVolume total 5 items received
I0319 17:08:49.581361       1 scheduling_queue.go:908] About to try and schedule pod configmap-2144/pod-configmaps-aa01d3cd-4a69-11e9-af5d-a08cfde32bdd
I0319 17:08:49.581395       1 scheduler.go:453] Attempting to schedule pod: configmap-2144/pod-configmaps-aa01d3cd-4a69-11e9-af5d-a08cfde32bdd
I0319 17:08:49.582549       1 scheduler_binder.go:269] AssumePodVolumes for pod "configmap-2144/pod-configmaps-aa01d3cd-4a69-11e9-af5d-a08cfde32bdd", node "e2e-test-peterhornyack-windows-node-group-7n03"
I0319 17:08:49.582605       1 scheduler_binder.go:279] AssumePodVolumes for pod "configmap-2144/pod-configmaps-aa01d3cd-4a69-11e9-af5d-a08cfde32bdd", node "e2e-test-peterhornyack-windows-node-group-7n03": all PVCs bound and nothing to do
I0319 17:08:49.582657       1 factory.go:733] Attempting to bind pod-configmaps-aa01d3cd-4a69-11e9-af5d-a08cfde32bdd to e2e-test-peterhornyack-windows-node-group-7n03
I0319 17:08:49.592366       1 scheduler.go:572] pod configmap-2144/pod-configmaps-aa01d3cd-4a69-11e9-af5d-a08cfde32bdd is bound successfully on node e2e-test-peterhornyack-windows-node-group-7n03, 5 nodes evaluated, 2 nodes were found feasible
I0319 17:08:50.117889       1 wrap.go:47] GET /healthz: (80.803µs) 200 [kube-probe/1.15+ 127.0.0.1:54522]
I0319 17:09:00.118360       1 wrap.go:47] GET /healthz: (79.805µs) 200 [kube-probe/1.15+ 127.0.0.1:54556]
I0319 17:09:10.117950       1 wrap.go:47] GET /healthz: (89.912µs) 200 [kube-probe/1.15+ 127.0.0.1:54596]
I0319 17:09:20.122132       1 wrap.go:47] GET /healthz: (91.488µs) 200 [kube-probe/1.15+ 127.0.0.1:54628]
I0319 17:09:25.872179       1 scheduling_queue.go:908] About to try and schedule pod var-expansion-1070/var-expansion-bfa368d4-4a69-11e9-af5d-a08cfde32bdd
I0319 17:09:25.872222       1 scheduler.go:453] Attempting to schedule pod: var-expansion-1070/var-expansion-bfa368d4-4a69-11e9-af5d-a08cfde32bdd
I0319 17:09:25.874351       1 scheduler_binder.go:269] AssumePodVolumes for pod "var-expansion-1070/var-expansion-bfa368d4-4a69-11e9-af5d-a08cfde32bdd", node "e2e-test-peterhornyack-windows-node-group-7n03"
I0319 17:09:25.874395       1 scheduler_binder.go:279] AssumePodVolumes for pod "var-expansion-1070/var-expansion-bfa368d4-4a69-11e9-af5d-a08cfde32bdd", node "e2e-test-peterhornyack-windows-node-group-7n03": all PVCs bound and nothing to do
I0319 17:09:25.874505       1 factory.go:733] Attempting to bind var-expansion-bfa368d4-4a69-11e9-af5d-a08cfde32bdd to e2e-test-peterhornyack-windows-node-group-7n03
I0319 17:09:25.883265       1 scheduler.go:572] pod var-expansion-1070/var-expansion-bfa368d4-4a69-11e9-af5d-a08cfde32bdd is bound successfully on node e2e-test-peterhornyack-windows-node-group-7n03, 5 nodes evaluated, 2 nodes were found feasible
I0319 17:09:30.118054       1 wrap.go:47] GET /healthz: (57.084µs) 200 [kube-probe/1.15+ 127.0.0.1:54662]
I0319 17:09:40.117855       1 wrap.go:47] GET /healthz: (82.35µs) 200 [kube-probe/1.15+ 127.0.0.1:54710]
I0319 17:09:46.476751       1 scheduling_queue.go:908] About to try and schedule pod downward-api-2631/downwardapi-volume-cbeb8182-4a69-11e9-af5d-a08cfde32bdd
I0319 17:09:46.476806       1 scheduler.go:453] Attempting to schedule pod: downward-api-2631/downwardapi-volume-cbeb8182-4a69-11e9-af5d-a08cfde32bdd
I0319 17:09:46.477145       1 scheduler_binder.go:269] AssumePodVolumes for pod "downward-api-2631/downwardapi-volume-cbeb8182-4a69-11e9-af5d-a08cfde32bdd", node "e2e-test-peterhornyack-windows-node-group-7n03"
I0319 17:09:46.477165       1 scheduler_binder.go:279] AssumePodVolumes for pod "downward-api-2631/downwardapi-volume-cbeb8182-4a69-11e9-af5d-a08cfde32bdd", node "e2e-test-peterhornyack-windows-node-group-7n03": all PVCs bound and nothing to do
I0319 17:09:46.477239       1 factory.go:733] Attempting to bind downwardapi-volume-cbeb8182-4a69-11e9-af5d-a08cfde32bdd to e2e-test-peterhornyack-windows-node-group-7n03
I0319 17:09:46.484844       1 scheduler.go:572] pod downward-api-2631/downwardapi-volume-cbeb8182-4a69-11e9-af5d-a08cfde32bdd is bound successfully on node e2e-test-peterhornyack-windows-node-group-7n03, 5 nodes evaluated, 2 nodes were found feasible
I0319 17:09:50.118100       1 wrap.go:47] GET /healthz: (88.468µs) 200 [kube-probe/1.15+ 127.0.0.1:54742]
I0319 17:10:00.118328       1 wrap.go:47] GET /healthz: (90.382µs) 200 [kube-probe/1.15+ 127.0.0.1:54776]
I0319 17:10:02.914381       1 scheduling_queue.go:908] About to try and schedule pod container-runtime-8360/image-pull-testd5b86802-4a69-11e9-af5d-a08cfde32bdd
I0319 17:10:02.914426       1 scheduler.go:453] Attempting to schedule pod: container-runtime-8360/image-pull-testd5b86802-4a69-11e9-af5d-a08cfde32bdd
I0319 17:10:02.915621       1 scheduler_binder.go:269] AssumePodVolumes for pod "container-runtime-8360/image-pull-testd5b86802-4a69-11e9-af5d-a08cfde32bdd", node "e2e-test-peterhornyack-windows-node-group-dp2r"
I0319 17:10:02.918591       1 scheduler_binder.go:279] AssumePodVolumes for pod "container-runtime-8360/image-pull-testd5b86802-4a69-11e9-af5d-a08cfde32bdd", node "e2e-test-peterhornyack-windows-node-group-dp2r": all PVCs bound and nothing to do
I0319 17:10:02.918694       1 factory.go:733] Attempting to bind image-pull-testd5b86802-4a69-11e9-af5d-a08cfde32bdd to e2e-test-peterhornyack-windows-node-group-dp2r
I0319 17:10:02.926208       1 scheduler.go:572] pod container-runtime-8360/image-pull-testd5b86802-4a69-11e9-af5d-a08cfde32bdd is bound successfully on node e2e-test-peterhornyack-windows-node-group-dp2r, 5 nodes evaluated, 2 nodes were found feasible
I0319 17:10:10.118131       1 wrap.go:47] GET /healthz: (165.119µs) 200 [kube-probe/1.15+ 127.0.0.1:54816]
I0319 17:10:19.694557       1 scheduling_queue.go:908] About to try and schedule pod secrets-9334/pod-secrets-dfb86eea-4a69-11e9-af5d-a08cfde32bdd
I0319 17:10:19.694612       1 scheduler.go:453] Attempting to schedule pod: secrets-9334/pod-secrets-dfb86eea-4a69-11e9-af5d-a08cfde32bdd
I0319 17:10:19.696837       1 scheduler_binder.go:269] AssumePodVolumes for pod "secrets-9334/pod-secrets-dfb86eea-4a69-11e9-af5d-a08cfde32bdd", node "e2e-test-peterhornyack-windows-node-group-7n03"
I0319 17:10:19.696867       1 scheduler_binder.go:279] AssumePodVolumes for pod "secrets-9334/pod-secrets-dfb86eea-4a69-11e9-af5d-a08cfde32bdd", node "e2e-test-peterhornyack-windows-node-group-7n03": all PVCs bound and nothing to do
I0319 17:10:19.696932       1 factory.go:733] Attempting to bind pod-secrets-dfb86eea-4a69-11e9-af5d-a08cfde32bdd to e2e-test-peterhornyack-windows-node-group-7n03
I0319 17:10:19.713109       1 scheduler.go:572] pod secrets-9334/pod-secrets-dfb86eea-4a69-11e9-af5d-a08cfde32bdd is bound successfully on node e2e-test-peterhornyack-windows-node-group-7n03, 5 nodes evaluated, 2 nodes were found feasible
I0319 17:10:20.118206       1 wrap.go:47] GET /healthz: (76.271µs) 200 [kube-probe/1.15+ 127.0.0.1:54850]
I0319 17:10:30.118331       1 wrap.go:47] GET /healthz: (95.853µs) 200 [kube-probe/1.15+ 127.0.0.1:54884]
I0319 17:10:40.117893       1 wrap.go:47] GET /healthz: (76.928µs) 200 [kube-probe/1.15+ 127.0.0.1:54932]
I0319 17:10:50.118264       1 wrap.go:47] GET /healthz: (81.659µs) 200 [kube-probe/1.15+ 127.0.0.1:54964]
I0319 17:11:00.117826       1 wrap.go:47] GET /healthz: (83.026µs) 200 [kube-probe/1.15+ 127.0.0.1:54998]
I0319 17:11:00.474934       1 scheduling_queue.go:908] About to try and schedule pod projected-2029/pod-projected-configmaps-f8079bc5-4a69-11e9-af5d-a08cfde32bdd
I0319 17:11:00.474967       1 scheduler.go:453] Attempting to schedule pod: projected-2029/pod-projected-configmaps-f8079bc5-4a69-11e9-af5d-a08cfde32bdd
I0319 17:11:00.478491       1 scheduler_binder.go:269] AssumePodVolumes for pod "projected-2029/pod-projected-configmaps-f8079bc5-4a69-11e9-af5d-a08cfde32bdd", node "e2e-test-peterhornyack-windows-node-group-7n03"
I0319 17:11:00.478549       1 scheduler_binder.go:279] AssumePodVolumes for pod "projected-2029/pod-projected-configmaps-f8079bc5-4a69-11e9-af5d-a08cfde32bdd", node "e2e-test-peterhornyack-windows-node-group-7n03": all PVCs bound and nothing to do
I0319 17:11:00.478648       1 factory.go:733] Attempting to bind pod-projected-configmaps-f8079bc5-4a69-11e9-af5d-a08cfde32bdd to e2e-test-peterhornyack-windows-node-group-7n03
I0319 17:11:00.487215       1 scheduler.go:572] pod projected-2029/pod-projected-configmaps-f8079bc5-4a69-11e9-af5d-a08cfde32bdd is bound successfully on node e2e-test-peterhornyack-windows-node-group-7n03, 5 nodes evaluated, 2 nodes were found feasible
I0319 17:11:10.117798       1 wrap.go:47] GET /healthz: (71.493µs) 200 [kube-probe/1.15+ 127.0.0.1:55036]
I0319 17:11:18.074816       1 reflector.go:370] k8s.io/client-go/informers/factory.go:133: Watch close - *v1.Node total 35 items received
I0319 17:11:20.118050       1 wrap.go:47] GET /healthz: (75.519µs) 200 [kube-probe/1.15+ 127.0.0.1:55068]
I0319 17:11:30.118324       1 wrap.go:47] GET /healthz: (78.517µs) 200 [kube-probe/1.15+ 127.0.0.1:55104]
I0319 17:11:40.121848       1 wrap.go:47] GET /healthz: (84.594µs) 200 [kube-probe/1.15+ 127.0.0.1:55154]
I0319 17:11:50.118064       1 wrap.go:47] GET /healthz: (93.628µs) 200 [kube-probe/1.15+ 127.0.0.1:55186]
I0319 17:11:58.059765       1 reflector.go:370] k8s.io/client-go/informers/factory.go:133: Watch close - *v1.ReplicaSet total 0 items received
I0319 17:12:00.093921       1 reflector.go:370] k8s.io/client-go/informers/factory.go:133: Watch close - *v1.Service total 1 items received
I0319 17:12:00.119163       1 wrap.go:47] GET /healthz: (75.236µs) 200 [kube-probe/1.15+ 127.0.0.1:55220]
I0319 17:12:10.118128       1 wrap.go:47] GET /healthz: (101.515µs) 200 [kube-probe/1.15+ 127.0.0.1:55258]
I0319 17:12:20.117966       1 wrap.go:47] GET /healthz: (80.037µs) 200 [kube-probe/1.15+ 127.0.0.1:55290]
I0319 17:12:30.118094       1 wrap.go:47] GET /healthz: (111.713µs) 200 [kube-probe/1.15+ 127.0.0.1:55326]
I0319 17:12:34.511130       1 scheduling_queue.go:908] About to try and schedule pod volume-9475/gcepd-injector-hvk8
I0319 17:12:34.512096       1 scheduler.go:453] Attempting to schedule pod: volume-9475/gcepd-injector-hvk8
I0319 17:12:34.513856       1 csi_volume_predicate.go:147] Not considering non-CSI volume volume-9475/pvc-x7k8p
I0319 17:12:34.513910       1 scheduler_binder.go:665] All bound volumes for Pod "volume-9475/gcepd-injector-hvk8" match with Node "e2e-test-peterhornyack-windows-node-group-7n03"
I0319 17:12:34.513979       1 csi_volume_predicate.go:147] Not considering non-CSI volume volume-9475/pvc-x7k8p
I0319 17:12:34.514000       1 scheduler_binder.go:665] All bound volumes for Pod "volume-9475/gcepd-injector-hvk8" match with Node "e2e-test-peterhornyack-windows-node-group-dp2r"
I0319 17:12:34.515547       1 scheduler_binder.go:269] AssumePodVolumes for pod "volume-9475/gcepd-injector-hvk8", node "e2e-test-peterhornyack-windows-node-group-dp2r"
I0319 17:12:34.515577       1 scheduler_binder.go:279] AssumePodVolumes for pod "volume-9475/gcepd-injector-hvk8", node "e2e-test-peterhornyack-windows-node-group-dp2r": all PVCs bound and nothing to do
I0319 17:12:34.515637       1 factory.go:733] Attempting to bind gcepd-injector-hvk8 to e2e-test-peterhornyack-windows-node-group-dp2r
I0319 17:12:34.525328       1 scheduler.go:572] pod volume-9475/gcepd-injector-hvk8 is bound successfully on node e2e-test-peterhornyack-windows-node-group-dp2r, 5 nodes evaluated, 2 nodes were found feasible
I0319 17:12:40.118303       1 wrap.go:47] GET /healthz: (74.194µs) 200 [kube-probe/1.15+ 127.0.0.1:55376]
I0319 17:12:50.117880       1 wrap.go:47] GET /healthz: (145.777µs) 200 [kube-probe/1.15+ 127.0.0.1:55410]
I0319 17:13:00.117895       1 wrap.go:47] GET /healthz: (71.289µs) 200 [kube-probe/1.15+ 127.0.0.1:55446]
I0319 17:13:07.352044       1 scheduling_queue.go:908] About to try and schedule pod volume-9475/gcepd-client
I0319 17:13:07.352089       1 scheduler.go:453] Attempting to schedule pod: volume-9475/gcepd-client
I0319 17:13:07.352318       1 csi_volume_predicate.go:147] Not considering non-CSI volume volume-9475/pvc-x7k8p
I0319 17:13:07.352367       1 scheduler_binder.go:665] All bound volumes for Pod "volume-9475/gcepd-client" match with Node "e2e-test-peterhornyack-windows-node-group-7n03"
I0319 17:13:07.352408       1 csi_volume_predicate.go:147] Not considering non-CSI volume volume-9475/pvc-x7k8p
I0319 17:13:07.352427       1 scheduler_binder.go:665] All bound volumes for Pod "volume-9475/gcepd-client" match with Node "e2e-test-peterhornyack-windows-node-group-dp2r"
I0319 17:13:07.352693       1 scheduler_binder.go:269] AssumePodVolumes for pod "volume-9475/gcepd-client", node "e2e-test-peterhornyack-windows-node-group-dp2r"
I0319 17:13:07.352731       1 scheduler_binder.go:279] AssumePodVolumes for pod "volume-9475/gcepd-client", node "e2e-test-peterhornyack-windows-node-group-dp2r": all PVCs bound and nothing to do
I0319 17:13:07.352778       1 factory.go:733] Attempting to bind gcepd-client to e2e-test-peterhornyack-windows-node-group-dp2r
I0319 17:13:07.361193       1 scheduler.go:572] pod volume-9475/gcepd-client is bound successfully on node e2e-test-peterhornyack-windows-node-group-dp2r, 5 nodes evaluated, 2 nodes were found feasible
I0319 17:13:10.117851       1 wrap.go:47] GET /healthz: (74.978µs) 200 [kube-probe/1.15+ 127.0.0.1:55484]
I0319 17:13:20.118242       1 wrap.go:47] GET /healthz: (105.2µs) 200 [kube-probe/1.15+ 127.0.0.1:55516]
I0319 17:13:30.067274       1 reflector.go:370] k8s.io/client-go/informers/factory.go:133: Watch close - *v1beta1.PodDisruptionBudget total 0 items received
I0319 17:13:30.117817       1 wrap.go:47] GET /healthz: (70.727µs) 200 [kube-probe/1.15+ 127.0.0.1:55550]
I0319 17:13:40.140190       1 wrap.go:47] GET /healthz: (80.349µs) 200 [kube-probe/1.15+ 127.0.0.1:55600]
I0319 17:13:41.079997       1 reflector.go:370] k8s.io/client-go/informers/factory.go:133: Watch close - *v1.StorageClass total 2 items received
I0319 17:13:50.158311       1 wrap.go:47] GET /healthz: (89.879µs) 200 [kube-probe/1.15+ 127.0.0.1:55632]
I0319 17:13:54.104654       1 reflector.go:370] k8s.io/client-go/informers/factory.go:133: Watch close - *v1.ReplicationController total 0 items received
I0319 17:14:00.118303       1 wrap.go:47] GET /healthz: (97.477µs) 200 [kube-probe/1.15+ 127.0.0.1:55668]
I0319 17:14:10.117796       1 wrap.go:47] GET /healthz: (57.668µs) 200 [kube-probe/1.15+ 127.0.0.1:55706]
I0319 17:14:20.118989       1 wrap.go:47] GET /healthz: (78.094µs) 200 [kube-probe/1.15+ 127.0.0.1:55740]
I0319 17:14:30.118258       1 wrap.go:47] GET /healthz: (84.716µs) 200 [kube-probe/1.15+ 127.0.0.1:55774]
I0319 17:14:37.081978       1 reflector.go:370] k8s.io/client-go/informers/factory.go:133: Watch close - *v1.PersistentVolumeClaim total 11 items received
I0319 17:14:40.118288       1 wrap.go:47] GET /healthz: (74.73µs) 200 [kube-probe/1.15+ 127.0.0.1:55822]
I0319 17:14:50.117889       1 wrap.go:47] GET /healthz: (87.755µs) 200 [kube-probe/1.15+ 127.0.0.1:55854]
I0319 17:15:00.117792       1 wrap.go:47] GET /healthz: (55.589µs) 200 [kube-probe/1.15+ 127.0.0.1:55888]
I0319 17:15:00.824087       1 scheduling_queue.go:908] About to try and schedule pod kubectl-9414/e2e-test-nginx-pod
I0319 17:15:00.824119       1 scheduler.go:453] Attempting to schedule pod: kubectl-9414/e2e-test-nginx-pod
I0319 17:15:00.824438       1 scheduler_binder.go:269] AssumePodVolumes for pod "kubectl-9414/e2e-test-nginx-pod", node "e2e-test-peterhornyack-windows-node-group-7n03"
I0319 17:15:00.824455       1 scheduler_binder.go:279] AssumePodVolumes for pod "kubectl-9414/e2e-test-nginx-pod", node "e2e-test-peterhornyack-windows-node-group-7n03": all PVCs bound and nothing to do
I0319 17:15:00.824494       1 factory.go:733] Attempting to bind e2e-test-nginx-pod to e2e-test-peterhornyack-windows-node-group-7n03
I0319 17:15:00.837390       1 scheduler.go:572] pod kubectl-9414/e2e-test-nginx-pod is bound successfully on node e2e-test-peterhornyack-windows-node-group-7n03, 5 nodes evaluated, 2 nodes were found feasible
I0319 17:15:10.120296       1 wrap.go:47] GET /healthz: (90.069µs) 200 [kube-probe/1.15+ 127.0.0.1:55928]
I0319 17:15:11.040258       1 reflector.go:370] k8s.io/kubernetes/cmd/kube-scheduler/app/server.go:223: Watch close - *v1.Pod total 114 items received
I0319 17:15:11.474737       1 scheduling_queue.go:908] About to try and schedule pod container-lifecycle-hook-1468/pod-handle-http-request
I0319 17:15:11.474773       1 scheduler.go:453] Attempting to schedule pod: container-lifecycle-hook-1468/pod-handle-http-request
I0319 17:15:11.476936       1 scheduler_binder.go:269] AssumePodVolumes for pod "container-lifecycle-hook-1468/pod-handle-http-request", node "e2e-test-peterhornyack-windows-node-group-dp2r"
I0319 17:15:11.476970       1 scheduler_binder.go:279] AssumePodVolumes for pod "container-lifecycle-hook-1468/pod-handle-http-request", node "e2e-test-peterhornyack-windows-node-group-dp2r": all PVCs bound and nothing to do
I0319 17:15:11.477176       1 factory.go:733] Attempting to bind pod-handle-http-request to e2e-test-peterhornyack-windows-node-group-dp2r
I0319 17:15:11.485216       1 scheduler.go:572] pod container-lifecycle-hook-1468/pod-handle-http-request is bound successfully on node e2e-test-peterhornyack-windows-node-group-dp2r, 5 nodes evaluated, 2 nodes were found feasible
I0319 17:15:20.118068       1 wrap.go:47] GET /healthz: (111.801µs) 200 [kube-probe/1.15+ 127.0.0.1:55960]
I0319 17:15:25.649442       1 scheduling_queue.go:908] About to try and schedule pod container-lifecycle-hook-1468/pod-with-prestop-exec-hook
I0319 17:15:25.649475       1 scheduler.go:453] Attempting to schedule pod: container-lifecycle-hook-1468/pod-with-prestop-exec-hook
I0319 17:15:25.651180       1 scheduler_binder.go:269] AssumePodVolumes for pod "container-lifecycle-hook-1468/pod-with-prestop-exec-hook", node "e2e-test-peterhornyack-windows-node-group-7n03"
I0319 17:15:25.651212       1 scheduler_binder.go:279] AssumePodVolumes for pod "container-lifecycle-hook-1468/pod-with-prestop-exec-hook", node "e2e-test-peterhornyack-windows-node-group-7n03": all PVCs bound and nothing to do
I0319 17:15:25.651279       1 factory.go:733] Attempting to bind pod-with-prestop-exec-hook to e2e-test-peterhornyack-windows-node-group-7n03
I0319 17:15:25.659165       1 scheduler.go:572] pod container-lifecycle-hook-1468/pod-with-prestop-exec-hook is bound successfully on node e2e-test-peterhornyack-windows-node-group-7n03, 5 nodes evaluated, 2 nodes were found feasible
I0319 17:15:30.118074       1 wrap.go:47] GET /healthz: (152.956µs) 200 [kube-probe/1.15+ 127.0.0.1:55994]
I0319 17:15:40.118518       1 wrap.go:47] GET /healthz: (77.909µs) 200 [kube-probe/1.15+ 127.0.0.1:56044]
I0319 17:15:50.118319       1 wrap.go:47] GET /healthz: (82.09µs) 200 [kube-probe/1.15+ 127.0.0.1:56078]
I0319 17:16:00.119343       1 wrap.go:47] GET /healthz: (80.556µs) 200 [kube-probe/1.15+ 127.0.0.1:56112]
I0319 17:16:08.051222       1 scheduling_queue.go:908] About to try and schedule pod containers-6867/client-containers-af5ad189-4a6a-11e9-af5d-a08cfde32bdd
I0319 17:16:08.051258       1 scheduler.go:453] Attempting to schedule pod: containers-6867/client-containers-af5ad189-4a6a-11e9-af5d-a08cfde32bdd
I0319 17:16:08.055851       1 scheduler_binder.go:269] AssumePodVolumes for pod "containers-6867/client-containers-af5ad189-4a6a-11e9-af5d-a08cfde32bdd", node "e2e-test-peterhornyack-windows-node-group-dp2r"
I0319 17:16:08.055895       1 scheduler_binder.go:279] AssumePodVolumes for pod "containers-6867/client-containers-af5ad189-4a6a-11e9-af5d-a08cfde32bdd", node "e2e-test-peterhornyack-windows-node-group-dp2r": all PVCs bound and nothing to do
I0319 17:16:08.055958       1 factory.go:733] Attempting to bind client-containers-af5ad189-4a6a-11e9-af5d-a08cfde32bdd to e2e-test-peterhornyack-windows-node-group-dp2r
I0319 17:16:08.076230       1 scheduler.go:572] pod containers-6867/client-containers-af5ad189-4a6a-11e9-af5d-a08cfde32bdd is bound successfully on node e2e-test-peterhornyack-windows-node-group-dp2r, 5 nodes evaluated, 2 nodes were found feasible
I0319 17:16:10.117611       1 wrap.go:47] GET /healthz: (75.199µs) 200 [kube-probe/1.15+ 127.0.0.1:56150]
I0319 17:16:13.039926       1 reflector.go:370] k8s.io/client-go/informers/factory.go:133: Watch close - *v1.StatefulSet total 12 items received
I0319 17:16:20.046111       1 reflector.go:370] k8s.io/client-go/informers/factory.go:133: Watch close - *v1.PersistentVolume total 7 items received
I0319 17:16:20.117984       1 wrap.go:47] GET /healthz: (68.454µs) 200 [kube-probe/1.15+ 127.0.0.1:56182]
I0319 17:16:28.588466       1 scheduling_queue.go:908] About to try and schedule pod dns-1640/dns-test-bb9928c7-4a6a-11e9-af5d-a08cfde32bdd
I0319 17:16:28.588497       1 scheduler.go:453] Attempting to schedule pod: dns-1640/dns-test-bb9928c7-4a6a-11e9-af5d-a08cfde32bdd
I0319 17:16:28.588887       1 scheduler_binder.go:269] AssumePodVolumes for pod "dns-1640/dns-test-bb9928c7-4a6a-11e9-af5d-a08cfde32bdd", node "e2e-test-peterhornyack-windows-node-group-7n03"
I0319 17:16:28.588907       1 scheduler_binder.go:279] AssumePodVolumes for pod "dns-1640/dns-test-bb9928c7-4a6a-11e9-af5d-a08cfde32bdd", node "e2e-test-peterhornyack-windows-node-group-7n03": all PVCs bound and nothing to do
I0319 17:16:28.588964       1 factory.go:733] Attempting to bind dns-test-bb9928c7-4a6a-11e9-af5d-a08cfde32bdd to e2e-test-peterhornyack-windows-node-group-7n03
I0319 17:16:28.596294       1 scheduler.go:572] pod dns-1640/dns-test-bb9928c7-4a6a-11e9-af5d-a08cfde32bdd is bound successfully on node e2e-test-peterhornyack-windows-node-group-7n03, 5 nodes evaluated, 2 nodes were found feasible
I0319 17:16:30.117972       1 wrap.go:47] GET /healthz: (68.576µs) 200 [kube-probe/1.15+ 127.0.0.1:56218]
I0319 17:16:40.118185       1 wrap.go:47] GET /healthz: (82.117µs) 200 [kube-probe/1.15+ 127.0.0.1:56266]
I0319 17:16:50.118399       1 wrap.go:47] GET /healthz: (75.044µs) 200 [kube-probe/1.15+ 127.0.0.1:56298]
I0319 17:17:00.118247       1 wrap.go:47] GET /healthz: (91.388µs) 200 [kube-probe/1.15+ 127.0.0.1:56332]
I0319 17:17:09.699292       1 scheduling_queue.go:908] About to try and schedule pod projected-3094/labelsupdated418a441-4a6a-11e9-af5d-a08cfde32bdd
I0319 17:17:09.699327       1 scheduler.go:453] Attempting to schedule pod: projected-3094/labelsupdated418a441-4a6a-11e9-af5d-a08cfde32bdd
I0319 17:17:09.699732       1 scheduler_binder.go:269] AssumePodVolumes for pod "projected-3094/labelsupdated418a441-4a6a-11e9-af5d-a08cfde32bdd", node "e2e-test-peterhornyack-windows-node-group-7n03"
I0319 17:17:09.699750       1 scheduler_binder.go:279] AssumePodVolumes for pod "projected-3094/labelsupdated418a441-4a6a-11e9-af5d-a08cfde32bdd", node "e2e-test-peterhornyack-windows-node-group-7n03": all PVCs bound and nothing to do
I0319 17:17:09.706341       1 factory.go:733] Attempting to bind labelsupdated418a441-4a6a-11e9-af5d-a08cfde32bdd to e2e-test-peterhornyack-windows-node-group-7n03
I0319 17:17:09.722951       1 scheduler.go:572] pod projected-3094/labelsupdated418a441-4a6a-11e9-af5d-a08cfde32bdd is bound successfully on node e2e-test-peterhornyack-windows-node-group-7n03, 5 nodes evaluated, 2 nodes were found feasible
I0319 17:17:10.118099       1 wrap.go:47] GET /healthz: (95.163µs) 200 [kube-probe/1.15+ 127.0.0.1:56374]
I0319 17:17:20.118140       1 wrap.go:47] GET /healthz: (78.602µs) 200 [kube-probe/1.15+ 127.0.0.1:56406]
I0319 17:17:30.118412       1 wrap.go:47] GET /healthz: (70.446µs) 200 [kube-probe/1.15+ 127.0.0.1:56452]
I0319 17:17:40.118277       1 wrap.go:47] GET /healthz: (80.391µs) 200 [kube-probe/1.15+ 127.0.0.1:56502]
I0319 17:17:50.118059       1 wrap.go:47] GET /healthz: (83.687µs) 200 [kube-probe/1.15+ 127.0.0.1:56534]
I0319 17:18:00.118077       1 wrap.go:47] GET /healthz: (87.81µs) 200 [kube-probe/1.15+ 127.0.0.1:56568]
I0319 17:18:10.118131       1 wrap.go:47] GET /healthz: (95.93µs) 200 [kube-probe/1.15+ 127.0.0.1:56608]
I0319 17:18:20.118174       1 wrap.go:47] GET /healthz: (76.097µs) 200 [kube-probe/1.15+ 127.0.0.1:56640]
I0319 17:18:30.118372       1 wrap.go:47] GET /healthz: (78.031µs) 200 [kube-probe/1.15+ 127.0.0.1:56676]
I0319 17:18:30.767703       1 scheduling_queue.go:908] About to try and schedule pod pods-2171/server-envvars-046c260e-4a6b-11e9-af5d-a08cfde32bdd
I0319 17:18:30.769527       1 scheduler.go:453] Attempting to schedule pod: pods-2171/server-envvars-046c260e-4a6b-11e9-af5d-a08cfde32bdd
I0319 17:18:30.769981       1 scheduler_binder.go:269] AssumePodVolumes for pod "pods-2171/server-envvars-046c260e-4a6b-11e9-af5d-a08cfde32bdd", node "e2e-test-peterhornyack-windows-node-group-7n03"
I0319 17:18:30.770000       1 scheduler_binder.go:279] AssumePodVolumes for pod "pods-2171/server-envvars-046c260e-4a6b-11e9-af5d-a08cfde32bdd", node "e2e-test-peterhornyack-windows-node-group-7n03": all PVCs bound and nothing to do
I0319 17:18:30.770069       1 factory.go:733] Attempting to bind server-envvars-046c260e-4a6b-11e9-af5d-a08cfde32bdd to e2e-test-peterhornyack-windows-node-group-7n03
I0319 17:18:30.778576       1 scheduler.go:572] pod pods-2171/server-envvars-046c260e-4a6b-11e9-af5d-a08cfde32bdd is bound successfully on node e2e-test-peterhornyack-windows-node-group-7n03, 5 nodes evaluated, 2 nodes were found feasible
I0319 17:18:40.118393       1 wrap.go:47] GET /healthz: (78.698µs) 200 [kube-probe/1.15+ 127.0.0.1:56724]
I0319 17:18:42.996793       1 scheduling_queue.go:908] About to try and schedule pod pods-2171/client-envvars-0bb6cc23-4a6b-11e9-af5d-a08cfde32bdd
I0319 17:18:42.996826       1 scheduler.go:453] Attempting to schedule pod: pods-2171/client-envvars-0bb6cc23-4a6b-11e9-af5d-a08cfde32bdd
I0319 17:18:42.999919       1 scheduler_binder.go:269] AssumePodVolumes for pod "pods-2171/client-envvars-0bb6cc23-4a6b-11e9-af5d-a08cfde32bdd", node "e2e-test-peterhornyack-windows-node-group-7n03"
I0319 17:18:42.999966       1 scheduler_binder.go:279] AssumePodVolumes for pod "pods-2171/client-envvars-0bb6cc23-4a6b-11e9-af5d-a08cfde32bdd", node "e2e-test-peterhornyack-windows-node-group-7n03": all PVCs bound and nothing to do
I0319 17:18:43.000065       1 factory.go:733] Attempting to bind client-envvars-0bb6cc23-4a6b-11e9-af5d-a08cfde32bdd to e2e-test-peterhornyack-windows-node-group-7n03
I0319 17:18:43.010177       1 scheduler.go:572] pod pods-2171/client-envvars-0bb6cc23-4a6b-11e9-af5d-a08cfde32bdd is bound successfully on node e2e-test-peterhornyack-windows-node-group-7n03, 5 nodes evaluated, 2 nodes were found feasible
I0319 17:18:50.118218       1 wrap.go:47] GET /healthz: (83.587µs) 200 [kube-probe/1.15+ 127.0.0.1:56760]
I0319 17:19:00.118106       1 wrap.go:47] GET /healthz: (101.253µs) 200 [kube-probe/1.15+ 127.0.0.1:56794]
I0319 17:19:10.118302       1 wrap.go:47] GET /healthz: (96.759µs) 200 [kube-probe/1.15+ 127.0.0.1:56832]
I0319 17:19:15.473088       1 scheduling_queue.go:908] About to try and schedule pod configmap-6310/pod-configmaps-1f111c47-4a6b-11e9-af5d-a08cfde32bdd
I0319 17:19:15.473827       1 scheduler.go:453] Attempting to schedule pod: configmap-6310/pod-configmaps-1f111c47-4a6b-11e9-af5d-a08cfde32bdd
I0319 17:19:15.474239       1 scheduler_binder.go:269] AssumePodVolumes for pod "configmap-6310/pod-configmaps-1f111c47-4a6b-11e9-af5d-a08cfde32bdd", node "e2e-test-peterhornyack-windows-node-group-7n03"
I0319 17:19:15.474261       1 scheduler_binder.go:279] AssumePodVolumes for pod "configmap-6310/pod-configmaps-1f111c47-4a6b-11e9-af5d-a08cfde32bdd", node "e2e-test-peterhornyack-windows-node-group-7n03": all PVCs bound and nothing to do
I0319 17:19:15.474334       1 factory.go:733] Attempting to bind pod-configmaps-1f111c47-4a6b-11e9-af5d-a08cfde32bdd to e2e-test-peterhornyack-windows-node-group-7n03
I0319 17:19:15.486367       1 scheduler.go:572] pod configmap-6310/pod-configmaps-1f111c47-4a6b-11e9-af5d-a08cfde32bdd is bound successfully on node e2e-test-peterhornyack-windows-node-group-7n03, 5 nodes evaluated, 2 nodes were found feasible
I0319 17:19:20.118171       1 wrap.go:47] GET /healthz: (71.235µs) 200 [kube-probe/1.15+ 127.0.0.1:56864]
I0319 17:19:22.063105       1 reflector.go:370] k8s.io/client-go/informers/factory.go:133: Watch close - *v1.ReplicaSet total 0 items received
I0319 17:19:30.118534       1 wrap.go:47] GET /healthz: (89.209µs) 200 [kube-probe/1.15+ 127.0.0.1:56898]
I0319 17:19:33.078694       1 reflector.go:370] k8s.io/client-go/informers/factory.go:133: Watch close - *v1.Node total 65 items received
I0319 17:19:40.101052       1 scheduling_queue.go:908] About to try and schedule pod prestop-5157/server
I0319 17:19:40.101082       1 scheduler.go:453] Attempting to schedule pod: prestop-5157/server
I0319 17:19:40.101397       1 scheduler_binder.go:269] AssumePodVolumes for pod "prestop-5157/server", node "e2e-test-peterhornyack-windows-node-group-dp2r"
I0319 17:19:40.101425       1 scheduler_binder.go:279] AssumePodVolumes for pod "prestop-5157/server", node "e2e-test-peterhornyack-windows-node-group-dp2r": all PVCs bound and nothing to do
I0319 17:19:40.101475       1 factory.go:733] Attempting to bind server to e2e-test-peterhornyack-windows-node-group-dp2r
I0319 17:19:40.109891       1 scheduler.go:572] pod prestop-5157/server is bound successfully on node e2e-test-peterhornyack-windows-node-group-dp2r, 5 nodes evaluated, 2 nodes were found feasible
I0319 17:19:40.117897       1 wrap.go:47] GET /healthz: (54.067µs) 200 [kube-probe/1.15+ 127.0.0.1:56946]
I0319 17:19:48.273123       1 scheduling_queue.go:908] About to try and schedule pod prestop-5157/tester
I0319 17:19:48.273171       1 scheduler.go:453] Attempting to schedule pod: prestop-5157/tester
I0319 17:19:48.274892       1 scheduler_binder.go:269] AssumePodVolumes for pod "prestop-5157/tester", node "e2e-test-peterhornyack-windows-node-group-7n03"
I0319 17:19:48.274925       1 scheduler_binder.go:279] AssumePodVolumes for pod "prestop-5157/tester", node "e2e-test-peterhornyack-windows-node-group-7n03": all PVCs bound and nothing to do
I0319 17:19:48.274993       1 factory.go:733] Attempting to bind tester to e2e-test-peterhornyack-windows-node-group-7n03
I0319 17:19:48.284958       1 scheduler.go:572] pod prestop-5157/tester is bound successfully on node e2e-test-peterhornyack-windows-node-group-7n03, 5 nodes evaluated, 2 nodes were found feasible
I0319 17:19:50.119576       1 wrap.go:47] GET /healthz: (79.297µs) 200 [kube-probe/1.15+ 127.0.0.1:56980]
I0319 17:19:56.107740       1 reflector.go:370] k8s.io/client-go/informers/factory.go:133: Watch close - *v1.ReplicationController total 0 items received
I0319 17:20:00.118220       1 wrap.go:47] GET /healthz: (80.64µs) 200 [kube-probe/1.15+ 127.0.0.1:57014]
I0319 17:20:10.118274       1 wrap.go:47] GET /healthz: (75.251µs) 200 [kube-probe/1.15+ 127.0.0.1:57056]
I0319 17:20:20.118767       1 wrap.go:47] GET /healthz: (63.803µs) 200 [kube-probe/1.15+ 127.0.0.1:57088]
I0319 17:20:25.629302       1 scheduling_queue.go:908] About to try and schedule pod proxy-282/proxy-service-gs9j2-rjd4w
I0319 17:20:25.629337       1 scheduler.go:453] Attempting to schedule pod: proxy-282/proxy-service-gs9j2-rjd4w
I0319 17:20:25.629771       1 scheduler_binder.go:269] AssumePodVolumes for pod "proxy-282/proxy-service-gs9j2-rjd4w", node "e2e-test-peterhornyack-windows-node-group-dp2r"
I0319 17:20:25.629790       1 scheduler_binder.go:279] AssumePodVolumes for pod "proxy-282/proxy-service-gs9j2-rjd4w", node "e2e-test-peterhornyack-windows-node-group-dp2r": all PVCs bound and nothing to do
I0319 17:20:25.629854       1 factory.go:733] Attempting to bind proxy-service-gs9j2-rjd4w to e2e-test-peterhornyack-windows-node-group-dp2r
I0319 17:20:25.648401       1 scheduler.go:572] pod proxy-282/proxy-service-gs9j2-rjd4w is bound successfully on node e2e-test-peterhornyack-windows-node-group-dp2r, 5 nodes evaluated, 2 nodes were found feasible
I0319 17:20:30.118242       1 wrap.go:47] GET /healthz: (77.908µs) 200 [kube-probe/1.15+ 127.0.0.1:57124]
I0319 17:20:40.118105       1 wrap.go:47] GET /healthz: (159.272µs) 200 [kube-probe/1.15+ 127.0.0.1:57222]
I0319 17:20:47.833826       1 scheduling_queue.go:908] About to try and schedule pod gc-6059/simpletest.rc-zw68h
I0319 17:20:47.833892       1 scheduler.go:453] Attempting to schedule pod: gc-6059/simpletest.rc-zw68h
I0319 17:20:47.837521       1 scheduler_binder.go:269] AssumePodVolumes for pod "gc-6059/simpletest.rc-zw68h", node "e2e-test-peterhornyack-windows-node-group-7n03"
I0319 17:20:47.837552       1 scheduler_binder.go:279] AssumePodVolumes for pod "gc-6059/simpletest.rc-zw68h", node "e2e-test-peterhornyack-windows-node-group-7n03": all PVCs bound and nothing to do
I0319 17:20:47.837631       1 factory.go:733] Attempting to bind simpletest.rc-zw68h to e2e-test-peterhornyack-windows-node-group-7n03
I0319 17:20:47.851363       1 scheduling_queue.go:908] About to try and schedule pod gc-6059/simpletest.rc-f64j7
I0319 17:20:47.851395       1 scheduler.go:453] Attempting to schedule pod: gc-6059/simpletest.rc-f64j7
I0319 17:20:47.851714       1 scheduler_binder.go:269] AssumePodVolumes for pod "gc-6059/simpletest.rc-f64j7", node "e2e-test-peterhornyack-windows-node-group-7n03"
I0319 17:20:47.851729       1 scheduler_binder.go:279] AssumePodVolumes for pod "gc-6059/simpletest.rc-f64j7", node "e2e-test-peterhornyack-windows-node-group-7n03": all PVCs bound and nothing to do
I0319 17:20:47.851767       1 factory.go:733] Attempting to bind simpletest.rc-f64j7 to e2e-test-peterhornyack-windows-node-group-7n03
I0319 17:20:47.867403       1 scheduler.go:572] pod gc-6059/simpletest.rc-zw68h is bound successfully on node e2e-test-peterhornyack-windows-node-group-7n03, 5 nodes evaluated, 2 nodes were found feasible
I0319 17:20:47.871428       1 scheduling_queue.go:908] About to try and schedule pod gc-6059/simpletest.rc-xbjvh
I0319 17:20:47.874267       1 scheduler.go:453] Attempting to schedule pod: gc-6059/simpletest.rc-xbjvh
I0319 17:20:47.879736       1 scheduler_binder.go:269] AssumePodVolumes for pod "gc-6059/simpletest.rc-xbjvh", node "e2e-test-peterhornyack-windows-node-group-7n03"
I0319 17:20:47.879779       1 scheduler_binder.go:279] AssumePodVolumes for pod "gc-6059/simpletest.rc-xbjvh", node "e2e-test-peterhornyack-windows-node-group-7n03": all PVCs bound and nothing to do
I0319 17:20:47.879824       1 factory.go:733] Attempting to bind simpletest.rc-xbjvh to e2e-test-peterhornyack-windows-node-group-7n03
I0319 17:20:47.885570       1 scheduler.go:572] pod gc-6059/simpletest.rc-f64j7 is bound successfully on node e2e-test-peterhornyack-windows-node-group-7n03, 5 nodes evaluated, 2 nodes were found feasible
I0319 17:20:47.911216       1 scheduling_queue.go:908] About to try and schedule pod gc-6059/simpletest.rc-29hf6
I0319 17:20:47.911247       1 scheduler.go:453] Attempting to schedule pod: gc-6059/simpletest.rc-29hf6
I0319 17:20:47.913178       1 scheduler_binder.go:269] AssumePodVolumes for pod "gc-6059/simpletest.rc-29hf6", node "e2e-test-peterhornyack-windows-node-group-7n03"
I0319 17:20:47.913209       1 scheduler_binder.go:279] AssumePodVolumes for pod "gc-6059/simpletest.rc-29hf6", node "e2e-test-peterhornyack-windows-node-group-7n03": all PVCs bound and nothing to do
I0319 17:20:47.913294       1 factory.go:733] Attempting to bind simpletest.rc-29hf6 to e2e-test-peterhornyack-windows-node-group-7n03
I0319 17:20:47.913600       1 scheduling_queue.go:908] About to try and schedule pod gc-6059/simpletest.rc-l5szl
I0319 17:20:47.913630       1 scheduler.go:453] Attempting to schedule pod: gc-6059/simpletest.rc-l5szl
I0319 17:20:47.924252       1 scheduler_binder.go:269] AssumePodVolumes for pod "gc-6059/simpletest.rc-l5szl", node "e2e-test-peterhornyack-windows-node-group-7n03"
I0319 17:20:47.924330       1 scheduler_binder.go:279] AssumePodVolumes for pod "gc-6059/simpletest.rc-l5szl", node "e2e-test-peterhornyack-windows-node-group-7n03": all PVCs bound and nothing to do
I0319 17:20:47.924372       1 factory.go:733] Attempting to bind simpletest.rc-l5szl to e2e-test-peterhornyack-windows-node-group-7n03
I0319 17:20:47.949879       1 scheduler.go:572] pod gc-6059/simpletest.rc-xbjvh is bound successfully on node e2e-test-peterhornyack-windows-node-group-7n03, 5 nodes evaluated, 2 nodes were found feasible
I0319 17:20:47.963878       1 scheduling_queue.go:908] About to try and schedule pod gc-6059/simpletest.rc-d6xdm
I0319 17:20:47.963925       1 scheduler.go:453] Attempting to schedule pod: gc-6059/simpletest.rc-d6xdm
I0319 17:20:47.965106       1 scheduler_binder.go:269] AssumePodVolumes for pod "gc-6059/simpletest.rc-d6xdm", node "e2e-test-peterhornyack-windows-node-group-7n03"
I0319 17:20:47.965146       1 scheduler_binder.go:279] AssumePodVolumes for pod "gc-6059/simpletest.rc-d6xdm", node "e2e-test-peterhornyack-windows-node-group-7n03": all PVCs bound and nothing to do
I0319 17:20:47.965183       1 factory.go:733] Attempting to bind simpletest.rc-d6xdm to e2e-test-peterhornyack-windows-node-group-7n03
I0319 17:20:47.975425       1 scheduling_queue.go:908] About to try and schedule pod gc-6059/simpletest.rc-9dv4v
I0319 17:20:47.975457       1 scheduler.go:453] Attempting to schedule pod: gc-6059/simpletest.rc-9dv4v
I0319 17:20:47.975777       1 scheduler_binder.go:269] AssumePodVolumes for pod "gc-6059/simpletest.rc-9dv4v", node "e2e-test-peterhornyack-windows-node-group-7n03"
I0319 17:20:47.975794       1 scheduler_binder.go:279] AssumePodVolumes for pod "gc-6059/simpletest.rc-9dv4v", node "e2e-test-peterhornyack-windows-node-group-7n03": all PVCs bound and nothing to do
I0319 17:20:47.975828       1 factory.go:733] Attempting to bind simpletest.rc-9dv4v to e2e-test-peterhornyack-windows-node-group-7n03
I0319 17:20:47.982211       1 scheduler.go:572] pod gc-6059/simpletest.rc-29hf6 is bound successfully on node e2e-test-peterhornyack-windows-node-group-7n03, 5 nodes evaluated, 2 nodes were found feasible
I0319 17:20:47.999487       1 scheduler.go:572] pod gc-6059/simpletest.rc-l5szl is bound successfully on node e2e-test-peterhornyack-windows-node-group-7n03, 5 nodes evaluated, 2 nodes were found feasible
I0319 17:20:47.999582       1 scheduling_queue.go:908] About to try and schedule pod gc-6059/simpletest.rc-ppv4t
I0319 17:20:47.999592       1 scheduler.go:453] Attempting to schedule pod: gc-6059/simpletest.rc-ppv4t
I0319 17:20:48.000074       1 scheduler_binder.go:269] AssumePodVolumes for pod "gc-6059/simpletest.rc-ppv4t", node "e2e-test-peterhornyack-windows-node-group-7n03"
I0319 17:20:48.000093       1 scheduler_binder.go:279] AssumePodVolumes for pod "gc-6059/simpletest.rc-ppv4t", node "e2e-test-peterhornyack-windows-node-group-7n03": all PVCs bound and nothing to do
I0319 17:20:48.000141       1 factory.go:733] Attempting to bind simpletest.rc-ppv4t to e2e-test-peterhornyack-windows-node-group-7n03
I0319 17:20:48.006600       1 scheduling_queue.go:908] About to try and schedule pod gc-6059/simpletest.rc-jtvjc
I0319 17:20:48.006632       1 scheduler.go:453] Attempting to schedule pod: gc-6059/simpletest.rc-jtvjc
I0319 17:20:48.010615       1 scheduler_binder.go:269] AssumePodVolumes for pod "gc-6059/simpletest.rc-jtvjc", node "e2e-test-peterhornyack-windows-node-group-7n03"
I0319 17:20:48.010660       1 scheduler_binder.go:279] AssumePodVolumes for pod "gc-6059/simpletest.rc-jtvjc", node "e2e-test-peterhornyack-windows-node-group-7n03": all PVCs bound and nothing to do
I0319 17:20:48.010698       1 factory.go:733] Attempting to bind simpletest.rc-jtvjc to e2e-test-peterhornyack-windows-node-group-7n03
I0319 17:20:48.018146       1 scheduling_queue.go:908] About to try and schedule pod gc-6059/simpletest.rc-wkxdq
I0319 17:20:48.018172       1 scheduler.go:453] Attempting to schedule pod: gc-6059/simpletest.rc-wkxdq
I0319 17:20:48.018338       1 scheduler.go:572] pod gc-6059/simpletest.rc-d6xdm is bound successfully on node e2e-test-peterhornyack-windows-node-group-7n03, 5 nodes evaluated, 2 nodes were found feasible
I0319 17:20:48.029089       1 scheduler_binder.go:269] AssumePodVolumes for pod "gc-6059/simpletest.rc-wkxdq", node "e2e-test-peterhornyack-windows-node-group-dp2r"
I0319 17:20:48.029156       1 scheduler_binder.go:279] AssumePodVolumes for pod "gc-6059/simpletest.rc-wkxdq", node "e2e-test-peterhornyack-windows-node-group-dp2r": all PVCs bound and nothing to do
I0319 17:20:48.029238       1 factory.go:733] Attempting to bind simpletest.rc-wkxdq to e2e-test-peterhornyack-windows-node-group-dp2r
I0319 17:20:48.039369       1 scheduler.go:572] pod gc-6059/simpletest.rc-9dv4v is bound successfully on node e2e-test-peterhornyack-windows-node-group-7n03, 5 nodes evaluated, 2 nodes were found feasible
I0319 17:20:48.039783       1 scheduler.go:572] pod gc-6059/simpletest.rc-jtvjc is bound successfully on node e2e-test-peterhornyack-windows-node-group-7n03, 5 nodes evaluated, 2 nodes were found feasible
I0319 17:20:48.045706       1 scheduler.go:572] pod gc-6059/simpletest.rc-ppv4t is bound successfully on node e2e-test-peterhornyack-windows-node-group-7n03, 5 nodes evaluated, 2 nodes were found feasible
I0319 17:20:48.072833       1 scheduler.go:572] pod gc-6059/simpletest.rc-wkxdq is bound successfully on node e2e-test-peterhornyack-windows-node-group-dp2r, 5 nodes evaluated, 2 nodes were found feasible
I0319 17:20:50.118641       1 wrap.go:47] GET /healthz: (97.224µs) 200 [kube-probe/1.15+ 127.0.0.1:57254]
I0319 17:21:00.117927       1 wrap.go:47] GET /healthz: (69.355µs) 200 [kube-probe/1.15+ 127.0.0.1:57288]
I0319 17:21:10.118057       1 wrap.go:47] GET /healthz: (85.359µs) 200 [kube-probe/1.15+ 127.0.0.1:57326]
I0319 17:21:13.097147       1 reflector.go:370] k8s.io/client-go/informers/factory.go:133: Watch close - *v1.Service total 6 items received
I0319 17:21:16.087440       1 reflector.go:370] k8s.io/client-go/informers/factory.go:133: Watch close - *v1.PersistentVolumeClaim total 0 items received
I0319 17:21:20.118155       1 wrap.go:47] GET /healthz: (122.388µs) 200 [kube-probe/1.15+ 127.0.0.1:57362]
I0319 17:21:26.083935       1 reflector.go:370] k8s.io/client-go/informers/factory.go:133: Watch close - *v1.StorageClass total 0 items received
I0319 17:21:30.118479       1 wrap.go:47] GET /healthz: (83.17µs) 200 [kube-probe/1.15+ 127.0.0.1:57398]
I0319 17:21:36.239791       1 scheduling_queue.go:908] About to try and schedule pod projected-699/pod-projected-secrets-72f8b7a3-4a6b-11e9-af5d-a08cfde32bdd
I0319 17:21:36.239844       1 scheduler.go:453] Attempting to schedule pod: projected-699/pod-projected-secrets-72f8b7a3-4a6b-11e9-af5d-a08cfde32bdd
I0319 17:21:36.241888       1 scheduler_binder.go:269] AssumePodVolumes for pod "projected-699/pod-projected-secrets-72f8b7a3-4a6b-11e9-af5d-a08cfde32bdd", node "e2e-test-peterhornyack-windows-node-group-7n03"
I0319 17:21:36.241937       1 scheduler_binder.go:279] AssumePodVolumes for pod "projected-699/pod-projected-secrets-72f8b7a3-4a6b-11e9-af5d-a08cfde32bdd", node "e2e-test-peterhornyack-windows-node-group-7n03": all PVCs bound and nothing to do
I0319 17:21:36.242003       1 factory.go:733] Attempting to bind pod-projected-secrets-72f8b7a3-4a6b-11e9-af5d-a08cfde32bdd to e2e-test-peterhornyack-windows-node-group-7n03
I0319 17:21:36.250945       1 scheduler.go:572] pod projected-699/pod-projected-secrets-72f8b7a3-4a6b-11e9-af5d-a08cfde32bdd is bound successfully on node e2e-test-peterhornyack-windows-node-group-7n03, 5 nodes evaluated, 2 nodes were found feasible
I0319 17:21:40.117951       1 wrap.go:47] GET /healthz: (94.065µs) 200 [kube-probe/1.15+ 127.0.0.1:57446]
I0319 17:21:43.049337       1 reflector.go:370] k8s.io/client-go/informers/factory.go:133: Watch close - *v1.PersistentVolume total 0 items received
I0319 17:21:50.117885       1 wrap.go:47] GET /healthz: (71.415µs) 200 [kube-probe/1.15+ 127.0.0.1:57478]
I0319 17:22:00.118170       1 wrap.go:47] GET /healthz: (87.955µs) 200 [kube-probe/1.15+ 127.0.0.1:57512]
I0319 17:22:10.119056       1 wrap.go:47] GET /healthz: (78.256µs) 200 [kube-probe/1.15+ 127.0.0.1:57550]
I0319 17:22:20.121681       1 wrap.go:47] GET /healthz: (80.094µs) 200 [kube-probe/1.15+ 127.0.0.1:57582]
I0319 17:22:28.042216       1 reflector.go:370] k8s.io/client-go/informers/factory.go:133: Watch close - *v1.StatefulSet total 0 items received
I0319 17:22:30.118284       1 wrap.go:47] GET /healthz: (71.804µs) 200 [kube-probe/1.15+ 127.0.0.1:57618]
I0319 17:22:40.118275       1 wrap.go:47] GET /healthz: (73.275µs) 200 [kube-probe/1.15+ 127.0.0.1:57668]
I0319 17:22:43.044179       1 reflector.go:370] k8s.io/kubernetes/cmd/kube-scheduler/app/server.go:223: Watch close - *v1.Pod total 148 items received
I0319 17:22:50.118154       1 wrap.go:47] GET /healthz: (83.966µs) 200 [kube-probe/1.15+ 127.0.0.1:57700]
I0319 17:23:00.119625       1 wrap.go:47] GET /healthz: (1.413982ms) 200 [kube-probe/1.15+ 127.0.0.1:57734]
I0319 17:23:06.071229       1 reflector.go:370] k8s.io/client-go/informers/factory.go:133: Watch close - *v1beta1.PodDisruptionBudget total 0 items received
I0319 17:23:10.118100       1 wrap.go:47] GET /healthz: (98.021µs) 200 [kube-probe/1.15+ 127.0.0.1:57772]
I0319 17:23:16.817139       1 scheduling_queue.go:908] About to try and schedule pod container-probe-4077/liveness-http
I0319 17:23:16.817172       1 scheduler.go:453] Attempting to schedule pod: container-probe-4077/liveness-http
I0319 17:23:16.818632       1 scheduler_binder.go:269] AssumePodVolumes for pod "container-probe-4077/liveness-http", node "e2e-test-peterhornyack-windows-node-group-dp2r"
I0319 17:23:16.818664       1 scheduler_binder.go:279] AssumePodVolumes for pod "container-probe-4077/liveness-http", node "e2e-test-peterhornyack-windows-node-group-dp2r": all PVCs bound and nothing to do
I0319 17:23:16.818743       1 factory.go:733] Attempting to bind liveness-http to e2e-test-peterhornyack-windows-node-group-dp2r
I0319 17:23:16.831989       1 scheduler.go:572] pod container-probe-4077/liveness-http is bound successfully on node e2e-test-peterhornyack-windows-node-group-dp2r, 5 nodes evaluated, 2 nodes were found feasible
I0319 17:23:20.118149       1 wrap.go:47] GET /healthz: (93.762µs) 200 [kube-probe/1.15+ 127.0.0.1:57804]
I0319 17:23:30.118186       1 wrap.go:47] GET /healthz: (86.713µs) 200 [kube-probe/1.15+ 127.0.0.1:57838]
I0319 17:23:40.118174       1 wrap.go:47] GET /healthz: (82.232µs) 200 [kube-probe/1.15+ 127.0.0.1:57886]
I0319 17:23:50.118424       1 wrap.go:47] GET /healthz: (79.645µs) 200 [kube-probe/1.15+ 127.0.0.1:57920]
I0319 17:24:00.119838       1 wrap.go:47] GET /healthz: (113.987µs) 200 [kube-probe/1.15+ 127.0.0.1:57956]
I0319 17:24:10.118756       1 wrap.go:47] GET /healthz: (78.136µs) 200 [kube-probe/1.15+ 127.0.0.1:57994]
I0319 17:24:20.118235       1 wrap.go:47] GET /healthz: (73.899µs) 200 [kube-probe/1.15+ 127.0.0.1:58026]
I0319 17:24:30.118075       1 wrap.go:47] GET /healthz: (90.069µs) 200 [kube-probe/1.15+ 127.0.0.1:58060]
I0319 17:24:40.118156       1 wrap.go:47] GET /healthz: (77.334µs) 200 [kube-probe/1.15+ 127.0.0.1:58212]
I0319 17:24:50.117892       1 wrap.go:47] GET /healthz: (81.581µs) 200 [kube-probe/1.15+ 127.0.0.1:58244]
I0319 17:25:00.117908       1 wrap.go:47] GET /healthz: (74.187µs) 200 [kube-probe/1.15+ 127.0.0.1:58280]
I0319 17:25:10.118057       1 wrap.go:47] GET /healthz: (83.454µs) 200 [kube-probe/1.15+ 127.0.0.1:58318]
I0319 17:25:20.117967       1 wrap.go:47] GET /healthz: (59.087µs) 200 [kube-probe/1.15+ 127.0.0.1:58350]
I0319 17:25:30.118315       1 wrap.go:47] GET /healthz: (73.428µs) 200 [kube-probe/1.15+ 127.0.0.1:58386]
I0319 17:25:40.117898       1 wrap.go:47] GET /healthz: (81.194µs) 200 [kube-probe/1.15+ 127.0.0.1:58434]
I0319 17:25:50.118152       1 wrap.go:47] GET /healthz: (73.466µs) 200 [kube-probe/1.15+ 127.0.0.1:58466]
I0319 17:25:52.068992       1 reflector.go:370] k8s.io/client-go/informers/factory.go:133: Watch close - *v1.ReplicaSet total 0 items received
I0319 17:26:00.117890       1 wrap.go:47] GET /healthz: (90.935µs) 200 [kube-probe/1.15+ 127.0.0.1:58500]
I0319 17:26:10.118165       1 wrap.go:47] GET /healthz: (81.593µs) 200 [kube-probe/1.15+ 127.0.0.1:58540]
I0319 17:26:20.118183       1 wrap.go:47] GET /healthz: (80.703µs) 200 [kube-probe/1.15+ 127.0.0.1:58572]
I0319 17:26:30.118389       1 wrap.go:47] GET /healthz: (72.052µs) 200 [kube-probe/1.15+ 127.0.0.1:58606]
I0319 17:26:40.118207       1 wrap.go:47] GET /healthz: (78.909µs) 200 [kube-probe/1.15+ 127.0.0.1:58654]
I0319 17:26:50.118381       1 wrap.go:47] GET /healthz: (95.539µs) 200 [kube-probe/1.15+ 127.0.0.1:58688]
I0319 17:26:51.696411       1 scheduling_queue.go:908] About to try and schedule pod hostpath-8366/pod-host-path-test
I0319 17:26:51.696441       1 scheduler.go:453] Attempting to schedule pod: hostpath-8366/pod-host-path-test
I0319 17:26:51.696879       1 scheduler_binder.go:269] AssumePodVolumes for pod "hostpath-8366/pod-host-path-test", node "e2e-test-peterhornyack-windows-node-group-7n03"
I0319 17:26:51.696898       1 scheduler_binder.go:279] AssumePodVolumes for pod "hostpath-8366/pod-host-path-test", node "e2e-test-peterhornyack-windows-node-group-7n03": all PVCs bound and nothing to do
I0319 17:26:51.696963       1 factory.go:733] Attempting to bind pod-host-path-test to e2e-test-peterhornyack-windows-node-group-7n03
I0319 17:26:51.706788       1 scheduler.go:572] pod hostpath-8366/pod-host-path-test is bound successfully on node e2e-test-peterhornyack-windows-node-group-7n03, 5 nodes evaluated, 2 nodes were found feasible
I0319 17:26:59.089058       1 reflector.go:370] k8s.io/client-go/informers/factory.go:133: Watch close - *v1.StorageClass total 0 items received
I0319 17:27:00.117907       1 wrap.go:47] GET /healthz: (78.006µs) 200 [kube-probe/1.15+ 127.0.0.1:58722]
I0319 17:27:10.117927       1 wrap.go:47] GET /healthz: (54.424µs) 200 [kube-probe/1.15+ 127.0.0.1:58760]
I0319 17:27:19.161512       1 scheduling_queue.go:908] About to try and schedule pod kubectl-1534/e2e-test-nginx-deployment-54fc8fc46-2nzq9
I0319 17:27:19.163589       1 scheduler.go:453] Attempting to schedule pod: kubectl-1534/e2e-test-nginx-deployment-54fc8fc46-2nzq9
I0319 17:27:19.164064       1 scheduler_binder.go:269] AssumePodVolumes for pod "kubectl-1534/e2e-test-nginx-deployment-54fc8fc46-2nzq9", node "e2e-test-peterhornyack-windows-node-group-dp2r"
I0319 17:27:19.164085       1 scheduler_binder.go:279] AssumePodVolumes for pod "kubectl-1534/e2e-test-nginx-deployment-54fc8fc46-2nzq9", node "e2e-test-peterhornyack-windows-node-group-dp2r": all PVCs bound and nothing to do
I0319 17:27:19.169847       1 factory.go:733] Attempting to bind e2e-test-nginx-deployment-54fc8fc46-2nzq9 to e2e-test-peterhornyack-windows-node-group-dp2r
I0319 17:27:19.205084       1 scheduler.go:572] pod kubectl-1534/e2e-test-nginx-deployment-54fc8fc46-2nzq9 is bound successfully on node e2e-test-peterhornyack-windows-node-group-dp2r, 5 nodes evaluated, 2 nodes were found feasible
I0319 17:27:20.118522       1 wrap.go:47] GET /healthz: (109.848µs) 200 [kube-probe/1.15+ 127.0.0.1:58796]
I0319 17:27:21.110976       1 reflector.go:370] k8s.io/client-go/informers/factory.go:133: Watch close - *v1.ReplicationController total 14 items received
I0319 17:27:29.573718       1 scheduling_queue.go:908] About to try and schedule pod replication-controller-1906/pod-release-9jl72
I0319 17:27:29.573749       1 scheduler.go:453] Attempting to schedule pod: replication-controller-1906/pod-release-9jl72
I0319 17:27:29.576711       1 scheduler_binder.go:269] AssumePodVolumes for pod "replication-controller-1906/pod-release-9jl72", node "e2e-test-peterhornyack-windows-node-group-7n03"
I0319 17:27:29.576762       1 scheduler_binder.go:279] AssumePodVolumes for pod "replication-controller-1906/pod-release-9jl72", node "e2e-test-peterhornyack-windows-node-group-7n03": all PVCs bound and nothing to do
I0319 17:27:29.576858       1 factory.go:733] Attempting to bind pod-release-9jl72 to e2e-test-peterhornyack-windows-node-group-7n03
I0319 17:27:29.596878       1 scheduler.go:572] pod replication-controller-1906/pod-release-9jl72 is bound successfully on node e2e-test-peterhornyack-windows-node-group-7n03, 5 nodes evaluated, 2 nodes were found feasible
I0319 17:27:29.733173       1 scheduling_queue.go:908] About to try and schedule pod replication-controller-1906/pod-release-4bsv4
I0319 17:27:29.733221       1 scheduler.go:453] Attempting to schedule pod: replication-controller-1906/pod-release-4bsv4
I0319 17:27:29.738102       1 scheduler_binder.go:269] AssumePodVolumes for pod "replication-controller-1906/pod-release-4bsv4", node "e2e-test-peterhornyack-windows-node-group-dp2r"
I0319 17:27:29.738182       1 scheduler_binder.go:279] AssumePodVolumes for pod "replication-controller-1906/pod-release-4bsv4", node "e2e-test-peterhornyack-windows-node-group-dp2r": all PVCs bound and nothing to do
I0319 17:27:29.738263       1 factory.go:733] Attempting to bind pod-release-4bsv4 to e2e-test-peterhornyack-windows-node-group-dp2r
I0319 17:27:29.756241       1 scheduler.go:572] pod replication-controller-1906/pod-release-4bsv4 is bound successfully on node e2e-test-peterhornyack-windows-node-group-dp2r, 5 nodes evaluated, 2 nodes were found feasible
I0319 17:27:30.118231       1 wrap.go:47] GET /healthz: (73.314µs) 200 [kube-probe/1.15+ 127.0.0.1:58832]
I0319 17:27:40.118376       1 wrap.go:47] GET /healthz: (61.621µs) 200 [kube-probe/1.15+ 127.0.0.1:58882]
I0319 17:27:42.186465       1 scheduling_queue.go:908] About to try and schedule pod volume-4425/gcepd-injector-7df2
I0319 17:27:42.186521       1 scheduler.go:453] Attempting to schedule pod: volume-4425/gcepd-injector-7df2
I0319 17:27:42.187391       1 csi_volume_predicate.go:147] Not considering non-CSI volume volume-4425/pvc-m594g
I0319 17:27:42.187470       1 scheduler_binder.go:665] All bound volumes for Pod "volume-4425/gcepd-injector-7df2" match with Node "e2e-test-peterhornyack-windows-node-group-7n03"
I0319 17:27:42.187533       1 csi_volume_predicate.go:147] Not considering non-CSI volume volume-4425/pvc-m594g
I0319 17:27:42.187557       1 scheduler_binder.go:665] All bound volumes for Pod "volume-4425/gcepd-injector-7df2" match with Node "e2e-test-peterhornyack-windows-node-group-dp2r"
I0319 17:27:42.187796       1 scheduler_binder.go:269] AssumePodVolumes for pod "volume-4425/gcepd-injector-7df2", node "e2e-test-peterhornyack-windows-node-group-dp2r"
I0319 17:27:42.187814       1 scheduler_binder.go:279] AssumePodVolumes for pod "volume-4425/gcepd-injector-7df2", node "e2e-test-peterhornyack-windows-node-group-dp2r": all PVCs bound and nothing to do
I0319 17:27:42.187876       1 factory.go:733] Attempting to bind gcepd-injector-7df2 to e2e-test-peterhornyack-windows-node-group-dp2r
I0319 17:27:42.198713       1 scheduler.go:572] pod volume-4425/gcepd-injector-7df2 is bound successfully on node e2e-test-peterhornyack-windows-node-group-dp2r, 5 nodes evaluated, 2 nodes were found feasible
I0319 17:27:50.117778       1 wrap.go:47] GET /healthz: (79.071µs) 200 [kube-probe/1.15+ 127.0.0.1:58916]
I0319 17:28:00.117955       1 wrap.go:47] GET /healthz: (54.445µs) 200 [kube-probe/1.15+ 127.0.0.1:58950]
I0319 17:28:10.117887       1 wrap.go:47] GET /healthz: (73.839µs) 200 [kube-probe/1.15+ 127.0.0.1:58990]
I0319 17:28:12.997932       1 scheduling_queue.go:908] About to try and schedule pod volume-4425/gcepd-client
I0319 17:28:12.997963       1 scheduler.go:453] Attempting to schedule pod: volume-4425/gcepd-client
I0319 17:28:12.998197       1 csi_volume_predicate.go:147] Not considering non-CSI volume volume-4425/pvc-m594g
I0319 17:28:12.999129       1 scheduler_binder.go:665] All bound volumes for Pod "volume-4425/gcepd-client" match with Node "e2e-test-peterhornyack-windows-node-group-7n03"
I0319 17:28:12.999286       1 csi_volume_predicate.go:147] Not considering non-CSI volume volume-4425/pvc-m594g
I0319 17:28:12.999349       1 scheduler_binder.go:665] All bound volumes for Pod "volume-4425/gcepd-client" match with Node "e2e-test-peterhornyack-windows-node-group-dp2r"
I0319 17:28:12.999577       1 scheduler_binder.go:269] AssumePodVolumes for pod "volume-4425/gcepd-client", node "e2e-test-peterhornyack-windows-node-group-dp2r"
I0319 17:28:12.999591       1 scheduler_binder.go:279] AssumePodVolumes for pod "volume-4425/gcepd-client", node "e2e-test-peterhornyack-windows-node-group-dp2r": all PVCs bound and nothing to do
I0319 17:28:12.999651       1 factory.go:733] Attempting to bind gcepd-client to e2e-test-peterhornyack-windows-node-group-dp2r
I0319 17:28:13.014114       1 scheduler.go:572] pod volume-4425/gcepd-client is bound successfully on node e2e-test-peterhornyack-windows-node-group-dp2r, 5 nodes evaluated, 2 nodes were found feasible
I0319 17:28:20.117823       1 wrap.go:47] GET /healthz: (68.632µs) 200 [kube-probe/1.15+ 127.0.0.1:59022]
I0319 17:28:30.118095       1 wrap.go:47] GET /healthz: (109.67µs) 200 [kube-probe/1.15+ 127.0.0.1:59058]
I0319 17:28:40.118120       1 wrap.go:47] GET /healthz: (87.446µs) 200 [kube-probe/1.15+ 127.0.0.1:59108]
I0319 17:28:50.117938       1 wrap.go:47] GET /healthz: (63.231µs) 200 [kube-probe/1.15+ 127.0.0.1:59140]
I0319 17:28:57.082724       1 reflector.go:370] k8s.io/client-go/informers/factory.go:133: Watch close - *v1.Node total 71 items received
I0319 17:29:00.118106       1 wrap.go:47] GET /healthz: (113.639µs) 200 [kube-probe/1.15+ 127.0.0.1:59174]
I0319 17:29:03.047216       1 reflector.go:370] k8s.io/kubernetes/cmd/kube-scheduler/app/server.go:223: Watch close - *v1.Pod total 46 items received
I0319 17:29:10.118281       1 wrap.go:47] GET /healthz: (96.315µs) 200 [kube-probe/1.15+ 127.0.0.1:59214]
I0319 17:29:13.612175       1 scheduling_queue.go:908] About to try and schedule pod gc-5120/simpletest.rc-t47d2
I0319 17:29:13.612221       1 scheduler.go:453] Attempting to schedule pod: gc-5120/simpletest.rc-t47d2
I0319 17:29:13.612670       1 scheduler_binder.go:269] AssumePodVolumes for pod "gc-5120/simpletest.rc-t47d2", node "e2e-test-peterhornyack-windows-node-group-7n03"
I0319 17:29:13.612703       1 scheduler_binder.go:279] AssumePodVolumes for pod "gc-5120/simpletest.rc-t47d2", node "e2e-test-peterhornyack-windows-node-group-7n03": all PVCs bound and nothing to do
I0319 17:29:13.612760       1 factory.go:733] Attempting to bind simpletest.rc-t47d2 to e2e-test-peterhornyack-windows-node-group-7n03
I0319 17:29:13.634868       1 scheduling_queue.go:908] About to try and schedule pod gc-5120/simpletest.rc-5k7md
I0319 17:29:13.634904       1 scheduler.go:453] Attempting to schedule pod: gc-5120/simpletest.rc-5k7md
I0319 17:29:13.639091       1 scheduler_binder.go:269] AssumePodVolumes for pod "gc-5120/simpletest.rc-5k7md", node "e2e-test-peterhornyack-windows-node-group-dp2r"
I0319 17:29:13.639136       1 scheduler_binder.go:279] AssumePodVolumes for pod "gc-5120/simpletest.rc-5k7md", node "e2e-test-peterhornyack-windows-node-group-dp2r": all PVCs bound and nothing to do
I0319 17:29:13.639202       1 factory.go:733] Attempting to bind simpletest.rc-5k7md to e2e-test-peterhornyack-windows-node-group-dp2r
I0319 17:29:13.647885       1 scheduler.go:572] pod gc-5120/simpletest.rc-t47d2 is bound successfully on node e2e-test-peterhornyack-windows-node-group-7n03, 5 nodes evaluated, 2 nodes were found feasible
I0319 17:29:13.648292       1 scheduling_queue.go:908] About to try and schedule pod gc-5120/simpletest.rc-zfg5j
I0319 17:29:13.648310       1 scheduler.go:453] Attempting to schedule pod: gc-5120/simpletest.rc-zfg5j
I0319 17:29:13.648590       1 scheduler_binder.go:269] AssumePodVolumes for pod "gc-5120/simpletest.rc-zfg5j", node "e2e-test-peterhornyack-windows-node-group-7n03"
I0319 17:29:13.648606       1 scheduler_binder.go:279] AssumePodVolumes for pod "gc-5120/simpletest.rc-zfg5j", node "e2e-test-peterhornyack-windows-node-group-7n03": all PVCs bound and nothing to do
I0319 17:29:13.648638       1 factory.go:733] Attempting to bind simpletest.rc-zfg5j to e2e-test-peterhornyack-windows-node-group-7n03
I0319 17:29:13.670636       1 scheduler.go:572] pod gc-5120/simpletest.rc-5k7md is bound successfully on node e2e-test-peterhornyack-windows-node-group-dp2r, 5 nodes evaluated, 2 nodes were found feasible
I0319 17:29:13.674465       1 scheduling_queue.go:908] About to try and schedule pod gc-5120/simpletest.rc-dn5c4
I0319 17:29:13.674492       1 scheduler.go:453] Attempting to schedule pod: gc-5120/simpletest.rc-dn5c4
I0319 17:29:13.674876       1 scheduler_binder.go:269] AssumePodVolumes for pod "gc-5120/simpletest.rc-dn5c4", node "e2e-test-peterhornyack-windows-node-group-dp2r"
I0319 17:29:13.674892       1 scheduler_binder.go:279] AssumePodVolumes for pod "gc-5120/simpletest.rc-dn5c4", node "e2e-test-peterhornyack-windows-node-group-dp2r": all PVCs bound and nothing to do
I0319 17:29:13.674951       1 factory.go:733] Attempting to bind simpletest.rc-dn5c4 to e2e-test-peterhornyack-windows-node-group-dp2r
I0319 17:29:13.682618       1 scheduling_queue.go:908] About to try and schedule pod gc-5120/simpletest.rc-5mhdn
I0319 17:29:13.682664       1 scheduler.go:453] Attempting to schedule pod: gc-5120/simpletest.rc-5mhdn
I0319 17:29:13.687522       1 scheduler_binder.go:269] AssumePodVolumes for pod "gc-5120/simpletest.rc-5mhdn", node "e2e-test-peterhornyack-windows-node-group-7n03"
I0319 17:29:13.687559       1 scheduler_binder.go:279] AssumePodVolumes for pod "gc-5120/simpletest.rc-5mhdn", node "e2e-test-peterhornyack-windows-node-group-7n03": all PVCs bound and nothing to do
I0319 17:29:13.690633       1 factory.go:733] Attempting to bind simpletest.rc-5mhdn to e2e-test-peterhornyack-windows-node-group-7n03
I0319 17:29:13.697491       1 scheduler.go:572] pod gc-5120/simpletest.rc-zfg5j is bound successfully on node e2e-test-peterhornyack-windows-node-group-7n03, 5 nodes evaluated, 2 nodes were found feasible
I0319 17:29:13.697588       1 scheduling_queue.go:908] About to try and schedule pod gc-5120/simpletest.rc-7k2zb
I0319 17:29:13.697599       1 scheduler.go:453] Attempting to schedule pod: gc-5120/simpletest.rc-7k2zb
I0319 17:29:13.700237       1 scheduler_binder.go:269] AssumePodVolumes for pod "gc-5120/simpletest.rc-7k2zb", node "e2e-test-peterhornyack-windows-node-group-dp2r"
I0319 17:29:13.700271       1 scheduler_binder.go:279] AssumePodVolumes for pod "gc-5120/simpletest.rc-7k2zb", node "e2e-test-peterhornyack-windows-node-group-dp2r": all PVCs bound and nothing to do
I0319 17:29:13.700310       1 factory.go:733] Attempting to bind simpletest.rc-7k2zb to e2e-test-peterhornyack-windows-node-group-dp2r
I0319 17:29:13.709403       1 scheduling_queue.go:908] About to try and schedule pod gc-5120/simpletest.rc-wbxdf
I0319 17:29:13.709429       1 scheduler.go:453] Attempting to schedule pod: gc-5120/simpletest.rc-wbxdf
I0319 17:29:13.709987       1 scheduler_binder.go:269] AssumePodVolumes for pod "gc-5120/simpletest.rc-wbxdf", node "e2e-test-peterhornyack-windows-node-group-7n03"
I0319 17:29:13.710007       1 scheduler_binder.go:279] AssumePodVolumes for pod "gc-5120/simpletest.rc-wbxdf", node "e2e-test-peterhornyack-windows-node-group-7n03": all PVCs bound and nothing to do
I0319 17:29:13.710054       1 factory.go:733] Attempting to bind simpletest.rc-wbxdf to e2e-test-peterhornyack-windows-node-group-7n03
I0319 17:29:13.719927       1 scheduler.go:572] pod gc-5120/simpletest.rc-5mhdn is bound successfully on node e2e-test-peterhornyack-windows-node-group-7n03, 5 nodes evaluated, 2 nodes were found feasible
I0319 17:29:13.723205       1 scheduling_queue.go:908] About to try and schedule pod gc-5120/simpletest.rc-gb77p
I0319 17:29:13.723235       1 scheduler.go:453] Attempting to schedule pod: gc-5120/simpletest.rc-gb77p
I0319 17:29:13.725472       1 scheduler_binder.go:269] AssumePodVolumes for pod "gc-5120/simpletest.rc-gb77p", node "e2e-test-peterhornyack-windows-node-group-dp2r"
I0319 17:29:13.725499       1 scheduler_binder.go:279] AssumePodVolumes for pod "gc-5120/simpletest.rc-gb77p", node "e2e-test-peterhornyack-windows-node-group-dp2r": all PVCs bound and nothing to do
I0319 17:29:13.725561       1 factory.go:733] Attempting to bind simpletest.rc-gb77p to e2e-test-peterhornyack-windows-node-group-dp2r
I0319 17:29:13.725850       1 scheduling_queue.go:908] About to try and schedule pod gc-5120/simpletest.rc-dl9pm
I0319 17:29:13.725877       1 scheduler.go:453] Attempting to schedule pod: gc-5120/simpletest.rc-dl9pm
I0319 17:29:13.726080       1 scheduler_binder.go:269] AssumePodVolumes for pod "gc-5120/simpletest.rc-dl9pm", node "e2e-test-peterhornyack-windows-node-group-7n03"
I0319 17:29:13.726094       1 scheduler_binder.go:279] AssumePodVolumes for pod "gc-5120/simpletest.rc-dl9pm", node "e2e-test-peterhornyack-windows-node-group-7n03": all PVCs bound and nothing to do
I0319 17:29:13.726128       1 factory.go:733] Attempting to bind simpletest.rc-dl9pm to e2e-test-peterhornyack-windows-node-group-7n03
I0319 17:29:13.726593       1 scheduling_queue.go:908] About to try and schedule pod gc-5120/simpletest.rc-fbh7d
I0319 17:29:13.726616       1 scheduler.go:453] Attempting to schedule pod: gc-5120/simpletest.rc-fbh7d
I0319 17:29:13.726772       1 scheduler_binder.go:269] AssumePodVolumes for pod "gc-5120/simpletest.rc-fbh7d", node "e2e-test-peterhornyack-windows-node-group-dp2r"
I0319 17:29:13.726784       1 scheduler_binder.go:279] AssumePodVolumes for pod "gc-5120/simpletest.rc-fbh7d", node "e2e-test-peterhornyack-windows-node-group-dp2r": all PVCs bound and nothing to do
I0319 17:29:13.726804       1 factory.go:733] Attempting to bind simpletest.rc-fbh7d to e2e-test-peterhornyack-windows-node-group-dp2r
I0319 17:29:13.745087       1 scheduler.go:572] pod gc-5120/simpletest.rc-dn5c4 is bound successfully on node e2e-test-peterhornyack-windows-node-group-dp2r, 5 nodes evaluated, 2 nodes were found feasible
I0319 17:29:13.753342       1 scheduler.go:572] pod gc-5120/simpletest.rc-7k2zb is bound successfully on node e2e-test-peterhornyack-windows-node-group-dp2r, 5 nodes evaluated, 2 nodes were found feasible
I0319 17:29:13.770730       1 scheduler.go:572] pod gc-5120/simpletest.rc-wbxdf is bound successfully on node e2e-test-peterhornyack-windows-node-group-7n03, 5 nodes evaluated, 2 nodes were found feasible
I0319 17:29:13.779145       1 scheduler.go:572] pod gc-5120/simpletest.rc-gb77p is bound successfully on node e2e-test-peterhornyack-windows-node-group-dp2r, 5 nodes evaluated, 2 nodes were found feasible
I0319 17:29:13.786392       1 scheduler.go:572] pod gc-5120/simpletest.rc-dl9pm is bound successfully on node e2e-test-peterhornyack-windows-node-group-7n03, 5 nodes evaluated, 2 nodes were found feasible
I0319 17:29:13.786482       1 scheduler.go:572] pod gc-5120/simpletest.rc-fbh7d is bound successfully on node e2e-test-peterhornyack-windows-node-group-dp2r, 5 nodes evaluated, 2 nodes were found feasible
I0319 17:29:20.118640       1 wrap.go:47] GET /healthz: (79.949µs) 200 [kube-probe/1.15+ 127.0.0.1:59246]
I0319 17:29:27.920018       1 scheduling_queue.go:908] About to try and schedule pod pods-8757/back-off-cap
I0319 17:29:27.920081       1 scheduler.go:453] Attempting to schedule pod: pods-8757/back-off-cap
I0319 17:29:27.921533       1 scheduler_binder.go:269] AssumePodVolumes for pod "pods-8757/back-off-cap", node "e2e-test-peterhornyack-windows-node-group-7n03"
I0319 17:29:27.924314       1 scheduler_binder.go:279] AssumePodVolumes for pod "pods-8757/back-off-cap", node "e2e-test-peterhornyack-windows-node-group-7n03": all PVCs bound and nothing to do
I0319 17:29:27.924410       1 factory.go:733] Attempting to bind back-off-cap to e2e-test-peterhornyack-windows-node-group-7n03
I0319 17:29:27.931257       1 scheduler.go:572] pod pods-8757/back-off-cap is bound successfully on node e2e-test-peterhornyack-windows-node-group-7n03, 5 nodes evaluated, 2 nodes were found feasible
I0319 17:29:30.118162       1 wrap.go:47] GET /healthz: (86.305µs) 200 [kube-probe/1.15+ 127.0.0.1:59282]
I0319 17:29:32.100748       1 reflector.go:370] k8s.io/client-go/informers/factory.go:133: Watch close - *v1.Service total 0 items received
I0319 17:29:40.118097       1 wrap.go:47] GET /healthz: (90.479µs) 200 [kube-probe/1.15+ 127.0.0.1:59330]
I0319 17:29:49.074739       1 reflector.go:370] k8s.io/client-go/informers/factory.go:133: Watch close - *v1beta1.PodDisruptionBudget total 0 items received
I0319 17:29:50.119015       1 wrap.go:47] GET /healthz: (86.13µs) 200 [kube-probe/1.15+ 127.0.0.1:59364]
I0319 17:30:00.120687       1 wrap.go:47] GET /healthz: (87.406µs) 200 [kube-probe/1.15+ 127.0.0.1:59398]
I0319 17:30:10.117872       1 wrap.go:47] GET /healthz: (68.613µs) 200 [kube-probe/1.15+ 127.0.0.1:59436]
I0319 17:30:12.053111       1 reflector.go:370] k8s.io/client-go/informers/factory.go:133: Watch close - *v1.PersistentVolume total 5 items received
I0319 17:30:20.117898       1 wrap.go:47] GET /healthz: (72.106µs) 200 [kube-probe/1.15+ 127.0.0.1:59468]
I0319 17:30:25.090728       1 reflector.go:370] k8s.io/client-go/informers/factory.go:133: Watch close - *v1.PersistentVolumeClaim total 6 items received
I0319 17:30:30.118193       1 wrap.go:47] GET /healthz: (113.8µs) 200 [kube-probe/1.15+ 127.0.0.1:59502]
I0319 17:30:40.117882       1 wrap.go:47] GET /healthz: (82.376µs) 200 [kube-probe/1.15+ 127.0.0.1:59550]
I0319 17:30:50.118100       1 wrap.go:47] GET /healthz: (87.707µs) 200 [kube-probe/1.15+ 127.0.0.1:59582]
I0319 17:31:00.118236       1 wrap.go:47] GET /healthz: (83.772µs) 200 [kube-probe/1.15+ 127.0.0.1:59620]
I0319 17:31:10.123286       1 wrap.go:47] GET /healthz: (81.889µs) 200 [kube-probe/1.15+ 127.0.0.1:59658]
I0319 17:31:17.048902       1 reflector.go:370] k8s.io/client-go/informers/factory.go:133: Watch close - *v1.StatefulSet total 0 items received
I0319 17:31:20.118134       1 wrap.go:47] GET /healthz: (89.06µs) 200 [kube-probe/1.15+ 127.0.0.1:59690]
I0319 17:31:30.117988       1 wrap.go:47] GET /healthz: (82.686µs) 200 [kube-probe/1.15+ 127.0.0.1:59724]
I0319 17:31:40.117835       1 wrap.go:47] GET /healthz: (81.472µs) 200 [kube-probe/1.15+ 127.0.0.1:59772]
I0319 17:31:50.117966       1 wrap.go:47] GET /healthz: (84.367µs) 200 [kube-probe/1.15+ 127.0.0.1:59804]
I0319 17:32:00.118163       1 wrap.go:47] GET /healthz: (74.729µs) 200 [kube-probe/1.15+ 127.0.0.1:59838]
I0319 17:32:10.117895       1 wrap.go:47] GET /healthz: (71.485µs) 200 [kube-probe/1.15+ 127.0.0.1:59876]
I0319 17:32:20.118332       1 wrap.go:47] GET /healthz: (83.199µs) 200 [kube-probe/1.15+ 127.0.0.1:59912]
I0319 17:32:30.118146       1 wrap.go:47] GET /healthz: (78.423µs) 200 [kube-probe/1.15+ 127.0.0.1:59946]
I0319 17:32:40.119074       1 wrap.go:47] GET /healthz: (86.628µs) 200 [kube-probe/1.15+ 127.0.0.1:59994]
I0319 17:32:50.118257       1 wrap.go:47] GET /healthz: (76.591µs) 200 [kube-probe/1.15+ 127.0.0.1:60026]
I0319 17:33:00.118073       1 wrap.go:47] GET /healthz: (102.864µs) 200 [kube-probe/1.15+ 127.0.0.1:60060]
I0319 17:33:10.118542       1 wrap.go:47] GET /healthz: (77.428µs) 200 [kube-probe/1.15+ 127.0.0.1:60098]
I0319 17:33:20.118193       1 wrap.go:47] GET /healthz: (72.144µs) 200 [kube-probe/1.15+ 127.0.0.1:60130]
I0319 17:33:30.117803       1 wrap.go:47] GET /healthz: (82.51µs) 200 [kube-probe/1.15+ 127.0.0.1:60166]
I0319 17:33:32.072660       1 reflector.go:370] k8s.io/client-go/informers/factory.go:133: Watch close - *v1.ReplicaSet total 4 items received
I0319 17:33:40.120865       1 wrap.go:47] GET /healthz: (78.246µs) 200 [kube-probe/1.15+ 127.0.0.1:60216]
I0319 17:33:50.118131       1 wrap.go:47] GET /healthz: (95.183µs) 200 [kube-probe/1.15+ 127.0.0.1:60248]
I0319 17:34:00.117969       1 wrap.go:47] GET /healthz: (86.915µs) 200 [kube-probe/1.15+ 127.0.0.1:60282]
I0319 17:34:09.049901       1 reflector.go:370] k8s.io/kubernetes/cmd/kube-scheduler/app/server.go:223: Watch close - *v1.Pod total 70 items received
I0319 17:34:10.118143       1 wrap.go:47] GET /healthz: (77.298µs) 200 [kube-probe/1.15+ 127.0.0.1:60320]
I0319 17:34:20.118234       1 wrap.go:47] GET /healthz: (77.828µs) 200 [kube-probe/1.15+ 127.0.0.1:60356]
I0319 17:34:30.117819       1 wrap.go:47] GET /healthz: (99.819µs) 200 [kube-probe/1.15+ 127.0.0.1:60390]
I0319 17:34:40.118135       1 wrap.go:47] GET /healthz: (93.281µs) 200 [kube-probe/1.15+ 127.0.0.1:60440]
I0319 17:34:50.122531       1 wrap.go:47] GET /healthz: (87.811µs) 200 [kube-probe/1.15+ 127.0.0.1:60472]
I0319 17:35:00.118075       1 wrap.go:47] GET /healthz: (71.637µs) 200 [kube-probe/1.15+ 127.0.0.1:60506]
I0319 17:35:10.118604       1 wrap.go:47] GET /healthz: (67.598µs) 200 [kube-probe/1.15+ 127.0.0.1:60546]
I0319 17:35:17.102889       1 reflector.go:370] k8s.io/client-go/informers/factory.go:133: Watch close - *v1.Service total 0 items received
I0319 17:35:20.119101       1 wrap.go:47] GET /healthz: (116.778µs) 200 [kube-probe/1.15+ 127.0.0.1:60578]
I0319 17:35:30.118171       1 wrap.go:47] GET /healthz: (78.317µs) 200 [kube-probe/1.15+ 127.0.0.1:60612]
I0319 17:35:40.117917       1 wrap.go:47] GET /healthz: (77.342µs) 200 [kube-probe/1.15+ 127.0.0.1:60660]
I0319 17:35:50.118106       1 wrap.go:47] GET /healthz: (90.903µs) 200 [kube-probe/1.15+ 127.0.0.1:60692]
I0319 17:36:00.117978       1 wrap.go:47] GET /healthz: (83.949µs) 200 [kube-probe/1.15+ 127.0.0.1:60728]
I0319 17:36:02.056323       1 reflector.go:370] k8s.io/client-go/informers/factory.go:133: Watch close - *v1.PersistentVolume total 0 items received
I0319 17:36:10.121317       1 wrap.go:47] GET /healthz: (77.574µs) 200 [kube-probe/1.15+ 127.0.0.1:60766]
I0319 17:36:20.118094       1 wrap.go:47] GET /healthz: (90.304µs) 200 [kube-probe/1.15+ 127.0.0.1:60798]
I0319 17:36:23.078002       1 reflector.go:370] k8s.io/client-go/informers/factory.go:133: Watch close - *v1beta1.PodDisruptionBudget total 0 items received
I0319 17:36:30.118113       1 wrap.go:47] GET /healthz: (86.98µs) 200 [kube-probe/1.15+ 127.0.0.1:60834]
I0319 17:36:40.118202       1 wrap.go:47] GET /healthz: (62.643µs) 200 [kube-probe/1.15+ 127.0.0.1:60882]
I0319 17:36:49.114303       1 reflector.go:370] k8s.io/client-go/informers/factory.go:133: Watch close - *v1.ReplicationController total 15 items received
I0319 17:36:50.118072       1 wrap.go:47] GET /healthz: (98.875µs) 200 [kube-probe/1.15+ 127.0.0.1:60914]
I0319 17:36:57.094098       1 reflector.go:370] k8s.io/client-go/informers/factory.go:133: Watch close - *v1.StorageClass total 2 items received
I0319 17:37:00.117938       1 wrap.go:47] GET /healthz: (75.502µs) 200 [kube-probe/1.15+ 127.0.0.1:60948]
I0319 17:37:10.118675       1 wrap.go:47] GET /healthz: (78.284µs) 200 [kube-probe/1.15+ 127.0.0.1:60988]
I0319 17:37:20.118183       1 wrap.go:47] GET /healthz: (87.857µs) 200 [kube-probe/1.15+ 127.0.0.1:32788]
I0319 17:37:26.094977       1 reflector.go:370] k8s.io/client-go/informers/factory.go:133: Watch close - *v1.PersistentVolumeClaim total 0 items received
I0319 17:37:30.118268       1 wrap.go:47] GET /healthz: (71.666µs) 200 [kube-probe/1.15+ 127.0.0.1:32822]
I0319 17:37:40.118499       1 wrap.go:47] GET /healthz: (71.035µs) 200 [kube-probe/1.15+ 127.0.0.1:32870]
I0319 17:37:50.118218       1 wrap.go:47] GET /healthz: (118.877µs) 200 [kube-probe/1.15+ 127.0.0.1:32904]
I0319 17:38:00.118083       1 wrap.go:47] GET /healthz: (137.63µs) 200 [kube-probe/1.15+ 127.0.0.1:32938]
I0319 17:38:10.118048       1 wrap.go:47] GET /healthz: (72.575µs) 200 [kube-probe/1.15+ 127.0.0.1:32976]
I0319 17:38:20.118595       1 wrap.go:47] GET /healthz: (60.414µs) 200 [kube-probe/1.15+ 127.0.0.1:33010]
I0319 17:38:30.118082       1 wrap.go:47] GET /healthz: (108.76µs) 200 [kube-probe/1.15+ 127.0.0.1:33044]
I0319 17:38:40.118076       1 wrap.go:47] GET /healthz: (127.462µs) 200 [kube-probe/1.15+ 127.0.0.1:33092]
I0319 17:38:42.087811       1 reflector.go:370] k8s.io/client-go/informers/factory.go:133: Watch close - *v1.Node total 64 items received
I0319 17:38:50.118470       1 wrap.go:47] GET /healthz: (71.903µs) 200 [kube-probe/1.15+ 127.0.0.1:33124]
I0319 17:39:00.118153       1 wrap.go:47] GET /healthz: (75.368µs) 200 [kube-probe/1.15+ 127.0.0.1:33158]
I0319 17:39:10.118212       1 wrap.go:47] GET /healthz: (75.155µs) 200 [kube-probe/1.15+ 127.0.0.1:33196]
I0319 17:39:20.117904       1 wrap.go:47] GET /healthz: (90.588µs) 200 [kube-probe/1.15+ 127.0.0.1:33230]
I0319 17:39:30.117823       1 wrap.go:47] GET /healthz: (81.341µs) 200 [kube-probe/1.15+ 127.0.0.1:33264]
I0319 17:39:40.118357       1 wrap.go:47] GET /healthz: (73.391µs) 200 [kube-probe/1.15+ 127.0.0.1:33314]
I0319 17:39:50.118809       1 wrap.go:47] GET /healthz: (83.736µs) 200 [kube-probe/1.15+ 127.0.0.1:33346]
I0319 17:40:00.117933       1 wrap.go:47] GET /healthz: (88.121µs) 200 [kube-probe/1.15+ 127.0.0.1:33380]
I0319 17:40:10.118100       1 wrap.go:47] GET /healthz: (85.277µs) 200 [kube-probe/1.15+ 127.0.0.1:33420]
I0319 17:40:19.053454       1 reflector.go:370] k8s.io/kubernetes/cmd/kube-scheduler/app/server.go:223: Watch close - *v1.Pod total 3 items received
I0319 17:40:20.118534       1 wrap.go:47] GET /healthz: (73.384µs) 200 [kube-probe/1.15+ 127.0.0.1:33454]
I0319 17:40:30.118137       1 wrap.go:47] GET /healthz: (62.654µs) 200 [kube-probe/1.15+ 127.0.0.1:33488]
I0319 17:40:40.118360       1 wrap.go:47] GET /healthz: (73.218µs) 200 [kube-probe/1.15+ 127.0.0.1:33538]
I0319 17:40:47.079913       1 reflector.go:370] k8s.io/client-go/informers/factory.go:133: Watch close - *v1.ReplicaSet total 0 items received
I0319 17:40:50.117892       1 wrap.go:47] GET /healthz: (78.321µs) 200 [kube-probe/1.15+ 127.0.0.1:33572]
I0319 17:40:59.051883       1 reflector.go:370] k8s.io/client-go/informers/factory.go:133: Watch close - *v1.StatefulSet total 0 items received
I0319 17:41:00.117979       1 wrap.go:47] GET /healthz: (76.541µs) 200 [kube-probe/1.15+ 127.0.0.1:33606]
I0319 17:41:10.118128       1 wrap.go:47] GET /healthz: (85.345µs) 200 [kube-probe/1.15+ 127.0.0.1:33646]
I0319 17:41:20.117975       1 wrap.go:47] GET /healthz: (80.878µs) 200 [kube-probe/1.15+ 127.0.0.1:33678]
I0319 17:41:30.117935       1 wrap.go:47] GET /healthz: (72.56µs) 200 [kube-probe/1.15+ 127.0.0.1:33714]
I0319 17:41:40.117984       1 wrap.go:47] GET /healthz: (79.491µs) 200 [kube-probe/1.15+ 127.0.0.1:33762]
I0319 17:41:50.118872       1 wrap.go:47] GET /healthz: (80.349µs) 200 [kube-probe/1.15+ 127.0.0.1:33794]
I0319 17:42:00.118888       1 wrap.go:47] GET /healthz: (74.341µs) 200 [kube-probe/1.15+ 127.0.0.1:33832]
I0319 17:42:10.118404       1 wrap.go:47] GET /healthz: (80.772µs) 200 [kube-probe/1.15+ 127.0.0.1:33870]
I0319 17:42:20.119178       1 wrap.go:47] GET /healthz: (86.514µs) 200 [kube-probe/1.15+ 127.0.0.1:33902]
I0319 17:42:30.118721       1 wrap.go:47] GET /healthz: (80.196µs) 200 [kube-probe/1.15+ 127.0.0.1:33936]
I0319 17:42:40.117928       1 wrap.go:47] GET /healthz: (69.993µs) 200 [kube-probe/1.15+ 127.0.0.1:33984]
I0319 17:42:42.097493       1 reflector.go:370] k8s.io/client-go/informers/factory.go:133: Watch close - *v1.StorageClass total 0 items received
I0319 17:42:50.118219       1 wrap.go:47] GET /healthz: (78.582µs) 200 [kube-probe/1.15+ 127.0.0.1:34016]
I0319 17:43:00.117980       1 wrap.go:47] GET /healthz: (127.555µs) 200 [kube-probe/1.15+ 127.0.0.1:34050]
I0319 17:43:10.118004       1 wrap.go:47] GET /healthz: (69.115µs) 200 [kube-probe/1.15+ 127.0.0.1:34102]
I0319 17:43:20.118110       1 wrap.go:47] GET /healthz: (95.312µs) 200 [kube-probe/1.15+ 127.0.0.1:34136]
I0319 17:43:30.118123       1 wrap.go:47] GET /healthz: (115.378µs) 200 [kube-probe/1.15+ 127.0.0.1:34172]
I0319 17:43:33.107310       1 reflector.go:370] k8s.io/client-go/informers/factory.go:133: Watch close - *v1.Service total 0 items received
I0319 17:43:40.118083       1 wrap.go:47] GET /healthz: (86.756µs) 200 [kube-probe/1.15+ 127.0.0.1:34220]
I0319 17:43:50.117791       1 wrap.go:47] GET /healthz: (77.964µs) 200 [kube-probe/1.15+ 127.0.0.1:34252]
I0319 17:44:00.117797       1 wrap.go:47] GET /healthz: (75.73µs) 200 [kube-probe/1.15+ 127.0.0.1:34286]
I0319 17:44:10.117921       1 wrap.go:47] GET /healthz: (75.073µs) 200 [kube-probe/1.15+ 127.0.0.1:34324]
I0319 17:44:20.118431       1 wrap.go:47] GET /healthz: (79.255µs) 200 [kube-probe/1.15+ 127.0.0.1:34356]
I0319 17:44:30.118422       1 wrap.go:47] GET /healthz: (59.206µs) 200 [kube-probe/1.15+ 127.0.0.1:34392]
I0319 17:44:40.117719       1 wrap.go:47] GET /healthz: (78.629µs) 200 [kube-probe/1.15+ 127.0.0.1:34452]
I0319 17:44:50.117909       1 wrap.go:47] GET /healthz: (57.455µs) 200 [kube-probe/1.15+ 127.0.0.1:34486]
I0319 17:45:00.118117       1 wrap.go:47] GET /healthz: (126.878µs) 200 [kube-probe/1.15+ 127.0.0.1:34520]
I0319 17:45:10.118248       1 wrap.go:47] GET /healthz: (79.652µs) 200 [kube-probe/1.15+ 127.0.0.1:34558]
I0319 17:45:14.090976       1 reflector.go:370] k8s.io/client-go/informers/factory.go:133: Watch close - *v1.Node total 48 items received
I0319 17:45:14.098135       1 reflector.go:370] k8s.io/client-go/informers/factory.go:133: Watch close - *v1.PersistentVolumeClaim total 0 items received
I0319 17:45:18.059732       1 reflector.go:370] k8s.io/client-go/informers/factory.go:133: Watch close - *v1.PersistentVolume total 0 items received
I0319 17:45:19.081393       1 reflector.go:370] k8s.io/client-go/informers/factory.go:133: Watch close - *v1beta1.PodDisruptionBudget total 0 items received
I0319 17:45:20.118076       1 wrap.go:47] GET /healthz: (84.997µs) 200 [kube-probe/1.15+ 127.0.0.1:34590]
I0319 17:45:30.118083       1 wrap.go:47] GET /healthz: (123.324µs) 200 [kube-probe/1.15+ 127.0.0.1:34624]
I0319 17:45:33.118010       1 reflector.go:370] k8s.io/client-go/informers/factory.go:133: Watch close - *v1.ReplicationController total 0 items received
I0319 17:45:40.118107       1 wrap.go:47] GET /healthz: (84.911µs) 200 [kube-probe/1.15+ 127.0.0.1:34770]
I0319 17:45:50.118006       1 wrap.go:47] GET /healthz: (80.077µs) 200 [kube-probe/1.15+ 127.0.0.1:34802]
I0319 17:46:00.118292       1 wrap.go:47] GET /healthz: (72.67µs) 200 [kube-probe/1.15+ 127.0.0.1:34836]
I0319 17:46:10.054543       1 reflector.go:370] k8s.io/client-go/informers/factory.go:133: Watch close - *v1.StatefulSet total 0 items received
I0319 17:46:10.118101       1 wrap.go:47] GET /healthz: (118.777µs) 200 [kube-probe/1.15+ 127.0.0.1:34876]
I0319 17:46:20.118018       1 wrap.go:47] GET /healthz: (60.455µs) 200 [kube-probe/1.15+ 127.0.0.1:34908]
I0319 17:46:30.118069       1 wrap.go:47] GET /healthz: (105.901µs) 200 [kube-probe/1.15+ 127.0.0.1:34942]
I0319 17:46:40.118210       1 wrap.go:47] GET /healthz: (81.984µs) 200 [kube-probe/1.15+ 127.0.0.1:34990]
I0319 17:46:50.117882       1 wrap.go:47] GET /healthz: (79.151µs) 200 [kube-probe/1.15+ 127.0.0.1:35024]
I0319 17:47:00.117776       1 wrap.go:47] GET /healthz: (77.737µs) 200 [kube-probe/1.15+ 127.0.0.1:35058]
I0319 17:47:10.117960       1 wrap.go:47] GET /healthz: (74.069µs) 200 [kube-probe/1.15+ 127.0.0.1:35096]
I0319 17:47:20.119107       1 wrap.go:47] GET /healthz: (89.523µs) 200 [kube-probe/1.15+ 127.0.0.1:35128]
I0319 17:47:30.118231       1 wrap.go:47] GET /healthz: (69.79µs) 200 [kube-probe/1.15+ 127.0.0.1:35164]
I0319 17:47:40.117900       1 wrap.go:47] GET /healthz: (80.721µs) 200 [kube-probe/1.15+ 127.0.0.1:35212]
I0319 17:47:50.118933       1 wrap.go:47] GET /healthz: (78.127µs) 200 [kube-probe/1.15+ 127.0.0.1:35244]
I0319 17:48:00.117868       1 wrap.go:47] GET /healthz: (54.799µs) 200 [kube-probe/1.15+ 127.0.0.1:35278]
I0319 17:48:10.117938       1 wrap.go:47] GET /healthz: (85.624µs) 200 [kube-probe/1.15+ 127.0.0.1:35318]
I0319 17:48:20.117770       1 wrap.go:47] GET /healthz: (74.047µs) 200 [kube-probe/1.15+ 127.0.0.1:35352]
I0319 17:48:26.086664       1 reflector.go:370] k8s.io/client-go/informers/factory.go:133: Watch close - *v1.ReplicaSet total 0 items received
I0319 17:48:30.125345       1 wrap.go:47] GET /healthz: (76.533µs) 200 [kube-probe/1.15+ 127.0.0.1:35386]
I0319 17:48:40.119184       1 wrap.go:47] GET /healthz: (86.408µs) 200 [kube-probe/1.15+ 127.0.0.1:35434]
I0319 17:48:50.118348       1 wrap.go:47] GET /healthz: (102.671µs) 200 [kube-probe/1.15+ 127.0.0.1:35466]
I0319 17:49:00.118085       1 wrap.go:47] GET /healthz: (87.806µs) 200 [kube-probe/1.15+ 127.0.0.1:35502]
I0319 17:49:10.118878       1 wrap.go:47] GET /healthz: (129.124µs) 200 [kube-probe/1.15+ 127.0.0.1:35540]
I0319 17:49:19.056823       1 reflector.go:370] k8s.io/kubernetes/cmd/kube-scheduler/app/server.go:223: Watch close - *v1.Pod total 6 items received
I0319 17:49:20.118408       1 wrap.go:47] GET /healthz: (88.627µs) 200 [kube-probe/1.15+ 127.0.0.1:35574]
I0319 17:49:30.118132       1 wrap.go:47] GET /healthz: (92.484µs) 200 [kube-probe/1.15+ 127.0.0.1:35608]
I0319 17:49:37.100503       1 reflector.go:370] k8s.io/client-go/informers/factory.go:133: Watch close - *v1.StorageClass total 0 items received
I0319 17:49:40.117925       1 wrap.go:47] GET /healthz: (98.026µs) 200 [kube-probe/1.15+ 127.0.0.1:35656]
I0319 17:49:50.117934       1 wrap.go:47] GET /healthz: (66.297µs) 200 [kube-probe/1.15+ 127.0.0.1:35688]
I0319 17:50:00.118339       1 wrap.go:47] GET /healthz: (91.069µs) 200 [kube-probe/1.15+ 127.0.0.1:35722]
I0319 17:50:10.117996       1 wrap.go:47] GET /healthz: (90.181µs) 200 [kube-probe/1.15+ 127.0.0.1:35762]
I0319 17:50:20.118151       1 wrap.go:47] GET /healthz: (72.567µs) 200 [kube-probe/1.15+ 127.0.0.1:35796]
I0319 17:50:30.118269       1 wrap.go:47] GET /healthz: (75.111µs) 200 [kube-probe/1.15+ 127.0.0.1:35832]
I0319 17:50:39.101681       1 reflector.go:370] k8s.io/client-go/informers/factory.go:133: Watch close - *v1.PersistentVolumeClaim total 0 items received
I0319 17:50:40.117914       1 wrap.go:47] GET /healthz: (88.925µs) 200 [kube-probe/1.15+ 127.0.0.1:35892]
I0319 17:50:48.120927       1 reflector.go:370] k8s.io/client-go/informers/factory.go:133: Watch close - *v1.Service total 0 items received
I0319 17:50:50.118242       1 wrap.go:47] GET /healthz: (76.757µs) 200 [kube-probe/1.15+ 127.0.0.1:35924]
I0319 17:51:00.118078       1 wrap.go:47] GET /healthz: (102.805µs) 200 [kube-probe/1.15+ 127.0.0.1:35958]
I0319 17:51:10.118144       1 wrap.go:47] GET /healthz: (72.876µs) 200 [kube-probe/1.15+ 127.0.0.1:36000]
I0319 17:51:11.128929       1 reflector.go:370] k8s.io/client-go/informers/factory.go:133: Watch close - *v1.ReplicationController total 0 items received
I0319 17:51:20.117844       1 wrap.go:47] GET /healthz: (118.442µs) 200 [kube-probe/1.15+ 127.0.0.1:36032]
I0319 17:51:23.084666       1 reflector.go:370] k8s.io/client-go/informers/factory.go:133: Watch close - *v1beta1.PodDisruptionBudget total 0 items received
I0319 17:51:28.062956       1 reflector.go:370] k8s.io/client-go/informers/factory.go:133: Watch close - *v1.PersistentVolume total 0 items received
I0319 17:51:30.118356       1 wrap.go:47] GET /healthz: (81.684µs) 200 [kube-probe/1.15+ 127.0.0.1:36066]
I0319 17:51:40.117930       1 wrap.go:47] GET /healthz: (69.631µs) 200 [kube-probe/1.15+ 127.0.0.1:36116]
I0319 17:51:50.118167       1 wrap.go:47] GET /healthz: (156.848µs) 200 [kube-probe/1.15+ 127.0.0.1:36150]
I0319 17:52:00.118053       1 wrap.go:47] GET /healthz: (112.182µs) 200 [kube-probe/1.15+ 127.0.0.1:36184]
I0319 17:52:10.118230       1 wrap.go:47] GET /healthz: (80.77µs) 200 [kube-probe/1.15+ 127.0.0.1:36222]
I0319 17:52:11.058845       1 reflector.go:370] k8s.io/client-go/informers/factory.go:133: Watch close - *v1.StatefulSet total 0 items received
I0319 17:52:20.117925       1 wrap.go:47] GET /healthz: (81.147µs) 200 [kube-probe/1.15+ 127.0.0.1:36254]
I0319 17:52:30.117829       1 wrap.go:47] GET /healthz: (58.473µs) 200 [kube-probe/1.15+ 127.0.0.1:36288]
I0319 17:52:40.117882       1 wrap.go:47] GET /healthz: (70.937µs) 200 [kube-probe/1.15+ 127.0.0.1:36336]
I0319 17:52:50.119366       1 wrap.go:47] GET /healthz: (71.124µs) 200 [kube-probe/1.15+ 127.0.0.1:36368]
I0319 17:53:00.117860       1 wrap.go:47] GET /healthz: (74.515µs) 200 [kube-probe/1.15+ 127.0.0.1:36404]
I0319 17:53:10.118395       1 wrap.go:47] GET /healthz: (59.918µs) 200 [kube-probe/1.15+ 127.0.0.1:36444]
I0319 17:53:20.118135       1 wrap.go:47] GET /healthz: (64.066µs) 200 [kube-probe/1.15+ 127.0.0.1:36476]
I0319 17:53:22.097529       1 reflector.go:370] k8s.io/client-go/informers/factory.go:133: Watch close - *v1.Node total 56 items received
I0319 17:53:30.118224       1 wrap.go:47] GET /healthz: (78.057µs) 200 [kube-probe/1.15+ 127.0.0.1:36510]
I0319 17:53:40.118324       1 wrap.go:47] GET /healthz: (141.391µs) 200 [kube-probe/1.15+ 127.0.0.1:36558]
I0319 17:53:50.117887       1 wrap.go:47] GET /healthz: (118.431µs) 200 [kube-probe/1.15+ 127.0.0.1:36590]
I0319 17:54:00.118075       1 wrap.go:47] GET /healthz: (102.042µs) 200 [kube-probe/1.15+ 127.0.0.1:36624]
I0319 17:54:10.118054       1 wrap.go:47] GET /healthz: (70.671µs) 200 [kube-probe/1.15+ 127.0.0.1:36664]
I0319 17:54:20.118015       1 wrap.go:47] GET /healthz: (69.267µs) 200 [kube-probe/1.15+ 127.0.0.1:36696]
I0319 17:54:30.117946       1 wrap.go:47] GET /healthz: (83.008µs) 200 [kube-probe/1.15+ 127.0.0.1:36736]
I0319 17:54:38.103622       1 reflector.go:370] k8s.io/client-go/informers/factory.go:133: Watch close - *v1.StorageClass total 0 items received
I0319 17:54:40.118155       1 wrap.go:47] GET /healthz: (67.766µs) 200 [kube-probe/1.15+ 127.0.0.1:36820]
I0319 17:54:50.117866       1 wrap.go:47] GET /healthz: (69.781µs) 200 [kube-probe/1.15+ 127.0.0.1:36852]
I0319 17:55:00.118177       1 wrap.go:47] GET /healthz: (82.172µs) 200 [kube-probe/1.15+ 127.0.0.1:36886]
I0319 17:55:10.118172       1 wrap.go:47] GET /healthz: (100.709µs) 200 [kube-probe/1.15+ 127.0.0.1:36924]
I0319 17:55:18.060654       1 reflector.go:370] k8s.io/kubernetes/cmd/kube-scheduler/app/server.go:223: Watch close - *v1.Pod total 3 items received
I0319 17:55:20.118418       1 wrap.go:47] GET /healthz: (82.622µs) 200 [kube-probe/1.15+ 127.0.0.1:36958]
I0319 17:55:30.117946       1 wrap.go:47] GET /healthz: (76.926µs) 200 [kube-probe/1.15+ 127.0.0.1:36992]
I0319 17:55:40.118533       1 wrap.go:47] GET /healthz: (91.635µs) 200 [kube-probe/1.15+ 127.0.0.1:37064]
I0319 17:55:50.117902       1 wrap.go:47] GET /healthz: (120.154µs) 200 [kube-probe/1.15+ 127.0.0.1:37098]
I0319 17:56:00.117846       1 wrap.go:47] GET /healthz: (83.277µs) 200 [kube-probe/1.15+ 127.0.0.1:37132]
I0319 17:56:10.117794       1 wrap.go:47] GET /healthz: (73.042µs) 200 [kube-probe/1.15+ 127.0.0.1:37170]
I0319 17:56:20.119266       1 wrap.go:47] GET /healthz: (72.202µs) 200 [kube-probe/1.15+ 127.0.0.1:37202]
I0319 17:56:30.118082       1 wrap.go:47] GET /healthz: (101.963µs) 200 [kube-probe/1.15+ 127.0.0.1:37236]
I0319 17:56:40.117886       1 wrap.go:47] GET /healthz: (79.612µs) 200 [kube-probe/1.15+ 127.0.0.1:37286]
I0319 17:56:48.088885       1 reflector.go:370] k8s.io/client-go/informers/factory.go:133: Watch close - *v1.ReplicaSet total 0 items received
I0319 17:56:50.118084       1 wrap.go:47] GET /healthz: (111.96µs) 200 [kube-probe/1.15+ 127.0.0.1:37318]
I0319 17:57:00.118010       1 wrap.go:47] GET /healthz: (90.887µs) 200 [kube-probe/1.15+ 127.0.0.1:37352]
I0319 17:57:10.117987       1 wrap.go:47] GET /healthz: (87.648µs) 200 [kube-probe/1.15+ 127.0.0.1:37392]
I0319 17:57:20.117964       1 wrap.go:47] GET /healthz: (94.097µs) 200 [kube-probe/1.15+ 127.0.0.1:37424]
I0319 17:57:30.118018       1 wrap.go:47] GET /healthz: (68.013µs) 200 [kube-probe/1.15+ 127.0.0.1:37458]
I0319 17:57:40.117970       1 wrap.go:47] GET /healthz: (77.495µs) 200 [kube-probe/1.15+ 127.0.0.1:37506]
I0319 17:57:50.118108       1 wrap.go:47] GET /healthz: (102.414µs) 200 [kube-probe/1.15+ 127.0.0.1:37540]
I0319 17:57:50.272333       1 scheduling_queue.go:908] About to try and schedule pod windows-volumes-2298/pod-82cb83e9-4a70-11e9-af5d-a08cfde32bdd
I0319 17:57:50.272379       1 scheduler.go:453] Attempting to schedule pod: windows-volumes-2298/pod-82cb83e9-4a70-11e9-af5d-a08cfde32bdd
I0319 17:57:50.276121       1 scheduler_binder.go:269] AssumePodVolumes for pod "windows-volumes-2298/pod-82cb83e9-4a70-11e9-af5d-a08cfde32bdd", node "e2e-test-peterhornyack-windows-node-group-dp2r"
I0319 17:57:50.276159       1 scheduler_binder.go:279] AssumePodVolumes for pod "windows-volumes-2298/pod-82cb83e9-4a70-11e9-af5d-a08cfde32bdd", node "e2e-test-peterhornyack-windows-node-group-dp2r": all PVCs bound and nothing to do
I0319 17:57:50.277101       1 factory.go:733] Attempting to bind pod-82cb83e9-4a70-11e9-af5d-a08cfde32bdd to e2e-test-peterhornyack-windows-node-group-dp2r
I0319 17:57:50.285001       1 scheduler.go:572] pod windows-volumes-2298/pod-82cb83e9-4a70-11e9-af5d-a08cfde32bdd is bound successfully on node e2e-test-peterhornyack-windows-node-group-dp2r, 5 nodes evaluated, 2 nodes were found feasible
I0319 17:57:58.837908       1 scheduling_queue.go:908] About to try and schedule pod windows-volumes-2298/pod-87e5b827-4a70-11e9-af5d-a08cfde32bdd
I0319 17:57:58.837939       1 scheduler.go:453] Attempting to schedule pod: windows-volumes-2298/pod-87e5b827-4a70-11e9-af5d-a08cfde32bdd
I0319 17:57:58.842961       1 scheduler_binder.go:269] AssumePodVolumes for pod "windows-volumes-2298/pod-87e5b827-4a70-11e9-af5d-a08cfde32bdd", node "e2e-test-peterhornyack-windows-node-group-7n03"
I0319 17:57:58.842997       1 scheduler_binder.go:279] AssumePodVolumes for pod "windows-volumes-2298/pod-87e5b827-4a70-11e9-af5d-a08cfde32bdd", node "e2e-test-peterhornyack-windows-node-group-7n03": all PVCs bound and nothing to do
I0319 17:57:58.845328       1 factory.go:733] Attempting to bind pod-87e5b827-4a70-11e9-af5d-a08cfde32bdd to e2e-test-peterhornyack-windows-node-group-7n03
I0319 17:57:58.853273       1 scheduler.go:572] pod windows-volumes-2298/pod-87e5b827-4a70-11e9-af5d-a08cfde32bdd is bound successfully on node e2e-test-peterhornyack-windows-node-group-7n03, 5 nodes evaluated, 2 nodes were found feasible
I0319 17:58:00.117990       1 wrap.go:47] GET /healthz: (106.213µs) 200 [kube-probe/1.15+ 127.0.0.1:37576]
I0319 17:58:03.132566       1 reflector.go:370] k8s.io/client-go/informers/factory.go:133: Watch close - *v1.ReplicationController total 0 items received
I0319 17:58:10.117953       1 wrap.go:47] GET /healthz: (72.661µs) 200 [kube-probe/1.15+ 127.0.0.1:37620]
I0319 17:58:20.117933       1 wrap.go:47] GET /healthz: (84.36µs) 200 [kube-probe/1.15+ 127.0.0.1:37652]
I0319 17:58:25.089186       1 reflector.go:370] k8s.io/client-go/informers/factory.go:133: Watch close - *v1beta1.PodDisruptionBudget total 0 items received
I0319 17:58:30.119272       1 wrap.go:47] GET /healthz: (76.302µs) 200 [kube-probe/1.15+ 127.0.0.1:37686]
I0319 17:58:34.326155       1 scheduling_queue.go:908] About to try and schedule pod pod-network-test-3657/netserver-0
I0319 17:58:34.326187       1 scheduler.go:453] Attempting to schedule pod: pod-network-test-3657/netserver-0
I0319 17:58:34.326552       1 scheduler_binder.go:269] AssumePodVolumes for pod "pod-network-test-3657/netserver-0", node "e2e-test-peterhornyack-windows-node-group-7n03"
I0319 17:58:34.326568       1 scheduler_binder.go:279] AssumePodVolumes for pod "pod-network-test-3657/netserver-0", node "e2e-test-peterhornyack-windows-node-group-7n03": all PVCs bound and nothing to do
I0319 17:58:34.328322       1 factory.go:733] Attempting to bind netserver-0 to e2e-test-peterhornyack-windows-node-group-7n03
I0319 17:58:34.336331       1 scheduler.go:572] pod pod-network-test-3657/netserver-0 is bound successfully on node e2e-test-peterhornyack-windows-node-group-7n03, 5 nodes evaluated, 1 nodes were found feasible
I0319 17:58:34.375344       1 scheduling_queue.go:908] About to try and schedule pod pod-network-test-3657/netserver-1
I0319 17:58:34.375387       1 scheduler.go:453] Attempting to schedule pod: pod-network-test-3657/netserver-1
I0319 17:58:34.375629       1 scheduler_binder.go:269] AssumePodVolumes for pod "pod-network-test-3657/netserver-1", node "e2e-test-peterhornyack-windows-node-group-dp2r"
I0319 17:58:34.375645       1 scheduler_binder.go:279] AssumePodVolumes for pod "pod-network-test-3657/netserver-1", node "e2e-test-peterhornyack-windows-node-group-dp2r": all PVCs bound and nothing to do
I0319 17:58:34.375685       1 factory.go:733] Attempting to bind netserver-1 to e2e-test-peterhornyack-windows-node-group-dp2r
I0319 17:58:34.385107       1 scheduler.go:572] pod pod-network-test-3657/netserver-1 is bound successfully on node e2e-test-peterhornyack-windows-node-group-dp2r, 5 nodes evaluated, 1 nodes were found feasible
I0319 17:58:40.066459       1 reflector.go:370] k8s.io/client-go/informers/factory.go:133: Watch close - *v1.PersistentVolume total 0 items received
I0319 17:58:40.118492       1 wrap.go:47] GET /healthz: (71.816µs) 200 [kube-probe/1.15+ 127.0.0.1:37736]
I0319 17:58:50.118364       1 wrap.go:47] GET /healthz: (73.831µs) 200 [kube-probe/1.15+ 127.0.0.1:37768]
I0319 17:59:00.117869       1 wrap.go:47] GET /healthz: (81.317µs) 200 [kube-probe/1.15+ 127.0.0.1:37804]
I0319 17:59:04.641305       1 scheduling_queue.go:908] About to try and schedule pod pod-network-test-3657/test-container-pod
I0319 17:59:04.641340       1 scheduler.go:453] Attempting to schedule pod: pod-network-test-3657/test-container-pod
I0319 17:59:04.641706       1 scheduler_binder.go:269] AssumePodVolumes for pod "pod-network-test-3657/test-container-pod", node "e2e-test-peterhornyack-windows-node-group-7n03"
I0319 17:59:04.641724       1 scheduler_binder.go:279] AssumePodVolumes for pod "pod-network-test-3657/test-container-pod", node "e2e-test-peterhornyack-windows-node-group-7n03": all PVCs bound and nothing to do
I0319 17:59:04.641802       1 factory.go:733] Attempting to bind test-container-pod to e2e-test-peterhornyack-windows-node-group-7n03
I0319 17:59:04.650255       1 scheduler.go:572] pod pod-network-test-3657/test-container-pod is bound successfully on node e2e-test-peterhornyack-windows-node-group-7n03, 5 nodes evaluated, 2 nodes were found feasible
I0319 17:59:04.685986       1 scheduling_queue.go:908] About to try and schedule pod pod-network-test-3657/host-test-container-pod
I0319 17:59:04.686016       1 scheduler.go:453] Attempting to schedule pod: pod-network-test-3657/host-test-container-pod
I0319 17:59:04.686325       1 scheduler_binder.go:269] AssumePodVolumes for pod "pod-network-test-3657/host-test-container-pod", node "e2e-test-peterhornyack-windows-node-group-7n03"
I0319 17:59:04.686343       1 scheduler_binder.go:279] AssumePodVolumes for pod "pod-network-test-3657/host-test-container-pod", node "e2e-test-peterhornyack-windows-node-group-7n03": all PVCs bound and nothing to do
I0319 17:59:04.686390       1 factory.go:733] Attempting to bind host-test-container-pod to e2e-test-peterhornyack-windows-node-group-7n03
I0319 17:59:04.698073       1 scheduler.go:572] pod pod-network-test-3657/host-test-container-pod is bound successfully on node e2e-test-peterhornyack-windows-node-group-7n03, 5 nodes evaluated, 2 nodes were found feasible
I0319 17:59:09.124501       1 reflector.go:370] k8s.io/client-go/informers/factory.go:133: Watch close - *v1.Service total 0 items received
I0319 17:59:10.117785       1 wrap.go:47] GET /healthz: (72.898µs) 200 [kube-probe/1.15+ 127.0.0.1:37842]
I0319 17:59:20.117961       1 wrap.go:47] GET /healthz: (75.43µs) 200 [kube-probe/1.15+ 127.0.0.1:37878]
I0319 17:59:30.117769       1 wrap.go:47] GET /healthz: (71.311µs) 200 [kube-probe/1.15+ 127.0.0.1:37912]
I0319 17:59:40.107982       1 reflector.go:370] k8s.io/client-go/informers/factory.go:133: Watch close - *v1.StorageClass total 0 items received
I0319 17:59:40.117977       1 wrap.go:47] GET /healthz: (111.504µs) 200 [kube-probe/1.15+ 127.0.0.1:37960]
I0319 17:59:43.152595       1 scheduling_queue.go:908] About to try and schedule pod container-probe-8331/liveness-http
I0319 17:59:43.152627       1 scheduler.go:453] Attempting to schedule pod: container-probe-8331/liveness-http
I0319 17:59:43.152973       1 scheduler_binder.go:269] AssumePodVolumes for pod "container-probe-8331/liveness-http", node "e2e-test-peterhornyack-windows-node-group-dp2r"
I0319 17:59:43.153000       1 scheduler_binder.go:279] AssumePodVolumes for pod "container-probe-8331/liveness-http", node "e2e-test-peterhornyack-windows-node-group-dp2r": all PVCs bound and nothing to do
I0319 17:59:43.153065       1 factory.go:733] Attempting to bind liveness-http to e2e-test-peterhornyack-windows-node-group-dp2r
I0319 17:59:43.160876       1 scheduler.go:572] pod container-probe-8331/liveness-http is bound successfully on node e2e-test-peterhornyack-windows-node-group-dp2r, 5 nodes evaluated, 2 nodes were found feasible
I0319 17:59:50.118435       1 wrap.go:47] GET /healthz: (91.142µs) 200 [kube-probe/1.15+ 127.0.0.1:37992]
I0319 18:00:00.120385       1 wrap.go:47] GET /healthz: (80.601µs) 200 [kube-probe/1.15+ 127.0.0.1:38028]
I0319 18:00:10.118015       1 wrap.go:47] GET /healthz: (86.049µs) 200 [kube-probe/1.15+ 127.0.0.1:38066]
I0319 18:00:20.118141       1 wrap.go:47] GET /healthz: (64.598µs) 200 [kube-probe/1.15+ 127.0.0.1:38100]
I0319 18:00:30.118236       1 wrap.go:47] GET /healthz: (82.415µs) 200 [kube-probe/1.15+ 127.0.0.1:38134]
I0319 18:00:31.104911       1 reflector.go:370] k8s.io/client-go/informers/factory.go:133: Watch close - *v1.PersistentVolumeClaim total 0 items received
I0319 18:00:40.119631       1 wrap.go:47] GET /healthz: (82.236µs) 200 [kube-probe/1.15+ 127.0.0.1:38182]
I0319 18:00:50.117908       1 wrap.go:47] GET /healthz: (68.988µs) 200 [kube-probe/1.15+ 127.0.0.1:38214]
I0319 18:00:53.063860       1 reflector.go:370] k8s.io/kubernetes/cmd/kube-scheduler/app/server.go:223: Watch close - *v1.Pod total 52 items received
I0319 18:01:00.118001       1 wrap.go:47] GET /healthz: (75.28µs) 200 [kube-probe/1.15+ 127.0.0.1:38248]
I0319 18:01:10.118040       1 wrap.go:47] GET /healthz: (72.373µs) 200 [kube-probe/1.15+ 127.0.0.1:38286]
I0319 18:01:20.117987       1 wrap.go:47] GET /healthz: (80.094µs) 200 [kube-probe/1.15+ 127.0.0.1:38320]
I0319 18:01:30.118069       1 wrap.go:47] GET /healthz: (87.337µs) 200 [kube-probe/1.15+ 127.0.0.1:38356]
I0319 18:01:40.118048       1 wrap.go:47] GET /healthz: (69.648µs) 200 [kube-probe/1.15+ 127.0.0.1:38404]
I0319 18:01:50.118149       1 wrap.go:47] GET /healthz: (81µs) 200 [kube-probe/1.15+ 127.0.0.1:38436]
I0319 18:02:00.117765       1 wrap.go:47] GET /healthz: (64.825µs) 200 [kube-probe/1.15+ 127.0.0.1:38470]
I0319 18:02:10.061375       1 reflector.go:370] k8s.io/client-go/informers/factory.go:133: Watch close - *v1.StatefulSet total 0 items received
I0319 18:02:10.117903       1 wrap.go:47] GET /healthz: (70.669µs) 200 [kube-probe/1.15+ 127.0.0.1:38510]
I0319 18:02:13.100895       1 reflector.go:370] k8s.io/client-go/informers/factory.go:133: Watch close - *v1.Node total 63 items received
I0319 18:02:20.118249       1 wrap.go:47] GET /healthz: (83.422µs) 200 [kube-probe/1.15+ 127.0.0.1:38542]
I0319 18:02:30.118129       1 wrap.go:47] GET /healthz: (117.307µs) 200 [kube-probe/1.15+ 127.0.0.1:38576]
I0319 18:02:40.118298       1 wrap.go:47] GET /healthz: (62.985µs) 200 [kube-probe/1.15+ 127.0.0.1:38626]
I0319 18:02:50.118114       1 wrap.go:47] GET /healthz: (106.937µs) 200 [kube-probe/1.15+ 127.0.0.1:38660]
I0319 18:03:00.118480       1 wrap.go:47] GET /healthz: (70.924µs) 200 [kube-probe/1.15+ 127.0.0.1:38694]
I0319 18:03:10.119277       1 wrap.go:47] GET /healthz: (87.514µs) 200 [kube-probe/1.15+ 127.0.0.1:38732]
I0319 18:03:20.118263       1 wrap.go:47] GET /healthz: (81.447µs) 200 [kube-probe/1.15+ 127.0.0.1:38764]
I0319 18:03:30.117956       1 wrap.go:47] GET /healthz: (77.904µs) 200 [kube-probe/1.15+ 127.0.0.1:38798]
I0319 18:03:40.092957       1 reflector.go:370] k8s.io/client-go/informers/factory.go:133: Watch close - *v1.ReplicaSet total 0 items received
I0319 18:03:40.122898       1 wrap.go:47] GET /healthz: (79.702µs) 200 [kube-probe/1.15+ 127.0.0.1:38846]
I0319 18:03:50.121483       1 wrap.go:47] GET /healthz: (121.696µs) 200 [kube-probe/1.15+ 127.0.0.1:38878]
I0319 18:04:00.118283       1 wrap.go:47] GET /healthz: (254.376µs) 200 [kube-probe/1.15+ 127.0.0.1:38914]
I0319 18:04:08.774358       1 scheduling_queue.go:908] About to try and schedule pod downward-api-7723/downwardapi-volume-64659b9a-4a71-11e9-af5d-a08cfde32bdd
I0319 18:04:08.774403       1 scheduler.go:453] Attempting to schedule pod: downward-api-7723/downwardapi-volume-64659b9a-4a71-11e9-af5d-a08cfde32bdd
I0319 18:04:08.775668       1 scheduler_binder.go:269] AssumePodVolumes for pod "downward-api-7723/downwardapi-volume-64659b9a-4a71-11e9-af5d-a08cfde32bdd", node "e2e-test-peterhornyack-windows-node-group-7n03"
I0319 18:04:08.775700       1 scheduler_binder.go:279] AssumePodVolumes for pod "downward-api-7723/downwardapi-volume-64659b9a-4a71-11e9-af5d-a08cfde32bdd", node "e2e-test-peterhornyack-windows-node-group-7n03": all PVCs bound and nothing to do
I0319 18:04:08.775763       1 factory.go:733] Attempting to bind downwardapi-volume-64659b9a-4a71-11e9-af5d-a08cfde32bdd to e2e-test-peterhornyack-windows-node-group-7n03
I0319 18:04:08.785143       1 scheduler.go:572] pod downward-api-7723/downwardapi-volume-64659b9a-4a71-11e9-af5d-a08cfde32bdd is bound successfully on node e2e-test-peterhornyack-windows-node-group-7n03, 5 nodes evaluated, 2 nodes were found feasible
I0319 18:04:10.118001       1 wrap.go:47] GET /healthz: (81.841µs) 200 [kube-probe/1.15+ 127.0.0.1:38954]
I0319 18:04:20.118250       1 wrap.go:47] GET /healthz: (72.722µs) 200 [kube-probe/1.15+ 127.0.0.1:38986]
I0319 18:04:29.679005       1 scheduling_queue.go:908] About to try and schedule pod provisioning-8216/pvc-writer-node1-84l6z
I0319 18:04:29.679074       1 scheduler.go:453] Attempting to schedule pod: provisioning-8216/pvc-writer-node1-84l6z
I0319 18:04:29.679277       1 csi_volume_predicate.go:147] Not considering non-CSI volume provisioning-8216/pvc-v4s8t
I0319 18:04:29.679384       1 scheduler_binder.go:665] All bound volumes for Pod "provisioning-8216/pvc-writer-node1-84l6z" match with Node "e2e-test-peterhornyack-windows-node-group-7n03"
I0319 18:04:29.679425       1 csi_volume_predicate.go:147] Not considering non-CSI volume provisioning-8216/pvc-v4s8t
I0319 18:04:29.679462       1 scheduler_binder.go:665] All bound volumes for Pod "provisioning-8216/pvc-writer-node1-84l6z" match with Node "e2e-test-peterhornyack-windows-node-group-dp2r"
I0319 18:04:29.679651       1 scheduler_binder.go:269] AssumePodVolumes for pod "provisioning-8216/pvc-writer-node1-84l6z", node "e2e-test-peterhornyack-windows-node-group-dp2r"
I0319 18:04:29.679665       1 scheduler_binder.go:279] AssumePodVolumes for pod "provisioning-8216/pvc-writer-node1-84l6z", node "e2e-test-peterhornyack-windows-node-group-dp2r": all PVCs bound and nothing to do
I0319 18:04:29.679721       1 factory.go:733] Attempting to bind pvc-writer-node1-84l6z to e2e-test-peterhornyack-windows-node-group-dp2r
I0319 18:04:29.687804       1 scheduler.go:572] pod provisioning-8216/pvc-writer-node1-84l6z is bound successfully on node e2e-test-peterhornyack-windows-node-group-dp2r, 5 nodes evaluated, 2 nodes were found feasible
I0319 18:04:30.127574       1 wrap.go:47] GET /healthz: (94.425µs) 200 [kube-probe/1.15+ 127.0.0.1:39028]
I0319 18:04:40.146878       1 wrap.go:47] GET /healthz: (82.991µs) 200 [kube-probe/1.15+ 127.0.0.1:39076]
I0319 18:04:50.117847       1 wrap.go:47] GET /healthz: (75.01µs) 200 [kube-probe/1.15+ 127.0.0.1:39108]
I0319 18:04:58.528144       1 scheduling_queue.go:908] About to try and schedule pod provisioning-8216/pvc-reader-node2-qn8pg
I0319 18:04:58.528177       1 scheduler.go:453] Attempting to schedule pod: provisioning-8216/pvc-reader-node2-qn8pg
I0319 18:04:58.530454       1 csi_volume_predicate.go:147] Not considering non-CSI volume provisioning-8216/pvc-v4s8t
I0319 18:04:58.530505       1 scheduler_binder.go:665] All bound volumes for Pod "provisioning-8216/pvc-reader-node2-qn8pg" match with Node "e2e-test-peterhornyack-windows-node-group-7n03"
I0319 18:04:58.530624       1 scheduler_binder.go:269] AssumePodVolumes for pod "provisioning-8216/pvc-reader-node2-qn8pg", node "e2e-test-peterhornyack-windows-node-group-7n03"
I0319 18:04:58.530637       1 scheduler_binder.go:279] AssumePodVolumes for pod "provisioning-8216/pvc-reader-node2-qn8pg", node "e2e-test-peterhornyack-windows-node-group-7n03": all PVCs bound and nothing to do
I0319 18:04:58.530700       1 factory.go:733] Attempting to bind pvc-reader-node2-qn8pg to e2e-test-peterhornyack-windows-node-group-7n03
I0319 18:04:58.539194       1 scheduler.go:572] pod provisioning-8216/pvc-reader-node2-qn8pg is bound successfully on node e2e-test-peterhornyack-windows-node-group-7n03, 5 nodes evaluated, 1 nodes were found feasible
I0319 18:05:00.118968       1 wrap.go:47] GET /healthz: (77.022µs) 200 [kube-probe/1.15+ 127.0.0.1:39142]
I0319 18:05:10.117792       1 wrap.go:47] GET /healthz: (63.855µs) 200 [kube-probe/1.15+ 127.0.0.1:39182]
I0319 18:05:20.118696       1 wrap.go:47] GET /healthz: (71.66µs) 200 [kube-probe/1.15+ 127.0.0.1:39214]
I0319 18:05:29.111576       1 reflector.go:370] k8s.io/client-go/informers/factory.go:133: Watch close - *v1.StorageClass total 1 items received
I0319 18:05:30.118369       1 wrap.go:47] GET /healthz: (72.272µs) 200 [kube-probe/1.15+ 127.0.0.1:39250]
I0319 18:05:40.118904       1 wrap.go:47] GET /healthz: (93.034µs) 200 [kube-probe/1.15+ 127.0.0.1:39298]
I0319 18:05:50.118582       1 wrap.go:47] GET /healthz: (85.829µs) 200 [kube-probe/1.15+ 127.0.0.1:39330]
I0319 18:06:00.118402       1 wrap.go:47] GET /healthz: (70.925µs) 200 [kube-probe/1.15+ 127.0.0.1:39364]
I0319 18:06:10.118071       1 wrap.go:47] GET /healthz: (100.455µs) 200 [kube-probe/1.15+ 127.0.0.1:39402]
I0319 18:06:15.070204       1 scheduling_queue.go:908] About to try and schedule pod gc-6374/simpletest.deployment-64f8744559-8tb5s
I0319 18:06:15.070259       1 scheduler.go:453] Attempting to schedule pod: gc-6374/simpletest.deployment-64f8744559-8tb5s
I0319 18:06:15.070617       1 scheduler_binder.go:269] AssumePodVolumes for pod "gc-6374/simpletest.deployment-64f8744559-8tb5s", node "e2e-test-peterhornyack-windows-node-group-7n03"
I0319 18:06:15.070633       1 scheduler_binder.go:279] AssumePodVolumes for pod "gc-6374/simpletest.deployment-64f8744559-8tb5s", node "e2e-test-peterhornyack-windows-node-group-7n03": all PVCs bound and nothing to do
I0319 18:06:15.070688       1 factory.go:733] Attempting to bind simpletest.deployment-64f8744559-8tb5s to e2e-test-peterhornyack-windows-node-group-7n03
I0319 18:06:15.093943       1 scheduler.go:572] pod gc-6374/simpletest.deployment-64f8744559-8tb5s is bound successfully on node e2e-test-peterhornyack-windows-node-group-7n03, 5 nodes evaluated, 2 nodes were found feasible
I0319 18:06:15.102554       1 scheduling_queue.go:908] About to try and schedule pod gc-6374/simpletest.deployment-64f8744559-gk87k
I0319 18:06:15.102584       1 scheduler.go:453] Attempting to schedule pod: gc-6374/simpletest.deployment-64f8744559-gk87k
I0319 18:06:15.102869       1 scheduler_binder.go:269] AssumePodVolumes for pod "gc-6374/simpletest.deployment-64f8744559-gk87k", node "e2e-test-peterhornyack-windows-node-group-dp2r"
I0319 18:06:15.102885       1 scheduler_binder.go:279] AssumePodVolumes for pod "gc-6374/simpletest.deployment-64f8744559-gk87k", node "e2e-test-peterhornyack-windows-node-group-dp2r": all PVCs bound and nothing to do
I0319 18:06:15.102921       1 factory.go:733] Attempting to bind simpletest.deployment-64f8744559-gk87k to e2e-test-peterhornyack-windows-node-group-dp2r
I0319 18:06:15.145982       1 scheduler.go:572] pod gc-6374/simpletest.deployment-64f8744559-gk87k is bound successfully on node e2e-test-peterhornyack-windows-node-group-dp2r, 5 nodes evaluated, 2 nodes were found feasible
I0319 18:06:20.117909       1 wrap.go:47] GET /healthz: (68.131µs) 200 [kube-probe/1.15+ 127.0.0.1:39436]
I0319 18:06:24.139392       1 scheduling_queue.go:908] About to try and schedule pod containers-4588/client-containers-b51449d6-4a71-11e9-af5d-a08cfde32bdd
I0319 18:06:24.139423       1 scheduler.go:453] Attempting to schedule pod: containers-4588/client-containers-b51449d6-4a71-11e9-af5d-a08cfde32bdd
I0319 18:06:24.139726       1 scheduler_binder.go:269] AssumePodVolumes for pod "containers-4588/client-containers-b51449d6-4a71-11e9-af5d-a08cfde32bdd", node "e2e-test-peterhornyack-windows-node-group-dp2r"
I0319 18:06:24.139750       1 scheduler_binder.go:279] AssumePodVolumes for pod "containers-4588/client-containers-b51449d6-4a71-11e9-af5d-a08cfde32bdd", node "e2e-test-peterhornyack-windows-node-group-dp2r": all PVCs bound and nothing to do
I0319 18:06:24.139804       1 factory.go:733] Attempting to bind client-containers-b51449d6-4a71-11e9-af5d-a08cfde32bdd to e2e-test-peterhornyack-windows-node-group-dp2r
I0319 18:06:24.148945       1 scheduler.go:572] pod containers-4588/client-containers-b51449d6-4a71-11e9-af5d-a08cfde32bdd is bound successfully on node e2e-test-peterhornyack-windows-node-group-dp2r, 5 nodes evaluated, 2 nodes were found feasible
I0319 18:06:30.118294       1 wrap.go:47] GET /healthz: (72.743µs) 200 [kube-probe/1.15+ 127.0.0.1:39470]
I0319 18:06:40.118064       1 wrap.go:47] GET /healthz: (102.499µs) 200 [kube-probe/1.15+ 127.0.0.1:39518]
I0319 18:06:42.097668       1 reflector.go:370] k8s.io/client-go/informers/factory.go:133: Watch close - *v1beta1.PodDisruptionBudget total 0 items received
I0319 18:06:50.118321       1 wrap.go:47] GET /healthz: (81.092µs) 200 [kube-probe/1.15+ 127.0.0.1:39550]
I0319 18:06:54.135690       1 reflector.go:370] k8s.io/client-go/informers/factory.go:133: Watch close - *v1.ReplicationController total 0 items received
I0319 18:07:00.117838       1 wrap.go:47] GET /healthz: (80.521µs) 200 [kube-probe/1.15+ 127.0.0.1:39586]
I0319 18:07:10.118227       1 wrap.go:47] GET /healthz: (77.061µs) 200 [kube-probe/1.15+ 127.0.0.1:39624]
I0319 18:07:13.065973       1 reflector.go:370] k8s.io/client-go/informers/factory.go:133: Watch close - *v1.StatefulSet total 0 items received
I0319 18:07:20.118154       1 wrap.go:47] GET /healthz: (65.503µs) 200 [kube-probe/1.15+ 127.0.0.1:39656]
I0319 18:07:30.117851       1 wrap.go:47] GET /healthz: (80.484µs) 200 [kube-probe/1.15+ 127.0.0.1:39690]
I0319 18:07:40.118532       1 wrap.go:47] GET /healthz: (81.745µs) 200 [kube-probe/1.15+ 127.0.0.1:39740]
I0319 18:07:47.069872       1 reflector.go:370] k8s.io/client-go/informers/factory.go:133: Watch close - *v1.PersistentVolume total 5 items received
I0319 18:07:50.118696       1 wrap.go:47] GET /healthz: (81.014µs) 200 [kube-probe/1.15+ 127.0.0.1:39772]
I0319 18:07:53.403211       1 scheduling_queue.go:908] About to try and schedule pod init-container-2499/pod-init-ea490ef6-4a71-11e9-af5d-a08cfde32bdd
I0319 18:07:53.403244       1 scheduler.go:453] Attempting to schedule pod: init-container-2499/pod-init-ea490ef6-4a71-11e9-af5d-a08cfde32bdd
I0319 18:07:53.403636       1 scheduler_binder.go:269] AssumePodVolumes for pod "init-container-2499/pod-init-ea490ef6-4a71-11e9-af5d-a08cfde32bdd", node "e2e-test-peterhornyack-windows-node-group-dp2r"
I0319 18:07:53.403655       1 scheduler_binder.go:279] AssumePodVolumes for pod "init-container-2499/pod-init-ea490ef6-4a71-11e9-af5d-a08cfde32bdd", node "e2e-test-peterhornyack-windows-node-group-dp2r": all PVCs bound and nothing to do
I0319 18:07:53.403716       1 factory.go:733] Attempting to bind pod-init-ea490ef6-4a71-11e9-af5d-a08cfde32bdd to e2e-test-peterhornyack-windows-node-group-dp2r
I0319 18:07:53.412496       1 scheduler.go:572] pod init-container-2499/pod-init-ea490ef6-4a71-11e9-af5d-a08cfde32bdd is bound successfully on node e2e-test-peterhornyack-windows-node-group-dp2r, 5 nodes evaluated, 2 nodes were found feasible
I0319 18:07:58.127909       1 reflector.go:370] k8s.io/client-go/informers/factory.go:133: Watch close - *v1.Service total 0 items received
I0319 18:08:00.117832       1 wrap.go:47] GET /healthz: (73.391µs) 200 [kube-probe/1.15+ 127.0.0.1:39806]
I0319 18:08:10.118483       1 wrap.go:47] GET /healthz: (83.548µs) 200 [kube-probe/1.15+ 127.0.0.1:39844]
I0319 18:08:20.117943       1 wrap.go:47] GET /healthz: (79.948µs) 200 [kube-probe/1.15+ 127.0.0.1:39878]
I0319 18:08:29.107664       1 reflector.go:370] k8s.io/client-go/informers/factory.go:133: Watch close - *v1.PersistentVolumeClaim total 6 items received
I0319 18:08:30.067199       1 reflector.go:370] k8s.io/kubernetes/cmd/kube-scheduler/app/server.go:223: Watch close - *v1.Pod total 40 items received
I0319 18:08:30.118268       1 wrap.go:47] GET /healthz: (80.382µs) 200 [kube-probe/1.15+ 127.0.0.1:39912]
I0319 18:08:38.508384       1 scheduling_queue.go:908] About to try and schedule pod kubectl-4507/update-demo-nautilus-jwns7
I0319 18:08:38.508415       1 scheduler.go:453] Attempting to schedule pod: kubectl-4507/update-demo-nautilus-jwns7
I0319 18:08:38.511492       1 scheduler_binder.go:269] AssumePodVolumes for pod "kubectl-4507/update-demo-nautilus-jwns7", node "e2e-test-peterhornyack-windows-node-group-7n03"
I0319 18:08:38.511523       1 scheduler_binder.go:279] AssumePodVolumes for pod "kubectl-4507/update-demo-nautilus-jwns7", node "e2e-test-peterhornyack-windows-node-group-7n03": all PVCs bound and nothing to do
I0319 18:08:38.514568       1 factory.go:733] Attempting to bind update-demo-nautilus-jwns7 to e2e-test-peterhornyack-windows-node-group-7n03
I0319 18:08:38.520766       1 scheduling_queue.go:908] About to try and schedule pod kubectl-4507/update-demo-nautilus-c68p2
I0319 18:08:38.520792       1 scheduler.go:453] Attempting to schedule pod: kubectl-4507/update-demo-nautilus-c68p2
I0319 18:08:38.525848       1 scheduler_binder.go:269] AssumePodVolumes for pod "kubectl-4507/update-demo-nautilus-c68p2", node "e2e-test-peterhornyack-windows-node-group-dp2r"
I0319 18:08:38.525878       1 scheduler_binder.go:279] AssumePodVolumes for pod "kubectl-4507/update-demo-nautilus-c68p2", node "e2e-test-peterhornyack-windows-node-group-dp2r": all PVCs bound and nothing to do
I0319 18:08:38.525938       1 factory.go:733] Attempting to bind update-demo-nautilus-c68p2 to e2e-test-peterhornyack-windows-node-group-dp2r
I0319 18:08:38.542652       1 scheduler.go:572] pod kubectl-4507/update-demo-nautilus-c68p2 is bound successfully on node e2e-test-peterhornyack-windows-node-group-dp2r, 5 nodes evaluated, 2 nodes were found feasible
I0319 18:08:38.543268       1 scheduler.go:572] pod kubectl-4507/update-demo-nautilus-jwns7 is bound successfully on node e2e-test-peterhornyack-windows-node-group-7n03, 5 nodes evaluated, 2 nodes were found feasible
I0319 18:08:40.118690       1 wrap.go:47] GET /healthz: (83.071µs) 200 [kube-probe/1.15+ 127.0.0.1:39960]
I0319 18:08:50.117922       1 wrap.go:47] GET /healthz: (75.009µs) 200 [kube-probe/1.15+ 127.0.0.1:39994]
I0319 18:08:51.786215       1 scheduling_queue.go:908] About to try and schedule pod kubectl-4507/update-demo-kitten-t5xt7
I0319 18:08:51.786244       1 scheduler.go:453] Attempting to schedule pod: kubectl-4507/update-demo-kitten-t5xt7
I0319 18:08:51.786650       1 scheduler_binder.go:269] AssumePodVolumes for pod "kubectl-4507/update-demo-kitten-t5xt7", node "e2e-test-peterhornyack-windows-node-group-7n03"
I0319 18:08:51.786666       1 scheduler_binder.go:279] AssumePodVolumes for pod "kubectl-4507/update-demo-kitten-t5xt7", node "e2e-test-peterhornyack-windows-node-group-7n03": all PVCs bound and nothing to do
I0319 18:08:51.786727       1 factory.go:733] Attempting to bind update-demo-kitten-t5xt7 to e2e-test-peterhornyack-windows-node-group-7n03
I0319 18:08:51.806465       1 scheduler.go:572] pod kubectl-4507/update-demo-kitten-t5xt7 is bound successfully on node e2e-test-peterhornyack-windows-node-group-7n03, 5 nodes evaluated, 2 nodes were found feasible
I0319 18:09:00.118883       1 wrap.go:47] GET /healthz: (77.251µs) 200 [kube-probe/1.15+ 127.0.0.1:40032]
I0319 18:09:01.735930       1 scheduling_queue.go:908] About to try and schedule pod kubectl-4507/update-demo-kitten-cxrzr
I0319 18:09:01.735964       1 scheduler.go:453] Attempting to schedule pod: kubectl-4507/update-demo-kitten-cxrzr
I0319 18:09:01.736413       1 scheduler_binder.go:269] AssumePodVolumes for pod "kubectl-4507/update-demo-kitten-cxrzr", node "e2e-test-peterhornyack-windows-node-group-dp2r"
I0319 18:09:01.736435       1 scheduler_binder.go:279] AssumePodVolumes for pod "kubectl-4507/update-demo-kitten-cxrzr", node "e2e-test-peterhornyack-windows-node-group-dp2r": all PVCs bound and nothing to do
I0319 18:09:01.736495       1 factory.go:733] Attempting to bind update-demo-kitten-cxrzr to e2e-test-peterhornyack-windows-node-group-dp2r
I0319 18:09:01.759646       1 scheduler.go:572] pod kubectl-4507/update-demo-kitten-cxrzr is bound successfully on node e2e-test-peterhornyack-windows-node-group-dp2r, 5 nodes evaluated, 2 nodes were found feasible
I0319 18:09:10.117637       1 wrap.go:47] GET /healthz: (76.205µs) 200 [kube-probe/1.15+ 127.0.0.1:40070]
I0319 18:09:20.118148       1 wrap.go:47] GET /healthz: (77.204µs) 200 [kube-probe/1.15+ 127.0.0.1:40102]
I0319 18:09:30.119177       1 wrap.go:47] GET /healthz: (396.662µs) 200 [kube-probe/1.15+ 127.0.0.1:40140]
I0319 18:09:40.118092       1 wrap.go:47] GET /healthz: (91.981µs) 200 [kube-probe/1.15+ 127.0.0.1:40190]
I0319 18:09:50.096192       1 reflector.go:370] k8s.io/client-go/informers/factory.go:133: Watch close - *v1.ReplicaSet total 4 items received
I0319 18:09:50.118079       1 wrap.go:47] GET /healthz: (85.332µs) 200 [kube-probe/1.15+ 127.0.0.1:40222]
I0319 18:10:00.121936       1 wrap.go:47] GET /healthz: (78.451µs) 200 [kube-probe/1.15+ 127.0.0.1:40258]
I0319 18:10:10.118779       1 wrap.go:47] GET /healthz: (89.976µs) 200 [kube-probe/1.15+ 127.0.0.1:40296]
I0319 18:10:20.125553       1 wrap.go:47] GET /healthz: (85.576µs) 200 [kube-probe/1.15+ 127.0.0.1:40328]
I0319 18:10:30.117956       1 wrap.go:47] GET /healthz: (72.091µs) 200 [kube-probe/1.15+ 127.0.0.1:40362]
I0319 18:10:40.117891       1 wrap.go:47] GET /healthz: (71.124µs) 200 [kube-probe/1.15+ 127.0.0.1:40410]
I0319 18:10:47.458403       1 scheduling_queue.go:908] About to try and schedule pod downward-api-848/downwardapi-volume-5207c321-4a72-11e9-af5d-a08cfde32bdd
I0319 18:10:47.458434       1 scheduler.go:453] Attempting to schedule pod: downward-api-848/downwardapi-volume-5207c321-4a72-11e9-af5d-a08cfde32bdd
I0319 18:10:47.459719       1 scheduler_binder.go:269] AssumePodVolumes for pod "downward-api-848/downwardapi-volume-5207c321-4a72-11e9-af5d-a08cfde32bdd", node "e2e-test-peterhornyack-windows-node-group-7n03"
I0319 18:10:47.459746       1 scheduler_binder.go:279] AssumePodVolumes for pod "downward-api-848/downwardapi-volume-5207c321-4a72-11e9-af5d-a08cfde32bdd", node "e2e-test-peterhornyack-windows-node-group-7n03": all PVCs bound and nothing to do
I0319 18:10:47.459807       1 factory.go:733] Attempting to bind downwardapi-volume-5207c321-4a72-11e9-af5d-a08cfde32bdd to e2e-test-peterhornyack-windows-node-group-7n03
I0319 18:10:47.467355       1 scheduler.go:572] pod downward-api-848/downwardapi-volume-5207c321-4a72-11e9-af5d-a08cfde32bdd is bound successfully on node e2e-test-peterhornyack-windows-node-group-7n03, 5 nodes evaluated, 2 nodes were found feasible
I0319 18:10:50.117871       1 wrap.go:47] GET /healthz: (80.809µs) 200 [kube-probe/1.15+ 127.0.0.1:40444]
I0319 18:11:00.117778       1 wrap.go:47] GET /healthz: (59.444µs) 200 [kube-probe/1.15+ 127.0.0.1:40478]
I0319 18:11:09.103743       1 reflector.go:370] k8s.io/client-go/informers/factory.go:133: Watch close - *v1.Node total 70 items received
I0319 18:11:10.091478       1 scheduling_queue.go:908] About to try and schedule pod init-container-2497/pod-init-5f8594ad-4a72-11e9-af5d-a08cfde32bdd
I0319 18:11:10.091514       1 scheduler.go:453] Attempting to schedule pod: init-container-2497/pod-init-5f8594ad-4a72-11e9-af5d-a08cfde32bdd
I0319 18:11:10.093735       1 scheduler_binder.go:269] AssumePodVolumes for pod "init-container-2497/pod-init-5f8594ad-4a72-11e9-af5d-a08cfde32bdd", node "e2e-test-peterhornyack-windows-node-group-dp2r"
I0319 18:11:10.093766       1 scheduler_binder.go:279] AssumePodVolumes for pod "init-container-2497/pod-init-5f8594ad-4a72-11e9-af5d-a08cfde32bdd", node "e2e-test-peterhornyack-windows-node-group-dp2r": all PVCs bound and nothing to do
I0319 18:11:10.093832       1 factory.go:733] Attempting to bind pod-init-5f8594ad-4a72-11e9-af5d-a08cfde32bdd to e2e-test-peterhornyack-windows-node-group-dp2r
I0319 18:11:10.101800       1 scheduler.go:572] pod init-container-2497/pod-init-5f8594ad-4a72-11e9-af5d-a08cfde32bdd is bound successfully on node e2e-test-peterhornyack-windows-node-group-dp2r, 5 nodes evaluated, 2 nodes were found feasible
I0319 18:11:10.119183       1 wrap.go:47] GET /healthz: (191.99µs) 200 [kube-probe/1.15+ 127.0.0.1:40520]
I0319 18:11:20.118050       1 wrap.go:47] GET /healthz: (70.935µs) 200 [kube-probe/1.15+ 127.0.0.1:40552]
I0319 18:11:30.121613       1 wrap.go:47] GET /healthz: (78.102µs) 200 [kube-probe/1.15+ 127.0.0.1:40586]
I0319 18:11:31.969167       1 scheduling_queue.go:908] About to try and schedule pod services-3307/nodeport-test-fzz78
I0319 18:11:31.969211       1 scheduler.go:453] Attempting to schedule pod: services-3307/nodeport-test-fzz78
I0319 18:11:31.971435       1 scheduler_binder.go:269] AssumePodVolumes for pod "services-3307/nodeport-test-fzz78", node "e2e-test-peterhornyack-windows-node-group-7n03"
I0319 18:11:31.971490       1 scheduler_binder.go:279] AssumePodVolumes for pod "services-3307/nodeport-test-fzz78", node "e2e-test-peterhornyack-windows-node-group-7n03": all PVCs bound and nothing to do
I0319 18:11:31.971554       1 factory.go:733] Attempting to bind nodeport-test-fzz78 to e2e-test-peterhornyack-windows-node-group-7n03
I0319 18:11:31.983738       1 scheduler.go:572] pod services-3307/nodeport-test-fzz78 is bound successfully on node e2e-test-peterhornyack-windows-node-group-7n03, 5 nodes evaluated, 2 nodes were found feasible
I0319 18:11:40.118450       1 wrap.go:47] GET /healthz: (72.451µs) 200 [kube-probe/1.15+ 127.0.0.1:40636]
I0319 18:11:42.326926       1 scheduling_queue.go:908] About to try and schedule pod services-3307/pod-72bcebb8-4a72-11e9-af5d-a08cfde32bdd
I0319 18:11:42.326979       1 scheduler.go:453] Attempting to schedule pod: services-3307/pod-72bcebb8-4a72-11e9-af5d-a08cfde32bdd
I0319 18:11:42.328240       1 scheduler_binder.go:269] AssumePodVolumes for pod "services-3307/pod-72bcebb8-4a72-11e9-af5d-a08cfde32bdd", node "e2e-test-peterhornyack-windows-node-group-7n03"
I0319 18:11:42.328291       1 scheduler_binder.go:279] AssumePodVolumes for pod "services-3307/pod-72bcebb8-4a72-11e9-af5d-a08cfde32bdd", node "e2e-test-peterhornyack-windows-node-group-7n03": all PVCs bound and nothing to do
I0319 18:11:42.328344       1 factory.go:733] Attempting to bind pod-72bcebb8-4a72-11e9-af5d-a08cfde32bdd to e2e-test-peterhornyack-windows-node-group-7n03
I0319 18:11:42.335110       1 scheduler.go:572] pod services-3307/pod-72bcebb8-4a72-11e9-af5d-a08cfde32bdd is bound successfully on node e2e-test-peterhornyack-windows-node-group-7n03, 5 nodes evaluated, 2 nodes were found feasible
I0319 18:11:50.119178       1 wrap.go:47] GET /healthz: (99.98µs) 200 [kube-probe/1.15+ 127.0.0.1:40668]
I0319 18:12:00.117817       1 wrap.go:47] GET /healthz: (81.527µs) 200 [kube-probe/1.15+ 127.0.0.1:40718]
I0319 18:12:08.114466       1 reflector.go:370] k8s.io/client-go/informers/factory.go:133: Watch close - *v1.StorageClass total 1 items received
I0319 18:12:10.117800       1 wrap.go:47] GET /healthz: (77.684µs) 200 [kube-probe/1.15+ 127.0.0.1:40760]
I0319 18:12:20.118135       1 wrap.go:47] GET /healthz: (93.096µs) 200 [kube-probe/1.15+ 127.0.0.1:40792]
I0319 18:12:24.653436       1 scheduling_queue.go:908] About to try and schedule pod configmap-5014/pod-configmaps-8bf7135d-4a72-11e9-af5d-a08cfde32bdd
I0319 18:12:24.653471       1 scheduler.go:453] Attempting to schedule pod: configmap-5014/pod-configmaps-8bf7135d-4a72-11e9-af5d-a08cfde32bdd
I0319 18:12:24.655360       1 scheduler_binder.go:269] AssumePodVolumes for pod "configmap-5014/pod-configmaps-8bf7135d-4a72-11e9-af5d-a08cfde32bdd", node "e2e-test-peterhornyack-windows-node-group-7n03"
I0319 18:12:24.655402       1 scheduler_binder.go:279] AssumePodVolumes for pod "configmap-5014/pod-configmaps-8bf7135d-4a72-11e9-af5d-a08cfde32bdd", node "e2e-test-peterhornyack-windows-node-group-7n03": all PVCs bound and nothing to do
I0319 18:12:24.655463       1 factory.go:733] Attempting to bind pod-configmaps-8bf7135d-4a72-11e9-af5d-a08cfde32bdd to e2e-test-peterhornyack-windows-node-group-7n03
I0319 18:12:24.664347       1 scheduler.go:572] pod configmap-5014/pod-configmaps-8bf7135d-4a72-11e9-af5d-a08cfde32bdd is bound successfully on node e2e-test-peterhornyack-windows-node-group-7n03, 5 nodes evaluated, 2 nodes were found feasible
I0319 18:12:30.118149       1 wrap.go:47] GET /healthz: (158.148µs) 200 [kube-probe/1.15+ 127.0.0.1:40830]
I0319 18:12:40.118704       1 wrap.go:47] GET /healthz: (78.727µs) 200 [kube-probe/1.15+ 127.0.0.1:40878]
I0319 18:12:49.588075       1 scheduling_queue.go:908] About to try and schedule pod configmap-1441/pod-configmaps-9ad3e5d4-4a72-11e9-af5d-a08cfde32bdd
I0319 18:12:49.588106       1 scheduler.go:453] Attempting to schedule pod: configmap-1441/pod-configmaps-9ad3e5d4-4a72-11e9-af5d-a08cfde32bdd
I0319 18:12:49.588973       1 scheduler_binder.go:269] AssumePodVolumes for pod "configmap-1441/pod-configmaps-9ad3e5d4-4a72-11e9-af5d-a08cfde32bdd", node "e2e-test-peterhornyack-windows-node-group-dp2r"
I0319 18:12:49.588998       1 scheduler_binder.go:279] AssumePodVolumes for pod "configmap-1441/pod-configmaps-9ad3e5d4-4a72-11e9-af5d-a08cfde32bdd", node "e2e-test-peterhornyack-windows-node-group-dp2r": all PVCs bound and nothing to do
I0319 18:12:49.589081       1 factory.go:733] Attempting to bind pod-configmaps-9ad3e5d4-4a72-11e9-af5d-a08cfde32bdd to e2e-test-peterhornyack-windows-node-group-dp2r
I0319 18:12:49.598381       1 scheduler.go:572] pod configmap-1441/pod-configmaps-9ad3e5d4-4a72-11e9-af5d-a08cfde32bdd is bound successfully on node e2e-test-peterhornyack-windows-node-group-dp2r, 5 nodes evaluated, 2 nodes were found feasible
I0319 18:12:50.118499       1 wrap.go:47] GET /healthz: (79.204µs) 200 [kube-probe/1.15+ 127.0.0.1:40910]
I0319 18:13:00.118126       1 wrap.go:47] GET /healthz: (94.314µs) 200 [kube-probe/1.15+ 127.0.0.1:40944]
I0319 18:13:10.118149       1 wrap.go:47] GET /healthz: (79.882µs) 200 [kube-probe/1.15+ 127.0.0.1:40984]
I0319 18:13:10.484442       1 scheduling_queue.go:908] About to try and schedule pod kubectl-6411/update-demo-nautilus-b7lnp
I0319 18:13:10.484487       1 scheduler.go:453] Attempting to schedule pod: kubectl-6411/update-demo-nautilus-b7lnp
I0319 18:13:10.486271       1 scheduler_binder.go:269] AssumePodVolumes for pod "kubectl-6411/update-demo-nautilus-b7lnp", node "e2e-test-peterhornyack-windows-node-group-7n03"
I0319 18:13:10.486301       1 scheduler_binder.go:279] AssumePodVolumes for pod "kubectl-6411/update-demo-nautilus-b7lnp", node "e2e-test-peterhornyack-windows-node-group-7n03": all PVCs bound and nothing to do
I0319 18:13:10.486379       1 factory.go:733] Attempting to bind update-demo-nautilus-b7lnp to e2e-test-peterhornyack-windows-node-group-7n03
I0319 18:13:10.500241       1 scheduler.go:572] pod kubectl-6411/update-demo-nautilus-b7lnp is bound successfully on node e2e-test-peterhornyack-windows-node-group-7n03, 5 nodes evaluated, 2 nodes were found feasible
I0319 18:13:10.512616       1 scheduling_queue.go:908] About to try and schedule pod kubectl-6411/update-demo-nautilus-jc4fc
I0319 18:13:10.512650       1 scheduler.go:453] Attempting to schedule pod: kubectl-6411/update-demo-nautilus-jc4fc
I0319 18:13:10.512937       1 scheduler_binder.go:269] AssumePodVolumes for pod "kubectl-6411/update-demo-nautilus-jc4fc", node "e2e-test-peterhornyack-windows-node-group-dp2r"
I0319 18:13:10.512952       1 scheduler_binder.go:279] AssumePodVolumes for pod "kubectl-6411/update-demo-nautilus-jc4fc", node "e2e-test-peterhornyack-windows-node-group-dp2r": all PVCs bound and nothing to do
I0319 18:13:10.512992       1 factory.go:733] Attempting to bind update-demo-nautilus-jc4fc to e2e-test-peterhornyack-windows-node-group-dp2r
I0319 18:13:10.553549       1 scheduler.go:572] pod kubectl-6411/update-demo-nautilus-jc4fc is bound successfully on node e2e-test-peterhornyack-windows-node-group-dp2r, 5 nodes evaluated, 2 nodes were found feasible
I0319 18:13:20.117965       1 wrap.go:47] GET /healthz: (81.89µs) 200 [kube-probe/1.15+ 127.0.0.1:41016]
I0319 18:13:30.118307       1 wrap.go:47] GET /healthz: (75.262µs) 200 [kube-probe/1.15+ 127.0.0.1:41054]
I0319 18:13:37.126221       1 reflector.go:370] k8s.io/client-go/informers/factory.go:133: Watch close - *v1beta1.PodDisruptionBudget total 0 items received
I0319 18:13:39.574386       1 scheduling_queue.go:908] About to try and schedule pod downward-api-8099/downwardapi-volume-b89ef619-4a72-11e9-af5d-a08cfde32bdd
I0319 18:13:39.574443       1 scheduler.go:453] Attempting to schedule pod: downward-api-8099/downwardapi-volume-b89ef619-4a72-11e9-af5d-a08cfde32bdd
I0319 18:13:39.577605       1 scheduler_binder.go:269] AssumePodVolumes for pod "downward-api-8099/downwardapi-volume-b89ef619-4a72-11e9-af5d-a08cfde32bdd", node "e2e-test-peterhornyack-windows-node-group-7n03"
I0319 18:13:39.577664       1 scheduler_binder.go:279] AssumePodVolumes for pod "downward-api-8099/downwardapi-volume-b89ef619-4a72-11e9-af5d-a08cfde32bdd", node "e2e-test-peterhornyack-windows-node-group-7n03": all PVCs bound and nothing to do
I0319 18:13:39.577753       1 factory.go:733] Attempting to bind downwardapi-volume-b89ef619-4a72-11e9-af5d-a08cfde32bdd to e2e-test-peterhornyack-windows-node-group-7n03
I0319 18:13:39.587228       1 scheduler.go:572] pod downward-api-8099/downwardapi-volume-b89ef619-4a72-11e9-af5d-a08cfde32bdd is bound successfully on node e2e-test-peterhornyack-windows-node-group-7n03, 5 nodes evaluated, 2 nodes were found feasible
I0319 18:13:40.118191       1 wrap.go:47] GET /healthz: (73.296µs) 200 [kube-probe/1.15+ 127.0.0.1:41104]
I0319 18:13:50.117634       1 wrap.go:47] GET /healthz: (85.058µs) 200 [kube-probe/1.15+ 127.0.0.1:41138]
I0319 18:13:56.051401       1 scheduling_queue.go:908] About to try and schedule pod container-probe-3633/liveness-exec
I0319 18:13:56.051432       1 scheduler.go:453] Attempting to schedule pod: container-probe-3633/liveness-exec
I0319 18:13:56.051826       1 scheduler_binder.go:269] AssumePodVolumes for pod "container-probe-3633/liveness-exec", node "e2e-test-peterhornyack-windows-node-group-dp2r"
I0319 18:13:56.051844       1 scheduler_binder.go:279] AssumePodVolumes for pod "container-probe-3633/liveness-exec", node "e2e-test-peterhornyack-windows-node-group-dp2r": all PVCs bound and nothing to do
I0319 18:13:56.051908       1 factory.go:733] Attempting to bind liveness-exec to e2e-test-peterhornyack-windows-node-group-dp2r
I0319 18:13:56.061746       1 scheduler.go:572] pod container-probe-3633/liveness-exec is bound successfully on node e2e-test-peterhornyack-windows-node-group-dp2r, 5 nodes evaluated, 2 nodes were found feasible
I0319 18:14:00.117805       1 wrap.go:47] GET /healthz: (73.862µs) 200 [kube-probe/1.15+ 127.0.0.1:41172]
I0319 18:14:10.118309       1 wrap.go:47] GET /healthz: (86.526µs) 200 [kube-probe/1.15+ 127.0.0.1:41210]
I0319 18:14:20.118175       1 wrap.go:47] GET /healthz: (150.15µs) 200 [kube-probe/1.15+ 127.0.0.1:41242]
I0319 18:14:30.118298       1 wrap.go:47] GET /healthz: (80.189µs) 200 [kube-probe/1.15+ 127.0.0.1:41276]
I0319 18:14:38.868226       1 scheduling_queue.go:908] About to try and schedule pod projected-7742/downwardapi-volume-dbf5f4dd-4a72-11e9-af5d-a08cfde32bdd
I0319 18:14:38.868259       1 scheduler.go:453] Attempting to schedule pod: projected-7742/downwardapi-volume-dbf5f4dd-4a72-11e9-af5d-a08cfde32bdd
I0319 18:14:38.868627       1 scheduler_binder.go:269] AssumePodVolumes for pod "projected-7742/downwardapi-volume-dbf5f4dd-4a72-11e9-af5d-a08cfde32bdd", node "e2e-test-peterhornyack-windows-node-group-7n03"
I0319 18:14:38.868645       1 scheduler_binder.go:279] AssumePodVolumes for pod "projected-7742/downwardapi-volume-dbf5f4dd-4a72-11e9-af5d-a08cfde32bdd", node "e2e-test-peterhornyack-windows-node-group-7n03": all PVCs bound and nothing to do
I0319 18:14:38.868708       1 factory.go:733] Attempting to bind downwardapi-volume-dbf5f4dd-4a72-11e9-af5d-a08cfde32bdd to e2e-test-peterhornyack-windows-node-group-7n03
I0319 18:14:38.876941       1 scheduler.go:572] pod projected-7742/downwardapi-volume-dbf5f4dd-4a72-11e9-af5d-a08cfde32bdd is bound successfully on node e2e-test-peterhornyack-windows-node-group-7n03, 5 nodes evaluated, 2 nodes were found feasible
I0319 18:14:40.118057       1 wrap.go:47] GET /healthz: (75.329µs) 200 [kube-probe/1.15+ 127.0.0.1:41324]
I0319 18:14:50.118976       1 wrap.go:47] GET /healthz: (64.388µs) 200 [kube-probe/1.15+ 127.0.0.1:41358]
I0319 18:14:55.882429       1 scheduling_queue.go:908] About to try and schedule pod aggregator-6384/sample-apiserver-deployment-5fd6fbfc47-rtnch
I0319 18:14:55.882479       1 scheduler.go:453] Attempting to schedule pod: aggregator-6384/sample-apiserver-deployment-5fd6fbfc47-rtnch
I0319 18:14:55.884658       1 scheduler_binder.go:269] AssumePodVolumes for pod "aggregator-6384/sample-apiserver-deployment-5fd6fbfc47-rtnch", node "e2e-test-peterhornyack-windows-node-group-dp2r"
I0319 18:14:55.884702       1 scheduler_binder.go:279] AssumePodVolumes for pod "aggregator-6384/sample-apiserver-deployment-5fd6fbfc47-rtnch", node "e2e-test-peterhornyack-windows-node-group-dp2r": all PVCs bound and nothing to do
I0319 18:14:55.884765       1 factory.go:733] Attempting to bind sample-apiserver-deployment-5fd6fbfc47-rtnch to e2e-test-peterhornyack-windows-node-group-dp2r
I0319 18:14:55.913294       1 scheduler.go:572] pod aggregator-6384/sample-apiserver-deployment-5fd6fbfc47-rtnch is bound successfully on node e2e-test-peterhornyack-windows-node-group-dp2r, 5 nodes evaluated, 2 nodes were found feasible
I0319 18:15:00.117977       1 wrap.go:47] GET /healthz: (77.306µs) 200 [kube-probe/1.15+ 127.0.0.1:41394]
I0319 18:15:03.139269       1 reflector.go:370] k8s.io/client-go/informers/factory.go:133: Watch close - *v1.ReplicationController total 44 items received
I0319 18:15:10.118015       1 wrap.go:47] GET /healthz: (70.002µs) 200 [kube-probe/1.15+ 127.0.0.1:41434]
I0319 18:15:20.117785       1 wrap.go:47] GET /healthz: (76.177µs) 200 [kube-probe/1.15+ 127.0.0.1:41470]
I0319 18:15:30.117958       1 wrap.go:47] GET /healthz: (77.297µs) 200 [kube-probe/1.15+ 127.0.0.1:41504]
I0319 18:15:30.355376       1 scheduling_queue.go:908] About to try and schedule pod containers-7022/client-containers-faa6f87f-4a72-11e9-af5d-a08cfde32bdd
I0319 18:15:30.355412       1 scheduler.go:453] Attempting to schedule pod: containers-7022/client-containers-faa6f87f-4a72-11e9-af5d-a08cfde32bdd
I0319 18:15:30.356071       1 scheduler_binder.go:269] AssumePodVolumes for pod "containers-7022/client-containers-faa6f87f-4a72-11e9-af5d-a08cfde32bdd", node "e2e-test-peterhornyack-windows-node-group-dp2r"
I0319 18:15:30.356112       1 scheduler_binder.go:279] AssumePodVolumes for pod "containers-7022/client-containers-faa6f87f-4a72-11e9-af5d-a08cfde32bdd", node "e2e-test-peterhornyack-windows-node-group-dp2r": all PVCs bound and nothing to do
I0319 18:15:30.356159       1 factory.go:733] Attempting to bind client-containers-faa6f87f-4a72-11e9-af5d-a08cfde32bdd to e2e-test-peterhornyack-windows-node-group-dp2r
I0319 18:15:30.364538       1 scheduler.go:572] pod containers-7022/client-containers-faa6f87f-4a72-11e9-af5d-a08cfde32bdd is bound successfully on node e2e-test-peterhornyack-windows-node-group-dp2r, 5 nodes evaluated, 2 nodes were found feasible
I0319 18:15:40.118220       1 wrap.go:47] GET /healthz: (77.938µs) 200 [kube-probe/1.15+ 127.0.0.1:41552]
I0319 18:15:50.118104       1 wrap.go:47] GET /healthz: (117.947µs) 200 [kube-probe/1.15+ 127.0.0.1:41584]
I0319 18:15:50.942476       1 scheduling_queue.go:908] About to try and schedule pod pods-7650/pod-submit-remove-06e584c6-4a73-11e9-af5d-a08cfde32bdd
I0319 18:15:50.942524       1 scheduler.go:453] Attempting to schedule pod: pods-7650/pod-submit-remove-06e584c6-4a73-11e9-af5d-a08cfde32bdd
I0319 18:15:50.943101       1 scheduler_binder.go:269] AssumePodVolumes for pod "pods-7650/pod-submit-remove-06e584c6-4a73-11e9-af5d-a08cfde32bdd", node "e2e-test-peterhornyack-windows-node-group-dp2r"
I0319 18:15:50.943150       1 scheduler_binder.go:279] AssumePodVolumes for pod "pods-7650/pod-submit-remove-06e584c6-4a73-11e9-af5d-a08cfde32bdd", node "e2e-test-peterhornyack-windows-node-group-dp2r": all PVCs bound and nothing to do
I0319 18:15:50.943213       1 factory.go:733] Attempting to bind pod-submit-remove-06e584c6-4a73-11e9-af5d-a08cfde32bdd to e2e-test-peterhornyack-windows-node-group-dp2r
I0319 18:15:50.951490       1 scheduler.go:572] pod pods-7650/pod-submit-remove-06e584c6-4a73-11e9-af5d-a08cfde32bdd is bound successfully on node e2e-test-peterhornyack-windows-node-group-dp2r, 5 nodes evaluated, 2 nodes were found feasible
I0319 18:16:00.117844       1 wrap.go:47] GET /healthz: (84.369µs) 200 [kube-probe/1.15+ 127.0.0.1:41618]
I0319 18:16:05.131326       1 reflector.go:370] k8s.io/client-go/informers/factory.go:133: Watch close - *v1.Service total 4 items received
I0319 18:16:06.111648       1 reflector.go:370] k8s.io/client-go/informers/factory.go:133: Watch close - *v1.PersistentVolumeClaim total 0 items received
I0319 18:16:10.117775       1 wrap.go:47] GET /healthz: (78.889µs) 200 [kube-probe/1.15+ 127.0.0.1:41658]
I0319 18:16:18.521998       1 scheduling_queue.go:908] About to try and schedule pod pod-network-test-1422/netserver-0
I0319 18:16:18.522066       1 scheduler.go:453] Attempting to schedule pod: pod-network-test-1422/netserver-0
I0319 18:16:18.522433       1 scheduler_binder.go:269] AssumePodVolumes for pod "pod-network-test-1422/netserver-0", node "e2e-test-peterhornyack-windows-node-group-7n03"
I0319 18:16:18.522451       1 scheduler_binder.go:279] AssumePodVolumes for pod "pod-network-test-1422/netserver-0", node "e2e-test-peterhornyack-windows-node-group-7n03": all PVCs bound and nothing to do
I0319 18:16:18.522500       1 factory.go:733] Attempting to bind netserver-0 to e2e-test-peterhornyack-windows-node-group-7n03
I0319 18:16:18.522913       1 cache.go:643] Couldn't expire cache for pod pod-network-test-1422/netserver-0. Binding is still in progress.
I0319 18:16:18.531298       1 scheduler.go:572] pod pod-network-test-1422/netserver-0 is bound successfully on node e2e-test-peterhornyack-windows-node-group-7n03, 5 nodes evaluated, 1 nodes were found feasible
I0319 18:16:18.572708       1 scheduling_queue.go:908] About to try and schedule pod pod-network-test-1422/netserver-1
I0319 18:16:18.572743       1 scheduler.go:453] Attempting to schedule pod: pod-network-test-1422/netserver-1
I0319 18:16:18.572988       1 scheduler_binder.go:269] AssumePodVolumes for pod "pod-network-test-1422/netserver-1", node "e2e-test-peterhornyack-windows-node-group-dp2r"
I0319 18:16:18.573016       1 scheduler_binder.go:279] AssumePodVolumes for pod "pod-network-test-1422/netserver-1", node "e2e-test-peterhornyack-windows-node-group-dp2r": all PVCs bound and nothing to do
I0319 18:16:18.573076       1 factory.go:733] Attempting to bind netserver-1 to e2e-test-peterhornyack-windows-node-group-dp2r
I0319 18:16:18.582166       1 scheduler.go:572] pod pod-network-test-1422/netserver-1 is bound successfully on node e2e-test-peterhornyack-windows-node-group-dp2r, 5 nodes evaluated, 1 nodes were found feasible
I0319 18:16:20.117771       1 wrap.go:47] GET /healthz: (77.556µs) 200 [kube-probe/1.15+ 127.0.0.1:41690]
I0319 18:16:23.099436       1 reflector.go:370] k8s.io/client-go/informers/factory.go:133: Watch close - *v1.ReplicaSet total 5 items received
I0319 18:16:30.118541       1 wrap.go:47] GET /healthz: (71.672µs) 200 [kube-probe/1.15+ 127.0.0.1:41724]
I0319 18:16:40.118507       1 wrap.go:47] GET /healthz: (74.315µs) 200 [kube-probe/1.15+ 127.0.0.1:41774]
I0319 18:16:42.871448       1 scheduling_queue.go:908] About to try and schedule pod pod-network-test-1422/test-container-pod
I0319 18:16:42.871498       1 scheduler.go:453] Attempting to schedule pod: pod-network-test-1422/test-container-pod
I0319 18:16:42.873279       1 scheduler_binder.go:269] AssumePodVolumes for pod "pod-network-test-1422/test-container-pod", node "e2e-test-peterhornyack-windows-node-group-7n03"
I0319 18:16:42.873323       1 scheduler_binder.go:279] AssumePodVolumes for pod "pod-network-test-1422/test-container-pod", node "e2e-test-peterhornyack-windows-node-group-7n03": all PVCs bound and nothing to do
I0319 18:16:42.873375       1 factory.go:733] Attempting to bind test-container-pod to e2e-test-peterhornyack-windows-node-group-7n03
I0319 18:16:42.881229       1 scheduler.go:572] pod pod-network-test-1422/test-container-pod is bound successfully on node e2e-test-peterhornyack-windows-node-group-7n03, 5 nodes evaluated, 2 nodes were found feasible
I0319 18:16:42.921055       1 scheduling_queue.go:908] About to try and schedule pod pod-network-test-1422/host-test-container-pod
I0319 18:16:42.921097       1 scheduler.go:453] Attempting to schedule pod: pod-network-test-1422/host-test-container-pod
I0319 18:16:42.921377       1 scheduler_binder.go:269] AssumePodVolumes for pod "pod-network-test-1422/host-test-container-pod", node "e2e-test-peterhornyack-windows-node-group-7n03"
I0319 18:16:42.921392       1 scheduler_binder.go:279] AssumePodVolumes for pod "pod-network-test-1422/host-test-container-pod", node "e2e-test-peterhornyack-windows-node-group-7n03": all PVCs bound and nothing to do
I0319 18:16:42.921442       1 factory.go:733] Attempting to bind host-test-container-pod to e2e-test-peterhornyack-windows-node-group-7n03
I0319 18:16:42.931261       1 scheduler.go:572] pod pod-network-test-1422/host-test-container-pod is bound successfully on node e2e-test-peterhornyack-windows-node-group-7n03, 5 nodes evaluated, 2 nodes were found feasible
I0319 18:16:50.118256       1 wrap.go:47] GET /healthz: (75.176µs) 200 [kube-probe/1.15+ 127.0.0.1:41806]
I0319 18:16:58.069249       1 reflector.go:370] k8s.io/client-go/informers/factory.go:133: Watch close - *v1.StatefulSet total 0 items received
I0319 18:17:00.118131       1 wrap.go:47] GET /healthz: (127.148µs) 200 [kube-probe/1.15+ 127.0.0.1:41844]
I0319 18:17:10.117877       1 wrap.go:47] GET /healthz: (73.225µs) 200 [kube-probe/1.15+ 127.0.0.1:41882]
I0319 18:17:15.074213       1 reflector.go:370] k8s.io/client-go/informers/factory.go:133: Watch close - *v1.PersistentVolume total 0 items received
I0319 18:17:18.621275       1 scheduling_queue.go:908] About to try and schedule pod gc-7549/simpletest.rc-xmxsk
I0319 18:17:18.621336       1 scheduler.go:453] Attempting to schedule pod: gc-7549/simpletest.rc-xmxsk
I0319 18:17:18.621689       1 scheduler_binder.go:269] AssumePodVolumes for pod "gc-7549/simpletest.rc-xmxsk", node "e2e-test-peterhornyack-windows-node-group-7n03"
I0319 18:17:18.621705       1 scheduler_binder.go:279] AssumePodVolumes for pod "gc-7549/simpletest.rc-xmxsk", node "e2e-test-peterhornyack-windows-node-group-7n03": all PVCs bound and nothing to do
I0319 18:17:18.623249       1 factory.go:733] Attempting to bind simpletest.rc-xmxsk to e2e-test-peterhornyack-windows-node-group-7n03
I0319 18:17:18.636415       1 scheduling_queue.go:908] About to try and schedule pod gc-7549/simpletest.rc-8z5j6
I0319 18:17:18.636449       1 scheduler.go:453] Attempting to schedule pod: gc-7549/simpletest.rc-8z5j6
I0319 18:17:18.636726       1 scheduler_binder.go:269] AssumePodVolumes for pod "gc-7549/simpletest.rc-8z5j6", node "e2e-test-peterhornyack-windows-node-group-dp2r"
I0319 18:17:18.636742       1 scheduler_binder.go:279] AssumePodVolumes for pod "gc-7549/simpletest.rc-8z5j6", node "e2e-test-peterhornyack-windows-node-group-dp2r": all PVCs bound and nothing to do
I0319 18:17:18.636791       1 factory.go:733] Attempting to bind simpletest.rc-8z5j6 to e2e-test-peterhornyack-windows-node-group-dp2r
I0319 18:17:18.649867       1 scheduler.go:572] pod gc-7549/simpletest.rc-xmxsk is bound successfully on node e2e-test-peterhornyack-windows-node-group-7n03, 5 nodes evaluated, 2 nodes were found feasible
I0319 18:17:18.677736       1 scheduler.go:572] pod gc-7549/simpletest.rc-8z5j6 is bound successfully on node e2e-test-peterhornyack-windows-node-group-dp2r, 5 nodes evaluated, 2 nodes were found feasible
I0319 18:17:20.117898       1 wrap.go:47] GET /healthz: (76.041µs) 200 [kube-probe/1.15+ 127.0.0.1:41916]
I0319 18:17:30.118127       1 wrap.go:47] GET /healthz: (111.571µs) 200 [kube-probe/1.15+ 127.0.0.1:41950]
I0319 18:17:33.070016       1 reflector.go:370] k8s.io/kubernetes/cmd/kube-scheduler/app/server.go:223: Watch close - *v1.Pod total 167 items received
I0319 18:17:37.144096       1 scheduling_queue.go:908] About to try and schedule pod kubectl-5730/e2e-test-nginx-rc-8qwl6
I0319 18:17:37.144150       1 scheduler.go:453] Attempting to schedule pod: kubectl-5730/e2e-test-nginx-rc-8qwl6
I0319 18:17:37.145593       1 scheduler_binder.go:269] AssumePodVolumes for pod "kubectl-5730/e2e-test-nginx-rc-8qwl6", node "e2e-test-peterhornyack-windows-node-group-7n03"
I0319 18:17:37.145619       1 scheduler_binder.go:279] AssumePodVolumes for pod "kubectl-5730/e2e-test-nginx-rc-8qwl6", node "e2e-test-peterhornyack-windows-node-group-7n03": all PVCs bound and nothing to do
I0319 18:17:37.148148       1 factory.go:733] Attempting to bind e2e-test-nginx-rc-8qwl6 to e2e-test-peterhornyack-windows-node-group-7n03
I0319 18:17:37.163237       1 scheduler.go:572] pod kubectl-5730/e2e-test-nginx-rc-8qwl6 is bound successfully on node e2e-test-peterhornyack-windows-node-group-7n03, 5 nodes evaluated, 2 nodes were found feasible
I0319 18:17:40.118379       1 wrap.go:47] GET /healthz: (69.387µs) 200 [kube-probe/1.15+ 127.0.0.1:41998]
I0319 18:17:50.118303       1 wrap.go:47] GET /healthz: (80.933µs) 200 [kube-probe/1.15+ 127.0.0.1:42030]
I0319 18:18:00.117950       1 wrap.go:47] GET /healthz: (85.262µs) 200 [kube-probe/1.15+ 127.0.0.1:42066]
I0319 18:18:02.107328       1 reflector.go:370] k8s.io/client-go/informers/factory.go:133: Watch close - *v1.Node total 47 items received
I0319 18:18:10.118335       1 wrap.go:47] GET /healthz: (92.477µs) 200 [kube-probe/1.15+ 127.0.0.1:42104]
I0319 18:18:10.129380       1 scheduling_queue.go:908] About to try and schedule pod var-expansion-2125/var-expansion-59e296d1-4a73-11e9-af5d-a08cfde32bdd
I0319 18:18:10.129444       1 scheduler.go:453] Attempting to schedule pod: var-expansion-2125/var-expansion-59e296d1-4a73-11e9-af5d-a08cfde32bdd
I0319 18:18:10.129931       1 scheduler_binder.go:269] AssumePodVolumes for pod "var-expansion-2125/var-expansion-59e296d1-4a73-11e9-af5d-a08cfde32bdd", node "e2e-test-peterhornyack-windows-node-group-dp2r"
I0319 18:18:10.129972       1 scheduler_binder.go:279] AssumePodVolumes for pod "var-expansion-2125/var-expansion-59e296d1-4a73-11e9-af5d-a08cfde32bdd", node "e2e-test-peterhornyack-windows-node-group-dp2r": all PVCs bound and nothing to do
I0319 18:18:10.130037       1 factory.go:733] Attempting to bind var-expansion-59e296d1-4a73-11e9-af5d-a08cfde32bdd to e2e-test-peterhornyack-windows-node-group-dp2r
I0319 18:18:10.144455       1 scheduler.go:572] pod var-expansion-2125/var-expansion-59e296d1-4a73-11e9-af5d-a08cfde32bdd is bound successfully on node e2e-test-peterhornyack-windows-node-group-dp2r, 5 nodes evaluated, 2 nodes were found feasible
I0319 18:18:20.118113       1 wrap.go:47] GET /healthz: (97.445µs) 200 [kube-probe/1.15+ 127.0.0.1:42136]
I0319 18:18:26.600353       1 scheduling_queue.go:908] About to try and schedule pod init-container-3055/pod-init-63b43de6-4a73-11e9-af5d-a08cfde32bdd
I0319 18:18:26.602108       1 scheduler.go:453] Attempting to schedule pod: init-container-3055/pod-init-63b43de6-4a73-11e9-af5d-a08cfde32bdd
I0319 18:18:26.602620       1 scheduler_binder.go:269] AssumePodVolumes for pod "init-container-3055/pod-init-63b43de6-4a73-11e9-af5d-a08cfde32bdd", node "e2e-test-peterhornyack-windows-node-group-7n03"
I0319 18:18:26.602639       1 scheduler_binder.go:279] AssumePodVolumes for pod "init-container-3055/pod-init-63b43de6-4a73-11e9-af5d-a08cfde32bdd", node "e2e-test-peterhornyack-windows-node-group-7n03": all PVCs bound and nothing to do
I0319 18:18:26.604803       1 factory.go:733] Attempting to bind pod-init-63b43de6-4a73-11e9-af5d-a08cfde32bdd to e2e-test-peterhornyack-windows-node-group-7n03
I0319 18:18:26.613847       1 scheduler.go:572] pod init-container-3055/pod-init-63b43de6-4a73-11e9-af5d-a08cfde32bdd is bound successfully on node e2e-test-peterhornyack-windows-node-group-7n03, 5 nodes evaluated, 2 nodes were found feasible
I0319 18:18:30.117957       1 wrap.go:47] GET /healthz: (78.322µs) 200 [kube-probe/1.15+ 127.0.0.1:42172]
I0319 18:18:40.118159       1 wrap.go:47] GET /healthz: (81.611µs) 200 [kube-probe/1.15+ 127.0.0.1:42220]
I0319 18:18:50.118192       1 wrap.go:47] GET /healthz: (80.868µs) 200 [kube-probe/1.15+ 127.0.0.1:42252]
I0319 18:19:00.117880       1 wrap.go:47] GET /healthz: (86.138µs) 200 [kube-probe/1.15+ 127.0.0.1:42286]
I0319 18:19:10.118116       1 wrap.go:47] GET /healthz: (88.923µs) 200 [kube-probe/1.15+ 127.0.0.1:42324]
I0319 18:19:20.117952       1 wrap.go:47] GET /healthz: (81.914µs) 200 [kube-probe/1.15+ 127.0.0.1:42358]
I0319 18:19:26.117862       1 reflector.go:370] k8s.io/client-go/informers/factory.go:133: Watch close - *v1.StorageClass total 0 items received
I0319 18:19:30.117822       1 wrap.go:47] GET /healthz: (83.97µs) 200 [kube-probe/1.15+ 127.0.0.1:42392]
I0319 18:19:40.117966       1 wrap.go:47] GET /healthz: (75.816µs) 200 [kube-probe/1.15+ 127.0.0.1:42440]
I0319 18:19:50.118189       1 wrap.go:47] GET /healthz: (83.525µs) 200 [kube-probe/1.15+ 127.0.0.1:42474]
I0319 18:20:00.117751       1 wrap.go:47] GET /healthz: (67.425µs) 200 [kube-probe/1.15+ 127.0.0.1:42508]
I0319 18:20:10.117894       1 wrap.go:47] GET /healthz: (76.319µs) 200 [kube-probe/1.15+ 127.0.0.1:42546]
I0319 18:20:20.117876       1 wrap.go:47] GET /healthz: (73.847µs) 200 [kube-probe/1.15+ 127.0.0.1:42578]
I0319 18:20:30.118943       1 wrap.go:47] GET /healthz: (75.012µs) 200 [kube-probe/1.15+ 127.0.0.1:42612]
I0319 18:20:40.117861       1 wrap.go:47] GET /healthz: (78.675µs) 200 [kube-probe/1.15+ 127.0.0.1:42660]
I0319 18:20:50.117763       1 wrap.go:47] GET /healthz: (72.205µs) 200 [kube-probe/1.15+ 127.0.0.1:42694]
I0319 18:21:00.117846       1 wrap.go:47] GET /healthz: (58.955µs) 200 [kube-probe/1.15+ 127.0.0.1:42730]
I0319 18:21:08.132376       1 reflector.go:370] k8s.io/client-go/informers/factory.go:133: Watch close - *v1beta1.PodDisruptionBudget total 0 items received
I0319 18:21:10.118223       1 wrap.go:47] GET /healthz: (78.218µs) 200 [kube-probe/1.15+ 127.0.0.1:42768]
I0319 18:21:20.118001       1 wrap.go:47] GET /healthz: (71.915µs) 200 [kube-probe/1.15+ 127.0.0.1:42800]
I0319 18:21:30.118151       1 wrap.go:47] GET /healthz: (72.156µs) 200 [kube-probe/1.15+ 127.0.0.1:42834]
I0319 18:21:40.119062       1 wrap.go:47] GET /healthz: (86.119µs) 200 [kube-probe/1.15+ 127.0.0.1:42882]
I0319 18:21:50.118777       1 wrap.go:47] GET /healthz: (67.774µs) 200 [kube-probe/1.15+ 127.0.0.1:42914]
I0319 18:22:00.119378       1 wrap.go:47] GET /healthz: (81.229µs) 200 [kube-probe/1.15+ 127.0.0.1:42948]
I0319 18:22:10.103205       1 reflector.go:370] k8s.io/client-go/informers/factory.go:133: Watch close - *v1.ReplicaSet total 0 items received
I0319 18:22:10.118100       1 wrap.go:47] GET /healthz: (93.483µs) 200 [kube-probe/1.15+ 127.0.0.1:42990]
I0319 18:22:13.115208       1 reflector.go:370] k8s.io/client-go/informers/factory.go:133: Watch close - *v1.PersistentVolumeClaim total 0 items received
I0319 18:22:20.117833       1 wrap.go:47] GET /healthz: (71.508µs) 200 [kube-probe/1.15+ 127.0.0.1:43022]
I0319 18:22:30.118083       1 wrap.go:47] GET /healthz: (85.589µs) 200 [kube-probe/1.15+ 127.0.0.1:43056]
I0319 18:22:40.117613       1 wrap.go:47] GET /healthz: (89.88µs) 200 [kube-probe/1.15+ 127.0.0.1:43104]
I0319 18:22:50.119141       1 wrap.go:47] GET /healthz: (76.75µs) 200 [kube-probe/1.15+ 127.0.0.1:43136]
I0319 18:22:54.072334       1 reflector.go:370] k8s.io/client-go/informers/factory.go:133: Watch close - *v1.StatefulSet total 0 items received
I0319 18:23:00.119383       1 wrap.go:47] GET /healthz: (76.623µs) 200 [kube-probe/1.15+ 127.0.0.1:43170]
I0319 18:23:10.117985       1 wrap.go:47] GET /healthz: (69.405µs) 200 [kube-probe/1.15+ 127.0.0.1:43208]
I0319 18:23:20.117780       1 wrap.go:47] GET /healthz: (80.058µs) 200 [kube-probe/1.15+ 127.0.0.1:43240]
I0319 18:23:30.119417       1 wrap.go:47] GET /healthz: (110.382µs) 200 [kube-probe/1.15+ 127.0.0.1:43284]
I0319 18:23:40.118181       1 wrap.go:47] GET /healthz: (73.475µs) 200 [kube-probe/1.15+ 127.0.0.1:43332]
I0319 18:23:43.110706       1 reflector.go:370] k8s.io/client-go/informers/factory.go:133: Watch close - *v1.Node total 40 items received
I0319 18:23:50.118167       1 wrap.go:47] GET /healthz: (134.724µs) 200 [kube-probe/1.15+ 127.0.0.1:43364]
I0319 18:23:52.347164       1 scheduling_queue.go:908] About to try and schedule pod gc-5640/pod1
I0319 18:23:52.347218       1 scheduler.go:453] Attempting to schedule pod: gc-5640/pod1
I0319 18:23:52.349261       1 scheduler_binder.go:269] AssumePodVolumes for pod "gc-5640/pod1", node "e2e-test-peterhornyack-windows-node-group-dp2r"
I0319 18:23:52.349303       1 scheduler_binder.go:279] AssumePodVolumes for pod "gc-5640/pod1", node "e2e-test-peterhornyack-windows-node-group-dp2r": all PVCs bound and nothing to do
I0319 18:23:52.349357       1 factory.go:733] Attempting to bind pod1 to e2e-test-peterhornyack-windows-node-group-dp2r
I0319 18:23:52.360056       1 scheduler.go:572] pod gc-5640/pod1 is bound successfully on node e2e-test-peterhornyack-windows-node-group-dp2r, 5 nodes evaluated, 2 nodes were found feasible
I0319 18:23:52.393773       1 scheduling_queue.go:908] About to try and schedule pod gc-5640/pod2
I0319 18:23:52.393808       1 scheduler.go:453] Attempting to schedule pod: gc-5640/pod2
I0319 18:23:52.394131       1 scheduler_binder.go:269] AssumePodVolumes for pod "gc-5640/pod2", node "e2e-test-peterhornyack-windows-node-group-7n03"
I0319 18:23:52.394149       1 scheduler_binder.go:279] AssumePodVolumes for pod "gc-5640/pod2", node "e2e-test-peterhornyack-windows-node-group-7n03": all PVCs bound and nothing to do
I0319 18:23:52.394185       1 factory.go:733] Attempting to bind pod2 to e2e-test-peterhornyack-windows-node-group-7n03
I0319 18:23:52.402417       1 scheduler.go:572] pod gc-5640/pod2 is bound successfully on node e2e-test-peterhornyack-windows-node-group-7n03, 5 nodes evaluated, 2 nodes were found feasible
I0319 18:23:52.441136       1 scheduling_queue.go:908] About to try and schedule pod gc-5640/pod3
I0319 18:23:52.441166       1 scheduler.go:453] Attempting to schedule pod: gc-5640/pod3
I0319 18:23:52.441480       1 scheduler_binder.go:269] AssumePodVolumes for pod "gc-5640/pod3", node "e2e-test-peterhornyack-windows-node-group-dp2r"
I0319 18:23:52.441494       1 scheduler_binder.go:279] AssumePodVolumes for pod "gc-5640/pod3", node "e2e-test-peterhornyack-windows-node-group-dp2r": all PVCs bound and nothing to do
I0319 18:23:52.441553       1 factory.go:733] Attempting to bind pod3 to e2e-test-peterhornyack-windows-node-group-dp2r
I0319 18:23:52.449871       1 scheduler.go:572] pod gc-5640/pod3 is bound successfully on node e2e-test-peterhornyack-windows-node-group-dp2r, 5 nodes evaluated, 2 nodes were found feasible
I0319 18:24:00.118347       1 wrap.go:47] GET /healthz: (72.49µs) 200 [kube-probe/1.15+ 127.0.0.1:43398]
I0319 18:24:06.392224       1 scheduling_queue.go:908] About to try and schedule pod kubectl-9874/e2e-test-rm-busybox-job-2szxn
I0319 18:24:06.392278       1 scheduler.go:453] Attempting to schedule pod: kubectl-9874/e2e-test-rm-busybox-job-2szxn
I0319 18:24:06.395377       1 scheduler_binder.go:269] AssumePodVolumes for pod "kubectl-9874/e2e-test-rm-busybox-job-2szxn", node "e2e-test-peterhornyack-windows-node-group-7n03"
I0319 18:24:06.395410       1 scheduler_binder.go:279] AssumePodVolumes for pod "kubectl-9874/e2e-test-rm-busybox-job-2szxn", node "e2e-test-peterhornyack-windows-node-group-7n03": all PVCs bound and nothing to do
I0319 18:24:06.397838       1 factory.go:733] Attempting to bind e2e-test-rm-busybox-job-2szxn to e2e-test-peterhornyack-windows-node-group-7n03
I0319 18:24:06.413336       1 scheduler.go:572] pod kubectl-9874/e2e-test-rm-busybox-job-2szxn is bound successfully on node e2e-test-peterhornyack-windows-node-group-7n03, 5 nodes evaluated, 2 nodes were found feasible
I0319 18:24:10.117900       1 wrap.go:47] GET /healthz: (59.885µs) 200 [kube-probe/1.15+ 127.0.0.1:43438]
I0319 18:24:10.141808       1 reflector.go:370] k8s.io/client-go/informers/factory.go:133: Watch close - *v1.ReplicationController total 9 items received
I0319 18:24:17.073281       1 reflector.go:370] k8s.io/kubernetes/cmd/kube-scheduler/app/server.go:223: Watch close - *v1.Pod total 45 items received
I0319 18:24:20.117964       1 wrap.go:47] GET /healthz: (79.044µs) 200 [kube-probe/1.15+ 127.0.0.1:43472]
I0319 18:24:21.134830       1 reflector.go:370] k8s.io/client-go/informers/factory.go:133: Watch close - *v1.Service total 0 items received
I0319 18:24:30.117879       1 wrap.go:47] GET /healthz: (78.639µs) 200 [kube-probe/1.15+ 127.0.0.1:43506]
I0319 18:24:40.118088       1 wrap.go:47] GET /healthz: (103.79µs) 200 [kube-probe/1.15+ 127.0.0.1:43556]
I0319 18:24:42.876948       1 scheduling_queue.go:908] About to try and schedule pod init-container-9374/pod-init-43fadda9-4a74-11e9-af5d-a08cfde32bdd
I0319 18:24:42.876998       1 scheduler.go:453] Attempting to schedule pod: init-container-9374/pod-init-43fadda9-4a74-11e9-af5d-a08cfde32bdd
I0319 18:24:42.879179       1 scheduler_binder.go:269] AssumePodVolumes for pod "init-container-9374/pod-init-43fadda9-4a74-11e9-af5d-a08cfde32bdd", node "e2e-test-peterhornyack-windows-node-group-dp2r"
I0319 18:24:42.879225       1 scheduler_binder.go:279] AssumePodVolumes for pod "init-container-9374/pod-init-43fadda9-4a74-11e9-af5d-a08cfde32bdd", node "e2e-test-peterhornyack-windows-node-group-dp2r": all PVCs bound and nothing to do
I0319 18:24:42.879303       1 factory.go:733] Attempting to bind pod-init-43fadda9-4a74-11e9-af5d-a08cfde32bdd to e2e-test-peterhornyack-windows-node-group-dp2r
I0319 18:24:42.888199       1 scheduler.go:572] pod init-container-9374/pod-init-43fadda9-4a74-11e9-af5d-a08cfde32bdd is bound successfully on node e2e-test-peterhornyack-windows-node-group-dp2r, 5 nodes evaluated, 2 nodes were found feasible
I0319 18:24:50.117910       1 wrap.go:47] GET /healthz: (133.27µs) 200 [kube-probe/1.15+ 127.0.0.1:43588]
I0319 18:24:56.077771       1 reflector.go:370] k8s.io/client-go/informers/factory.go:133: Watch close - *v1.PersistentVolume total 0 items received
I0319 18:25:00.117751       1 wrap.go:47] GET /healthz: (75.093µs) 200 [kube-probe/1.15+ 127.0.0.1:43624]
I0319 18:25:10.118122       1 wrap.go:47] GET /healthz: (90.734µs) 200 [kube-probe/1.15+ 127.0.0.1:43662]
I0319 18:25:20.117938       1 wrap.go:47] GET /healthz: (75.869µs) 200 [kube-probe/1.15+ 127.0.0.1:43694]
I0319 18:25:30.118190       1 wrap.go:47] GET /healthz: (72.157µs) 200 [kube-probe/1.15+ 127.0.0.1:43728]
I0319 18:25:40.118047       1 wrap.go:47] GET /healthz: (70.59µs) 200 [kube-probe/1.15+ 127.0.0.1:43776]
I0319 18:25:50.117863       1 wrap.go:47] GET /healthz: (84.551µs) 200 [kube-probe/1.15+ 127.0.0.1:43810]
I0319 18:26:00.118087       1 wrap.go:47] GET /healthz: (90.955µs) 200 [kube-probe/1.15+ 127.0.0.1:43844]
I0319 18:26:01.642156       1 scheduling_queue.go:908] About to try and schedule pod pods-7900/pod-back-off-image
I0319 18:26:01.642191       1 scheduler.go:453] Attempting to schedule pod: pods-7900/pod-back-off-image
I0319 18:26:01.642596       1 scheduler_binder.go:269] AssumePodVolumes for pod "pods-7900/pod-back-off-image", node "e2e-test-peterhornyack-windows-node-group-7n03"
I0319 18:26:01.642614       1 scheduler_binder.go:279] AssumePodVolumes for pod "pods-7900/pod-back-off-image", node "e2e-test-peterhornyack-windows-node-group-7n03": all PVCs bound and nothing to do
I0319 18:26:01.642677       1 factory.go:733] Attempting to bind pod-back-off-image to e2e-test-peterhornyack-windows-node-group-7n03
I0319 18:26:01.651800       1 scheduler.go:572] pod pods-7900/pod-back-off-image is bound successfully on node e2e-test-peterhornyack-windows-node-group-7n03, 5 nodes evaluated, 2 nodes were found feasible
I0319 18:26:10.117769       1 wrap.go:47] GET /healthz: (79.904µs) 200 [kube-probe/1.15+ 127.0.0.1:43882]
I0319 18:26:20.119189       1 wrap.go:47] GET /healthz: (77.712µs) 200 [kube-probe/1.15+ 127.0.0.1:43916]
I0319 18:26:24.121862       1 reflector.go:370] k8s.io/client-go/informers/factory.go:133: Watch close - *v1.StorageClass total 0 items received
I0319 18:26:30.118098       1 wrap.go:47] GET /healthz: (98.794µs) 200 [kube-probe/1.15+ 127.0.0.1:43950]
I0319 18:26:40.117959       1 wrap.go:47] GET /healthz: (88.39µs) 200 [kube-probe/1.15+ 127.0.0.1:43998]
I0319 18:26:50.117971       1 wrap.go:47] GET /healthz: (71.036µs) 200 [kube-probe/1.15+ 127.0.0.1:44030]
I0319 18:27:00.117958       1 wrap.go:47] GET /healthz: (80.01µs) 200 [kube-probe/1.15+ 127.0.0.1:44066]
I0319 18:27:10.117818       1 wrap.go:47] GET /healthz: (123.772µs) 200 [kube-probe/1.15+ 127.0.0.1:44104]
I0319 18:27:20.118136       1 wrap.go:47] GET /healthz: (106.961µs) 200 [kube-probe/1.15+ 127.0.0.1:44136]
I0319 18:27:30.117842       1 wrap.go:47] GET /healthz: (67.895µs) 200 [kube-probe/1.15+ 127.0.0.1:44170]
I0319 18:27:40.122599       1 wrap.go:47] GET /healthz: (78.923µs) 200 [kube-probe/1.15+ 127.0.0.1:44220]
I0319 18:27:50.117789       1 wrap.go:47] GET /healthz: (70.533µs) 200 [kube-probe/1.15+ 127.0.0.1:44252]
I0319 18:28:00.118290       1 wrap.go:47] GET /healthz: (73.586µs) 200 [kube-probe/1.15+ 127.0.0.1:44286]
I0319 18:28:10.118252       1 wrap.go:47] GET /healthz: (76.384µs) 200 [kube-probe/1.15+ 127.0.0.1:44324]
I0319 18:28:20.118009       1 wrap.go:47] GET /healthz: (76.249µs) 200 [kube-probe/1.15+ 127.0.0.1:44358]
I0319 18:28:23.105746       1 reflector.go:370] k8s.io/client-go/informers/factory.go:133: Watch close - *v1.ReplicaSet total 0 items received
I0319 18:28:30.118418       1 wrap.go:47] GET /healthz: (79.505µs) 200 [kube-probe/1.15+ 127.0.0.1:44392]
I0319 18:28:36.075297       1 reflector.go:370] k8s.io/client-go/informers/factory.go:133: Watch close - *v1.StatefulSet total 0 items received
I0319 18:28:40.118009       1 wrap.go:47] GET /healthz: (73.068µs) 200 [kube-probe/1.15+ 127.0.0.1:44440]
I0319 18:28:50.117837       1 wrap.go:47] GET /healthz: (123.338µs) 200 [kube-probe/1.15+ 127.0.0.1:44472]
I0319 18:28:58.118926       1 reflector.go:370] k8s.io/client-go/informers/factory.go:133: Watch close - *v1.PersistentVolumeClaim total 0 items received
I0319 18:29:00.117888       1 wrap.go:47] GET /healthz: (82.233µs) 200 [kube-probe/1.15+ 127.0.0.1:44508]
I0319 18:29:08.135424       1 reflector.go:370] k8s.io/client-go/informers/factory.go:133: Watch close - *v1beta1.PodDisruptionBudget total 0 items received
I0319 18:29:10.117845       1 wrap.go:47] GET /healthz: (61µs) 200 [kube-probe/1.15+ 127.0.0.1:44546]
I0319 18:29:20.118400       1 wrap.go:47] GET /healthz: (76.597µs) 200 [kube-probe/1.15+ 127.0.0.1:44578]
I0319 18:29:30.118401       1 wrap.go:47] GET /healthz: (111.046µs) 200 [kube-probe/1.15+ 127.0.0.1:44614]
I0319 18:29:33.077101       1 reflector.go:370] k8s.io/kubernetes/cmd/kube-scheduler/app/server.go:223: Watch close - *v1.Pod total 36 items received
I0319 18:29:40.117774       1 wrap.go:47] GET /healthz: (58.497µs) 200 [kube-probe/1.15+ 127.0.0.1:44662]
I0319 18:29:50.117952       1 wrap.go:47] GET /healthz: (82.036µs) 200 [kube-probe/1.15+ 127.0.0.1:44694]
I0319 18:30:00.117712       1 wrap.go:47] GET /healthz: (72.937µs) 200 [kube-probe/1.15+ 127.0.0.1:44728]
I0319 18:30:10.117825       1 wrap.go:47] GET /healthz: (79.012µs) 200 [kube-probe/1.15+ 127.0.0.1:44766]
I0319 18:30:20.117812       1 wrap.go:47] GET /healthz: (75.191µs) 200 [kube-probe/1.15+ 127.0.0.1:44798]
I0319 18:30:30.118240       1 wrap.go:47] GET /healthz: (64.325µs) 200 [kube-probe/1.15+ 127.0.0.1:44834]
I0319 18:30:40.118382       1 wrap.go:47] GET /healthz: (94.637µs) 200 [kube-probe/1.15+ 127.0.0.1:44884]
I0319 18:30:50.118093       1 wrap.go:47] GET /healthz: (113.59µs) 200 [kube-probe/1.15+ 127.0.0.1:44916]
I0319 18:30:57.138114       1 reflector.go:370] k8s.io/client-go/informers/factory.go:133: Watch close - *v1.Service total 0 items received
I0319 18:31:00.118176       1 wrap.go:47] GET /healthz: (81.694µs) 200 [kube-probe/1.15+ 127.0.0.1:44950]
I0319 18:31:09.114060       1 reflector.go:370] k8s.io/client-go/informers/factory.go:133: Watch close - *v1.Node total 51 items received
I0319 18:31:10.118717       1 wrap.go:47] GET /healthz: (81.533µs) 200 [kube-probe/1.15+ 127.0.0.1:44988]
I0319 18:31:12.096400       1 scheduling_queue.go:908] About to try and schedule pod projected-8415/annotationupdate2bf77b9f-4a75-11e9-af5d-a08cfde32bdd
I0319 18:31:12.096447       1 scheduler.go:453] Attempting to schedule pod: projected-8415/annotationupdate2bf77b9f-4a75-11e9-af5d-a08cfde32bdd
I0319 18:31:12.097924       1 scheduler_binder.go:269] AssumePodVolumes for pod "projected-8415/annotationupdate2bf77b9f-4a75-11e9-af5d-a08cfde32bdd", node "e2e-test-peterhornyack-windows-node-group-7n03"
I0319 18:31:12.099050       1 scheduler_binder.go:279] AssumePodVolumes for pod "projected-8415/annotationupdate2bf77b9f-4a75-11e9-af5d-a08cfde32bdd", node "e2e-test-peterhornyack-windows-node-group-7n03": all PVCs bound and nothing to do
I0319 18:31:12.099135       1 factory.go:733] Attempting to bind annotationupdate2bf77b9f-4a75-11e9-af5d-a08cfde32bdd to e2e-test-peterhornyack-windows-node-group-7n03
I0319 18:31:12.106853       1 scheduler.go:572] pod projected-8415/annotationupdate2bf77b9f-4a75-11e9-af5d-a08cfde32bdd is bound successfully on node e2e-test-peterhornyack-windows-node-group-7n03, 5 nodes evaluated, 2 nodes were found feasible
I0319 18:31:20.117806       1 wrap.go:47] GET /healthz: (77.596µs) 200 [kube-probe/1.15+ 127.0.0.1:45020]
I0319 18:31:30.117721       1 wrap.go:47] GET /healthz: (80.63µs) 200 [kube-probe/1.15+ 127.0.0.1:45054]
I0319 18:31:40.118597       1 wrap.go:47] GET /healthz: (71.331µs) 200 [kube-probe/1.15+ 127.0.0.1:45102]
I0319 18:31:49.040709       1 scheduling_queue.go:908] About to try and schedule pod downward-api-2205/downward-api-41fcdf24-4a75-11e9-af5d-a08cfde32bdd
I0319 18:31:49.042129       1 scheduler.go:453] Attempting to schedule pod: downward-api-2205/downward-api-41fcdf24-4a75-11e9-af5d-a08cfde32bdd
I0319 18:31:49.044316       1 scheduler_binder.go:269] AssumePodVolumes for pod "downward-api-2205/downward-api-41fcdf24-4a75-11e9-af5d-a08cfde32bdd", node "e2e-test-peterhornyack-windows-node-group-7n03"
I0319 18:31:49.044732       1 scheduler_binder.go:279] AssumePodVolumes for pod "downward-api-2205/downward-api-41fcdf24-4a75-11e9-af5d-a08cfde32bdd", node "e2e-test-peterhornyack-windows-node-group-7n03": all PVCs bound and nothing to do
I0319 18:31:49.044821       1 factory.go:733] Attempting to bind downward-api-41fcdf24-4a75-11e9-af5d-a08cfde32bdd to e2e-test-peterhornyack-windows-node-group-7n03
I0319 18:31:49.052818       1 scheduler.go:572] pod downward-api-2205/downward-api-41fcdf24-4a75-11e9-af5d-a08cfde32bdd is bound successfully on node e2e-test-peterhornyack-windows-node-group-7n03, 5 nodes evaluated, 2 nodes were found feasible
I0319 18:31:50.118222       1 wrap.go:47] GET /healthz: (92.172µs) 200 [kube-probe/1.15+ 127.0.0.1:45136]
I0319 18:31:53.124817       1 reflector.go:370] k8s.io/client-go/informers/factory.go:133: Watch close - *v1.StorageClass total 0 items received
I0319 18:32:00.118367       1 wrap.go:47] GET /healthz: (91.914µs) 200 [kube-probe/1.15+ 127.0.0.1:45172]
I0319 18:32:06.013004       1 scheduling_queue.go:908] About to try and schedule pod kubectl-1940/redis-master-h86c6
I0319 18:32:06.013068       1 scheduler.go:453] Attempting to schedule pod: kubectl-1940/redis-master-h86c6
I0319 18:32:06.015624       1 scheduler_binder.go:269] AssumePodVolumes for pod "kubectl-1940/redis-master-h86c6", node "e2e-test-peterhornyack-windows-node-group-dp2r"
I0319 18:32:06.015656       1 scheduler_binder.go:279] AssumePodVolumes for pod "kubectl-1940/redis-master-h86c6", node "e2e-test-peterhornyack-windows-node-group-dp2r": all PVCs bound and nothing to do
I0319 18:32:06.015717       1 factory.go:733] Attempting to bind redis-master-h86c6 to e2e-test-peterhornyack-windows-node-group-dp2r
I0319 18:32:06.027690       1 scheduler.go:572] pod kubectl-1940/redis-master-h86c6 is bound successfully on node e2e-test-peterhornyack-windows-node-group-dp2r, 5 nodes evaluated, 2 nodes were found feasible
I0319 18:32:10.117851       1 wrap.go:47] GET /healthz: (79.599µs) 200 [kube-probe/1.15+ 127.0.0.1:45210]
I0319 18:32:14.145100       1 reflector.go:370] k8s.io/client-go/informers/factory.go:133: Watch close - *v1.ReplicationController total 3 items received
I0319 18:32:20.118189       1 wrap.go:47] GET /healthz: (75.578µs) 200 [kube-probe/1.15+ 127.0.0.1:45242]
I0319 18:32:30.117952       1 wrap.go:47] GET /healthz: (73.815µs) 200 [kube-probe/1.15+ 127.0.0.1:45276]
I0319 18:32:34.082534       1 reflector.go:370] k8s.io/client-go/informers/factory.go:133: Watch close - *v1.PersistentVolume total 0 items received
I0319 18:32:40.118084       1 wrap.go:47] GET /healthz: (96.365µs) 200 [kube-probe/1.15+ 127.0.0.1:45324]
I0319 18:32:46.694818       1 scheduling_queue.go:908] About to try and schedule pod statefulset-9091/ss2-0
I0319 18:32:46.694866       1 scheduler.go:453] Attempting to schedule pod: statefulset-9091/ss2-0
I0319 18:32:46.695647       1 scheduler_binder.go:269] AssumePodVolumes for pod "statefulset-9091/ss2-0", node "e2e-test-peterhornyack-windows-node-group-7n03"
I0319 18:32:46.695688       1 scheduler_binder.go:279] AssumePodVolumes for pod "statefulset-9091/ss2-0", node "e2e-test-peterhornyack-windows-node-group-7n03": all PVCs bound and nothing to do
I0319 18:32:46.695730       1 factory.go:733] Attempting to bind ss2-0 to e2e-test-peterhornyack-windows-node-group-7n03
I0319 18:32:46.710829       1 scheduler.go:572] pod statefulset-9091/ss2-0 is bound successfully on node e2e-test-peterhornyack-windows-node-group-7n03, 5 nodes evaluated, 2 nodes were found feasible
I0319 18:32:50.117804       1 wrap.go:47] GET /healthz: (79.478µs) 200 [kube-probe/1.15+ 127.0.0.1:45358]
I0319 18:32:54.321856       1 scheduling_queue.go:908] About to try and schedule pod statefulset-9091/ss2-1
I0319 18:32:54.321887       1 scheduler.go:453] Attempting to schedule pod: statefulset-9091/ss2-1
I0319 18:32:54.322307       1 scheduler_binder.go:269] AssumePodVolumes for pod "statefulset-9091/ss2-1", node "e2e-test-peterhornyack-windows-node-group-dp2r"
I0319 18:32:54.322326       1 scheduler_binder.go:279] AssumePodVolumes for pod "statefulset-9091/ss2-1", node "e2e-test-peterhornyack-windows-node-group-dp2r": all PVCs bound and nothing to do
I0319 18:32:54.323839       1 factory.go:733] Attempting to bind ss2-1 to e2e-test-peterhornyack-windows-node-group-dp2r
I0319 18:32:54.341267       1 scheduler.go:572] pod statefulset-9091/ss2-1 is bound successfully on node e2e-test-peterhornyack-windows-node-group-dp2r, 5 nodes evaluated, 2 nodes were found feasible
I0319 18:33:00.117789       1 wrap.go:47] GET /healthz: (83.778µs) 200 [kube-probe/1.15+ 127.0.0.1:45392]
I0319 18:33:02.130017       1 scheduling_queue.go:908] About to try and schedule pod statefulset-9091/ss2-2
I0319 18:33:02.130092       1 scheduler.go:453] Attempting to schedule pod: statefulset-9091/ss2-2
I0319 18:33:02.134122       1 scheduler_binder.go:269] AssumePodVolumes for pod "statefulset-9091/ss2-2", node "e2e-test-peterhornyack-windows-node-group-7n03"
I0319 18:33:02.134152       1 scheduler_binder.go:279] AssumePodVolumes for pod "statefulset-9091/ss2-2", node "e2e-test-peterhornyack-windows-node-group-7n03": all PVCs bound and nothing to do
I0319 18:33:02.134223       1 factory.go:733] Attempting to bind ss2-2 to e2e-test-peterhornyack-windows-node-group-7n03
I0319 18:33:02.153707       1 scheduler.go:572] pod statefulset-9091/ss2-2 is bound successfully on node e2e-test-peterhornyack-windows-node-group-7n03, 5 nodes evaluated, 2 nodes were found feasible
I0319 18:33:10.120404       1 wrap.go:47] GET /healthz: (76.32µs) 200 [kube-probe/1.15+ 127.0.0.1:45434]
I0319 18:33:20.118092       1 wrap.go:47] GET /healthz: (84.218µs) 200 [kube-probe/1.15+ 127.0.0.1:45468]
I0319 18:33:30.118015       1 wrap.go:47] GET /healthz: (69.891µs) 200 [kube-probe/1.15+ 127.0.0.1:45504]
I0319 18:33:40.117790       1 wrap.go:47] GET /healthz: (79.483µs) 200 [kube-probe/1.15+ 127.0.0.1:45552]
I0319 18:33:50.119549       1 wrap.go:47] GET /healthz: (85.684µs) 200 [kube-probe/1.15+ 127.0.0.1:45584]
I0319 18:34:00.117746       1 wrap.go:47] GET /healthz: (79.141µs) 200 [kube-probe/1.15+ 127.0.0.1:45618]
I0319 18:34:09.122005       1 reflector.go:370] k8s.io/client-go/informers/factory.go:133: Watch close - *v1.PersistentVolumeClaim total 0 items received
I0319 18:34:10.118358       1 wrap.go:47] GET /healthz: (71.775µs) 200 [kube-probe/1.15+ 127.0.0.1:45656]
I0319 18:34:10.737671       1 scheduling_queue.go:908] About to try and schedule pod statefulset-9091/ss2-2
I0319 18:34:10.737714       1 scheduler.go:453] Attempting to schedule pod: statefulset-9091/ss2-2
I0319 18:34:10.743279       1 scheduler_binder.go:269] AssumePodVolumes for pod "statefulset-9091/ss2-2", node "e2e-test-peterhornyack-windows-node-group-dp2r"
I0319 18:34:10.743328       1 scheduler_binder.go:279] AssumePodVolumes for pod "statefulset-9091/ss2-2", node "e2e-test-peterhornyack-windows-node-group-dp2r": all PVCs bound and nothing to do
I0319 18:34:10.743392       1 factory.go:733] Attempting to bind ss2-2 to e2e-test-peterhornyack-windows-node-group-dp2r
I0319 18:34:10.759942       1 scheduler.go:572] pod statefulset-9091/ss2-2 is bound successfully on node e2e-test-peterhornyack-windows-node-group-dp2r, 5 nodes evaluated, 2 nodes were found feasible
I0319 18:34:20.117879       1 wrap.go:47] GET /healthz: (79.209µs) 200 [kube-probe/1.15+ 127.0.0.1:45690]
I0319 18:34:30.117743       1 wrap.go:47] GET /healthz: (70.641µs) 200 [kube-probe/1.15+ 127.0.0.1:45724]
I0319 18:34:37.014043       1 scheduling_queue.go:908] About to try and schedule pod statefulset-9091/ss2-1
I0319 18:34:37.014080       1 scheduler.go:453] Attempting to schedule pod: statefulset-9091/ss2-1
I0319 18:34:37.017357       1 scheduler_binder.go:269] AssumePodVolumes for pod "statefulset-9091/ss2-1", node "e2e-test-peterhornyack-windows-node-group-dp2r"
I0319 18:34:37.017451       1 scheduler_binder.go:279] AssumePodVolumes for pod "statefulset-9091/ss2-1", node "e2e-test-peterhornyack-windows-node-group-dp2r": all PVCs bound and nothing to do
I0319 18:34:37.017509       1 factory.go:733] Attempting to bind ss2-1 to e2e-test-peterhornyack-windows-node-group-dp2r
I0319 18:34:37.033856       1 scheduler.go:572] pod statefulset-9091/ss2-1 is bound successfully on node e2e-test-peterhornyack-windows-node-group-dp2r, 5 nodes evaluated, 2 nodes were found feasible
I0319 18:34:40.118372       1 wrap.go:47] GET /healthz: (74.979µs) 200 [kube-probe/1.15+ 127.0.0.1:45776]
I0319 18:34:50.118367       1 wrap.go:47] GET /healthz: (75.376µs) 200 [kube-probe/1.15+ 127.0.0.1:45808]
I0319 18:35:00.118362       1 wrap.go:47] GET /healthz: (75.334µs) 200 [kube-probe/1.15+ 127.0.0.1:45842]
I0319 18:35:10.117804       1 wrap.go:47] GET /healthz: (102.615µs) 200 [kube-probe/1.15+ 127.0.0.1:45882]
I0319 18:35:11.642332       1 scheduling_queue.go:908] About to try and schedule pod statefulset-9091/ss2-0
I0319 18:35:11.642367       1 scheduler.go:453] Attempting to schedule pod: statefulset-9091/ss2-0
I0319 18:35:11.643559       1 scheduler_binder.go:269] AssumePodVolumes for pod "statefulset-9091/ss2-0", node "e2e-test-peterhornyack-windows-node-group-dp2r"
I0319 18:35:11.646314       1 scheduler_binder.go:279] AssumePodVolumes for pod "statefulset-9091/ss2-0", node "e2e-test-peterhornyack-windows-node-group-dp2r": all PVCs bound and nothing to do
I0319 18:35:11.646421       1 factory.go:733] Attempting to bind ss2-0 to e2e-test-peterhornyack-windows-node-group-dp2r
I0319 18:35:11.667256       1 scheduler.go:572] pod statefulset-9091/ss2-0 is bound successfully on node e2e-test-peterhornyack-windows-node-group-dp2r, 5 nodes evaluated, 2 nodes were found feasible
I0319 18:35:18.113246       1 reflector.go:370] k8s.io/client-go/informers/factory.go:133: Watch close - *v1.ReplicaSet total 0 items received
I0319 18:35:20.117884       1 wrap.go:47] GET /healthz: (70.298µs) 200 [kube-probe/1.15+ 127.0.0.1:45916]
I0319 18:35:30.118095       1 wrap.go:47] GET /healthz: (89.151µs) 200 [kube-probe/1.15+ 127.0.0.1:45952]
I0319 18:35:37.661965       1 scheduling_queue.go:908] About to try and schedule pod statefulset-9091/ss2-2
I0319 18:35:37.662007       1 scheduler.go:453] Attempting to schedule pod: statefulset-9091/ss2-2
I0319 18:35:37.662406       1 scheduler_binder.go:269] AssumePodVolumes for pod "statefulset-9091/ss2-2", node "e2e-test-peterhornyack-windows-node-group-7n03"
I0319 18:35:37.662425       1 scheduler_binder.go:279] AssumePodVolumes for pod "statefulset-9091/ss2-2", node "e2e-test-peterhornyack-windows-node-group-7n03": all PVCs bound and nothing to do
I0319 18:35:37.662481       1 factory.go:733] Attempting to bind ss2-2 to e2e-test-peterhornyack-windows-node-group-7n03
I0319 18:35:37.673501       1 scheduler.go:572] pod statefulset-9091/ss2-2 is bound successfully on node e2e-test-peterhornyack-windows-node-group-7n03, 5 nodes evaluated, 2 nodes were found feasible
I0319 18:35:40.117864       1 wrap.go:47] GET /healthz: (66.063µs) 200 [kube-probe/1.15+ 127.0.0.1:46002]
I0319 18:35:50.118364       1 wrap.go:47] GET /healthz: (79.258µs) 200 [kube-probe/1.15+ 127.0.0.1:46036]
I0319 18:36:00.117734       1 wrap.go:47] GET /healthz: (109.904µs) 200 [kube-probe/1.15+ 127.0.0.1:46072]
I0319 18:36:10.117606       1 wrap.go:47] GET /healthz: (85.346µs) 200 [kube-probe/1.15+ 127.0.0.1:46110]
I0319 18:36:20.118153       1 wrap.go:47] GET /healthz: (76.114µs) 200 [kube-probe/1.15+ 127.0.0.1:46142]
I0319 18:36:30.117948       1 wrap.go:47] GET /healthz: (75.278µs) 200 [kube-probe/1.15+ 127.0.0.1:46176]
I0319 18:36:38.189129       1 scheduling_queue.go:908] About to try and schedule pod statefulset-9091/ss2-1
I0319 18:36:38.189160       1 scheduler.go:453] Attempting to schedule pod: statefulset-9091/ss2-1
I0319 18:36:38.192601       1 scheduler_binder.go:269] AssumePodVolumes for pod "statefulset-9091/ss2-1", node "e2e-test-peterhornyack-windows-node-group-dp2r"
I0319 18:36:38.192665       1 scheduler_binder.go:279] AssumePodVolumes for pod "statefulset-9091/ss2-1", node "e2e-test-peterhornyack-windows-node-group-dp2r": all PVCs bound and nothing to do
I0319 18:36:38.192735       1 factory.go:733] Attempting to bind ss2-1 to e2e-test-peterhornyack-windows-node-group-dp2r
I0319 18:36:38.212564       1 scheduler.go:572] pod statefulset-9091/ss2-1 is bound successfully on node e2e-test-peterhornyack-windows-node-group-dp2r, 5 nodes evaluated, 2 nodes were found feasible
I0319 18:36:40.118253       1 wrap.go:47] GET /healthz: (72.551µs) 200 [kube-probe/1.15+ 127.0.0.1:46236]
I0319 18:36:50.117745       1 wrap.go:47] GET /healthz: (81.529µs) 200 [kube-probe/1.15+ 127.0.0.1:46270]
I0319 18:37:00.118236       1 wrap.go:47] GET /healthz: (82.157µs) 200 [kube-probe/1.15+ 127.0.0.1:46304]
I0319 18:37:10.118150       1 wrap.go:47] GET /healthz: (77.593µs) 200 [kube-probe/1.15+ 127.0.0.1:46342]
I0319 18:37:20.117963       1 wrap.go:47] GET /healthz: (59.112µs) 200 [kube-probe/1.15+ 127.0.0.1:46376]
I0319 18:37:30.118223       1 wrap.go:47] GET /healthz: (76.25µs) 200 [kube-probe/1.15+ 127.0.0.1:46412]
I0319 18:37:37.727798       1 scheduling_queue.go:908] About to try and schedule pod statefulset-9091/ss2-0
I0319 18:37:37.727844       1 scheduler.go:453] Attempting to schedule pod: statefulset-9091/ss2-0
I0319 18:37:37.731870       1 scheduler_binder.go:269] AssumePodVolumes for pod "statefulset-9091/ss2-0", node "e2e-test-peterhornyack-windows-node-group-7n03"
I0319 18:37:37.731930       1 scheduler_binder.go:279] AssumePodVolumes for pod "statefulset-9091/ss2-0", node "e2e-test-peterhornyack-windows-node-group-7n03": all PVCs bound and nothing to do
I0319 18:37:37.732445       1 factory.go:733] Attempting to bind ss2-0 to e2e-test-peterhornyack-windows-node-group-7n03
I0319 18:37:37.747757       1 scheduler.go:572] pod statefulset-9091/ss2-0 is bound successfully on node e2e-test-peterhornyack-windows-node-group-7n03, 5 nodes evaluated, 2 nodes were found feasible
I0319 18:37:40.123732       1 wrap.go:47] GET /healthz: (88.719µs) 200 [kube-probe/1.15+ 127.0.0.1:46460]
I0319 18:37:50.118112       1 wrap.go:47] GET /healthz: (94.578µs) 200 [kube-probe/1.15+ 127.0.0.1:46492]
I0319 18:38:00.117869       1 wrap.go:47] GET /healthz: (68.781µs) 200 [kube-probe/1.15+ 127.0.0.1:46528]
I0319 18:38:03.087106       1 reflector.go:370] k8s.io/client-go/informers/factory.go:133: Watch close - *v1.PersistentVolume total 0 items received
I0319 18:38:10.117900       1 wrap.go:47] GET /healthz: (63.923µs) 200 [kube-probe/1.15+ 127.0.0.1:46566]
I0319 18:38:14.078073       1 reflector.go:370] k8s.io/client-go/informers/factory.go:133: Watch close - *v1.StatefulSet total 34 items received
I0319 18:38:20.121640       1 wrap.go:47] GET /healthz: (74.788µs) 200 [kube-probe/1.15+ 127.0.0.1:46598]
I0319 18:38:21.138555       1 reflector.go:370] k8s.io/client-go/informers/factory.go:133: Watch close - *v1beta1.PodDisruptionBudget total 0 items received
I0319 18:38:30.118252       1 wrap.go:47] GET /healthz: (80.111µs) 200 [kube-probe/1.15+ 127.0.0.1:46632]
I0319 18:38:40.118139       1 wrap.go:47] GET /healthz: (77.002µs) 200 [kube-probe/1.15+ 127.0.0.1:46682]
I0319 18:38:50.117978       1 wrap.go:47] GET /healthz: (70.585µs) 200 [kube-probe/1.15+ 127.0.0.1:46716]
I0319 18:39:00.117765       1 wrap.go:47] GET /healthz: (82.432µs) 200 [kube-probe/1.15+ 127.0.0.1:46750]
I0319 18:39:10.118093       1 wrap.go:47] GET /healthz: (87.477µs) 200 [kube-probe/1.15+ 127.0.0.1:46790]
I0319 18:39:10.125142       1 reflector.go:370] k8s.io/client-go/informers/factory.go:133: Watch close - *v1.PersistentVolumeClaim total 0 items received
I0319 18:39:15.080585       1 reflector.go:370] k8s.io/kubernetes/cmd/kube-scheduler/app/server.go:223: Watch close - *v1.Pod total 139 items received
I0319 18:39:20.117933       1 wrap.go:47] GET /healthz: (60.691µs) 200 [kube-probe/1.15+ 127.0.0.1:46822]
I0319 18:39:29.141222       1 reflector.go:370] k8s.io/client-go/informers/factory.go:133: Watch close - *v1.Service total 2 items received
I0319 18:39:29.416082       1 scheduling_queue.go:908] About to try and schedule pod projected-5161/pod-projected-secrets-54640b3a-4a76-11e9-af5d-a08cfde32bdd
I0319 18:39:29.416115       1 scheduler.go:453] Attempting to schedule pod: projected-5161/pod-projected-secrets-54640b3a-4a76-11e9-af5d-a08cfde32bdd
I0319 18:39:29.416510       1 scheduler_binder.go:269] AssumePodVolumes for pod "projected-5161/pod-projected-secrets-54640b3a-4a76-11e9-af5d-a08cfde32bdd", node "e2e-test-peterhornyack-windows-node-group-7n03"
I0319 18:39:29.416542       1 scheduler_binder.go:279] AssumePodVolumes for pod "projected-5161/pod-projected-secrets-54640b3a-4a76-11e9-af5d-a08cfde32bdd", node "e2e-test-peterhornyack-windows-node-group-7n03": all PVCs bound and nothing to do
I0319 18:39:29.416595       1 factory.go:733] Attempting to bind pod-projected-secrets-54640b3a-4a76-11e9-af5d-a08cfde32bdd to e2e-test-peterhornyack-windows-node-group-7n03
I0319 18:39:29.423784       1 scheduler.go:572] pod projected-5161/pod-projected-secrets-54640b3a-4a76-11e9-af5d-a08cfde32bdd is bound successfully on node e2e-test-peterhornyack-windows-node-group-7n03, 5 nodes evaluated, 2 nodes were found feasible
I0319 18:39:30.117902       1 wrap.go:47] GET /healthz: (78.819µs) 200 [kube-probe/1.15+ 127.0.0.1:46856]
I0319 18:39:40.117594       1 wrap.go:47] GET /healthz: (65.181µs) 200 [kube-probe/1.15+ 127.0.0.1:46904]
I0319 18:39:48.148748       1 reflector.go:370] k8s.io/client-go/informers/factory.go:133: Watch close - *v1.ReplicationController total 2 items received
I0319 18:39:50.117974       1 wrap.go:47] GET /healthz: (78.783µs) 200 [kube-probe/1.15+ 127.0.0.1:46936]
I0319 18:40:00.118107       1 wrap.go:47] GET /healthz: (88.516µs) 200 [kube-probe/1.15+ 127.0.0.1:46970]
I0319 18:40:10.117859       1 wrap.go:47] GET /healthz: (81.052µs) 200 [kube-probe/1.15+ 127.0.0.1:47010]
I0319 18:40:20.118016       1 wrap.go:47] GET /healthz: (73.991µs) 200 [kube-probe/1.15+ 127.0.0.1:47042]
I0319 18:40:28.213740       1 scheduling_queue.go:908] About to try and schedule pod emptydir-wrapper-2030/pod-secrets-776f8b24-4a76-11e9-af5d-a08cfde32bdd
I0319 18:40:28.213788       1 scheduler.go:453] Attempting to schedule pod: emptydir-wrapper-2030/pod-secrets-776f8b24-4a76-11e9-af5d-a08cfde32bdd
I0319 18:40:28.214251       1 scheduler_binder.go:269] AssumePodVolumes for pod "emptydir-wrapper-2030/pod-secrets-776f8b24-4a76-11e9-af5d-a08cfde32bdd", node "e2e-test-peterhornyack-windows-node-group-7n03"
I0319 18:40:28.214300       1 scheduler_binder.go:279] AssumePodVolumes for pod "emptydir-wrapper-2030/pod-secrets-776f8b24-4a76-11e9-af5d-a08cfde32bdd", node "e2e-test-peterhornyack-windows-node-group-7n03": all PVCs bound and nothing to do
I0319 18:40:28.214347       1 factory.go:733] Attempting to bind pod-secrets-776f8b24-4a76-11e9-af5d-a08cfde32bdd to e2e-test-peterhornyack-windows-node-group-7n03
I0319 18:40:28.223706       1 scheduler.go:572] pod emptydir-wrapper-2030/pod-secrets-776f8b24-4a76-11e9-af5d-a08cfde32bdd is bound successfully on node e2e-test-peterhornyack-windows-node-group-7n03, 5 nodes evaluated, 2 nodes were found feasible
I0319 18:40:30.118237       1 wrap.go:47] GET /healthz: (79.901µs) 200 [kube-probe/1.15+ 127.0.0.1:47078]
I0319 18:40:40.117962       1 wrap.go:47] GET /healthz: (113.922µs) 200 [kube-probe/1.15+ 127.0.0.1:47126]
I0319 18:40:45.150111       1 scheduling_queue.go:908] About to try and schedule pod svcaccounts-6113/pod-service-account-81884a43-4a76-11e9-af5d-a08cfde32bdd
I0319 18:40:45.150161       1 scheduler.go:453] Attempting to schedule pod: svcaccounts-6113/pod-service-account-81884a43-4a76-11e9-af5d-a08cfde32bdd
I0319 18:40:45.151156       1 scheduler_binder.go:269] AssumePodVolumes for pod "svcaccounts-6113/pod-service-account-81884a43-4a76-11e9-af5d-a08cfde32bdd", node "e2e-test-peterhornyack-windows-node-group-dp2r"
I0319 18:40:45.151180       1 scheduler_binder.go:279] AssumePodVolumes for pod "svcaccounts-6113/pod-service-account-81884a43-4a76-11e9-af5d-a08cfde32bdd", node "e2e-test-peterhornyack-windows-node-group-dp2r": all PVCs bound and nothing to do
I0319 18:40:45.151505       1 factory.go:733] Attempting to bind pod-service-account-81884a43-4a76-11e9-af5d-a08cfde32bdd to e2e-test-peterhornyack-windows-node-group-dp2r
I0319 18:40:45.160325       1 scheduler.go:572] pod svcaccounts-6113/pod-service-account-81884a43-4a76-11e9-af5d-a08cfde32bdd is bound successfully on node e2e-test-peterhornyack-windows-node-group-dp2r, 5 nodes evaluated, 2 nodes were found feasible
I0319 18:40:50.117906       1 wrap.go:47] GET /healthz: (77.418µs) 200 [kube-probe/1.15+ 127.0.0.1:47158]
I0319 18:41:00.117461       1 wrap.go:47] GET /healthz: (89.394µs) 200 [kube-probe/1.15+ 127.0.0.1:47198]
I0319 18:41:01.116333       1 reflector.go:370] k8s.io/client-go/informers/factory.go:133: Watch close - *v1.Node total 70 items received
I0319 18:41:04.008466       1 scheduling_queue.go:908] About to try and schedule pod kubectl-6533/redis-master-nmf2b
I0319 18:41:04.008496       1 scheduler.go:453] Attempting to schedule pod: kubectl-6533/redis-master-nmf2b
I0319 18:41:04.008901       1 scheduler_binder.go:269] AssumePodVolumes for pod "kubectl-6533/redis-master-nmf2b", node "e2e-test-peterhornyack-windows-node-group-dp2r"
I0319 18:41:04.008978       1 scheduler_binder.go:279] AssumePodVolumes for pod "kubectl-6533/redis-master-nmf2b", node "e2e-test-peterhornyack-windows-node-group-dp2r": all PVCs bound and nothing to do
I0319 18:41:04.013062       1 factory.go:733] Attempting to bind redis-master-nmf2b to e2e-test-peterhornyack-windows-node-group-dp2r
I0319 18:41:04.026094       1 scheduler.go:572] pod kubectl-6533/redis-master-nmf2b is bound successfully on node e2e-test-peterhornyack-windows-node-group-dp2r, 5 nodes evaluated, 2 nodes were found feasible
I0319 18:41:10.117721       1 wrap.go:47] GET /healthz: (63.976µs) 200 [kube-probe/1.15+ 127.0.0.1:47240]
I0319 18:41:20.117840       1 wrap.go:47] GET /healthz: (75.576µs) 200 [kube-probe/1.15+ 127.0.0.1:47272]
I0319 18:41:21.127979       1 reflector.go:370] k8s.io/client-go/informers/factory.go:133: Watch close - *v1.StorageClass total 0 items received
I0319 18:41:30.118167       1 wrap.go:47] GET /healthz: (72.216µs) 200 [kube-probe/1.15+ 127.0.0.1:47308]
I0319 18:41:37.379326       1 scheduling_queue.go:908] About to try and schedule pod pods-5127/pod-hostip-a0a9c0e8-4a76-11e9-af5d-a08cfde32bdd
I0319 18:41:37.379364       1 scheduler.go:453] Attempting to schedule pod: pods-5127/pod-hostip-a0a9c0e8-4a76-11e9-af5d-a08cfde32bdd
I0319 18:41:37.380101       1 scheduler_binder.go:269] AssumePodVolumes for pod "pods-5127/pod-hostip-a0a9c0e8-4a76-11e9-af5d-a08cfde32bdd", node "e2e-test-peterhornyack-windows-node-group-dp2r"
I0319 18:41:37.380139       1 scheduler_binder.go:279] AssumePodVolumes for pod "pods-5127/pod-hostip-a0a9c0e8-4a76-11e9-af5d-a08cfde32bdd", node "e2e-test-peterhornyack-windows-node-group-dp2r": all PVCs bound and nothing to do
I0319 18:41:37.380196       1 factory.go:733] Attempting to bind pod-hostip-a0a9c0e8-4a76-11e9-af5d-a08cfde32bdd to e2e-test-peterhornyack-windows-node-group-dp2r
I0319 18:41:37.388606       1 scheduler.go:572] pod pods-5127/pod-hostip-a0a9c0e8-4a76-11e9-af5d-a08cfde32bdd is bound successfully on node e2e-test-peterhornyack-windows-node-group-dp2r, 5 nodes evaluated, 2 nodes were found feasible
I0319 18:41:40.118600       1 wrap.go:47] GET /healthz: (72.006µs) 200 [kube-probe/1.15+ 127.0.0.1:47360]
I0319 18:41:50.117825       1 wrap.go:47] GET /healthz: (78.146µs) 200 [kube-probe/1.15+ 127.0.0.1:47392]
I0319 18:42:00.117901       1 wrap.go:47] GET /healthz: (73.653µs) 200 [kube-probe/1.15+ 127.0.0.1:47426]
I0319 18:42:09.571409       1 scheduling_queue.go:908] About to try and schedule pod container-runtime-6312/terminate-cmd-rpab3d9e9f1-4a76-11e9-af5d-a08cfde32bdd
I0319 18:42:09.571442       1 scheduler.go:453] Attempting to schedule pod: container-runtime-6312/terminate-cmd-rpab3d9e9f1-4a76-11e9-af5d-a08cfde32bdd
I0319 18:42:09.571780       1 scheduler_binder.go:269] AssumePodVolumes for pod "container-runtime-6312/terminate-cmd-rpab3d9e9f1-4a76-11e9-af5d-a08cfde32bdd", node "e2e-test-peterhornyack-windows-node-group-7n03"
I0319 18:42:09.571834       1 scheduler_binder.go:279] AssumePodVolumes for pod "container-runtime-6312/terminate-cmd-rpab3d9e9f1-4a76-11e9-af5d-a08cfde32bdd", node "e2e-test-peterhornyack-windows-node-group-7n03": all PVCs bound and nothing to do
I0319 18:42:09.571882       1 factory.go:733] Attempting to bind terminate-cmd-rpab3d9e9f1-4a76-11e9-af5d-a08cfde32bdd to e2e-test-peterhornyack-windows-node-group-7n03
I0319 18:42:09.580521       1 scheduler.go:572] pod container-runtime-6312/terminate-cmd-rpab3d9e9f1-4a76-11e9-af5d-a08cfde32bdd is bound successfully on node e2e-test-peterhornyack-windows-node-group-7n03, 5 nodes evaluated, 2 nodes were found feasible
I0319 18:42:10.117865       1 wrap.go:47] GET /healthz: (114.78µs) 200 [kube-probe/1.15+ 127.0.0.1:47472]
I0319 18:42:20.117890       1 wrap.go:47] GET /healthz: (129.147µs) 200 [kube-probe/1.15+ 127.0.0.1:47614]
I0319 18:42:30.117901       1 wrap.go:47] GET /healthz: (57.371µs) 200 [kube-probe/1.15+ 127.0.0.1:47648]
I0319 18:42:40.119178       1 wrap.go:47] GET /healthz: (79.282µs) 200 [kube-probe/1.15+ 127.0.0.1:47696]
I0319 18:42:46.385895       1 scheduling_queue.go:908] About to try and schedule pod container-runtime-6312/terminate-cmd-rpofc9cb87ae-4a76-11e9-af5d-a08cfde32bdd
I0319 18:42:46.385926       1 scheduler.go:453] Attempting to schedule pod: container-runtime-6312/terminate-cmd-rpofc9cb87ae-4a76-11e9-af5d-a08cfde32bdd
I0319 18:42:46.388952       1 scheduler_binder.go:269] AssumePodVolumes for pod "container-runtime-6312/terminate-cmd-rpofc9cb87ae-4a76-11e9-af5d-a08cfde32bdd", node "e2e-test-peterhornyack-windows-node-group-dp2r"
I0319 18:42:46.388985       1 scheduler_binder.go:279] AssumePodVolumes for pod "container-runtime-6312/terminate-cmd-rpofc9cb87ae-4a76-11e9-af5d-a08cfde32bdd", node "e2e-test-peterhornyack-windows-node-group-dp2r": all PVCs bound and nothing to do
I0319 18:42:46.389719       1 factory.go:733] Attempting to bind terminate-cmd-rpofc9cb87ae-4a76-11e9-af5d-a08cfde32bdd to e2e-test-peterhornyack-windows-node-group-dp2r
I0319 18:42:46.397197       1 scheduler.go:572] pod container-runtime-6312/terminate-cmd-rpofc9cb87ae-4a76-11e9-af5d-a08cfde32bdd is bound successfully on node e2e-test-peterhornyack-windows-node-group-dp2r, 5 nodes evaluated, 2 nodes were found feasible
I0319 18:42:50.118318       1 wrap.go:47] GET /healthz: (87.362µs) 200 [kube-probe/1.15+ 127.0.0.1:47732]
I0319 18:43:00.118001       1 wrap.go:47] GET /healthz: (70.96µs) 200 [kube-probe/1.15+ 127.0.0.1:47766]
I0319 18:43:06.524408       1 scheduling_queue.go:908] About to try and schedule pod container-runtime-6312/terminate-cmd-rpnd5ccbb4b-4a76-11e9-af5d-a08cfde32bdd
I0319 18:43:06.524440       1 scheduler.go:453] Attempting to schedule pod: container-runtime-6312/terminate-cmd-rpnd5ccbb4b-4a76-11e9-af5d-a08cfde32bdd
I0319 18:43:06.524873       1 scheduler_binder.go:269] AssumePodVolumes for pod "container-runtime-6312/terminate-cmd-rpnd5ccbb4b-4a76-11e9-af5d-a08cfde32bdd", node "e2e-test-peterhornyack-windows-node-group-7n03"
I0319 18:43:06.524893       1 scheduler_binder.go:279] AssumePodVolumes for pod "container-runtime-6312/terminate-cmd-rpnd5ccbb4b-4a76-11e9-af5d-a08cfde32bdd", node "e2e-test-peterhornyack-windows-node-group-7n03": all PVCs bound and nothing to do
I0319 18:43:06.524956       1 factory.go:733] Attempting to bind terminate-cmd-rpnd5ccbb4b-4a76-11e9-af5d-a08cfde32bdd to e2e-test-peterhornyack-windows-node-group-7n03
I0319 18:43:06.534734       1 scheduler.go:572] pod container-runtime-6312/terminate-cmd-rpnd5ccbb4b-4a76-11e9-af5d-a08cfde32bdd is bound successfully on node e2e-test-peterhornyack-windows-node-group-7n03, 5 nodes evaluated, 2 nodes were found feasible
I0319 18:43:10.118111       1 wrap.go:47] GET /healthz: (123.809µs) 200 [kube-probe/1.15+ 127.0.0.1:47814]
I0319 18:43:20.117931       1 wrap.go:47] GET /healthz: (78.156µs) 200 [kube-probe/1.15+ 127.0.0.1:47846]
I0319 18:43:25.425965       1 scheduling_queue.go:908] About to try and schedule pod gc-6212/simpletest.deployment-58f7b978d-qs5rt
I0319 18:43:25.427438       1 scheduler.go:453] Attempting to schedule pod: gc-6212/simpletest.deployment-58f7b978d-qs5rt
I0319 18:43:25.429081       1 scheduler_binder.go:269] AssumePodVolumes for pod "gc-6212/simpletest.deployment-58f7b978d-qs5rt", node "e2e-test-peterhornyack-windows-node-group-dp2r"
I0319 18:43:25.429122       1 scheduler_binder.go:279] AssumePodVolumes for pod "gc-6212/simpletest.deployment-58f7b978d-qs5rt", node "e2e-test-peterhornyack-windows-node-group-dp2r": all PVCs bound and nothing to do
I0319 18:43:25.429170       1 factory.go:733] Attempting to bind simpletest.deployment-58f7b978d-qs5rt to e2e-test-peterhornyack-windows-node-group-dp2r
I0319 18:43:25.441220       1 scheduler.go:572] pod gc-6212/simpletest.deployment-58f7b978d-qs5rt is bound successfully on node e2e-test-peterhornyack-windows-node-group-dp2r, 5 nodes evaluated, 2 nodes were found feasible
I0319 18:43:25.459330       1 scheduling_queue.go:908] About to try and schedule pod gc-6212/simpletest.deployment-58f7b978d-ttlmf
I0319 18:43:25.459364       1 scheduler.go:453] Attempting to schedule pod: gc-6212/simpletest.deployment-58f7b978d-ttlmf
I0319 18:43:25.464044       1 scheduler_binder.go:269] AssumePodVolumes for pod "gc-6212/simpletest.deployment-58f7b978d-ttlmf", node "e2e-test-peterhornyack-windows-node-group-7n03"
I0319 18:43:25.464077       1 scheduler_binder.go:279] AssumePodVolumes for pod "gc-6212/simpletest.deployment-58f7b978d-ttlmf", node "e2e-test-peterhornyack-windows-node-group-7n03": all PVCs bound and nothing to do
I0319 18:43:25.464145       1 factory.go:733] Attempting to bind simpletest.deployment-58f7b978d-ttlmf to e2e-test-peterhornyack-windows-node-group-7n03
I0319 18:43:25.494316       1 scheduler.go:572] pod gc-6212/simpletest.deployment-58f7b978d-ttlmf is bound successfully on node e2e-test-peterhornyack-windows-node-group-7n03, 5 nodes evaluated, 2 nodes were found feasible
I0319 18:43:30.118184       1 wrap.go:47] GET /healthz: (74.382µs) 200 [kube-probe/1.15+ 127.0.0.1:47880]
I0319 18:43:30.124468       1 reflector.go:370] k8s.io/client-go/informers/factory.go:133: Watch close - *v1.ReplicaSet total 4 items received
I0319 18:43:40.118213       1 wrap.go:47] GET /healthz: (321.601µs) 200 [kube-probe/1.15+ 127.0.0.1:47930]
I0319 18:43:50.118609       1 wrap.go:47] GET /healthz: (92.149µs) 200 [kube-probe/1.15+ 127.0.0.1:47962]
I0319 18:44:00.117750       1 wrap.go:47] GET /healthz: (79.275µs) 200 [kube-probe/1.15+ 127.0.0.1:47996]
I0319 18:44:04.141881       1 scheduling_queue.go:908] About to try and schedule pod configmap-9612/pod-configmaps-f8222ae5-4a76-11e9-af5d-a08cfde32bdd
I0319 18:44:04.141927       1 scheduler.go:453] Attempting to schedule pod: configmap-9612/pod-configmaps-f8222ae5-4a76-11e9-af5d-a08cfde32bdd
I0319 18:44:04.142296       1 scheduler_binder.go:269] AssumePodVolumes for pod "configmap-9612/pod-configmaps-f8222ae5-4a76-11e9-af5d-a08cfde32bdd", node "e2e-test-peterhornyack-windows-node-group-7n03"
I0319 18:44:04.142314       1 scheduler_binder.go:279] AssumePodVolumes for pod "configmap-9612/pod-configmaps-f8222ae5-4a76-11e9-af5d-a08cfde32bdd", node "e2e-test-peterhornyack-windows-node-group-7n03": all PVCs bound and nothing to do
I0319 18:44:04.142374       1 factory.go:733] Attempting to bind pod-configmaps-f8222ae5-4a76-11e9-af5d-a08cfde32bdd to e2e-test-peterhornyack-windows-node-group-7n03
I0319 18:44:04.150230       1 scheduler.go:572] pod configmap-9612/pod-configmaps-f8222ae5-4a76-11e9-af5d-a08cfde32bdd is bound successfully on node e2e-test-peterhornyack-windows-node-group-7n03, 5 nodes evaluated, 2 nodes were found feasible
I0319 18:44:10.118301       1 wrap.go:47] GET /healthz: (59.575µs) 200 [kube-probe/1.15+ 127.0.0.1:48036]
I0319 18:44:11.141120       1 reflector.go:370] k8s.io/client-go/informers/factory.go:133: Watch close - *v1beta1.PodDisruptionBudget total 0 items received
I0319 18:44:20.117800       1 wrap.go:47] GET /healthz: (80.872µs) 200 [kube-probe/1.15+ 127.0.0.1:48072]
I0319 18:44:30.118211       1 wrap.go:47] GET /healthz: (70.253µs) 200 [kube-probe/1.15+ 127.0.0.1:48106]
I0319 18:44:40.118171       1 wrap.go:47] GET /healthz: (73.224µs) 200 [kube-probe/1.15+ 127.0.0.1:48156]
I0319 18:44:43.437323       1 scheduling_queue.go:908] About to try and schedule pod svcaccounts-2293/pod-service-account-defaultsa
I0319 18:44:43.437367       1 scheduler.go:453] Attempting to schedule pod: svcaccounts-2293/pod-service-account-defaultsa
I0319 18:44:43.438954       1 scheduler_binder.go:269] AssumePodVolumes for pod "svcaccounts-2293/pod-service-account-defaultsa", node "e2e-test-peterhornyack-windows-node-group-7n03"
I0319 18:44:43.438981       1 scheduler_binder.go:279] AssumePodVolumes for pod "svcaccounts-2293/pod-service-account-defaultsa", node "e2e-test-peterhornyack-windows-node-group-7n03": all PVCs bound and nothing to do
I0319 18:44:43.439074       1 factory.go:733] Attempting to bind pod-service-account-defaultsa to e2e-test-peterhornyack-windows-node-group-7n03
I0319 18:44:43.446867       1 scheduler.go:572] pod svcaccounts-2293/pod-service-account-defaultsa is bound successfully on node e2e-test-peterhornyack-windows-node-group-7n03, 5 nodes evaluated, 2 nodes were found feasible
I0319 18:44:43.480383       1 scheduling_queue.go:908] About to try and schedule pod svcaccounts-2293/pod-service-account-mountsa
I0319 18:44:43.480419       1 scheduler.go:453] Attempting to schedule pod: svcaccounts-2293/pod-service-account-mountsa
I0319 18:44:43.482567       1 scheduler_binder.go:269] AssumePodVolumes for pod "svcaccounts-2293/pod-service-account-mountsa", node "e2e-test-peterhornyack-windows-node-group-7n03"
I0319 18:44:43.482607       1 scheduler_binder.go:279] AssumePodVolumes for pod "svcaccounts-2293/pod-service-account-mountsa", node "e2e-test-peterhornyack-windows-node-group-7n03": all PVCs bound and nothing to do
I0319 18:44:43.482650       1 factory.go:733] Attempting to bind pod-service-account-mountsa to e2e-test-peterhornyack-windows-node-group-7n03
I0319 18:44:43.490976       1 scheduler.go:572] pod svcaccounts-2293/pod-service-account-mountsa is bound successfully on node e2e-test-peterhornyack-windows-node-group-7n03, 5 nodes evaluated, 2 nodes were found feasible
I0319 18:44:43.525292       1 scheduling_queue.go:908] About to try and schedule pod svcaccounts-2293/pod-service-account-nomountsa
I0319 18:44:43.525336       1 scheduler.go:453] Attempting to schedule pod: svcaccounts-2293/pod-service-account-nomountsa
I0319 18:44:43.525611       1 scheduler_binder.go:269] AssumePodVolumes for pod "svcaccounts-2293/pod-service-account-nomountsa", node "e2e-test-peterhornyack-windows-node-group-7n03"
I0319 18:44:43.525625       1 scheduler_binder.go:279] AssumePodVolumes for pod "svcaccounts-2293/pod-service-account-nomountsa", node "e2e-test-peterhornyack-windows-node-group-7n03": all PVCs bound and nothing to do
I0319 18:44:43.525775       1 factory.go:733] Attempting to bind pod-service-account-nomountsa to e2e-test-peterhornyack-windows-node-group-7n03
I0319 18:44:43.533643       1 scheduler.go:572] pod svcaccounts-2293/pod-service-account-nomountsa is bound successfully on node e2e-test-peterhornyack-windows-node-group-7n03, 5 nodes evaluated, 2 nodes were found feasible
I0319 18:44:43.574891       1 scheduling_queue.go:908] About to try and schedule pod svcaccounts-2293/pod-service-account-defaultsa-mountspec
I0319 18:44:43.574940       1 scheduler.go:453] Attempting to schedule pod: svcaccounts-2293/pod-service-account-defaultsa-mountspec
I0319 18:44:43.575278       1 scheduler_binder.go:269] AssumePodVolumes for pod "svcaccounts-2293/pod-service-account-defaultsa-mountspec", node "e2e-test-peterhornyack-windows-node-group-7n03"
I0319 18:44:43.575305       1 scheduler_binder.go:279] AssumePodVolumes for pod "svcaccounts-2293/pod-service-account-defaultsa-mountspec", node "e2e-test-peterhornyack-windows-node-group-7n03": all PVCs bound and nothing to do
I0319 18:44:43.575364       1 factory.go:733] Attempting to bind pod-service-account-defaultsa-mountspec to e2e-test-peterhornyack-windows-node-group-7n03
I0319 18:44:43.584415       1 scheduler.go:572] pod svcaccounts-2293/pod-service-account-defaultsa-mountspec is bound successfully on node e2e-test-peterhornyack-windows-node-group-7n03, 5 nodes evaluated, 2 nodes were found feasible
I0319 18:44:43.617749       1 scheduling_queue.go:908] About to try and schedule pod svcaccounts-2293/pod-service-account-mountsa-mountspec
I0319 18:44:43.617784       1 scheduler.go:453] Attempting to schedule pod: svcaccounts-2293/pod-service-account-mountsa-mountspec
I0319 18:44:43.620377       1 scheduler_binder.go:269] AssumePodVolumes for pod "svcaccounts-2293/pod-service-account-mountsa-mountspec", node "e2e-test-peterhornyack-windows-node-group-7n03"
I0319 18:44:43.620408       1 scheduler_binder.go:279] AssumePodVolumes for pod "svcaccounts-2293/pod-service-account-mountsa-mountspec", node "e2e-test-peterhornyack-windows-node-group-7n03": all PVCs bound and nothing to do
I0319 18:44:43.620494       1 factory.go:733] Attempting to bind pod-service-account-mountsa-mountspec to e2e-test-peterhornyack-windows-node-group-7n03
I0319 18:44:43.632844       1 scheduler.go:572] pod svcaccounts-2293/pod-service-account-mountsa-mountspec is bound successfully on node e2e-test-peterhornyack-windows-node-group-7n03, 5 nodes evaluated, 2 nodes were found feasible
I0319 18:44:43.678304       1 scheduling_queue.go:908] About to try and schedule pod svcaccounts-2293/pod-service-account-nomountsa-mountspec
I0319 18:44:43.678347       1 scheduler.go:453] Attempting to schedule pod: svcaccounts-2293/pod-service-account-nomountsa-mountspec
I0319 18:44:43.678623       1 scheduler_binder.go:269] AssumePodVolumes for pod "svcaccounts-2293/pod-service-account-nomountsa-mountspec", node "e2e-test-peterhornyack-windows-node-group-7n03"
I0319 18:44:43.678639       1 scheduler_binder.go:279] AssumePodVolumes for pod "svcaccounts-2293/pod-service-account-nomountsa-mountspec", node "e2e-test-peterhornyack-windows-node-group-7n03": all PVCs bound and nothing to do
I0319 18:44:43.678692       1 factory.go:733] Attempting to bind pod-service-account-nomountsa-mountspec to e2e-test-peterhornyack-windows-node-group-7n03
I0319 18:44:43.702279       1 scheduler.go:572] pod svcaccounts-2293/pod-service-account-nomountsa-mountspec is bound successfully on node e2e-test-peterhornyack-windows-node-group-7n03, 5 nodes evaluated, 2 nodes were found feasible
I0319 18:44:43.727923       1 scheduling_queue.go:908] About to try and schedule pod svcaccounts-2293/pod-service-account-defaultsa-nomountspec
I0319 18:44:43.727955       1 scheduler.go:453] Attempting to schedule pod: svcaccounts-2293/pod-service-account-defaultsa-nomountspec
I0319 18:44:43.731532       1 scheduler_binder.go:269] AssumePodVolumes for pod "svcaccounts-2293/pod-service-account-defaultsa-nomountspec", node "e2e-test-peterhornyack-windows-node-group-7n03"
I0319 18:44:43.731567       1 scheduler_binder.go:279] AssumePodVolumes for pod "svcaccounts-2293/pod-service-account-defaultsa-nomountspec", node "e2e-test-peterhornyack-windows-node-group-7n03": all PVCs bound and nothing to do
I0319 18:44:43.731629       1 factory.go:733] Attempting to bind pod-service-account-defaultsa-nomountspec to e2e-test-peterhornyack-windows-node-group-7n03
I0319 18:44:43.749175       1 scheduler.go:572] pod svcaccounts-2293/pod-service-account-defaultsa-nomountspec is bound successfully on node e2e-test-peterhornyack-windows-node-group-7n03, 5 nodes evaluated, 2 nodes were found feasible
I0319 18:44:43.778155       1 scheduling_queue.go:908] About to try and schedule pod svcaccounts-2293/pod-service-account-mountsa-nomountspec
I0319 18:44:43.778264       1 scheduler.go:453] Attempting to schedule pod: svcaccounts-2293/pod-service-account-mountsa-nomountspec
I0319 18:44:43.778636       1 scheduler_binder.go:269] AssumePodVolumes for pod "svcaccounts-2293/pod-service-account-mountsa-nomountspec", node "e2e-test-peterhornyack-windows-node-group-7n03"
I0319 18:44:43.778654       1 scheduler_binder.go:279] AssumePodVolumes for pod "svcaccounts-2293/pod-service-account-mountsa-nomountspec", node "e2e-test-peterhornyack-windows-node-group-7n03": all PVCs bound and nothing to do
I0319 18:44:43.778735       1 factory.go:733] Attempting to bind pod-service-account-mountsa-nomountspec to e2e-test-peterhornyack-windows-node-group-7n03
I0319 18:44:43.811679       1 scheduler.go:572] pod svcaccounts-2293/pod-service-account-mountsa-nomountspec is bound successfully on node e2e-test-peterhornyack-windows-node-group-7n03, 5 nodes evaluated, 2 nodes were found feasible
I0319 18:44:43.823651       1 scheduling_queue.go:908] About to try and schedule pod svcaccounts-2293/pod-service-account-nomountsa-nomountspec
I0319 18:44:43.823699       1 scheduler.go:453] Attempting to schedule pod: svcaccounts-2293/pod-service-account-nomountsa-nomountspec
I0319 18:44:43.824362       1 scheduler_binder.go:269] AssumePodVolumes for pod "svcaccounts-2293/pod-service-account-nomountsa-nomountspec", node "e2e-test-peterhornyack-windows-node-group-7n03"
I0319 18:44:43.824405       1 scheduler_binder.go:279] AssumePodVolumes for pod "svcaccounts-2293/pod-service-account-nomountsa-nomountspec", node "e2e-test-peterhornyack-windows-node-group-7n03": all PVCs bound and nothing to do
I0319 18:44:43.824460       1 factory.go:733] Attempting to bind pod-service-account-nomountsa-nomountspec to e2e-test-peterhornyack-windows-node-group-7n03
I0319 18:44:43.834924       1 scheduler.go:572] pod svcaccounts-2293/pod-service-account-nomountsa-nomountspec is bound successfully on node e2e-test-peterhornyack-windows-node-group-7n03, 5 nodes evaluated, 2 nodes were found feasible
I0319 18:44:50.118335       1 wrap.go:47] GET /healthz: (72.309µs) 200 [kube-probe/1.15+ 127.0.0.1:48188]
I0319 18:45:00.119206       1 wrap.go:47] GET /healthz: (81.474µs) 200 [kube-probe/1.15+ 127.0.0.1:48222]
I0319 18:45:10.117855       1 wrap.go:47] GET /healthz: (76.681µs) 200 [kube-probe/1.15+ 127.0.0.1:48264]
I0319 18:45:20.117745       1 wrap.go:47] GET /healthz: (69.417µs) 200 [kube-probe/1.15+ 127.0.0.1:48298]
I0319 18:45:25.832435       1 scheduling_queue.go:908] About to try and schedule pod projected-3542/downwardapi-volume-28d4fea9-4a77-11e9-af5d-a08cfde32bdd
I0319 18:45:25.832582       1 scheduler.go:453] Attempting to schedule pod: projected-3542/downwardapi-volume-28d4fea9-4a77-11e9-af5d-a08cfde32bdd
I0319 18:45:25.832922       1 scheduler_binder.go:269] AssumePodVolumes for pod "projected-3542/downwardapi-volume-28d4fea9-4a77-11e9-af5d-a08cfde32bdd", node "e2e-test-peterhornyack-windows-node-group-7n03"
I0319 18:45:25.832952       1 scheduler_binder.go:279] AssumePodVolumes for pod "projected-3542/downwardapi-volume-28d4fea9-4a77-11e9-af5d-a08cfde32bdd", node "e2e-test-peterhornyack-windows-node-group-7n03": all PVCs bound and nothing to do
I0319 18:45:25.833002       1 factory.go:733] Attempting to bind downwardapi-volume-28d4fea9-4a77-11e9-af5d-a08cfde32bdd to e2e-test-peterhornyack-windows-node-group-7n03
I0319 18:45:25.840636       1 scheduler.go:572] pod projected-3542/downwardapi-volume-28d4fea9-4a77-11e9-af5d-a08cfde32bdd is bound successfully on node e2e-test-peterhornyack-windows-node-group-7n03, 5 nodes evaluated, 2 nodes were found feasible
I0319 18:45:30.118051       1 wrap.go:47] GET /healthz: (71.421µs) 200 [kube-probe/1.15+ 127.0.0.1:48332]
I0319 18:45:40.090401       1 reflector.go:370] k8s.io/client-go/informers/factory.go:133: Watch close - *v1.PersistentVolume total 0 items received
I0319 18:45:40.118013       1 wrap.go:47] GET /healthz: (88.011µs) 200 [kube-probe/1.15+ 127.0.0.1:48382]
I0319 18:45:50.117941       1 wrap.go:47] GET /healthz: (97.419µs) 200 [kube-probe/1.15+ 127.0.0.1:48414]
I0319 18:46:00.118216       1 wrap.go:47] GET /healthz: (87.234µs) 200 [kube-probe/1.15+ 127.0.0.1:48448]
I0319 18:46:10.117964       1 wrap.go:47] GET /healthz: (75.427µs) 200 [kube-probe/1.15+ 127.0.0.1:48492]
I0319 18:46:20.118374       1 wrap.go:47] GET /healthz: (86.693µs) 200 [kube-probe/1.15+ 127.0.0.1:48524]
I0319 18:46:30.118267       1 wrap.go:47] GET /healthz: (72.04µs) 200 [kube-probe/1.15+ 127.0.0.1:48560]
I0319 18:46:40.118174       1 wrap.go:47] GET /healthz: (81.27µs) 200 [kube-probe/1.15+ 127.0.0.1:48608]
I0319 18:46:47.679611       1 scheduling_queue.go:908] About to try and schedule pod replicaset-7270/my-hostname-basic-599bca0c-4a77-11e9-af5d-a08cfde32bdd-cqjgl
I0319 18:46:47.679653       1 scheduler.go:453] Attempting to schedule pod: replicaset-7270/my-hostname-basic-599bca0c-4a77-11e9-af5d-a08cfde32bdd-cqjgl
I0319 18:46:47.688219       1 scheduler_binder.go:269] AssumePodVolumes for pod "replicaset-7270/my-hostname-basic-599bca0c-4a77-11e9-af5d-a08cfde32bdd-cqjgl", node "e2e-test-peterhornyack-windows-node-group-7n03"
I0319 18:46:47.688274       1 scheduler_binder.go:279] AssumePodVolumes for pod "replicaset-7270/my-hostname-basic-599bca0c-4a77-11e9-af5d-a08cfde32bdd-cqjgl", node "e2e-test-peterhornyack-windows-node-group-7n03": all PVCs bound and nothing to do
I0319 18:46:47.688346       1 factory.go:733] Attempting to bind my-hostname-basic-599bca0c-4a77-11e9-af5d-a08cfde32bdd-cqjgl to e2e-test-peterhornyack-windows-node-group-7n03
I0319 18:46:47.703530       1 scheduler.go:572] pod replicaset-7270/my-hostname-basic-599bca0c-4a77-11e9-af5d-a08cfde32bdd-cqjgl is bound successfully on node e2e-test-peterhornyack-windows-node-group-7n03, 5 nodes evaluated, 2 nodes were found feasible
I0319 18:46:50.119368       1 wrap.go:47] GET /healthz: (74.993µs) 200 [kube-probe/1.15+ 127.0.0.1:48640]
I0319 18:46:52.152851       1 reflector.go:370] k8s.io/client-go/informers/factory.go:133: Watch close - *v1.ReplicationController total 6 items received
I0319 18:47:00.117866       1 wrap.go:47] GET /healthz: (71.581µs) 200 [kube-probe/1.15+ 127.0.0.1:48676]
I0319 18:47:09.207366       1 scheduling_queue.go:908] About to try and schedule pod container-probe-6088/test-webserver-6672a001-4a77-11e9-af5d-a08cfde32bdd
I0319 18:47:09.207410       1 scheduler.go:453] Attempting to schedule pod: container-probe-6088/test-webserver-6672a001-4a77-11e9-af5d-a08cfde32bdd
I0319 18:47:09.208545       1 scheduler_binder.go:269] AssumePodVolumes for pod "container-probe-6088/test-webserver-6672a001-4a77-11e9-af5d-a08cfde32bdd", node "e2e-test-peterhornyack-windows-node-group-7n03"
I0319 18:47:09.208594       1 scheduler_binder.go:279] AssumePodVolumes for pod "container-probe-6088/test-webserver-6672a001-4a77-11e9-af5d-a08cfde32bdd", node "e2e-test-peterhornyack-windows-node-group-7n03": all PVCs bound and nothing to do
I0319 18:47:09.208642       1 factory.go:733] Attempting to bind test-webserver-6672a001-4a77-11e9-af5d-a08cfde32bdd to e2e-test-peterhornyack-windows-node-group-7n03
I0319 18:47:09.217562       1 scheduler.go:572] pod container-probe-6088/test-webserver-6672a001-4a77-11e9-af5d-a08cfde32bdd is bound successfully on node e2e-test-peterhornyack-windows-node-group-7n03, 5 nodes evaluated, 2 nodes were found feasible
I0319 18:47:10.118074       1 wrap.go:47] GET /healthz: (87.954µs) 200 [kube-probe/1.15+ 127.0.0.1:48720]
I0319 18:47:20.117990       1 wrap.go:47] GET /healthz: (65.55µs) 200 [kube-probe/1.15+ 127.0.0.1:48752]
I0319 18:47:30.118016       1 wrap.go:47] GET /healthz: (140.7µs) 200 [kube-probe/1.15+ 127.0.0.1:48786]
I0319 18:47:33.145992       1 reflector.go:370] k8s.io/client-go/informers/factory.go:133: Watch close - *v1.Service total 2 items received
I0319 18:47:37.083843       1 reflector.go:370] k8s.io/kubernetes/cmd/kube-scheduler/app/server.go:223: Watch close - *v1.Pod total 158 items received
I0319 18:47:40.117814       1 wrap.go:47] GET /healthz: (74.445µs) 200 [kube-probe/1.15+ 127.0.0.1:48834]
I0319 18:47:44.081127       1 reflector.go:370] k8s.io/client-go/informers/factory.go:133: Watch close - *v1.StatefulSet total 6 items received
I0319 18:47:50.117970       1 wrap.go:47] GET /healthz: (75.992µs) 200 [kube-probe/1.15+ 127.0.0.1:48868]
I0319 18:48:00.118224       1 wrap.go:47] GET /healthz: (74.835µs) 200 [kube-probe/1.15+ 127.0.0.1:48906]
I0319 18:48:01.715832       1 scheduling_queue.go:908] About to try and schedule pod volume-977/exec-volume-test-gcepd-dynamicpv-4dkg
I0319 18:48:01.715867       1 scheduler.go:453] Attempting to schedule pod: volume-977/exec-volume-test-gcepd-dynamicpv-4dkg
I0319 18:48:01.717956       1 csi_volume_predicate.go:147] Not considering non-CSI volume volume-977/pvc-fzxlh
I0319 18:48:01.718551       1 scheduler_binder.go:665] All bound volumes for Pod "volume-977/exec-volume-test-gcepd-dynamicpv-4dkg" match with Node "e2e-test-peterhornyack-windows-node-group-7n03"
I0319 18:48:01.718643       1 csi_volume_predicate.go:147] Not considering non-CSI volume volume-977/pvc-fzxlh
I0319 18:48:01.718669       1 scheduler_binder.go:665] All bound volumes for Pod "volume-977/exec-volume-test-gcepd-dynamicpv-4dkg" match with Node "e2e-test-peterhornyack-windows-node-group-dp2r"
I0319 18:48:01.720351       1 scheduler_binder.go:269] AssumePodVolumes for pod "volume-977/exec-volume-test-gcepd-dynamicpv-4dkg", node "e2e-test-peterhornyack-windows-node-group-7n03"
I0319 18:48:01.720373       1 scheduler_binder.go:279] AssumePodVolumes for pod "volume-977/exec-volume-test-gcepd-dynamicpv-4dkg", node "e2e-test-peterhornyack-windows-node-group-7n03": all PVCs bound and nothing to do
I0319 18:48:01.720440       1 factory.go:733] Attempting to bind exec-volume-test-gcepd-dynamicpv-4dkg to e2e-test-peterhornyack-windows-node-group-7n03
I0319 18:48:01.729104       1 scheduler.go:572] pod volume-977/exec-volume-test-gcepd-dynamicpv-4dkg is bound successfully on node e2e-test-peterhornyack-windows-node-group-7n03, 5 nodes evaluated, 2 nodes were found feasible
I0319 18:48:10.118108       1 wrap.go:47] GET /healthz: (93.827µs) 200 [kube-probe/1.15+ 127.0.0.1:48948]
I0319 18:48:20.117885       1 wrap.go:47] GET /healthz: (80.853µs) 200 [kube-probe/1.15+ 127.0.0.1:48980]
I0319 18:48:30.118129       1 wrap.go:47] GET /healthz: (87.542µs) 200 [kube-probe/1.15+ 127.0.0.1:49018]
I0319 18:48:40.118132       1 wrap.go:47] GET /healthz: (98.921µs) 200 [kube-probe/1.15+ 127.0.0.1:49066]
I0319 18:48:46.128289       1 reflector.go:370] k8s.io/client-go/informers/factory.go:133: Watch close - *v1.PersistentVolumeClaim total 6 items received
I0319 18:48:48.127217       1 reflector.go:370] k8s.io/client-go/informers/factory.go:133: Watch close - *v1.ReplicaSet total 8 items received
I0319 18:48:50.117855       1 wrap.go:47] GET /healthz: (117.362µs) 200 [kube-probe/1.15+ 127.0.0.1:49098]
I0319 18:48:54.119441       1 reflector.go:370] k8s.io/client-go/informers/factory.go:133: Watch close - *v1.Node total 57 items received
I0319 18:49:00.120202       1 wrap.go:47] GET /healthz: (73.46µs) 200 [kube-probe/1.15+ 127.0.0.1:49134]
I0319 18:49:03.127982       1 scheduling_queue.go:908] About to try and schedule pod projected-783/pod-projected-configmaps-aa5a09d1-4a77-11e9-af5d-a08cfde32bdd
I0319 18:49:03.128013       1 scheduler.go:453] Attempting to schedule pod: projected-783/pod-projected-configmaps-aa5a09d1-4a77-11e9-af5d-a08cfde32bdd
I0319 18:49:03.129601       1 scheduler_binder.go:269] AssumePodVolumes for pod "projected-783/pod-projected-configmaps-aa5a09d1-4a77-11e9-af5d-a08cfde32bdd", node "e2e-test-peterhornyack-windows-node-group-7n03"
I0319 18:49:03.129643       1 scheduler_binder.go:279] AssumePodVolumes for pod "projected-783/pod-projected-configmaps-aa5a09d1-4a77-11e9-af5d-a08cfde32bdd", node "e2e-test-peterhornyack-windows-node-group-7n03": all PVCs bound and nothing to do
I0319 18:49:03.129684       1 factory.go:733] Attempting to bind pod-projected-configmaps-aa5a09d1-4a77-11e9-af5d-a08cfde32bdd to e2e-test-peterhornyack-windows-node-group-7n03
I0319 18:49:03.140541       1 scheduler.go:572] pod projected-783/pod-projected-configmaps-aa5a09d1-4a77-11e9-af5d-a08cfde32bdd is bound successfully on node e2e-test-peterhornyack-windows-node-group-7n03, 5 nodes evaluated, 2 nodes were found feasible
I0319 18:49:10.118013       1 wrap.go:47] GET /healthz: (68.582µs) 200 [kube-probe/1.15+ 127.0.0.1:49172]
I0319 18:49:19.606820       1 scheduling_queue.go:908] About to try and schedule pod gc-7312/simpletest-rc-to-be-deleted-f2f56
I0319 18:49:19.606854       1 scheduler.go:453] Attempting to schedule pod: gc-7312/simpletest-rc-to-be-deleted-f2f56
I0319 18:49:19.608593       1 scheduler_binder.go:269] AssumePodVolumes for pod "gc-7312/simpletest-rc-to-be-deleted-f2f56", node "e2e-test-peterhornyack-windows-node-group-7n03"
I0319 18:49:19.608622       1 scheduler_binder.go:279] AssumePodVolumes for pod "gc-7312/simpletest-rc-to-be-deleted-f2f56", node "e2e-test-peterhornyack-windows-node-group-7n03": all PVCs bound and nothing to do
I0319 18:49:19.611110       1 factory.go:733] Attempting to bind simpletest-rc-to-be-deleted-f2f56 to e2e-test-peterhornyack-windows-node-group-7n03
I0319 18:49:19.621281       1 scheduling_queue.go:908] About to try and schedule pod gc-7312/simpletest-rc-to-be-deleted-v5679
I0319 18:49:19.621308       1 scheduler.go:453] Attempting to schedule pod: gc-7312/simpletest-rc-to-be-deleted-v5679
I0319 18:49:19.621560       1 scheduler_binder.go:269] AssumePodVolumes for pod "gc-7312/simpletest-rc-to-be-deleted-v5679", node "e2e-test-peterhornyack-windows-node-group-dp2r"
I0319 18:49:19.621584       1 scheduler_binder.go:279] AssumePodVolumes for pod "gc-7312/simpletest-rc-to-be-deleted-v5679", node "e2e-test-peterhornyack-windows-node-group-dp2r": all PVCs bound and nothing to do
I0319 18:49:19.621619       1 factory.go:733] Attempting to bind simpletest-rc-to-be-deleted-v5679 to e2e-test-peterhornyack-windows-node-group-dp2r
I0319 18:49:19.664339       1 scheduler.go:572] pod gc-7312/simpletest-rc-to-be-deleted-f2f56 is bound successfully on node e2e-test-peterhornyack-windows-node-group-7n03, 5 nodes evaluated, 2 nodes were found feasible
I0319 18:49:19.664674       1 scheduling_queue.go:908] About to try and schedule pod gc-7312/simpletest-rc-to-be-deleted-r2z6l
I0319 18:49:19.665155       1 scheduler.go:453] Attempting to schedule pod: gc-7312/simpletest-rc-to-be-deleted-r2z6l
I0319 18:49:19.665517       1 scheduler_binder.go:269] AssumePodVolumes for pod "gc-7312/simpletest-rc-to-be-deleted-r2z6l", node "e2e-test-peterhornyack-windows-node-group-7n03"
I0319 18:49:19.665534       1 scheduler_binder.go:279] AssumePodVolumes for pod "gc-7312/simpletest-rc-to-be-deleted-r2z6l", node "e2e-test-peterhornyack-windows-node-group-7n03": all PVCs bound and nothing to do
I0319 18:49:19.665581       1 factory.go:733] Attempting to bind simpletest-rc-to-be-deleted-r2z6l to e2e-test-peterhornyack-windows-node-group-7n03
I0319 18:49:19.722365       1 scheduler.go:572] pod gc-7312/simpletest-rc-to-be-deleted-v5679 is bound successfully on node e2e-test-peterhornyack-windows-node-group-dp2r, 5 nodes evaluated, 2 nodes were found feasible
I0319 18:49:19.776339       1 scheduler.go:572] pod gc-7312/simpletest-rc-to-be-deleted-r2z6l is bound successfully on node e2e-test-peterhornyack-windows-node-group-7n03, 5 nodes evaluated, 2 nodes were found feasible
I0319 18:49:19.783857       1 scheduling_queue.go:908] About to try and schedule pod gc-7312/simpletest-rc-to-be-deleted-d9nq5
I0319 18:49:19.783884       1 scheduler.go:453] Attempting to schedule pod: gc-7312/simpletest-rc-to-be-deleted-d9nq5
I0319 18:49:19.785632       1 scheduler_binder.go:269] AssumePodVolumes for pod "gc-7312/simpletest-rc-to-be-deleted-d9nq5", node "e2e-test-peterhornyack-windows-node-group-dp2r"
I0319 18:49:19.785658       1 scheduler_binder.go:279] AssumePodVolumes for pod "gc-7312/simpletest-rc-to-be-deleted-d9nq5", node "e2e-test-peterhornyack-windows-node-group-dp2r": all PVCs bound and nothing to do
I0319 18:49:19.785699       1 factory.go:733] Attempting to bind simpletest-rc-to-be-deleted-d9nq5 to e2e-test-peterhornyack-windows-node-group-dp2r
I0319 18:49:19.791358       1 scheduling_queue.go:908] About to try and schedule pod gc-7312/simpletest-rc-to-be-deleted-9gczj
I0319 18:49:19.791400       1 scheduler.go:453] Attempting to schedule pod: gc-7312/simpletest-rc-to-be-deleted-9gczj
I0319 18:49:19.791718       1 scheduler_binder.go:269] AssumePodVolumes for pod "gc-7312/simpletest-rc-to-be-deleted-9gczj", node "e2e-test-peterhornyack-windows-node-group-7n03"
I0319 18:49:19.791736       1 scheduler_binder.go:279] AssumePodVolumes for pod "gc-7312/simpletest-rc-to-be-deleted-9gczj", node "e2e-test-peterhornyack-windows-node-group-7n03": all PVCs bound and nothing to do
I0319 18:49:19.791785       1 factory.go:733] Attempting to bind simpletest-rc-to-be-deleted-9gczj to e2e-test-peterhornyack-windows-node-group-7n03
I0319 18:49:19.794405       1 scheduling_queue.go:908] About to try and schedule pod gc-7312/simpletest-rc-to-be-deleted-9zp54
I0319 18:49:19.794443       1 scheduler.go:453] Attempting to schedule pod: gc-7312/simpletest-rc-to-be-deleted-9zp54
I0319 18:49:19.794727       1 scheduler_binder.go:269] AssumePodVolumes for pod "gc-7312/simpletest-rc-to-be-deleted-9zp54", node "e2e-test-peterhornyack-windows-node-group-dp2r"
I0319 18:49:19.794743       1 scheduler_binder.go:279] AssumePodVolumes for pod "gc-7312/simpletest-rc-to-be-deleted-9zp54", node "e2e-test-peterhornyack-windows-node-group-dp2r": all PVCs bound and nothing to do
I0319 18:49:19.794793       1 factory.go:733] Attempting to bind simpletest-rc-to-be-deleted-9zp54 to e2e-test-peterhornyack-windows-node-group-dp2r
I0319 18:49:19.795005       1 scheduling_queue.go:908] About to try and schedule pod gc-7312/simpletest-rc-to-be-deleted-bsbks
I0319 18:49:19.795016       1 scheduler.go:453] Attempting to schedule pod: gc-7312/simpletest-rc-to-be-deleted-bsbks
I0319 18:49:19.801387       1 scheduler_binder.go:269] AssumePodVolumes for pod "gc-7312/simpletest-rc-to-be-deleted-bsbks", node "e2e-test-peterhornyack-windows-node-group-7n03"
I0319 18:49:19.801416       1 scheduler_binder.go:279] AssumePodVolumes for pod "gc-7312/simpletest-rc-to-be-deleted-bsbks", node "e2e-test-peterhornyack-windows-node-group-7n03": all PVCs bound and nothing to do
I0319 18:49:19.801448       1 factory.go:733] Attempting to bind simpletest-rc-to-be-deleted-bsbks to e2e-test-peterhornyack-windows-node-group-7n03
I0319 18:49:19.894212       1 scheduler.go:572] pod gc-7312/simpletest-rc-to-be-deleted-9gczj is bound successfully on node e2e-test-peterhornyack-windows-node-group-7n03, 5 nodes evaluated, 2 nodes were found feasible
I0319 18:49:19.909730       1 scheduler.go:572] pod gc-7312/simpletest-rc-to-be-deleted-d9nq5 is bound successfully on node e2e-test-peterhornyack-windows-node-group-dp2r, 5 nodes evaluated, 2 nodes were found feasible
I0319 18:49:19.909804       1 scheduler.go:572] pod gc-7312/simpletest-rc-to-be-deleted-bsbks is bound successfully on node e2e-test-peterhornyack-windows-node-group-7n03, 5 nodes evaluated, 2 nodes were found feasible
I0319 18:49:19.933107       1 scheduling_queue.go:908] About to try and schedule pod gc-7312/simpletest-rc-to-be-deleted-tw8mm
I0319 18:49:19.933162       1 scheduler.go:453] Attempting to schedule pod: gc-7312/simpletest-rc-to-be-deleted-tw8mm
I0319 18:49:19.934182       1 scheduler_binder.go:269] AssumePodVolumes for pod "gc-7312/simpletest-rc-to-be-deleted-tw8mm", node "e2e-test-peterhornyack-windows-node-group-dp2r"
I0319 18:49:19.934208       1 scheduler_binder.go:279] AssumePodVolumes for pod "gc-7312/simpletest-rc-to-be-deleted-tw8mm", node "e2e-test-peterhornyack-windows-node-group-dp2r": all PVCs bound and nothing to do
I0319 18:49:19.934261       1 factory.go:733] Attempting to bind simpletest-rc-to-be-deleted-tw8mm to e2e-test-peterhornyack-windows-node-group-dp2r
I0319 18:49:19.940151       1 scheduling_queue.go:908] About to try and schedule pod gc-7312/simpletest-rc-to-be-deleted-ps6kz
I0319 18:49:19.940708       1 scheduler.go:453] Attempting to schedule pod: gc-7312/simpletest-rc-to-be-deleted-ps6kz
I0319 18:49:19.946091       1 scheduler_binder.go:269] AssumePodVolumes for pod "gc-7312/simpletest-rc-to-be-deleted-ps6kz", node "e2e-test-peterhornyack-windows-node-group-7n03"
I0319 18:49:19.946129       1 scheduler_binder.go:279] AssumePodVolumes for pod "gc-7312/simpletest-rc-to-be-deleted-ps6kz", node "e2e-test-peterhornyack-windows-node-group-7n03": all PVCs bound and nothing to do
I0319 18:49:19.946201       1 factory.go:733] Attempting to bind simpletest-rc-to-be-deleted-ps6kz to e2e-test-peterhornyack-windows-node-group-7n03
I0319 18:49:19.946595       1 scheduling_queue.go:908] About to try and schedule pod gc-7312/simpletest-rc-to-be-deleted-9q4xk
I0319 18:49:19.946622       1 scheduler.go:453] Attempting to schedule pod: gc-7312/simpletest-rc-to-be-deleted-9q4xk
I0319 18:49:19.946904       1 scheduler_binder.go:269] AssumePodVolumes for pod "gc-7312/simpletest-rc-to-be-deleted-9q4xk", node "e2e-test-peterhornyack-windows-node-group-dp2r"
I0319 18:49:19.946918       1 scheduler_binder.go:279] AssumePodVolumes for pod "gc-7312/simpletest-rc-to-be-deleted-9q4xk", node "e2e-test-peterhornyack-windows-node-group-dp2r": all PVCs bound and nothing to do
I0319 18:49:19.946941       1 factory.go:733] Attempting to bind simpletest-rc-to-be-deleted-9q4xk to e2e-test-peterhornyack-windows-node-group-dp2r
I0319 18:49:19.971492       1 scheduler.go:572] pod gc-7312/simpletest-rc-to-be-deleted-9zp54 is bound successfully on node e2e-test-peterhornyack-windows-node-group-dp2r, 5 nodes evaluated, 2 nodes were found feasible
I0319 18:49:20.055052       1 scheduler.go:572] pod gc-7312/simpletest-rc-to-be-deleted-tw8mm is bound successfully on node e2e-test-peterhornyack-windows-node-group-dp2r, 5 nodes evaluated, 2 nodes were found feasible
I0319 18:49:20.074273       1 scheduler.go:572] pod gc-7312/simpletest-rc-to-be-deleted-ps6kz is bound successfully on node e2e-test-peterhornyack-windows-node-group-7n03, 5 nodes evaluated, 2 nodes were found feasible
I0319 18:49:20.104377       1 scheduler.go:572] pod gc-7312/simpletest-rc-to-be-deleted-9q4xk is bound successfully on node e2e-test-peterhornyack-windows-node-group-dp2r, 5 nodes evaluated, 2 nodes were found feasible
I0319 18:49:20.118417       1 wrap.go:47] GET /healthz: (64.312µs) 200 [kube-probe/1.15+ 127.0.0.1:49204]
I0319 18:49:30.117683       1 wrap.go:47] GET /healthz: (86.526µs) 200 [kube-probe/1.15+ 127.0.0.1:49238]
I0319 18:49:36.143213       1 reflector.go:370] k8s.io/client-go/informers/factory.go:133: Watch close - *v1beta1.PodDisruptionBudget total 0 items received
I0319 18:49:40.117884       1 wrap.go:47] GET /healthz: (70.367µs) 200 [kube-probe/1.15+ 127.0.0.1:49286]
I0319 18:49:46.502117       1 scheduling_queue.go:908] About to try and schedule pod events-6449/send-events-c43423d1-4a77-11e9-af5d-a08cfde32bdd
I0319 18:49:46.502161       1 scheduler.go:453] Attempting to schedule pod: events-6449/send-events-c43423d1-4a77-11e9-af5d-a08cfde32bdd
I0319 18:49:46.502502       1 scheduler_binder.go:269] AssumePodVolumes for pod "events-6449/send-events-c43423d1-4a77-11e9-af5d-a08cfde32bdd", node "e2e-test-peterhornyack-windows-node-group-7n03"
I0319 18:49:46.502520       1 scheduler_binder.go:279] AssumePodVolumes for pod "events-6449/send-events-c43423d1-4a77-11e9-af5d-a08cfde32bdd", node "e2e-test-peterhornyack-windows-node-group-7n03": all PVCs bound and nothing to do
I0319 18:49:46.502574       1 factory.go:733] Attempting to bind send-events-c43423d1-4a77-11e9-af5d-a08cfde32bdd to e2e-test-peterhornyack-windows-node-group-7n03
I0319 18:49:46.509909       1 scheduler.go:572] pod events-6449/send-events-c43423d1-4a77-11e9-af5d-a08cfde32bdd is bound successfully on node e2e-test-peterhornyack-windows-node-group-7n03, 5 nodes evaluated, 2 nodes were found feasible
I0319 18:49:47.131484       1 reflector.go:370] k8s.io/client-go/informers/factory.go:133: Watch close - *v1.StorageClass total 2 items received
I0319 18:49:50.118104       1 wrap.go:47] GET /healthz: (93.571µs) 200 [kube-probe/1.15+ 127.0.0.1:49320]
I0319 18:50:00.117595       1 wrap.go:47] GET /healthz: (78.352µs) 200 [kube-probe/1.15+ 127.0.0.1:49354]
I0319 18:50:10.117841       1 wrap.go:47] GET /healthz: (76.694µs) 200 [kube-probe/1.15+ 127.0.0.1:49394]
I0319 18:50:20.117827       1 wrap.go:47] GET /healthz: (72.132µs) 200 [kube-probe/1.15+ 127.0.0.1:49426]
I0319 18:50:27.746428       1 scheduling_queue.go:908] About to try and schedule pod kubectl-3955/pause
I0319 18:50:27.746471       1 scheduler.go:453] Attempting to schedule pod: kubectl-3955/pause
I0319 18:50:27.748292       1 scheduler_binder.go:269] AssumePodVolumes for pod "kubectl-3955/pause", node "e2e-test-peterhornyack-windows-node-group-dp2r"
I0319 18:50:27.748350       1 scheduler_binder.go:279] AssumePodVolumes for pod "kubectl-3955/pause", node "e2e-test-peterhornyack-windows-node-group-dp2r": all PVCs bound and nothing to do
I0319 18:50:27.748401       1 factory.go:733] Attempting to bind pause to e2e-test-peterhornyack-windows-node-group-dp2r
I0319 18:50:27.756949       1 scheduler.go:572] pod kubectl-3955/pause is bound successfully on node e2e-test-peterhornyack-windows-node-group-dp2r, 5 nodes evaluated, 2 nodes were found feasible
I0319 18:50:30.117815       1 wrap.go:47] GET /healthz: (78.975µs) 200 [kube-probe/1.15+ 127.0.0.1:49460]
I0319 18:50:40.117888       1 wrap.go:47] GET /healthz: (125.298µs) 200 [kube-probe/1.15+ 127.0.0.1:49508]
I0319 18:50:45.929993       1 scheduling_queue.go:908] About to try and schedule pod configmap-5407/pod-configmaps-e7a0bfd3-4a77-11e9-af5d-a08cfde32bdd
I0319 18:50:45.932111       1 scheduler.go:453] Attempting to schedule pod: configmap-5407/pod-configmaps-e7a0bfd3-4a77-11e9-af5d-a08cfde32bdd
I0319 18:50:45.932452       1 scheduler_binder.go:269] AssumePodVolumes for pod "configmap-5407/pod-configmaps-e7a0bfd3-4a77-11e9-af5d-a08cfde32bdd", node "e2e-test-peterhornyack-windows-node-group-7n03"
I0319 18:50:45.932484       1 scheduler_binder.go:279] AssumePodVolumes for pod "configmap-5407/pod-configmaps-e7a0bfd3-4a77-11e9-af5d-a08cfde32bdd", node "e2e-test-peterhornyack-windows-node-group-7n03": all PVCs bound and nothing to do
I0319 18:50:45.934138       1 factory.go:733] Attempting to bind pod-configmaps-e7a0bfd3-4a77-11e9-af5d-a08cfde32bdd to e2e-test-peterhornyack-windows-node-group-7n03
I0319 18:50:45.943233       1 scheduler.go:572] pod configmap-5407/pod-configmaps-e7a0bfd3-4a77-11e9-af5d-a08cfde32bdd is bound successfully on node e2e-test-peterhornyack-windows-node-group-7n03, 5 nodes evaluated, 2 nodes were found feasible
I0319 18:50:50.118965       1 wrap.go:47] GET /healthz: (72.728µs) 200 [kube-probe/1.15+ 127.0.0.1:49540]
I0319 18:51:00.118105       1 wrap.go:47] GET /healthz: (99.489µs) 200 [kube-probe/1.15+ 127.0.0.1:49574]
I0319 18:51:10.117900       1 wrap.go:47] GET /healthz: (67.757µs) 200 [kube-probe/1.15+ 127.0.0.1:49616]
I0319 18:51:10.373346       1 scheduling_queue.go:908] About to try and schedule pod pods-9112/pod-exec-websocket-f63207df-4a77-11e9-af5d-a08cfde32bdd
I0319 18:51:10.373393       1 scheduler.go:453] Attempting to schedule pod: pods-9112/pod-exec-websocket-f63207df-4a77-11e9-af5d-a08cfde32bdd
I0319 18:51:10.373694       1 scheduler_binder.go:269] AssumePodVolumes for pod "pods-9112/pod-exec-websocket-f63207df-4a77-11e9-af5d-a08cfde32bdd", node "e2e-test-peterhornyack-windows-node-group-dp2r"
I0319 18:51:10.373733       1 scheduler_binder.go:279] AssumePodVolumes for pod "pods-9112/pod-exec-websocket-f63207df-4a77-11e9-af5d-a08cfde32bdd", node "e2e-test-peterhornyack-windows-node-group-dp2r": all PVCs bound and nothing to do
I0319 18:51:10.373780       1 factory.go:733] Attempting to bind pod-exec-websocket-f63207df-4a77-11e9-af5d-a08cfde32bdd to e2e-test-peterhornyack-windows-node-group-dp2r
I0319 18:51:10.385513       1 scheduler.go:572] pod pods-9112/pod-exec-websocket-f63207df-4a77-11e9-af5d-a08cfde32bdd is bound successfully on node e2e-test-peterhornyack-windows-node-group-dp2r, 5 nodes evaluated, 2 nodes were found feasible
I0319 18:51:20.117934       1 wrap.go:47] GET /healthz: (69.606µs) 200 [kube-probe/1.15+ 127.0.0.1:49650]
I0319 18:51:30.117838       1 wrap.go:47] GET /healthz: (59.114µs) 200 [kube-probe/1.15+ 127.0.0.1:49686]
I0319 18:51:40.117788       1 wrap.go:47] GET /healthz: (68.44µs) 200 [kube-probe/1.15+ 127.0.0.1:49734]
I0319 18:51:50.117844       1 wrap.go:47] GET /healthz: (74.543µs) 200 [kube-probe/1.15+ 127.0.0.1:49766]
I0319 18:51:50.873552       1 scheduling_queue.go:908] About to try and schedule pod downward-api-3204/downward-api-0e55b50c-4a78-11e9-af5d-a08cfde32bdd
I0319 18:51:50.873584       1 scheduler.go:453] Attempting to schedule pod: downward-api-3204/downward-api-0e55b50c-4a78-11e9-af5d-a08cfde32bdd
I0319 18:51:50.874218       1 scheduler_binder.go:269] AssumePodVolumes for pod "downward-api-3204/downward-api-0e55b50c-4a78-11e9-af5d-a08cfde32bdd", node "e2e-test-peterhornyack-windows-node-group-7n03"
I0319 18:51:50.874244       1 scheduler_binder.go:279] AssumePodVolumes for pod "downward-api-3204/downward-api-0e55b50c-4a78-11e9-af5d-a08cfde32bdd", node "e2e-test-peterhornyack-windows-node-group-7n03": all PVCs bound and nothing to do
I0319 18:51:50.874949       1 factory.go:733] Attempting to bind downward-api-0e55b50c-4a78-11e9-af5d-a08cfde32bdd to e2e-test-peterhornyack-windows-node-group-7n03
I0319 18:51:50.883216       1 scheduler.go:572] pod downward-api-3204/downward-api-0e55b50c-4a78-11e9-af5d-a08cfde32bdd is bound successfully on node e2e-test-peterhornyack-windows-node-group-7n03, 5 nodes evaluated, 2 nodes were found feasible
I0319 18:51:55.156697       1 reflector.go:370] k8s.io/client-go/informers/factory.go:133: Watch close - *v1.ReplicationController total 16 items received
I0319 18:52:00.117839       1 wrap.go:47] GET /healthz: (54.446µs) 200 [kube-probe/1.15+ 127.0.0.1:49800]
I0319 18:52:07.316935       1 scheduling_queue.go:908] About to try and schedule pod container-lifecycle-hook-3809/pod-handle-http-request
I0319 18:52:07.316961       1 scheduler.go:453] Attempting to schedule pod: container-lifecycle-hook-3809/pod-handle-http-request
I0319 18:52:07.317273       1 scheduler_binder.go:269] AssumePodVolumes for pod "container-lifecycle-hook-3809/pod-handle-http-request", node "e2e-test-peterhornyack-windows-node-group-dp2r"
I0319 18:52:07.317304       1 scheduler_binder.go:279] AssumePodVolumes for pod "container-lifecycle-hook-3809/pod-handle-http-request", node "e2e-test-peterhornyack-windows-node-group-dp2r": all PVCs bound and nothing to do
I0319 18:52:07.317355       1 factory.go:733] Attempting to bind pod-handle-http-request to e2e-test-peterhornyack-windows-node-group-dp2r
I0319 18:52:07.336409       1 scheduler.go:572] pod container-lifecycle-hook-3809/pod-handle-http-request is bound successfully on node e2e-test-peterhornyack-windows-node-group-dp2r, 5 nodes evaluated, 2 nodes were found feasible
I0319 18:52:10.117935       1 wrap.go:47] GET /healthz: (70.301µs) 200 [kube-probe/1.15+ 127.0.0.1:49838]
I0319 18:52:15.502770       1 scheduling_queue.go:908] About to try and schedule pod container-lifecycle-hook-3809/pod-with-poststart-http-hook
I0319 18:52:15.502802       1 scheduler.go:453] Attempting to schedule pod: container-lifecycle-hook-3809/pod-with-poststart-http-hook
I0319 18:52:15.504531       1 scheduler_binder.go:269] AssumePodVolumes for pod "container-lifecycle-hook-3809/pod-with-poststart-http-hook", node "e2e-test-peterhornyack-windows-node-group-7n03"
I0319 18:52:15.504572       1 scheduler_binder.go:279] AssumePodVolumes for pod "container-lifecycle-hook-3809/pod-with-poststart-http-hook", node "e2e-test-peterhornyack-windows-node-group-7n03": all PVCs bound and nothing to do
I0319 18:52:15.504620       1 factory.go:733] Attempting to bind pod-with-poststart-http-hook to e2e-test-peterhornyack-windows-node-group-7n03
I0319 18:52:15.512291       1 scheduler.go:572] pod container-lifecycle-hook-3809/pod-with-poststart-http-hook is bound successfully on node e2e-test-peterhornyack-windows-node-group-7n03, 5 nodes evaluated, 2 nodes were found feasible
I0319 18:52:20.118078       1 wrap.go:47] GET /healthz: (97.836µs) 200 [kube-probe/1.15+ 127.0.0.1:49870]
I0319 18:52:30.117861       1 wrap.go:47] GET /healthz: (77.396µs) 200 [kube-probe/1.15+ 127.0.0.1:49904]
I0319 18:52:40.118018       1 wrap.go:47] GET /healthz: (68.58µs) 200 [kube-probe/1.15+ 127.0.0.1:49958]
I0319 18:52:50.119533       1 wrap.go:47] GET /healthz: (70.729µs) 200 [kube-probe/1.15+ 127.0.0.1:49990]
I0319 18:53:00.118374       1 wrap.go:47] GET /healthz: (78.403µs) 200 [kube-probe/1.15+ 127.0.0.1:50024]
I0319 18:53:10.118056       1 wrap.go:47] GET /healthz: (75.802µs) 200 [kube-probe/1.15+ 127.0.0.1:50064]
I0319 18:53:20.118577       1 wrap.go:47] GET /healthz: (70.837µs) 200 [kube-probe/1.15+ 127.0.0.1:50096]
I0319 18:53:28.087188       1 reflector.go:370] k8s.io/kubernetes/cmd/kube-scheduler/app/server.go:223: Watch close - *v1.Pod total 119 items received
I0319 18:53:30.117868       1 wrap.go:47] GET /healthz: (72.686µs) 200 [kube-probe/1.15+ 127.0.0.1:50130]
I0319 18:53:40.117726       1 wrap.go:47] GET /healthz: (72.32µs) 200 [kube-probe/1.15+ 127.0.0.1:50180]
I0319 18:53:50.117864       1 wrap.go:47] GET /healthz: (82.857µs) 200 [kube-probe/1.15+ 127.0.0.1:50214]
I0319 18:54:00.117833       1 wrap.go:47] GET /healthz: (88.404µs) 200 [kube-probe/1.15+ 127.0.0.1:50250]
I0319 18:54:08.093640       1 reflector.go:370] k8s.io/client-go/informers/factory.go:133: Watch close - *v1.PersistentVolume total 5 items received
I0319 18:54:10.127502       1 wrap.go:47] GET /healthz: (102.942µs) 200 [kube-probe/1.15+ 127.0.0.1:50288]
I0319 18:54:20.130332       1 wrap.go:47] GET /healthz: (89.102µs) 200 [kube-probe/1.15+ 127.0.0.1:50320]
I0319 18:54:21.821698       1 scheduling_queue.go:908] About to try and schedule pod downward-api-9712/labelsupdate684efb3a-4a78-11e9-af5d-a08cfde32bdd
I0319 18:54:21.821733       1 scheduler.go:453] Attempting to schedule pod: downward-api-9712/labelsupdate684efb3a-4a78-11e9-af5d-a08cfde32bdd
I0319 18:54:21.823528       1 scheduler_binder.go:269] AssumePodVolumes for pod "downward-api-9712/labelsupdate684efb3a-4a78-11e9-af5d-a08cfde32bdd", node "e2e-test-peterhornyack-windows-node-group-7n03"
I0319 18:54:21.823560       1 scheduler_binder.go:279] AssumePodVolumes for pod "downward-api-9712/labelsupdate684efb3a-4a78-11e9-af5d-a08cfde32bdd", node "e2e-test-peterhornyack-windows-node-group-7n03": all PVCs bound and nothing to do
I0319 18:54:21.823621       1 factory.go:733] Attempting to bind labelsupdate684efb3a-4a78-11e9-af5d-a08cfde32bdd to e2e-test-peterhornyack-windows-node-group-7n03
I0319 18:54:21.831784       1 scheduler.go:572] pod downward-api-9712/labelsupdate684efb3a-4a78-11e9-af5d-a08cfde32bdd is bound successfully on node e2e-test-peterhornyack-windows-node-group-7n03, 5 nodes evaluated, 2 nodes were found feasible
I0319 18:54:30.117941       1 wrap.go:47] GET /healthz: (135.598µs) 200 [kube-probe/1.15+ 127.0.0.1:50356]
I0319 18:54:39.148775       1 reflector.go:370] k8s.io/client-go/informers/factory.go:133: Watch close - *v1.Service total 0 items received
I0319 18:54:40.119632       1 wrap.go:47] GET /healthz: (320.786µs) 200 [kube-probe/1.15+ 127.0.0.1:50404]
I0319 18:54:50.117994       1 wrap.go:47] GET /healthz: (164.24µs) 200 [kube-probe/1.15+ 127.0.0.1:50436]
I0319 18:54:58.796196       1 scheduling_queue.go:908] About to try and schedule pod hybrid-network-9383/pod-7e589031-4a78-11e9-af5d-a08cfde32bdd
I0319 18:54:58.796247       1 scheduler.go:453] Attempting to schedule pod: hybrid-network-9383/pod-7e589031-4a78-11e9-af5d-a08cfde32bdd
I0319 18:54:58.796733       1 scheduler_binder.go:269] AssumePodVolumes for pod "hybrid-network-9383/pod-7e589031-4a78-11e9-af5d-a08cfde32bdd", node "e2e-test-peterhornyack-minion-group-b97j"
I0319 18:54:58.796753       1 scheduler_binder.go:279] AssumePodVolumes for pod "hybrid-network-9383/pod-7e589031-4a78-11e9-af5d-a08cfde32bdd", node "e2e-test-peterhornyack-minion-group-b97j": all PVCs bound and nothing to do
I0319 18:54:58.796823       1 factory.go:733] Attempting to bind pod-7e589031-4a78-11e9-af5d-a08cfde32bdd to e2e-test-peterhornyack-minion-group-b97j
I0319 18:54:58.803658       1 scheduler.go:572] pod hybrid-network-9383/pod-7e589031-4a78-11e9-af5d-a08cfde32bdd is bound successfully on node e2e-test-peterhornyack-minion-group-b97j, 5 nodes evaluated, 3 nodes were found feasible
I0319 18:55:00.117908       1 wrap.go:47] GET /healthz: (79.648µs) 200 [kube-probe/1.15+ 127.0.0.1:50472]
I0319 18:55:04.971058       1 scheduling_queue.go:908] About to try and schedule pod hybrid-network-9383/pod-8207a8c8-4a78-11e9-af5d-a08cfde32bdd
I0319 18:55:04.971090       1 scheduler.go:453] Attempting to schedule pod: hybrid-network-9383/pod-8207a8c8-4a78-11e9-af5d-a08cfde32bdd
I0319 18:55:04.971772       1 scheduler_binder.go:269] AssumePodVolumes for pod "hybrid-network-9383/pod-8207a8c8-4a78-11e9-af5d-a08cfde32bdd", node "e2e-test-peterhornyack-windows-node-group-7n03"
I0319 18:55:04.971816       1 scheduler_binder.go:279] AssumePodVolumes for pod "hybrid-network-9383/pod-8207a8c8-4a78-11e9-af5d-a08cfde32bdd", node "e2e-test-peterhornyack-windows-node-group-7n03": all PVCs bound and nothing to do
I0319 18:55:04.971885       1 factory.go:733] Attempting to bind pod-8207a8c8-4a78-11e9-af5d-a08cfde32bdd to e2e-test-peterhornyack-windows-node-group-7n03
I0319 18:55:04.979356       1 scheduler.go:572] pod hybrid-network-9383/pod-8207a8c8-4a78-11e9-af5d-a08cfde32bdd is bound successfully on node e2e-test-peterhornyack-windows-node-group-7n03, 5 nodes evaluated, 2 nodes were found feasible
I0319 18:55:10.118132       1 wrap.go:47] GET /healthz: (87.425µs) 200 [kube-probe/1.15+ 127.0.0.1:50510]
I0319 18:55:15.084323       1 reflector.go:370] k8s.io/client-go/informers/factory.go:133: Watch close - *v1.StatefulSet total 0 items received
I0319 18:55:20.117957       1 wrap.go:47] GET /healthz: (73.415µs) 200 [kube-probe/1.15+ 127.0.0.1:50554]
I0319 18:55:24.130762       1 reflector.go:370] k8s.io/client-go/informers/factory.go:133: Watch close - *v1.ReplicaSet total 0 items received
I0319 18:55:30.118134       1 wrap.go:47] GET /healthz: (74.501µs) 200 [kube-probe/1.15+ 127.0.0.1:50604]
I0319 18:55:40.118005       1 wrap.go:47] GET /healthz: (77.021µs) 200 [kube-probe/1.15+ 127.0.0.1:50708]
I0319 18:55:50.117885       1 wrap.go:47] GET /healthz: (78.641µs) 200 [kube-probe/1.15+ 127.0.0.1:50756]
I0319 18:56:00.117912       1 wrap.go:47] GET /healthz: (75.451µs) 200 [kube-probe/1.15+ 127.0.0.1:50796]
I0319 18:56:10.117872       1 wrap.go:47] GET /healthz: (75.374µs) 200 [kube-probe/1.15+ 127.0.0.1:50836]
I0319 18:56:20.118960       1 wrap.go:47] GET /healthz: (75.592µs) 200 [kube-probe/1.15+ 127.0.0.1:50870]
I0319 18:56:30.118110       1 wrap.go:47] GET /healthz: (96.292µs) 200 [kube-probe/1.15+ 127.0.0.1:50904]
I0319 18:56:40.117882       1 wrap.go:47] GET /healthz: (70.835µs) 200 [kube-probe/1.15+ 127.0.0.1:50966]
I0319 18:56:41.965683       1 scheduling_queue.go:908] About to try and schedule pod services-6500/pod1
I0319 18:56:41.965721       1 scheduler.go:453] Attempting to schedule pod: services-6500/pod1
I0319 18:56:41.966271       1 scheduler_binder.go:269] AssumePodVolumes for pod "services-6500/pod1", node "e2e-test-peterhornyack-windows-node-group-7n03"
I0319 18:56:41.967092       1 scheduler_binder.go:279] AssumePodVolumes for pod "services-6500/pod1", node "e2e-test-peterhornyack-windows-node-group-7n03": all PVCs bound and nothing to do
I0319 18:56:41.967226       1 factory.go:733] Attempting to bind pod1 to e2e-test-peterhornyack-windows-node-group-7n03
I0319 18:56:41.974015       1 scheduler.go:572] pod services-6500/pod1 is bound successfully on node e2e-test-peterhornyack-windows-node-group-7n03, 5 nodes evaluated, 2 nodes were found feasible
I0319 18:56:48.122671       1 reflector.go:370] k8s.io/client-go/informers/factory.go:133: Watch close - *v1.Node total 57 items received
I0319 18:56:48.134261       1 reflector.go:370] k8s.io/client-go/informers/factory.go:133: Watch close - *v1.StorageClass total 0 items received
I0319 18:56:50.118113       1 wrap.go:47] GET /healthz: (100.584µs) 200 [kube-probe/1.15+ 127.0.0.1:51000]
I0319 18:56:50.772964       1 scheduling_queue.go:908] About to try and schedule pod services-6500/pod2
I0319 18:56:50.772994       1 scheduler.go:453] Attempting to schedule pod: services-6500/pod2
I0319 18:56:50.773343       1 scheduler_binder.go:269] AssumePodVolumes for pod "services-6500/pod2", node "e2e-test-peterhornyack-windows-node-group-dp2r"
I0319 18:56:50.773375       1 scheduler_binder.go:279] AssumePodVolumes for pod "services-6500/pod2", node "e2e-test-peterhornyack-windows-node-group-dp2r": all PVCs bound and nothing to do
I0319 18:56:50.773520       1 factory.go:733] Attempting to bind pod2 to e2e-test-peterhornyack-windows-node-group-dp2r
I0319 18:56:50.782325       1 scheduler.go:572] pod services-6500/pod2 is bound successfully on node e2e-test-peterhornyack-windows-node-group-dp2r, 5 nodes evaluated, 2 nodes were found feasible
I0319 18:57:00.118211       1 wrap.go:47] GET /healthz: (57.042µs) 200 [kube-probe/1.15+ 127.0.0.1:51034]
I0319 18:57:02.160055       1 reflector.go:370] k8s.io/client-go/informers/factory.go:133: Watch close - *v1.ReplicationController total 0 items received
I0319 18:57:10.118101       1 wrap.go:47] GET /healthz: (106.013µs) 200 [kube-probe/1.15+ 127.0.0.1:51074]
I0319 18:57:20.123913       1 wrap.go:47] GET /healthz: (72.725µs) 200 [kube-probe/1.15+ 127.0.0.1:51106]
I0319 18:57:30.117979       1 wrap.go:47] GET /healthz: (68.896µs) 200 [kube-probe/1.15+ 127.0.0.1:51142]
I0319 18:57:31.625282       1 scheduling_queue.go:908] About to try and schedule pod dns-1803/dns-test-d96f9686-4a78-11e9-af5d-a08cfde32bdd
I0319 18:57:31.625340       1 scheduler.go:453] Attempting to schedule pod: dns-1803/dns-test-d96f9686-4a78-11e9-af5d-a08cfde32bdd
I0319 18:57:31.625730       1 scheduler_binder.go:269] AssumePodVolumes for pod "dns-1803/dns-test-d96f9686-4a78-11e9-af5d-a08cfde32bdd", node "e2e-test-peterhornyack-windows-node-group-7n03"
I0319 18:57:31.625762       1 scheduler_binder.go:279] AssumePodVolumes for pod "dns-1803/dns-test-d96f9686-4a78-11e9-af5d-a08cfde32bdd", node "e2e-test-peterhornyack-windows-node-group-7n03": all PVCs bound and nothing to do
I0319 18:57:31.625808       1 factory.go:733] Attempting to bind dns-test-d96f9686-4a78-11e9-af5d-a08cfde32bdd to e2e-test-peterhornyack-windows-node-group-7n03
I0319 18:57:31.634082       1 scheduler.go:572] pod dns-1803/dns-test-d96f9686-4a78-11e9-af5d-a08cfde32bdd is bound successfully on node e2e-test-peterhornyack-windows-node-group-7n03, 5 nodes evaluated, 2 nodes were found feasible
I0319 18:57:40.117769       1 wrap.go:47] GET /healthz: (71.203µs) 200 [kube-probe/1.15+ 127.0.0.1:51190]
I0319 18:57:50.119109       1 wrap.go:47] GET /healthz: (109.999µs) 200 [kube-probe/1.15+ 127.0.0.1:51224]
I0319 18:58:00.117875       1 wrap.go:47] GET /healthz: (71.748µs) 200 [kube-probe/1.15+ 127.0.0.1:51258]
I0319 18:58:05.906291       1 scheduling_queue.go:908] About to try and schedule pod hostpath-3166/pod-host-path-test
I0319 18:58:05.906322       1 scheduler.go:453] Attempting to schedule pod: hostpath-3166/pod-host-path-test
I0319 18:58:05.906648       1 scheduler_binder.go:269] AssumePodVolumes for pod "hostpath-3166/pod-host-path-test", node "e2e-test-peterhornyack-windows-node-group-7n03"
I0319 18:58:05.906665       1 scheduler_binder.go:279] AssumePodVolumes for pod "hostpath-3166/pod-host-path-test", node "e2e-test-peterhornyack-windows-node-group-7n03": all PVCs bound and nothing to do
I0319 18:58:05.906727       1 factory.go:733] Attempting to bind pod-host-path-test to e2e-test-peterhornyack-windows-node-group-7n03
I0319 18:58:05.916164       1 scheduler.go:572] pod hostpath-3166/pod-host-path-test is bound successfully on node e2e-test-peterhornyack-windows-node-group-7n03, 5 nodes evaluated, 2 nodes were found feasible
I0319 18:58:10.117785       1 wrap.go:47] GET /healthz: (75.748µs) 200 [kube-probe/1.15+ 127.0.0.1:51298]
I0319 18:58:17.131858       1 reflector.go:370] k8s.io/client-go/informers/factory.go:133: Watch close - *v1.PersistentVolumeClaim total 0 items received
I0319 18:58:20.117937       1 wrap.go:47] GET /healthz: (70.951µs) 200 [kube-probe/1.15+ 127.0.0.1:51332]
I0319 18:58:27.146220       1 reflector.go:370] k8s.io/client-go/informers/factory.go:133: Watch close - *v1beta1.PodDisruptionBudget total 0 items received
I0319 18:58:30.118163       1 wrap.go:47] GET /healthz: (77.987µs) 200 [kube-probe/1.15+ 127.0.0.1:51366]
I0319 18:58:32.625334       1 scheduling_queue.go:908] About to try and schedule pod downward-api-4402/downwardapi-volume-fdcb6fc4-4a78-11e9-af5d-a08cfde32bdd
I0319 18:58:32.625363       1 scheduler.go:453] Attempting to schedule pod: downward-api-4402/downwardapi-volume-fdcb6fc4-4a78-11e9-af5d-a08cfde32bdd
I0319 18:58:32.628205       1 scheduler_binder.go:269] AssumePodVolumes for pod "downward-api-4402/downwardapi-volume-fdcb6fc4-4a78-11e9-af5d-a08cfde32bdd", node "e2e-test-peterhornyack-windows-node-group-7n03"
I0319 18:58:32.628273       1 scheduler_binder.go:279] AssumePodVolumes for pod "downward-api-4402/downwardapi-volume-fdcb6fc4-4a78-11e9-af5d-a08cfde32bdd", node "e2e-test-peterhornyack-windows-node-group-7n03": all PVCs bound and nothing to do
I0319 18:58:32.628324       1 factory.go:733] Attempting to bind downwardapi-volume-fdcb6fc4-4a78-11e9-af5d-a08cfde32bdd to e2e-test-peterhornyack-windows-node-group-7n03
I0319 18:58:32.640652       1 scheduler.go:572] pod downward-api-4402/downwardapi-volume-fdcb6fc4-4a78-11e9-af5d-a08cfde32bdd is bound successfully on node e2e-test-peterhornyack-windows-node-group-7n03, 5 nodes evaluated, 2 nodes were found feasible
I0319 18:58:40.118272       1 wrap.go:47] GET /healthz: (71.361µs) 200 [kube-probe/1.15+ 127.0.0.1:51418]
I0319 18:58:50.117904       1 wrap.go:47] GET /healthz: (77.681µs) 200 [kube-probe/1.15+ 127.0.0.1:51450]
I0319 18:58:53.154717       1 scheduling_queue.go:908] About to try and schedule pod windows-volumes-4620/pod-0a08380a-4a79-11e9-af5d-a08cfde32bdd
I0319 18:58:53.154750       1 scheduler.go:453] Attempting to schedule pod: windows-volumes-4620/pod-0a08380a-4a79-11e9-af5d-a08cfde32bdd
I0319 18:58:53.155145       1 scheduler_binder.go:269] AssumePodVolumes for pod "windows-volumes-4620/pod-0a08380a-4a79-11e9-af5d-a08cfde32bdd", node "e2e-test-peterhornyack-windows-node-group-dp2r"
I0319 18:58:53.155164       1 scheduler_binder.go:279] AssumePodVolumes for pod "windows-volumes-4620/pod-0a08380a-4a79-11e9-af5d-a08cfde32bdd", node "e2e-test-peterhornyack-windows-node-group-dp2r": all PVCs bound and nothing to do
I0319 18:58:53.155233       1 factory.go:733] Attempting to bind pod-0a08380a-4a79-11e9-af5d-a08cfde32bdd to e2e-test-peterhornyack-windows-node-group-dp2r
I0319 18:58:53.163110       1 scheduler.go:572] pod windows-volumes-4620/pod-0a08380a-4a79-11e9-af5d-a08cfde32bdd is bound successfully on node e2e-test-peterhornyack-windows-node-group-dp2r, 5 nodes evaluated, 2 nodes were found feasible
I0319 18:58:59.702230       1 scheduling_queue.go:908] About to try and schedule pod windows-volumes-4620/pod-0deff470-4a79-11e9-af5d-a08cfde32bdd
I0319 18:58:59.702263       1 scheduler.go:453] Attempting to schedule pod: windows-volumes-4620/pod-0deff470-4a79-11e9-af5d-a08cfde32bdd
I0319 18:58:59.702880       1 scheduler_binder.go:269] AssumePodVolumes for pod "windows-volumes-4620/pod-0deff470-4a79-11e9-af5d-a08cfde32bdd", node "e2e-test-peterhornyack-windows-node-group-7n03"
I0319 18:58:59.702918       1 scheduler_binder.go:279] AssumePodVolumes for pod "windows-volumes-4620/pod-0deff470-4a79-11e9-af5d-a08cfde32bdd", node "e2e-test-peterhornyack-windows-node-group-7n03": all PVCs bound and nothing to do
I0319 18:58:59.702989       1 factory.go:733] Attempting to bind pod-0deff470-4a79-11e9-af5d-a08cfde32bdd to e2e-test-peterhornyack-windows-node-group-7n03
I0319 18:58:59.710972       1 scheduler.go:572] pod windows-volumes-4620/pod-0deff470-4a79-11e9-af5d-a08cfde32bdd is bound successfully on node e2e-test-peterhornyack-windows-node-group-7n03, 5 nodes evaluated, 2 nodes were found feasible
I0319 18:59:00.117901       1 wrap.go:47] GET /healthz: (82.081µs) 200 [kube-probe/1.15+ 127.0.0.1:51486]
I0319 18:59:10.117899       1 wrap.go:47] GET /healthz: (55.884µs) 200 [kube-probe/1.15+ 127.0.0.1:51532]
I0319 18:59:20.118256       1 wrap.go:47] GET /healthz: (79.529µs) 200 [kube-probe/1.15+ 127.0.0.1:51568]
I0319 18:59:30.118005       1 wrap.go:47] GET /healthz: (71.542µs) 200 [kube-probe/1.15+ 127.0.0.1:51604]
I0319 18:59:40.117842       1 wrap.go:47] GET /healthz: (118.84µs) 200 [kube-probe/1.15+ 127.0.0.1:51652]
I0319 18:59:44.087377       1 scheduling_queue.go:908] About to try and schedule pod deployment-7086/test-recreate-deployment-78b595d858-thmkb
I0319 18:59:44.087406       1 scheduler.go:453] Attempting to schedule pod: deployment-7086/test-recreate-deployment-78b595d858-thmkb
I0319 18:59:44.087835       1 scheduler_binder.go:269] AssumePodVolumes for pod "deployment-7086/test-recreate-deployment-78b595d858-thmkb", node "e2e-test-peterhornyack-windows-node-group-dp2r"
I0319 18:59:44.087868       1 scheduler_binder.go:279] AssumePodVolumes for pod "deployment-7086/test-recreate-deployment-78b595d858-thmkb", node "e2e-test-peterhornyack-windows-node-group-dp2r": all PVCs bound and nothing to do
I0319 18:59:44.087930       1 factory.go:733] Attempting to bind test-recreate-deployment-78b595d858-thmkb to e2e-test-peterhornyack-windows-node-group-dp2r
I0319 18:59:44.120250       1 scheduler.go:572] pod deployment-7086/test-recreate-deployment-78b595d858-thmkb is bound successfully on node e2e-test-peterhornyack-windows-node-group-dp2r, 5 nodes evaluated, 2 nodes were found feasible
I0319 18:59:50.118077       1 wrap.go:47] GET /healthz: (108.245µs) 200 [kube-probe/1.15+ 127.0.0.1:51684]
I0319 18:59:52.431353       1 scheduling_queue.go:908] About to try and schedule pod deployment-7086/test-recreate-deployment-5ccf74d6d5-s45w8
I0319 18:59:52.431387       1 scheduler.go:453] Attempting to schedule pod: deployment-7086/test-recreate-deployment-5ccf74d6d5-s45w8
I0319 18:59:52.435242       1 scheduler_binder.go:269] AssumePodVolumes for pod "deployment-7086/test-recreate-deployment-5ccf74d6d5-s45w8", node "e2e-test-peterhornyack-windows-node-group-7n03"
I0319 18:59:52.435286       1 scheduler_binder.go:279] AssumePodVolumes for pod "deployment-7086/test-recreate-deployment-5ccf74d6d5-s45w8", node "e2e-test-peterhornyack-windows-node-group-7n03": all PVCs bound and nothing to do
I0319 18:59:52.435339       1 factory.go:733] Attempting to bind test-recreate-deployment-5ccf74d6d5-s45w8 to e2e-test-peterhornyack-windows-node-group-7n03
I0319 18:59:52.460224       1 scheduler.go:572] pod deployment-7086/test-recreate-deployment-5ccf74d6d5-s45w8 is bound successfully on node e2e-test-peterhornyack-windows-node-group-7n03, 5 nodes evaluated, 2 nodes were found feasible
I0319 19:00:00.119246       1 wrap.go:47] GET /healthz: (73.378µs) 200 [kube-probe/1.15+ 127.0.0.1:51720]
I0319 19:00:00.716393       1 scheduling_queue.go:908] About to try and schedule pod svc-latency-868/svc-latency-rc-5m7c9
I0319 19:00:00.718390       1 scheduler.go:453] Attempting to schedule pod: svc-latency-868/svc-latency-rc-5m7c9
I0319 19:00:00.723166       1 scheduler_binder.go:269] AssumePodVolumes for pod "svc-latency-868/svc-latency-rc-5m7c9", node "e2e-test-peterhornyack-windows-node-group-dp2r"
I0319 19:00:00.723202       1 scheduler_binder.go:279] AssumePodVolumes for pod "svc-latency-868/svc-latency-rc-5m7c9", node "e2e-test-peterhornyack-windows-node-group-dp2r": all PVCs bound and nothing to do
I0319 19:00:00.723275       1 factory.go:733] Attempting to bind svc-latency-rc-5m7c9 to e2e-test-peterhornyack-windows-node-group-dp2r
I0319 19:00:00.739232       1 scheduler.go:572] pod svc-latency-868/svc-latency-rc-5m7c9 is bound successfully on node e2e-test-peterhornyack-windows-node-group-dp2r, 5 nodes evaluated, 2 nodes were found feasible
I0319 19:00:10.117815       1 wrap.go:47] GET /healthz: (73.617µs) 200 [kube-probe/1.15+ 127.0.0.1:51760]
I0319 19:00:20.117843       1 wrap.go:47] GET /healthz: (77.064µs) 200 [kube-probe/1.15+ 127.0.0.1:51796]
I0319 19:00:30.117820       1 wrap.go:47] GET /healthz: (76.255µs) 200 [kube-probe/1.15+ 127.0.0.1:51830]
I0319 19:00:31.995158       1 scheduling_queue.go:908] About to try and schedule pod deployment-585/test-rolling-update-controller-57dss
I0319 19:00:31.996050       1 scheduler.go:453] Attempting to schedule pod: deployment-585/test-rolling-update-controller-57dss
I0319 19:00:31.996553       1 scheduler_binder.go:269] AssumePodVolumes for pod "deployment-585/test-rolling-update-controller-57dss", node "e2e-test-peterhornyack-windows-node-group-7n03"
I0319 19:00:31.996579       1 scheduler_binder.go:279] AssumePodVolumes for pod "deployment-585/test-rolling-update-controller-57dss", node "e2e-test-peterhornyack-windows-node-group-7n03": all PVCs bound and nothing to do
I0319 19:00:31.996635       1 factory.go:733] Attempting to bind test-rolling-update-controller-57dss to e2e-test-peterhornyack-windows-node-group-7n03
I0319 19:00:32.016205       1 scheduler.go:572] pod deployment-585/test-rolling-update-controller-57dss is bound successfully on node e2e-test-peterhornyack-windows-node-group-7n03, 5 nodes evaluated, 2 nodes were found feasible
I0319 19:00:40.118326       1 wrap.go:47] GET /healthz: (69.2µs) 200 [kube-probe/1.15+ 127.0.0.1:51878]
I0319 19:00:40.205336       1 scheduling_queue.go:908] About to try and schedule pod deployment-585/test-rolling-update-deployment-7fcdf5fb94-52l92
I0319 19:00:40.205379       1 scheduler.go:453] Attempting to schedule pod: deployment-585/test-rolling-update-deployment-7fcdf5fb94-52l92
I0319 19:00:40.205766       1 scheduler_binder.go:269] AssumePodVolumes for pod "deployment-585/test-rolling-update-deployment-7fcdf5fb94-52l92", node "e2e-test-peterhornyack-windows-node-group-dp2r"
I0319 19:00:40.205798       1 scheduler_binder.go:279] AssumePodVolumes for pod "deployment-585/test-rolling-update-deployment-7fcdf5fb94-52l92", node "e2e-test-peterhornyack-windows-node-group-dp2r": all PVCs bound and nothing to do
I0319 19:00:40.205844       1 factory.go:733] Attempting to bind test-rolling-update-deployment-7fcdf5fb94-52l92 to e2e-test-peterhornyack-windows-node-group-dp2r
I0319 19:00:40.231178       1 scheduler.go:572] pod deployment-585/test-rolling-update-deployment-7fcdf5fb94-52l92 is bound successfully on node e2e-test-peterhornyack-windows-node-group-dp2r, 5 nodes evaluated, 2 nodes were found feasible
I0319 19:00:48.087658       1 reflector.go:370] k8s.io/client-go/informers/factory.go:133: Watch close - *v1.StatefulSet total 0 items received
I0319 19:00:50.118435       1 wrap.go:47] GET /healthz: (75.787µs) 200 [kube-probe/1.15+ 127.0.0.1:51912]
I0319 19:00:59.472115       1 scheduling_queue.go:908] About to try and schedule pod volume-8334/exec-volume-test-gcepd-xsj8
I0319 19:00:59.472176       1 scheduler.go:453] Attempting to schedule pod: volume-8334/exec-volume-test-gcepd-xsj8
I0319 19:00:59.472610       1 scheduler_binder.go:269] AssumePodVolumes for pod "volume-8334/exec-volume-test-gcepd-xsj8", node "e2e-test-peterhornyack-windows-node-group-7n03"
I0319 19:00:59.472642       1 scheduler_binder.go:279] AssumePodVolumes for pod "volume-8334/exec-volume-test-gcepd-xsj8", node "e2e-test-peterhornyack-windows-node-group-7n03": all PVCs bound and nothing to do
I0319 19:00:59.472689       1 factory.go:733] Attempting to bind exec-volume-test-gcepd-xsj8 to e2e-test-peterhornyack-windows-node-group-7n03
I0319 19:00:59.482523       1 scheduler.go:572] pod volume-8334/exec-volume-test-gcepd-xsj8 is bound successfully on node e2e-test-peterhornyack-windows-node-group-7n03, 5 nodes evaluated, 2 nodes were found feasible
I0319 19:01:00.118075       1 wrap.go:47] GET /healthz: (107.468µs) 200 [kube-probe/1.15+ 127.0.0.1:51946]
I0319 19:01:10.118006       1 wrap.go:47] GET /healthz: (89.649µs) 200 [kube-probe/1.15+ 127.0.0.1:51986]
I0319 19:01:10.152369       1 reflector.go:370] k8s.io/client-go/informers/factory.go:133: Watch close - *v1.Service total 408 items received
I0319 19:01:20.117808       1 wrap.go:47] GET /healthz: (82.931µs) 200 [kube-probe/1.15+ 127.0.0.1:52018]
I0319 19:01:30.117699       1 wrap.go:47] GET /healthz: (135.319µs) 200 [kube-probe/1.15+ 127.0.0.1:52052]
