Log file created at: 2019/04/05 02:22:43
Running on machine: e2e-test-peterhornyack-master
Binary: Built with gc go1.12.1 for linux/amd64
Log line format: [IWEF]mmdd hh:mm:ss.uuuuuu threadid file:line] msg
I0405 02:22:43.524611       1 flags.go:33] FLAG: --address="0.0.0.0"
I0405 02:22:43.524899       1 flags.go:33] FLAG: --algorithm-provider=""
I0405 02:22:43.524905       1 flags.go:33] FLAG: --alsologtostderr="false"
I0405 02:22:43.524912       1 flags.go:33] FLAG: --authentication-kubeconfig=""
I0405 02:22:43.525508       1 flags.go:33] FLAG: --authentication-skip-lookup="false"
I0405 02:22:43.525526       1 flags.go:33] FLAG: --authentication-token-webhook-cache-ttl="10s"
I0405 02:22:43.525557       1 flags.go:33] FLAG: --authentication-tolerate-lookup-failure="true"
I0405 02:22:43.525565       1 flags.go:33] FLAG: --authorization-always-allow-paths="[/healthz]"
I0405 02:22:43.525591       1 flags.go:33] FLAG: --authorization-kubeconfig=""
I0405 02:22:43.525598       1 flags.go:33] FLAG: --authorization-webhook-cache-authorized-ttl="10s"
I0405 02:22:43.525606       1 flags.go:33] FLAG: --authorization-webhook-cache-unauthorized-ttl="10s"
I0405 02:22:43.525614       1 flags.go:33] FLAG: --bind-address="0.0.0.0"
I0405 02:22:43.525634       1 flags.go:33] FLAG: --cert-dir=""
I0405 02:22:43.525638       1 flags.go:33] FLAG: --client-ca-file=""
I0405 02:22:43.525641       1 flags.go:33] FLAG: --config=""
I0405 02:22:43.525643       1 flags.go:33] FLAG: --contention-profiling="false"
I0405 02:22:43.525647       1 flags.go:33] FLAG: --feature-gates="ExperimentalCriticalPodAnnotation=true"
I0405 02:22:43.525658       1 flags.go:33] FLAG: --hard-pod-affinity-symmetric-weight="1"
I0405 02:22:43.525666       1 flags.go:33] FLAG: --help="false"
I0405 02:22:43.525669       1 flags.go:33] FLAG: --http2-max-streams-per-connection="0"
I0405 02:22:43.525674       1 flags.go:33] FLAG: --kube-api-burst="100"
I0405 02:22:43.525677       1 flags.go:33] FLAG: --kube-api-content-type="application/vnd.kubernetes.protobuf"
I0405 02:22:43.525680       1 flags.go:33] FLAG: --kube-api-qps="50"
I0405 02:22:43.525686       1 flags.go:33] FLAG: --kubeconfig="/etc/srv/kubernetes/kube-scheduler/kubeconfig"
I0405 02:22:43.525689       1 flags.go:33] FLAG: --leader-elect="true"
I0405 02:22:43.525695       1 flags.go:33] FLAG: --leader-elect-lease-duration="15s"
I0405 02:22:43.525698       1 flags.go:33] FLAG: --leader-elect-renew-deadline="10s"
I0405 02:22:43.525779       1 flags.go:33] FLAG: --leader-elect-resource-lock="endpoints"
I0405 02:22:43.525792       1 flags.go:33] FLAG: --leader-elect-retry-period="2s"
I0405 02:22:43.525795       1 flags.go:33] FLAG: --lock-object-name="kube-scheduler"
I0405 02:22:43.525797       1 flags.go:33] FLAG: --lock-object-namespace="kube-system"
I0405 02:22:43.525800       1 flags.go:33] FLAG: --log-backtrace-at=":0"
I0405 02:22:43.525809       1 flags.go:33] FLAG: --log-dir=""
I0405 02:22:43.525811       1 flags.go:33] FLAG: --log-file="/var/log/kube-scheduler.log"
I0405 02:22:43.525814       1 flags.go:33] FLAG: --log-flush-frequency="5s"
I0405 02:22:43.525817       1 flags.go:33] FLAG: --logtostderr="false"
I0405 02:22:43.525820       1 flags.go:33] FLAG: --master=""
I0405 02:22:43.525822       1 flags.go:33] FLAG: --policy-config-file=""
I0405 02:22:43.525825       1 flags.go:33] FLAG: --policy-configmap=""
I0405 02:22:43.525831       1 flags.go:33] FLAG: --policy-configmap-namespace="kube-system"
I0405 02:22:43.525834       1 flags.go:33] FLAG: --port="10251"
I0405 02:22:43.525836       1 flags.go:33] FLAG: --profiling="false"
I0405 02:22:43.525839       1 flags.go:33] FLAG: --requestheader-allowed-names="[]"
I0405 02:22:43.525843       1 flags.go:33] FLAG: --requestheader-client-ca-file=""
I0405 02:22:43.525845       1 flags.go:33] FLAG: --requestheader-extra-headers-prefix="[x-remote-extra-]"
I0405 02:22:43.525858       1 flags.go:33] FLAG: --requestheader-group-headers="[x-remote-group]"
I0405 02:22:43.525862       1 flags.go:33] FLAG: --requestheader-username-headers="[x-remote-user]"
I0405 02:22:43.525871       1 flags.go:33] FLAG: --scheduler-name="default-scheduler"
I0405 02:22:43.525874       1 flags.go:33] FLAG: --secure-port="10259"
I0405 02:22:43.525877       1 flags.go:33] FLAG: --skip-headers="false"
I0405 02:22:43.525879       1 flags.go:33] FLAG: --stderrthreshold="2"
I0405 02:22:43.525882       1 flags.go:33] FLAG: --tls-cert-file=""
I0405 02:22:43.525888       1 flags.go:33] FLAG: --tls-cipher-suites="[]"
I0405 02:22:43.525891       1 flags.go:33] FLAG: --tls-min-version=""
I0405 02:22:43.525893       1 flags.go:33] FLAG: --tls-private-key-file=""
I0405 02:22:43.525896       1 flags.go:33] FLAG: --tls-sni-cert-key="[]"
I0405 02:22:43.525906       1 flags.go:33] FLAG: --use-legacy-policy-config="false"
I0405 02:22:43.525909       1 flags.go:33] FLAG: --v="4"
I0405 02:22:43.525912       1 flags.go:33] FLAG: --version="false"
I0405 02:22:43.525948       1 flags.go:33] FLAG: --vmodule=""
I0405 02:22:43.525951       1 flags.go:33] FLAG: --write-config-to=""
Log file created at: 2019/04/05 02:22:45
Running on machine: e2e-test-peterhornyack-master
Binary: Built with gc go1.12.1 for linux/amd64
Log line format: [IWEF]mmdd hh:mm:ss.uuuuuu threadid file:line] msg
Log file created at: 2019/04/05 02:22:45
Running on machine: e2e-test-peterhornyack-master
Binary: Built with gc go1.12.1 for linux/amd64
Log line format: [IWEF]mmdd hh:mm:ss.uuuuuu threadid file:line] msg
E0405 02:22:45.595781       1 reflector.go:131] k8s.io/kubernetes/cmd/kube-scheduler/app/server.go:223: Failed to list *v1.Pod: Get https://localhost:443/api/v1/pods?fieldSelector=status.phase%21%3DFailed%2Cstatus.phase%21%3DSucceeded&limit=500&resourceVersion=0: dial tcp [::1]:443: connect: connection refused
E0405 02:22:45.596234       1 reflector.go:131] k8s.io/client-go/informers/factory.go:133: Failed to list *v1.PersistentVolume: Get https://localhost:443/api/v1/persistentvolumes?limit=500&resourceVersion=0: dial tcp [::1]:443: connect: connection refused
E0405 02:22:45.596313       1 reflector.go:131] k8s.io/client-go/informers/factory.go:133: Failed to list *v1.ReplicationController: Get https://localhost:443/api/v1/replicationcontrollers?limit=500&resourceVersion=0: dial tcp [::1]:443: connect: connection refused
E0405 02:22:45.598075       1 reflector.go:131] k8s.io/client-go/informers/factory.go:133: Failed to list *v1beta1.PodDisruptionBudget: Get https://localhost:443/apis/policy/v1beta1/poddisruptionbudgets?limit=500&resourceVersion=0: dial tcp [::1]:443: connect: connection refused
E0405 02:22:45.598171       1 reflector.go:131] k8s.io/client-go/informers/factory.go:133: Failed to list *v1.StorageClass: Get https://localhost:443/apis/storage.k8s.io/v1/storageclasses?limit=500&resourceVersion=0: dial tcp [::1]:443: connect: connection refused
E0405 02:22:45.598238       1 reflector.go:131] k8s.io/client-go/informers/factory.go:133: Failed to list *v1.Node: Get https://localhost:443/api/v1/nodes?limit=500&resourceVersion=0: dial tcp [::1]:443: connect: connection refused
E0405 02:22:45.598298       1 reflector.go:131] k8s.io/client-go/informers/factory.go:133: Failed to list *v1.Service: Get https://localhost:443/api/v1/services?limit=500&resourceVersion=0: dial tcp [::1]:443: connect: connection refused
E0405 02:22:45.598359       1 reflector.go:131] k8s.io/client-go/informers/factory.go:133: Failed to list *v1.ReplicaSet: Get https://localhost:443/apis/apps/v1/replicasets?limit=500&resourceVersion=0: dial tcp [::1]:443: connect: connection refused
E0405 02:22:45.598416       1 reflector.go:131] k8s.io/client-go/informers/factory.go:133: Failed to list *v1.PersistentVolumeClaim: Get https://localhost:443/api/v1/persistentvolumeclaims?limit=500&resourceVersion=0: dial tcp [::1]:443: connect: connection refused
E0405 02:22:45.598477       1 reflector.go:131] k8s.io/client-go/informers/factory.go:133: Failed to list *v1.StatefulSet: Get https://localhost:443/apis/apps/v1/statefulsets?limit=500&resourceVersion=0: dial tcp [::1]:443: connect: connection refused
W0405 02:22:45.560724       1 authentication.go:249] No authentication-kubeconfig provided in order to lookup client-ca-file in configmap/extension-apiserver-authentication in kube-system, so client certificate authentication won't work.
W0405 02:22:45.561078       1 authentication.go:252] No authentication-kubeconfig provided in order to lookup requestheader-client-ca-file in configmap/extension-apiserver-authentication in kube-system, so request-header client certificate authentication won't work.
W0405 02:22:45.561095       1 authorization.go:146] No authorization-kubeconfig provided, so SubjectAccessReview of authorization tokens won't work.
W0405 02:22:45.573375       1 authorization.go:47] Authorization is disabled
W0405 02:22:45.573392       1 authentication.go:55] Authentication is disabled
E0405 02:22:45.595781       1 reflector.go:131] k8s.io/kubernetes/cmd/kube-scheduler/app/server.go:223: Failed to list *v1.Pod: Get https://localhost:443/api/v1/pods?fieldSelector=status.phase%21%3DFailed%2Cstatus.phase%21%3DSucceeded&limit=500&resourceVersion=0: dial tcp [::1]:443: connect: connection refused
E0405 02:22:45.596234       1 reflector.go:131] k8s.io/client-go/informers/factory.go:133: Failed to list *v1.PersistentVolume: Get https://localhost:443/api/v1/persistentvolumes?limit=500&resourceVersion=0: dial tcp [::1]:443: connect: connection refused
E0405 02:22:45.596313       1 reflector.go:131] k8s.io/client-go/informers/factory.go:133: Failed to list *v1.ReplicationController: Get https://localhost:443/api/v1/replicationcontrollers?limit=500&resourceVersion=0: dial tcp [::1]:443: connect: connection refused
E0405 02:22:45.598075       1 reflector.go:131] k8s.io/client-go/informers/factory.go:133: Failed to list *v1beta1.PodDisruptionBudget: Get https://localhost:443/apis/policy/v1beta1/poddisruptionbudgets?limit=500&resourceVersion=0: dial tcp [::1]:443: connect: connection refused
E0405 02:22:45.598171       1 reflector.go:131] k8s.io/client-go/informers/factory.go:133: Failed to list *v1.StorageClass: Get https://localhost:443/apis/storage.k8s.io/v1/storageclasses?limit=500&resourceVersion=0: dial tcp [::1]:443: connect: connection refused
E0405 02:22:45.598238       1 reflector.go:131] k8s.io/client-go/informers/factory.go:133: Failed to list *v1.Node: Get https://localhost:443/api/v1/nodes?limit=500&resourceVersion=0: dial tcp [::1]:443: connect: connection refused
E0405 02:22:45.598298       1 reflector.go:131] k8s.io/client-go/informers/factory.go:133: Failed to list *v1.Service: Get https://localhost:443/api/v1/services?limit=500&resourceVersion=0: dial tcp [::1]:443: connect: connection refused
E0405 02:22:45.598359       1 reflector.go:131] k8s.io/client-go/informers/factory.go:133: Failed to list *v1.ReplicaSet: Get https://localhost:443/apis/apps/v1/replicasets?limit=500&resourceVersion=0: dial tcp [::1]:443: connect: connection refused
E0405 02:22:45.598416       1 reflector.go:131] k8s.io/client-go/informers/factory.go:133: Failed to list *v1.PersistentVolumeClaim: Get https://localhost:443/api/v1/persistentvolumeclaims?limit=500&resourceVersion=0: dial tcp [::1]:443: connect: connection refused
E0405 02:22:45.598477       1 reflector.go:131] k8s.io/client-go/informers/factory.go:133: Failed to list *v1.StatefulSet: Get https://localhost:443/apis/apps/v1/statefulsets?limit=500&resourceVersion=0: dial tcp [::1]:443: connect: connection refused
I0405 02:22:44.595836       1 serving.go:319] Generated self-signed cert in-memory
W0405 02:22:45.560724       1 authentication.go:249] No authentication-kubeconfig provided in order to lookup client-ca-file in configmap/extension-apiserver-authentication in kube-system, so client certificate authentication won't work.
W0405 02:22:45.561078       1 authentication.go:252] No authentication-kubeconfig provided in order to lookup requestheader-client-ca-file in configmap/extension-apiserver-authentication in kube-system, so request-header client certificate authentication won't work.
W0405 02:22:45.561095       1 authorization.go:146] No authorization-kubeconfig provided, so SubjectAccessReview of authorization tokens won't work.
I0405 02:22:45.567303       1 server.go:142] Version: v1.15.0-alpha.0.1887+bae0630ef897d6-dirty
I0405 02:22:45.567366       1 defaults.go:87] TaintNodesByCondition is enabled, PodToleratesNodeTaints predicate is mandatory
I0405 02:22:45.567375       1 server.go:161] Starting Kubernetes Scheduler version v1.15.0-alpha.0.1887+bae0630ef897d6-dirty
I0405 02:22:45.567717       1 factory.go:332] Creating scheduler from algorithm provider 'DefaultProvider'
I0405 02:22:45.567727       1 factory.go:413] Creating scheduler with fit predicates 'map[CheckNodeUnschedulable:{} CheckVolumeBinding:{} GeneralPredicates:{} MatchInterPodAffinity:{} MaxAzureDiskVolumeCount:{} MaxCSIVolumeCountPred:{} MaxEBSVolumeCount:{} MaxGCEPDVolumeCount:{} NoDiskConflict:{} NoVolumeZoneConflict:{} PodToleratesNodeTaints:{}]' and priority functions 'map[BalancedResourceAllocation:{} ImageLocalityPriority:{} InterPodAffinityPriority:{} LeastRequestedPriority:{} NodeAffinityPriority:{} NodePreferAvoidPodsPriority:{} SelectorSpreadPriority:{} TaintTolerationPriority:{}]'
W0405 02:22:45.573375       1 authorization.go:47] Authorization is disabled
W0405 02:22:45.573392       1 authentication.go:55] Authentication is disabled
I0405 02:22:45.573405       1 deprecated_insecure_serving.go:49] Serving healthz insecurely on [::]:10251
I0405 02:22:45.573991       1 secure_serving.go:116] Serving securely on [::]:10259
I0405 02:22:45.578048       1 reflector.go:128] Starting reflector *v1.Pod (0s) from k8s.io/kubernetes/cmd/kube-scheduler/app/server.go:223
I0405 02:22:45.578073       1 reflector.go:166] Listing and watching *v1.Pod from k8s.io/kubernetes/cmd/kube-scheduler/app/server.go:223
I0405 02:22:45.581090       1 reflector.go:128] Starting reflector *v1.PersistentVolume (0s) from k8s.io/client-go/informers/factory.go:133
I0405 02:22:45.581106       1 reflector.go:166] Listing and watching *v1.PersistentVolume from k8s.io/client-go/informers/factory.go:133
I0405 02:22:45.583168       1 reflector.go:128] Starting reflector *v1.PersistentVolumeClaim (0s) from k8s.io/client-go/informers/factory.go:133
I0405 02:22:45.583187       1 reflector.go:166] Listing and watching *v1.PersistentVolumeClaim from k8s.io/client-go/informers/factory.go:133
I0405 02:22:45.587083       1 reflector.go:128] Starting reflector *v1.ReplicationController (0s) from k8s.io/client-go/informers/factory.go:133
I0405 02:22:45.587098       1 reflector.go:166] Listing and watching *v1.ReplicationController from k8s.io/client-go/informers/factory.go:133
I0405 02:22:45.587636       1 reflector.go:128] Starting reflector *v1.StatefulSet (0s) from k8s.io/client-go/informers/factory.go:133
I0405 02:22:45.587645       1 reflector.go:166] Listing and watching *v1.StatefulSet from k8s.io/client-go/informers/factory.go:133
I0405 02:22:45.588975       1 reflector.go:128] Starting reflector *v1beta1.PodDisruptionBudget (0s) from k8s.io/client-go/informers/factory.go:133
I0405 02:22:45.588986       1 reflector.go:166] Listing and watching *v1beta1.PodDisruptionBudget from k8s.io/client-go/informers/factory.go:133
I0405 02:22:45.589353       1 reflector.go:128] Starting reflector *v1.StorageClass (0s) from k8s.io/client-go/informers/factory.go:133
I0405 02:22:45.589359       1 reflector.go:166] Listing and watching *v1.StorageClass from k8s.io/client-go/informers/factory.go:133
I0405 02:22:45.589754       1 reflector.go:128] Starting reflector *v1.Node (0s) from k8s.io/client-go/informers/factory.go:133
I0405 02:22:45.589760       1 reflector.go:166] Listing and watching *v1.Node from k8s.io/client-go/informers/factory.go:133
I0405 02:22:45.593305       1 reflector.go:128] Starting reflector *v1.Service (0s) from k8s.io/client-go/informers/factory.go:133
I0405 02:22:45.593319       1 reflector.go:166] Listing and watching *v1.Service from k8s.io/client-go/informers/factory.go:133
I0405 02:22:45.593796       1 reflector.go:128] Starting reflector *v1.ReplicaSet (0s) from k8s.io/client-go/informers/factory.go:133
I0405 02:22:45.593805       1 reflector.go:166] Listing and watching *v1.ReplicaSet from k8s.io/client-go/informers/factory.go:133
E0405 02:22:45.595781       1 reflector.go:131] k8s.io/kubernetes/cmd/kube-scheduler/app/server.go:223: Failed to list *v1.Pod: Get https://localhost:443/api/v1/pods?fieldSelector=status.phase%21%3DFailed%2Cstatus.phase%21%3DSucceeded&limit=500&resourceVersion=0: dial tcp [::1]:443: connect: connection refused
E0405 02:22:45.596234       1 reflector.go:131] k8s.io/client-go/informers/factory.go:133: Failed to list *v1.PersistentVolume: Get https://localhost:443/api/v1/persistentvolumes?limit=500&resourceVersion=0: dial tcp [::1]:443: connect: connection refused
E0405 02:22:45.596313       1 reflector.go:131] k8s.io/client-go/informers/factory.go:133: Failed to list *v1.ReplicationController: Get https://localhost:443/api/v1/replicationcontrollers?limit=500&resourceVersion=0: dial tcp [::1]:443: connect: connection refused
E0405 02:22:45.598075       1 reflector.go:131] k8s.io/client-go/informers/factory.go:133: Failed to list *v1beta1.PodDisruptionBudget: Get https://localhost:443/apis/policy/v1beta1/poddisruptionbudgets?limit=500&resourceVersion=0: dial tcp [::1]:443: connect: connection refused
E0405 02:22:45.598171       1 reflector.go:131] k8s.io/client-go/informers/factory.go:133: Failed to list *v1.StorageClass: Get https://localhost:443/apis/storage.k8s.io/v1/storageclasses?limit=500&resourceVersion=0: dial tcp [::1]:443: connect: connection refused
E0405 02:22:45.598238       1 reflector.go:131] k8s.io/client-go/informers/factory.go:133: Failed to list *v1.Node: Get https://localhost:443/api/v1/nodes?limit=500&resourceVersion=0: dial tcp [::1]:443: connect: connection refused
E0405 02:22:45.598298       1 reflector.go:131] k8s.io/client-go/informers/factory.go:133: Failed to list *v1.Service: Get https://localhost:443/api/v1/services?limit=500&resourceVersion=0: dial tcp [::1]:443: connect: connection refused
E0405 02:22:45.598359       1 reflector.go:131] k8s.io/client-go/informers/factory.go:133: Failed to list *v1.ReplicaSet: Get https://localhost:443/apis/apps/v1/replicasets?limit=500&resourceVersion=0: dial tcp [::1]:443: connect: connection refused
E0405 02:22:45.598416       1 reflector.go:131] k8s.io/client-go/informers/factory.go:133: Failed to list *v1.PersistentVolumeClaim: Get https://localhost:443/api/v1/persistentvolumeclaims?limit=500&resourceVersion=0: dial tcp [::1]:443: connect: connection refused
E0405 02:22:45.598477       1 reflector.go:131] k8s.io/client-go/informers/factory.go:133: Failed to list *v1.StatefulSet: Get https://localhost:443/apis/apps/v1/statefulsets?limit=500&resourceVersion=0: dial tcp [::1]:443: connect: connection refused
I0405 02:22:46.604002       1 reflector.go:166] Listing and watching *v1.StorageClass from k8s.io/client-go/informers/factory.go:133
I0405 02:22:46.604587       1 reflector.go:166] Listing and watching *v1.Pod from k8s.io/kubernetes/cmd/kube-scheduler/app/server.go:223
I0405 02:22:46.604838       1 reflector.go:166] Listing and watching *v1.PersistentVolume from k8s.io/client-go/informers/factory.go:133
I0405 02:22:46.605119       1 reflector.go:166] Listing and watching *v1.ReplicationController from k8s.io/client-go/informers/factory.go:133
I0405 02:22:46.608628       1 reflector.go:166] Listing and watching *v1beta1.PodDisruptionBudget from k8s.io/client-go/informers/factory.go:133
I0405 02:22:46.625690       1 reflector.go:166] Listing and watching *v1.StatefulSet from k8s.io/client-go/informers/factory.go:133
I0405 02:22:46.626871       1 reflector.go:166] Listing and watching *v1.Node from k8s.io/client-go/informers/factory.go:133
I0405 02:22:46.627961       1 reflector.go:166] Listing and watching *v1.Service from k8s.io/client-go/informers/factory.go:133
I0405 02:22:46.628296       1 reflector.go:166] Listing and watching *v1.ReplicaSet from k8s.io/client-go/informers/factory.go:133
I0405 02:22:46.634066       1 reflector.go:166] Listing and watching *v1.PersistentVolumeClaim from k8s.io/client-go/informers/factory.go:133
E0405 02:22:56.611718       1 reflector.go:131] k8s.io/kubernetes/cmd/kube-scheduler/app/server.go:223: Failed to list *v1.Pod: Get https://localhost:443/api/v1/pods?fieldSelector=status.phase%21%3DFailed%2Cstatus.phase%21%3DSucceeded&limit=500&resourceVersion=0: net/http: TLS handshake timeout
E0405 02:22:56.613203       1 reflector.go:131] k8s.io/client-go/informers/factory.go:133: Failed to list *v1beta1.PodDisruptionBudget: Get https://localhost:443/apis/policy/v1beta1/poddisruptionbudgets?limit=500&resourceVersion=0: net/http: TLS handshake timeout
E0405 02:22:56.613322       1 reflector.go:131] k8s.io/client-go/informers/factory.go:133: Failed to list *v1.StorageClass: Get https://localhost:443/apis/storage.k8s.io/v1/storageclasses?limit=500&resourceVersion=0: net/http: TLS handshake timeout
E0405 02:22:56.616106       1 reflector.go:131] k8s.io/client-go/informers/factory.go:133: Failed to list *v1.ReplicationController: Get https://localhost:443/api/v1/replicationcontrollers?limit=500&resourceVersion=0: net/http: TLS handshake timeout
E0405 02:22:56.618997       1 reflector.go:131] k8s.io/client-go/informers/factory.go:133: Failed to list *v1.PersistentVolume: Get https://localhost:443/api/v1/persistentvolumes?limit=500&resourceVersion=0: net/http: TLS handshake timeout
E0405 02:22:56.642509       1 reflector.go:131] k8s.io/client-go/informers/factory.go:133: Failed to list *v1.Service: Get https://localhost:443/api/v1/services?limit=500&resourceVersion=0: net/http: TLS handshake timeout
E0405 02:22:56.642663       1 reflector.go:131] k8s.io/client-go/informers/factory.go:133: Failed to list *v1.ReplicaSet: Get https://localhost:443/apis/apps/v1/replicasets?limit=500&resourceVersion=0: net/http: TLS handshake timeout
E0405 02:22:56.642778       1 reflector.go:131] k8s.io/client-go/informers/factory.go:133: Failed to list *v1.Node: Get https://localhost:443/api/v1/nodes?limit=500&resourceVersion=0: net/http: TLS handshake timeout
E0405 02:22:56.642896       1 reflector.go:131] k8s.io/client-go/informers/factory.go:133: Failed to list *v1.StatefulSet: Get https://localhost:443/apis/apps/v1/statefulsets?limit=500&resourceVersion=0: net/http: TLS handshake timeout
E0405 02:22:56.653521       1 reflector.go:131] k8s.io/client-go/informers/factory.go:133: Failed to list *v1.PersistentVolumeClaim: Get https://localhost:443/api/v1/persistentvolumeclaims?limit=500&resourceVersion=0: net/http: TLS handshake timeout
E0405 02:22:56.611718       1 reflector.go:131] k8s.io/kubernetes/cmd/kube-scheduler/app/server.go:223: Failed to list *v1.Pod: Get https://localhost:443/api/v1/pods?fieldSelector=status.phase%21%3DFailed%2Cstatus.phase%21%3DSucceeded&limit=500&resourceVersion=0: net/http: TLS handshake timeout
E0405 02:22:56.613203       1 reflector.go:131] k8s.io/client-go/informers/factory.go:133: Failed to list *v1beta1.PodDisruptionBudget: Get https://localhost:443/apis/policy/v1beta1/poddisruptionbudgets?limit=500&resourceVersion=0: net/http: TLS handshake timeout
E0405 02:22:56.613322       1 reflector.go:131] k8s.io/client-go/informers/factory.go:133: Failed to list *v1.StorageClass: Get https://localhost:443/apis/storage.k8s.io/v1/storageclasses?limit=500&resourceVersion=0: net/http: TLS handshake timeout
E0405 02:22:56.616106       1 reflector.go:131] k8s.io/client-go/informers/factory.go:133: Failed to list *v1.ReplicationController: Get https://localhost:443/api/v1/replicationcontrollers?limit=500&resourceVersion=0: net/http: TLS handshake timeout
E0405 02:22:56.618997       1 reflector.go:131] k8s.io/client-go/informers/factory.go:133: Failed to list *v1.PersistentVolume: Get https://localhost:443/api/v1/persistentvolumes?limit=500&resourceVersion=0: net/http: TLS handshake timeout
E0405 02:22:56.642509       1 reflector.go:131] k8s.io/client-go/informers/factory.go:133: Failed to list *v1.Service: Get https://localhost:443/api/v1/services?limit=500&resourceVersion=0: net/http: TLS handshake timeout
E0405 02:22:56.642663       1 reflector.go:131] k8s.io/client-go/informers/factory.go:133: Failed to list *v1.ReplicaSet: Get https://localhost:443/apis/apps/v1/replicasets?limit=500&resourceVersion=0: net/http: TLS handshake timeout
E0405 02:22:56.642778       1 reflector.go:131] k8s.io/client-go/informers/factory.go:133: Failed to list *v1.Node: Get https://localhost:443/api/v1/nodes?limit=500&resourceVersion=0: net/http: TLS handshake timeout
E0405 02:22:56.642896       1 reflector.go:131] k8s.io/client-go/informers/factory.go:133: Failed to list *v1.StatefulSet: Get https://localhost:443/apis/apps/v1/statefulsets?limit=500&resourceVersion=0: net/http: TLS handshake timeout
E0405 02:22:56.653521       1 reflector.go:131] k8s.io/client-go/informers/factory.go:133: Failed to list *v1.PersistentVolumeClaim: Get https://localhost:443/api/v1/persistentvolumeclaims?limit=500&resourceVersion=0: net/http: TLS handshake timeout
I0405 02:22:56.611706       1 trace.go:81] Trace[1409465305]: "Reflector k8s.io/kubernetes/cmd/kube-scheduler/app/server.go:223 ListAndWatch" (started: 2019-04-05 02:22:46.6045955 +0000 UTC m=+3.179070085) (total time: 10.007049341s):
Trace[1409465305]: [10.007049341s] [10.007049341s] END
E0405 02:22:56.611718       1 reflector.go:131] k8s.io/kubernetes/cmd/kube-scheduler/app/server.go:223: Failed to list *v1.Pod: Get https://localhost:443/api/v1/pods?fieldSelector=status.phase%21%3DFailed%2Cstatus.phase%21%3DSucceeded&limit=500&resourceVersion=0: net/http: TLS handshake timeout
I0405 02:22:56.613186       1 trace.go:81] Trace[341514596]: "Reflector k8s.io/client-go/informers/factory.go:133 ListAndWatch" (started: 2019-04-05 02:22:46.608642253 +0000 UTC m=+3.183116840) (total time: 10.004501319s):
Trace[341514596]: [10.004501319s] [10.004501319s] END
E0405 02:22:56.613203       1 reflector.go:131] k8s.io/client-go/informers/factory.go:133: Failed to list *v1beta1.PodDisruptionBudget: Get https://localhost:443/apis/policy/v1beta1/poddisruptionbudgets?limit=500&resourceVersion=0: net/http: TLS handshake timeout
I0405 02:22:56.613318       1 trace.go:81] Trace[1760684109]: "Reflector k8s.io/client-go/informers/factory.go:133 ListAndWatch" (started: 2019-04-05 02:22:46.604033392 +0000 UTC m=+3.178508103) (total time: 10.009272237s):
Trace[1760684109]: [10.009272237s] [10.009272237s] END
E0405 02:22:56.613322       1 reflector.go:131] k8s.io/client-go/informers/factory.go:133: Failed to list *v1.StorageClass: Get https://localhost:443/apis/storage.k8s.io/v1/storageclasses?limit=500&resourceVersion=0: net/http: TLS handshake timeout
I0405 02:22:56.616098       1 trace.go:81] Trace[104724442]: "Reflector k8s.io/client-go/informers/factory.go:133 ListAndWatch" (started: 2019-04-05 02:22:46.605123375 +0000 UTC m=+3.179597976) (total time: 10.01094807s):
Trace[104724442]: [10.01094807s] [10.01094807s] END
E0405 02:22:56.616106       1 reflector.go:131] k8s.io/client-go/informers/factory.go:133: Failed to list *v1.ReplicationController: Get https://localhost:443/api/v1/replicationcontrollers?limit=500&resourceVersion=0: net/http: TLS handshake timeout
I0405 02:22:56.618989       1 trace.go:81] Trace[263291709]: "Reflector k8s.io/client-go/informers/factory.go:133 ListAndWatch" (started: 2019-04-05 02:22:46.604843669 +0000 UTC m=+3.179318254) (total time: 10.014121809s):
Trace[263291709]: [10.014121809s] [10.014121809s] END
E0405 02:22:56.618997       1 reflector.go:131] k8s.io/client-go/informers/factory.go:133: Failed to list *v1.PersistentVolume: Get https://localhost:443/api/v1/persistentvolumes?limit=500&resourceVersion=0: net/http: TLS handshake timeout
I0405 02:22:56.642497       1 trace.go:81] Trace[442647478]: "Reflector k8s.io/client-go/informers/factory.go:133 ListAndWatch" (started: 2019-04-05 02:22:46.627968637 +0000 UTC m=+3.202443230) (total time: 10.01447666s):
Trace[442647478]: [10.01447666s] [10.01447666s] END
E0405 02:22:56.642509       1 reflector.go:131] k8s.io/client-go/informers/factory.go:133: Failed to list *v1.Service: Get https://localhost:443/api/v1/services?limit=500&resourceVersion=0: net/http: TLS handshake timeout
I0405 02:22:56.642660       1 trace.go:81] Trace[476963929]: "Reflector k8s.io/client-go/informers/factory.go:133 ListAndWatch" (started: 2019-04-05 02:22:46.628300973 +0000 UTC m=+3.202775559) (total time: 10.014345513s):
Trace[476963929]: [10.014345513s] [10.014345513s] END
E0405 02:22:56.642663       1 reflector.go:131] k8s.io/client-go/informers/factory.go:133: Failed to list *v1.ReplicaSet: Get https://localhost:443/apis/apps/v1/replicasets?limit=500&resourceVersion=0: net/http: TLS handshake timeout
I0405 02:22:56.642774       1 trace.go:81] Trace[1721671144]: "Reflector k8s.io/client-go/informers/factory.go:133 ListAndWatch" (started: 2019-04-05 02:22:46.626883581 +0000 UTC m=+3.201358168) (total time: 10.015839723s):
Trace[1721671144]: [10.015839723s] [10.015839723s] END
E0405 02:22:56.642778       1 reflector.go:131] k8s.io/client-go/informers/factory.go:133: Failed to list *v1.Node: Get https://localhost:443/api/v1/nodes?limit=500&resourceVersion=0: net/http: TLS handshake timeout
I0405 02:22:56.642894       1 trace.go:81] Trace[873201338]: "Reflector k8s.io/client-go/informers/factory.go:133 ListAndWatch" (started: 2019-04-05 02:22:46.625711572 +0000 UTC m=+3.200186163) (total time: 10.017172579s):
Trace[873201338]: [10.017172579s] [10.017172579s] END
E0405 02:22:56.642896       1 reflector.go:131] k8s.io/client-go/informers/factory.go:133: Failed to list *v1.StatefulSet: Get https://localhost:443/apis/apps/v1/statefulsets?limit=500&resourceVersion=0: net/http: TLS handshake timeout
I0405 02:22:56.653509       1 trace.go:81] Trace[207827490]: "Reflector k8s.io/client-go/informers/factory.go:133 ListAndWatch" (started: 2019-04-05 02:22:46.634080875 +0000 UTC m=+3.208555461) (total time: 10.019391986s):
Trace[207827490]: [10.019391986s] [10.019391986s] END
E0405 02:22:56.653521       1 reflector.go:131] k8s.io/client-go/informers/factory.go:133: Failed to list *v1.PersistentVolumeClaim: Get https://localhost:443/api/v1/persistentvolumeclaims?limit=500&resourceVersion=0: net/http: TLS handshake timeout
I0405 02:22:57.611945       1 reflector.go:166] Listing and watching *v1.Pod from k8s.io/kubernetes/cmd/kube-scheduler/app/server.go:223
I0405 02:22:57.613349       1 reflector.go:166] Listing and watching *v1beta1.PodDisruptionBudget from k8s.io/client-go/informers/factory.go:133
I0405 02:22:57.614429       1 reflector.go:166] Listing and watching *v1.StorageClass from k8s.io/client-go/informers/factory.go:133
I0405 02:22:57.616229       1 reflector.go:166] Listing and watching *v1.ReplicationController from k8s.io/client-go/informers/factory.go:133
I0405 02:22:57.619150       1 reflector.go:166] Listing and watching *v1.PersistentVolume from k8s.io/client-go/informers/factory.go:133
I0405 02:22:57.643195       1 reflector.go:166] Listing and watching *v1.Service from k8s.io/client-go/informers/factory.go:133
I0405 02:22:57.644217       1 reflector.go:166] Listing and watching *v1.ReplicaSet from k8s.io/client-go/informers/factory.go:133
I0405 02:22:57.646969       1 reflector.go:166] Listing and watching *v1.StatefulSet from k8s.io/client-go/informers/factory.go:133
I0405 02:22:57.647269       1 reflector.go:166] Listing and watching *v1.Node from k8s.io/client-go/informers/factory.go:133
I0405 02:22:57.657761       1 reflector.go:166] Listing and watching *v1.PersistentVolumeClaim from k8s.io/client-go/informers/factory.go:133
E0405 02:23:07.546291       1 reflector.go:131] k8s.io/client-go/informers/factory.go:133: Failed to list *v1.PersistentVolume: persistentvolumes is forbidden: User "system:kube-scheduler" cannot list resource "persistentvolumes" in API group "" at the cluster scope
E0405 02:23:07.546606       1 reflector.go:131] k8s.io/kubernetes/cmd/kube-scheduler/app/server.go:223: Failed to list *v1.Pod: pods is forbidden: User "system:kube-scheduler" cannot list resource "pods" in API group "" at the cluster scope
E0405 02:23:07.546772       1 reflector.go:131] k8s.io/client-go/informers/factory.go:133: Failed to list *v1beta1.PodDisruptionBudget: poddisruptionbudgets.policy is forbidden: User "system:kube-scheduler" cannot list resource "poddisruptionbudgets" in API group "policy" at the cluster scope
E0405 02:23:07.546945       1 reflector.go:131] k8s.io/client-go/informers/factory.go:133: Failed to list *v1.Node: nodes is forbidden: User "system:kube-scheduler" cannot list resource "nodes" in API group "" at the cluster scope
E0405 02:23:07.547072       1 reflector.go:131] k8s.io/client-go/informers/factory.go:133: Failed to list *v1.PersistentVolumeClaim: persistentvolumeclaims is forbidden: User "system:kube-scheduler" cannot list resource "persistentvolumeclaims" in API group "" at the cluster scope
E0405 02:23:07.547218       1 reflector.go:131] k8s.io/client-go/informers/factory.go:133: Failed to list *v1.Service: services is forbidden: User "system:kube-scheduler" cannot list resource "services" in API group "" at the cluster scope
E0405 02:23:07.547362       1 reflector.go:131] k8s.io/client-go/informers/factory.go:133: Failed to list *v1.ReplicaSet: replicasets.apps is forbidden: User "system:kube-scheduler" cannot list resource "replicasets" in API group "apps" at the cluster scope
E0405 02:23:07.547499       1 reflector.go:131] k8s.io/client-go/informers/factory.go:133: Failed to list *v1.StatefulSet: statefulsets.apps is forbidden: User "system:kube-scheduler" cannot list resource "statefulsets" in API group "apps" at the cluster scope
E0405 02:23:07.547641       1 reflector.go:131] k8s.io/client-go/informers/factory.go:133: Failed to list *v1.StorageClass: storageclasses.storage.k8s.io is forbidden: User "system:kube-scheduler" cannot list resource "storageclasses" in API group "storage.k8s.io" at the cluster scope
E0405 02:23:07.549985       1 reflector.go:131] k8s.io/client-go/informers/factory.go:133: Failed to list *v1.ReplicationController: replicationcontrollers is forbidden: User "system:kube-scheduler" cannot list resource "replicationcontrollers" in API group "" at the cluster scope
E0405 02:23:07.546291       1 reflector.go:131] k8s.io/client-go/informers/factory.go:133: Failed to list *v1.PersistentVolume: persistentvolumes is forbidden: User "system:kube-scheduler" cannot list resource "persistentvolumes" in API group "" at the cluster scope
E0405 02:23:07.546606       1 reflector.go:131] k8s.io/kubernetes/cmd/kube-scheduler/app/server.go:223: Failed to list *v1.Pod: pods is forbidden: User "system:kube-scheduler" cannot list resource "pods" in API group "" at the cluster scope
E0405 02:23:07.546772       1 reflector.go:131] k8s.io/client-go/informers/factory.go:133: Failed to list *v1beta1.PodDisruptionBudget: poddisruptionbudgets.policy is forbidden: User "system:kube-scheduler" cannot list resource "poddisruptionbudgets" in API group "policy" at the cluster scope
E0405 02:23:07.546945       1 reflector.go:131] k8s.io/client-go/informers/factory.go:133: Failed to list *v1.Node: nodes is forbidden: User "system:kube-scheduler" cannot list resource "nodes" in API group "" at the cluster scope
E0405 02:23:07.547072       1 reflector.go:131] k8s.io/client-go/informers/factory.go:133: Failed to list *v1.PersistentVolumeClaim: persistentvolumeclaims is forbidden: User "system:kube-scheduler" cannot list resource "persistentvolumeclaims" in API group "" at the cluster scope
E0405 02:23:07.547218       1 reflector.go:131] k8s.io/client-go/informers/factory.go:133: Failed to list *v1.Service: services is forbidden: User "system:kube-scheduler" cannot list resource "services" in API group "" at the cluster scope
E0405 02:23:07.547362       1 reflector.go:131] k8s.io/client-go/informers/factory.go:133: Failed to list *v1.ReplicaSet: replicasets.apps is forbidden: User "system:kube-scheduler" cannot list resource "replicasets" in API group "apps" at the cluster scope
E0405 02:23:07.547499       1 reflector.go:131] k8s.io/client-go/informers/factory.go:133: Failed to list *v1.StatefulSet: statefulsets.apps is forbidden: User "system:kube-scheduler" cannot list resource "statefulsets" in API group "apps" at the cluster scope
E0405 02:23:07.547641       1 reflector.go:131] k8s.io/client-go/informers/factory.go:133: Failed to list *v1.StorageClass: storageclasses.storage.k8s.io is forbidden: User "system:kube-scheduler" cannot list resource "storageclasses" in API group "storage.k8s.io" at the cluster scope
E0405 02:23:07.549985       1 reflector.go:131] k8s.io/client-go/informers/factory.go:133: Failed to list *v1.ReplicationController: replicationcontrollers is forbidden: User "system:kube-scheduler" cannot list resource "replicationcontrollers" in API group "" at the cluster scope
I0405 02:23:07.370297       1 wrap.go:47] GET /healthz: (78.26µs) 200 [kube-probe/1.15+ 127.0.0.1:60042]
E0405 02:23:07.546291       1 reflector.go:131] k8s.io/client-go/informers/factory.go:133: Failed to list *v1.PersistentVolume: persistentvolumes is forbidden: User "system:kube-scheduler" cannot list resource "persistentvolumes" in API group "" at the cluster scope
E0405 02:23:07.546606       1 reflector.go:131] k8s.io/kubernetes/cmd/kube-scheduler/app/server.go:223: Failed to list *v1.Pod: pods is forbidden: User "system:kube-scheduler" cannot list resource "pods" in API group "" at the cluster scope
E0405 02:23:07.546772       1 reflector.go:131] k8s.io/client-go/informers/factory.go:133: Failed to list *v1beta1.PodDisruptionBudget: poddisruptionbudgets.policy is forbidden: User "system:kube-scheduler" cannot list resource "poddisruptionbudgets" in API group "policy" at the cluster scope
E0405 02:23:07.546945       1 reflector.go:131] k8s.io/client-go/informers/factory.go:133: Failed to list *v1.Node: nodes is forbidden: User "system:kube-scheduler" cannot list resource "nodes" in API group "" at the cluster scope
E0405 02:23:07.547072       1 reflector.go:131] k8s.io/client-go/informers/factory.go:133: Failed to list *v1.PersistentVolumeClaim: persistentvolumeclaims is forbidden: User "system:kube-scheduler" cannot list resource "persistentvolumeclaims" in API group "" at the cluster scope
E0405 02:23:07.547218       1 reflector.go:131] k8s.io/client-go/informers/factory.go:133: Failed to list *v1.Service: services is forbidden: User "system:kube-scheduler" cannot list resource "services" in API group "" at the cluster scope
E0405 02:23:07.547362       1 reflector.go:131] k8s.io/client-go/informers/factory.go:133: Failed to list *v1.ReplicaSet: replicasets.apps is forbidden: User "system:kube-scheduler" cannot list resource "replicasets" in API group "apps" at the cluster scope
E0405 02:23:07.547499       1 reflector.go:131] k8s.io/client-go/informers/factory.go:133: Failed to list *v1.StatefulSet: statefulsets.apps is forbidden: User "system:kube-scheduler" cannot list resource "statefulsets" in API group "apps" at the cluster scope
E0405 02:23:07.547641       1 reflector.go:131] k8s.io/client-go/informers/factory.go:133: Failed to list *v1.StorageClass: storageclasses.storage.k8s.io is forbidden: User "system:kube-scheduler" cannot list resource "storageclasses" in API group "storage.k8s.io" at the cluster scope
E0405 02:23:07.549985       1 reflector.go:131] k8s.io/client-go/informers/factory.go:133: Failed to list *v1.ReplicationController: replicationcontrollers is forbidden: User "system:kube-scheduler" cannot list resource "replicationcontrollers" in API group "" at the cluster scope
E0405 02:23:08.553149       1 reflector.go:131] k8s.io/client-go/informers/factory.go:133: Failed to list *v1.PersistentVolume: persistentvolumes is forbidden: User "system:kube-scheduler" cannot list resource "persistentvolumes" in API group "" at the cluster scope
E0405 02:23:08.553461       1 reflector.go:131] k8s.io/kubernetes/cmd/kube-scheduler/app/server.go:223: Failed to list *v1.Pod: pods is forbidden: User "system:kube-scheduler" cannot list resource "pods" in API group "" at the cluster scope
E0405 02:23:08.555347       1 reflector.go:131] k8s.io/client-go/informers/factory.go:133: Failed to list *v1beta1.PodDisruptionBudget: poddisruptionbudgets.policy is forbidden: User "system:kube-scheduler" cannot list resource "poddisruptionbudgets" in API group "policy" at the cluster scope
E0405 02:23:08.560802       1 reflector.go:131] k8s.io/client-go/informers/factory.go:133: Failed to list *v1.Node: nodes is forbidden: User "system:kube-scheduler" cannot list resource "nodes" in API group "" at the cluster scope
E0405 02:23:08.563566       1 reflector.go:131] k8s.io/client-go/informers/factory.go:133: Failed to list *v1.PersistentVolumeClaim: persistentvolumeclaims is forbidden: User "system:kube-scheduler" cannot list resource "persistentvolumeclaims" in API group "" at the cluster scope
E0405 02:23:08.565903       1 reflector.go:131] k8s.io/client-go/informers/factory.go:133: Failed to list *v1.Service: services is forbidden: User "system:kube-scheduler" cannot list resource "services" in API group "" at the cluster scope
E0405 02:23:08.574022       1 reflector.go:131] k8s.io/client-go/informers/factory.go:133: Failed to list *v1.ReplicaSet: replicasets.apps is forbidden: User "system:kube-scheduler" cannot list resource "replicasets" in API group "apps" at the cluster scope
E0405 02:23:08.578780       1 reflector.go:131] k8s.io/client-go/informers/factory.go:133: Failed to list *v1.ReplicationController: replicationcontrollers is forbidden: User "system:kube-scheduler" cannot list resource "replicationcontrollers" in API group "" at the cluster scope
E0405 02:23:08.579066       1 reflector.go:131] k8s.io/client-go/informers/factory.go:133: Failed to list *v1.StatefulSet: statefulsets.apps is forbidden: User "system:kube-scheduler" cannot list resource "statefulsets" in API group "apps" at the cluster scope
E0405 02:23:08.579233       1 reflector.go:131] k8s.io/client-go/informers/factory.go:133: Failed to list *v1.StorageClass: storageclasses.storage.k8s.io is forbidden: User "system:kube-scheduler" cannot list resource "storageclasses" in API group "storage.k8s.io" at the cluster scope
E0405 02:23:08.553149       1 reflector.go:131] k8s.io/client-go/informers/factory.go:133: Failed to list *v1.PersistentVolume: persistentvolumes is forbidden: User "system:kube-scheduler" cannot list resource "persistentvolumes" in API group "" at the cluster scope
E0405 02:23:08.553461       1 reflector.go:131] k8s.io/kubernetes/cmd/kube-scheduler/app/server.go:223: Failed to list *v1.Pod: pods is forbidden: User "system:kube-scheduler" cannot list resource "pods" in API group "" at the cluster scope
E0405 02:23:08.555347       1 reflector.go:131] k8s.io/client-go/informers/factory.go:133: Failed to list *v1beta1.PodDisruptionBudget: poddisruptionbudgets.policy is forbidden: User "system:kube-scheduler" cannot list resource "poddisruptionbudgets" in API group "policy" at the cluster scope
E0405 02:23:08.560802       1 reflector.go:131] k8s.io/client-go/informers/factory.go:133: Failed to list *v1.Node: nodes is forbidden: User "system:kube-scheduler" cannot list resource "nodes" in API group "" at the cluster scope
E0405 02:23:08.563566       1 reflector.go:131] k8s.io/client-go/informers/factory.go:133: Failed to list *v1.PersistentVolumeClaim: persistentvolumeclaims is forbidden: User "system:kube-scheduler" cannot list resource "persistentvolumeclaims" in API group "" at the cluster scope
E0405 02:23:08.565903       1 reflector.go:131] k8s.io/client-go/informers/factory.go:133: Failed to list *v1.Service: services is forbidden: User "system:kube-scheduler" cannot list resource "services" in API group "" at the cluster scope
E0405 02:23:08.574022       1 reflector.go:131] k8s.io/client-go/informers/factory.go:133: Failed to list *v1.ReplicaSet: replicasets.apps is forbidden: User "system:kube-scheduler" cannot list resource "replicasets" in API group "apps" at the cluster scope
E0405 02:23:08.578780       1 reflector.go:131] k8s.io/client-go/informers/factory.go:133: Failed to list *v1.ReplicationController: replicationcontrollers is forbidden: User "system:kube-scheduler" cannot list resource "replicationcontrollers" in API group "" at the cluster scope
E0405 02:23:08.579066       1 reflector.go:131] k8s.io/client-go/informers/factory.go:133: Failed to list *v1.StatefulSet: statefulsets.apps is forbidden: User "system:kube-scheduler" cannot list resource "statefulsets" in API group "apps" at the cluster scope
E0405 02:23:08.579233       1 reflector.go:131] k8s.io/client-go/informers/factory.go:133: Failed to list *v1.StorageClass: storageclasses.storage.k8s.io is forbidden: User "system:kube-scheduler" cannot list resource "storageclasses" in API group "storage.k8s.io" at the cluster scope
I0405 02:23:08.550334       1 reflector.go:166] Listing and watching *v1.Pod from k8s.io/kubernetes/cmd/kube-scheduler/app/server.go:223
I0405 02:23:08.550570       1 reflector.go:166] Listing and watching *v1.PersistentVolume from k8s.io/client-go/informers/factory.go:133
E0405 02:23:08.553149       1 reflector.go:131] k8s.io/client-go/informers/factory.go:133: Failed to list *v1.PersistentVolume: persistentvolumes is forbidden: User "system:kube-scheduler" cannot list resource "persistentvolumes" in API group "" at the cluster scope
E0405 02:23:08.553461       1 reflector.go:131] k8s.io/kubernetes/cmd/kube-scheduler/app/server.go:223: Failed to list *v1.Pod: pods is forbidden: User "system:kube-scheduler" cannot list resource "pods" in API group "" at the cluster scope
I0405 02:23:08.553943       1 reflector.go:166] Listing and watching *v1beta1.PodDisruptionBudget from k8s.io/client-go/informers/factory.go:133
E0405 02:23:08.555347       1 reflector.go:131] k8s.io/client-go/informers/factory.go:133: Failed to list *v1beta1.PodDisruptionBudget: poddisruptionbudgets.policy is forbidden: User "system:kube-scheduler" cannot list resource "poddisruptionbudgets" in API group "policy" at the cluster scope
I0405 02:23:08.557197       1 reflector.go:166] Listing and watching *v1.Node from k8s.io/client-go/informers/factory.go:133
I0405 02:23:08.560508       1 reflector.go:166] Listing and watching *v1.PersistentVolumeClaim from k8s.io/client-go/informers/factory.go:133
E0405 02:23:08.560802       1 reflector.go:131] k8s.io/client-go/informers/factory.go:133: Failed to list *v1.Node: nodes is forbidden: User "system:kube-scheduler" cannot list resource "nodes" in API group "" at the cluster scope
I0405 02:23:08.563307       1 reflector.go:166] Listing and watching *v1.Service from k8s.io/client-go/informers/factory.go:133
E0405 02:23:08.563566       1 reflector.go:131] k8s.io/client-go/informers/factory.go:133: Failed to list *v1.PersistentVolumeClaim: persistentvolumeclaims is forbidden: User "system:kube-scheduler" cannot list resource "persistentvolumeclaims" in API group "" at the cluster scope
E0405 02:23:08.565903       1 reflector.go:131] k8s.io/client-go/informers/factory.go:133: Failed to list *v1.Service: services is forbidden: User "system:kube-scheduler" cannot list resource "services" in API group "" at the cluster scope
I0405 02:23:08.568880       1 reflector.go:166] Listing and watching *v1.ReplicaSet from k8s.io/client-go/informers/factory.go:133
E0405 02:23:08.574022       1 reflector.go:131] k8s.io/client-go/informers/factory.go:133: Failed to list *v1.ReplicaSet: replicasets.apps is forbidden: User "system:kube-scheduler" cannot list resource "replicasets" in API group "apps" at the cluster scope
I0405 02:23:08.575757       1 reflector.go:166] Listing and watching *v1.StatefulSet from k8s.io/client-go/informers/factory.go:133
I0405 02:23:08.575979       1 reflector.go:166] Listing and watching *v1.StorageClass from k8s.io/client-go/informers/factory.go:133
I0405 02:23:08.576072       1 reflector.go:166] Listing and watching *v1.ReplicationController from k8s.io/client-go/informers/factory.go:133
E0405 02:23:08.578780       1 reflector.go:131] k8s.io/client-go/informers/factory.go:133: Failed to list *v1.ReplicationController: replicationcontrollers is forbidden: User "system:kube-scheduler" cannot list resource "replicationcontrollers" in API group "" at the cluster scope
E0405 02:23:08.579066       1 reflector.go:131] k8s.io/client-go/informers/factory.go:133: Failed to list *v1.StatefulSet: statefulsets.apps is forbidden: User "system:kube-scheduler" cannot list resource "statefulsets" in API group "apps" at the cluster scope
E0405 02:23:08.579233       1 reflector.go:131] k8s.io/client-go/informers/factory.go:133: Failed to list *v1.StorageClass: storageclasses.storage.k8s.io is forbidden: User "system:kube-scheduler" cannot list resource "storageclasses" in API group "storage.k8s.io" at the cluster scope
I0405 02:23:09.554593       1 reflector.go:166] Listing and watching *v1.PersistentVolume from k8s.io/client-go/informers/factory.go:133
I0405 02:23:09.559795       1 reflector.go:166] Listing and watching *v1.Pod from k8s.io/kubernetes/cmd/kube-scheduler/app/server.go:223
I0405 02:23:09.561363       1 reflector.go:166] Listing and watching *v1beta1.PodDisruptionBudget from k8s.io/client-go/informers/factory.go:133
I0405 02:23:09.563647       1 reflector.go:166] Listing and watching *v1.Node from k8s.io/client-go/informers/factory.go:133
I0405 02:23:09.566679       1 reflector.go:166] Listing and watching *v1.PersistentVolumeClaim from k8s.io/client-go/informers/factory.go:133
I0405 02:23:09.569985       1 reflector.go:166] Listing and watching *v1.Service from k8s.io/client-go/informers/factory.go:133
I0405 02:23:09.574529       1 reflector.go:166] Listing and watching *v1.ReplicaSet from k8s.io/client-go/informers/factory.go:133
I0405 02:23:09.581884       1 reflector.go:166] Listing and watching *v1.StatefulSet from k8s.io/client-go/informers/factory.go:133
I0405 02:23:09.582148       1 reflector.go:166] Listing and watching *v1.ReplicationController from k8s.io/client-go/informers/factory.go:133
I0405 02:23:09.586588       1 reflector.go:166] Listing and watching *v1.StorageClass from k8s.io/client-go/informers/factory.go:133
I0405 02:23:09.674437       1 shared_informer.go:123] caches populated
I0405 02:23:09.774542       1 shared_informer.go:123] caches populated
I0405 02:23:09.874768       1 shared_informer.go:123] caches populated
I0405 02:23:09.975006       1 shared_informer.go:123] caches populated
I0405 02:23:10.075135       1 shared_informer.go:123] caches populated
I0405 02:23:10.175417       1 shared_informer.go:123] caches populated
I0405 02:23:10.276062       1 shared_informer.go:123] caches populated
I0405 02:23:10.376875       1 shared_informer.go:123] caches populated
I0405 02:23:10.477354       1 shared_informer.go:123] caches populated
I0405 02:23:10.477375       1 controller_utils.go:1028] Waiting for caches to sync for scheduler controller
I0405 02:23:10.578196       1 shared_informer.go:123] caches populated
I0405 02:23:10.578228       1 controller_utils.go:1035] Caches are synced for scheduler controller
I0405 02:23:10.578304       1 leaderelection.go:217] attempting to acquire leader lease  kube-system/kube-scheduler...
I0405 02:23:10.589940       1 leaderelection.go:227] successfully acquired lease kube-system/kube-scheduler
I0405 02:23:10.692097       1 shared_informer.go:123] caches populated
I0405 02:23:17.362884       1 wrap.go:47] GET /healthz: (115.233µs) 200 [kube-probe/1.15+ 127.0.0.1:60746]
E0405 02:23:26.021479       1 scheduler.go:482] error selecting node for pod: no nodes available to schedule pods
E0405 02:23:26.022340       1 scheduler.go:482] error selecting node for pod: no nodes available to schedule pods
E0405 02:23:26.161896       1 scheduler.go:482] error selecting node for pod: no nodes available to schedule pods
E0405 02:23:26.162546       1 scheduler.go:482] error selecting node for pod: no nodes available to schedule pods
E0405 02:23:26.432875       1 scheduler.go:482] error selecting node for pod: no nodes available to schedule pods
E0405 02:23:26.815410       1 scheduler.go:482] error selecting node for pod: no nodes available to schedule pods
E0405 02:23:26.815856       1 scheduler.go:482] error selecting node for pod: no nodes available to schedule pods
E0405 02:23:27.635809       1 scheduler.go:482] error selecting node for pod: no nodes available to schedule pods
E0405 02:23:27.640953       1 scheduler.go:482] error selecting node for pod: no nodes available to schedule pods
E0405 02:23:27.646018       1 scheduler.go:482] error selecting node for pod: no nodes available to schedule pods
E0405 02:23:26.021479       1 scheduler.go:482] error selecting node for pod: no nodes available to schedule pods
E0405 02:23:26.022340       1 scheduler.go:482] error selecting node for pod: no nodes available to schedule pods
E0405 02:23:26.161896       1 scheduler.go:482] error selecting node for pod: no nodes available to schedule pods
E0405 02:23:26.162546       1 scheduler.go:482] error selecting node for pod: no nodes available to schedule pods
E0405 02:23:26.432875       1 scheduler.go:482] error selecting node for pod: no nodes available to schedule pods
E0405 02:23:26.815410       1 scheduler.go:482] error selecting node for pod: no nodes available to schedule pods
E0405 02:23:26.815856       1 scheduler.go:482] error selecting node for pod: no nodes available to schedule pods
E0405 02:23:27.635809       1 scheduler.go:482] error selecting node for pod: no nodes available to schedule pods
E0405 02:23:27.640953       1 scheduler.go:482] error selecting node for pod: no nodes available to schedule pods
E0405 02:23:27.646018       1 scheduler.go:482] error selecting node for pod: no nodes available to schedule pods
I0405 02:23:25.979978       1 scheduling_queue.go:895] About to try and schedule pod kube-system/coredns-5b969f4c88-464mz
I0405 02:23:25.980488       1 scheduler.go:454] Attempting to schedule pod: kube-system/coredns-5b969f4c88-464mz
I0405 02:23:25.980585       1 factory.go:645] Unable to schedule kube-system/coredns-5b969f4c88-464mz: no nodes are registered to the cluster; waiting
I0405 02:23:25.980629       1 factory.go:743] Updating pod condition for kube-system/coredns-5b969f4c88-464mz to (PodScheduled==False, Reason=Unschedulable)
E0405 02:23:26.021479       1 scheduler.go:482] error selecting node for pod: no nodes available to schedule pods
I0405 02:23:26.022226       1 scheduling_queue.go:895] About to try and schedule pod kube-system/coredns-5b969f4c88-464mz
I0405 02:23:26.022239       1 scheduler.go:454] Attempting to schedule pod: kube-system/coredns-5b969f4c88-464mz
I0405 02:23:26.022298       1 factory.go:645] Unable to schedule kube-system/coredns-5b969f4c88-464mz: no nodes are registered to the cluster; waiting
I0405 02:23:26.022331       1 factory.go:743] Updating pod condition for kube-system/coredns-5b969f4c88-464mz to (PodScheduled==False, Reason=Unschedulable)
E0405 02:23:26.022340       1 scheduler.go:482] error selecting node for pod: no nodes available to schedule pods
I0405 02:23:26.136333       1 scheduling_queue.go:895] About to try and schedule pod kube-system/l7-default-backend-8f479dd9-jx5v6
I0405 02:23:26.136348       1 scheduler.go:454] Attempting to schedule pod: kube-system/l7-default-backend-8f479dd9-jx5v6
I0405 02:23:26.136381       1 factory.go:645] Unable to schedule kube-system/l7-default-backend-8f479dd9-jx5v6: no nodes are registered to the cluster; waiting
I0405 02:23:26.137857       1 factory.go:743] Updating pod condition for kube-system/l7-default-backend-8f479dd9-jx5v6 to (PodScheduled==False, Reason=Unschedulable)
E0405 02:23:26.161896       1 scheduler.go:482] error selecting node for pod: no nodes available to schedule pods
I0405 02:23:26.162447       1 scheduling_queue.go:895] About to try and schedule pod kube-system/l7-default-backend-8f479dd9-jx5v6
I0405 02:23:26.162461       1 scheduler.go:454] Attempting to schedule pod: kube-system/l7-default-backend-8f479dd9-jx5v6
I0405 02:23:26.162505       1 factory.go:645] Unable to schedule kube-system/l7-default-backend-8f479dd9-jx5v6: no nodes are registered to the cluster; waiting
I0405 02:23:26.162536       1 factory.go:743] Updating pod condition for kube-system/l7-default-backend-8f479dd9-jx5v6 to (PodScheduled==False, Reason=Unschedulable)
E0405 02:23:26.162546       1 scheduler.go:482] error selecting node for pod: no nodes available to schedule pods
I0405 02:23:26.398649       1 scheduling_queue.go:895] About to try and schedule pod kube-system/heapster-v1.6.0-beta.1-5858bf5485-mwbsb
I0405 02:23:26.398680       1 scheduler.go:454] Attempting to schedule pod: kube-system/heapster-v1.6.0-beta.1-5858bf5485-mwbsb
I0405 02:23:26.398722       1 factory.go:645] Unable to schedule kube-system/heapster-v1.6.0-beta.1-5858bf5485-mwbsb: no nodes are registered to the cluster; waiting
I0405 02:23:26.398824       1 factory.go:743] Updating pod condition for kube-system/heapster-v1.6.0-beta.1-5858bf5485-mwbsb to (PodScheduled==False, Reason=Unschedulable)
E0405 02:23:26.432875       1 scheduler.go:482] error selecting node for pod: no nodes available to schedule pods
I0405 02:23:26.799240       1 scheduling_queue.go:895] About to try and schedule pod kube-system/event-exporter-v0.2.4-65d8d98768-2nbf2
I0405 02:23:26.799369       1 scheduler.go:454] Attempting to schedule pod: kube-system/event-exporter-v0.2.4-65d8d98768-2nbf2
I0405 02:23:26.799403       1 factory.go:645] Unable to schedule kube-system/event-exporter-v0.2.4-65d8d98768-2nbf2: no nodes are registered to the cluster; waiting
I0405 02:23:26.799451       1 factory.go:743] Updating pod condition for kube-system/event-exporter-v0.2.4-65d8d98768-2nbf2 to (PodScheduled==False, Reason=Unschedulable)
E0405 02:23:26.815410       1 scheduler.go:482] error selecting node for pod: no nodes available to schedule pods
I0405 02:23:26.815764       1 scheduling_queue.go:895] About to try and schedule pod kube-system/event-exporter-v0.2.4-65d8d98768-2nbf2
I0405 02:23:26.815771       1 scheduler.go:454] Attempting to schedule pod: kube-system/event-exporter-v0.2.4-65d8d98768-2nbf2
I0405 02:23:26.815807       1 factory.go:645] Unable to schedule kube-system/event-exporter-v0.2.4-65d8d98768-2nbf2: no nodes are registered to the cluster; waiting
I0405 02:23:26.815845       1 factory.go:743] Updating pod condition for kube-system/event-exporter-v0.2.4-65d8d98768-2nbf2 to (PodScheduled==False, Reason=Unschedulable)
E0405 02:23:26.815856       1 scheduler.go:482] error selecting node for pod: no nodes available to schedule pods
I0405 02:23:27.366370       1 wrap.go:47] GET /healthz: (78.559µs) 200 [kube-probe/1.15+ 127.0.0.1:60864]
I0405 02:23:27.635685       1 scheduling_queue.go:895] About to try and schedule pod kube-system/coredns-5b969f4c88-464mz
I0405 02:23:27.635699       1 scheduler.go:454] Attempting to schedule pod: kube-system/coredns-5b969f4c88-464mz
I0405 02:23:27.635762       1 factory.go:645] Unable to schedule kube-system/coredns-5b969f4c88-464mz: no nodes are registered to the cluster; waiting
I0405 02:23:27.635799       1 factory.go:743] Updating pod condition for kube-system/coredns-5b969f4c88-464mz to (PodScheduled==False, Reason=Unschedulable)
E0405 02:23:27.635809       1 scheduler.go:482] error selecting node for pod: no nodes available to schedule pods
I0405 02:23:27.640813       1 scheduling_queue.go:895] About to try and schedule pod kube-system/heapster-v1.6.0-beta.1-5858bf5485-mwbsb
I0405 02:23:27.640827       1 scheduler.go:454] Attempting to schedule pod: kube-system/heapster-v1.6.0-beta.1-5858bf5485-mwbsb
I0405 02:23:27.640894       1 factory.go:645] Unable to schedule kube-system/heapster-v1.6.0-beta.1-5858bf5485-mwbsb: no nodes are registered to the cluster; waiting
I0405 02:23:27.640941       1 factory.go:743] Updating pod condition for kube-system/heapster-v1.6.0-beta.1-5858bf5485-mwbsb to (PodScheduled==False, Reason=Unschedulable)
E0405 02:23:27.640953       1 scheduler.go:482] error selecting node for pod: no nodes available to schedule pods
I0405 02:23:27.645913       1 scheduling_queue.go:895] About to try and schedule pod kube-system/l7-default-backend-8f479dd9-jx5v6
I0405 02:23:27.645938       1 scheduler.go:454] Attempting to schedule pod: kube-system/l7-default-backend-8f479dd9-jx5v6
I0405 02:23:27.645980       1 factory.go:645] Unable to schedule kube-system/l7-default-backend-8f479dd9-jx5v6: no nodes are registered to the cluster; waiting
I0405 02:23:27.646008       1 factory.go:743] Updating pod condition for kube-system/l7-default-backend-8f479dd9-jx5v6 to (PodScheduled==False, Reason=Unschedulable)
E0405 02:23:27.646018       1 scheduler.go:482] error selecting node for pod: no nodes available to schedule pods
I0405 02:23:27.754674       1 backoff_utils.go:79] Backing off 2s
I0405 02:23:27.754811       1 backoff_utils.go:79] Backing off 2s
I0405 02:23:27.754886       1 backoff_utils.go:79] Backing off 2s
I0405 02:23:28.393535       1 scheduling_queue.go:895] About to try and schedule pod kube-system/metrics-server-v0.3.1-677c578bdf-m9zc5
I0405 02:23:28.393549       1 scheduler.go:454] Attempting to schedule pod: kube-system/metrics-server-v0.3.1-677c578bdf-m9zc5
I0405 02:23:28.393966       1 factory.go:645] Unable to schedule kube-system/metrics-server-v0.3.1-677c578bdf-m9zc5: no nodes are registered to the cluster; waiting
I0405 02:23:28.394010       1 factory.go:743] Updating pod condition for kube-system/metrics-server-v0.3.1-677c578bdf-m9zc5 to (PodScheduled==False, Reason=Unschedulable)
E0405 02:23:28.511665       1 scheduler.go:482] error selecting node for pod: no nodes available to schedule pods
E0405 02:23:28.512174       1 scheduler.go:482] error selecting node for pod: no nodes available to schedule pods
E0405 02:23:28.632527       1 scheduler.go:482] error selecting node for pod: no nodes available to schedule pods
E0405 02:23:28.511665       1 scheduler.go:482] error selecting node for pod: no nodes available to schedule pods
E0405 02:23:28.512174       1 scheduler.go:482] error selecting node for pod: no nodes available to schedule pods
E0405 02:23:28.632527       1 scheduler.go:482] error selecting node for pod: no nodes available to schedule pods
E0405 02:23:28.511665       1 scheduler.go:482] error selecting node for pod: no nodes available to schedule pods
I0405 02:23:28.512056       1 scheduling_queue.go:895] About to try and schedule pod kube-system/metrics-server-v0.3.1-677c578bdf-m9zc5
I0405 02:23:28.512064       1 scheduler.go:454] Attempting to schedule pod: kube-system/metrics-server-v0.3.1-677c578bdf-m9zc5
I0405 02:23:28.512132       1 factory.go:645] Unable to schedule kube-system/metrics-server-v0.3.1-677c578bdf-m9zc5: no nodes are registered to the cluster; waiting
I0405 02:23:28.512164       1 factory.go:743] Updating pod condition for kube-system/metrics-server-v0.3.1-677c578bdf-m9zc5 to (PodScheduled==False, Reason=Unschedulable)
E0405 02:23:28.512174       1 scheduler.go:482] error selecting node for pod: no nodes available to schedule pods
I0405 02:23:28.632402       1 scheduling_queue.go:895] About to try and schedule pod kube-system/event-exporter-v0.2.4-65d8d98768-2nbf2
I0405 02:23:28.632416       1 scheduler.go:454] Attempting to schedule pod: kube-system/event-exporter-v0.2.4-65d8d98768-2nbf2
I0405 02:23:28.632471       1 factory.go:645] Unable to schedule kube-system/event-exporter-v0.2.4-65d8d98768-2nbf2: no nodes are registered to the cluster; waiting
I0405 02:23:28.632502       1 factory.go:743] Updating pod condition for kube-system/event-exporter-v0.2.4-65d8d98768-2nbf2 to (PodScheduled==False, Reason=Unschedulable)
E0405 02:23:28.632527       1 scheduler.go:482] error selecting node for pod: no nodes available to schedule pods
I0405 02:23:28.643719       1 backoff_utils.go:79] Backing off 2s
I0405 02:23:29.624314       1 scheduling_queue.go:895] About to try and schedule pod kube-system/fluentd-gcp-v3.2.0-skc2h
I0405 02:23:29.624329       1 scheduler.go:454] Attempting to schedule pod: kube-system/fluentd-gcp-v3.2.0-skc2h
I0405 02:23:29.624672       1 scheduler_binder.go:255] AssumePodVolumes for pod "kube-system/fluentd-gcp-v3.2.0-skc2h", node "e2e-test-peterhornyack-master"
I0405 02:23:29.624683       1 scheduler_binder.go:265] AssumePodVolumes for pod "kube-system/fluentd-gcp-v3.2.0-skc2h", node "e2e-test-peterhornyack-master": all PVCs bound and nothing to do
I0405 02:23:29.624748       1 factory.go:734] Attempting to bind fluentd-gcp-v3.2.0-skc2h to e2e-test-peterhornyack-master
I0405 02:23:29.625100       1 scheduling_queue.go:895] About to try and schedule pod kube-system/metadata-proxy-v0.1-xckkt
I0405 02:23:29.625105       1 scheduler.go:454] Attempting to schedule pod: kube-system/metadata-proxy-v0.1-xckkt
I0405 02:23:29.625225       1 scheduler_binder.go:255] AssumePodVolumes for pod "kube-system/metadata-proxy-v0.1-xckkt", node "e2e-test-peterhornyack-master"
I0405 02:23:29.625232       1 scheduler_binder.go:265] AssumePodVolumes for pod "kube-system/metadata-proxy-v0.1-xckkt", node "e2e-test-peterhornyack-master": all PVCs bound and nothing to do
I0405 02:23:29.625251       1 factory.go:734] Attempting to bind metadata-proxy-v0.1-xckkt to e2e-test-peterhornyack-master
I0405 02:23:29.641132       1 cache.go:643] Couldn't expire cache for pod kube-system/fluentd-gcp-v3.2.0-skc2h. Binding is still in progress.
I0405 02:23:29.641149       1 cache.go:643] Couldn't expire cache for pod kube-system/metadata-proxy-v0.1-xckkt. Binding is still in progress.
I0405 02:23:29.641202       1 scheduling_queue.go:895] About to try and schedule pod kube-system/metrics-server-v0.3.1-677c578bdf-m9zc5
I0405 02:23:29.641209       1 scheduler.go:454] Attempting to schedule pod: kube-system/metrics-server-v0.3.1-677c578bdf-m9zc5
I0405 02:23:29.641346       1 factory.go:648] Unable to schedule kube-system/metrics-server-v0.3.1-677c578bdf-m9zc5: no fit: 0/1 nodes are available: 1 node(s) were unschedulable.; waiting
I0405 02:23:29.641391       1 factory.go:743] Updating pod condition for kube-system/metrics-server-v0.3.1-677c578bdf-m9zc5 to (PodScheduled==False, Reason=Unschedulable)
I0405 02:23:29.650981       1 scheduler.go:575] pod kube-system/metadata-proxy-v0.1-xckkt is bound successfully on node e2e-test-peterhornyack-master, 1 nodes evaluated, 1 nodes were found feasible
I0405 02:23:29.651147       1 scheduler.go:575] pod kube-system/fluentd-gcp-v3.2.0-skc2h is bound successfully on node e2e-test-peterhornyack-master, 1 nodes evaluated, 1 nodes were found feasible
I0405 02:23:29.783908       1 generic_scheduler.go:308] Preemption will not help schedule pod kube-system/metrics-server-v0.3.1-677c578bdf-m9zc5 on any node.
I0405 02:23:29.784489       1 scheduling_queue.go:895] About to try and schedule pod kube-system/metrics-server-v0.3.1-677c578bdf-m9zc5
I0405 02:23:29.784497       1 scheduler.go:454] Attempting to schedule pod: kube-system/metrics-server-v0.3.1-677c578bdf-m9zc5
I0405 02:23:29.784607       1 factory.go:648] Unable to schedule kube-system/metrics-server-v0.3.1-677c578bdf-m9zc5: no fit: 0/1 nodes are available: 1 node(s) were unschedulable.; waiting
I0405 02:23:29.784634       1 factory.go:743] Updating pod condition for kube-system/metrics-server-v0.3.1-677c578bdf-m9zc5 to (PodScheduled==False, Reason=Unschedulable)
I0405 02:23:29.828653       1 backoff_utils.go:79] Backing off 2s
I0405 02:23:29.838531       1 generic_scheduler.go:308] Preemption will not help schedule pod kube-system/metrics-server-v0.3.1-677c578bdf-m9zc5 on any node.
I0405 02:23:30.642115       1 scheduling_queue.go:895] About to try and schedule pod kube-system/heapster-v1.6.0-beta.1-5858bf5485-mwbsb
I0405 02:23:30.642128       1 scheduler.go:454] Attempting to schedule pod: kube-system/heapster-v1.6.0-beta.1-5858bf5485-mwbsb
I0405 02:23:30.642249       1 factory.go:648] Unable to schedule kube-system/heapster-v1.6.0-beta.1-5858bf5485-mwbsb: no fit: 0/1 nodes are available: 1 node(s) were unschedulable.; waiting
I0405 02:23:30.642291       1 factory.go:743] Updating pod condition for kube-system/heapster-v1.6.0-beta.1-5858bf5485-mwbsb to (PodScheduled==False, Reason=Unschedulable)
I0405 02:23:30.676850       1 generic_scheduler.go:308] Preemption will not help schedule pod kube-system/heapster-v1.6.0-beta.1-5858bf5485-mwbsb on any node.
I0405 02:23:30.676914       1 scheduling_queue.go:895] About to try and schedule pod kube-system/coredns-5b969f4c88-464mz
I0405 02:23:30.676942       1 scheduler.go:454] Attempting to schedule pod: kube-system/coredns-5b969f4c88-464mz
I0405 02:23:30.677016       1 factory.go:648] Unable to schedule kube-system/coredns-5b969f4c88-464mz: no fit: 0/1 nodes are available: 1 node(s) were unschedulable.; waiting
I0405 02:23:30.677040       1 factory.go:743] Updating pod condition for kube-system/coredns-5b969f4c88-464mz to (PodScheduled==False, Reason=Unschedulable)
I0405 02:23:30.682048       1 backoff_utils.go:79] Backing off 4s
I0405 02:23:31.680697       1 generic_scheduler.go:308] Preemption will not help schedule pod kube-system/coredns-5b969f4c88-464mz on any node.
I0405 02:23:31.680757       1 scheduling_queue.go:895] About to try and schedule pod kube-system/heapster-v1.6.0-beta.1-5858bf5485-mwbsb
I0405 02:23:31.680763       1 scheduler.go:454] Attempting to schedule pod: kube-system/heapster-v1.6.0-beta.1-5858bf5485-mwbsb
I0405 02:23:31.680856       1 factory.go:648] Unable to schedule kube-system/heapster-v1.6.0-beta.1-5858bf5485-mwbsb: no fit: 0/1 nodes are available: 1 node(s) were unschedulable.; waiting
I0405 02:23:31.680881       1 factory.go:743] Updating pod condition for kube-system/heapster-v1.6.0-beta.1-5858bf5485-mwbsb to (PodScheduled==False, Reason=Unschedulable)
I0405 02:23:31.776561       1 backoff_utils.go:79] Backing off 4s
I0405 02:23:31.780701       1 generic_scheduler.go:308] Preemption will not help schedule pod kube-system/heapster-v1.6.0-beta.1-5858bf5485-mwbsb on any node.
I0405 02:23:31.784205       1 scheduling_queue.go:895] About to try and schedule pod kube-system/l7-default-backend-8f479dd9-jx5v6
I0405 02:23:31.784218       1 scheduler.go:454] Attempting to schedule pod: kube-system/l7-default-backend-8f479dd9-jx5v6
I0405 02:23:31.784311       1 factory.go:648] Unable to schedule kube-system/l7-default-backend-8f479dd9-jx5v6: no fit: 0/1 nodes are available: 1 node(s) were unschedulable.; waiting
I0405 02:23:31.784354       1 factory.go:743] Updating pod condition for kube-system/l7-default-backend-8f479dd9-jx5v6 to (PodScheduled==False, Reason=Unschedulable)
I0405 02:23:31.878361       1 generic_scheduler.go:308] Preemption will not help schedule pod kube-system/l7-default-backend-8f479dd9-jx5v6 on any node.
I0405 02:23:31.878423       1 scheduling_queue.go:895] About to try and schedule pod kube-system/event-exporter-v0.2.4-65d8d98768-2nbf2
I0405 02:23:31.878429       1 scheduler.go:454] Attempting to schedule pod: kube-system/event-exporter-v0.2.4-65d8d98768-2nbf2
I0405 02:23:31.878506       1 factory.go:648] Unable to schedule kube-system/event-exporter-v0.2.4-65d8d98768-2nbf2: no fit: 0/1 nodes are available: 1 node(s) were unschedulable.; waiting
I0405 02:23:31.878528       1 factory.go:743] Updating pod condition for kube-system/event-exporter-v0.2.4-65d8d98768-2nbf2 to (PodScheduled==False, Reason=Unschedulable)
I0405 02:23:31.917987       1 generic_scheduler.go:308] Preemption will not help schedule pod kube-system/event-exporter-v0.2.4-65d8d98768-2nbf2 on any node.
I0405 02:23:31.918189       1 scheduling_queue.go:895] About to try and schedule pod kube-system/l7-default-backend-8f479dd9-jx5v6
I0405 02:23:31.918212       1 scheduler.go:454] Attempting to schedule pod: kube-system/l7-default-backend-8f479dd9-jx5v6
I0405 02:23:31.918309       1 factory.go:648] Unable to schedule kube-system/l7-default-backend-8f479dd9-jx5v6: no fit: 0/1 nodes are available: 1 node(s) were unschedulable.; waiting
I0405 02:23:31.918341       1 factory.go:743] Updating pod condition for kube-system/l7-default-backend-8f479dd9-jx5v6 to (PodScheduled==False, Reason=Unschedulable)
I0405 02:23:31.928102       1 generic_scheduler.go:308] Preemption will not help schedule pod kube-system/l7-default-backend-8f479dd9-jx5v6 on any node.
I0405 02:23:31.928149       1 scheduling_queue.go:895] About to try and schedule pod kube-system/event-exporter-v0.2.4-65d8d98768-2nbf2
I0405 02:23:31.928154       1 scheduler.go:454] Attempting to schedule pod: kube-system/event-exporter-v0.2.4-65d8d98768-2nbf2
I0405 02:23:31.933342       1 factory.go:648] Unable to schedule kube-system/event-exporter-v0.2.4-65d8d98768-2nbf2: no fit: 0/1 nodes are available: 1 node(s) were unschedulable.; waiting
I0405 02:23:31.933389       1 factory.go:743] Updating pod condition for kube-system/event-exporter-v0.2.4-65d8d98768-2nbf2 to (PodScheduled==False, Reason=Unschedulable)
I0405 02:23:31.938019       1 backoff_utils.go:79] Backing off 4s
I0405 02:23:31.948723       1 backoff_utils.go:79] Backing off 4s
I0405 02:23:31.948811       1 generic_scheduler.go:308] Preemption will not help schedule pod kube-system/event-exporter-v0.2.4-65d8d98768-2nbf2 on any node.
I0405 02:23:32.041404       1 scheduling_queue.go:895] About to try and schedule pod kube-system/kubernetes-dashboard-85bcf5dbf8-v56pc
I0405 02:23:32.041415       1 scheduler.go:454] Attempting to schedule pod: kube-system/kubernetes-dashboard-85bcf5dbf8-v56pc
I0405 02:23:32.041515       1 factory.go:648] Unable to schedule kube-system/kubernetes-dashboard-85bcf5dbf8-v56pc: no fit: 0/1 nodes are available: 1 node(s) were unschedulable.; waiting
I0405 02:23:32.041538       1 factory.go:743] Updating pod condition for kube-system/kubernetes-dashboard-85bcf5dbf8-v56pc to (PodScheduled==False, Reason=Unschedulable)
I0405 02:23:32.071550       1 generic_scheduler.go:308] Preemption will not help schedule pod kube-system/kubernetes-dashboard-85bcf5dbf8-v56pc on any node.
I0405 02:23:32.071613       1 scheduling_queue.go:895] About to try and schedule pod kube-system/kubernetes-dashboard-85bcf5dbf8-v56pc
I0405 02:23:32.071627       1 scheduler.go:454] Attempting to schedule pod: kube-system/kubernetes-dashboard-85bcf5dbf8-v56pc
I0405 02:23:32.071713       1 factory.go:648] Unable to schedule kube-system/kubernetes-dashboard-85bcf5dbf8-v56pc: no fit: 0/1 nodes are available: 1 node(s) were unschedulable.; waiting
I0405 02:23:32.071744       1 factory.go:743] Updating pod condition for kube-system/kubernetes-dashboard-85bcf5dbf8-v56pc to (PodScheduled==False, Reason=Unschedulable)
I0405 02:23:32.107639       1 generic_scheduler.go:308] Preemption will not help schedule pod kube-system/kubernetes-dashboard-85bcf5dbf8-v56pc on any node.
I0405 02:23:32.124951       1 scheduling_queue.go:895] About to try and schedule pod kube-system/kube-dns-autoscaler-97df449df-hz62r
I0405 02:23:32.124963       1 scheduler.go:454] Attempting to schedule pod: kube-system/kube-dns-autoscaler-97df449df-hz62r
I0405 02:23:32.128160       1 factory.go:648] Unable to schedule kube-system/kube-dns-autoscaler-97df449df-hz62r: no fit: 0/1 nodes are available: 1 node(s) were unschedulable.; waiting
I0405 02:23:32.128208       1 factory.go:743] Updating pod condition for kube-system/kube-dns-autoscaler-97df449df-hz62r to (PodScheduled==False, Reason=Unschedulable)
I0405 02:23:32.162147       1 generic_scheduler.go:308] Preemption will not help schedule pod kube-system/kube-dns-autoscaler-97df449df-hz62r on any node.
I0405 02:23:32.162295       1 scheduling_queue.go:895] About to try and schedule pod kube-system/kube-dns-autoscaler-97df449df-hz62r
I0405 02:23:32.162303       1 scheduler.go:454] Attempting to schedule pod: kube-system/kube-dns-autoscaler-97df449df-hz62r
I0405 02:23:32.162391       1 factory.go:648] Unable to schedule kube-system/kube-dns-autoscaler-97df449df-hz62r: no fit: 0/1 nodes are available: 1 node(s) were unschedulable.; waiting
I0405 02:23:32.162421       1 factory.go:743] Updating pod condition for kube-system/kube-dns-autoscaler-97df449df-hz62r to (PodScheduled==False, Reason=Unschedulable)
I0405 02:23:32.172705       1 generic_scheduler.go:308] Preemption will not help schedule pod kube-system/kube-dns-autoscaler-97df449df-hz62r on any node.
I0405 02:23:32.270597       1 scheduling_queue.go:895] About to try and schedule pod kube-system/fluentd-gcp-scaler-7db4984bf4-jlvpg
I0405 02:23:32.270622       1 scheduler.go:454] Attempting to schedule pod: kube-system/fluentd-gcp-scaler-7db4984bf4-jlvpg
I0405 02:23:32.270697       1 factory.go:648] Unable to schedule kube-system/fluentd-gcp-scaler-7db4984bf4-jlvpg: no fit: 0/1 nodes are available: 1 node(s) were unschedulable.; waiting
I0405 02:23:32.270733       1 factory.go:743] Updating pod condition for kube-system/fluentd-gcp-scaler-7db4984bf4-jlvpg to (PodScheduled==False, Reason=Unschedulable)
I0405 02:23:32.300785       1 generic_scheduler.go:308] Preemption will not help schedule pod kube-system/fluentd-gcp-scaler-7db4984bf4-jlvpg on any node.
I0405 02:23:32.300872       1 scheduling_queue.go:895] About to try and schedule pod kube-system/fluentd-gcp-scaler-7db4984bf4-jlvpg
I0405 02:23:32.300878       1 scheduler.go:454] Attempting to schedule pod: kube-system/fluentd-gcp-scaler-7db4984bf4-jlvpg
I0405 02:23:32.300954       1 factory.go:648] Unable to schedule kube-system/fluentd-gcp-scaler-7db4984bf4-jlvpg: no fit: 0/1 nodes are available: 1 node(s) were unschedulable.; waiting
I0405 02:23:32.300981       1 factory.go:743] Updating pod condition for kube-system/fluentd-gcp-scaler-7db4984bf4-jlvpg to (PodScheduled==False, Reason=Unschedulable)
I0405 02:23:32.319273       1 generic_scheduler.go:308] Preemption will not help schedule pod kube-system/fluentd-gcp-scaler-7db4984bf4-jlvpg on any node.
I0405 02:23:32.644161       1 scheduling_queue.go:895] About to try and schedule pod kube-system/metrics-server-v0.3.1-677c578bdf-m9zc5
I0405 02:23:32.644196       1 scheduler.go:454] Attempting to schedule pod: kube-system/metrics-server-v0.3.1-677c578bdf-m9zc5
I0405 02:23:32.644284       1 factory.go:648] Unable to schedule kube-system/metrics-server-v0.3.1-677c578bdf-m9zc5: no fit: 0/1 nodes are available: 1 node(s) were unschedulable.; waiting
I0405 02:23:32.644314       1 factory.go:743] Updating pod condition for kube-system/metrics-server-v0.3.1-677c578bdf-m9zc5 to (PodScheduled==False, Reason=Unschedulable)
I0405 02:23:32.660678       1 backoff_utils.go:79] Backing off 4s
I0405 02:23:32.667837       1 generic_scheduler.go:308] Preemption will not help schedule pod kube-system/metrics-server-v0.3.1-677c578bdf-m9zc5 on any node.
I0405 02:23:37.362524       1 wrap.go:47] GET /healthz: (78.301µs) 200 [kube-probe/1.15+ 127.0.0.1:60954]
I0405 02:23:47.363060       1 wrap.go:47] GET /healthz: (79.943µs) 200 [kube-probe/1.15+ 127.0.0.1:60986]
I0405 02:23:57.362754       1 wrap.go:47] GET /healthz: (89.939µs) 200 [kube-probe/1.15+ 127.0.0.1:32876]
I0405 02:24:07.363069       1 wrap.go:47] GET /healthz: (82.248µs) 200 [kube-probe/1.15+ 127.0.0.1:32910]
I0405 02:24:17.362813       1 wrap.go:47] GET /healthz: (71.712µs) 200 [kube-probe/1.15+ 127.0.0.1:32940]
I0405 02:24:27.363275       1 wrap.go:47] GET /healthz: (76.463µs) 200 [kube-probe/1.15+ 127.0.0.1:32986]
I0405 02:24:37.363105       1 wrap.go:47] GET /healthz: (85.132µs) 200 [kube-probe/1.15+ 127.0.0.1:33020]
I0405 02:24:45.575898       1 scheduling_queue.go:895] About to try and schedule pod kube-system/coredns-5b969f4c88-464mz
I0405 02:24:45.575913       1 scheduler.go:454] Attempting to schedule pod: kube-system/coredns-5b969f4c88-464mz
I0405 02:24:45.576105       1 factory.go:648] Unable to schedule kube-system/coredns-5b969f4c88-464mz: no fit: 0/1 nodes are available: 1 node(s) were unschedulable.; waiting
I0405 02:24:45.576146       1 factory.go:743] Updating pod condition for kube-system/coredns-5b969f4c88-464mz to (PodScheduled==False, Reason=Unschedulable)
I0405 02:24:45.584557       1 generic_scheduler.go:308] Preemption will not help schedule pod kube-system/coredns-5b969f4c88-464mz on any node.
I0405 02:24:45.584634       1 scheduling_queue.go:895] About to try and schedule pod kube-system/heapster-v1.6.0-beta.1-5858bf5485-mwbsb
I0405 02:24:45.584642       1 scheduler.go:454] Attempting to schedule pod: kube-system/heapster-v1.6.0-beta.1-5858bf5485-mwbsb
I0405 02:24:45.584738       1 factory.go:648] Unable to schedule kube-system/heapster-v1.6.0-beta.1-5858bf5485-mwbsb: no fit: 0/1 nodes are available: 1 node(s) were unschedulable.; waiting
I0405 02:24:45.584767       1 factory.go:743] Updating pod condition for kube-system/heapster-v1.6.0-beta.1-5858bf5485-mwbsb to (PodScheduled==False, Reason=Unschedulable)
I0405 02:24:45.590422       1 generic_scheduler.go:308] Preemption will not help schedule pod kube-system/heapster-v1.6.0-beta.1-5858bf5485-mwbsb on any node.
I0405 02:24:45.591006       1 scheduling_queue.go:895] About to try and schedule pod kube-system/kubernetes-dashboard-85bcf5dbf8-v56pc
I0405 02:24:45.591016       1 scheduler.go:454] Attempting to schedule pod: kube-system/kubernetes-dashboard-85bcf5dbf8-v56pc
I0405 02:24:45.591131       1 factory.go:648] Unable to schedule kube-system/kubernetes-dashboard-85bcf5dbf8-v56pc: no fit: 0/1 nodes are available: 1 node(s) were unschedulable.; waiting
I0405 02:24:45.591163       1 factory.go:743] Updating pod condition for kube-system/kubernetes-dashboard-85bcf5dbf8-v56pc to (PodScheduled==False, Reason=Unschedulable)
I0405 02:24:45.596145       1 generic_scheduler.go:308] Preemption will not help schedule pod kube-system/kubernetes-dashboard-85bcf5dbf8-v56pc on any node.
I0405 02:24:45.598084       1 scheduling_queue.go:895] About to try and schedule pod kube-system/kube-dns-autoscaler-97df449df-hz62r
I0405 02:24:45.599608       1 scheduler.go:454] Attempting to schedule pod: kube-system/kube-dns-autoscaler-97df449df-hz62r
I0405 02:24:45.599728       1 factory.go:648] Unable to schedule kube-system/kube-dns-autoscaler-97df449df-hz62r: no fit: 0/1 nodes are available: 1 node(s) were unschedulable.; waiting
I0405 02:24:45.599761       1 factory.go:743] Updating pod condition for kube-system/kube-dns-autoscaler-97df449df-hz62r to (PodScheduled==False, Reason=Unschedulable)
I0405 02:24:45.609736       1 generic_scheduler.go:308] Preemption will not help schedule pod kube-system/kube-dns-autoscaler-97df449df-hz62r on any node.
I0405 02:24:45.610053       1 scheduling_queue.go:895] About to try and schedule pod kube-system/metrics-server-v0.3.1-677c578bdf-m9zc5
I0405 02:24:45.610061       1 scheduler.go:454] Attempting to schedule pod: kube-system/metrics-server-v0.3.1-677c578bdf-m9zc5
I0405 02:24:45.610303       1 factory.go:648] Unable to schedule kube-system/metrics-server-v0.3.1-677c578bdf-m9zc5: no fit: 0/1 nodes are available: 1 node(s) were unschedulable.; waiting
I0405 02:24:45.610334       1 factory.go:743] Updating pod condition for kube-system/metrics-server-v0.3.1-677c578bdf-m9zc5 to (PodScheduled==False, Reason=Unschedulable)
I0405 02:24:45.614998       1 generic_scheduler.go:308] Preemption will not help schedule pod kube-system/metrics-server-v0.3.1-677c578bdf-m9zc5 on any node.
I0405 02:24:45.616290       1 scheduling_queue.go:895] About to try and schedule pod kube-system/l7-default-backend-8f479dd9-jx5v6
I0405 02:24:45.616312       1 scheduler.go:454] Attempting to schedule pod: kube-system/l7-default-backend-8f479dd9-jx5v6
I0405 02:24:45.616412       1 factory.go:648] Unable to schedule kube-system/l7-default-backend-8f479dd9-jx5v6: no fit: 0/1 nodes are available: 1 node(s) were unschedulable.; waiting
I0405 02:24:45.616443       1 factory.go:743] Updating pod condition for kube-system/l7-default-backend-8f479dd9-jx5v6 to (PodScheduled==False, Reason=Unschedulable)
I0405 02:24:45.621260       1 generic_scheduler.go:308] Preemption will not help schedule pod kube-system/l7-default-backend-8f479dd9-jx5v6 on any node.
I0405 02:24:45.624911       1 scheduling_queue.go:895] About to try and schedule pod kube-system/event-exporter-v0.2.4-65d8d98768-2nbf2
I0405 02:24:45.624944       1 scheduler.go:454] Attempting to schedule pod: kube-system/event-exporter-v0.2.4-65d8d98768-2nbf2
I0405 02:24:45.625046       1 factory.go:648] Unable to schedule kube-system/event-exporter-v0.2.4-65d8d98768-2nbf2: no fit: 0/1 nodes are available: 1 node(s) were unschedulable.; waiting
I0405 02:24:45.625080       1 factory.go:743] Updating pod condition for kube-system/event-exporter-v0.2.4-65d8d98768-2nbf2 to (PodScheduled==False, Reason=Unschedulable)
I0405 02:24:45.635238       1 generic_scheduler.go:308] Preemption will not help schedule pod kube-system/event-exporter-v0.2.4-65d8d98768-2nbf2 on any node.
I0405 02:24:45.636461       1 scheduling_queue.go:895] About to try and schedule pod kube-system/fluentd-gcp-scaler-7db4984bf4-jlvpg
I0405 02:24:45.636471       1 scheduler.go:454] Attempting to schedule pod: kube-system/fluentd-gcp-scaler-7db4984bf4-jlvpg
I0405 02:24:45.642487       1 factory.go:648] Unable to schedule kube-system/fluentd-gcp-scaler-7db4984bf4-jlvpg: no fit: 0/1 nodes are available: 1 node(s) were unschedulable.; waiting
I0405 02:24:45.642572       1 factory.go:743] Updating pod condition for kube-system/fluentd-gcp-scaler-7db4984bf4-jlvpg to (PodScheduled==False, Reason=Unschedulable)
I0405 02:24:45.655317       1 generic_scheduler.go:308] Preemption will not help schedule pod kube-system/fluentd-gcp-scaler-7db4984bf4-jlvpg on any node.
I0405 02:24:47.363035       1 wrap.go:47] GET /healthz: (92.939µs) 200 [kube-probe/1.15+ 127.0.0.1:33058]
I0405 02:24:57.363024       1 wrap.go:47] GET /healthz: (87.054µs) 200 [kube-probe/1.15+ 127.0.0.1:33100]
I0405 02:25:07.362950       1 wrap.go:47] GET /healthz: (91.262µs) 200 [kube-probe/1.15+ 127.0.0.1:33136]
I0405 02:25:17.362886       1 wrap.go:47] GET /healthz: (95.795µs) 200 [kube-probe/1.15+ 127.0.0.1:33168]
I0405 02:25:27.363156       1 wrap.go:47] GET /healthz: (76.791µs) 200 [kube-probe/1.15+ 127.0.0.1:33218]
I0405 02:25:36.446228       1 scheduling_queue.go:895] About to try and schedule pod kube-system/heapster-v1.6.0-beta.1-5858bf5485-mwbsb
I0405 02:25:36.446268       1 scheduler.go:454] Attempting to schedule pod: kube-system/heapster-v1.6.0-beta.1-5858bf5485-mwbsb
I0405 02:25:36.446598       1 scheduler_binder.go:255] AssumePodVolumes for pod "kube-system/heapster-v1.6.0-beta.1-5858bf5485-mwbsb", node "e2e-test-peterhornyack-minion-group-wsfw"
I0405 02:25:36.446609       1 scheduler_binder.go:265] AssumePodVolumes for pod "kube-system/heapster-v1.6.0-beta.1-5858bf5485-mwbsb", node "e2e-test-peterhornyack-minion-group-wsfw": all PVCs bound and nothing to do
I0405 02:25:36.446685       1 factory.go:734] Attempting to bind heapster-v1.6.0-beta.1-5858bf5485-mwbsb to e2e-test-peterhornyack-minion-group-wsfw
I0405 02:25:36.447030       1 scheduling_queue.go:895] About to try and schedule pod kube-system/coredns-5b969f4c88-464mz
I0405 02:25:36.447037       1 scheduler.go:454] Attempting to schedule pod: kube-system/coredns-5b969f4c88-464mz
I0405 02:25:36.447234       1 scheduler_binder.go:255] AssumePodVolumes for pod "kube-system/coredns-5b969f4c88-464mz", node "e2e-test-peterhornyack-minion-group-wsfw"
I0405 02:25:36.447255       1 scheduler_binder.go:265] AssumePodVolumes for pod "kube-system/coredns-5b969f4c88-464mz", node "e2e-test-peterhornyack-minion-group-wsfw": all PVCs bound and nothing to do
I0405 02:25:36.447280       1 factory.go:734] Attempting to bind coredns-5b969f4c88-464mz to e2e-test-peterhornyack-minion-group-wsfw
I0405 02:25:36.455159       1 scheduling_queue.go:895] About to try and schedule pod kube-system/kubernetes-dashboard-85bcf5dbf8-v56pc
I0405 02:25:36.455179       1 scheduler.go:454] Attempting to schedule pod: kube-system/kubernetes-dashboard-85bcf5dbf8-v56pc
I0405 02:25:36.455386       1 scheduler_binder.go:255] AssumePodVolumes for pod "kube-system/kubernetes-dashboard-85bcf5dbf8-v56pc", node "e2e-test-peterhornyack-minion-group-wsfw"
I0405 02:25:36.455396       1 scheduler_binder.go:265] AssumePodVolumes for pod "kube-system/kubernetes-dashboard-85bcf5dbf8-v56pc", node "e2e-test-peterhornyack-minion-group-wsfw": all PVCs bound and nothing to do
I0405 02:25:36.455442       1 factory.go:734] Attempting to bind kubernetes-dashboard-85bcf5dbf8-v56pc to e2e-test-peterhornyack-minion-group-wsfw
I0405 02:25:36.466831       1 scheduling_queue.go:895] About to try and schedule pod kube-system/kube-dns-autoscaler-97df449df-hz62r
I0405 02:25:36.466850       1 scheduler.go:454] Attempting to schedule pod: kube-system/kube-dns-autoscaler-97df449df-hz62r
I0405 02:25:36.467067       1 scheduler_binder.go:255] AssumePodVolumes for pod "kube-system/kube-dns-autoscaler-97df449df-hz62r", node "e2e-test-peterhornyack-minion-group-wsfw"
I0405 02:25:36.467078       1 scheduler_binder.go:265] AssumePodVolumes for pod "kube-system/kube-dns-autoscaler-97df449df-hz62r", node "e2e-test-peterhornyack-minion-group-wsfw": all PVCs bound and nothing to do
I0405 02:25:36.467126       1 factory.go:734] Attempting to bind kube-dns-autoscaler-97df449df-hz62r to e2e-test-peterhornyack-minion-group-wsfw
I0405 02:25:36.467501       1 scheduling_queue.go:895] About to try and schedule pod kube-system/metrics-server-v0.3.1-677c578bdf-m9zc5
I0405 02:25:36.467509       1 scheduler.go:454] Attempting to schedule pod: kube-system/metrics-server-v0.3.1-677c578bdf-m9zc5
I0405 02:25:36.467637       1 scheduler_binder.go:255] AssumePodVolumes for pod "kube-system/metrics-server-v0.3.1-677c578bdf-m9zc5", node "e2e-test-peterhornyack-minion-group-wsfw"
I0405 02:25:36.467645       1 scheduler_binder.go:265] AssumePodVolumes for pod "kube-system/metrics-server-v0.3.1-677c578bdf-m9zc5", node "e2e-test-peterhornyack-minion-group-wsfw": all PVCs bound and nothing to do
I0405 02:25:36.467667       1 factory.go:734] Attempting to bind metrics-server-v0.3.1-677c578bdf-m9zc5 to e2e-test-peterhornyack-minion-group-wsfw
I0405 02:25:36.467834       1 scheduling_queue.go:895] About to try and schedule pod kube-system/l7-default-backend-8f479dd9-jx5v6
I0405 02:25:36.467839       1 scheduler.go:454] Attempting to schedule pod: kube-system/l7-default-backend-8f479dd9-jx5v6
I0405 02:25:36.467908       1 scheduler_binder.go:255] AssumePodVolumes for pod "kube-system/l7-default-backend-8f479dd9-jx5v6", node "e2e-test-peterhornyack-minion-group-wsfw"
I0405 02:25:36.467915       1 scheduler_binder.go:265] AssumePodVolumes for pod "kube-system/l7-default-backend-8f479dd9-jx5v6", node "e2e-test-peterhornyack-minion-group-wsfw": all PVCs bound and nothing to do
I0405 02:25:36.467950       1 factory.go:734] Attempting to bind l7-default-backend-8f479dd9-jx5v6 to e2e-test-peterhornyack-minion-group-wsfw
I0405 02:25:36.470762       1 scheduling_queue.go:895] About to try and schedule pod kube-system/event-exporter-v0.2.4-65d8d98768-2nbf2
I0405 02:25:36.470777       1 scheduler.go:454] Attempting to schedule pod: kube-system/event-exporter-v0.2.4-65d8d98768-2nbf2
I0405 02:25:36.475569       1 scheduler_binder.go:255] AssumePodVolumes for pod "kube-system/event-exporter-v0.2.4-65d8d98768-2nbf2", node "e2e-test-peterhornyack-minion-group-wsfw"
I0405 02:25:36.475609       1 scheduler_binder.go:265] AssumePodVolumes for pod "kube-system/event-exporter-v0.2.4-65d8d98768-2nbf2", node "e2e-test-peterhornyack-minion-group-wsfw": all PVCs bound and nothing to do
I0405 02:25:36.475693       1 factory.go:734] Attempting to bind event-exporter-v0.2.4-65d8d98768-2nbf2 to e2e-test-peterhornyack-minion-group-wsfw
I0405 02:25:36.477701       1 scheduling_queue.go:895] About to try and schedule pod kube-system/fluentd-gcp-scaler-7db4984bf4-jlvpg
I0405 02:25:36.477717       1 scheduler.go:454] Attempting to schedule pod: kube-system/fluentd-gcp-scaler-7db4984bf4-jlvpg
I0405 02:25:36.477876       1 scheduler_binder.go:255] AssumePodVolumes for pod "kube-system/fluentd-gcp-scaler-7db4984bf4-jlvpg", node "e2e-test-peterhornyack-minion-group-wsfw"
I0405 02:25:36.477885       1 scheduler_binder.go:265] AssumePodVolumes for pod "kube-system/fluentd-gcp-scaler-7db4984bf4-jlvpg", node "e2e-test-peterhornyack-minion-group-wsfw": all PVCs bound and nothing to do
I0405 02:25:36.477917       1 factory.go:734] Attempting to bind fluentd-gcp-scaler-7db4984bf4-jlvpg to e2e-test-peterhornyack-minion-group-wsfw
I0405 02:25:36.491401       1 scheduler.go:575] pod kube-system/coredns-5b969f4c88-464mz is bound successfully on node e2e-test-peterhornyack-minion-group-wsfw, 2 nodes evaluated, 1 nodes were found feasible
I0405 02:25:36.492019       1 scheduler.go:575] pod kube-system/heapster-v1.6.0-beta.1-5858bf5485-mwbsb is bound successfully on node e2e-test-peterhornyack-minion-group-wsfw, 2 nodes evaluated, 1 nodes were found feasible
I0405 02:25:36.521041       1 scheduler.go:575] pod kube-system/event-exporter-v0.2.4-65d8d98768-2nbf2 is bound successfully on node e2e-test-peterhornyack-minion-group-wsfw, 2 nodes evaluated, 1 nodes were found feasible
I0405 02:25:36.536256       1 scheduler.go:575] pod kube-system/l7-default-backend-8f479dd9-jx5v6 is bound successfully on node e2e-test-peterhornyack-minion-group-wsfw, 2 nodes evaluated, 1 nodes were found feasible
I0405 02:25:36.541370       1 scheduler.go:575] pod kube-system/kubernetes-dashboard-85bcf5dbf8-v56pc is bound successfully on node e2e-test-peterhornyack-minion-group-wsfw, 2 nodes evaluated, 1 nodes were found feasible
I0405 02:25:36.541437       1 scheduler.go:575] pod kube-system/fluentd-gcp-scaler-7db4984bf4-jlvpg is bound successfully on node e2e-test-peterhornyack-minion-group-wsfw, 2 nodes evaluated, 1 nodes were found feasible
I0405 02:25:36.541470       1 scheduler.go:575] pod kube-system/kube-dns-autoscaler-97df449df-hz62r is bound successfully on node e2e-test-peterhornyack-minion-group-wsfw, 2 nodes evaluated, 1 nodes were found feasible
I0405 02:25:36.541529       1 scheduler.go:575] pod kube-system/metrics-server-v0.3.1-677c578bdf-m9zc5 is bound successfully on node e2e-test-peterhornyack-minion-group-wsfw, 2 nodes evaluated, 1 nodes were found feasible
I0405 02:25:36.545429       1 scheduling_queue.go:895] About to try and schedule pod kube-system/fluentd-gcp-v3.2.0-vblzx
I0405 02:25:36.545443       1 scheduler.go:454] Attempting to schedule pod: kube-system/fluentd-gcp-v3.2.0-vblzx
I0405 02:25:36.549912       1 scheduler_binder.go:255] AssumePodVolumes for pod "kube-system/fluentd-gcp-v3.2.0-vblzx", node "e2e-test-peterhornyack-minion-group-wsfw"
I0405 02:25:36.549947       1 scheduler_binder.go:265] AssumePodVolumes for pod "kube-system/fluentd-gcp-v3.2.0-vblzx", node "e2e-test-peterhornyack-minion-group-wsfw": all PVCs bound and nothing to do
I0405 02:25:36.550996       1 factory.go:734] Attempting to bind fluentd-gcp-v3.2.0-vblzx to e2e-test-peterhornyack-minion-group-wsfw
I0405 02:25:36.560266       1 scheduling_queue.go:895] About to try and schedule pod kube-system/metadata-proxy-v0.1-cstkg
I0405 02:25:36.560280       1 scheduler.go:454] Attempting to schedule pod: kube-system/metadata-proxy-v0.1-cstkg
I0405 02:25:36.560501       1 scheduler_binder.go:255] AssumePodVolumes for pod "kube-system/metadata-proxy-v0.1-cstkg", node "e2e-test-peterhornyack-minion-group-wsfw"
I0405 02:25:36.560512       1 scheduler_binder.go:265] AssumePodVolumes for pod "kube-system/metadata-proxy-v0.1-cstkg", node "e2e-test-peterhornyack-minion-group-wsfw": all PVCs bound and nothing to do
I0405 02:25:36.560556       1 factory.go:734] Attempting to bind metadata-proxy-v0.1-cstkg to e2e-test-peterhornyack-minion-group-wsfw
I0405 02:25:36.590228       1 scheduler.go:575] pod kube-system/fluentd-gcp-v3.2.0-vblzx is bound successfully on node e2e-test-peterhornyack-minion-group-wsfw, 2 nodes evaluated, 1 nodes were found feasible
I0405 02:25:36.590304       1 scheduler.go:575] pod kube-system/metadata-proxy-v0.1-cstkg is bound successfully on node e2e-test-peterhornyack-minion-group-wsfw, 2 nodes evaluated, 1 nodes were found feasible
I0405 02:25:37.363319       1 wrap.go:47] GET /healthz: (122.202µs) 200 [kube-probe/1.15+ 127.0.0.1:33254]
I0405 02:25:47.363028       1 wrap.go:47] GET /healthz: (118.855µs) 200 [kube-probe/1.15+ 127.0.0.1:33286]
I0405 02:25:57.362760       1 wrap.go:47] GET /healthz: (74.945µs) 200 [kube-probe/1.15+ 127.0.0.1:33322]
I0405 02:25:58.983300       1 scheduling_queue.go:895] About to try and schedule pod kube-system/heapster-v1.6.0-beta.1-77858557dc-b4bcz
I0405 02:25:58.983329       1 scheduler.go:454] Attempting to schedule pod: kube-system/heapster-v1.6.0-beta.1-77858557dc-b4bcz
I0405 02:25:58.983500       1 scheduler_binder.go:255] AssumePodVolumes for pod "kube-system/heapster-v1.6.0-beta.1-77858557dc-b4bcz", node "e2e-test-peterhornyack-minion-group-wsfw"
I0405 02:25:58.983510       1 scheduler_binder.go:265] AssumePodVolumes for pod "kube-system/heapster-v1.6.0-beta.1-77858557dc-b4bcz", node "e2e-test-peterhornyack-minion-group-wsfw": all PVCs bound and nothing to do
I0405 02:25:58.983567       1 factory.go:734] Attempting to bind heapster-v1.6.0-beta.1-77858557dc-b4bcz to e2e-test-peterhornyack-minion-group-wsfw
I0405 02:25:58.989567       1 scheduling_queue.go:895] About to try and schedule pod kube-system/metrics-server-v0.3.1-7d9cf58c5c-mktdk
I0405 02:25:58.989577       1 scheduler.go:454] Attempting to schedule pod: kube-system/metrics-server-v0.3.1-7d9cf58c5c-mktdk
I0405 02:25:58.989697       1 scheduler_binder.go:255] AssumePodVolumes for pod "kube-system/metrics-server-v0.3.1-7d9cf58c5c-mktdk", node "e2e-test-peterhornyack-minion-group-wsfw"
I0405 02:25:58.989706       1 scheduler_binder.go:265] AssumePodVolumes for pod "kube-system/metrics-server-v0.3.1-7d9cf58c5c-mktdk", node "e2e-test-peterhornyack-minion-group-wsfw": all PVCs bound and nothing to do
I0405 02:25:58.989733       1 factory.go:734] Attempting to bind metrics-server-v0.3.1-7d9cf58c5c-mktdk to e2e-test-peterhornyack-minion-group-wsfw
I0405 02:25:59.010131       1 scheduler.go:575] pod kube-system/metrics-server-v0.3.1-7d9cf58c5c-mktdk is bound successfully on node e2e-test-peterhornyack-minion-group-wsfw, 2 nodes evaluated, 1 nodes were found feasible
I0405 02:25:59.012501       1 scheduler.go:575] pod kube-system/heapster-v1.6.0-beta.1-77858557dc-b4bcz is bound successfully on node e2e-test-peterhornyack-minion-group-wsfw, 2 nodes evaluated, 1 nodes were found feasible
I0405 02:26:06.342452       1 scheduling_queue.go:895] About to try and schedule pod kube-system/fluentd-gcp-v3.2.0-fm2nh
I0405 02:26:06.342467       1 scheduler.go:454] Attempting to schedule pod: kube-system/fluentd-gcp-v3.2.0-fm2nh
I0405 02:26:06.342762       1 scheduler_binder.go:255] AssumePodVolumes for pod "kube-system/fluentd-gcp-v3.2.0-fm2nh", node "e2e-test-peterhornyack-minion-group-wsfw"
I0405 02:26:06.342773       1 scheduler_binder.go:265] AssumePodVolumes for pod "kube-system/fluentd-gcp-v3.2.0-fm2nh", node "e2e-test-peterhornyack-minion-group-wsfw": all PVCs bound and nothing to do
I0405 02:26:06.342834       1 factory.go:734] Attempting to bind fluentd-gcp-v3.2.0-fm2nh to e2e-test-peterhornyack-minion-group-wsfw
I0405 02:26:06.362111       1 scheduler.go:575] pod kube-system/fluentd-gcp-v3.2.0-fm2nh is bound successfully on node e2e-test-peterhornyack-minion-group-wsfw, 2 nodes evaluated, 1 nodes were found feasible
I0405 02:26:07.362618       1 wrap.go:47] GET /healthz: (60.405µs) 200 [kube-probe/1.15+ 127.0.0.1:33386]
I0405 02:26:13.947398       1 scheduling_queue.go:895] About to try and schedule pod kube-system/fluentd-gcp-v3.2.0-r4xc6
I0405 02:26:13.947413       1 scheduler.go:454] Attempting to schedule pod: kube-system/fluentd-gcp-v3.2.0-r4xc6
I0405 02:26:13.947679       1 scheduler_binder.go:255] AssumePodVolumes for pod "kube-system/fluentd-gcp-v3.2.0-r4xc6", node "e2e-test-peterhornyack-master"
I0405 02:26:13.947704       1 scheduler_binder.go:265] AssumePodVolumes for pod "kube-system/fluentd-gcp-v3.2.0-r4xc6", node "e2e-test-peterhornyack-master": all PVCs bound and nothing to do
I0405 02:26:13.947759       1 factory.go:734] Attempting to bind fluentd-gcp-v3.2.0-r4xc6 to e2e-test-peterhornyack-master
I0405 02:26:13.978216       1 scheduler.go:575] pod kube-system/fluentd-gcp-v3.2.0-r4xc6 is bound successfully on node e2e-test-peterhornyack-master, 2 nodes evaluated, 1 nodes were found feasible
I0405 02:26:17.364234       1 wrap.go:47] GET /healthz: (51.665µs) 200 [kube-probe/1.15+ 127.0.0.1:33464]
I0405 02:26:27.362652       1 wrap.go:47] GET /healthz: (67.333µs) 200 [kube-probe/1.15+ 127.0.0.1:33560]
I0405 02:26:37.362886       1 wrap.go:47] GET /healthz: (64.185µs) 200 [kube-probe/1.15+ 127.0.0.1:33596]
I0405 02:26:47.362668       1 wrap.go:47] GET /healthz: (52.65µs) 200 [kube-probe/1.15+ 127.0.0.1:33632]
I0405 02:26:57.362980       1 wrap.go:47] GET /healthz: (111.756µs) 200 [kube-probe/1.15+ 127.0.0.1:33670]
I0405 02:27:07.363142       1 wrap.go:47] GET /healthz: (126.955µs) 200 [kube-probe/1.15+ 127.0.0.1:33706]
I0405 02:27:17.363041       1 wrap.go:47] GET /healthz: (97.484µs) 200 [kube-probe/1.15+ 127.0.0.1:33746]
I0405 02:27:27.362855       1 wrap.go:47] GET /healthz: (79.075µs) 200 [kube-probe/1.15+ 127.0.0.1:33798]
I0405 02:27:31.867375       1 scheduling_queue.go:895] About to try and schedule pod kube-system/coredns-5b969f4c88-s4l5s
I0405 02:27:31.867391       1 scheduler.go:454] Attempting to schedule pod: kube-system/coredns-5b969f4c88-s4l5s
I0405 02:27:31.867753       1 scheduler_binder.go:255] AssumePodVolumes for pod "kube-system/coredns-5b969f4c88-s4l5s", node "e2e-test-peterhornyack-minion-group-wsfw"
I0405 02:27:31.867778       1 scheduler_binder.go:265] AssumePodVolumes for pod "kube-system/coredns-5b969f4c88-s4l5s", node "e2e-test-peterhornyack-minion-group-wsfw": all PVCs bound and nothing to do
I0405 02:27:31.867827       1 factory.go:734] Attempting to bind coredns-5b969f4c88-s4l5s to e2e-test-peterhornyack-minion-group-wsfw
I0405 02:27:31.891253       1 scheduler.go:575] pod kube-system/coredns-5b969f4c88-s4l5s is bound successfully on node e2e-test-peterhornyack-minion-group-wsfw, 3 nodes evaluated, 1 nodes were found feasible
I0405 02:27:37.363344       1 wrap.go:47] GET /healthz: (79.943µs) 200 [kube-probe/1.15+ 127.0.0.1:33832]
I0405 02:27:47.362858       1 wrap.go:47] GET /healthz: (93.831µs) 200 [kube-probe/1.15+ 127.0.0.1:33866]
I0405 02:27:47.442549       1 wrap.go:47] GET /healthz: (54.353µs) 200 [kube-probe/1.15+ 127.0.0.1:33874]
I0405 02:27:47.775137       1 wrap.go:47] GET /healthz: (76.114µs) 200 [kube-probe/1.15+ 127.0.0.1:33884]
I0405 02:27:57.362838       1 wrap.go:47] GET /healthz: (83.857µs) 200 [kube-probe/1.15+ 127.0.0.1:33914]
I0405 02:28:07.363233       1 wrap.go:47] GET /healthz: (87.032µs) 200 [kube-probe/1.15+ 127.0.0.1:33950]
I0405 02:28:17.362499       1 wrap.go:47] GET /healthz: (57.733µs) 200 [kube-probe/1.15+ 127.0.0.1:33986]
I0405 02:28:18.580843       1 reflector.go:384] k8s.io/client-go/informers/factory.go:133: Watch close - *v1.ReplicaSet total 52 items received
I0405 02:28:19.589961       1 reflector.go:384] k8s.io/client-go/informers/factory.go:133: Watch close - *v1.StorageClass total 1 items received
I0405 02:28:27.363485       1 wrap.go:47] GET /healthz: (66.774µs) 200 [kube-probe/1.15+ 127.0.0.1:34036]
I0405 02:28:37.362948       1 wrap.go:47] GET /healthz: (75.878µs) 200 [kube-probe/1.15+ 127.0.0.1:34072]
I0405 02:28:47.363771       1 wrap.go:47] GET /healthz: (144.324µs) 200 [kube-probe/1.15+ 127.0.0.1:34104]
I0405 02:28:57.362625       1 wrap.go:47] GET /healthz: (72.368µs) 200 [kube-probe/1.15+ 127.0.0.1:34136]
I0405 02:29:07.362787       1 wrap.go:47] GET /healthz: (65.707µs) 200 [kube-probe/1.15+ 127.0.0.1:34172]
I0405 02:29:17.364284       1 wrap.go:47] GET /healthz: (76.168µs) 200 [kube-probe/1.15+ 127.0.0.1:34208]
I0405 02:29:27.362744       1 wrap.go:47] GET /healthz: (65.29µs) 200 [kube-probe/1.15+ 127.0.0.1:34256]
I0405 02:29:34.563237       1 reflector.go:384] k8s.io/kubernetes/cmd/kube-scheduler/app/server.go:223: Watch close - *v1.Pod total 119 items received
I0405 02:29:37.363808       1 wrap.go:47] GET /healthz: (126.873µs) 200 [kube-probe/1.15+ 127.0.0.1:34290]
I0405 02:29:47.364312       1 wrap.go:47] GET /healthz: (82.499µs) 200 [kube-probe/1.15+ 127.0.0.1:34322]
I0405 02:29:57.362643       1 wrap.go:47] GET /healthz: (71.887µs) 200 [kube-probe/1.15+ 127.0.0.1:34358]
I0405 02:30:03.586813       1 reflector.go:384] k8s.io/client-go/informers/factory.go:133: Watch close - *v1.ReplicationController total 0 items received
I0405 02:30:07.363194       1 wrap.go:47] GET /healthz: (86.927µs) 200 [kube-probe/1.15+ 127.0.0.1:34394]
I0405 02:30:16.567525       1 reflector.go:384] k8s.io/client-go/informers/factory.go:133: Watch close - *v1.Node total 52 items received
I0405 02:30:17.363852       1 wrap.go:47] GET /healthz: (209.114µs) 200 [kube-probe/1.15+ 127.0.0.1:34430]
I0405 02:30:27.362701       1 wrap.go:47] GET /healthz: (57.378µs) 200 [kube-probe/1.15+ 127.0.0.1:34478]
I0405 02:30:37.363275       1 wrap.go:47] GET /healthz: (73.148µs) 200 [kube-probe/1.15+ 127.0.0.1:34512]
I0405 02:30:43.565423       1 reflector.go:384] k8s.io/client-go/informers/factory.go:133: Watch close - *v1beta1.PodDisruptionBudget total 0 items received
I0405 02:30:47.363788       1 wrap.go:47] GET /healthz: (77.066µs) 200 [kube-probe/1.15+ 127.0.0.1:34544]
I0405 02:30:57.363313       1 wrap.go:47] GET /healthz: (98.859µs) 200 [kube-probe/1.15+ 127.0.0.1:34576]
I0405 02:31:07.363213       1 wrap.go:47] GET /healthz: (111.599µs) 200 [kube-probe/1.15+ 127.0.0.1:34614]
I0405 02:31:17.364231       1 wrap.go:47] GET /healthz: (71.356µs) 200 [kube-probe/1.15+ 127.0.0.1:34650]
I0405 02:31:27.362649       1 wrap.go:47] GET /healthz: (83.662µs) 200 [kube-probe/1.15+ 127.0.0.1:34700]
I0405 02:31:37.363284       1 wrap.go:47] GET /healthz: (79.476µs) 200 [kube-probe/1.15+ 127.0.0.1:34734]
I0405 02:31:40.574785       1 reflector.go:384] k8s.io/client-go/informers/factory.go:133: Watch close - *v1.Service total 6 items received
I0405 02:31:47.363765       1 wrap.go:47] GET /healthz: (147.662µs) 200 [kube-probe/1.15+ 127.0.0.1:34766]
I0405 02:31:57.363009       1 wrap.go:47] GET /healthz: (101.712µs) 200 [kube-probe/1.15+ 127.0.0.1:34798]
I0405 02:32:03.587208       1 reflector.go:384] k8s.io/client-go/informers/factory.go:133: Watch close - *v1.StatefulSet total 0 items received
I0405 02:32:07.362751       1 wrap.go:47] GET /healthz: (86.736µs) 200 [kube-probe/1.15+ 127.0.0.1:34834]
I0405 02:32:17.363424       1 wrap.go:47] GET /healthz: (62.521µs) 200 [kube-probe/1.15+ 127.0.0.1:34870]
I0405 02:32:27.363279       1 wrap.go:47] GET /healthz: (96.811µs) 200 [kube-probe/1.15+ 127.0.0.1:34920]
I0405 02:32:32.559413       1 reflector.go:384] k8s.io/client-go/informers/factory.go:133: Watch close - *v1.PersistentVolume total 0 items received
I0405 02:32:37.363060       1 wrap.go:47] GET /healthz: (79.171µs) 200 [kube-probe/1.15+ 127.0.0.1:34954]
I0405 02:32:45.892224       1 scheduling_queue.go:895] About to try and schedule pod default/linux-nginx-7c4f9bd84f-x5pxr
I0405 02:32:45.892239       1 scheduler.go:454] Attempting to schedule pod: default/linux-nginx-7c4f9bd84f-x5pxr
I0405 02:32:45.894846       1 scheduler_binder.go:255] AssumePodVolumes for pod "default/linux-nginx-7c4f9bd84f-x5pxr", node "e2e-test-peterhornyack-minion-group-wsfw"
I0405 02:32:45.898213       1 scheduler_binder.go:265] AssumePodVolumes for pod "default/linux-nginx-7c4f9bd84f-x5pxr", node "e2e-test-peterhornyack-minion-group-wsfw": all PVCs bound and nothing to do
I0405 02:32:45.898323       1 factory.go:734] Attempting to bind linux-nginx-7c4f9bd84f-x5pxr to e2e-test-peterhornyack-minion-group-wsfw
I0405 02:32:45.919845       1 scheduler.go:575] pod default/linux-nginx-7c4f9bd84f-x5pxr is bound successfully on node e2e-test-peterhornyack-minion-group-wsfw, 4 nodes evaluated, 1 nodes were found feasible
I0405 02:32:47.363761       1 wrap.go:47] GET /healthz: (150.423µs) 200 [kube-probe/1.15+ 127.0.0.1:34986]
I0405 02:32:56.829475       1 scheduling_queue.go:895] About to try and schedule pod default/linux-ubuntu-5dbcdfff9d-7klgf
I0405 02:32:56.829506       1 scheduler.go:454] Attempting to schedule pod: default/linux-ubuntu-5dbcdfff9d-7klgf
I0405 02:32:56.829780       1 scheduler_binder.go:255] AssumePodVolumes for pod "default/linux-ubuntu-5dbcdfff9d-7klgf", node "e2e-test-peterhornyack-minion-group-wsfw"
I0405 02:32:56.829791       1 scheduler_binder.go:265] AssumePodVolumes for pod "default/linux-ubuntu-5dbcdfff9d-7klgf", node "e2e-test-peterhornyack-minion-group-wsfw": all PVCs bound and nothing to do
I0405 02:32:56.829854       1 factory.go:734] Attempting to bind linux-ubuntu-5dbcdfff9d-7klgf to e2e-test-peterhornyack-minion-group-wsfw
I0405 02:32:56.852213       1 scheduler.go:575] pod default/linux-ubuntu-5dbcdfff9d-7klgf is bound successfully on node e2e-test-peterhornyack-minion-group-wsfw, 4 nodes evaluated, 1 nodes were found feasible
I0405 02:32:57.363342       1 wrap.go:47] GET /healthz: (75.767µs) 200 [kube-probe/1.15+ 127.0.0.1:35020]
I0405 02:32:59.569909       1 reflector.go:384] k8s.io/client-go/informers/factory.go:133: Watch close - *v1.PersistentVolumeClaim total 0 items received
I0405 02:33:07.364000       1 wrap.go:47] GET /healthz: (120.759µs) 200 [kube-probe/1.15+ 127.0.0.1:35056]
I0405 02:33:07.722243       1 scheduling_queue.go:895] About to try and schedule pod default/windows-nettest-944bd6d8d-t7d6f
I0405 02:33:07.722270       1 scheduler.go:454] Attempting to schedule pod: default/windows-nettest-944bd6d8d-t7d6f
I0405 02:33:07.726161       1 scheduler_binder.go:255] AssumePodVolumes for pod "default/windows-nettest-944bd6d8d-t7d6f", node "e2e-test-peterhornyack-windows-node-group-lkqs"
I0405 02:33:07.726194       1 scheduler_binder.go:265] AssumePodVolumes for pod "default/windows-nettest-944bd6d8d-t7d6f", node "e2e-test-peterhornyack-windows-node-group-lkqs": all PVCs bound and nothing to do
I0405 02:33:07.726266       1 factory.go:734] Attempting to bind windows-nettest-944bd6d8d-t7d6f to e2e-test-peterhornyack-windows-node-group-lkqs
I0405 02:33:07.750056       1 scheduler.go:575] pod default/windows-nettest-944bd6d8d-t7d6f is bound successfully on node e2e-test-peterhornyack-windows-node-group-lkqs, 4 nodes evaluated, 2 nodes were found feasible
I0405 02:33:17.364432       1 wrap.go:47] GET /healthz: (76.293µs) 200 [kube-probe/1.15+ 127.0.0.1:35092]
I0405 02:33:27.363247       1 wrap.go:47] GET /healthz: (125.222µs) 200 [kube-probe/1.15+ 127.0.0.1:35136]
I0405 02:33:37.363134       1 wrap.go:47] GET /healthz: (80.524µs) 200 [kube-probe/1.15+ 127.0.0.1:35174]
I0405 02:33:47.363114       1 wrap.go:47] GET /healthz: (81.624µs) 200 [kube-probe/1.15+ 127.0.0.1:35208]
I0405 02:33:56.582892       1 reflector.go:384] k8s.io/client-go/informers/factory.go:133: Watch close - *v1.ReplicaSet total 11 items received
I0405 02:33:57.362710       1 wrap.go:47] GET /healthz: (73.95µs) 200 [kube-probe/1.15+ 127.0.0.1:35240]
I0405 02:34:07.363051       1 wrap.go:47] GET /healthz: (79.471µs) 200 [kube-probe/1.15+ 127.0.0.1:35276]
I0405 02:34:17.364091       1 wrap.go:47] GET /healthz: (74.843µs) 200 [kube-probe/1.15+ 127.0.0.1:35312]
I0405 02:34:27.362974       1 wrap.go:47] GET /healthz: (100.641µs) 200 [kube-probe/1.15+ 127.0.0.1:35362]
I0405 02:34:37.363150       1 wrap.go:47] GET /healthz: (126.41µs) 200 [kube-probe/1.15+ 127.0.0.1:35396]
I0405 02:34:47.363024       1 wrap.go:47] GET /healthz: (95.245µs) 200 [kube-probe/1.15+ 127.0.0.1:35428]
I0405 02:34:57.363116       1 wrap.go:47] GET /healthz: (80.175µs) 200 [kube-probe/1.15+ 127.0.0.1:35462]
I0405 02:35:07.363305       1 wrap.go:47] GET /healthz: (91.133µs) 200 [kube-probe/1.15+ 127.0.0.1:35498]
I0405 02:35:17.362910       1 wrap.go:47] GET /healthz: (90.979µs) 200 [kube-probe/1.15+ 127.0.0.1:35534]
I0405 02:35:18.565495       1 reflector.go:384] k8s.io/kubernetes/cmd/kube-scheduler/app/server.go:223: Watch close - *v1.Pod total 11 items received
I0405 02:35:27.363188       1 wrap.go:47] GET /healthz: (80.858µs) 200 [kube-probe/1.15+ 127.0.0.1:35582]
I0405 02:35:32.592320       1 reflector.go:384] k8s.io/client-go/informers/factory.go:133: Watch close - *v1.StorageClass total 0 items received
I0405 02:35:37.362873       1 wrap.go:47] GET /healthz: (75.864µs) 200 [kube-probe/1.15+ 127.0.0.1:35616]
I0405 02:35:47.363970       1 wrap.go:47] GET /healthz: (103.852µs) 200 [kube-probe/1.15+ 127.0.0.1:35650]
I0405 02:35:53.144896       1 scheduling_queue.go:895] About to try and schedule pod default/windows-powershell-7c9878bbfd-5zppd
I0405 02:35:53.144909       1 scheduler.go:454] Attempting to schedule pod: default/windows-powershell-7c9878bbfd-5zppd
I0405 02:35:53.149682       1 scheduler_binder.go:255] AssumePodVolumes for pod "default/windows-powershell-7c9878bbfd-5zppd", node "e2e-test-peterhornyack-windows-node-group-rqkw"
I0405 02:35:53.149696       1 scheduler_binder.go:265] AssumePodVolumes for pod "default/windows-powershell-7c9878bbfd-5zppd", node "e2e-test-peterhornyack-windows-node-group-rqkw": all PVCs bound and nothing to do
I0405 02:35:53.149770       1 factory.go:734] Attempting to bind windows-powershell-7c9878bbfd-5zppd to e2e-test-peterhornyack-windows-node-group-rqkw
I0405 02:35:53.206909       1 scheduler.go:575] pod default/windows-powershell-7c9878bbfd-5zppd is bound successfully on node e2e-test-peterhornyack-windows-node-group-rqkw, 4 nodes evaluated, 2 nodes were found feasible
I0405 02:35:57.362982       1 wrap.go:47] GET /healthz: (104.146µs) 200 [kube-probe/1.15+ 127.0.0.1:35684]
I0405 02:36:07.362963       1 wrap.go:47] GET /healthz: (80.718µs) 200 [kube-probe/1.15+ 127.0.0.1:35720]
I0405 02:36:17.363004       1 wrap.go:47] GET /healthz: (98.275µs) 200 [kube-probe/1.15+ 127.0.0.1:35758]
I0405 02:36:27.362895       1 wrap.go:47] GET /healthz: (87.635µs) 200 [kube-probe/1.15+ 127.0.0.1:35806]
I0405 02:36:37.362909       1 wrap.go:47] GET /healthz: (73.205µs) 200 [kube-probe/1.15+ 127.0.0.1:35840]
I0405 02:36:47.363013       1 wrap.go:47] GET /healthz: (116.964µs) 200 [kube-probe/1.15+ 127.0.0.1:35872]
I0405 02:36:57.362773       1 wrap.go:47] GET /healthz: (75.683µs) 200 [kube-probe/1.15+ 127.0.0.1:35904]
I0405 02:37:07.363316       1 wrap.go:47] GET /healthz: (80.354µs) 200 [kube-probe/1.15+ 127.0.0.1:35940]
I0405 02:37:15.570031       1 reflector.go:384] k8s.io/client-go/informers/factory.go:133: Watch close - *v1.Node total 42 items received
I0405 02:37:17.362628       1 wrap.go:47] GET /healthz: (56.371µs) 200 [kube-probe/1.15+ 127.0.0.1:35976]
I0405 02:37:27.362651       1 wrap.go:47] GET /healthz: (64.344µs) 200 [kube-probe/1.15+ 127.0.0.1:36028]
I0405 02:37:29.589486       1 reflector.go:384] k8s.io/client-go/informers/factory.go:133: Watch close - *v1.StatefulSet total 0 items received
I0405 02:37:35.561670       1 reflector.go:384] k8s.io/client-go/informers/factory.go:133: Watch close - *v1.PersistentVolume total 0 items received
I0405 02:37:37.362793       1 wrap.go:47] GET /healthz: (75.832µs) 200 [kube-probe/1.15+ 127.0.0.1:36062]
I0405 02:37:47.362615       1 wrap.go:47] GET /healthz: (61.436µs) 200 [kube-probe/1.15+ 127.0.0.1:36094]
I0405 02:37:54.567752       1 reflector.go:384] k8s.io/client-go/informers/factory.go:133: Watch close - *v1beta1.PodDisruptionBudget total 0 items received
I0405 02:37:57.363152       1 wrap.go:47] GET /healthz: (77.81µs) 200 [kube-probe/1.15+ 127.0.0.1:36126]
I0405 02:38:07.363225       1 wrap.go:47] GET /healthz: (78.636µs) 200 [kube-probe/1.15+ 127.0.0.1:36162]
I0405 02:38:17.362784       1 wrap.go:47] GET /healthz: (78.865µs) 200 [kube-probe/1.15+ 127.0.0.1:36198]
I0405 02:38:27.366608       1 wrap.go:47] GET /healthz: (119.321µs) 200 [kube-probe/1.15+ 127.0.0.1:36246]
I0405 02:38:37.363161       1 wrap.go:47] GET /healthz: (77.197µs) 200 [kube-probe/1.15+ 127.0.0.1:36280]
I0405 02:38:47.362656       1 wrap.go:47] GET /healthz: (73.166µs) 200 [kube-probe/1.15+ 127.0.0.1:36314]
I0405 02:38:47.577287       1 reflector.go:384] k8s.io/client-go/informers/factory.go:133: Watch close - *v1.Service total 0 items received
I0405 02:38:57.362893       1 wrap.go:47] GET /healthz: (72.942µs) 200 [kube-probe/1.15+ 127.0.0.1:36348]
I0405 02:39:05.589103       1 reflector.go:384] k8s.io/client-go/informers/factory.go:133: Watch close - *v1.ReplicationController total 0 items received
I0405 02:39:07.363137       1 wrap.go:47] GET /healthz: (86.017µs) 200 [kube-probe/1.15+ 127.0.0.1:36384]
I0405 02:39:17.362704       1 wrap.go:47] GET /healthz: (68.942µs) 200 [kube-probe/1.15+ 127.0.0.1:36424]
I0405 02:39:27.362757       1 wrap.go:47] GET /healthz: (70.008µs) 200 [kube-probe/1.15+ 127.0.0.1:36472]
I0405 02:39:37.362944       1 wrap.go:47] GET /healthz: (63.145µs) 200 [kube-probe/1.15+ 127.0.0.1:36506]
I0405 02:39:47.364908       1 wrap.go:47] GET /healthz: (77.647µs) 200 [kube-probe/1.15+ 127.0.0.1:36538]
I0405 02:39:52.974822       1 scheduling_queue.go:895] About to try and schedule pod default/linux-nginx-7c4f9bd84f-h8nlw
I0405 02:39:52.975730       1 scheduler.go:454] Attempting to schedule pod: default/linux-nginx-7c4f9bd84f-h8nlw
I0405 02:39:52.978260       1 scheduler_binder.go:255] AssumePodVolumes for pod "default/linux-nginx-7c4f9bd84f-h8nlw", node "e2e-test-peterhornyack-minion-group-wsfw"
I0405 02:39:52.978277       1 scheduler_binder.go:265] AssumePodVolumes for pod "default/linux-nginx-7c4f9bd84f-h8nlw", node "e2e-test-peterhornyack-minion-group-wsfw": all PVCs bound and nothing to do
I0405 02:39:52.978348       1 factory.go:734] Attempting to bind linux-nginx-7c4f9bd84f-h8nlw to e2e-test-peterhornyack-minion-group-wsfw
I0405 02:39:52.996840       1 scheduler.go:575] pod default/linux-nginx-7c4f9bd84f-h8nlw is bound successfully on node e2e-test-peterhornyack-minion-group-wsfw, 4 nodes evaluated, 1 nodes were found feasible
I0405 02:39:57.363257       1 wrap.go:47] GET /healthz: (74.393µs) 200 [kube-probe/1.15+ 127.0.0.1:36570]
I0405 02:40:03.897914       1 scheduling_queue.go:895] About to try and schedule pod default/linux-ubuntu-5dbcdfff9d-kjw5f
I0405 02:40:03.897946       1 scheduler.go:454] Attempting to schedule pod: default/linux-ubuntu-5dbcdfff9d-kjw5f
I0405 02:40:03.899211       1 scheduler_binder.go:255] AssumePodVolumes for pod "default/linux-ubuntu-5dbcdfff9d-kjw5f", node "e2e-test-peterhornyack-minion-group-wsfw"
I0405 02:40:03.899225       1 scheduler_binder.go:265] AssumePodVolumes for pod "default/linux-ubuntu-5dbcdfff9d-kjw5f", node "e2e-test-peterhornyack-minion-group-wsfw": all PVCs bound and nothing to do
I0405 02:40:03.899289       1 factory.go:734] Attempting to bind linux-ubuntu-5dbcdfff9d-kjw5f to e2e-test-peterhornyack-minion-group-wsfw
I0405 02:40:03.920440       1 scheduler.go:575] pod default/linux-ubuntu-5dbcdfff9d-kjw5f is bound successfully on node e2e-test-peterhornyack-minion-group-wsfw, 4 nodes evaluated, 1 nodes were found feasible
I0405 02:40:07.362993       1 wrap.go:47] GET /healthz: (116.863µs) 200 [kube-probe/1.15+ 127.0.0.1:36608]
I0405 02:40:14.818067       1 scheduling_queue.go:895] About to try and schedule pod default/windows-nettest-944bd6d8d-82mfg
I0405 02:40:14.818082       1 scheduler.go:454] Attempting to schedule pod: default/windows-nettest-944bd6d8d-82mfg
I0405 02:40:14.821317       1 scheduler_binder.go:255] AssumePodVolumes for pod "default/windows-nettest-944bd6d8d-82mfg", node "e2e-test-peterhornyack-windows-node-group-lkqs"
I0405 02:40:14.821349       1 scheduler_binder.go:265] AssumePodVolumes for pod "default/windows-nettest-944bd6d8d-82mfg", node "e2e-test-peterhornyack-windows-node-group-lkqs": all PVCs bound and nothing to do
I0405 02:40:14.821435       1 factory.go:734] Attempting to bind windows-nettest-944bd6d8d-82mfg to e2e-test-peterhornyack-windows-node-group-lkqs
I0405 02:40:14.844116       1 scheduler.go:575] pod default/windows-nettest-944bd6d8d-82mfg is bound successfully on node e2e-test-peterhornyack-windows-node-group-lkqs, 4 nodes evaluated, 2 nodes were found feasible
I0405 02:40:17.363261       1 wrap.go:47] GET /healthz: (77.544µs) 200 [kube-probe/1.15+ 127.0.0.1:36644]
I0405 02:40:25.719870       1 scheduling_queue.go:895] About to try and schedule pod default/windows-powershell-7c9878bbfd-ckgr6
I0405 02:40:25.719895       1 scheduler.go:454] Attempting to schedule pod: default/windows-powershell-7c9878bbfd-ckgr6
I0405 02:40:25.723297       1 scheduler_binder.go:255] AssumePodVolumes for pod "default/windows-powershell-7c9878bbfd-ckgr6", node "e2e-test-peterhornyack-windows-node-group-rqkw"
I0405 02:40:25.723313       1 scheduler_binder.go:265] AssumePodVolumes for pod "default/windows-powershell-7c9878bbfd-ckgr6", node "e2e-test-peterhornyack-windows-node-group-rqkw": all PVCs bound and nothing to do
I0405 02:40:25.725545       1 factory.go:734] Attempting to bind windows-powershell-7c9878bbfd-ckgr6 to e2e-test-peterhornyack-windows-node-group-rqkw
I0405 02:40:25.752634       1 scheduler.go:575] pod default/windows-powershell-7c9878bbfd-ckgr6 is bound successfully on node e2e-test-peterhornyack-windows-node-group-rqkw, 4 nodes evaluated, 2 nodes were found feasible
I0405 02:40:27.363899       1 wrap.go:47] GET /healthz: (75.014µs) 200 [kube-probe/1.15+ 127.0.0.1:36694]
I0405 02:40:37.363389       1 wrap.go:47] GET /healthz: (87.97µs) 200 [kube-probe/1.15+ 127.0.0.1:36730]
I0405 02:40:47.362900       1 wrap.go:47] GET /healthz: (83.017µs) 200 [kube-probe/1.15+ 127.0.0.1:36764]
I0405 02:40:57.363331       1 wrap.go:47] GET /healthz: (74.141µs) 200 [kube-probe/1.15+ 127.0.0.1:36804]
I0405 02:41:07.363057       1 wrap.go:47] GET /healthz: (79.163µs) 200 [kube-probe/1.15+ 127.0.0.1:36842]
I0405 02:41:17.363024       1 wrap.go:47] GET /healthz: (118.127µs) 200 [kube-probe/1.15+ 127.0.0.1:36884]
I0405 02:41:27.363038       1 wrap.go:47] GET /healthz: (114.645µs) 200 [kube-probe/1.15+ 127.0.0.1:36936]
I0405 02:41:37.362673       1 wrap.go:47] GET /healthz: (80.755µs) 200 [kube-probe/1.15+ 127.0.0.1:36970]
I0405 02:41:47.362825       1 wrap.go:47] GET /healthz: (60.803µs) 200 [kube-probe/1.15+ 127.0.0.1:37002]
I0405 02:41:48.567804       1 reflector.go:384] k8s.io/kubernetes/cmd/kube-scheduler/app/server.go:223: Watch close - *v1.Pod total 49 items received
I0405 02:41:57.362784       1 wrap.go:47] GET /healthz: (139.408µs) 200 [kube-probe/1.15+ 127.0.0.1:37036]
I0405 02:42:03.594858       1 reflector.go:384] k8s.io/client-go/informers/factory.go:133: Watch close - *v1.StorageClass total 0 items received
I0405 02:42:07.362990       1 wrap.go:47] GET /healthz: (110.584µs) 200 [kube-probe/1.15+ 127.0.0.1:37072]
I0405 02:42:09.572515       1 reflector.go:384] k8s.io/client-go/informers/factory.go:133: Watch close - *v1.PersistentVolumeClaim total 0 items received
I0405 02:42:17.363034       1 wrap.go:47] GET /healthz: (99.416µs) 200 [kube-probe/1.15+ 127.0.0.1:37108]
I0405 02:42:20.584731       1 reflector.go:384] k8s.io/client-go/informers/factory.go:133: Watch close - *v1.ReplicaSet total 28 items received
I0405 02:42:27.363003       1 wrap.go:47] GET /healthz: (88.924µs) 200 [kube-probe/1.15+ 127.0.0.1:37156]
I0405 02:42:37.363003       1 wrap.go:47] GET /healthz: (117.094µs) 200 [kube-probe/1.15+ 127.0.0.1:37192]
I0405 02:42:47.363758       1 wrap.go:47] GET /healthz: (85.035µs) 200 [kube-probe/1.15+ 127.0.0.1:37224]
I0405 02:42:56.569759       1 reflector.go:384] k8s.io/client-go/informers/factory.go:133: Watch close - *v1beta1.PodDisruptionBudget total 0 items received
I0405 02:42:57.362666       1 wrap.go:47] GET /healthz: (84.033µs) 200 [kube-probe/1.15+ 127.0.0.1:37256]
I0405 02:43:07.363001       1 wrap.go:47] GET /healthz: (85.934µs) 200 [kube-probe/1.15+ 127.0.0.1:37292]
I0405 02:43:17.362965       1 wrap.go:47] GET /healthz: (99.373µs) 200 [kube-probe/1.15+ 127.0.0.1:37328]
I0405 02:43:27.362745       1 wrap.go:47] GET /healthz: (50.013µs) 200 [kube-probe/1.15+ 127.0.0.1:37378]
I0405 02:43:37.362621       1 wrap.go:47] GET /healthz: (62.552µs) 200 [kube-probe/1.15+ 127.0.0.1:37412]
I0405 02:43:47.363042       1 wrap.go:47] GET /healthz: (66.597µs) 200 [kube-probe/1.15+ 127.0.0.1:37446]
I0405 02:43:50.591750       1 reflector.go:384] k8s.io/client-go/informers/factory.go:133: Watch close - *v1.StatefulSet total 0 items received
I0405 02:43:53.564071       1 reflector.go:384] k8s.io/client-go/informers/factory.go:133: Watch close - *v1.PersistentVolume total 0 items received
I0405 02:43:57.363170       1 wrap.go:47] GET /healthz: (63.863µs) 200 [kube-probe/1.15+ 127.0.0.1:37478]
I0405 02:44:07.362635       1 wrap.go:47] GET /healthz: (76.279µs) 200 [kube-probe/1.15+ 127.0.0.1:37514]
I0405 02:44:17.362959       1 wrap.go:47] GET /healthz: (64.153µs) 200 [kube-probe/1.15+ 127.0.0.1:37550]
I0405 02:44:27.362912       1 wrap.go:47] GET /healthz: (82.639µs) 200 [kube-probe/1.15+ 127.0.0.1:37598]
I0405 02:44:37.362775       1 wrap.go:47] GET /healthz: (89.321µs) 200 [kube-probe/1.15+ 127.0.0.1:37632]
I0405 02:44:47.362642       1 wrap.go:47] GET /healthz: (73.073µs) 200 [kube-probe/1.15+ 127.0.0.1:37664]
I0405 02:44:57.362852       1 wrap.go:47] GET /healthz: (85.104µs) 200 [kube-probe/1.15+ 127.0.0.1:37698]
I0405 02:45:07.362535       1 wrap.go:47] GET /healthz: (79.172µs) 200 [kube-probe/1.15+ 127.0.0.1:37736]
I0405 02:45:17.363220       1 wrap.go:47] GET /healthz: (76.837µs) 200 [kube-probe/1.15+ 127.0.0.1:37772]
I0405 02:45:19.235292       1 scheduling_queue.go:895] About to try and schedule pod kubectl-448/e2e-test-nginx-rc-mxj5b
I0405 02:45:19.235305       1 scheduler.go:454] Attempting to schedule pod: kubectl-448/e2e-test-nginx-rc-mxj5b
I0405 02:45:19.235703       1 scheduler_binder.go:255] AssumePodVolumes for pod "kubectl-448/e2e-test-nginx-rc-mxj5b", node "e2e-test-peterhornyack-windows-node-group-lkqs"
I0405 02:45:19.235712       1 scheduler_binder.go:265] AssumePodVolumes for pod "kubectl-448/e2e-test-nginx-rc-mxj5b", node "e2e-test-peterhornyack-windows-node-group-lkqs": all PVCs bound and nothing to do
I0405 02:45:19.235757       1 factory.go:734] Attempting to bind e2e-test-nginx-rc-mxj5b to e2e-test-peterhornyack-windows-node-group-lkqs
I0405 02:45:19.249656       1 scheduler.go:575] pod kubectl-448/e2e-test-nginx-rc-mxj5b is bound successfully on node e2e-test-peterhornyack-windows-node-group-lkqs, 4 nodes evaluated, 2 nodes were found feasible
I0405 02:45:27.362737       1 wrap.go:47] GET /healthz: (76.58µs) 200 [kube-probe/1.15+ 127.0.0.1:37820]
I0405 02:45:37.363772       1 wrap.go:47] GET /healthz: (80.919µs) 200 [kube-probe/1.15+ 127.0.0.1:37854]
I0405 02:45:47.365805       1 wrap.go:47] GET /healthz: (178.222µs) 200 [kube-probe/1.15+ 127.0.0.1:37886]
I0405 02:45:57.362750       1 wrap.go:47] GET /healthz: (67.674µs) 200 [kube-probe/1.15+ 127.0.0.1:37920]
I0405 02:46:07.362850       1 wrap.go:47] GET /healthz: (97.914µs) 200 [kube-probe/1.15+ 127.0.0.1:37958]
I0405 02:46:17.364295       1 wrap.go:47] GET /healthz: (79.138µs) 200 [kube-probe/1.15+ 127.0.0.1:37994]
I0405 02:46:18.248824       1 scheduling_queue.go:895] About to try and schedule pod downward-api-7571/downwardapi-volume-e990a741-6b26-4045-ab75-14a44006882d
I0405 02:46:18.248841       1 scheduler.go:454] Attempting to schedule pod: downward-api-7571/downwardapi-volume-e990a741-6b26-4045-ab75-14a44006882d
I0405 02:46:18.249231       1 scheduler_binder.go:255] AssumePodVolumes for pod "downward-api-7571/downwardapi-volume-e990a741-6b26-4045-ab75-14a44006882d", node "e2e-test-peterhornyack-windows-node-group-rqkw"
I0405 02:46:18.249245       1 scheduler_binder.go:265] AssumePodVolumes for pod "downward-api-7571/downwardapi-volume-e990a741-6b26-4045-ab75-14a44006882d", node "e2e-test-peterhornyack-windows-node-group-rqkw": all PVCs bound and nothing to do
I0405 02:46:18.249403       1 factory.go:734] Attempting to bind downwardapi-volume-e990a741-6b26-4045-ab75-14a44006882d to e2e-test-peterhornyack-windows-node-group-rqkw
I0405 02:46:18.257741       1 scheduler.go:575] pod downward-api-7571/downwardapi-volume-e990a741-6b26-4045-ab75-14a44006882d is bound successfully on node e2e-test-peterhornyack-windows-node-group-rqkw, 4 nodes evaluated, 2 nodes were found feasible
I0405 02:46:27.362974       1 wrap.go:47] GET /healthz: (103.687µs) 200 [kube-probe/1.15+ 127.0.0.1:38046]
I0405 02:46:29.571860       1 reflector.go:384] k8s.io/client-go/informers/factory.go:133: Watch close - *v1.Node total 48 items received
I0405 02:46:37.363032       1 wrap.go:47] GET /healthz: (118.811µs) 200 [kube-probe/1.15+ 127.0.0.1:38082]
I0405 02:46:42.846157       1 scheduling_queue.go:895] About to try and schedule pod replicaset-4583/my-hostname-basic-e0b51260-d543-49d0-9ed2-ae9a8f557d0f-ffvfn
I0405 02:46:42.846174       1 scheduler.go:454] Attempting to schedule pod: replicaset-4583/my-hostname-basic-e0b51260-d543-49d0-9ed2-ae9a8f557d0f-ffvfn
I0405 02:46:42.846542       1 scheduler_binder.go:255] AssumePodVolumes for pod "replicaset-4583/my-hostname-basic-e0b51260-d543-49d0-9ed2-ae9a8f557d0f-ffvfn", node "e2e-test-peterhornyack-windows-node-group-lkqs"
I0405 02:46:42.847957       1 scheduler_binder.go:265] AssumePodVolumes for pod "replicaset-4583/my-hostname-basic-e0b51260-d543-49d0-9ed2-ae9a8f557d0f-ffvfn", node "e2e-test-peterhornyack-windows-node-group-lkqs": all PVCs bound and nothing to do
I0405 02:46:42.848027       1 factory.go:734] Attempting to bind my-hostname-basic-e0b51260-d543-49d0-9ed2-ae9a8f557d0f-ffvfn to e2e-test-peterhornyack-windows-node-group-lkqs
I0405 02:46:42.861488       1 scheduler.go:575] pod replicaset-4583/my-hostname-basic-e0b51260-d543-49d0-9ed2-ae9a8f557d0f-ffvfn is bound successfully on node e2e-test-peterhornyack-windows-node-group-lkqs, 4 nodes evaluated, 2 nodes were found feasible
I0405 02:46:47.363119       1 wrap.go:47] GET /healthz: (87.568µs) 200 [kube-probe/1.15+ 127.0.0.1:38116]
I0405 02:46:57.363075       1 wrap.go:47] GET /healthz: (81.633µs) 200 [kube-probe/1.15+ 127.0.0.1:38148]
I0405 02:47:06.178782       1 scheduling_queue.go:895] About to try and schedule pod downward-api-1609/annotationupdate71c93ef9-8a8d-47f4-a171-6606df46f51e
I0405 02:47:06.178824       1 scheduler.go:454] Attempting to schedule pod: downward-api-1609/annotationupdate71c93ef9-8a8d-47f4-a171-6606df46f51e
I0405 02:47:06.179869       1 scheduler_binder.go:255] AssumePodVolumes for pod "downward-api-1609/annotationupdate71c93ef9-8a8d-47f4-a171-6606df46f51e", node "e2e-test-peterhornyack-windows-node-group-rqkw"
I0405 02:47:06.179885       1 scheduler_binder.go:265] AssumePodVolumes for pod "downward-api-1609/annotationupdate71c93ef9-8a8d-47f4-a171-6606df46f51e", node "e2e-test-peterhornyack-windows-node-group-rqkw": all PVCs bound and nothing to do
I0405 02:47:06.179977       1 factory.go:734] Attempting to bind annotationupdate71c93ef9-8a8d-47f4-a171-6606df46f51e to e2e-test-peterhornyack-windows-node-group-rqkw
I0405 02:47:06.187366       1 scheduler.go:575] pod downward-api-1609/annotationupdate71c93ef9-8a8d-47f4-a171-6606df46f51e is bound successfully on node e2e-test-peterhornyack-windows-node-group-rqkw, 4 nodes evaluated, 2 nodes were found feasible
I0405 02:47:07.362868       1 wrap.go:47] GET /healthz: (80.058µs) 200 [kube-probe/1.15+ 127.0.0.1:38186]
I0405 02:47:09.570024       1 reflector.go:384] k8s.io/kubernetes/cmd/kube-scheduler/app/server.go:223: Watch close - *v1.Pod total 25 items received
I0405 02:47:17.362678       1 wrap.go:47] GET /healthz: (49.968µs) 200 [kube-probe/1.15+ 127.0.0.1:38222]
I0405 02:47:27.362960       1 wrap.go:47] GET /healthz: (62.349µs) 200 [kube-probe/1.15+ 127.0.0.1:38270]
I0405 02:47:37.362975       1 wrap.go:47] GET /healthz: (118.905µs) 200 [kube-probe/1.15+ 127.0.0.1:38306]
I0405 02:47:47.362994       1 wrap.go:47] GET /healthz: (104.175µs) 200 [kube-probe/1.15+ 127.0.0.1:38338]
I0405 02:47:51.960838       1 scheduling_queue.go:895] About to try and schedule pod svcaccounts-1254/pod-service-account-defaultsa
I0405 02:47:51.960864       1 scheduler.go:454] Attempting to schedule pod: svcaccounts-1254/pod-service-account-defaultsa
I0405 02:47:51.961379       1 scheduler_binder.go:255] AssumePodVolumes for pod "svcaccounts-1254/pod-service-account-defaultsa", node "e2e-test-peterhornyack-windows-node-group-rqkw"
I0405 02:47:51.961391       1 scheduler_binder.go:265] AssumePodVolumes for pod "svcaccounts-1254/pod-service-account-defaultsa", node "e2e-test-peterhornyack-windows-node-group-rqkw": all PVCs bound and nothing to do
I0405 02:47:51.962473       1 factory.go:734] Attempting to bind pod-service-account-defaultsa to e2e-test-peterhornyack-windows-node-group-rqkw
I0405 02:47:51.970273       1 scheduler.go:575] pod svcaccounts-1254/pod-service-account-defaultsa is bound successfully on node e2e-test-peterhornyack-windows-node-group-rqkw, 4 nodes evaluated, 2 nodes were found feasible
I0405 02:47:52.007039       1 scheduling_queue.go:895] About to try and schedule pod svcaccounts-1254/pod-service-account-mountsa
I0405 02:47:52.007053       1 scheduler.go:454] Attempting to schedule pod: svcaccounts-1254/pod-service-account-mountsa
I0405 02:47:52.009066       1 scheduler_binder.go:255] AssumePodVolumes for pod "svcaccounts-1254/pod-service-account-mountsa", node "e2e-test-peterhornyack-windows-node-group-rqkw"
I0405 02:47:52.009084       1 scheduler_binder.go:265] AssumePodVolumes for pod "svcaccounts-1254/pod-service-account-mountsa", node "e2e-test-peterhornyack-windows-node-group-rqkw": all PVCs bound and nothing to do
I0405 02:47:52.009142       1 factory.go:734] Attempting to bind pod-service-account-mountsa to e2e-test-peterhornyack-windows-node-group-rqkw
I0405 02:47:52.015558       1 scheduler.go:575] pod svcaccounts-1254/pod-service-account-mountsa is bound successfully on node e2e-test-peterhornyack-windows-node-group-rqkw, 4 nodes evaluated, 2 nodes were found feasible
I0405 02:47:52.053008       1 scheduling_queue.go:895] About to try and schedule pod svcaccounts-1254/pod-service-account-nomountsa
I0405 02:47:52.053025       1 scheduler.go:454] Attempting to schedule pod: svcaccounts-1254/pod-service-account-nomountsa
I0405 02:47:52.053330       1 scheduler_binder.go:255] AssumePodVolumes for pod "svcaccounts-1254/pod-service-account-nomountsa", node "e2e-test-peterhornyack-windows-node-group-rqkw"
I0405 02:47:52.053340       1 scheduler_binder.go:265] AssumePodVolumes for pod "svcaccounts-1254/pod-service-account-nomountsa", node "e2e-test-peterhornyack-windows-node-group-rqkw": all PVCs bound and nothing to do
I0405 02:47:52.054562       1 factory.go:734] Attempting to bind pod-service-account-nomountsa to e2e-test-peterhornyack-windows-node-group-rqkw
I0405 02:47:52.062140       1 scheduler.go:575] pod svcaccounts-1254/pod-service-account-nomountsa is bound successfully on node e2e-test-peterhornyack-windows-node-group-rqkw, 4 nodes evaluated, 2 nodes were found feasible
I0405 02:47:52.099914       1 scheduling_queue.go:895] About to try and schedule pod svcaccounts-1254/pod-service-account-defaultsa-mountspec
I0405 02:47:52.099952       1 scheduler.go:454] Attempting to schedule pod: svcaccounts-1254/pod-service-account-defaultsa-mountspec
I0405 02:47:52.100202       1 scheduler_binder.go:255] AssumePodVolumes for pod "svcaccounts-1254/pod-service-account-defaultsa-mountspec", node "e2e-test-peterhornyack-windows-node-group-rqkw"
I0405 02:47:52.100214       1 scheduler_binder.go:265] AssumePodVolumes for pod "svcaccounts-1254/pod-service-account-defaultsa-mountspec", node "e2e-test-peterhornyack-windows-node-group-rqkw": all PVCs bound and nothing to do
I0405 02:47:52.100710       1 factory.go:734] Attempting to bind pod-service-account-defaultsa-mountspec to e2e-test-peterhornyack-windows-node-group-rqkw
I0405 02:47:52.108780       1 scheduler.go:575] pod svcaccounts-1254/pod-service-account-defaultsa-mountspec is bound successfully on node e2e-test-peterhornyack-windows-node-group-rqkw, 4 nodes evaluated, 2 nodes were found feasible
I0405 02:47:52.145218       1 scheduling_queue.go:895] About to try and schedule pod svcaccounts-1254/pod-service-account-mountsa-mountspec
I0405 02:47:52.145233       1 scheduler.go:454] Attempting to schedule pod: svcaccounts-1254/pod-service-account-mountsa-mountspec
I0405 02:47:52.145872       1 scheduler_binder.go:255] AssumePodVolumes for pod "svcaccounts-1254/pod-service-account-mountsa-mountspec", node "e2e-test-peterhornyack-windows-node-group-rqkw"
I0405 02:47:52.145884       1 scheduler_binder.go:265] AssumePodVolumes for pod "svcaccounts-1254/pod-service-account-mountsa-mountspec", node "e2e-test-peterhornyack-windows-node-group-rqkw": all PVCs bound and nothing to do
I0405 02:47:52.145956       1 factory.go:734] Attempting to bind pod-service-account-mountsa-mountspec to e2e-test-peterhornyack-windows-node-group-rqkw
I0405 02:47:52.152895       1 scheduler.go:575] pod svcaccounts-1254/pod-service-account-mountsa-mountspec is bound successfully on node e2e-test-peterhornyack-windows-node-group-rqkw, 4 nodes evaluated, 2 nodes were found feasible
I0405 02:47:52.189708       1 scheduling_queue.go:895] About to try and schedule pod svcaccounts-1254/pod-service-account-nomountsa-mountspec
I0405 02:47:52.189723       1 scheduler.go:454] Attempting to schedule pod: svcaccounts-1254/pod-service-account-nomountsa-mountspec
I0405 02:47:52.190507       1 scheduler_binder.go:255] AssumePodVolumes for pod "svcaccounts-1254/pod-service-account-nomountsa-mountspec", node "e2e-test-peterhornyack-windows-node-group-rqkw"
I0405 02:47:52.190520       1 scheduler_binder.go:265] AssumePodVolumes for pod "svcaccounts-1254/pod-service-account-nomountsa-mountspec", node "e2e-test-peterhornyack-windows-node-group-rqkw": all PVCs bound and nothing to do
I0405 02:47:52.190584       1 factory.go:734] Attempting to bind pod-service-account-nomountsa-mountspec to e2e-test-peterhornyack-windows-node-group-rqkw
I0405 02:47:52.196648       1 scheduler.go:575] pod svcaccounts-1254/pod-service-account-nomountsa-mountspec is bound successfully on node e2e-test-peterhornyack-windows-node-group-rqkw, 4 nodes evaluated, 2 nodes were found feasible
I0405 02:47:52.235882       1 scheduling_queue.go:895] About to try and schedule pod svcaccounts-1254/pod-service-account-defaultsa-nomountspec
I0405 02:47:52.235897       1 scheduler.go:454] Attempting to schedule pod: svcaccounts-1254/pod-service-account-defaultsa-nomountspec
I0405 02:47:52.237189       1 scheduler_binder.go:255] AssumePodVolumes for pod "svcaccounts-1254/pod-service-account-defaultsa-nomountspec", node "e2e-test-peterhornyack-windows-node-group-rqkw"
I0405 02:47:52.237205       1 scheduler_binder.go:265] AssumePodVolumes for pod "svcaccounts-1254/pod-service-account-defaultsa-nomountspec", node "e2e-test-peterhornyack-windows-node-group-rqkw": all PVCs bound and nothing to do
I0405 02:47:52.237266       1 factory.go:734] Attempting to bind pod-service-account-defaultsa-nomountspec to e2e-test-peterhornyack-windows-node-group-rqkw
I0405 02:47:52.244347       1 scheduler.go:575] pod svcaccounts-1254/pod-service-account-defaultsa-nomountspec is bound successfully on node e2e-test-peterhornyack-windows-node-group-rqkw, 4 nodes evaluated, 2 nodes were found feasible
I0405 02:47:52.281523       1 scheduling_queue.go:895] About to try and schedule pod svcaccounts-1254/pod-service-account-mountsa-nomountspec
I0405 02:47:52.281540       1 scheduler.go:454] Attempting to schedule pod: svcaccounts-1254/pod-service-account-mountsa-nomountspec
I0405 02:47:52.283065       1 scheduler_binder.go:255] AssumePodVolumes for pod "svcaccounts-1254/pod-service-account-mountsa-nomountspec", node "e2e-test-peterhornyack-windows-node-group-rqkw"
I0405 02:47:52.283081       1 scheduler_binder.go:265] AssumePodVolumes for pod "svcaccounts-1254/pod-service-account-mountsa-nomountspec", node "e2e-test-peterhornyack-windows-node-group-rqkw": all PVCs bound and nothing to do
I0405 02:47:52.283146       1 factory.go:734] Attempting to bind pod-service-account-mountsa-nomountspec to e2e-test-peterhornyack-windows-node-group-rqkw
I0405 02:47:52.289372       1 scheduler.go:575] pod svcaccounts-1254/pod-service-account-mountsa-nomountspec is bound successfully on node e2e-test-peterhornyack-windows-node-group-rqkw, 4 nodes evaluated, 2 nodes were found feasible
I0405 02:47:52.328225       1 scheduling_queue.go:895] About to try and schedule pod svcaccounts-1254/pod-service-account-nomountsa-nomountspec
I0405 02:47:52.328241       1 scheduler.go:454] Attempting to schedule pod: svcaccounts-1254/pod-service-account-nomountsa-nomountspec
I0405 02:47:52.328832       1 scheduler_binder.go:255] AssumePodVolumes for pod "svcaccounts-1254/pod-service-account-nomountsa-nomountspec", node "e2e-test-peterhornyack-windows-node-group-rqkw"
I0405 02:47:52.328861       1 scheduler_binder.go:265] AssumePodVolumes for pod "svcaccounts-1254/pod-service-account-nomountsa-nomountspec", node "e2e-test-peterhornyack-windows-node-group-rqkw": all PVCs bound and nothing to do
I0405 02:47:52.328901       1 factory.go:734] Attempting to bind pod-service-account-nomountsa-nomountspec to e2e-test-peterhornyack-windows-node-group-rqkw
I0405 02:47:52.335312       1 scheduler.go:575] pod svcaccounts-1254/pod-service-account-nomountsa-nomountspec is bound successfully on node e2e-test-peterhornyack-windows-node-group-rqkw, 4 nodes evaluated, 2 nodes were found feasible
I0405 02:47:57.362727       1 wrap.go:47] GET /healthz: (77.116µs) 200 [kube-probe/1.15+ 127.0.0.1:38372]
I0405 02:48:07.363079       1 wrap.go:47] GET /healthz: (138.171µs) 200 [kube-probe/1.15+ 127.0.0.1:38408]
I0405 02:48:16.447289       1 scheduling_queue.go:895] About to try and schedule pod projected-1134/projected-volume-a203afff-49fc-4250-bed0-8c2879070599
I0405 02:48:16.447369       1 scheduler.go:454] Attempting to schedule pod: projected-1134/projected-volume-a203afff-49fc-4250-bed0-8c2879070599
I0405 02:48:16.447820       1 scheduler_binder.go:255] AssumePodVolumes for pod "projected-1134/projected-volume-a203afff-49fc-4250-bed0-8c2879070599", node "e2e-test-peterhornyack-windows-node-group-rqkw"
I0405 02:48:16.447834       1 scheduler_binder.go:265] AssumePodVolumes for pod "projected-1134/projected-volume-a203afff-49fc-4250-bed0-8c2879070599", node "e2e-test-peterhornyack-windows-node-group-rqkw": all PVCs bound and nothing to do
I0405 02:48:16.447872       1 factory.go:734] Attempting to bind projected-volume-a203afff-49fc-4250-bed0-8c2879070599 to e2e-test-peterhornyack-windows-node-group-rqkw
I0405 02:48:16.467019       1 scheduler.go:575] pod projected-1134/projected-volume-a203afff-49fc-4250-bed0-8c2879070599 is bound successfully on node e2e-test-peterhornyack-windows-node-group-rqkw, 4 nodes evaluated, 2 nodes were found feasible
I0405 02:48:17.362713       1 wrap.go:47] GET /healthz: (58.058µs) 200 [kube-probe/1.15+ 127.0.0.1:38444]
I0405 02:48:17.591087       1 reflector.go:384] k8s.io/client-go/informers/factory.go:133: Watch close - *v1.ReplicationController total 5 items received
I0405 02:48:27.379215       1 wrap.go:47] GET /healthz: (51.678µs) 200 [kube-probe/1.15+ 127.0.0.1:38492]
I0405 02:48:37.362695       1 wrap.go:47] GET /healthz: (50.195µs) 200 [kube-probe/1.15+ 127.0.0.1:38526]
I0405 02:48:46.579662       1 reflector.go:384] k8s.io/client-go/informers/factory.go:133: Watch close - *v1.Service total 0 items received
I0405 02:48:47.362724       1 wrap.go:47] GET /healthz: (72.361µs) 200 [kube-probe/1.15+ 127.0.0.1:38558]
I0405 02:48:49.447292       1 scheduling_queue.go:895] About to try and schedule pod secrets-2488/pod-secrets-69aeaf47-b01b-4d3b-b080-163a0af87571
I0405 02:48:49.447304       1 scheduler.go:454] Attempting to schedule pod: secrets-2488/pod-secrets-69aeaf47-b01b-4d3b-b080-163a0af87571
I0405 02:48:49.448388       1 scheduler_binder.go:255] AssumePodVolumes for pod "secrets-2488/pod-secrets-69aeaf47-b01b-4d3b-b080-163a0af87571", node "e2e-test-peterhornyack-windows-node-group-rqkw"
I0405 02:48:49.448401       1 scheduler_binder.go:265] AssumePodVolumes for pod "secrets-2488/pod-secrets-69aeaf47-b01b-4d3b-b080-163a0af87571", node "e2e-test-peterhornyack-windows-node-group-rqkw": all PVCs bound and nothing to do
I0405 02:48:49.449104       1 factory.go:734] Attempting to bind pod-secrets-69aeaf47-b01b-4d3b-b080-163a0af87571 to e2e-test-peterhornyack-windows-node-group-rqkw
I0405 02:48:49.455019       1 scheduler.go:575] pod secrets-2488/pod-secrets-69aeaf47-b01b-4d3b-b080-163a0af87571 is bound successfully on node e2e-test-peterhornyack-windows-node-group-rqkw, 4 nodes evaluated, 2 nodes were found feasible
I0405 02:48:57.363091       1 wrap.go:47] GET /healthz: (113.833µs) 200 [kube-probe/1.15+ 127.0.0.1:38592]
I0405 02:49:07.363069       1 wrap.go:47] GET /healthz: (79.301µs) 200 [kube-probe/1.15+ 127.0.0.1:38628]
I0405 02:49:17.362772       1 wrap.go:47] GET /healthz: (74.881µs) 200 [kube-probe/1.15+ 127.0.0.1:38664]
I0405 02:49:18.597024       1 reflector.go:384] k8s.io/client-go/informers/factory.go:133: Watch close - *v1.StorageClass total 0 items received
I0405 02:49:27.362868       1 wrap.go:47] GET /healthz: (50.601µs) 200 [kube-probe/1.15+ 127.0.0.1:38714]
I0405 02:49:30.703951       1 scheduling_queue.go:895] About to try and schedule pod deployment-2119/test-rolling-update-controller-jqbnr
I0405 02:49:30.703975       1 scheduler.go:454] Attempting to schedule pod: deployment-2119/test-rolling-update-controller-jqbnr
I0405 02:49:30.704498       1 scheduler_binder.go:255] AssumePodVolumes for pod "deployment-2119/test-rolling-update-controller-jqbnr", node "e2e-test-peterhornyack-windows-node-group-lkqs"
I0405 02:49:30.704510       1 scheduler_binder.go:265] AssumePodVolumes for pod "deployment-2119/test-rolling-update-controller-jqbnr", node "e2e-test-peterhornyack-windows-node-group-lkqs": all PVCs bound and nothing to do
I0405 02:49:30.707300       1 factory.go:734] Attempting to bind test-rolling-update-controller-jqbnr to e2e-test-peterhornyack-windows-node-group-lkqs
I0405 02:49:30.724161       1 scheduler.go:575] pod deployment-2119/test-rolling-update-controller-jqbnr is bound successfully on node e2e-test-peterhornyack-windows-node-group-lkqs, 4 nodes evaluated, 2 nodes were found feasible
I0405 02:49:37.362982       1 wrap.go:47] GET /healthz: (90.613µs) 200 [kube-probe/1.15+ 127.0.0.1:38748]
I0405 02:49:37.594029       1 reflector.go:384] k8s.io/client-go/informers/factory.go:133: Watch close - *v1.StatefulSet total 0 items received
I0405 02:49:38.901785       1 scheduling_queue.go:895] About to try and schedule pod deployment-2119/test-rolling-update-deployment-7fcdf5fb94-8pq2x
I0405 02:49:38.901799       1 scheduler.go:454] Attempting to schedule pod: deployment-2119/test-rolling-update-deployment-7fcdf5fb94-8pq2x
I0405 02:49:38.902166       1 scheduler_binder.go:255] AssumePodVolumes for pod "deployment-2119/test-rolling-update-deployment-7fcdf5fb94-8pq2x", node "e2e-test-peterhornyack-windows-node-group-lkqs"
I0405 02:49:38.902189       1 scheduler_binder.go:265] AssumePodVolumes for pod "deployment-2119/test-rolling-update-deployment-7fcdf5fb94-8pq2x", node "e2e-test-peterhornyack-windows-node-group-lkqs": all PVCs bound and nothing to do
I0405 02:49:38.902230       1 factory.go:734] Attempting to bind test-rolling-update-deployment-7fcdf5fb94-8pq2x to e2e-test-peterhornyack-windows-node-group-lkqs
I0405 02:49:38.916769       1 scheduler.go:575] pod deployment-2119/test-rolling-update-deployment-7fcdf5fb94-8pq2x is bound successfully on node e2e-test-peterhornyack-windows-node-group-lkqs, 4 nodes evaluated, 2 nodes were found feasible
I0405 02:49:46.574843       1 reflector.go:384] k8s.io/client-go/informers/factory.go:133: Watch close - *v1.PersistentVolumeClaim total 0 items received
I0405 02:49:47.362849       1 wrap.go:47] GET /healthz: (73.59µs) 200 [kube-probe/1.15+ 127.0.0.1:38780]
I0405 02:49:57.363375       1 wrap.go:47] GET /healthz: (80.962µs) 200 [kube-probe/1.15+ 127.0.0.1:38812]
I0405 02:49:59.340404       1 scheduling_queue.go:895] About to try and schedule pod secrets-6795/pod-configmaps-3e204463-41b2-4895-a924-2d0b6856aa75
I0405 02:49:59.340418       1 scheduler.go:454] Attempting to schedule pod: secrets-6795/pod-configmaps-3e204463-41b2-4895-a924-2d0b6856aa75
I0405 02:49:59.340746       1 scheduler_binder.go:255] AssumePodVolumes for pod "secrets-6795/pod-configmaps-3e204463-41b2-4895-a924-2d0b6856aa75", node "e2e-test-peterhornyack-windows-node-group-rqkw"
I0405 02:49:59.340757       1 scheduler_binder.go:265] AssumePodVolumes for pod "secrets-6795/pod-configmaps-3e204463-41b2-4895-a924-2d0b6856aa75", node "e2e-test-peterhornyack-windows-node-group-rqkw": all PVCs bound and nothing to do
I0405 02:49:59.340813       1 factory.go:734] Attempting to bind pod-configmaps-3e204463-41b2-4895-a924-2d0b6856aa75 to e2e-test-peterhornyack-windows-node-group-rqkw
I0405 02:49:59.347855       1 scheduler.go:575] pod secrets-6795/pod-configmaps-3e204463-41b2-4895-a924-2d0b6856aa75 is bound successfully on node e2e-test-peterhornyack-windows-node-group-rqkw, 4 nodes evaluated, 2 nodes were found feasible
I0405 02:50:07.363022       1 wrap.go:47] GET /healthz: (100.361µs) 200 [kube-probe/1.15+ 127.0.0.1:38850]
I0405 02:50:17.362856       1 wrap.go:47] GET /healthz: (78.261µs) 200 [kube-probe/1.15+ 127.0.0.1:38888]
I0405 02:50:24.160451       1 scheduling_queue.go:895] About to try and schedule pod secrets-1708/pod-secrets-98bcb0a1-f5e6-40bb-9283-d6abb83df253
I0405 02:50:24.160465       1 scheduler.go:454] Attempting to schedule pod: secrets-1708/pod-secrets-98bcb0a1-f5e6-40bb-9283-d6abb83df253
I0405 02:50:24.160979       1 scheduler_binder.go:255] AssumePodVolumes for pod "secrets-1708/pod-secrets-98bcb0a1-f5e6-40bb-9283-d6abb83df253", node "e2e-test-peterhornyack-windows-node-group-rqkw"
I0405 02:50:24.160994       1 scheduler_binder.go:265] AssumePodVolumes for pod "secrets-1708/pod-secrets-98bcb0a1-f5e6-40bb-9283-d6abb83df253", node "e2e-test-peterhornyack-windows-node-group-rqkw": all PVCs bound and nothing to do
I0405 02:50:24.161058       1 factory.go:734] Attempting to bind pod-secrets-98bcb0a1-f5e6-40bb-9283-d6abb83df253 to e2e-test-peterhornyack-windows-node-group-rqkw
I0405 02:50:24.167288       1 scheduler.go:575] pod secrets-1708/pod-secrets-98bcb0a1-f5e6-40bb-9283-d6abb83df253 is bound successfully on node e2e-test-peterhornyack-windows-node-group-rqkw, 4 nodes evaluated, 2 nodes were found feasible
I0405 02:50:27.362487       1 wrap.go:47] GET /healthz: (75.337µs) 200 [kube-probe/1.15+ 127.0.0.1:38936]
I0405 02:50:32.571631       1 reflector.go:384] k8s.io/client-go/informers/factory.go:133: Watch close - *v1beta1.PodDisruptionBudget total 0 items received
I0405 02:50:37.362967       1 wrap.go:47] GET /healthz: (148.199µs) 200 [kube-probe/1.15+ 127.0.0.1:38970]
I0405 02:50:40.717551       1 scheduling_queue.go:895] About to try and schedule pod container-lifecycle-hook-8693/pod-handle-http-request
I0405 02:50:40.717564       1 scheduler.go:454] Attempting to schedule pod: container-lifecycle-hook-8693/pod-handle-http-request
I0405 02:50:40.718479       1 scheduler_binder.go:255] AssumePodVolumes for pod "container-lifecycle-hook-8693/pod-handle-http-request", node "e2e-test-peterhornyack-windows-node-group-rqkw"
I0405 02:50:40.718490       1 scheduler_binder.go:265] AssumePodVolumes for pod "container-lifecycle-hook-8693/pod-handle-http-request", node "e2e-test-peterhornyack-windows-node-group-rqkw": all PVCs bound and nothing to do
I0405 02:50:40.718524       1 factory.go:734] Attempting to bind pod-handle-http-request to e2e-test-peterhornyack-windows-node-group-rqkw
I0405 02:50:40.729796       1 scheduler.go:575] pod container-lifecycle-hook-8693/pod-handle-http-request is bound successfully on node e2e-test-peterhornyack-windows-node-group-rqkw, 4 nodes evaluated, 2 nodes were found feasible
I0405 02:50:42.566378       1 reflector.go:384] k8s.io/client-go/informers/factory.go:133: Watch close - *v1.PersistentVolume total 0 items received
I0405 02:50:47.362803       1 wrap.go:47] GET /healthz: (72.747µs) 200 [kube-probe/1.15+ 127.0.0.1:39002]
I0405 02:50:52.892361       1 scheduling_queue.go:895] About to try and schedule pod container-lifecycle-hook-8693/pod-with-prestop-exec-hook
I0405 02:50:52.892378       1 scheduler.go:454] Attempting to schedule pod: container-lifecycle-hook-8693/pod-with-prestop-exec-hook
I0405 02:50:52.892688       1 scheduler_binder.go:255] AssumePodVolumes for pod "container-lifecycle-hook-8693/pod-with-prestop-exec-hook", node "e2e-test-peterhornyack-windows-node-group-lkqs"
I0405 02:50:52.892698       1 scheduler_binder.go:265] AssumePodVolumes for pod "container-lifecycle-hook-8693/pod-with-prestop-exec-hook", node "e2e-test-peterhornyack-windows-node-group-lkqs": all PVCs bound and nothing to do
I0405 02:50:52.892755       1 factory.go:734] Attempting to bind pod-with-prestop-exec-hook to e2e-test-peterhornyack-windows-node-group-lkqs
I0405 02:50:52.899857       1 scheduler.go:575] pod container-lifecycle-hook-8693/pod-with-prestop-exec-hook is bound successfully on node e2e-test-peterhornyack-windows-node-group-lkqs, 4 nodes evaluated, 2 nodes were found feasible
I0405 02:50:57.362957       1 wrap.go:47] GET /healthz: (67.403µs) 200 [kube-probe/1.15+ 127.0.0.1:39036]
I0405 02:51:01.586828       1 reflector.go:384] k8s.io/client-go/informers/factory.go:133: Watch close - *v1.ReplicaSet total 19 items received
I0405 02:51:07.362913       1 wrap.go:47] GET /healthz: (76.338µs) 200 [kube-probe/1.15+ 127.0.0.1:39072]
I0405 02:51:17.362627       1 wrap.go:47] GET /healthz: (76.599µs) 200 [kube-probe/1.15+ 127.0.0.1:39108]
I0405 02:51:27.363484       1 wrap.go:47] GET /healthz: (163.395µs) 200 [kube-probe/1.15+ 127.0.0.1:39158]
I0405 02:51:33.815738       1 scheduling_queue.go:895] About to try and schedule pod kubectl-3592/redis-master-qq7pn
I0405 02:51:33.815761       1 scheduler.go:454] Attempting to schedule pod: kubectl-3592/redis-master-qq7pn
I0405 02:51:33.816281       1 scheduler_binder.go:255] AssumePodVolumes for pod "kubectl-3592/redis-master-qq7pn", node "e2e-test-peterhornyack-windows-node-group-lkqs"
I0405 02:51:33.816294       1 scheduler_binder.go:265] AssumePodVolumes for pod "kubectl-3592/redis-master-qq7pn", node "e2e-test-peterhornyack-windows-node-group-lkqs": all PVCs bound and nothing to do
I0405 02:51:33.816339       1 factory.go:734] Attempting to bind redis-master-qq7pn to e2e-test-peterhornyack-windows-node-group-lkqs
I0405 02:51:33.832114       1 scheduler.go:575] pod kubectl-3592/redis-master-qq7pn is bound successfully on node e2e-test-peterhornyack-windows-node-group-lkqs, 4 nodes evaluated, 2 nodes were found feasible
I0405 02:51:37.362942       1 wrap.go:47] GET /healthz: (81.567µs) 200 [kube-probe/1.15+ 127.0.0.1:39192]
I0405 02:51:47.362887       1 wrap.go:47] GET /healthz: (74.198µs) 200 [kube-probe/1.15+ 127.0.0.1:39226]
I0405 02:51:57.363113       1 wrap.go:47] GET /healthz: (79.407µs) 200 [kube-probe/1.15+ 127.0.0.1:39258]
I0405 02:52:07.362721       1 wrap.go:47] GET /healthz: (72.099µs) 200 [kube-probe/1.15+ 127.0.0.1:39294]
I0405 02:52:10.218961       1 scheduling_queue.go:895] About to try and schedule pod pod-network-test-643/netserver-0
I0405 02:52:10.218976       1 scheduler.go:454] Attempting to schedule pod: pod-network-test-643/netserver-0
I0405 02:52:10.219236       1 scheduler_binder.go:255] AssumePodVolumes for pod "pod-network-test-643/netserver-0", node "e2e-test-peterhornyack-windows-node-group-lkqs"
I0405 02:52:10.219259       1 scheduler_binder.go:265] AssumePodVolumes for pod "pod-network-test-643/netserver-0", node "e2e-test-peterhornyack-windows-node-group-lkqs": all PVCs bound and nothing to do
I0405 02:52:10.219311       1 factory.go:734] Attempting to bind netserver-0 to e2e-test-peterhornyack-windows-node-group-lkqs
I0405 02:52:10.226168       1 cache.go:643] Couldn't expire cache for pod pod-network-test-643/netserver-0. Binding is still in progress.
I0405 02:52:10.226602       1 scheduler.go:575] pod pod-network-test-643/netserver-0 is bound successfully on node e2e-test-peterhornyack-windows-node-group-lkqs, 4 nodes evaluated, 1 nodes were found feasible
I0405 02:52:10.265154       1 scheduling_queue.go:895] About to try and schedule pod pod-network-test-643/netserver-1
I0405 02:52:10.265182       1 scheduler.go:454] Attempting to schedule pod: pod-network-test-643/netserver-1
I0405 02:52:10.265399       1 scheduler_binder.go:255] AssumePodVolumes for pod "pod-network-test-643/netserver-1", node "e2e-test-peterhornyack-windows-node-group-rqkw"
I0405 02:52:10.265437       1 scheduler_binder.go:265] AssumePodVolumes for pod "pod-network-test-643/netserver-1", node "e2e-test-peterhornyack-windows-node-group-rqkw": all PVCs bound and nothing to do
I0405 02:52:10.265478       1 factory.go:734] Attempting to bind netserver-1 to e2e-test-peterhornyack-windows-node-group-rqkw
I0405 02:52:10.272994       1 scheduler.go:575] pod pod-network-test-643/netserver-1 is bound successfully on node e2e-test-peterhornyack-windows-node-group-rqkw, 4 nodes evaluated, 1 nodes were found feasible
I0405 02:52:17.363027       1 wrap.go:47] GET /healthz: (90.545µs) 200 [kube-probe/1.15+ 127.0.0.1:39330]
I0405 02:52:27.362730       1 wrap.go:47] GET /healthz: (77.215µs) 200 [kube-probe/1.15+ 127.0.0.1:39380]
I0405 02:52:37.366976       1 wrap.go:47] GET /healthz: (112.514µs) 200 [kube-probe/1.15+ 127.0.0.1:39414]
I0405 02:52:38.522964       1 scheduling_queue.go:895] About to try and schedule pod pod-network-test-643/test-container-pod
I0405 02:52:38.522979       1 scheduler.go:454] Attempting to schedule pod: pod-network-test-643/test-container-pod
I0405 02:52:38.523343       1 scheduler_binder.go:255] AssumePodVolumes for pod "pod-network-test-643/test-container-pod", node "e2e-test-peterhornyack-windows-node-group-lkqs"
I0405 02:52:38.523354       1 scheduler_binder.go:265] AssumePodVolumes for pod "pod-network-test-643/test-container-pod", node "e2e-test-peterhornyack-windows-node-group-lkqs": all PVCs bound and nothing to do
I0405 02:52:38.523398       1 factory.go:734] Attempting to bind test-container-pod to e2e-test-peterhornyack-windows-node-group-lkqs
I0405 02:52:38.529655       1 scheduler.go:575] pod pod-network-test-643/test-container-pod is bound successfully on node e2e-test-peterhornyack-windows-node-group-lkqs, 4 nodes evaluated, 2 nodes were found feasible
I0405 02:52:38.567998       1 scheduling_queue.go:895] About to try and schedule pod pod-network-test-643/host-test-container-pod
I0405 02:52:38.568031       1 scheduler.go:454] Attempting to schedule pod: pod-network-test-643/host-test-container-pod
I0405 02:52:38.568962       1 scheduler_binder.go:255] AssumePodVolumes for pod "pod-network-test-643/host-test-container-pod", node "e2e-test-peterhornyack-windows-node-group-lkqs"
I0405 02:52:38.568977       1 scheduler_binder.go:265] AssumePodVolumes for pod "pod-network-test-643/host-test-container-pod", node "e2e-test-peterhornyack-windows-node-group-lkqs": all PVCs bound and nothing to do
I0405 02:52:38.569029       1 factory.go:734] Attempting to bind host-test-container-pod to e2e-test-peterhornyack-windows-node-group-lkqs
I0405 02:52:38.575965       1 scheduler.go:575] pod pod-network-test-643/host-test-container-pod is bound successfully on node e2e-test-peterhornyack-windows-node-group-lkqs, 4 nodes evaluated, 2 nodes were found feasible
I0405 02:52:47.365838       1 wrap.go:47] GET /healthz: (265.341µs) 200 [kube-probe/1.15+ 127.0.0.1:39448]
I0405 02:52:57.363162       1 wrap.go:47] GET /healthz: (75.441µs) 200 [kube-probe/1.15+ 127.0.0.1:39484]
I0405 02:53:07.362778       1 wrap.go:47] GET /healthz: (78.795µs) 200 [kube-probe/1.15+ 127.0.0.1:39520]
I0405 02:53:14.115168       1 scheduling_queue.go:895] About to try and schedule pod security-context-test-356/busybox-readonly-false-7b20cb5f-e0c0-4645-af83-1b00c221ed87
I0405 02:53:14.115193       1 scheduler.go:454] Attempting to schedule pod: security-context-test-356/busybox-readonly-false-7b20cb5f-e0c0-4645-af83-1b00c221ed87
I0405 02:53:14.115504       1 scheduler_binder.go:255] AssumePodVolumes for pod "security-context-test-356/busybox-readonly-false-7b20cb5f-e0c0-4645-af83-1b00c221ed87", node "e2e-test-peterhornyack-windows-node-group-rqkw"
I0405 02:53:14.115756       1 scheduler_binder.go:265] AssumePodVolumes for pod "security-context-test-356/busybox-readonly-false-7b20cb5f-e0c0-4645-af83-1b00c221ed87", node "e2e-test-peterhornyack-windows-node-group-rqkw": all PVCs bound and nothing to do
I0405 02:53:14.115815       1 factory.go:734] Attempting to bind busybox-readonly-false-7b20cb5f-e0c0-4645-af83-1b00c221ed87 to e2e-test-peterhornyack-windows-node-group-rqkw
I0405 02:53:14.124289       1 scheduler.go:575] pod security-context-test-356/busybox-readonly-false-7b20cb5f-e0c0-4645-af83-1b00c221ed87 is bound successfully on node e2e-test-peterhornyack-windows-node-group-rqkw, 4 nodes evaluated, 2 nodes were found feasible
I0405 02:53:17.363068       1 wrap.go:47] GET /healthz: (77.429µs) 200 [kube-probe/1.15+ 127.0.0.1:39556]
I0405 02:53:27.363247       1 wrap.go:47] GET /healthz: (72.285µs) 200 [kube-probe/1.15+ 127.0.0.1:39604]
I0405 02:53:30.338627       1 scheduling_queue.go:895] About to try and schedule pod projected-2471/annotationupdate13e44177-264a-48d6-b182-e2a78a75572c
I0405 02:53:30.338644       1 scheduler.go:454] Attempting to schedule pod: projected-2471/annotationupdate13e44177-264a-48d6-b182-e2a78a75572c
I0405 02:53:30.339020       1 scheduler_binder.go:255] AssumePodVolumes for pod "projected-2471/annotationupdate13e44177-264a-48d6-b182-e2a78a75572c", node "e2e-test-peterhornyack-windows-node-group-rqkw"
I0405 02:53:30.339036       1 scheduler_binder.go:265] AssumePodVolumes for pod "projected-2471/annotationupdate13e44177-264a-48d6-b182-e2a78a75572c", node "e2e-test-peterhornyack-windows-node-group-rqkw": all PVCs bound and nothing to do
I0405 02:53:30.339072       1 factory.go:734] Attempting to bind annotationupdate13e44177-264a-48d6-b182-e2a78a75572c to e2e-test-peterhornyack-windows-node-group-rqkw
I0405 02:53:30.353787       1 scheduler.go:575] pod projected-2471/annotationupdate13e44177-264a-48d6-b182-e2a78a75572c is bound successfully on node e2e-test-peterhornyack-windows-node-group-rqkw, 4 nodes evaluated, 2 nodes were found feasible
I0405 02:53:37.363011       1 wrap.go:47] GET /healthz: (110.046µs) 200 [kube-probe/1.15+ 127.0.0.1:39638]
I0405 02:53:47.362990       1 wrap.go:47] GET /healthz: (123.128µs) 200 [kube-probe/1.15+ 127.0.0.1:39670]
I0405 02:53:57.363757       1 wrap.go:47] GET /healthz: (85.962µs) 200 [kube-probe/1.15+ 127.0.0.1:39704]
I0405 02:54:05.319535       1 scheduling_queue.go:895] About to try and schedule pod downward-api-6992/downward-api-52fc7034-775e-4f1a-84fd-f03c9757d981
I0405 02:54:05.319550       1 scheduler.go:454] Attempting to schedule pod: downward-api-6992/downward-api-52fc7034-775e-4f1a-84fd-f03c9757d981
I0405 02:54:05.321300       1 scheduler_binder.go:255] AssumePodVolumes for pod "downward-api-6992/downward-api-52fc7034-775e-4f1a-84fd-f03c9757d981", node "e2e-test-peterhornyack-windows-node-group-rqkw"
I0405 02:54:05.321316       1 scheduler_binder.go:265] AssumePodVolumes for pod "downward-api-6992/downward-api-52fc7034-775e-4f1a-84fd-f03c9757d981", node "e2e-test-peterhornyack-windows-node-group-rqkw": all PVCs bound and nothing to do
I0405 02:54:05.321383       1 factory.go:734] Attempting to bind downward-api-52fc7034-775e-4f1a-84fd-f03c9757d981 to e2e-test-peterhornyack-windows-node-group-rqkw
I0405 02:54:05.329474       1 scheduler.go:575] pod downward-api-6992/downward-api-52fc7034-775e-4f1a-84fd-f03c9757d981 is bound successfully on node e2e-test-peterhornyack-windows-node-group-rqkw, 4 nodes evaluated, 2 nodes were found feasible
I0405 02:54:07.362679       1 wrap.go:47] GET /healthz: (52.684µs) 200 [kube-probe/1.15+ 127.0.0.1:39742]
I0405 02:54:17.363824       1 wrap.go:47] GET /healthz: (73.481µs) 200 [kube-probe/1.15+ 127.0.0.1:39778]
I0405 02:54:21.838250       1 scheduling_queue.go:895] About to try and schedule pod projected-8087/pod-projected-configmaps-80a9c554-68f4-4804-9f9a-b8f13a9b2ee7
I0405 02:54:21.838263       1 scheduler.go:454] Attempting to schedule pod: projected-8087/pod-projected-configmaps-80a9c554-68f4-4804-9f9a-b8f13a9b2ee7
I0405 02:54:21.840309       1 scheduler_binder.go:255] AssumePodVolumes for pod "projected-8087/pod-projected-configmaps-80a9c554-68f4-4804-9f9a-b8f13a9b2ee7", node "e2e-test-peterhornyack-windows-node-group-rqkw"
I0405 02:54:21.840324       1 scheduler_binder.go:265] AssumePodVolumes for pod "projected-8087/pod-projected-configmaps-80a9c554-68f4-4804-9f9a-b8f13a9b2ee7", node "e2e-test-peterhornyack-windows-node-group-rqkw": all PVCs bound and nothing to do
I0405 02:54:21.840390       1 factory.go:734] Attempting to bind pod-projected-configmaps-80a9c554-68f4-4804-9f9a-b8f13a9b2ee7 to e2e-test-peterhornyack-windows-node-group-rqkw
I0405 02:54:21.849446       1 scheduler.go:575] pod projected-8087/pod-projected-configmaps-80a9c554-68f4-4804-9f9a-b8f13a9b2ee7 is bound successfully on node e2e-test-peterhornyack-windows-node-group-rqkw, 4 nodes evaluated, 2 nodes were found feasible
I0405 02:54:27.363094       1 wrap.go:47] GET /healthz: (68.442µs) 200 [kube-probe/1.15+ 127.0.0.1:39826]
I0405 02:54:27.572196       1 reflector.go:384] k8s.io/kubernetes/cmd/kube-scheduler/app/server.go:223: Watch close - *v1.Pod total 170 items received
I0405 02:54:37.370103       1 wrap.go:47] GET /healthz: (2.489978ms) 200 [kube-probe/1.15+ 127.0.0.1:39860]
I0405 02:54:44.418359       1 scheduling_queue.go:895] About to try and schedule pod projected-6067/pod-projected-configmaps-558e6a6e-566d-4fc3-bd18-bc633c87ba41
I0405 02:54:44.418385       1 scheduler.go:454] Attempting to schedule pod: projected-6067/pod-projected-configmaps-558e6a6e-566d-4fc3-bd18-bc633c87ba41
I0405 02:54:44.418959       1 scheduler_binder.go:255] AssumePodVolumes for pod "projected-6067/pod-projected-configmaps-558e6a6e-566d-4fc3-bd18-bc633c87ba41", node "e2e-test-peterhornyack-windows-node-group-rqkw"
I0405 02:54:44.418973       1 scheduler_binder.go:265] AssumePodVolumes for pod "projected-6067/pod-projected-configmaps-558e6a6e-566d-4fc3-bd18-bc633c87ba41", node "e2e-test-peterhornyack-windows-node-group-rqkw": all PVCs bound and nothing to do
I0405 02:54:44.419031       1 factory.go:734] Attempting to bind pod-projected-configmaps-558e6a6e-566d-4fc3-bd18-bc633c87ba41 to e2e-test-peterhornyack-windows-node-group-rqkw
I0405 02:54:44.432284       1 scheduler.go:575] pod projected-6067/pod-projected-configmaps-558e6a6e-566d-4fc3-bd18-bc633c87ba41 is bound successfully on node e2e-test-peterhornyack-windows-node-group-rqkw, 4 nodes evaluated, 2 nodes were found feasible
I0405 02:54:46.573914       1 reflector.go:384] k8s.io/client-go/informers/factory.go:133: Watch close - *v1.Node total 42 items received
I0405 02:54:47.363108       1 wrap.go:47] GET /healthz: (82.253µs) 200 [kube-probe/1.15+ 127.0.0.1:39892]
I0405 02:54:57.362944       1 wrap.go:47] GET /healthz: (93.178µs) 200 [kube-probe/1.15+ 127.0.0.1:39924]
I0405 02:55:00.861888       1 scheduling_queue.go:895] About to try and schedule pod projected-8493/pod-projected-secrets-bab0353e-a725-4e70-adfe-2bc86c0d5c9f
I0405 02:55:00.861903       1 scheduler.go:454] Attempting to schedule pod: projected-8493/pod-projected-secrets-bab0353e-a725-4e70-adfe-2bc86c0d5c9f
I0405 02:55:00.863326       1 scheduler_binder.go:255] AssumePodVolumes for pod "projected-8493/pod-projected-secrets-bab0353e-a725-4e70-adfe-2bc86c0d5c9f", node "e2e-test-peterhornyack-windows-node-group-rqkw"
I0405 02:55:00.863342       1 scheduler_binder.go:265] AssumePodVolumes for pod "projected-8493/pod-projected-secrets-bab0353e-a725-4e70-adfe-2bc86c0d5c9f", node "e2e-test-peterhornyack-windows-node-group-rqkw": all PVCs bound and nothing to do
I0405 02:55:00.863407       1 factory.go:734] Attempting to bind pod-projected-secrets-bab0353e-a725-4e70-adfe-2bc86c0d5c9f to e2e-test-peterhornyack-windows-node-group-rqkw
I0405 02:55:00.870464       1 scheduler.go:575] pod projected-8493/pod-projected-secrets-bab0353e-a725-4e70-adfe-2bc86c0d5c9f is bound successfully on node e2e-test-peterhornyack-windows-node-group-rqkw, 4 nodes evaluated, 2 nodes were found feasible
I0405 02:55:04.598970       1 reflector.go:384] k8s.io/client-go/informers/factory.go:133: Watch close - *v1.StorageClass total 0 items received
I0405 02:55:05.582073       1 reflector.go:384] k8s.io/client-go/informers/factory.go:133: Watch close - *v1.Service total 4 items received
I0405 02:55:07.363284       1 wrap.go:47] GET /healthz: (79.753µs) 200 [kube-probe/1.15+ 127.0.0.1:39960]
I0405 02:55:17.363141       1 wrap.go:47] GET /healthz: (78.236µs) 200 [kube-probe/1.15+ 127.0.0.1:39998]
I0405 02:55:25.446775       1 scheduling_queue.go:895] About to try and schedule pod projected-320/downwardapi-volume-c6c39edd-1ee9-4dc0-9836-857e2ef8a0dd
I0405 02:55:25.446789       1 scheduler.go:454] Attempting to schedule pod: projected-320/downwardapi-volume-c6c39edd-1ee9-4dc0-9836-857e2ef8a0dd
I0405 02:55:25.447167       1 scheduler_binder.go:255] AssumePodVolumes for pod "projected-320/downwardapi-volume-c6c39edd-1ee9-4dc0-9836-857e2ef8a0dd", node "e2e-test-peterhornyack-windows-node-group-rqkw"
I0405 02:55:25.447198       1 scheduler_binder.go:265] AssumePodVolumes for pod "projected-320/downwardapi-volume-c6c39edd-1ee9-4dc0-9836-857e2ef8a0dd", node "e2e-test-peterhornyack-windows-node-group-rqkw": all PVCs bound and nothing to do
I0405 02:55:25.447245       1 factory.go:734] Attempting to bind downwardapi-volume-c6c39edd-1ee9-4dc0-9836-857e2ef8a0dd to e2e-test-peterhornyack-windows-node-group-rqkw
I0405 02:55:25.454445       1 scheduler.go:575] pod projected-320/downwardapi-volume-c6c39edd-1ee9-4dc0-9836-857e2ef8a0dd is bound successfully on node e2e-test-peterhornyack-windows-node-group-rqkw, 4 nodes evaluated, 2 nodes were found feasible
I0405 02:55:27.362867       1 wrap.go:47] GET /healthz: (72.821µs) 200 [kube-probe/1.15+ 127.0.0.1:40046]
I0405 02:55:37.362898       1 wrap.go:47] GET /healthz: (72.595µs) 200 [kube-probe/1.15+ 127.0.0.1:40082]
I0405 02:55:41.888973       1 scheduling_queue.go:895] About to try and schedule pod projected-1960/downwardapi-volume-4e77a9a1-4f35-402b-ada5-4aa8ce9317d1
I0405 02:55:41.888992       1 scheduler.go:454] Attempting to schedule pod: projected-1960/downwardapi-volume-4e77a9a1-4f35-402b-ada5-4aa8ce9317d1
I0405 02:55:41.890052       1 scheduler_binder.go:255] AssumePodVolumes for pod "projected-1960/downwardapi-volume-4e77a9a1-4f35-402b-ada5-4aa8ce9317d1", node "e2e-test-peterhornyack-windows-node-group-rqkw"
I0405 02:55:41.890069       1 scheduler_binder.go:265] AssumePodVolumes for pod "projected-1960/downwardapi-volume-4e77a9a1-4f35-402b-ada5-4aa8ce9317d1", node "e2e-test-peterhornyack-windows-node-group-rqkw": all PVCs bound and nothing to do
I0405 02:55:41.890132       1 factory.go:734] Attempting to bind downwardapi-volume-4e77a9a1-4f35-402b-ada5-4aa8ce9317d1 to e2e-test-peterhornyack-windows-node-group-rqkw
I0405 02:55:41.900165       1 scheduler.go:575] pod projected-1960/downwardapi-volume-4e77a9a1-4f35-402b-ada5-4aa8ce9317d1 is bound successfully on node e2e-test-peterhornyack-windows-node-group-rqkw, 4 nodes evaluated, 2 nodes were found feasible
I0405 02:55:47.362693       1 wrap.go:47] GET /healthz: (74.016µs) 200 [kube-probe/1.15+ 127.0.0.1:40114]
I0405 02:55:57.362745       1 wrap.go:47] GET /healthz: (65.94µs) 200 [kube-probe/1.15+ 127.0.0.1:40146]
I0405 02:56:06.680811       1 scheduling_queue.go:895] About to try and schedule pod proxy-1881/proxy-service-lzxzg-l9t4g
I0405 02:56:06.680932       1 scheduler.go:454] Attempting to schedule pod: proxy-1881/proxy-service-lzxzg-l9t4g
I0405 02:56:06.681455       1 scheduler_binder.go:255] AssumePodVolumes for pod "proxy-1881/proxy-service-lzxzg-l9t4g", node "e2e-test-peterhornyack-windows-node-group-lkqs"
I0405 02:56:06.681466       1 scheduler_binder.go:265] AssumePodVolumes for pod "proxy-1881/proxy-service-lzxzg-l9t4g", node "e2e-test-peterhornyack-windows-node-group-lkqs": all PVCs bound and nothing to do
I0405 02:56:06.681532       1 factory.go:734] Attempting to bind proxy-service-lzxzg-l9t4g to e2e-test-peterhornyack-windows-node-group-lkqs
I0405 02:56:06.708173       1 scheduler.go:575] pod proxy-1881/proxy-service-lzxzg-l9t4g is bound successfully on node e2e-test-peterhornyack-windows-node-group-lkqs, 4 nodes evaluated, 2 nodes were found feasible
I0405 02:56:07.363538       1 wrap.go:47] GET /healthz: (187.293µs) 200 [kube-probe/1.15+ 127.0.0.1:40184]
I0405 02:56:08.574143       1 reflector.go:384] k8s.io/client-go/informers/factory.go:133: Watch close - *v1beta1.PodDisruptionBudget total 0 items received
I0405 02:56:17.363094       1 wrap.go:47] GET /healthz: (81.939µs) 200 [kube-probe/1.15+ 127.0.0.1:40220]
I0405 02:56:27.363237       1 wrap.go:47] GET /healthz: (76.137µs) 200 [kube-probe/1.15+ 127.0.0.1:40316]
I0405 02:56:37.363244       1 wrap.go:47] GET /healthz: (78.998µs) 200 [kube-probe/1.15+ 127.0.0.1:40390]
I0405 02:56:40.515436       1 scheduling_queue.go:895] About to try and schedule pod container-lifecycle-hook-8239/pod-handle-http-request
I0405 02:56:40.515450       1 scheduler.go:454] Attempting to schedule pod: container-lifecycle-hook-8239/pod-handle-http-request
I0405 02:56:40.516000       1 scheduler_binder.go:255] AssumePodVolumes for pod "container-lifecycle-hook-8239/pod-handle-http-request", node "e2e-test-peterhornyack-windows-node-group-rqkw"
I0405 02:56:40.516012       1 scheduler_binder.go:265] AssumePodVolumes for pod "container-lifecycle-hook-8239/pod-handle-http-request", node "e2e-test-peterhornyack-windows-node-group-rqkw": all PVCs bound and nothing to do
I0405 02:56:40.516125       1 factory.go:734] Attempting to bind pod-handle-http-request to e2e-test-peterhornyack-windows-node-group-rqkw
I0405 02:56:40.522784       1 scheduler.go:575] pod container-lifecycle-hook-8239/pod-handle-http-request is bound successfully on node e2e-test-peterhornyack-windows-node-group-rqkw, 4 nodes evaluated, 2 nodes were found feasible
I0405 02:56:45.589054       1 reflector.go:384] k8s.io/client-go/informers/factory.go:133: Watch close - *v1.ReplicaSet total 0 items received
I0405 02:56:47.362664       1 wrap.go:47] GET /healthz: (78.426µs) 200 [kube-probe/1.15+ 127.0.0.1:40422]
I0405 02:56:48.688570       1 scheduling_queue.go:895] About to try and schedule pod container-lifecycle-hook-8239/pod-with-poststart-exec-hook
I0405 02:56:48.688595       1 scheduler.go:454] Attempting to schedule pod: container-lifecycle-hook-8239/pod-with-poststart-exec-hook
I0405 02:56:48.688877       1 scheduler_binder.go:255] AssumePodVolumes for pod "container-lifecycle-hook-8239/pod-with-poststart-exec-hook", node "e2e-test-peterhornyack-windows-node-group-lkqs"
I0405 02:56:48.688887       1 scheduler_binder.go:265] AssumePodVolumes for pod "container-lifecycle-hook-8239/pod-with-poststart-exec-hook", node "e2e-test-peterhornyack-windows-node-group-lkqs": all PVCs bound and nothing to do
I0405 02:56:48.688956       1 factory.go:734] Attempting to bind pod-with-poststart-exec-hook to e2e-test-peterhornyack-windows-node-group-lkqs
I0405 02:56:48.695019       1 scheduler.go:575] pod container-lifecycle-hook-8239/pod-with-poststart-exec-hook is bound successfully on node e2e-test-peterhornyack-windows-node-group-lkqs, 4 nodes evaluated, 2 nodes were found feasible
I0405 02:56:57.362899       1 wrap.go:47] GET /healthz: (76.399µs) 200 [kube-probe/1.15+ 127.0.0.1:40454]
I0405 02:57:07.363002       1 wrap.go:47] GET /healthz: (111.175µs) 200 [kube-probe/1.15+ 127.0.0.1:40492]
I0405 02:57:17.363891       1 wrap.go:47] GET /healthz: (77.493µs) 200 [kube-probe/1.15+ 127.0.0.1:40528]
I0405 02:57:27.095359       1 scheduling_queue.go:895] About to try and schedule pod gc-2888/simpletest.deployment-6b769858bc-kbmg6
I0405 02:57:27.095376       1 scheduler.go:454] Attempting to schedule pod: gc-2888/simpletest.deployment-6b769858bc-kbmg6
I0405 02:57:27.095732       1 scheduler_binder.go:255] AssumePodVolumes for pod "gc-2888/simpletest.deployment-6b769858bc-kbmg6", node "e2e-test-peterhornyack-windows-node-group-lkqs"
I0405 02:57:27.095744       1 scheduler_binder.go:265] AssumePodVolumes for pod "gc-2888/simpletest.deployment-6b769858bc-kbmg6", node "e2e-test-peterhornyack-windows-node-group-lkqs": all PVCs bound and nothing to do
I0405 02:57:27.097993       1 factory.go:734] Attempting to bind simpletest.deployment-6b769858bc-kbmg6 to e2e-test-peterhornyack-windows-node-group-lkqs
I0405 02:57:27.116189       1 scheduler.go:575] pod gc-2888/simpletest.deployment-6b769858bc-kbmg6 is bound successfully on node e2e-test-peterhornyack-windows-node-group-lkqs, 4 nodes evaluated, 2 nodes were found feasible
I0405 02:57:27.117845       1 scheduling_queue.go:895] About to try and schedule pod gc-2888/simpletest.deployment-6b769858bc-4cwrx
I0405 02:57:27.117866       1 scheduler.go:454] Attempting to schedule pod: gc-2888/simpletest.deployment-6b769858bc-4cwrx
I0405 02:57:27.118172       1 scheduler_binder.go:255] AssumePodVolumes for pod "gc-2888/simpletest.deployment-6b769858bc-4cwrx", node "e2e-test-peterhornyack-windows-node-group-lkqs"
I0405 02:57:27.118182       1 scheduler_binder.go:265] AssumePodVolumes for pod "gc-2888/simpletest.deployment-6b769858bc-4cwrx", node "e2e-test-peterhornyack-windows-node-group-lkqs": all PVCs bound and nothing to do
I0405 02:57:27.118217       1 factory.go:734] Attempting to bind simpletest.deployment-6b769858bc-4cwrx to e2e-test-peterhornyack-windows-node-group-lkqs
I0405 02:57:27.149533       1 scheduler.go:575] pod gc-2888/simpletest.deployment-6b769858bc-4cwrx is bound successfully on node e2e-test-peterhornyack-windows-node-group-lkqs, 4 nodes evaluated, 2 nodes were found feasible
I0405 02:57:27.362846       1 wrap.go:47] GET /healthz: (86.943µs) 200 [kube-probe/1.15+ 127.0.0.1:40580]
I0405 02:57:34.568601       1 reflector.go:384] k8s.io/client-go/informers/factory.go:133: Watch close - *v1.PersistentVolume total 0 items received
I0405 02:57:36.111850       1 scheduling_queue.go:895] About to try and schedule pod replication-controller-9289/my-hostname-basic-5a45c195-77f5-48db-bc7f-e78a31eba9d9-gz7q4
I0405 02:57:36.111863       1 scheduler.go:454] Attempting to schedule pod: replication-controller-9289/my-hostname-basic-5a45c195-77f5-48db-bc7f-e78a31eba9d9-gz7q4
I0405 02:57:36.113222       1 scheduler_binder.go:255] AssumePodVolumes for pod "replication-controller-9289/my-hostname-basic-5a45c195-77f5-48db-bc7f-e78a31eba9d9-gz7q4", node "e2e-test-peterhornyack-windows-node-group-lkqs"
I0405 02:57:36.113236       1 scheduler_binder.go:265] AssumePodVolumes for pod "replication-controller-9289/my-hostname-basic-5a45c195-77f5-48db-bc7f-e78a31eba9d9-gz7q4", node "e2e-test-peterhornyack-windows-node-group-lkqs": all PVCs bound and nothing to do
I0405 02:57:36.114911       1 factory.go:734] Attempting to bind my-hostname-basic-5a45c195-77f5-48db-bc7f-e78a31eba9d9-gz7q4 to e2e-test-peterhornyack-windows-node-group-lkqs
I0405 02:57:36.132085       1 scheduler.go:575] pod replication-controller-9289/my-hostname-basic-5a45c195-77f5-48db-bc7f-e78a31eba9d9-gz7q4 is bound successfully on node e2e-test-peterhornyack-windows-node-group-lkqs, 4 nodes evaluated, 2 nodes were found feasible
I0405 02:57:36.593275       1 reflector.go:384] k8s.io/client-go/informers/factory.go:133: Watch close - *v1.ReplicationController total 14 items received
I0405 02:57:37.362910       1 wrap.go:47] GET /healthz: (82.699µs) 200 [kube-probe/1.15+ 127.0.0.1:40616]
I0405 02:57:47.362965       1 wrap.go:47] GET /healthz: (77.819µs) 200 [kube-probe/1.15+ 127.0.0.1:40652]
I0405 02:57:57.363751       1 wrap.go:47] GET /healthz: (79.843µs) 200 [kube-probe/1.15+ 127.0.0.1:40686]
I0405 02:57:57.415146       1 scheduling_queue.go:895] About to try and schedule pod configmap-914/pod-configmaps-376cd725-f8aa-428b-a50c-f3428a3a45d3
I0405 02:57:57.415160       1 scheduler.go:454] Attempting to schedule pod: configmap-914/pod-configmaps-376cd725-f8aa-428b-a50c-f3428a3a45d3
I0405 02:57:57.415413       1 scheduler_binder.go:255] AssumePodVolumes for pod "configmap-914/pod-configmaps-376cd725-f8aa-428b-a50c-f3428a3a45d3", node "e2e-test-peterhornyack-windows-node-group-rqkw"
I0405 02:57:57.415424       1 scheduler_binder.go:265] AssumePodVolumes for pod "configmap-914/pod-configmaps-376cd725-f8aa-428b-a50c-f3428a3a45d3", node "e2e-test-peterhornyack-windows-node-group-rqkw": all PVCs bound and nothing to do
I0405 02:57:57.415462       1 factory.go:734] Attempting to bind pod-configmaps-376cd725-f8aa-428b-a50c-f3428a3a45d3 to e2e-test-peterhornyack-windows-node-group-rqkw
I0405 02:57:57.425673       1 scheduler.go:575] pod configmap-914/pod-configmaps-376cd725-f8aa-428b-a50c-f3428a3a45d3 is bound successfully on node e2e-test-peterhornyack-windows-node-group-rqkw, 4 nodes evaluated, 2 nodes were found feasible
I0405 02:58:07.362757       1 wrap.go:47] GET /healthz: (76.253µs) 200 [kube-probe/1.15+ 127.0.0.1:40722]
I0405 02:58:13.854551       1 scheduling_queue.go:895] About to try and schedule pod downward-api-5915/downwardapi-volume-b06fe892-bda3-4331-93b4-b5cd410c2727
I0405 02:58:13.854565       1 scheduler.go:454] Attempting to schedule pod: downward-api-5915/downwardapi-volume-b06fe892-bda3-4331-93b4-b5cd410c2727
I0405 02:58:13.855207       1 scheduler_binder.go:255] AssumePodVolumes for pod "downward-api-5915/downwardapi-volume-b06fe892-bda3-4331-93b4-b5cd410c2727", node "e2e-test-peterhornyack-windows-node-group-rqkw"
I0405 02:58:13.855221       1 scheduler_binder.go:265] AssumePodVolumes for pod "downward-api-5915/downwardapi-volume-b06fe892-bda3-4331-93b4-b5cd410c2727", node "e2e-test-peterhornyack-windows-node-group-rqkw": all PVCs bound and nothing to do
I0405 02:58:13.855269       1 factory.go:734] Attempting to bind downwardapi-volume-b06fe892-bda3-4331-93b4-b5cd410c2727 to e2e-test-peterhornyack-windows-node-group-rqkw
I0405 02:58:13.862035       1 scheduler.go:575] pod downward-api-5915/downwardapi-volume-b06fe892-bda3-4331-93b4-b5cd410c2727 is bound successfully on node e2e-test-peterhornyack-windows-node-group-rqkw, 4 nodes evaluated, 2 nodes were found feasible
I0405 02:58:17.362563       1 wrap.go:47] GET /healthz: (53.412µs) 200 [kube-probe/1.15+ 127.0.0.1:40758]
I0405 02:58:27.362738       1 wrap.go:47] GET /healthz: (84.442µs) 200 [kube-probe/1.15+ 127.0.0.1:40806]
I0405 02:58:30.409411       1 scheduling_queue.go:895] About to try and schedule pod dns-710/dns-test-0904be2c-0888-4ddb-8e6d-853625c27164
I0405 02:58:30.409438       1 scheduler.go:454] Attempting to schedule pod: dns-710/dns-test-0904be2c-0888-4ddb-8e6d-853625c27164
I0405 02:58:30.413286       1 scheduler_binder.go:255] AssumePodVolumes for pod "dns-710/dns-test-0904be2c-0888-4ddb-8e6d-853625c27164", node "e2e-test-peterhornyack-windows-node-group-lkqs"
I0405 02:58:30.413319       1 scheduler_binder.go:265] AssumePodVolumes for pod "dns-710/dns-test-0904be2c-0888-4ddb-8e6d-853625c27164", node "e2e-test-peterhornyack-windows-node-group-lkqs": all PVCs bound and nothing to do
I0405 02:58:30.413375       1 factory.go:734] Attempting to bind dns-test-0904be2c-0888-4ddb-8e6d-853625c27164 to e2e-test-peterhornyack-windows-node-group-lkqs
I0405 02:58:30.423865       1 scheduler.go:575] pod dns-710/dns-test-0904be2c-0888-4ddb-8e6d-853625c27164 is bound successfully on node e2e-test-peterhornyack-windows-node-group-lkqs, 4 nodes evaluated, 2 nodes were found feasible
I0405 02:58:37.362531       1 wrap.go:47] GET /healthz: (75.558µs) 200 [kube-probe/1.15+ 127.0.0.1:40844]
I0405 02:58:38.596500       1 reflector.go:384] k8s.io/client-go/informers/factory.go:133: Watch close - *v1.StatefulSet total 0 items received
I0405 02:58:47.362966       1 wrap.go:47] GET /healthz: (99.89µs) 200 [kube-probe/1.15+ 127.0.0.1:40874]
I0405 02:58:57.362726       1 wrap.go:47] GET /healthz: (61.352µs) 200 [kube-probe/1.15+ 127.0.0.1:40906]
I0405 02:59:07.363027       1 wrap.go:47] GET /healthz: (89.967µs) 200 [kube-probe/1.15+ 127.0.0.1:40946]
I0405 02:59:07.576814       1 reflector.go:384] k8s.io/client-go/informers/factory.go:133: Watch close - *v1.PersistentVolumeClaim total 0 items received
I0405 02:59:15.978405       1 scheduling_queue.go:895] About to try and schedule pod projected-9917/labelsupdatec20128ed-ca1a-4834-bfde-46e53732b842
I0405 02:59:15.978421       1 scheduler.go:454] Attempting to schedule pod: projected-9917/labelsupdatec20128ed-ca1a-4834-bfde-46e53732b842
I0405 02:59:15.978788       1 scheduler_binder.go:255] AssumePodVolumes for pod "projected-9917/labelsupdatec20128ed-ca1a-4834-bfde-46e53732b842", node "e2e-test-peterhornyack-windows-node-group-rqkw"
I0405 02:59:15.978800       1 scheduler_binder.go:265] AssumePodVolumes for pod "projected-9917/labelsupdatec20128ed-ca1a-4834-bfde-46e53732b842", node "e2e-test-peterhornyack-windows-node-group-rqkw": all PVCs bound and nothing to do
I0405 02:59:15.978860       1 factory.go:734] Attempting to bind labelsupdatec20128ed-ca1a-4834-bfde-46e53732b842 to e2e-test-peterhornyack-windows-node-group-rqkw
I0405 02:59:15.985772       1 scheduler.go:575] pod projected-9917/labelsupdatec20128ed-ca1a-4834-bfde-46e53732b842 is bound successfully on node e2e-test-peterhornyack-windows-node-group-rqkw, 4 nodes evaluated, 2 nodes were found feasible
I0405 02:59:17.362958       1 wrap.go:47] GET /healthz: (61.386µs) 200 [kube-probe/1.15+ 127.0.0.1:40982]
I0405 02:59:27.362954       1 wrap.go:47] GET /healthz: (63.461µs) 200 [kube-probe/1.15+ 127.0.0.1:41030]
I0405 02:59:37.363032       1 wrap.go:47] GET /healthz: (92.65µs) 200 [kube-probe/1.15+ 127.0.0.1:41064]
I0405 02:59:47.363047       1 wrap.go:47] GET /healthz: (84.215µs) 200 [kube-probe/1.15+ 127.0.0.1:41096]
I0405 02:59:50.880449       1 scheduling_queue.go:895] About to try and schedule pod container-probe-1380/liveness-http
I0405 02:59:50.880463       1 scheduler.go:454] Attempting to schedule pod: container-probe-1380/liveness-http
I0405 02:59:50.880853       1 scheduler_binder.go:255] AssumePodVolumes for pod "container-probe-1380/liveness-http", node "e2e-test-peterhornyack-windows-node-group-lkqs"
I0405 02:59:50.880864       1 scheduler_binder.go:265] AssumePodVolumes for pod "container-probe-1380/liveness-http", node "e2e-test-peterhornyack-windows-node-group-lkqs": all PVCs bound and nothing to do
I0405 02:59:50.880916       1 factory.go:734] Attempting to bind liveness-http to e2e-test-peterhornyack-windows-node-group-lkqs
I0405 02:59:50.887124       1 scheduler.go:575] pod container-probe-1380/liveness-http is bound successfully on node e2e-test-peterhornyack-windows-node-group-lkqs, 4 nodes evaluated, 2 nodes were found feasible
I0405 02:59:57.362576       1 wrap.go:47] GET /healthz: (72.293µs) 200 [kube-probe/1.15+ 127.0.0.1:41128]
I0405 03:00:07.362793       1 wrap.go:47] GET /healthz: (62.832µs) 200 [kube-probe/1.15+ 127.0.0.1:41166]
I0405 03:00:17.363007       1 wrap.go:47] GET /healthz: (90.698µs) 200 [kube-probe/1.15+ 127.0.0.1:41204]
I0405 03:00:27.363117       1 wrap.go:47] GET /healthz: (86.069µs) 200 [kube-probe/1.15+ 127.0.0.1:41248]
I0405 03:00:37.362716       1 wrap.go:47] GET /healthz: (81.824µs) 200 [kube-probe/1.15+ 127.0.0.1:41286]
I0405 03:00:47.363077       1 wrap.go:47] GET /healthz: (77.134µs) 200 [kube-probe/1.15+ 127.0.0.1:41318]
I0405 03:00:57.364279       1 wrap.go:47] GET /healthz: (69.78µs) 200 [kube-probe/1.15+ 127.0.0.1:41350]
I0405 03:01:07.363121       1 wrap.go:47] GET /healthz: (92.595µs) 200 [kube-probe/1.15+ 127.0.0.1:41386]
I0405 03:01:17.363179       1 wrap.go:47] GET /healthz: (83.981µs) 200 [kube-probe/1.15+ 127.0.0.1:41422]
I0405 03:01:27.363516       1 wrap.go:47] GET /healthz: (201.891µs) 200 [kube-probe/1.15+ 127.0.0.1:41466]
I0405 03:01:37.364319       1 wrap.go:47] GET /healthz: (103.332µs) 200 [kube-probe/1.15+ 127.0.0.1:41508]
I0405 03:01:47.364323       1 wrap.go:47] GET /healthz: (81.552µs) 200 [kube-probe/1.15+ 127.0.0.1:41540]
I0405 03:01:57.362676       1 wrap.go:47] GET /healthz: (74.249µs) 200 [kube-probe/1.15+ 127.0.0.1:41572]
I0405 03:02:07.364265       1 wrap.go:47] GET /healthz: (68.339µs) 200 [kube-probe/1.15+ 127.0.0.1:41608]
I0405 03:02:17.363067       1 wrap.go:47] GET /healthz: (71.354µs) 200 [kube-probe/1.15+ 127.0.0.1:41644]
I0405 03:02:22.574738       1 reflector.go:384] k8s.io/kubernetes/cmd/kube-scheduler/app/server.go:223: Watch close - *v1.Pod total 93 items received
I0405 03:02:27.363083       1 wrap.go:47] GET /healthz: (80.281µs) 200 [kube-probe/1.15+ 127.0.0.1:41692]
I0405 03:02:36.162570       1 scheduling_queue.go:895] About to try and schedule pod init-container-4333/pod-init-ee50e249-1b87-4e3f-b835-3cb724b21147
I0405 03:02:36.162583       1 scheduler.go:454] Attempting to schedule pod: init-container-4333/pod-init-ee50e249-1b87-4e3f-b835-3cb724b21147
I0405 03:02:36.165112       1 scheduler_binder.go:255] AssumePodVolumes for pod "init-container-4333/pod-init-ee50e249-1b87-4e3f-b835-3cb724b21147", node "e2e-test-peterhornyack-windows-node-group-rqkw"
I0405 03:02:36.165126       1 scheduler_binder.go:265] AssumePodVolumes for pod "init-container-4333/pod-init-ee50e249-1b87-4e3f-b835-3cb724b21147", node "e2e-test-peterhornyack-windows-node-group-rqkw": all PVCs bound and nothing to do
I0405 03:02:36.165523       1 factory.go:734] Attempting to bind pod-init-ee50e249-1b87-4e3f-b835-3cb724b21147 to e2e-test-peterhornyack-windows-node-group-rqkw
I0405 03:02:36.171061       1 scheduler.go:575] pod init-container-4333/pod-init-ee50e249-1b87-4e3f-b835-3cb724b21147 is bound successfully on node e2e-test-peterhornyack-windows-node-group-rqkw, 4 nodes evaluated, 2 nodes were found feasible
I0405 03:02:37.371380       1 wrap.go:47] GET /healthz: (87.891µs) 200 [kube-probe/1.15+ 127.0.0.1:41726]
I0405 03:02:47.363173       1 wrap.go:47] GET /healthz: (76.806µs) 200 [kube-probe/1.15+ 127.0.0.1:41760]
I0405 03:02:57.362808       1 wrap.go:47] GET /healthz: (95.304µs) 200 [kube-probe/1.15+ 127.0.0.1:41792]
I0405 03:02:57.752282       1 scheduling_queue.go:895] About to try and schedule pod kubectl-1438/e2e-test-nginx-pod
I0405 03:02:57.752298       1 scheduler.go:454] Attempting to schedule pod: kubectl-1438/e2e-test-nginx-pod
I0405 03:02:57.752636       1 scheduler_binder.go:255] AssumePodVolumes for pod "kubectl-1438/e2e-test-nginx-pod", node "e2e-test-peterhornyack-windows-node-group-lkqs"
I0405 03:02:57.752647       1 scheduler_binder.go:265] AssumePodVolumes for pod "kubectl-1438/e2e-test-nginx-pod", node "e2e-test-peterhornyack-windows-node-group-lkqs": all PVCs bound and nothing to do
I0405 03:02:57.752865       1 factory.go:734] Attempting to bind e2e-test-nginx-pod to e2e-test-peterhornyack-windows-node-group-lkqs
I0405 03:02:57.761179       1 scheduler.go:575] pod kubectl-1438/e2e-test-nginx-pod is bound successfully on node e2e-test-peterhornyack-windows-node-group-lkqs, 4 nodes evaluated, 2 nodes were found feasible
I0405 03:02:59.595577       1 reflector.go:384] k8s.io/client-go/informers/factory.go:133: Watch close - *v1.ReplicationController total 2 items received
I0405 03:03:07.364283       1 wrap.go:47] GET /healthz: (77.061µs) 200 [kube-probe/1.15+ 127.0.0.1:41830]
I0405 03:03:17.363055       1 wrap.go:47] GET /healthz: (121.448µs) 200 [kube-probe/1.15+ 127.0.0.1:41866]
I0405 03:03:25.576105       1 reflector.go:384] k8s.io/client-go/informers/factory.go:133: Watch close - *v1.Node total 45 items received
I0405 03:03:27.363152       1 wrap.go:47] GET /healthz: (225.007µs) 200 [kube-probe/1.15+ 127.0.0.1:41914]
I0405 03:03:29.289823       1 scheduling_queue.go:895] About to try and schedule pod projected-2429/pod-projected-configmaps-bde4c518-3a48-4b2f-9ca7-07b782ce0acb
I0405 03:03:29.289838       1 scheduler.go:454] Attempting to schedule pod: projected-2429/pod-projected-configmaps-bde4c518-3a48-4b2f-9ca7-07b782ce0acb
I0405 03:03:29.290204       1 scheduler_binder.go:255] AssumePodVolumes for pod "projected-2429/pod-projected-configmaps-bde4c518-3a48-4b2f-9ca7-07b782ce0acb", node "e2e-test-peterhornyack-windows-node-group-rqkw"
I0405 03:03:29.290220       1 scheduler_binder.go:265] AssumePodVolumes for pod "projected-2429/pod-projected-configmaps-bde4c518-3a48-4b2f-9ca7-07b782ce0acb", node "e2e-test-peterhornyack-windows-node-group-rqkw": all PVCs bound and nothing to do
I0405 03:03:29.290255       1 factory.go:734] Attempting to bind pod-projected-configmaps-bde4c518-3a48-4b2f-9ca7-07b782ce0acb to e2e-test-peterhornyack-windows-node-group-rqkw
I0405 03:03:29.300774       1 scheduler.go:575] pod projected-2429/pod-projected-configmaps-bde4c518-3a48-4b2f-9ca7-07b782ce0acb is bound successfully on node e2e-test-peterhornyack-windows-node-group-rqkw, 4 nodes evaluated, 2 nodes were found feasible
I0405 03:03:29.576495       1 reflector.go:384] k8s.io/client-go/informers/factory.go:133: Watch close - *v1beta1.PodDisruptionBudget total 0 items received
I0405 03:03:37.364261       1 wrap.go:47] GET /healthz: (79.976µs) 200 [kube-probe/1.15+ 127.0.0.1:41948]
I0405 03:03:47.363114       1 wrap.go:47] GET /healthz: (79.089µs) 200 [kube-probe/1.15+ 127.0.0.1:41980]
I0405 03:03:57.362693       1 wrap.go:47] GET /healthz: (73.076µs) 200 [kube-probe/1.15+ 127.0.0.1:42012]
I0405 03:04:03.615662       1 scheduling_queue.go:895] About to try and schedule pod container-runtime-5247/image-pull-testa1cb5eb3-d014-4e83-8cdd-ba26eed35df2
I0405 03:04:03.615691       1 scheduler.go:454] Attempting to schedule pod: container-runtime-5247/image-pull-testa1cb5eb3-d014-4e83-8cdd-ba26eed35df2
I0405 03:04:03.618026       1 scheduler_binder.go:255] AssumePodVolumes for pod "container-runtime-5247/image-pull-testa1cb5eb3-d014-4e83-8cdd-ba26eed35df2", node "e2e-test-peterhornyack-windows-node-group-lkqs"
I0405 03:04:03.618062       1 scheduler_binder.go:265] AssumePodVolumes for pod "container-runtime-5247/image-pull-testa1cb5eb3-d014-4e83-8cdd-ba26eed35df2", node "e2e-test-peterhornyack-windows-node-group-lkqs": all PVCs bound and nothing to do
I0405 03:04:03.618136       1 factory.go:734] Attempting to bind image-pull-testa1cb5eb3-d014-4e83-8cdd-ba26eed35df2 to e2e-test-peterhornyack-windows-node-group-lkqs
I0405 03:04:03.624753       1 scheduler.go:575] pod container-runtime-5247/image-pull-testa1cb5eb3-d014-4e83-8cdd-ba26eed35df2 is bound successfully on node e2e-test-peterhornyack-windows-node-group-lkqs, 4 nodes evaluated, 2 nodes were found feasible
I0405 03:04:07.364300       1 wrap.go:47] GET /healthz: (79.19µs) 200 [kube-probe/1.15+ 127.0.0.1:42050]
I0405 03:04:15.584372       1 reflector.go:384] k8s.io/client-go/informers/factory.go:133: Watch close - *v1.Service total 6 items received
I0405 03:04:17.363687       1 wrap.go:47] GET /healthz: (65.144µs) 200 [kube-probe/1.15+ 127.0.0.1:42086]
I0405 03:04:27.369247       1 wrap.go:47] GET /healthz: (67.558µs) 200 [kube-probe/1.15+ 127.0.0.1:42276]
I0405 03:04:37.363758       1 wrap.go:47] GET /healthz: (78.53µs) 200 [kube-probe/1.15+ 127.0.0.1:42312]
I0405 03:04:37.601329       1 reflector.go:384] k8s.io/client-go/informers/factory.go:133: Watch close - *v1.StorageClass total 0 items received
I0405 03:04:44.571406       1 reflector.go:384] k8s.io/client-go/informers/factory.go:133: Watch close - *v1.PersistentVolume total 0 items received
I0405 03:04:47.363744       1 wrap.go:47] GET /healthz: (75.698µs) 200 [kube-probe/1.15+ 127.0.0.1:42344]
I0405 03:04:49.383791       1 scheduling_queue.go:895] About to try and schedule pod deployment-9123/test-cleanup-controller-tpg6d
I0405 03:04:49.383807       1 scheduler.go:454] Attempting to schedule pod: deployment-9123/test-cleanup-controller-tpg6d
I0405 03:04:49.390368       1 scheduler_binder.go:255] AssumePodVolumes for pod "deployment-9123/test-cleanup-controller-tpg6d", node "e2e-test-peterhornyack-windows-node-group-lkqs"
I0405 03:04:49.390388       1 scheduler_binder.go:265] AssumePodVolumes for pod "deployment-9123/test-cleanup-controller-tpg6d", node "e2e-test-peterhornyack-windows-node-group-lkqs": all PVCs bound and nothing to do
I0405 03:04:49.390454       1 factory.go:734] Attempting to bind test-cleanup-controller-tpg6d to e2e-test-peterhornyack-windows-node-group-lkqs
I0405 03:04:49.406543       1 scheduler.go:575] pod deployment-9123/test-cleanup-controller-tpg6d is bound successfully on node e2e-test-peterhornyack-windows-node-group-lkqs, 4 nodes evaluated, 2 nodes were found feasible
I0405 03:04:57.363022       1 wrap.go:47] GET /healthz: (92.841µs) 200 [kube-probe/1.15+ 127.0.0.1:42376]
I0405 03:04:57.675639       1 scheduling_queue.go:895] About to try and schedule pod deployment-9123/test-cleanup-deployment-5bc9d9c7bd-gws58
I0405 03:04:57.675665       1 scheduler.go:454] Attempting to schedule pod: deployment-9123/test-cleanup-deployment-5bc9d9c7bd-gws58
I0405 03:04:57.679522       1 scheduler_binder.go:255] AssumePodVolumes for pod "deployment-9123/test-cleanup-deployment-5bc9d9c7bd-gws58", node "e2e-test-peterhornyack-windows-node-group-lkqs"
I0405 03:04:57.679538       1 scheduler_binder.go:265] AssumePodVolumes for pod "deployment-9123/test-cleanup-deployment-5bc9d9c7bd-gws58", node "e2e-test-peterhornyack-windows-node-group-lkqs": all PVCs bound and nothing to do
I0405 03:04:57.679606       1 factory.go:734] Attempting to bind test-cleanup-deployment-5bc9d9c7bd-gws58 to e2e-test-peterhornyack-windows-node-group-lkqs
I0405 03:04:57.733415       1 scheduler.go:575] pod deployment-9123/test-cleanup-deployment-5bc9d9c7bd-gws58 is bound successfully on node e2e-test-peterhornyack-windows-node-group-lkqs, 4 nodes evaluated, 2 nodes were found feasible
I0405 03:05:07.362857       1 wrap.go:47] GET /healthz: (81.463µs) 200 [kube-probe/1.15+ 127.0.0.1:42412]
I0405 03:05:12.049057       1 scheduling_queue.go:895] About to try and schedule pod windows-volumes-813/pod-1ced23c1-f948-49a6-9352-2d62143584ff
I0405 03:05:12.049071       1 scheduler.go:454] Attempting to schedule pod: windows-volumes-813/pod-1ced23c1-f948-49a6-9352-2d62143584ff
I0405 03:05:12.049333       1 scheduler_binder.go:255] AssumePodVolumes for pod "windows-volumes-813/pod-1ced23c1-f948-49a6-9352-2d62143584ff", node "e2e-test-peterhornyack-windows-node-group-rqkw"
I0405 03:05:12.049344       1 scheduler_binder.go:265] AssumePodVolumes for pod "windows-volumes-813/pod-1ced23c1-f948-49a6-9352-2d62143584ff", node "e2e-test-peterhornyack-windows-node-group-rqkw": all PVCs bound and nothing to do
I0405 03:05:12.049384       1 factory.go:734] Attempting to bind pod-1ced23c1-f948-49a6-9352-2d62143584ff to e2e-test-peterhornyack-windows-node-group-rqkw
I0405 03:05:12.061348       1 scheduler.go:575] pod windows-volumes-813/pod-1ced23c1-f948-49a6-9352-2d62143584ff is bound successfully on node e2e-test-peterhornyack-windows-node-group-rqkw, 4 nodes evaluated, 2 nodes were found feasible
I0405 03:05:17.363746       1 wrap.go:47] GET /healthz: (139.025µs) 200 [kube-probe/1.15+ 127.0.0.1:42448]
I0405 03:05:22.585872       1 scheduling_queue.go:895] About to try and schedule pod windows-volumes-813/pod-38e68ef5-7352-4b8e-8b51-25e6697d4bf5
I0405 03:05:22.585899       1 scheduler.go:454] Attempting to schedule pod: windows-volumes-813/pod-38e68ef5-7352-4b8e-8b51-25e6697d4bf5
I0405 03:05:22.587436       1 scheduler_binder.go:255] AssumePodVolumes for pod "windows-volumes-813/pod-38e68ef5-7352-4b8e-8b51-25e6697d4bf5", node "e2e-test-peterhornyack-windows-node-group-lkqs"
I0405 03:05:22.587451       1 scheduler_binder.go:265] AssumePodVolumes for pod "windows-volumes-813/pod-38e68ef5-7352-4b8e-8b51-25e6697d4bf5", node "e2e-test-peterhornyack-windows-node-group-lkqs": all PVCs bound and nothing to do
I0405 03:05:22.587514       1 factory.go:734] Attempting to bind pod-38e68ef5-7352-4b8e-8b51-25e6697d4bf5 to e2e-test-peterhornyack-windows-node-group-lkqs
I0405 03:05:22.595048       1 scheduler.go:575] pod windows-volumes-813/pod-38e68ef5-7352-4b8e-8b51-25e6697d4bf5 is bound successfully on node e2e-test-peterhornyack-windows-node-group-lkqs, 4 nodes evaluated, 2 nodes were found feasible
I0405 03:05:27.363641       1 wrap.go:47] GET /healthz: (59.717µs) 200 [kube-probe/1.15+ 127.0.0.1:42496]
I0405 03:05:37.364282       1 wrap.go:47] GET /healthz: (75.563µs) 200 [kube-probe/1.15+ 127.0.0.1:42540]
I0405 03:05:47.364284       1 wrap.go:47] GET /healthz: (85.106µs) 200 [kube-probe/1.15+ 127.0.0.1:42572]
I0405 03:05:57.365317       1 wrap.go:47] GET /healthz: (84.647µs) 200 [kube-probe/1.15+ 127.0.0.1:42604]
I0405 03:05:57.885691       1 scheduling_queue.go:895] About to try and schedule pod downward-api-2415/downwardapi-volume-20a15cdf-8400-4897-850a-ef163fa50724
I0405 03:05:57.885711       1 scheduler.go:454] Attempting to schedule pod: downward-api-2415/downwardapi-volume-20a15cdf-8400-4897-850a-ef163fa50724
I0405 03:05:57.886534       1 scheduler_binder.go:255] AssumePodVolumes for pod "downward-api-2415/downwardapi-volume-20a15cdf-8400-4897-850a-ef163fa50724", node "e2e-test-peterhornyack-windows-node-group-rqkw"
I0405 03:05:57.886552       1 scheduler_binder.go:265] AssumePodVolumes for pod "downward-api-2415/downwardapi-volume-20a15cdf-8400-4897-850a-ef163fa50724", node "e2e-test-peterhornyack-windows-node-group-rqkw": all PVCs bound and nothing to do
I0405 03:05:57.886618       1 factory.go:734] Attempting to bind downwardapi-volume-20a15cdf-8400-4897-850a-ef163fa50724 to e2e-test-peterhornyack-windows-node-group-rqkw
I0405 03:05:57.894674       1 scheduler.go:575] pod downward-api-2415/downwardapi-volume-20a15cdf-8400-4897-850a-ef163fa50724 is bound successfully on node e2e-test-peterhornyack-windows-node-group-rqkw, 4 nodes evaluated, 2 nodes were found feasible
I0405 03:06:07.364396       1 wrap.go:47] GET /healthz: (81.115µs) 200 [kube-probe/1.15+ 127.0.0.1:42642]
I0405 03:06:14.311621       1 scheduling_queue.go:895] About to try and schedule pod init-container-9042/pod-init-63695e5d-6a63-4a15-b9ae-597d24e11378
I0405 03:06:14.311636       1 scheduler.go:454] Attempting to schedule pod: init-container-9042/pod-init-63695e5d-6a63-4a15-b9ae-597d24e11378
I0405 03:06:14.312146       1 scheduler_binder.go:255] AssumePodVolumes for pod "init-container-9042/pod-init-63695e5d-6a63-4a15-b9ae-597d24e11378", node "e2e-test-peterhornyack-windows-node-group-lkqs"
I0405 03:06:14.312160       1 scheduler_binder.go:265] AssumePodVolumes for pod "init-container-9042/pod-init-63695e5d-6a63-4a15-b9ae-597d24e11378", node "e2e-test-peterhornyack-windows-node-group-lkqs": all PVCs bound and nothing to do
I0405 03:06:14.312229       1 factory.go:734] Attempting to bind pod-init-63695e5d-6a63-4a15-b9ae-597d24e11378 to e2e-test-peterhornyack-windows-node-group-lkqs
I0405 03:06:14.321394       1 scheduler.go:575] pod init-container-9042/pod-init-63695e5d-6a63-4a15-b9ae-597d24e11378 is bound successfully on node e2e-test-peterhornyack-windows-node-group-lkqs, 4 nodes evaluated, 2 nodes were found feasible
I0405 03:06:17.366341       1 wrap.go:47] GET /healthz: (91.949µs) 200 [kube-probe/1.15+ 127.0.0.1:42678]
I0405 03:06:25.590971       1 reflector.go:384] k8s.io/client-go/informers/factory.go:133: Watch close - *v1.ReplicaSet total 18 items received
I0405 03:06:27.364289       1 wrap.go:47] GET /healthz: (113.545µs) 200 [kube-probe/1.15+ 127.0.0.1:42726]
I0405 03:06:36.167579       1 scheduling_queue.go:895] About to try and schedule pod container-probe-3124/test-webserver-abb7aba7-e925-4d01-b17e-6dd20f31b36c
I0405 03:06:36.167594       1 scheduler.go:454] Attempting to schedule pod: container-probe-3124/test-webserver-abb7aba7-e925-4d01-b17e-6dd20f31b36c
I0405 03:06:36.169445       1 scheduler_binder.go:255] AssumePodVolumes for pod "container-probe-3124/test-webserver-abb7aba7-e925-4d01-b17e-6dd20f31b36c", node "e2e-test-peterhornyack-windows-node-group-lkqs"
I0405 03:06:36.169463       1 scheduler_binder.go:265] AssumePodVolumes for pod "container-probe-3124/test-webserver-abb7aba7-e925-4d01-b17e-6dd20f31b36c", node "e2e-test-peterhornyack-windows-node-group-lkqs": all PVCs bound and nothing to do
I0405 03:06:36.169538       1 factory.go:734] Attempting to bind test-webserver-abb7aba7-e925-4d01-b17e-6dd20f31b36c to e2e-test-peterhornyack-windows-node-group-lkqs
I0405 03:06:36.177862       1 scheduler.go:575] pod container-probe-3124/test-webserver-abb7aba7-e925-4d01-b17e-6dd20f31b36c is bound successfully on node e2e-test-peterhornyack-windows-node-group-lkqs, 4 nodes evaluated, 2 nodes were found feasible
I0405 03:06:37.363792       1 wrap.go:47] GET /healthz: (156.581µs) 200 [kube-probe/1.15+ 127.0.0.1:42766]
I0405 03:06:47.366162       1 wrap.go:47] GET /healthz: (754.332µs) 200 [kube-probe/1.15+ 127.0.0.1:42798]
I0405 03:06:57.365200       1 wrap.go:47] GET /healthz: (61.948µs) 200 [kube-probe/1.15+ 127.0.0.1:42830]
I0405 03:07:07.363791       1 wrap.go:47] GET /healthz: (159.516µs) 200 [kube-probe/1.15+ 127.0.0.1:42866]
I0405 03:07:17.364306       1 wrap.go:47] GET /healthz: (83.086µs) 200 [kube-probe/1.15+ 127.0.0.1:42902]
I0405 03:07:20.599313       1 reflector.go:384] k8s.io/client-go/informers/factory.go:133: Watch close - *v1.StatefulSet total 0 items received
I0405 03:07:27.363767       1 wrap.go:47] GET /healthz: (152.97µs) 200 [kube-probe/1.15+ 127.0.0.1:42950]
I0405 03:07:37.365317       1 wrap.go:47] GET /healthz: (81.075µs) 200 [kube-probe/1.15+ 127.0.0.1:42986]
I0405 03:07:47.363818       1 wrap.go:47] GET /healthz: (259.734µs) 200 [kube-probe/1.15+ 127.0.0.1:43018]
I0405 03:07:57.365711       1 wrap.go:47] GET /healthz: (57.559µs) 200 [kube-probe/1.15+ 127.0.0.1:43052]
I0405 03:07:59.578909       1 reflector.go:384] k8s.io/client-go/informers/factory.go:133: Watch close - *v1.PersistentVolumeClaim total 0 items received
I0405 03:08:00.315390       1 scheduling_queue.go:895] About to try and schedule pod downward-api-2500/downward-api-b121b285-17cf-420a-9488-fb6c1c73c6a6
I0405 03:08:00.315406       1 scheduler.go:454] Attempting to schedule pod: downward-api-2500/downward-api-b121b285-17cf-420a-9488-fb6c1c73c6a6
I0405 03:08:00.315792       1 scheduler_binder.go:255] AssumePodVolumes for pod "downward-api-2500/downward-api-b121b285-17cf-420a-9488-fb6c1c73c6a6", node "e2e-test-peterhornyack-windows-node-group-lkqs"
I0405 03:08:00.315804       1 scheduler_binder.go:265] AssumePodVolumes for pod "downward-api-2500/downward-api-b121b285-17cf-420a-9488-fb6c1c73c6a6", node "e2e-test-peterhornyack-windows-node-group-lkqs": all PVCs bound and nothing to do
I0405 03:08:00.315861       1 factory.go:734] Attempting to bind downward-api-b121b285-17cf-420a-9488-fb6c1c73c6a6 to e2e-test-peterhornyack-windows-node-group-lkqs
I0405 03:08:00.330833       1 scheduler.go:575] pod downward-api-2500/downward-api-b121b285-17cf-420a-9488-fb6c1c73c6a6 is bound successfully on node e2e-test-peterhornyack-windows-node-group-lkqs, 4 nodes evaluated, 2 nodes were found feasible
I0405 03:08:07.364271       1 wrap.go:47] GET /healthz: (72.416µs) 200 [kube-probe/1.15+ 127.0.0.1:43088]
I0405 03:08:16.811141       1 scheduling_queue.go:895] About to try and schedule pod gc-1923/simpletest.rc-bwj6x
I0405 03:08:16.811156       1 scheduler.go:454] Attempting to schedule pod: gc-1923/simpletest.rc-bwj6x
I0405 03:08:16.815267       1 scheduler_binder.go:255] AssumePodVolumes for pod "gc-1923/simpletest.rc-bwj6x", node "e2e-test-peterhornyack-windows-node-group-lkqs"
I0405 03:08:16.815283       1 scheduler_binder.go:265] AssumePodVolumes for pod "gc-1923/simpletest.rc-bwj6x", node "e2e-test-peterhornyack-windows-node-group-lkqs": all PVCs bound and nothing to do
I0405 03:08:16.815326       1 factory.go:734] Attempting to bind simpletest.rc-bwj6x to e2e-test-peterhornyack-windows-node-group-lkqs
I0405 03:08:16.826448       1 scheduling_queue.go:895] About to try and schedule pod gc-1923/simpletest.rc-hdzrv
I0405 03:08:16.826463       1 scheduler.go:454] Attempting to schedule pod: gc-1923/simpletest.rc-hdzrv
I0405 03:08:16.827204       1 scheduler_binder.go:255] AssumePodVolumes for pod "gc-1923/simpletest.rc-hdzrv", node "e2e-test-peterhornyack-windows-node-group-lkqs"
I0405 03:08:16.827216       1 scheduler_binder.go:265] AssumePodVolumes for pod "gc-1923/simpletest.rc-hdzrv", node "e2e-test-peterhornyack-windows-node-group-lkqs": all PVCs bound and nothing to do
I0405 03:08:16.830561       1 factory.go:734] Attempting to bind simpletest.rc-hdzrv to e2e-test-peterhornyack-windows-node-group-lkqs
I0405 03:08:16.832424       1 scheduling_queue.go:895] About to try and schedule pod gc-1923/simpletest.rc-c9bx8
I0405 03:08:16.832450       1 scheduler.go:454] Attempting to schedule pod: gc-1923/simpletest.rc-c9bx8
I0405 03:08:16.836624       1 scheduler_binder.go:255] AssumePodVolumes for pod "gc-1923/simpletest.rc-c9bx8", node "e2e-test-peterhornyack-windows-node-group-lkqs"
I0405 03:08:16.836656       1 scheduler_binder.go:265] AssumePodVolumes for pod "gc-1923/simpletest.rc-c9bx8", node "e2e-test-peterhornyack-windows-node-group-lkqs": all PVCs bound and nothing to do
I0405 03:08:16.836724       1 factory.go:734] Attempting to bind simpletest.rc-c9bx8 to e2e-test-peterhornyack-windows-node-group-lkqs
I0405 03:08:16.851461       1 scheduler.go:575] pod gc-1923/simpletest.rc-bwj6x is bound successfully on node e2e-test-peterhornyack-windows-node-group-lkqs, 4 nodes evaluated, 2 nodes were found feasible
I0405 03:08:16.851803       1 scheduling_queue.go:895] About to try and schedule pod gc-1923/simpletest.rc-qd5sm
I0405 03:08:16.851810       1 scheduler.go:454] Attempting to schedule pod: gc-1923/simpletest.rc-qd5sm
I0405 03:08:16.858791       1 scheduler_binder.go:255] AssumePodVolumes for pod "gc-1923/simpletest.rc-qd5sm", node "e2e-test-peterhornyack-windows-node-group-lkqs"
I0405 03:08:16.858810       1 scheduler_binder.go:265] AssumePodVolumes for pod "gc-1923/simpletest.rc-qd5sm", node "e2e-test-peterhornyack-windows-node-group-lkqs": all PVCs bound and nothing to do
I0405 03:08:16.862046       1 factory.go:734] Attempting to bind simpletest.rc-qd5sm to e2e-test-peterhornyack-windows-node-group-lkqs
I0405 03:08:16.862565       1 scheduling_queue.go:895] About to try and schedule pod gc-1923/simpletest.rc-x5f76
I0405 03:08:16.862573       1 scheduler.go:454] Attempting to schedule pod: gc-1923/simpletest.rc-x5f76
I0405 03:08:16.866268       1 scheduler_binder.go:255] AssumePodVolumes for pod "gc-1923/simpletest.rc-x5f76", node "e2e-test-peterhornyack-windows-node-group-lkqs"
I0405 03:08:16.866284       1 scheduler_binder.go:265] AssumePodVolumes for pod "gc-1923/simpletest.rc-x5f76", node "e2e-test-peterhornyack-windows-node-group-lkqs": all PVCs bound and nothing to do
I0405 03:08:16.866321       1 factory.go:734] Attempting to bind simpletest.rc-x5f76 to e2e-test-peterhornyack-windows-node-group-lkqs
I0405 03:08:16.869483       1 scheduler.go:575] pod gc-1923/simpletest.rc-hdzrv is bound successfully on node e2e-test-peterhornyack-windows-node-group-lkqs, 4 nodes evaluated, 2 nodes were found feasible
I0405 03:08:16.873636       1 scheduling_queue.go:895] About to try and schedule pod gc-1923/simpletest.rc-vwc8c
I0405 03:08:16.873652       1 scheduler.go:454] Attempting to schedule pod: gc-1923/simpletest.rc-vwc8c
I0405 03:08:16.876318       1 scheduler_binder.go:255] AssumePodVolumes for pod "gc-1923/simpletest.rc-vwc8c", node "e2e-test-peterhornyack-windows-node-group-lkqs"
I0405 03:08:16.876336       1 scheduler_binder.go:265] AssumePodVolumes for pod "gc-1923/simpletest.rc-vwc8c", node "e2e-test-peterhornyack-windows-node-group-lkqs": all PVCs bound and nothing to do
I0405 03:08:16.876376       1 factory.go:734] Attempting to bind simpletest.rc-vwc8c to e2e-test-peterhornyack-windows-node-group-lkqs
I0405 03:08:16.881397       1 scheduler.go:575] pod gc-1923/simpletest.rc-c9bx8 is bound successfully on node e2e-test-peterhornyack-windows-node-group-lkqs, 4 nodes evaluated, 2 nodes were found feasible
I0405 03:08:16.884831       1 scheduling_queue.go:895] About to try and schedule pod gc-1923/simpletest.rc-tks7d
I0405 03:08:16.884841       1 scheduler.go:454] Attempting to schedule pod: gc-1923/simpletest.rc-tks7d
I0405 03:08:16.885174       1 scheduler_binder.go:255] AssumePodVolumes for pod "gc-1923/simpletest.rc-tks7d", node "e2e-test-peterhornyack-windows-node-group-lkqs"
I0405 03:08:16.885185       1 scheduler_binder.go:265] AssumePodVolumes for pod "gc-1923/simpletest.rc-tks7d", node "e2e-test-peterhornyack-windows-node-group-lkqs": all PVCs bound and nothing to do
I0405 03:08:16.889074       1 factory.go:734] Attempting to bind simpletest.rc-tks7d to e2e-test-peterhornyack-windows-node-group-lkqs
I0405 03:08:16.899576       1 scheduling_queue.go:895] About to try and schedule pod gc-1923/simpletest.rc-lm9nq
I0405 03:08:16.899591       1 scheduler.go:454] Attempting to schedule pod: gc-1923/simpletest.rc-lm9nq
I0405 03:08:16.901390       1 scheduler_binder.go:255] AssumePodVolumes for pod "gc-1923/simpletest.rc-lm9nq", node "e2e-test-peterhornyack-windows-node-group-lkqs"
I0405 03:08:16.901405       1 scheduler_binder.go:265] AssumePodVolumes for pod "gc-1923/simpletest.rc-lm9nq", node "e2e-test-peterhornyack-windows-node-group-lkqs": all PVCs bound and nothing to do
I0405 03:08:16.901468       1 factory.go:734] Attempting to bind simpletest.rc-lm9nq to e2e-test-peterhornyack-windows-node-group-lkqs
I0405 03:08:16.908410       1 scheduling_queue.go:895] About to try and schedule pod gc-1923/simpletest.rc-g5bxx
I0405 03:08:16.908430       1 scheduler.go:454] Attempting to schedule pod: gc-1923/simpletest.rc-g5bxx
I0405 03:08:16.912415       1 scheduler_binder.go:255] AssumePodVolumes for pod "gc-1923/simpletest.rc-g5bxx", node "e2e-test-peterhornyack-windows-node-group-lkqs"
I0405 03:08:16.914095       1 scheduler_binder.go:265] AssumePodVolumes for pod "gc-1923/simpletest.rc-g5bxx", node "e2e-test-peterhornyack-windows-node-group-lkqs": all PVCs bound and nothing to do
I0405 03:08:16.914171       1 factory.go:734] Attempting to bind simpletest.rc-g5bxx to e2e-test-peterhornyack-windows-node-group-lkqs
I0405 03:08:16.914873       1 scheduler.go:575] pod gc-1923/simpletest.rc-qd5sm is bound successfully on node e2e-test-peterhornyack-windows-node-group-lkqs, 4 nodes evaluated, 2 nodes were found feasible
I0405 03:08:16.918533       1 scheduler.go:575] pod gc-1923/simpletest.rc-x5f76 is bound successfully on node e2e-test-peterhornyack-windows-node-group-lkqs, 4 nodes evaluated, 2 nodes were found feasible
I0405 03:08:16.921588       1 scheduling_queue.go:895] About to try and schedule pod gc-1923/simpletest.rc-z9p26
I0405 03:08:16.921602       1 scheduler.go:454] Attempting to schedule pod: gc-1923/simpletest.rc-z9p26
I0405 03:08:16.925834       1 scheduler_binder.go:255] AssumePodVolumes for pod "gc-1923/simpletest.rc-z9p26", node "e2e-test-peterhornyack-windows-node-group-lkqs"
I0405 03:08:16.925863       1 scheduler_binder.go:265] AssumePodVolumes for pod "gc-1923/simpletest.rc-z9p26", node "e2e-test-peterhornyack-windows-node-group-lkqs": all PVCs bound and nothing to do
I0405 03:08:16.925910       1 factory.go:734] Attempting to bind simpletest.rc-z9p26 to e2e-test-peterhornyack-windows-node-group-lkqs
I0405 03:08:16.930118       1 scheduler.go:575] pod gc-1923/simpletest.rc-vwc8c is bound successfully on node e2e-test-peterhornyack-windows-node-group-lkqs, 4 nodes evaluated, 2 nodes were found feasible
I0405 03:08:16.930174       1 scheduler.go:575] pod gc-1923/simpletest.rc-tks7d is bound successfully on node e2e-test-peterhornyack-windows-node-group-lkqs, 4 nodes evaluated, 2 nodes were found feasible
I0405 03:08:16.941968       1 scheduler.go:575] pod gc-1923/simpletest.rc-lm9nq is bound successfully on node e2e-test-peterhornyack-windows-node-group-lkqs, 4 nodes evaluated, 2 nodes were found feasible
I0405 03:08:16.952831       1 scheduler.go:575] pod gc-1923/simpletest.rc-z9p26 is bound successfully on node e2e-test-peterhornyack-windows-node-group-lkqs, 4 nodes evaluated, 2 nodes were found feasible
I0405 03:08:16.958571       1 scheduler.go:575] pod gc-1923/simpletest.rc-g5bxx is bound successfully on node e2e-test-peterhornyack-windows-node-group-lkqs, 4 nodes evaluated, 2 nodes were found feasible
I0405 03:08:17.363790       1 wrap.go:47] GET /healthz: (150.569µs) 200 [kube-probe/1.15+ 127.0.0.1:43124]
I0405 03:08:27.366755       1 wrap.go:47] GET /healthz: (92.454µs) 200 [kube-probe/1.15+ 127.0.0.1:43168]
I0405 03:08:29.578208       1 reflector.go:384] k8s.io/client-go/informers/factory.go:133: Watch close - *v1.Node total 26 items received
I0405 03:08:31.152873       1 scheduling_queue.go:895] About to try and schedule pod secrets-4438/pod-secrets-851c1518-d6ea-4826-be5e-b85e410b92bd
I0405 03:08:31.152887       1 scheduler.go:454] Attempting to schedule pod: secrets-4438/pod-secrets-851c1518-d6ea-4826-be5e-b85e410b92bd
I0405 03:08:31.153207       1 scheduler_binder.go:255] AssumePodVolumes for pod "secrets-4438/pod-secrets-851c1518-d6ea-4826-be5e-b85e410b92bd", node "e2e-test-peterhornyack-windows-node-group-rqkw"
I0405 03:08:31.153217       1 scheduler_binder.go:265] AssumePodVolumes for pod "secrets-4438/pod-secrets-851c1518-d6ea-4826-be5e-b85e410b92bd", node "e2e-test-peterhornyack-windows-node-group-rqkw": all PVCs bound and nothing to do
I0405 03:08:31.153271       1 factory.go:734] Attempting to bind pod-secrets-851c1518-d6ea-4826-be5e-b85e410b92bd to e2e-test-peterhornyack-windows-node-group-rqkw
I0405 03:08:31.162058       1 scheduler.go:575] pod secrets-4438/pod-secrets-851c1518-d6ea-4826-be5e-b85e410b92bd is bound successfully on node e2e-test-peterhornyack-windows-node-group-rqkw, 4 nodes evaluated, 2 nodes were found feasible
I0405 03:08:37.413742       1 wrap.go:47] GET /healthz: (82.21µs) 200 [kube-probe/1.15+ 127.0.0.1:43206]
I0405 03:08:47.363875       1 wrap.go:47] GET /healthz: (137.391µs) 200 [kube-probe/1.15+ 127.0.0.1:43240]
I0405 03:08:56.189881       1 scheduling_queue.go:895] About to try and schedule pod kubectl-1891/update-demo-nautilus-hlb2x
I0405 03:08:56.189895       1 scheduler.go:454] Attempting to schedule pod: kubectl-1891/update-demo-nautilus-hlb2x
I0405 03:08:56.191493       1 scheduler_binder.go:255] AssumePodVolumes for pod "kubectl-1891/update-demo-nautilus-hlb2x", node "e2e-test-peterhornyack-windows-node-group-lkqs"
I0405 03:08:56.191506       1 scheduler_binder.go:265] AssumePodVolumes for pod "kubectl-1891/update-demo-nautilus-hlb2x", node "e2e-test-peterhornyack-windows-node-group-lkqs": all PVCs bound and nothing to do
I0405 03:08:56.191576       1 factory.go:734] Attempting to bind update-demo-nautilus-hlb2x to e2e-test-peterhornyack-windows-node-group-lkqs
I0405 03:08:56.202188       1 scheduling_queue.go:895] About to try and schedule pod kubectl-1891/update-demo-nautilus-jt6m9
I0405 03:08:56.202203       1 scheduler.go:454] Attempting to schedule pod: kubectl-1891/update-demo-nautilus-jt6m9
I0405 03:08:56.202512       1 scheduler_binder.go:255] AssumePodVolumes for pod "kubectl-1891/update-demo-nautilus-jt6m9", node "e2e-test-peterhornyack-windows-node-group-rqkw"
I0405 03:08:56.202530       1 scheduler_binder.go:265] AssumePodVolumes for pod "kubectl-1891/update-demo-nautilus-jt6m9", node "e2e-test-peterhornyack-windows-node-group-rqkw": all PVCs bound and nothing to do
I0405 03:08:56.202581       1 factory.go:734] Attempting to bind update-demo-nautilus-jt6m9 to e2e-test-peterhornyack-windows-node-group-rqkw
I0405 03:08:56.213477       1 scheduler.go:575] pod kubectl-1891/update-demo-nautilus-hlb2x is bound successfully on node e2e-test-peterhornyack-windows-node-group-lkqs, 4 nodes evaluated, 2 nodes were found feasible
I0405 03:08:56.227428       1 scheduler.go:575] pod kubectl-1891/update-demo-nautilus-jt6m9 is bound successfully on node e2e-test-peterhornyack-windows-node-group-rqkw, 4 nodes evaluated, 2 nodes were found feasible
I0405 03:08:57.363855       1 wrap.go:47] GET /healthz: (150.944µs) 200 [kube-probe/1.15+ 127.0.0.1:43272]
I0405 03:09:07.363863       1 wrap.go:47] GET /healthz: (134.956µs) 200 [kube-probe/1.15+ 127.0.0.1:43312]
I0405 03:09:17.363763       1 wrap.go:47] GET /healthz: (65.119µs) 200 [kube-probe/1.15+ 127.0.0.1:43352]
I0405 03:09:17.750584       1 scheduling_queue.go:895] About to try and schedule pod pod-network-test-2268/netserver-0
I0405 03:09:17.750599       1 scheduler.go:454] Attempting to schedule pod: pod-network-test-2268/netserver-0
I0405 03:09:17.751016       1 scheduler_binder.go:255] AssumePodVolumes for pod "pod-network-test-2268/netserver-0", node "e2e-test-peterhornyack-windows-node-group-lkqs"
I0405 03:09:17.751030       1 scheduler_binder.go:265] AssumePodVolumes for pod "pod-network-test-2268/netserver-0", node "e2e-test-peterhornyack-windows-node-group-lkqs": all PVCs bound and nothing to do
I0405 03:09:17.751098       1 factory.go:734] Attempting to bind netserver-0 to e2e-test-peterhornyack-windows-node-group-lkqs
I0405 03:09:17.761169       1 scheduler.go:575] pod pod-network-test-2268/netserver-0 is bound successfully on node e2e-test-peterhornyack-windows-node-group-lkqs, 4 nodes evaluated, 1 nodes were found feasible
I0405 03:09:17.794349       1 scheduling_queue.go:895] About to try and schedule pod pod-network-test-2268/netserver-1
I0405 03:09:17.794376       1 scheduler.go:454] Attempting to schedule pod: pod-network-test-2268/netserver-1
I0405 03:09:17.794596       1 scheduler_binder.go:255] AssumePodVolumes for pod "pod-network-test-2268/netserver-1", node "e2e-test-peterhornyack-windows-node-group-rqkw"
I0405 03:09:17.794621       1 scheduler_binder.go:265] AssumePodVolumes for pod "pod-network-test-2268/netserver-1", node "e2e-test-peterhornyack-windows-node-group-rqkw": all PVCs bound and nothing to do
I0405 03:09:17.794660       1 factory.go:734] Attempting to bind netserver-1 to e2e-test-peterhornyack-windows-node-group-rqkw
I0405 03:09:17.806600       1 scheduler.go:575] pod pod-network-test-2268/netserver-1 is bound successfully on node e2e-test-peterhornyack-windows-node-group-rqkw, 4 nodes evaluated, 1 nodes were found feasible
I0405 03:09:27.362889       1 wrap.go:47] GET /healthz: (96.295µs) 200 [kube-probe/1.15+ 127.0.0.1:43400]
I0405 03:09:36.049913       1 scheduling_queue.go:895] About to try and schedule pod pod-network-test-2268/test-container-pod
I0405 03:09:36.049944       1 scheduler.go:454] Attempting to schedule pod: pod-network-test-2268/test-container-pod
I0405 03:09:36.051261       1 scheduler_binder.go:255] AssumePodVolumes for pod "pod-network-test-2268/test-container-pod", node "e2e-test-peterhornyack-windows-node-group-lkqs"
I0405 03:09:36.051275       1 scheduler_binder.go:265] AssumePodVolumes for pod "pod-network-test-2268/test-container-pod", node "e2e-test-peterhornyack-windows-node-group-lkqs": all PVCs bound and nothing to do
I0405 03:09:36.051335       1 factory.go:734] Attempting to bind test-container-pod to e2e-test-peterhornyack-windows-node-group-lkqs
I0405 03:09:36.059079       1 scheduler.go:575] pod pod-network-test-2268/test-container-pod is bound successfully on node e2e-test-peterhornyack-windows-node-group-lkqs, 4 nodes evaluated, 2 nodes were found feasible
I0405 03:09:36.096236       1 scheduling_queue.go:895] About to try and schedule pod pod-network-test-2268/host-test-container-pod
I0405 03:09:36.096247       1 scheduler.go:454] Attempting to schedule pod: pod-network-test-2268/host-test-container-pod
I0405 03:09:36.096794       1 scheduler_binder.go:255] AssumePodVolumes for pod "pod-network-test-2268/host-test-container-pod", node "e2e-test-peterhornyack-windows-node-group-lkqs"
I0405 03:09:36.096806       1 scheduler_binder.go:265] AssumePodVolumes for pod "pod-network-test-2268/host-test-container-pod", node "e2e-test-peterhornyack-windows-node-group-lkqs": all PVCs bound and nothing to do
I0405 03:09:36.096836       1 factory.go:734] Attempting to bind host-test-container-pod to e2e-test-peterhornyack-windows-node-group-lkqs
I0405 03:09:36.103484       1 scheduler.go:575] pod pod-network-test-2268/host-test-container-pod is bound successfully on node e2e-test-peterhornyack-windows-node-group-lkqs, 4 nodes evaluated, 2 nodes were found feasible
I0405 03:09:37.365583       1 wrap.go:47] GET /healthz: (71.943µs) 200 [kube-probe/1.15+ 127.0.0.1:43434]
I0405 03:09:38.599123       1 reflector.go:384] k8s.io/client-go/informers/factory.go:133: Watch close - *v1.ReplicationController total 15 items received
I0405 03:09:47.363213       1 wrap.go:47] GET /healthz: (57.368µs) 200 [kube-probe/1.15+ 127.0.0.1:43468]
I0405 03:09:54.577171       1 reflector.go:384] k8s.io/kubernetes/cmd/kube-scheduler/app/server.go:223: Watch close - *v1.Pod total 171 items received
I0405 03:09:57.363740       1 wrap.go:47] GET /healthz: (136.145µs) 200 [kube-probe/1.15+ 127.0.0.1:43502]
I0405 03:10:07.364359       1 wrap.go:47] GET /healthz: (106.553µs) 200 [kube-probe/1.15+ 127.0.0.1:43538]
I0405 03:10:14.113402       1 scheduling_queue.go:895] About to try and schedule pod container-probe-155/liveness-http
I0405 03:10:14.113416       1 scheduler.go:454] Attempting to schedule pod: container-probe-155/liveness-http
I0405 03:10:14.113842       1 scheduler_binder.go:255] AssumePodVolumes for pod "container-probe-155/liveness-http", node "e2e-test-peterhornyack-windows-node-group-lkqs"
I0405 03:10:14.113854       1 scheduler_binder.go:265] AssumePodVolumes for pod "container-probe-155/liveness-http", node "e2e-test-peterhornyack-windows-node-group-lkqs": all PVCs bound and nothing to do
I0405 03:10:14.113931       1 factory.go:734] Attempting to bind liveness-http to e2e-test-peterhornyack-windows-node-group-lkqs
I0405 03:10:14.121391       1 scheduler.go:575] pod container-probe-155/liveness-http is bound successfully on node e2e-test-peterhornyack-windows-node-group-lkqs, 4 nodes evaluated, 2 nodes were found feasible
I0405 03:10:17.363750       1 wrap.go:47] GET /healthz: (153.94µs) 200 [kube-probe/1.15+ 127.0.0.1:43574]
I0405 03:10:25.578676       1 reflector.go:384] k8s.io/client-go/informers/factory.go:133: Watch close - *v1beta1.PodDisruptionBudget total 0 items received
I0405 03:10:27.363231       1 wrap.go:47] GET /healthz: (72.28µs) 200 [kube-probe/1.15+ 127.0.0.1:43624]
I0405 03:10:37.364283       1 wrap.go:47] GET /healthz: (77.578µs) 200 [kube-probe/1.15+ 127.0.0.1:43660]
I0405 03:10:47.365659       1 wrap.go:47] GET /healthz: (79.567µs) 200 [kube-probe/1.15+ 127.0.0.1:43692]
I0405 03:10:56.929777       1 scheduling_queue.go:895] About to try and schedule pod container-probe-1087/liveness-http
I0405 03:10:56.929793       1 scheduler.go:454] Attempting to schedule pod: container-probe-1087/liveness-http
I0405 03:10:56.930198       1 scheduler_binder.go:255] AssumePodVolumes for pod "container-probe-1087/liveness-http", node "e2e-test-peterhornyack-windows-node-group-lkqs"
I0405 03:10:56.930209       1 scheduler_binder.go:265] AssumePodVolumes for pod "container-probe-1087/liveness-http", node "e2e-test-peterhornyack-windows-node-group-lkqs": all PVCs bound and nothing to do
I0405 03:10:56.930267       1 factory.go:734] Attempting to bind liveness-http to e2e-test-peterhornyack-windows-node-group-lkqs
I0405 03:10:56.939251       1 scheduler.go:575] pod container-probe-1087/liveness-http is bound successfully on node e2e-test-peterhornyack-windows-node-group-lkqs, 4 nodes evaluated, 2 nodes were found feasible
I0405 03:10:57.363148       1 wrap.go:47] GET /healthz: (88.262µs) 200 [kube-probe/1.15+ 127.0.0.1:43724]
I0405 03:11:07.363061       1 wrap.go:47] GET /healthz: (76.982µs) 200 [kube-probe/1.15+ 127.0.0.1:43760]
I0405 03:11:17.363284       1 wrap.go:47] GET /healthz: (100.683µs) 200 [kube-probe/1.15+ 127.0.0.1:43796]
I0405 03:11:26.593286       1 reflector.go:384] k8s.io/client-go/informers/factory.go:133: Watch close - *v1.ReplicaSet total 0 items received
I0405 03:11:27.363257       1 wrap.go:47] GET /healthz: (80.819µs) 200 [kube-probe/1.15+ 127.0.0.1:43844]
I0405 03:11:29.586361       1 reflector.go:384] k8s.io/client-go/informers/factory.go:133: Watch close - *v1.Service total 0 items received
I0405 03:11:37.362845       1 wrap.go:47] GET /healthz: (77.629µs) 200 [kube-probe/1.15+ 127.0.0.1:43878]
I0405 03:11:47.363635       1 wrap.go:47] GET /healthz: (240.652µs) 200 [kube-probe/1.15+ 127.0.0.1:43912]
I0405 03:11:57.362975       1 wrap.go:47] GET /healthz: (98.624µs) 200 [kube-probe/1.15+ 127.0.0.1:43944]
I0405 03:12:07.363299       1 wrap.go:47] GET /healthz: (143.214µs) 200 [kube-probe/1.15+ 127.0.0.1:43982]
I0405 03:12:17.363280       1 wrap.go:47] GET /healthz: (69.211µs) 200 [kube-probe/1.15+ 127.0.0.1:44018]
I0405 03:12:27.362798       1 wrap.go:47] GET /healthz: (74.627µs) 200 [kube-probe/1.15+ 127.0.0.1:44066]
I0405 03:12:37.363152       1 wrap.go:47] GET /healthz: (62.873µs) 200 [kube-probe/1.15+ 127.0.0.1:44100]
I0405 03:12:47.363895       1 wrap.go:47] GET /healthz: (79.382µs) 200 [kube-probe/1.15+ 127.0.0.1:44132]
I0405 03:12:57.363191       1 wrap.go:47] GET /healthz: (80.292µs) 200 [kube-probe/1.15+ 127.0.0.1:44166]
I0405 03:12:59.573677       1 reflector.go:384] k8s.io/client-go/informers/factory.go:133: Watch close - *v1.PersistentVolume total 0 items received
I0405 03:13:07.363024       1 wrap.go:47] GET /healthz: (93.217µs) 200 [kube-probe/1.15+ 127.0.0.1:44202]
I0405 03:13:17.363070       1 wrap.go:47] GET /healthz: (80.945µs) 200 [kube-probe/1.15+ 127.0.0.1:44238]
I0405 03:13:23.603636       1 reflector.go:384] k8s.io/client-go/informers/factory.go:133: Watch close - *v1.StorageClass total 0 items received
I0405 03:13:27.364169       1 wrap.go:47] GET /healthz: (87.725µs) 200 [kube-probe/1.15+ 127.0.0.1:44286]
I0405 03:13:37.363233       1 wrap.go:47] GET /healthz: (81.064µs) 200 [kube-probe/1.15+ 127.0.0.1:44322]
I0405 03:13:38.580314       1 reflector.go:384] k8s.io/client-go/informers/factory.go:133: Watch close - *v1.Node total 26 items received
I0405 03:13:38.582672       1 reflector.go:384] k8s.io/client-go/informers/factory.go:133: Watch close - *v1.PersistentVolumeClaim total 0 items received
I0405 03:13:47.362897       1 wrap.go:47] GET /healthz: (69.76µs) 200 [kube-probe/1.15+ 127.0.0.1:44354]
I0405 03:13:57.362794       1 wrap.go:47] GET /healthz: (47.423µs) 200 [kube-probe/1.15+ 127.0.0.1:44386]
I0405 03:14:07.363041       1 wrap.go:47] GET /healthz: (104.16µs) 200 [kube-probe/1.15+ 127.0.0.1:44422]
I0405 03:14:17.363704       1 wrap.go:47] GET /healthz: (87.785µs) 200 [kube-probe/1.15+ 127.0.0.1:44460]
I0405 03:14:27.363189       1 wrap.go:47] GET /healthz: (48.437µs) 200 [kube-probe/1.15+ 127.0.0.1:44508]
I0405 03:14:37.363026       1 wrap.go:47] GET /healthz: (92.573µs) 200 [kube-probe/1.15+ 127.0.0.1:44542]
I0405 03:14:47.367481       1 wrap.go:47] GET /healthz: (96.767µs) 200 [kube-probe/1.15+ 127.0.0.1:44574]
I0405 03:14:54.601644       1 reflector.go:384] k8s.io/client-go/informers/factory.go:133: Watch close - *v1.StatefulSet total 0 items received
I0405 03:14:57.363057       1 wrap.go:47] GET /healthz: (80.054µs) 200 [kube-probe/1.15+ 127.0.0.1:44606]
I0405 03:15:07.363059       1 wrap.go:47] GET /healthz: (78.017µs) 200 [kube-probe/1.15+ 127.0.0.1:44644]
I0405 03:15:14.127791       1 scheduling_queue.go:895] About to try and schedule pod downward-api-8398/downwardapi-volume-8788ad03-ba2e-4467-b48c-83d4145cb247
I0405 03:15:14.127806       1 scheduler.go:454] Attempting to schedule pod: downward-api-8398/downwardapi-volume-8788ad03-ba2e-4467-b48c-83d4145cb247
I0405 03:15:14.129697       1 scheduler_binder.go:255] AssumePodVolumes for pod "downward-api-8398/downwardapi-volume-8788ad03-ba2e-4467-b48c-83d4145cb247", node "e2e-test-peterhornyack-windows-node-group-rqkw"
I0405 03:15:14.129723       1 scheduler_binder.go:265] AssumePodVolumes for pod "downward-api-8398/downwardapi-volume-8788ad03-ba2e-4467-b48c-83d4145cb247", node "e2e-test-peterhornyack-windows-node-group-rqkw": all PVCs bound and nothing to do
I0405 03:15:14.129807       1 factory.go:734] Attempting to bind downwardapi-volume-8788ad03-ba2e-4467-b48c-83d4145cb247 to e2e-test-peterhornyack-windows-node-group-rqkw
I0405 03:15:14.141161       1 scheduler.go:575] pod downward-api-8398/downwardapi-volume-8788ad03-ba2e-4467-b48c-83d4145cb247 is bound successfully on node e2e-test-peterhornyack-windows-node-group-rqkw, 4 nodes evaluated, 2 nodes were found feasible
I0405 03:15:17.363117       1 wrap.go:47] GET /healthz: (85.677µs) 200 [kube-probe/1.15+ 127.0.0.1:44680]
I0405 03:15:27.363636       1 wrap.go:47] GET /healthz: (79.41µs) 200 [kube-probe/1.15+ 127.0.0.1:44728]
I0405 03:15:30.571609       1 scheduling_queue.go:895] About to try and schedule pod events-1912/send-events-dfefe23f-4611-46f4-ae63-017bdef2ce99
I0405 03:15:30.572479       1 scheduler.go:454] Attempting to schedule pod: events-1912/send-events-dfefe23f-4611-46f4-ae63-017bdef2ce99
I0405 03:15:30.572960       1 scheduler_binder.go:255] AssumePodVolumes for pod "events-1912/send-events-dfefe23f-4611-46f4-ae63-017bdef2ce99", node "e2e-test-peterhornyack-windows-node-group-lkqs"
I0405 03:15:30.572981       1 scheduler_binder.go:265] AssumePodVolumes for pod "events-1912/send-events-dfefe23f-4611-46f4-ae63-017bdef2ce99", node "e2e-test-peterhornyack-windows-node-group-lkqs": all PVCs bound and nothing to do
I0405 03:15:30.573046       1 factory.go:734] Attempting to bind send-events-dfefe23f-4611-46f4-ae63-017bdef2ce99 to e2e-test-peterhornyack-windows-node-group-lkqs
I0405 03:15:30.581618       1 scheduler.go:575] pod events-1912/send-events-dfefe23f-4611-46f4-ae63-017bdef2ce99 is bound successfully on node e2e-test-peterhornyack-windows-node-group-lkqs, 4 nodes evaluated, 2 nodes were found feasible
I0405 03:15:37.363147       1 wrap.go:47] GET /healthz: (93.075µs) 200 [kube-probe/1.15+ 127.0.0.1:44766]
I0405 03:15:47.363633       1 wrap.go:47] GET /healthz: (119.661µs) 200 [kube-probe/1.15+ 127.0.0.1:44798]
I0405 03:15:53.307282       1 scheduling_queue.go:895] About to try and schedule pod kubectl-2689/redis-master-4dlf6
I0405 03:15:53.307296       1 scheduler.go:454] Attempting to schedule pod: kubectl-2689/redis-master-4dlf6
I0405 03:15:53.307705       1 scheduler_binder.go:255] AssumePodVolumes for pod "kubectl-2689/redis-master-4dlf6", node "e2e-test-peterhornyack-windows-node-group-lkqs"
I0405 03:15:53.307715       1 scheduler_binder.go:265] AssumePodVolumes for pod "kubectl-2689/redis-master-4dlf6", node "e2e-test-peterhornyack-windows-node-group-lkqs": all PVCs bound and nothing to do
I0405 03:15:53.307775       1 factory.go:734] Attempting to bind redis-master-4dlf6 to e2e-test-peterhornyack-windows-node-group-lkqs
I0405 03:15:53.327133       1 scheduler.go:575] pod kubectl-2689/redis-master-4dlf6 is bound successfully on node e2e-test-peterhornyack-windows-node-group-lkqs, 4 nodes evaluated, 2 nodes were found feasible
I0405 03:15:57.363144       1 wrap.go:47] GET /healthz: (82.478µs) 200 [kube-probe/1.15+ 127.0.0.1:44830]
I0405 03:16:07.363281       1 wrap.go:47] GET /healthz: (82.576µs) 200 [kube-probe/1.15+ 127.0.0.1:44866]
I0405 03:16:14.613724       1 scheduling_queue.go:895] About to try and schedule pod pods-6663/pod-hostip-c38ed9a0-547b-4a46-961b-607c46eaaeb8
I0405 03:16:14.613738       1 scheduler.go:454] Attempting to schedule pod: pods-6663/pod-hostip-c38ed9a0-547b-4a46-961b-607c46eaaeb8
I0405 03:16:14.614037       1 scheduler_binder.go:255] AssumePodVolumes for pod "pods-6663/pod-hostip-c38ed9a0-547b-4a46-961b-607c46eaaeb8", node "e2e-test-peterhornyack-windows-node-group-rqkw"
I0405 03:16:14.614048       1 scheduler_binder.go:265] AssumePodVolumes for pod "pods-6663/pod-hostip-c38ed9a0-547b-4a46-961b-607c46eaaeb8", node "e2e-test-peterhornyack-windows-node-group-rqkw": all PVCs bound and nothing to do
I0405 03:16:14.614086       1 factory.go:734] Attempting to bind pod-hostip-c38ed9a0-547b-4a46-961b-607c46eaaeb8 to e2e-test-peterhornyack-windows-node-group-rqkw
I0405 03:16:14.624285       1 scheduler.go:575] pod pods-6663/pod-hostip-c38ed9a0-547b-4a46-961b-607c46eaaeb8 is bound successfully on node e2e-test-peterhornyack-windows-node-group-rqkw, 4 nodes evaluated, 2 nodes were found feasible
I0405 03:16:17.362959       1 wrap.go:47] GET /healthz: (80.786µs) 200 [kube-probe/1.15+ 127.0.0.1:44902]
I0405 03:16:27.364266       1 wrap.go:47] GET /healthz: (81.127µs) 200 [kube-probe/1.15+ 127.0.0.1:44950]
I0405 03:16:37.363167       1 wrap.go:47] GET /healthz: (83.009µs) 200 [kube-probe/1.15+ 127.0.0.1:44986]
I0405 03:16:46.808247       1 scheduling_queue.go:895] About to try and schedule pod pods-5156/pod-logs-websocket-2c182175-cfe9-4e80-9aa1-fb94f2643e95
I0405 03:16:46.808282       1 scheduler.go:454] Attempting to schedule pod: pods-5156/pod-logs-websocket-2c182175-cfe9-4e80-9aa1-fb94f2643e95
I0405 03:16:46.808607       1 scheduler_binder.go:255] AssumePodVolumes for pod "pods-5156/pod-logs-websocket-2c182175-cfe9-4e80-9aa1-fb94f2643e95", node "e2e-test-peterhornyack-windows-node-group-lkqs"
I0405 03:16:46.808619       1 scheduler_binder.go:265] AssumePodVolumes for pod "pods-5156/pod-logs-websocket-2c182175-cfe9-4e80-9aa1-fb94f2643e95", node "e2e-test-peterhornyack-windows-node-group-lkqs": all PVCs bound and nothing to do
I0405 03:16:46.808665       1 factory.go:734] Attempting to bind pod-logs-websocket-2c182175-cfe9-4e80-9aa1-fb94f2643e95 to e2e-test-peterhornyack-windows-node-group-lkqs
I0405 03:16:46.815389       1 scheduler.go:575] pod pods-5156/pod-logs-websocket-2c182175-cfe9-4e80-9aa1-fb94f2643e95 is bound successfully on node e2e-test-peterhornyack-windows-node-group-lkqs, 4 nodes evaluated, 2 nodes were found feasible
I0405 03:16:47.363862       1 wrap.go:47] GET /healthz: (80.41µs) 200 [kube-probe/1.15+ 127.0.0.1:45020]
I0405 03:16:57.363486       1 wrap.go:47] GET /healthz: (82.173µs) 200 [kube-probe/1.15+ 127.0.0.1:45052]
I0405 03:17:07.362955       1 wrap.go:47] GET /healthz: (79.013µs) 200 [kube-probe/1.15+ 127.0.0.1:45088]
I0405 03:17:17.362663       1 wrap.go:47] GET /healthz: (70.352µs) 200 [kube-probe/1.15+ 127.0.0.1:45124]
I0405 03:17:22.580533       1 reflector.go:384] k8s.io/client-go/informers/factory.go:133: Watch close - *v1beta1.PodDisruptionBudget total 0 items received
I0405 03:17:27.363101       1 wrap.go:47] GET /healthz: (82.095µs) 200 [kube-probe/1.15+ 127.0.0.1:45172]
I0405 03:17:27.618693       1 scheduling_queue.go:895] About to try and schedule pod kubectl-1489/e2e-test-nginx-rc-s4ht7
I0405 03:17:27.618709       1 scheduler.go:454] Attempting to schedule pod: kubectl-1489/e2e-test-nginx-rc-s4ht7
I0405 03:17:27.619368       1 scheduler_binder.go:255] AssumePodVolumes for pod "kubectl-1489/e2e-test-nginx-rc-s4ht7", node "e2e-test-peterhornyack-windows-node-group-lkqs"
I0405 03:17:27.619381       1 scheduler_binder.go:265] AssumePodVolumes for pod "kubectl-1489/e2e-test-nginx-rc-s4ht7", node "e2e-test-peterhornyack-windows-node-group-lkqs": all PVCs bound and nothing to do
I0405 03:17:27.622078       1 factory.go:734] Attempting to bind e2e-test-nginx-rc-s4ht7 to e2e-test-peterhornyack-windows-node-group-lkqs
I0405 03:17:27.635997       1 scheduler.go:575] pod kubectl-1489/e2e-test-nginx-rc-s4ht7 is bound successfully on node e2e-test-peterhornyack-windows-node-group-lkqs, 4 nodes evaluated, 2 nodes were found feasible
I0405 03:17:28.902263       1 scheduling_queue.go:895] About to try and schedule pod kubectl-1489/e2e-test-nginx-rc-2cb6753b50179f2d0e29ad10434dad58-cz76z
I0405 03:17:28.902278       1 scheduler.go:454] Attempting to schedule pod: kubectl-1489/e2e-test-nginx-rc-2cb6753b50179f2d0e29ad10434dad58-cz76z
I0405 03:17:28.905031       1 scheduler_binder.go:255] AssumePodVolumes for pod "kubectl-1489/e2e-test-nginx-rc-2cb6753b50179f2d0e29ad10434dad58-cz76z", node "e2e-test-peterhornyack-windows-node-group-lkqs"
I0405 03:17:28.905050       1 scheduler_binder.go:265] AssumePodVolumes for pod "kubectl-1489/e2e-test-nginx-rc-2cb6753b50179f2d0e29ad10434dad58-cz76z", node "e2e-test-peterhornyack-windows-node-group-lkqs": all PVCs bound and nothing to do
I0405 03:17:28.908117       1 factory.go:734] Attempting to bind e2e-test-nginx-rc-2cb6753b50179f2d0e29ad10434dad58-cz76z to e2e-test-peterhornyack-windows-node-group-lkqs
I0405 03:17:28.931350       1 scheduler.go:575] pod kubectl-1489/e2e-test-nginx-rc-2cb6753b50179f2d0e29ad10434dad58-cz76z is bound successfully on node e2e-test-peterhornyack-windows-node-group-lkqs, 4 nodes evaluated, 2 nodes were found feasible
I0405 03:17:37.363213       1 wrap.go:47] GET /healthz: (74.058µs) 200 [kube-probe/1.15+ 127.0.0.1:45206]
I0405 03:17:44.588483       1 reflector.go:384] k8s.io/client-go/informers/factory.go:133: Watch close - *v1.Service total 0 items received
I0405 03:17:47.363135       1 wrap.go:47] GET /healthz: (91.407µs) 200 [kube-probe/1.15+ 127.0.0.1:45238]
I0405 03:17:57.363005       1 wrap.go:47] GET /healthz: (119.033µs) 200 [kube-probe/1.15+ 127.0.0.1:45270]
I0405 03:18:01.601407       1 reflector.go:384] k8s.io/client-go/informers/factory.go:133: Watch close - *v1.ReplicationController total 35 items received
I0405 03:18:07.362964       1 wrap.go:47] GET /healthz: (100.228µs) 200 [kube-probe/1.15+ 127.0.0.1:45310]
I0405 03:18:16.607220       1 scheduling_queue.go:895] About to try and schedule pod containers-6431/client-containers-3a61cbe6-9476-4981-a641-65a6986ca93f
I0405 03:18:16.607235       1 scheduler.go:454] Attempting to schedule pod: containers-6431/client-containers-3a61cbe6-9476-4981-a641-65a6986ca93f
I0405 03:18:16.610270       1 scheduler_binder.go:255] AssumePodVolumes for pod "containers-6431/client-containers-3a61cbe6-9476-4981-a641-65a6986ca93f", node "e2e-test-peterhornyack-windows-node-group-rqkw"
I0405 03:18:16.610313       1 scheduler_binder.go:265] AssumePodVolumes for pod "containers-6431/client-containers-3a61cbe6-9476-4981-a641-65a6986ca93f", node "e2e-test-peterhornyack-windows-node-group-rqkw": all PVCs bound and nothing to do
I0405 03:18:16.610368       1 factory.go:734] Attempting to bind client-containers-3a61cbe6-9476-4981-a641-65a6986ca93f to e2e-test-peterhornyack-windows-node-group-rqkw
I0405 03:18:16.618680       1 scheduler.go:575] pod containers-6431/client-containers-3a61cbe6-9476-4981-a641-65a6986ca93f is bound successfully on node e2e-test-peterhornyack-windows-node-group-rqkw, 4 nodes evaluated, 2 nodes were found feasible
I0405 03:18:17.363125       1 wrap.go:47] GET /healthz: (79.526µs) 200 [kube-probe/1.15+ 127.0.0.1:45346]
I0405 03:18:27.363022       1 wrap.go:47] GET /healthz: (94.991µs) 200 [kube-probe/1.15+ 127.0.0.1:45394]
I0405 03:18:37.232697       1 scheduling_queue.go:895] About to try and schedule pod emptydir-wrapper-1360/pod-secrets-8125d053-475c-40e2-b6e3-ea673a6a3ee1
I0405 03:18:37.232710       1 scheduler.go:454] Attempting to schedule pod: emptydir-wrapper-1360/pod-secrets-8125d053-475c-40e2-b6e3-ea673a6a3ee1
I0405 03:18:37.233674       1 scheduler_binder.go:255] AssumePodVolumes for pod "emptydir-wrapper-1360/pod-secrets-8125d053-475c-40e2-b6e3-ea673a6a3ee1", node "e2e-test-peterhornyack-windows-node-group-lkqs"
I0405 03:18:37.233687       1 scheduler_binder.go:265] AssumePodVolumes for pod "emptydir-wrapper-1360/pod-secrets-8125d053-475c-40e2-b6e3-ea673a6a3ee1", node "e2e-test-peterhornyack-windows-node-group-lkqs": all PVCs bound and nothing to do
I0405 03:18:37.234909       1 factory.go:734] Attempting to bind pod-secrets-8125d053-475c-40e2-b6e3-ea673a6a3ee1 to e2e-test-peterhornyack-windows-node-group-lkqs
I0405 03:18:37.240347       1 scheduler.go:575] pod emptydir-wrapper-1360/pod-secrets-8125d053-475c-40e2-b6e3-ea673a6a3ee1 is bound successfully on node e2e-test-peterhornyack-windows-node-group-lkqs, 4 nodes evaluated, 2 nodes were found feasible
I0405 03:18:37.362883       1 wrap.go:47] GET /healthz: (73.102µs) 200 [kube-probe/1.15+ 127.0.0.1:45428]
I0405 03:18:47.362984       1 wrap.go:47] GET /healthz: (86.474µs) 200 [kube-probe/1.15+ 127.0.0.1:45460]
I0405 03:18:47.595467       1 reflector.go:384] k8s.io/client-go/informers/factory.go:133: Watch close - *v1.ReplicaSet total 0 items received
I0405 03:18:49.583203       1 reflector.go:384] k8s.io/client-go/informers/factory.go:133: Watch close - *v1.Node total 26 items received
I0405 03:18:53.635712       1 scheduling_queue.go:895] About to try and schedule pod containers-7005/client-containers-dfa3f33e-f92c-4271-a146-4169f65ce240
I0405 03:18:53.635726       1 scheduler.go:454] Attempting to schedule pod: containers-7005/client-containers-dfa3f33e-f92c-4271-a146-4169f65ce240
I0405 03:18:53.636097       1 scheduler_binder.go:255] AssumePodVolumes for pod "containers-7005/client-containers-dfa3f33e-f92c-4271-a146-4169f65ce240", node "e2e-test-peterhornyack-windows-node-group-rqkw"
I0405 03:18:53.636111       1 scheduler_binder.go:265] AssumePodVolumes for pod "containers-7005/client-containers-dfa3f33e-f92c-4271-a146-4169f65ce240", node "e2e-test-peterhornyack-windows-node-group-rqkw": all PVCs bound and nothing to do
I0405 03:18:53.636506       1 factory.go:734] Attempting to bind client-containers-dfa3f33e-f92c-4271-a146-4169f65ce240 to e2e-test-peterhornyack-windows-node-group-rqkw
I0405 03:18:53.646102       1 scheduler.go:575] pod containers-7005/client-containers-dfa3f33e-f92c-4271-a146-4169f65ce240 is bound successfully on node e2e-test-peterhornyack-windows-node-group-rqkw, 4 nodes evaluated, 2 nodes were found feasible
I0405 03:18:57.363033       1 wrap.go:47] GET /healthz: (100.775µs) 200 [kube-probe/1.15+ 127.0.0.1:45492]
I0405 03:19:02.583749       1 reflector.go:384] k8s.io/kubernetes/cmd/kube-scheduler/app/server.go:223: Watch close - *v1.Pod total 91 items received
I0405 03:19:07.363644       1 wrap.go:47] GET /healthz: (279.589µs) 200 [kube-probe/1.15+ 127.0.0.1:45528]
I0405 03:19:14.160767       1 scheduling_queue.go:895] About to try and schedule pod downward-api-8744/downwardapi-volume-ff3d1b30-9829-4bd6-b13f-a17f804f4295
I0405 03:19:14.160781       1 scheduler.go:454] Attempting to schedule pod: downward-api-8744/downwardapi-volume-ff3d1b30-9829-4bd6-b13f-a17f804f4295
I0405 03:19:14.161832       1 scheduler_binder.go:255] AssumePodVolumes for pod "downward-api-8744/downwardapi-volume-ff3d1b30-9829-4bd6-b13f-a17f804f4295", node "e2e-test-peterhornyack-windows-node-group-rqkw"
I0405 03:19:14.163894       1 scheduler_binder.go:265] AssumePodVolumes for pod "downward-api-8744/downwardapi-volume-ff3d1b30-9829-4bd6-b13f-a17f804f4295", node "e2e-test-peterhornyack-windows-node-group-rqkw": all PVCs bound and nothing to do
I0405 03:19:14.163978       1 factory.go:734] Attempting to bind downwardapi-volume-ff3d1b30-9829-4bd6-b13f-a17f804f4295 to e2e-test-peterhornyack-windows-node-group-rqkw
I0405 03:19:14.169608       1 scheduler.go:575] pod downward-api-8744/downwardapi-volume-ff3d1b30-9829-4bd6-b13f-a17f804f4295 is bound successfully on node e2e-test-peterhornyack-windows-node-group-rqkw, 4 nodes evaluated, 2 nodes were found feasible
I0405 03:19:17.366044       1 wrap.go:47] GET /healthz: (2.50258ms) 200 [kube-probe/1.15+ 127.0.0.1:45566]
I0405 03:19:17.580550       1 reflector.go:384] k8s.io/client-go/informers/factory.go:133: Watch close - *v1.PersistentVolume total 0 items received
I0405 03:19:27.364688       1 wrap.go:47] GET /healthz: (71.15µs) 200 [kube-probe/1.15+ 127.0.0.1:45614]
I0405 03:19:37.362693       1 wrap.go:47] GET /healthz: (49.865µs) 200 [kube-probe/1.15+ 127.0.0.1:45650]
I0405 03:19:39.041845       1 scheduling_queue.go:895] About to try and schedule pod downward-api-7171/downwardapi-volume-4d73a37f-a976-483e-bbd0-7f7f1e780584
I0405 03:19:39.041862       1 scheduler.go:454] Attempting to schedule pod: downward-api-7171/downwardapi-volume-4d73a37f-a976-483e-bbd0-7f7f1e780584
I0405 03:19:39.042400       1 scheduler_binder.go:255] AssumePodVolumes for pod "downward-api-7171/downwardapi-volume-4d73a37f-a976-483e-bbd0-7f7f1e780584", node "e2e-test-peterhornyack-windows-node-group-rqkw"
I0405 03:19:39.042417       1 scheduler_binder.go:265] AssumePodVolumes for pod "downward-api-7171/downwardapi-volume-4d73a37f-a976-483e-bbd0-7f7f1e780584", node "e2e-test-peterhornyack-windows-node-group-rqkw": all PVCs bound and nothing to do
I0405 03:19:39.042489       1 factory.go:734] Attempting to bind downwardapi-volume-4d73a37f-a976-483e-bbd0-7f7f1e780584 to e2e-test-peterhornyack-windows-node-group-rqkw
I0405 03:19:39.052273       1 scheduler.go:575] pod downward-api-7171/downwardapi-volume-4d73a37f-a976-483e-bbd0-7f7f1e780584 is bound successfully on node e2e-test-peterhornyack-windows-node-group-rqkw, 4 nodes evaluated, 2 nodes were found feasible
I0405 03:19:47.363001       1 wrap.go:47] GET /healthz: (107.822µs) 200 [kube-probe/1.15+ 127.0.0.1:45684]
I0405 03:19:55.518356       1 scheduling_queue.go:895] About to try and schedule pod configmap-8492/pod-configmaps-2793c656-8812-43b6-b12d-f59895ac511a
I0405 03:19:55.518369       1 scheduler.go:454] Attempting to schedule pod: configmap-8492/pod-configmaps-2793c656-8812-43b6-b12d-f59895ac511a
I0405 03:19:55.520298       1 scheduler_binder.go:255] AssumePodVolumes for pod "configmap-8492/pod-configmaps-2793c656-8812-43b6-b12d-f59895ac511a", node "e2e-test-peterhornyack-windows-node-group-lkqs"
I0405 03:19:55.520310       1 scheduler_binder.go:265] AssumePodVolumes for pod "configmap-8492/pod-configmaps-2793c656-8812-43b6-b12d-f59895ac511a", node "e2e-test-peterhornyack-windows-node-group-lkqs": all PVCs bound and nothing to do
I0405 03:19:55.520372       1 factory.go:734] Attempting to bind pod-configmaps-2793c656-8812-43b6-b12d-f59895ac511a to e2e-test-peterhornyack-windows-node-group-lkqs
I0405 03:19:55.528102       1 scheduler.go:575] pod configmap-8492/pod-configmaps-2793c656-8812-43b6-b12d-f59895ac511a is bound successfully on node e2e-test-peterhornyack-windows-node-group-lkqs, 4 nodes evaluated, 2 nodes were found feasible
I0405 03:19:57.362962       1 wrap.go:47] GET /healthz: (92.537µs) 200 [kube-probe/1.15+ 127.0.0.1:45716]
I0405 03:20:07.362916       1 wrap.go:47] GET /healthz: (97.155µs) 200 [kube-probe/1.15+ 127.0.0.1:45752]
I0405 03:20:11.949817       1 scheduling_queue.go:895] About to try and schedule pod containers-89/client-containers-901da834-e43d-4930-b5da-676ffdfd12de
I0405 03:20:11.949831       1 scheduler.go:454] Attempting to schedule pod: containers-89/client-containers-901da834-e43d-4930-b5da-676ffdfd12de
I0405 03:20:11.951185       1 scheduler_binder.go:255] AssumePodVolumes for pod "containers-89/client-containers-901da834-e43d-4930-b5da-676ffdfd12de", node "e2e-test-peterhornyack-windows-node-group-rqkw"
I0405 03:20:11.951202       1 scheduler_binder.go:265] AssumePodVolumes for pod "containers-89/client-containers-901da834-e43d-4930-b5da-676ffdfd12de", node "e2e-test-peterhornyack-windows-node-group-rqkw": all PVCs bound and nothing to do
I0405 03:20:11.951628       1 factory.go:734] Attempting to bind client-containers-901da834-e43d-4930-b5da-676ffdfd12de to e2e-test-peterhornyack-windows-node-group-rqkw
I0405 03:20:11.956341       1 scheduler.go:575] pod containers-89/client-containers-901da834-e43d-4930-b5da-676ffdfd12de is bound successfully on node e2e-test-peterhornyack-windows-node-group-rqkw, 4 nodes evaluated, 2 nodes were found feasible
I0405 03:20:17.364318       1 wrap.go:47] GET /healthz: (80.896µs) 200 [kube-probe/1.15+ 127.0.0.1:45788]
I0405 03:20:27.362958       1 wrap.go:47] GET /healthz: (99.542µs) 200 [kube-probe/1.15+ 127.0.0.1:45836]
I0405 03:20:30.432804       1 scheduling_queue.go:895] About to try and schedule pod hostpath-4110/pod-host-path-test
I0405 03:20:30.432817       1 scheduler.go:454] Attempting to schedule pod: hostpath-4110/pod-host-path-test
I0405 03:20:30.433128       1 scheduler_binder.go:255] AssumePodVolumes for pod "hostpath-4110/pod-host-path-test", node "e2e-test-peterhornyack-windows-node-group-rqkw"
I0405 03:20:30.433138       1 scheduler_binder.go:265] AssumePodVolumes for pod "hostpath-4110/pod-host-path-test", node "e2e-test-peterhornyack-windows-node-group-rqkw": all PVCs bound and nothing to do
I0405 03:20:30.433192       1 factory.go:734] Attempting to bind pod-host-path-test to e2e-test-peterhornyack-windows-node-group-rqkw
I0405 03:20:30.439063       1 scheduler.go:575] pod hostpath-4110/pod-host-path-test is bound successfully on node e2e-test-peterhornyack-windows-node-group-rqkw, 4 nodes evaluated, 2 nodes were found feasible
I0405 03:20:37.363113       1 wrap.go:47] GET /healthz: (76.248µs) 200 [kube-probe/1.15+ 127.0.0.1:45872]
I0405 03:20:47.362699       1 wrap.go:47] GET /healthz: (58.808µs) 200 [kube-probe/1.15+ 127.0.0.1:45904]
I0405 03:20:57.240996       1 scheduling_queue.go:895] About to try and schedule pod kubectl-3407/e2e-test-nginx-pod
I0405 03:20:57.241007       1 scheduler.go:454] Attempting to schedule pod: kubectl-3407/e2e-test-nginx-pod
I0405 03:20:57.241386       1 scheduler_binder.go:255] AssumePodVolumes for pod "kubectl-3407/e2e-test-nginx-pod", node "e2e-test-peterhornyack-windows-node-group-lkqs"
I0405 03:20:57.241396       1 scheduler_binder.go:265] AssumePodVolumes for pod "kubectl-3407/e2e-test-nginx-pod", node "e2e-test-peterhornyack-windows-node-group-lkqs": all PVCs bound and nothing to do
I0405 03:20:57.241456       1 factory.go:734] Attempting to bind e2e-test-nginx-pod to e2e-test-peterhornyack-windows-node-group-lkqs
I0405 03:20:57.246848       1 scheduler.go:575] pod kubectl-3407/e2e-test-nginx-pod is bound successfully on node e2e-test-peterhornyack-windows-node-group-lkqs, 4 nodes evaluated, 2 nodes were found feasible
I0405 03:20:57.362777       1 wrap.go:47] GET /healthz: (56.235µs) 200 [kube-probe/1.15+ 127.0.0.1:45936]
I0405 03:21:03.605655       1 reflector.go:384] k8s.io/client-go/informers/factory.go:133: Watch close - *v1.StorageClass total 0 items received
I0405 03:21:07.363270       1 wrap.go:47] GET /healthz: (79.489µs) 200 [kube-probe/1.15+ 127.0.0.1:45974]
I0405 03:21:07.423845       1 scheduling_queue.go:895] About to try and schedule pod dns-666/dns-test-d8eec429-f60c-4d2a-9976-db9773e41c63
I0405 03:21:07.423859       1 scheduler.go:454] Attempting to schedule pod: dns-666/dns-test-d8eec429-f60c-4d2a-9976-db9773e41c63
I0405 03:21:07.425774       1 scheduler_binder.go:255] AssumePodVolumes for pod "dns-666/dns-test-d8eec429-f60c-4d2a-9976-db9773e41c63", node "e2e-test-peterhornyack-windows-node-group-lkqs"
I0405 03:21:07.425801       1 scheduler_binder.go:265] AssumePodVolumes for pod "dns-666/dns-test-d8eec429-f60c-4d2a-9976-db9773e41c63", node "e2e-test-peterhornyack-windows-node-group-lkqs": all PVCs bound and nothing to do
I0405 03:21:07.425844       1 factory.go:734] Attempting to bind dns-test-d8eec429-f60c-4d2a-9976-db9773e41c63 to e2e-test-peterhornyack-windows-node-group-lkqs
I0405 03:21:07.433330       1 scheduler.go:575] pod dns-666/dns-test-d8eec429-f60c-4d2a-9976-db9773e41c63 is bound successfully on node e2e-test-peterhornyack-windows-node-group-lkqs, 4 nodes evaluated, 2 nodes were found feasible
I0405 03:21:17.363816       1 wrap.go:47] GET /healthz: (76.259µs) 200 [kube-probe/1.15+ 127.0.0.1:46010]
I0405 03:21:25.586416       1 reflector.go:384] k8s.io/client-go/informers/factory.go:133: Watch close - *v1.PersistentVolumeClaim total 0 items received
I0405 03:21:27.363870       1 wrap.go:47] GET /healthz: (78.77µs) 200 [kube-probe/1.15+ 127.0.0.1:46062]
I0405 03:21:30.182769       1 scheduling_queue.go:895] About to try and schedule pod hostpath-3227/pod-host-path-test
I0405 03:21:30.182807       1 scheduler.go:454] Attempting to schedule pod: hostpath-3227/pod-host-path-test
I0405 03:21:30.185491       1 scheduler_binder.go:255] AssumePodVolumes for pod "hostpath-3227/pod-host-path-test", node "e2e-test-peterhornyack-windows-node-group-rqkw"
I0405 03:21:30.185507       1 scheduler_binder.go:265] AssumePodVolumes for pod "hostpath-3227/pod-host-path-test", node "e2e-test-peterhornyack-windows-node-group-rqkw": all PVCs bound and nothing to do
I0405 03:21:30.185614       1 factory.go:734] Attempting to bind pod-host-path-test to e2e-test-peterhornyack-windows-node-group-rqkw
I0405 03:21:30.191973       1 scheduler.go:575] pod hostpath-3227/pod-host-path-test is bound successfully on node e2e-test-peterhornyack-windows-node-group-rqkw, 4 nodes evaluated, 2 nodes were found feasible
I0405 03:21:37.362857       1 wrap.go:47] GET /healthz: (78.493µs) 200 [kube-probe/1.15+ 127.0.0.1:46098]
I0405 03:21:47.363047       1 wrap.go:47] GET /healthz: (66.228µs) 200 [kube-probe/1.15+ 127.0.0.1:46130]
I0405 03:21:57.363728       1 wrap.go:47] GET /healthz: (61.563µs) 200 [kube-probe/1.15+ 127.0.0.1:46164]
I0405 03:22:03.152344       1 scheduling_queue.go:895] About to try and schedule pod statefulset-3256/ss-0
I0405 03:22:03.152360       1 scheduler.go:454] Attempting to schedule pod: statefulset-3256/ss-0
I0405 03:22:03.152779       1 scheduler_binder.go:255] AssumePodVolumes for pod "statefulset-3256/ss-0", node "e2e-test-peterhornyack-windows-node-group-lkqs"
I0405 03:22:03.152789       1 scheduler_binder.go:265] AssumePodVolumes for pod "statefulset-3256/ss-0", node "e2e-test-peterhornyack-windows-node-group-lkqs": all PVCs bound and nothing to do
I0405 03:22:03.152977       1 factory.go:734] Attempting to bind ss-0 to e2e-test-peterhornyack-windows-node-group-lkqs
I0405 03:22:03.163541       1 scheduler.go:575] pod statefulset-3256/ss-0 is bound successfully on node e2e-test-peterhornyack-windows-node-group-lkqs, 4 nodes evaluated, 2 nodes were found feasible
I0405 03:22:07.362968       1 wrap.go:47] GET /healthz: (87.775µs) 200 [kube-probe/1.15+ 127.0.0.1:46202]
I0405 03:22:17.363092       1 wrap.go:47] GET /healthz: (61.043µs) 200 [kube-probe/1.15+ 127.0.0.1:46244]
I0405 03:22:24.429881       1 scheduling_queue.go:895] About to try and schedule pod statefulset-3256/ss-1
I0405 03:22:24.429892       1 scheduler.go:454] Attempting to schedule pod: statefulset-3256/ss-1
I0405 03:22:24.430259       1 scheduler_binder.go:255] AssumePodVolumes for pod "statefulset-3256/ss-1", node "e2e-test-peterhornyack-windows-node-group-lkqs"
I0405 03:22:24.430269       1 scheduler_binder.go:265] AssumePodVolumes for pod "statefulset-3256/ss-1", node "e2e-test-peterhornyack-windows-node-group-lkqs": all PVCs bound and nothing to do
I0405 03:22:24.430319       1 factory.go:734] Attempting to bind ss-1 to e2e-test-peterhornyack-windows-node-group-lkqs
I0405 03:22:24.438859       1 scheduler.go:575] pod statefulset-3256/ss-1 is bound successfully on node e2e-test-peterhornyack-windows-node-group-lkqs, 4 nodes evaluated, 2 nodes were found feasible
I0405 03:22:24.451179       1 scheduling_queue.go:895] About to try and schedule pod statefulset-3256/ss-2
I0405 03:22:24.451209       1 scheduler.go:454] Attempting to schedule pod: statefulset-3256/ss-2
I0405 03:22:24.451501       1 scheduler_binder.go:255] AssumePodVolumes for pod "statefulset-3256/ss-2", node "e2e-test-peterhornyack-windows-node-group-lkqs"
I0405 03:22:24.451523       1 scheduler_binder.go:265] AssumePodVolumes for pod "statefulset-3256/ss-2", node "e2e-test-peterhornyack-windows-node-group-lkqs": all PVCs bound and nothing to do
I0405 03:22:24.451550       1 factory.go:734] Attempting to bind ss-2 to e2e-test-peterhornyack-windows-node-group-lkqs
I0405 03:22:24.462353       1 scheduler.go:575] pod statefulset-3256/ss-2 is bound successfully on node e2e-test-peterhornyack-windows-node-group-lkqs, 4 nodes evaluated, 2 nodes were found feasible
I0405 03:22:27.363725       1 wrap.go:47] GET /healthz: (90.243µs) 200 [kube-probe/1.15+ 127.0.0.1:46292]
I0405 03:22:37.363215       1 wrap.go:47] GET /healthz: (80.109µs) 200 [kube-probe/1.15+ 127.0.0.1:46334]
I0405 03:22:47.362987       1 wrap.go:47] GET /healthz: (101.301µs) 200 [kube-probe/1.15+ 127.0.0.1:46372]
I0405 03:22:57.362718       1 wrap.go:47] GET /healthz: (71.364µs) 200 [kube-probe/1.15+ 127.0.0.1:46404]
I0405 03:23:07.362901       1 wrap.go:47] GET /healthz: (51.698µs) 200 [kube-probe/1.15+ 127.0.0.1:46450]
I0405 03:23:17.362873       1 wrap.go:47] GET /healthz: (77.276µs) 200 [kube-probe/1.15+ 127.0.0.1:46490]
I0405 03:23:27.363195       1 wrap.go:47] GET /healthz: (80.663µs) 200 [kube-probe/1.15+ 127.0.0.1:46538]
I0405 03:23:32.603893       1 reflector.go:384] k8s.io/client-go/informers/factory.go:133: Watch close - *v1.StatefulSet total 17 items received
I0405 03:23:37.362916       1 wrap.go:47] GET /healthz: (77.229µs) 200 [kube-probe/1.15+ 127.0.0.1:46572]
I0405 03:23:47.363047       1 wrap.go:47] GET /healthz: (111.396µs) 200 [kube-probe/1.15+ 127.0.0.1:46604]
I0405 03:23:57.362697       1 wrap.go:47] GET /healthz: (84.312µs) 200 [kube-probe/1.15+ 127.0.0.1:46636]
I0405 03:24:07.362735       1 wrap.go:47] GET /healthz: (106.428µs) 200 [kube-probe/1.15+ 127.0.0.1:46674]
I0405 03:24:17.362887       1 wrap.go:47] GET /healthz: (81.159µs) 200 [kube-probe/1.15+ 127.0.0.1:46710]
I0405 03:24:27.363169       1 wrap.go:47] GET /healthz: (81.653µs) 200 [kube-probe/1.15+ 127.0.0.1:46760]
I0405 03:24:27.582650       1 reflector.go:384] k8s.io/client-go/informers/factory.go:133: Watch close - *v1beta1.PodDisruptionBudget total 0 items received
I0405 03:24:37.363501       1 wrap.go:47] GET /healthz: (87.004µs) 200 [kube-probe/1.15+ 127.0.0.1:46794]
I0405 03:24:43.597959       1 reflector.go:384] k8s.io/client-go/informers/factory.go:133: Watch close - *v1.ReplicaSet total 0 items received
I0405 03:24:47.363175       1 wrap.go:47] GET /healthz: (81.495µs) 200 [kube-probe/1.15+ 127.0.0.1:46826]
I0405 03:24:57.363165       1 wrap.go:47] GET /healthz: (149.174µs) 200 [kube-probe/1.15+ 127.0.0.1:46858]
I0405 03:25:07.362745       1 wrap.go:47] GET /healthz: (70.288µs) 200 [kube-probe/1.15+ 127.0.0.1:46894]
I0405 03:25:17.363036       1 wrap.go:47] GET /healthz: (92.297µs) 200 [kube-probe/1.15+ 127.0.0.1:46930]
I0405 03:25:18.603767       1 reflector.go:384] k8s.io/client-go/informers/factory.go:133: Watch close - *v1.ReplicationController total 0 items received
I0405 03:25:27.362834       1 wrap.go:47] GET /healthz: (84.652µs) 200 [kube-probe/1.15+ 127.0.0.1:46978]
I0405 03:25:37.363710       1 wrap.go:47] GET /healthz: (81.298µs) 200 [kube-probe/1.15+ 127.0.0.1:47016]
I0405 03:25:46.586125       1 reflector.go:384] k8s.io/kubernetes/cmd/kube-scheduler/app/server.go:223: Watch close - *v1.Pod total 74 items received
I0405 03:25:47.364111       1 wrap.go:47] GET /healthz: (75.353µs) 200 [kube-probe/1.15+ 127.0.0.1:47048]
I0405 03:25:57.363081       1 wrap.go:47] GET /healthz: (82.836µs) 200 [kube-probe/1.15+ 127.0.0.1:47080]
I0405 03:26:07.367033       1 wrap.go:47] GET /healthz: (109.854µs) 200 [kube-probe/1.15+ 127.0.0.1:47116]
I0405 03:26:10.585559       1 reflector.go:384] k8s.io/client-go/informers/factory.go:133: Watch close - *v1.Node total 36 items received
I0405 03:26:17.362820       1 wrap.go:47] GET /healthz: (75.453µs) 200 [kube-probe/1.15+ 127.0.0.1:47152]
I0405 03:26:27.363340       1 wrap.go:47] GET /healthz: (184.024µs) 200 [kube-probe/1.15+ 127.0.0.1:47202]
I0405 03:26:37.362680       1 wrap.go:47] GET /healthz: (72.161µs) 200 [kube-probe/1.15+ 127.0.0.1:47236]
I0405 03:26:47.363550       1 wrap.go:47] GET /healthz: (173.843µs) 200 [kube-probe/1.15+ 127.0.0.1:47268]
I0405 03:26:57.363777       1 wrap.go:47] GET /healthz: (81.28µs) 200 [kube-probe/1.15+ 127.0.0.1:47302]
I0405 03:27:07.363115       1 wrap.go:47] GET /healthz: (200.955µs) 200 [kube-probe/1.15+ 127.0.0.1:47340]
I0405 03:27:10.607573       1 reflector.go:384] k8s.io/client-go/informers/factory.go:133: Watch close - *v1.StorageClass total 0 items received
I0405 03:27:17.365302       1 wrap.go:47] GET /healthz: (73.715µs) 200 [kube-probe/1.15+ 127.0.0.1:47376]
I0405 03:27:20.590945       1 reflector.go:384] k8s.io/client-go/informers/factory.go:133: Watch close - *v1.Service total 1 items received
I0405 03:27:27.362813       1 wrap.go:47] GET /healthz: (72.918µs) 200 [kube-probe/1.15+ 127.0.0.1:47424]
I0405 03:27:33.593158       1 reflector.go:384] k8s.io/client-go/informers/factory.go:133: Watch close - *v1.PersistentVolumeClaim total 0 items received
I0405 03:27:37.363004       1 wrap.go:47] GET /healthz: (94.931µs) 200 [kube-probe/1.15+ 127.0.0.1:47458]
I0405 03:27:47.363902       1 wrap.go:47] GET /healthz: (92.249µs) 200 [kube-probe/1.15+ 127.0.0.1:47490]
I0405 03:27:57.363725       1 wrap.go:47] GET /healthz: (86.803µs) 200 [kube-probe/1.15+ 127.0.0.1:47522]
I0405 03:27:57.582878       1 reflector.go:384] k8s.io/client-go/informers/factory.go:133: Watch close - *v1.PersistentVolume total 0 items received
I0405 03:28:07.363015       1 wrap.go:47] GET /healthz: (123.314µs) 200 [kube-probe/1.15+ 127.0.0.1:47560]
I0405 03:28:17.362999       1 wrap.go:47] GET /healthz: (94.385µs) 200 [kube-probe/1.15+ 127.0.0.1:47600]
I0405 03:28:26.001683       1 scheduling_queue.go:895] About to try and schedule pod volume-6174/gcepd-injector-km6p
I0405 03:28:26.001695       1 scheduler.go:454] Attempting to schedule pod: volume-6174/gcepd-injector-km6p
I0405 03:28:26.001996       1 scheduler_binder.go:651] All bound volumes for Pod "volume-6174/gcepd-injector-km6p" match with Node "e2e-test-peterhornyack-windows-node-group-lkqs"
I0405 03:28:26.002067       1 scheduler_binder.go:651] All bound volumes for Pod "volume-6174/gcepd-injector-km6p" match with Node "e2e-test-peterhornyack-windows-node-group-rqkw"
I0405 03:28:26.002284       1 scheduler_binder.go:255] AssumePodVolumes for pod "volume-6174/gcepd-injector-km6p", node "e2e-test-peterhornyack-windows-node-group-rqkw"
I0405 03:28:26.002292       1 scheduler_binder.go:265] AssumePodVolumes for pod "volume-6174/gcepd-injector-km6p", node "e2e-test-peterhornyack-windows-node-group-rqkw": all PVCs bound and nothing to do
I0405 03:28:26.002322       1 factory.go:734] Attempting to bind gcepd-injector-km6p to e2e-test-peterhornyack-windows-node-group-rqkw
I0405 03:28:26.010461       1 scheduler.go:575] pod volume-6174/gcepd-injector-km6p is bound successfully on node e2e-test-peterhornyack-windows-node-group-rqkw, 4 nodes evaluated, 2 nodes were found feasible
I0405 03:28:27.362664       1 wrap.go:47] GET /healthz: (60.596µs) 200 [kube-probe/1.15+ 127.0.0.1:47658]
I0405 03:28:37.362952       1 wrap.go:47] GET /healthz: (88.856µs) 200 [kube-probe/1.15+ 127.0.0.1:47694]
I0405 03:28:47.362706       1 wrap.go:47] GET /healthz: (59.192µs) 200 [kube-probe/1.15+ 127.0.0.1:47726]
I0405 03:28:56.783298       1 scheduling_queue.go:895] About to try and schedule pod volume-6174/gcepd-client
I0405 03:28:56.783326       1 scheduler.go:454] Attempting to schedule pod: volume-6174/gcepd-client
I0405 03:28:56.783591       1 scheduler_binder.go:651] All bound volumes for Pod "volume-6174/gcepd-client" match with Node "e2e-test-peterhornyack-windows-node-group-lkqs"
I0405 03:28:56.783658       1 scheduler_binder.go:651] All bound volumes for Pod "volume-6174/gcepd-client" match with Node "e2e-test-peterhornyack-windows-node-group-rqkw"
I0405 03:28:56.788211       1 scheduler_binder.go:255] AssumePodVolumes for pod "volume-6174/gcepd-client", node "e2e-test-peterhornyack-windows-node-group-lkqs"
I0405 03:28:56.788233       1 scheduler_binder.go:265] AssumePodVolumes for pod "volume-6174/gcepd-client", node "e2e-test-peterhornyack-windows-node-group-lkqs": all PVCs bound and nothing to do
I0405 03:28:56.788301       1 factory.go:734] Attempting to bind gcepd-client to e2e-test-peterhornyack-windows-node-group-lkqs
I0405 03:28:56.800155       1 scheduler.go:575] pod volume-6174/gcepd-client is bound successfully on node e2e-test-peterhornyack-windows-node-group-lkqs, 4 nodes evaluated, 2 nodes were found feasible
I0405 03:28:57.362866       1 wrap.go:47] GET /healthz: (81.308µs) 200 [kube-probe/1.15+ 127.0.0.1:47758]
I0405 03:29:07.362457       1 wrap.go:47] GET /healthz: (57.514µs) 200 [kube-probe/1.15+ 127.0.0.1:47794]
I0405 03:29:17.362699       1 wrap.go:47] GET /healthz: (61.93µs) 200 [kube-probe/1.15+ 127.0.0.1:47830]
I0405 03:29:27.362813       1 wrap.go:47] GET /healthz: (69.282µs) 200 [kube-probe/1.15+ 127.0.0.1:47880]
I0405 03:29:37.363798       1 wrap.go:47] GET /healthz: (86.802µs) 200 [kube-probe/1.15+ 127.0.0.1:47914]
I0405 03:29:47.362755       1 wrap.go:47] GET /healthz: (72.39µs) 200 [kube-probe/1.15+ 127.0.0.1:47948]
I0405 03:29:57.362781       1 wrap.go:47] GET /healthz: (52.034µs) 200 [kube-probe/1.15+ 127.0.0.1:47980]
I0405 03:30:07.363781       1 wrap.go:47] GET /healthz: (148.832µs) 200 [kube-probe/1.15+ 127.0.0.1:48018]
I0405 03:30:11.419376       1 scheduling_queue.go:895] About to try and schedule pod projected-6096/pod-projected-secrets-1668afe5-db50-48df-8ad8-e29058b131fe
I0405 03:30:11.419390       1 scheduler.go:454] Attempting to schedule pod: projected-6096/pod-projected-secrets-1668afe5-db50-48df-8ad8-e29058b131fe
I0405 03:30:11.420233       1 scheduler_binder.go:255] AssumePodVolumes for pod "projected-6096/pod-projected-secrets-1668afe5-db50-48df-8ad8-e29058b131fe", node "e2e-test-peterhornyack-windows-node-group-rqkw"
I0405 03:30:11.420247       1 scheduler_binder.go:265] AssumePodVolumes for pod "projected-6096/pod-projected-secrets-1668afe5-db50-48df-8ad8-e29058b131fe", node "e2e-test-peterhornyack-windows-node-group-rqkw": all PVCs bound and nothing to do
I0405 03:30:11.420328       1 factory.go:734] Attempting to bind pod-projected-secrets-1668afe5-db50-48df-8ad8-e29058b131fe to e2e-test-peterhornyack-windows-node-group-rqkw
I0405 03:30:11.430110       1 scheduler.go:575] pod projected-6096/pod-projected-secrets-1668afe5-db50-48df-8ad8-e29058b131fe is bound successfully on node e2e-test-peterhornyack-windows-node-group-rqkw, 4 nodes evaluated, 2 nodes were found feasible
I0405 03:30:17.362706       1 wrap.go:47] GET /healthz: (85.216µs) 200 [kube-probe/1.15+ 127.0.0.1:48054]
I0405 03:30:27.362803       1 wrap.go:47] GET /healthz: (76.167µs) 200 [kube-probe/1.15+ 127.0.0.1:48102]
I0405 03:30:27.606265       1 reflector.go:384] k8s.io/client-go/informers/factory.go:133: Watch close - *v1.StatefulSet total 1 items received
I0405 03:30:37.363050       1 wrap.go:47] GET /healthz: (82.962µs) 200 [kube-probe/1.15+ 127.0.0.1:48136]
I0405 03:30:43.878435       1 scheduling_queue.go:895] About to try and schedule pod projected-2098/pod-projected-configmaps-c8583d32-c546-46f9-96d2-0f91478b48b4
I0405 03:30:43.878449       1 scheduler.go:454] Attempting to schedule pod: projected-2098/pod-projected-configmaps-c8583d32-c546-46f9-96d2-0f91478b48b4
I0405 03:30:43.880811       1 scheduler_binder.go:255] AssumePodVolumes for pod "projected-2098/pod-projected-configmaps-c8583d32-c546-46f9-96d2-0f91478b48b4", node "e2e-test-peterhornyack-windows-node-group-rqkw"
I0405 03:30:43.880827       1 scheduler_binder.go:265] AssumePodVolumes for pod "projected-2098/pod-projected-configmaps-c8583d32-c546-46f9-96d2-0f91478b48b4", node "e2e-test-peterhornyack-windows-node-group-rqkw": all PVCs bound and nothing to do
I0405 03:30:43.880899       1 factory.go:734] Attempting to bind pod-projected-configmaps-c8583d32-c546-46f9-96d2-0f91478b48b4 to e2e-test-peterhornyack-windows-node-group-rqkw
I0405 03:30:43.887298       1 scheduler.go:575] pod projected-2098/pod-projected-configmaps-c8583d32-c546-46f9-96d2-0f91478b48b4 is bound successfully on node e2e-test-peterhornyack-windows-node-group-rqkw, 4 nodes evaluated, 2 nodes were found feasible
I0405 03:30:47.362877       1 wrap.go:47] GET /healthz: (71.028µs) 200 [kube-probe/1.15+ 127.0.0.1:48174]
I0405 03:30:55.585964       1 reflector.go:384] k8s.io/client-go/informers/factory.go:133: Watch close - *v1beta1.PodDisruptionBudget total 0 items received
I0405 03:30:57.362726       1 wrap.go:47] GET /healthz: (81.903µs) 200 [kube-probe/1.15+ 127.0.0.1:48206]
I0405 03:31:07.362987       1 wrap.go:47] GET /healthz: (92.005µs) 200 [kube-probe/1.15+ 127.0.0.1:48242]
I0405 03:31:17.362882       1 wrap.go:47] GET /healthz: (81.375µs) 200 [kube-probe/1.15+ 127.0.0.1:48278]
I0405 03:31:22.602105       1 reflector.go:384] k8s.io/client-go/informers/factory.go:133: Watch close - *v1.ReplicaSet total 0 items received
I0405 03:31:22.648860       1 scheduling_queue.go:895] About to try and schedule pod services-1204/nodeport-test-2kqtn
I0405 03:31:22.648876       1 scheduler.go:454] Attempting to schedule pod: services-1204/nodeport-test-2kqtn
I0405 03:31:22.649368       1 scheduler_binder.go:255] AssumePodVolumes for pod "services-1204/nodeport-test-2kqtn", node "e2e-test-peterhornyack-windows-node-group-rqkw"
I0405 03:31:22.649380       1 scheduler_binder.go:265] AssumePodVolumes for pod "services-1204/nodeport-test-2kqtn", node "e2e-test-peterhornyack-windows-node-group-rqkw": all PVCs bound and nothing to do
I0405 03:31:22.649449       1 factory.go:734] Attempting to bind nodeport-test-2kqtn to e2e-test-peterhornyack-windows-node-group-rqkw
I0405 03:31:22.658194       1 scheduler.go:575] pod services-1204/nodeport-test-2kqtn is bound successfully on node e2e-test-peterhornyack-windows-node-group-rqkw, 4 nodes evaluated, 2 nodes were found feasible
I0405 03:31:27.363167       1 wrap.go:47] GET /healthz: (63.485µs) 200 [kube-probe/1.15+ 127.0.0.1:48326]
I0405 03:31:32.992908       1 scheduling_queue.go:895] About to try and schedule pod services-1204/pod-3cfa301f-5a27-4ca5-ab43-8856d6a4de43
I0405 03:31:32.992942       1 scheduler.go:454] Attempting to schedule pod: services-1204/pod-3cfa301f-5a27-4ca5-ab43-8856d6a4de43
I0405 03:31:32.995120       1 scheduler_binder.go:255] AssumePodVolumes for pod "services-1204/pod-3cfa301f-5a27-4ca5-ab43-8856d6a4de43", node "e2e-test-peterhornyack-windows-node-group-lkqs"
I0405 03:31:32.995134       1 scheduler_binder.go:265] AssumePodVolumes for pod "services-1204/pod-3cfa301f-5a27-4ca5-ab43-8856d6a4de43", node "e2e-test-peterhornyack-windows-node-group-lkqs": all PVCs bound and nothing to do
I0405 03:31:32.995224       1 factory.go:734] Attempting to bind pod-3cfa301f-5a27-4ca5-ab43-8856d6a4de43 to e2e-test-peterhornyack-windows-node-group-lkqs
I0405 03:31:33.002320       1 scheduler.go:575] pod services-1204/pod-3cfa301f-5a27-4ca5-ab43-8856d6a4de43 is bound successfully on node e2e-test-peterhornyack-windows-node-group-lkqs, 4 nodes evaluated, 2 nodes were found feasible
I0405 03:31:37.363265       1 wrap.go:47] GET /healthz: (79.672µs) 200 [kube-probe/1.15+ 127.0.0.1:48362]
I0405 03:31:47.363123       1 wrap.go:47] GET /healthz: (66.725µs) 200 [kube-probe/1.15+ 127.0.0.1:48400]
I0405 03:31:57.363088       1 wrap.go:47] GET /healthz: (83.048µs) 200 [kube-probe/1.15+ 127.0.0.1:48440]
I0405 03:32:07.363179       1 wrap.go:47] GET /healthz: (82.122µs) 200 [kube-probe/1.15+ 127.0.0.1:48476]
I0405 03:32:14.609770       1 reflector.go:384] k8s.io/client-go/informers/factory.go:133: Watch close - *v1.StorageClass total 0 items received
I0405 03:32:15.481370       1 scheduling_queue.go:895] About to try and schedule pod deployment-5811/nginx-deployment-56d49d846f-8dxps
I0405 03:32:15.481386       1 scheduler.go:454] Attempting to schedule pod: deployment-5811/nginx-deployment-56d49d846f-8dxps
I0405 03:32:15.482477       1 scheduler_binder.go:255] AssumePodVolumes for pod "deployment-5811/nginx-deployment-56d49d846f-8dxps", node "e2e-test-peterhornyack-windows-node-group-lkqs"
I0405 03:32:15.482491       1 scheduler_binder.go:265] AssumePodVolumes for pod "deployment-5811/nginx-deployment-56d49d846f-8dxps", node "e2e-test-peterhornyack-windows-node-group-lkqs": all PVCs bound and nothing to do
I0405 03:32:15.482551       1 factory.go:734] Attempting to bind nginx-deployment-56d49d846f-8dxps to e2e-test-peterhornyack-windows-node-group-lkqs
I0405 03:32:15.497181       1 scheduler.go:575] pod deployment-5811/nginx-deployment-56d49d846f-8dxps is bound successfully on node e2e-test-peterhornyack-windows-node-group-lkqs, 4 nodes evaluated, 2 nodes were found feasible
I0405 03:32:15.507191       1 scheduling_queue.go:895] About to try and schedule pod deployment-5811/nginx-deployment-56d49d846f-k7t55
I0405 03:32:15.507206       1 scheduler.go:454] Attempting to schedule pod: deployment-5811/nginx-deployment-56d49d846f-k7t55
I0405 03:32:15.507529       1 scheduler_binder.go:255] AssumePodVolumes for pod "deployment-5811/nginx-deployment-56d49d846f-k7t55", node "e2e-test-peterhornyack-windows-node-group-lkqs"
I0405 03:32:15.507540       1 scheduler_binder.go:265] AssumePodVolumes for pod "deployment-5811/nginx-deployment-56d49d846f-k7t55", node "e2e-test-peterhornyack-windows-node-group-lkqs": all PVCs bound and nothing to do
I0405 03:32:15.507582       1 factory.go:734] Attempting to bind nginx-deployment-56d49d846f-k7t55 to e2e-test-peterhornyack-windows-node-group-lkqs
I0405 03:32:15.512261       1 scheduling_queue.go:895] About to try and schedule pod deployment-5811/nginx-deployment-56d49d846f-xkw5d
I0405 03:32:15.512286       1 scheduler.go:454] Attempting to schedule pod: deployment-5811/nginx-deployment-56d49d846f-xkw5d
I0405 03:32:15.515077       1 scheduler_binder.go:255] AssumePodVolumes for pod "deployment-5811/nginx-deployment-56d49d846f-xkw5d", node "e2e-test-peterhornyack-windows-node-group-lkqs"
I0405 03:32:15.515103       1 scheduler_binder.go:265] AssumePodVolumes for pod "deployment-5811/nginx-deployment-56d49d846f-xkw5d", node "e2e-test-peterhornyack-windows-node-group-lkqs": all PVCs bound and nothing to do
I0405 03:32:15.515157       1 factory.go:734] Attempting to bind nginx-deployment-56d49d846f-xkw5d to e2e-test-peterhornyack-windows-node-group-lkqs
I0405 03:32:15.533377       1 scheduler.go:575] pod deployment-5811/nginx-deployment-56d49d846f-xkw5d is bound successfully on node e2e-test-peterhornyack-windows-node-group-lkqs, 4 nodes evaluated, 2 nodes were found feasible
I0405 03:32:15.541556       1 scheduler.go:575] pod deployment-5811/nginx-deployment-56d49d846f-k7t55 is bound successfully on node e2e-test-peterhornyack-windows-node-group-lkqs, 4 nodes evaluated, 2 nodes were found feasible
I0405 03:32:15.541649       1 scheduling_queue.go:895] About to try and schedule pod deployment-5811/nginx-deployment-56d49d846f-rtwsq
I0405 03:32:15.541657       1 scheduler.go:454] Attempting to schedule pod: deployment-5811/nginx-deployment-56d49d846f-rtwsq
I0405 03:32:15.542051       1 scheduler_binder.go:255] AssumePodVolumes for pod "deployment-5811/nginx-deployment-56d49d846f-rtwsq", node "e2e-test-peterhornyack-windows-node-group-lkqs"
I0405 03:32:15.542061       1 scheduler_binder.go:265] AssumePodVolumes for pod "deployment-5811/nginx-deployment-56d49d846f-rtwsq", node "e2e-test-peterhornyack-windows-node-group-lkqs": all PVCs bound and nothing to do
I0405 03:32:15.542116       1 factory.go:734] Attempting to bind nginx-deployment-56d49d846f-rtwsq to e2e-test-peterhornyack-windows-node-group-lkqs
I0405 03:32:15.545200       1 scheduling_queue.go:895] About to try and schedule pod deployment-5811/nginx-deployment-56d49d846f-kkj25
I0405 03:32:15.545211       1 scheduler.go:454] Attempting to schedule pod: deployment-5811/nginx-deployment-56d49d846f-kkj25
I0405 03:32:15.547517       1 scheduler_binder.go:255] AssumePodVolumes for pod "deployment-5811/nginx-deployment-56d49d846f-kkj25", node "e2e-test-peterhornyack-windows-node-group-lkqs"
I0405 03:32:15.547543       1 scheduler_binder.go:265] AssumePodVolumes for pod "deployment-5811/nginx-deployment-56d49d846f-kkj25", node "e2e-test-peterhornyack-windows-node-group-lkqs": all PVCs bound and nothing to do
I0405 03:32:15.547582       1 factory.go:734] Attempting to bind nginx-deployment-56d49d846f-kkj25 to e2e-test-peterhornyack-windows-node-group-lkqs
I0405 03:32:15.547863       1 scheduling_queue.go:895] About to try and schedule pod deployment-5811/nginx-deployment-56d49d846f-v5cmd
I0405 03:32:15.547878       1 scheduler.go:454] Attempting to schedule pod: deployment-5811/nginx-deployment-56d49d846f-v5cmd
I0405 03:32:15.552431       1 scheduler_binder.go:255] AssumePodVolumes for pod "deployment-5811/nginx-deployment-56d49d846f-v5cmd", node "e2e-test-peterhornyack-windows-node-group-lkqs"
I0405 03:32:15.552443       1 scheduler_binder.go:265] AssumePodVolumes for pod "deployment-5811/nginx-deployment-56d49d846f-v5cmd", node "e2e-test-peterhornyack-windows-node-group-lkqs": all PVCs bound and nothing to do
I0405 03:32:15.552488       1 factory.go:734] Attempting to bind nginx-deployment-56d49d846f-v5cmd to e2e-test-peterhornyack-windows-node-group-lkqs
I0405 03:32:15.559051       1 scheduler.go:575] pod deployment-5811/nginx-deployment-56d49d846f-kkj25 is bound successfully on node e2e-test-peterhornyack-windows-node-group-lkqs, 4 nodes evaluated, 2 nodes were found feasible
I0405 03:32:15.559123       1 scheduling_queue.go:895] About to try and schedule pod deployment-5811/nginx-deployment-56d49d846f-w6lr9
I0405 03:32:15.559129       1 scheduler.go:454] Attempting to schedule pod: deployment-5811/nginx-deployment-56d49d846f-w6lr9
I0405 03:32:15.559389       1 scheduler_binder.go:255] AssumePodVolumes for pod "deployment-5811/nginx-deployment-56d49d846f-w6lr9", node "e2e-test-peterhornyack-windows-node-group-lkqs"
I0405 03:32:15.559399       1 scheduler_binder.go:265] AssumePodVolumes for pod "deployment-5811/nginx-deployment-56d49d846f-w6lr9", node "e2e-test-peterhornyack-windows-node-group-lkqs": all PVCs bound and nothing to do
I0405 03:32:15.559424       1 factory.go:734] Attempting to bind nginx-deployment-56d49d846f-w6lr9 to e2e-test-peterhornyack-windows-node-group-lkqs
I0405 03:32:15.578834       1 scheduler.go:575] pod deployment-5811/nginx-deployment-56d49d846f-rtwsq is bound successfully on node e2e-test-peterhornyack-windows-node-group-lkqs, 4 nodes evaluated, 2 nodes were found feasible
I0405 03:32:15.578956       1 scheduling_queue.go:895] About to try and schedule pod deployment-5811/nginx-deployment-56d49d846f-kdqg7
I0405 03:32:15.578962       1 scheduler.go:454] Attempting to schedule pod: deployment-5811/nginx-deployment-56d49d846f-kdqg7
I0405 03:32:15.579580       1 scheduler_binder.go:255] AssumePodVolumes for pod "deployment-5811/nginx-deployment-56d49d846f-kdqg7", node "e2e-test-peterhornyack-windows-node-group-lkqs"
I0405 03:32:15.579592       1 scheduler_binder.go:265] AssumePodVolumes for pod "deployment-5811/nginx-deployment-56d49d846f-kdqg7", node "e2e-test-peterhornyack-windows-node-group-lkqs": all PVCs bound and nothing to do
I0405 03:32:15.579649       1 factory.go:734] Attempting to bind nginx-deployment-56d49d846f-kdqg7 to e2e-test-peterhornyack-windows-node-group-lkqs
I0405 03:32:15.585421       1 scheduling_queue.go:895] About to try and schedule pod deployment-5811/nginx-deployment-56d49d846f-t285f
I0405 03:32:15.585437       1 scheduler.go:454] Attempting to schedule pod: deployment-5811/nginx-deployment-56d49d846f-t285f
I0405 03:32:15.589511       1 scheduler.go:575] pod deployment-5811/nginx-deployment-56d49d846f-w6lr9 is bound successfully on node e2e-test-peterhornyack-windows-node-group-lkqs, 4 nodes evaluated, 2 nodes were found feasible
I0405 03:32:15.589583       1 scheduler.go:575] pod deployment-5811/nginx-deployment-56d49d846f-v5cmd is bound successfully on node e2e-test-peterhornyack-windows-node-group-lkqs, 4 nodes evaluated, 2 nodes were found feasible
I0405 03:32:15.589876       1 scheduler_binder.go:255] AssumePodVolumes for pod "deployment-5811/nginx-deployment-56d49d846f-t285f", node "e2e-test-peterhornyack-windows-node-group-lkqs"
I0405 03:32:15.589886       1 scheduler_binder.go:265] AssumePodVolumes for pod "deployment-5811/nginx-deployment-56d49d846f-t285f", node "e2e-test-peterhornyack-windows-node-group-lkqs": all PVCs bound and nothing to do
I0405 03:32:15.589917       1 factory.go:734] Attempting to bind nginx-deployment-56d49d846f-t285f to e2e-test-peterhornyack-windows-node-group-lkqs
I0405 03:32:15.590229       1 scheduling_queue.go:895] About to try and schedule pod deployment-5811/nginx-deployment-56d49d846f-99x7k
I0405 03:32:15.590236       1 scheduler.go:454] Attempting to schedule pod: deployment-5811/nginx-deployment-56d49d846f-99x7k
I0405 03:32:15.590424       1 scheduler_binder.go:255] AssumePodVolumes for pod "deployment-5811/nginx-deployment-56d49d846f-99x7k", node "e2e-test-peterhornyack-windows-node-group-lkqs"
I0405 03:32:15.590432       1 scheduler_binder.go:265] AssumePodVolumes for pod "deployment-5811/nginx-deployment-56d49d846f-99x7k", node "e2e-test-peterhornyack-windows-node-group-lkqs": all PVCs bound and nothing to do
I0405 03:32:15.590450       1 factory.go:734] Attempting to bind nginx-deployment-56d49d846f-99x7k to e2e-test-peterhornyack-windows-node-group-lkqs
I0405 03:32:15.611375       1 scheduler.go:575] pod deployment-5811/nginx-deployment-56d49d846f-t285f is bound successfully on node e2e-test-peterhornyack-windows-node-group-lkqs, 4 nodes evaluated, 2 nodes were found feasible
I0405 03:32:15.611717       1 scheduler.go:575] pod deployment-5811/nginx-deployment-56d49d846f-kdqg7 is bound successfully on node e2e-test-peterhornyack-windows-node-group-lkqs, 4 nodes evaluated, 2 nodes were found feasible
I0405 03:32:15.624099       1 scheduler.go:575] pod deployment-5811/nginx-deployment-56d49d846f-99x7k is bound successfully on node e2e-test-peterhornyack-windows-node-group-lkqs, 4 nodes evaluated, 2 nodes were found feasible
I0405 03:32:17.363083       1 wrap.go:47] GET /healthz: (87.848µs) 200 [kube-probe/1.15+ 127.0.0.1:48512]
I0405 03:32:27.363368       1 wrap.go:47] GET /healthz: (110.035µs) 200 [kube-probe/1.15+ 127.0.0.1:48560]
I0405 03:32:37.363417       1 wrap.go:47] GET /healthz: (178.948µs) 200 [kube-probe/1.15+ 127.0.0.1:48594]
I0405 03:32:47.362735       1 wrap.go:47] GET /healthz: (77.714µs) 200 [kube-probe/1.15+ 127.0.0.1:48626]
I0405 03:32:55.595327       1 reflector.go:384] k8s.io/client-go/informers/factory.go:133: Watch close - *v1.PersistentVolumeClaim total 5 items received
I0405 03:32:56.588273       1 reflector.go:384] k8s.io/kubernetes/cmd/kube-scheduler/app/server.go:223: Watch close - *v1.Pod total 77 items received
I0405 03:32:57.363077       1 wrap.go:47] GET /healthz: (74.439µs) 200 [kube-probe/1.15+ 127.0.0.1:48658]
I0405 03:33:01.854389       1 scheduling_queue.go:895] About to try and schedule pod deployment-5811/nginx-deployment-5f9595f595-cmvcp
I0405 03:33:01.854405       1 scheduler.go:454] Attempting to schedule pod: deployment-5811/nginx-deployment-5f9595f595-cmvcp
I0405 03:33:01.854819       1 scheduler_binder.go:255] AssumePodVolumes for pod "deployment-5811/nginx-deployment-5f9595f595-cmvcp", node "e2e-test-peterhornyack-windows-node-group-rqkw"
I0405 03:33:01.854831       1 scheduler_binder.go:265] AssumePodVolumes for pod "deployment-5811/nginx-deployment-5f9595f595-cmvcp", node "e2e-test-peterhornyack-windows-node-group-rqkw": all PVCs bound and nothing to do
I0405 03:33:01.854888       1 factory.go:734] Attempting to bind nginx-deployment-5f9595f595-cmvcp to e2e-test-peterhornyack-windows-node-group-rqkw
I0405 03:33:01.871194       1 scheduler.go:575] pod deployment-5811/nginx-deployment-5f9595f595-cmvcp is bound successfully on node e2e-test-peterhornyack-windows-node-group-rqkw, 4 nodes evaluated, 2 nodes were found feasible
I0405 03:33:01.880212       1 scheduling_queue.go:895] About to try and schedule pod deployment-5811/nginx-deployment-5f9595f595-bq6qv
I0405 03:33:01.880226       1 scheduler.go:454] Attempting to schedule pod: deployment-5811/nginx-deployment-5f9595f595-bq6qv
I0405 03:33:01.880547       1 scheduler_binder.go:255] AssumePodVolumes for pod "deployment-5811/nginx-deployment-5f9595f595-bq6qv", node "e2e-test-peterhornyack-windows-node-group-rqkw"
I0405 03:33:01.880557       1 scheduler_binder.go:265] AssumePodVolumes for pod "deployment-5811/nginx-deployment-5f9595f595-bq6qv", node "e2e-test-peterhornyack-windows-node-group-rqkw": all PVCs bound and nothing to do
I0405 03:33:01.880595       1 factory.go:734] Attempting to bind nginx-deployment-5f9595f595-bq6qv to e2e-test-peterhornyack-windows-node-group-rqkw
I0405 03:33:01.883079       1 scheduling_queue.go:895] About to try and schedule pod deployment-5811/nginx-deployment-5f9595f595-lhptg
I0405 03:33:01.883094       1 scheduler.go:454] Attempting to schedule pod: deployment-5811/nginx-deployment-5f9595f595-lhptg
I0405 03:33:01.883391       1 scheduler_binder.go:255] AssumePodVolumes for pod "deployment-5811/nginx-deployment-5f9595f595-lhptg", node "e2e-test-peterhornyack-windows-node-group-rqkw"
I0405 03:33:01.883401       1 scheduler_binder.go:265] AssumePodVolumes for pod "deployment-5811/nginx-deployment-5f9595f595-lhptg", node "e2e-test-peterhornyack-windows-node-group-rqkw": all PVCs bound and nothing to do
I0405 03:33:01.883431       1 factory.go:734] Attempting to bind nginx-deployment-5f9595f595-lhptg to e2e-test-peterhornyack-windows-node-group-rqkw
I0405 03:33:01.911207       1 scheduler.go:575] pod deployment-5811/nginx-deployment-5f9595f595-lhptg is bound successfully on node e2e-test-peterhornyack-windows-node-group-rqkw, 4 nodes evaluated, 2 nodes were found feasible
I0405 03:33:01.911512       1 scheduler.go:575] pod deployment-5811/nginx-deployment-5f9595f595-bq6qv is bound successfully on node e2e-test-peterhornyack-windows-node-group-rqkw, 4 nodes evaluated, 2 nodes were found feasible
I0405 03:33:02.187290       1 scheduling_queue.go:895] About to try and schedule pod deployment-5811/nginx-deployment-5f9595f595-pqzvv
I0405 03:33:02.187316       1 scheduler.go:454] Attempting to schedule pod: deployment-5811/nginx-deployment-5f9595f595-pqzvv
I0405 03:33:02.190063       1 scheduler_binder.go:255] AssumePodVolumes for pod "deployment-5811/nginx-deployment-5f9595f595-pqzvv", node "e2e-test-peterhornyack-windows-node-group-rqkw"
I0405 03:33:02.190082       1 scheduler_binder.go:265] AssumePodVolumes for pod "deployment-5811/nginx-deployment-5f9595f595-pqzvv", node "e2e-test-peterhornyack-windows-node-group-rqkw": all PVCs bound and nothing to do
I0405 03:33:02.190154       1 factory.go:734] Attempting to bind nginx-deployment-5f9595f595-pqzvv to e2e-test-peterhornyack-windows-node-group-rqkw
I0405 03:33:02.197383       1 scheduler.go:575] pod deployment-5811/nginx-deployment-5f9595f595-pqzvv is bound successfully on node e2e-test-peterhornyack-windows-node-group-rqkw, 4 nodes evaluated, 2 nodes were found feasible
I0405 03:33:02.236286       1 scheduling_queue.go:895] About to try and schedule pod deployment-5811/nginx-deployment-5f9595f595-h7s66
I0405 03:33:02.236301       1 scheduler.go:454] Attempting to schedule pod: deployment-5811/nginx-deployment-5f9595f595-h7s66
I0405 03:33:02.236716       1 scheduler_binder.go:255] AssumePodVolumes for pod "deployment-5811/nginx-deployment-5f9595f595-h7s66", node "e2e-test-peterhornyack-windows-node-group-lkqs"
I0405 03:33:02.236726       1 scheduler_binder.go:265] AssumePodVolumes for pod "deployment-5811/nginx-deployment-5f9595f595-h7s66", node "e2e-test-peterhornyack-windows-node-group-lkqs": all PVCs bound and nothing to do
I0405 03:33:02.236765       1 factory.go:734] Attempting to bind nginx-deployment-5f9595f595-h7s66 to e2e-test-peterhornyack-windows-node-group-lkqs
I0405 03:33:02.248796       1 scheduler.go:575] pod deployment-5811/nginx-deployment-5f9595f595-h7s66 is bound successfully on node e2e-test-peterhornyack-windows-node-group-lkqs, 4 nodes evaluated, 2 nodes were found feasible
I0405 03:33:04.398266       1 scheduling_queue.go:895] About to try and schedule pod deployment-5811/nginx-deployment-56d49d846f-mnqfs
I0405 03:33:04.398294       1 scheduler.go:454] Attempting to schedule pod: deployment-5811/nginx-deployment-56d49d846f-mnqfs
I0405 03:33:04.398706       1 scheduler_binder.go:255] AssumePodVolumes for pod "deployment-5811/nginx-deployment-56d49d846f-mnqfs", node "e2e-test-peterhornyack-windows-node-group-lkqs"
I0405 03:33:04.398716       1 scheduler_binder.go:265] AssumePodVolumes for pod "deployment-5811/nginx-deployment-56d49d846f-mnqfs", node "e2e-test-peterhornyack-windows-node-group-lkqs": all PVCs bound and nothing to do
I0405 03:33:04.398774       1 factory.go:734] Attempting to bind nginx-deployment-56d49d846f-mnqfs to e2e-test-peterhornyack-windows-node-group-lkqs
I0405 03:33:04.423306       1 scheduling_queue.go:895] About to try and schedule pod deployment-5811/nginx-deployment-56d49d846f-gxjdw
I0405 03:33:04.423326       1 scheduler.go:454] Attempting to schedule pod: deployment-5811/nginx-deployment-56d49d846f-gxjdw
I0405 03:33:04.423694       1 scheduler_binder.go:255] AssumePodVolumes for pod "deployment-5811/nginx-deployment-56d49d846f-gxjdw", node "e2e-test-peterhornyack-windows-node-group-lkqs"
I0405 03:33:04.423710       1 scheduler_binder.go:265] AssumePodVolumes for pod "deployment-5811/nginx-deployment-56d49d846f-gxjdw", node "e2e-test-peterhornyack-windows-node-group-lkqs": all PVCs bound and nothing to do
I0405 03:33:04.423752       1 factory.go:734] Attempting to bind nginx-deployment-56d49d846f-gxjdw to e2e-test-peterhornyack-windows-node-group-lkqs
I0405 03:33:04.437359       1 scheduler.go:575] pod deployment-5811/nginx-deployment-56d49d846f-mnqfs is bound successfully on node e2e-test-peterhornyack-windows-node-group-lkqs, 4 nodes evaluated, 2 nodes were found feasible
I0405 03:33:04.437611       1 scheduling_queue.go:895] About to try and schedule pod deployment-5811/nginx-deployment-56d49d846f-sfqpp
I0405 03:33:04.437618       1 scheduler.go:454] Attempting to schedule pod: deployment-5811/nginx-deployment-56d49d846f-sfqpp
I0405 03:33:04.443837       1 scheduler_binder.go:255] AssumePodVolumes for pod "deployment-5811/nginx-deployment-56d49d846f-sfqpp", node "e2e-test-peterhornyack-windows-node-group-lkqs"
I0405 03:33:04.443859       1 scheduler_binder.go:265] AssumePodVolumes for pod "deployment-5811/nginx-deployment-56d49d846f-sfqpp", node "e2e-test-peterhornyack-windows-node-group-lkqs": all PVCs bound and nothing to do
I0405 03:33:04.445992       1 factory.go:734] Attempting to bind nginx-deployment-56d49d846f-sfqpp to e2e-test-peterhornyack-windows-node-group-lkqs
I0405 03:33:04.447054       1 scheduling_queue.go:895] About to try and schedule pod deployment-5811/nginx-deployment-5f9595f595-8gcqz
I0405 03:33:04.447063       1 scheduler.go:454] Attempting to schedule pod: deployment-5811/nginx-deployment-5f9595f595-8gcqz
I0405 03:33:04.453529       1 scheduler_binder.go:255] AssumePodVolumes for pod "deployment-5811/nginx-deployment-5f9595f595-8gcqz", node "e2e-test-peterhornyack-windows-node-group-rqkw"
I0405 03:33:04.453548       1 scheduler_binder.go:265] AssumePodVolumes for pod "deployment-5811/nginx-deployment-5f9595f595-8gcqz", node "e2e-test-peterhornyack-windows-node-group-rqkw": all PVCs bound and nothing to do
I0405 03:33:04.453603       1 factory.go:734] Attempting to bind nginx-deployment-5f9595f595-8gcqz to e2e-test-peterhornyack-windows-node-group-rqkw
I0405 03:33:04.494970       1 scheduler.go:575] pod deployment-5811/nginx-deployment-5f9595f595-8gcqz is bound successfully on node e2e-test-peterhornyack-windows-node-group-rqkw, 4 nodes evaluated, 2 nodes were found feasible
I0405 03:33:04.498287       1 scheduler.go:575] pod deployment-5811/nginx-deployment-56d49d846f-gxjdw is bound successfully on node e2e-test-peterhornyack-windows-node-group-lkqs, 4 nodes evaluated, 2 nodes were found feasible
I0405 03:33:04.500104       1 scheduler.go:575] pod deployment-5811/nginx-deployment-56d49d846f-sfqpp is bound successfully on node e2e-test-peterhornyack-windows-node-group-lkqs, 4 nodes evaluated, 2 nodes were found feasible
I0405 03:33:04.500406       1 scheduling_queue.go:895] About to try and schedule pod deployment-5811/nginx-deployment-56d49d846f-tpzsh
I0405 03:33:04.500414       1 scheduler.go:454] Attempting to schedule pod: deployment-5811/nginx-deployment-56d49d846f-tpzsh
I0405 03:33:04.510463       1 scheduler_binder.go:255] AssumePodVolumes for pod "deployment-5811/nginx-deployment-56d49d846f-tpzsh", node "e2e-test-peterhornyack-windows-node-group-lkqs"
I0405 03:33:04.510482       1 scheduler_binder.go:265] AssumePodVolumes for pod "deployment-5811/nginx-deployment-56d49d846f-tpzsh", node "e2e-test-peterhornyack-windows-node-group-lkqs": all PVCs bound and nothing to do
I0405 03:33:04.510557       1 factory.go:734] Attempting to bind nginx-deployment-56d49d846f-tpzsh to e2e-test-peterhornyack-windows-node-group-lkqs
I0405 03:33:04.512125       1 scheduling_queue.go:895] About to try and schedule pod deployment-5811/nginx-deployment-5f9595f595-drhl4
I0405 03:33:04.512139       1 scheduler.go:454] Attempting to schedule pod: deployment-5811/nginx-deployment-5f9595f595-drhl4
I0405 03:33:04.512526       1 scheduler_binder.go:255] AssumePodVolumes for pod "deployment-5811/nginx-deployment-5f9595f595-drhl4", node "e2e-test-peterhornyack-windows-node-group-rqkw"
I0405 03:33:04.512537       1 scheduler_binder.go:265] AssumePodVolumes for pod "deployment-5811/nginx-deployment-5f9595f595-drhl4", node "e2e-test-peterhornyack-windows-node-group-rqkw": all PVCs bound and nothing to do
I0405 03:33:04.512566       1 factory.go:734] Attempting to bind nginx-deployment-5f9595f595-drhl4 to e2e-test-peterhornyack-windows-node-group-rqkw
I0405 03:33:04.521511       1 scheduling_queue.go:895] About to try and schedule pod deployment-5811/nginx-deployment-56d49d846f-4tqsg
I0405 03:33:04.521530       1 scheduler.go:454] Attempting to schedule pod: deployment-5811/nginx-deployment-56d49d846f-4tqsg
I0405 03:33:04.521914       1 scheduler_binder.go:255] AssumePodVolumes for pod "deployment-5811/nginx-deployment-56d49d846f-4tqsg", node "e2e-test-peterhornyack-windows-node-group-lkqs"
I0405 03:33:04.526065       1 scheduler_binder.go:265] AssumePodVolumes for pod "deployment-5811/nginx-deployment-56d49d846f-4tqsg", node "e2e-test-peterhornyack-windows-node-group-lkqs": all PVCs bound and nothing to do
I0405 03:33:04.526150       1 factory.go:734] Attempting to bind nginx-deployment-56d49d846f-4tqsg to e2e-test-peterhornyack-windows-node-group-lkqs
I0405 03:33:04.528298       1 scheduling_queue.go:895] About to try and schedule pod deployment-5811/nginx-deployment-5f9595f595-4r8hn
I0405 03:33:04.528321       1 scheduler.go:454] Attempting to schedule pod: deployment-5811/nginx-deployment-5f9595f595-4r8hn
I0405 03:33:04.528681       1 scheduler_binder.go:255] AssumePodVolumes for pod "deployment-5811/nginx-deployment-5f9595f595-4r8hn", node "e2e-test-peterhornyack-windows-node-group-rqkw"
I0405 03:33:04.528690       1 scheduler_binder.go:265] AssumePodVolumes for pod "deployment-5811/nginx-deployment-5f9595f595-4r8hn", node "e2e-test-peterhornyack-windows-node-group-rqkw": all PVCs bound and nothing to do
I0405 03:33:04.528726       1 factory.go:734] Attempting to bind nginx-deployment-5f9595f595-4r8hn to e2e-test-peterhornyack-windows-node-group-rqkw
I0405 03:33:04.535145       1 scheduling_queue.go:895] About to try and schedule pod deployment-5811/nginx-deployment-56d49d846f-j4k6j
I0405 03:33:04.535164       1 scheduler.go:454] Attempting to schedule pod: deployment-5811/nginx-deployment-56d49d846f-j4k6j
I0405 03:33:04.540507       1 scheduler_binder.go:255] AssumePodVolumes for pod "deployment-5811/nginx-deployment-56d49d846f-j4k6j", node "e2e-test-peterhornyack-windows-node-group-lkqs"
I0405 03:33:04.544855       1 scheduler_binder.go:265] AssumePodVolumes for pod "deployment-5811/nginx-deployment-56d49d846f-j4k6j", node "e2e-test-peterhornyack-windows-node-group-lkqs": all PVCs bound and nothing to do
I0405 03:33:04.544985       1 factory.go:734] Attempting to bind nginx-deployment-56d49d846f-j4k6j to e2e-test-peterhornyack-windows-node-group-lkqs
I0405 03:33:04.549640       1 scheduling_queue.go:895] About to try and schedule pod deployment-5811/nginx-deployment-56d49d846f-pbbtg
I0405 03:33:04.549655       1 scheduler.go:454] Attempting to schedule pod: deployment-5811/nginx-deployment-56d49d846f-pbbtg
I0405 03:33:04.559206       1 scheduler_binder.go:255] AssumePodVolumes for pod "deployment-5811/nginx-deployment-56d49d846f-pbbtg", node "e2e-test-peterhornyack-windows-node-group-lkqs"
I0405 03:33:04.562584       1 scheduler_binder.go:265] AssumePodVolumes for pod "deployment-5811/nginx-deployment-56d49d846f-pbbtg", node "e2e-test-peterhornyack-windows-node-group-lkqs": all PVCs bound and nothing to do
I0405 03:33:04.562708       1 factory.go:734] Attempting to bind nginx-deployment-56d49d846f-pbbtg to e2e-test-peterhornyack-windows-node-group-lkqs
I0405 03:33:04.577332       1 scheduler.go:575] pod deployment-5811/nginx-deployment-56d49d846f-tpzsh is bound successfully on node e2e-test-peterhornyack-windows-node-group-lkqs, 4 nodes evaluated, 2 nodes were found feasible
I0405 03:33:04.577416       1 scheduling_queue.go:895] About to try and schedule pod deployment-5811/nginx-deployment-56d49d846f-bqjjv
I0405 03:33:04.577435       1 scheduler.go:454] Attempting to schedule pod: deployment-5811/nginx-deployment-56d49d846f-bqjjv
I0405 03:33:04.577854       1 scheduler_binder.go:255] AssumePodVolumes for pod "deployment-5811/nginx-deployment-56d49d846f-bqjjv", node "e2e-test-peterhornyack-windows-node-group-lkqs"
I0405 03:33:04.577865       1 scheduler_binder.go:265] AssumePodVolumes for pod "deployment-5811/nginx-deployment-56d49d846f-bqjjv", node "e2e-test-peterhornyack-windows-node-group-lkqs": all PVCs bound and nothing to do
I0405 03:33:04.577898       1 factory.go:734] Attempting to bind nginx-deployment-56d49d846f-bqjjv to e2e-test-peterhornyack-windows-node-group-lkqs
I0405 03:33:04.587106       1 scheduling_queue.go:895] About to try and schedule pod deployment-5811/nginx-deployment-5f9595f595-8wwx9
I0405 03:33:04.587119       1 scheduler.go:454] Attempting to schedule pod: deployment-5811/nginx-deployment-5f9595f595-8wwx9
I0405 03:33:04.587603       1 scheduler_binder.go:255] AssumePodVolumes for pod "deployment-5811/nginx-deployment-5f9595f595-8wwx9", node "e2e-test-peterhornyack-windows-node-group-rqkw"
I0405 03:33:04.587614       1 scheduler_binder.go:265] AssumePodVolumes for pod "deployment-5811/nginx-deployment-5f9595f595-8wwx9", node "e2e-test-peterhornyack-windows-node-group-rqkw": all PVCs bound and nothing to do
I0405 03:33:04.587658       1 factory.go:734] Attempting to bind nginx-deployment-5f9595f595-8wwx9 to e2e-test-peterhornyack-windows-node-group-rqkw
I0405 03:33:04.598113       1 scheduling_queue.go:895] About to try and schedule pod deployment-5811/nginx-deployment-56d49d846f-mp96l
I0405 03:33:04.598137       1 scheduler.go:454] Attempting to schedule pod: deployment-5811/nginx-deployment-56d49d846f-mp96l
I0405 03:33:04.598508       1 scheduler_binder.go:255] AssumePodVolumes for pod "deployment-5811/nginx-deployment-56d49d846f-mp96l", node "e2e-test-peterhornyack-windows-node-group-lkqs"
I0405 03:33:04.598518       1 scheduler_binder.go:265] AssumePodVolumes for pod "deployment-5811/nginx-deployment-56d49d846f-mp96l", node "e2e-test-peterhornyack-windows-node-group-lkqs": all PVCs bound and nothing to do
I0405 03:33:04.598558       1 factory.go:734] Attempting to bind nginx-deployment-56d49d846f-mp96l to e2e-test-peterhornyack-windows-node-group-lkqs
I0405 03:33:04.605979       1 scheduling_queue.go:895] About to try and schedule pod deployment-5811/nginx-deployment-5f9595f595-rzl9f
I0405 03:33:04.605998       1 scheduler.go:454] Attempting to schedule pod: deployment-5811/nginx-deployment-5f9595f595-rzl9f
I0405 03:33:04.608357       1 scheduler_binder.go:255] AssumePodVolumes for pod "deployment-5811/nginx-deployment-5f9595f595-rzl9f", node "e2e-test-peterhornyack-windows-node-group-rqkw"
I0405 03:33:04.608375       1 scheduler_binder.go:265] AssumePodVolumes for pod "deployment-5811/nginx-deployment-5f9595f595-rzl9f", node "e2e-test-peterhornyack-windows-node-group-rqkw": all PVCs bound and nothing to do
I0405 03:33:04.608436       1 factory.go:734] Attempting to bind nginx-deployment-5f9595f595-rzl9f to e2e-test-peterhornyack-windows-node-group-rqkw
I0405 03:33:04.613098       1 scheduling_queue.go:895] About to try and schedule pod deployment-5811/nginx-deployment-5f9595f595-b67hv
I0405 03:33:04.613437       1 scheduler.go:454] Attempting to schedule pod: deployment-5811/nginx-deployment-5f9595f595-b67hv
I0405 03:33:04.623744       1 scheduler_binder.go:255] AssumePodVolumes for pod "deployment-5811/nginx-deployment-5f9595f595-b67hv", node "e2e-test-peterhornyack-windows-node-group-rqkw"
I0405 03:33:04.623786       1 scheduler_binder.go:265] AssumePodVolumes for pod "deployment-5811/nginx-deployment-5f9595f595-b67hv", node "e2e-test-peterhornyack-windows-node-group-rqkw": all PVCs bound and nothing to do
I0405 03:33:04.623873       1 factory.go:734] Attempting to bind nginx-deployment-5f9595f595-b67hv to e2e-test-peterhornyack-windows-node-group-rqkw
I0405 03:33:04.639365       1 scheduler.go:575] pod deployment-5811/nginx-deployment-5f9595f595-drhl4 is bound successfully on node e2e-test-peterhornyack-windows-node-group-rqkw, 4 nodes evaluated, 2 nodes were found feasible
I0405 03:33:04.641643       1 scheduler.go:575] pod deployment-5811/nginx-deployment-56d49d846f-4tqsg is bound successfully on node e2e-test-peterhornyack-windows-node-group-lkqs, 4 nodes evaluated, 2 nodes were found feasible
I0405 03:33:04.641692       1 scheduler.go:575] pod deployment-5811/nginx-deployment-5f9595f595-4r8hn is bound successfully on node e2e-test-peterhornyack-windows-node-group-rqkw, 4 nodes evaluated, 2 nodes were found feasible
I0405 03:33:04.641742       1 scheduling_queue.go:895] About to try and schedule pod deployment-5811/nginx-deployment-5f9595f595-h77vj
I0405 03:33:04.641748       1 scheduler.go:454] Attempting to schedule pod: deployment-5811/nginx-deployment-5f9595f595-h77vj
I0405 03:33:04.647487       1 scheduler_binder.go:255] AssumePodVolumes for pod "deployment-5811/nginx-deployment-5f9595f595-h77vj", node "e2e-test-peterhornyack-windows-node-group-rqkw"
I0405 03:33:04.647502       1 scheduler_binder.go:265] AssumePodVolumes for pod "deployment-5811/nginx-deployment-5f9595f595-h77vj", node "e2e-test-peterhornyack-windows-node-group-rqkw": all PVCs bound and nothing to do
I0405 03:33:04.647544       1 factory.go:734] Attempting to bind nginx-deployment-5f9595f595-h77vj to e2e-test-peterhornyack-windows-node-group-rqkw
I0405 03:33:04.653272       1 scheduler.go:575] pod deployment-5811/nginx-deployment-56d49d846f-bqjjv is bound successfully on node e2e-test-peterhornyack-windows-node-group-lkqs, 4 nodes evaluated, 2 nodes were found feasible
I0405 03:33:04.653325       1 scheduler.go:575] pod deployment-5811/nginx-deployment-56d49d846f-j4k6j is bound successfully on node e2e-test-peterhornyack-windows-node-group-lkqs, 4 nodes evaluated, 2 nodes were found feasible
I0405 03:33:04.656006       1 scheduling_queue.go:895] About to try and schedule pod deployment-5811/nginx-deployment-56d49d846f-rjr5g
I0405 03:33:04.656023       1 scheduler.go:454] Attempting to schedule pod: deployment-5811/nginx-deployment-56d49d846f-rjr5g
I0405 03:33:04.660399       1 scheduler_binder.go:255] AssumePodVolumes for pod "deployment-5811/nginx-deployment-56d49d846f-rjr5g", node "e2e-test-peterhornyack-windows-node-group-lkqs"
I0405 03:33:04.660413       1 scheduler_binder.go:265] AssumePodVolumes for pod "deployment-5811/nginx-deployment-56d49d846f-rjr5g", node "e2e-test-peterhornyack-windows-node-group-lkqs": all PVCs bound and nothing to do
I0405 03:33:04.660449       1 factory.go:734] Attempting to bind nginx-deployment-56d49d846f-rjr5g to e2e-test-peterhornyack-windows-node-group-lkqs
I0405 03:33:04.660853       1 scheduler.go:575] pod deployment-5811/nginx-deployment-5f9595f595-rzl9f is bound successfully on node e2e-test-peterhornyack-windows-node-group-rqkw, 4 nodes evaluated, 2 nodes were found feasible
I0405 03:33:04.666158       1 scheduler.go:575] pod deployment-5811/nginx-deployment-5f9595f595-8wwx9 is bound successfully on node e2e-test-peterhornyack-windows-node-group-rqkw, 4 nodes evaluated, 2 nodes were found feasible
I0405 03:33:04.666505       1 scheduler.go:575] pod deployment-5811/nginx-deployment-56d49d846f-mp96l is bound successfully on node e2e-test-peterhornyack-windows-node-group-lkqs, 4 nodes evaluated, 2 nodes were found feasible
I0405 03:33:04.666541       1 scheduler.go:575] pod deployment-5811/nginx-deployment-56d49d846f-pbbtg is bound successfully on node e2e-test-peterhornyack-windows-node-group-lkqs, 4 nodes evaluated, 2 nodes were found feasible
I0405 03:33:04.677408       1 scheduling_queue.go:895] About to try and schedule pod deployment-5811/nginx-deployment-56d49d846f-5gg97
I0405 03:33:04.677421       1 scheduler.go:454] Attempting to schedule pod: deployment-5811/nginx-deployment-56d49d846f-5gg97
I0405 03:33:04.677791       1 scheduler_binder.go:255] AssumePodVolumes for pod "deployment-5811/nginx-deployment-56d49d846f-5gg97", node "e2e-test-peterhornyack-windows-node-group-rqkw"
I0405 03:33:04.677801       1 scheduler_binder.go:265] AssumePodVolumes for pod "deployment-5811/nginx-deployment-56d49d846f-5gg97", node "e2e-test-peterhornyack-windows-node-group-rqkw": all PVCs bound and nothing to do
I0405 03:33:04.677844       1 factory.go:734] Attempting to bind nginx-deployment-56d49d846f-5gg97 to e2e-test-peterhornyack-windows-node-group-rqkw
I0405 03:33:04.685018       1 scheduling_queue.go:895] About to try and schedule pod deployment-5811/nginx-deployment-56d49d846f-zh2n5
I0405 03:33:04.685037       1 scheduler.go:454] Attempting to schedule pod: deployment-5811/nginx-deployment-56d49d846f-zh2n5
I0405 03:33:04.685494       1 scheduler_binder.go:255] AssumePodVolumes for pod "deployment-5811/nginx-deployment-56d49d846f-zh2n5", node "e2e-test-peterhornyack-windows-node-group-rqkw"
I0405 03:33:04.685506       1 scheduler_binder.go:265] AssumePodVolumes for pod "deployment-5811/nginx-deployment-56d49d846f-zh2n5", node "e2e-test-peterhornyack-windows-node-group-rqkw": all PVCs bound and nothing to do
I0405 03:33:04.685545       1 factory.go:734] Attempting to bind nginx-deployment-56d49d846f-zh2n5 to e2e-test-peterhornyack-windows-node-group-rqkw
I0405 03:33:04.696718       1 scheduling_queue.go:895] About to try and schedule pod deployment-5811/nginx-deployment-5f9595f595-x7nnv
I0405 03:33:04.696738       1 scheduler.go:454] Attempting to schedule pod: deployment-5811/nginx-deployment-5f9595f595-x7nnv
I0405 03:33:04.697396       1 scheduler_binder.go:255] AssumePodVolumes for pod "deployment-5811/nginx-deployment-5f9595f595-x7nnv", node "e2e-test-peterhornyack-windows-node-group-rqkw"
I0405 03:33:04.697408       1 scheduler_binder.go:265] AssumePodVolumes for pod "deployment-5811/nginx-deployment-5f9595f595-x7nnv", node "e2e-test-peterhornyack-windows-node-group-rqkw": all PVCs bound and nothing to do
I0405 03:33:04.697451       1 factory.go:734] Attempting to bind nginx-deployment-5f9595f595-x7nnv to e2e-test-peterhornyack-windows-node-group-rqkw
I0405 03:33:04.709429       1 scheduler.go:575] pod deployment-5811/nginx-deployment-5f9595f595-b67hv is bound successfully on node e2e-test-peterhornyack-windows-node-group-rqkw, 4 nodes evaluated, 2 nodes were found feasible
I0405 03:33:04.709473       1 scheduler.go:575] pod deployment-5811/nginx-deployment-5f9595f595-h77vj is bound successfully on node e2e-test-peterhornyack-windows-node-group-rqkw, 4 nodes evaluated, 2 nodes were found feasible
I0405 03:33:04.722083       1 scheduler.go:575] pod deployment-5811/nginx-deployment-56d49d846f-rjr5g is bound successfully on node e2e-test-peterhornyack-windows-node-group-lkqs, 4 nodes evaluated, 2 nodes were found feasible
I0405 03:33:04.743289       1 scheduler.go:575] pod deployment-5811/nginx-deployment-56d49d846f-5gg97 is bound successfully on node e2e-test-peterhornyack-windows-node-group-rqkw, 4 nodes evaluated, 2 nodes were found feasible
I0405 03:33:04.743378       1 scheduler.go:575] pod deployment-5811/nginx-deployment-56d49d846f-zh2n5 is bound successfully on node e2e-test-peterhornyack-windows-node-group-rqkw, 4 nodes evaluated, 2 nodes were found feasible
I0405 03:33:04.758627       1 scheduler.go:575] pod deployment-5811/nginx-deployment-5f9595f595-x7nnv is bound successfully on node e2e-test-peterhornyack-windows-node-group-rqkw, 4 nodes evaluated, 2 nodes were found feasible
I0405 03:33:07.362978       1 wrap.go:47] GET /healthz: (101.954µs) 200 [kube-probe/1.15+ 127.0.0.1:48696]
I0405 03:33:14.996952       1 scheduling_queue.go:895] About to try and schedule pod pods-6076/pod-update-bc8dbc29-1f33-4a72-9fe5-18f825a48043
I0405 03:33:14.996966       1 scheduler.go:454] Attempting to schedule pod: pods-6076/pod-update-bc8dbc29-1f33-4a72-9fe5-18f825a48043
I0405 03:33:14.997298       1 scheduler_binder.go:255] AssumePodVolumes for pod "pods-6076/pod-update-bc8dbc29-1f33-4a72-9fe5-18f825a48043", node "e2e-test-peterhornyack-windows-node-group-lkqs"
I0405 03:33:14.997307       1 scheduler_binder.go:265] AssumePodVolumes for pod "pods-6076/pod-update-bc8dbc29-1f33-4a72-9fe5-18f825a48043", node "e2e-test-peterhornyack-windows-node-group-lkqs": all PVCs bound and nothing to do
I0405 03:33:14.997365       1 factory.go:734] Attempting to bind pod-update-bc8dbc29-1f33-4a72-9fe5-18f825a48043 to e2e-test-peterhornyack-windows-node-group-lkqs
I0405 03:33:15.003749       1 scheduler.go:575] pod pods-6076/pod-update-bc8dbc29-1f33-4a72-9fe5-18f825a48043 is bound successfully on node e2e-test-peterhornyack-windows-node-group-lkqs, 4 nodes evaluated, 2 nodes were found feasible
I0405 03:33:17.362681       1 wrap.go:47] GET /healthz: (67.909µs) 200 [kube-probe/1.15+ 127.0.0.1:48734]
I0405 03:33:27.363088       1 wrap.go:47] GET /healthz: (73.719µs) 200 [kube-probe/1.15+ 127.0.0.1:48782]
I0405 03:33:37.363020       1 wrap.go:47] GET /healthz: (109.187µs) 200 [kube-probe/1.15+ 127.0.0.1:48816]
I0405 03:33:47.363732       1 wrap.go:47] GET /healthz: (76.527µs) 200 [kube-probe/1.15+ 127.0.0.1:48848]
I0405 03:33:52.605781       1 reflector.go:384] k8s.io/client-go/informers/factory.go:133: Watch close - *v1.ReplicationController total 6 items received
I0405 03:33:54.587854       1 reflector.go:384] k8s.io/client-go/informers/factory.go:133: Watch close - *v1.Node total 43 items received
I0405 03:33:57.363205       1 wrap.go:47] GET /healthz: (52.401µs) 200 [kube-probe/1.15+ 127.0.0.1:48880]
I0405 03:34:07.363222       1 wrap.go:47] GET /healthz: (82.786µs) 200 [kube-probe/1.15+ 127.0.0.1:48916]
I0405 03:34:13.958737       1 scheduling_queue.go:895] About to try and schedule pod gc-2922/simpletest-rc-to-be-deleted-xjm6c
I0405 03:34:13.958748       1 scheduler.go:454] Attempting to schedule pod: gc-2922/simpletest-rc-to-be-deleted-xjm6c
I0405 03:34:13.960274       1 scheduler_binder.go:255] AssumePodVolumes for pod "gc-2922/simpletest-rc-to-be-deleted-xjm6c", node "e2e-test-peterhornyack-windows-node-group-lkqs"
I0405 03:34:13.960287       1 scheduler_binder.go:265] AssumePodVolumes for pod "gc-2922/simpletest-rc-to-be-deleted-xjm6c", node "e2e-test-peterhornyack-windows-node-group-lkqs": all PVCs bound and nothing to do
I0405 03:34:13.960359       1 factory.go:734] Attempting to bind simpletest-rc-to-be-deleted-xjm6c to e2e-test-peterhornyack-windows-node-group-lkqs
I0405 03:34:13.972025       1 scheduler.go:575] pod gc-2922/simpletest-rc-to-be-deleted-xjm6c is bound successfully on node e2e-test-peterhornyack-windows-node-group-lkqs, 4 nodes evaluated, 2 nodes were found feasible
I0405 03:34:13.979946       1 scheduling_queue.go:895] About to try and schedule pod gc-2922/simpletest-rc-to-be-deleted-grqpm
I0405 03:34:13.979956       1 scheduler.go:454] Attempting to schedule pod: gc-2922/simpletest-rc-to-be-deleted-grqpm
I0405 03:34:13.980186       1 scheduler_binder.go:255] AssumePodVolumes for pod "gc-2922/simpletest-rc-to-be-deleted-grqpm", node "e2e-test-peterhornyack-windows-node-group-lkqs"
I0405 03:34:13.980196       1 scheduler_binder.go:265] AssumePodVolumes for pod "gc-2922/simpletest-rc-to-be-deleted-grqpm", node "e2e-test-peterhornyack-windows-node-group-lkqs": all PVCs bound and nothing to do
I0405 03:34:13.980234       1 factory.go:734] Attempting to bind simpletest-rc-to-be-deleted-grqpm to e2e-test-peterhornyack-windows-node-group-lkqs
I0405 03:34:13.983696       1 scheduling_queue.go:895] About to try and schedule pod gc-2922/simpletest-rc-to-be-deleted-8kbhp
I0405 03:34:13.983707       1 scheduler.go:454] Attempting to schedule pod: gc-2922/simpletest-rc-to-be-deleted-8kbhp
I0405 03:34:13.985284       1 scheduler_binder.go:255] AssumePodVolumes for pod "gc-2922/simpletest-rc-to-be-deleted-8kbhp", node "e2e-test-peterhornyack-windows-node-group-lkqs"
I0405 03:34:13.985296       1 scheduler_binder.go:265] AssumePodVolumes for pod "gc-2922/simpletest-rc-to-be-deleted-8kbhp", node "e2e-test-peterhornyack-windows-node-group-lkqs": all PVCs bound and nothing to do
I0405 03:34:13.985351       1 factory.go:734] Attempting to bind simpletest-rc-to-be-deleted-8kbhp to e2e-test-peterhornyack-windows-node-group-lkqs
I0405 03:34:13.991420       1 scheduler.go:575] pod gc-2922/simpletest-rc-to-be-deleted-grqpm is bound successfully on node e2e-test-peterhornyack-windows-node-group-lkqs, 4 nodes evaluated, 2 nodes were found feasible
I0405 03:34:14.009361       1 scheduling_queue.go:895] About to try and schedule pod gc-2922/simpletest-rc-to-be-deleted-8zhc7
I0405 03:34:14.009559       1 scheduler.go:454] Attempting to schedule pod: gc-2922/simpletest-rc-to-be-deleted-8zhc7
I0405 03:34:14.012161       1 scheduler_binder.go:255] AssumePodVolumes for pod "gc-2922/simpletest-rc-to-be-deleted-8zhc7", node "e2e-test-peterhornyack-windows-node-group-lkqs"
I0405 03:34:14.012174       1 scheduler_binder.go:265] AssumePodVolumes for pod "gc-2922/simpletest-rc-to-be-deleted-8zhc7", node "e2e-test-peterhornyack-windows-node-group-lkqs": all PVCs bound and nothing to do
I0405 03:34:14.012205       1 factory.go:734] Attempting to bind simpletest-rc-to-be-deleted-8zhc7 to e2e-test-peterhornyack-windows-node-group-lkqs
I0405 03:34:14.016516       1 scheduling_queue.go:895] About to try and schedule pod gc-2922/simpletest-rc-to-be-deleted-j22sz
I0405 03:34:14.016527       1 scheduler.go:454] Attempting to schedule pod: gc-2922/simpletest-rc-to-be-deleted-j22sz
I0405 03:34:14.016766       1 scheduler_binder.go:255] AssumePodVolumes for pod "gc-2922/simpletest-rc-to-be-deleted-j22sz", node "e2e-test-peterhornyack-windows-node-group-lkqs"
I0405 03:34:14.016776       1 scheduler_binder.go:265] AssumePodVolumes for pod "gc-2922/simpletest-rc-to-be-deleted-j22sz", node "e2e-test-peterhornyack-windows-node-group-lkqs": all PVCs bound and nothing to do
I0405 03:34:14.018125       1 factory.go:734] Attempting to bind simpletest-rc-to-be-deleted-j22sz to e2e-test-peterhornyack-windows-node-group-lkqs
I0405 03:34:14.021487       1 scheduler.go:575] pod gc-2922/simpletest-rc-to-be-deleted-8kbhp is bound successfully on node e2e-test-peterhornyack-windows-node-group-lkqs, 4 nodes evaluated, 2 nodes were found feasible
I0405 03:34:14.021584       1 scheduling_queue.go:895] About to try and schedule pod gc-2922/simpletest-rc-to-be-deleted-ltld7
I0405 03:34:14.021591       1 scheduler.go:454] Attempting to schedule pod: gc-2922/simpletest-rc-to-be-deleted-ltld7
I0405 03:34:14.025560       1 scheduler_binder.go:255] AssumePodVolumes for pod "gc-2922/simpletest-rc-to-be-deleted-ltld7", node "e2e-test-peterhornyack-windows-node-group-lkqs"
I0405 03:34:14.025573       1 scheduler_binder.go:265] AssumePodVolumes for pod "gc-2922/simpletest-rc-to-be-deleted-ltld7", node "e2e-test-peterhornyack-windows-node-group-lkqs": all PVCs bound and nothing to do
I0405 03:34:14.025615       1 factory.go:734] Attempting to bind simpletest-rc-to-be-deleted-ltld7 to e2e-test-peterhornyack-windows-node-group-lkqs
I0405 03:34:14.028118       1 scheduling_queue.go:895] About to try and schedule pod gc-2922/simpletest-rc-to-be-deleted-pgcms
I0405 03:34:14.028126       1 scheduler.go:454] Attempting to schedule pod: gc-2922/simpletest-rc-to-be-deleted-pgcms
I0405 03:34:14.028364       1 scheduler_binder.go:255] AssumePodVolumes for pod "gc-2922/simpletest-rc-to-be-deleted-pgcms", node "e2e-test-peterhornyack-windows-node-group-lkqs"
I0405 03:34:14.028373       1 scheduler_binder.go:265] AssumePodVolumes for pod "gc-2922/simpletest-rc-to-be-deleted-pgcms", node "e2e-test-peterhornyack-windows-node-group-lkqs": all PVCs bound and nothing to do
I0405 03:34:14.028395       1 factory.go:734] Attempting to bind simpletest-rc-to-be-deleted-pgcms to e2e-test-peterhornyack-windows-node-group-lkqs
I0405 03:34:14.036349       1 scheduler.go:575] pod gc-2922/simpletest-rc-to-be-deleted-8zhc7 is bound successfully on node e2e-test-peterhornyack-windows-node-group-lkqs, 4 nodes evaluated, 2 nodes were found feasible
I0405 03:34:14.039798       1 scheduling_queue.go:895] About to try and schedule pod gc-2922/simpletest-rc-to-be-deleted-9jxn7
I0405 03:34:14.039807       1 scheduler.go:454] Attempting to schedule pod: gc-2922/simpletest-rc-to-be-deleted-9jxn7
I0405 03:34:14.040103       1 scheduler_binder.go:255] AssumePodVolumes for pod "gc-2922/simpletest-rc-to-be-deleted-9jxn7", node "e2e-test-peterhornyack-windows-node-group-lkqs"
I0405 03:34:14.040112       1 scheduler_binder.go:265] AssumePodVolumes for pod "gc-2922/simpletest-rc-to-be-deleted-9jxn7", node "e2e-test-peterhornyack-windows-node-group-lkqs": all PVCs bound and nothing to do
I0405 03:34:14.040137       1 factory.go:734] Attempting to bind simpletest-rc-to-be-deleted-9jxn7 to e2e-test-peterhornyack-windows-node-group-lkqs
I0405 03:34:14.043508       1 scheduling_queue.go:895] About to try and schedule pod gc-2922/simpletest-rc-to-be-deleted-bngbh
I0405 03:34:14.043530       1 scheduler.go:454] Attempting to schedule pod: gc-2922/simpletest-rc-to-be-deleted-bngbh
I0405 03:34:14.044139       1 scheduler_binder.go:255] AssumePodVolumes for pod "gc-2922/simpletest-rc-to-be-deleted-bngbh", node "e2e-test-peterhornyack-windows-node-group-lkqs"
I0405 03:34:14.044149       1 scheduler_binder.go:265] AssumePodVolumes for pod "gc-2922/simpletest-rc-to-be-deleted-bngbh", node "e2e-test-peterhornyack-windows-node-group-lkqs": all PVCs bound and nothing to do
I0405 03:34:14.045976       1 factory.go:734] Attempting to bind simpletest-rc-to-be-deleted-bngbh to e2e-test-peterhornyack-windows-node-group-lkqs
I0405 03:34:14.046401       1 scheduling_queue.go:895] About to try and schedule pod gc-2922/simpletest-rc-to-be-deleted-5bxgk
I0405 03:34:14.046408       1 scheduler.go:454] Attempting to schedule pod: gc-2922/simpletest-rc-to-be-deleted-5bxgk
I0405 03:34:14.051286       1 scheduler_binder.go:255] AssumePodVolumes for pod "gc-2922/simpletest-rc-to-be-deleted-5bxgk", node "e2e-test-peterhornyack-windows-node-group-lkqs"
I0405 03:34:14.051302       1 scheduler_binder.go:265] AssumePodVolumes for pod "gc-2922/simpletest-rc-to-be-deleted-5bxgk", node "e2e-test-peterhornyack-windows-node-group-lkqs": all PVCs bound and nothing to do
I0405 03:34:14.051336       1 factory.go:734] Attempting to bind simpletest-rc-to-be-deleted-5bxgk to e2e-test-peterhornyack-windows-node-group-lkqs
I0405 03:34:14.055708       1 scheduler.go:575] pod gc-2922/simpletest-rc-to-be-deleted-j22sz is bound successfully on node e2e-test-peterhornyack-windows-node-group-lkqs, 4 nodes evaluated, 2 nodes were found feasible
I0405 03:34:14.062184       1 scheduler.go:575] pod gc-2922/simpletest-rc-to-be-deleted-pgcms is bound successfully on node e2e-test-peterhornyack-windows-node-group-lkqs, 4 nodes evaluated, 2 nodes were found feasible
I0405 03:34:14.062251       1 scheduler.go:575] pod gc-2922/simpletest-rc-to-be-deleted-ltld7 is bound successfully on node e2e-test-peterhornyack-windows-node-group-lkqs, 4 nodes evaluated, 2 nodes were found feasible
I0405 03:34:14.068778       1 scheduler.go:575] pod gc-2922/simpletest-rc-to-be-deleted-bngbh is bound successfully on node e2e-test-peterhornyack-windows-node-group-lkqs, 4 nodes evaluated, 2 nodes were found feasible
I0405 03:34:14.071483       1 scheduler.go:575] pod gc-2922/simpletest-rc-to-be-deleted-5bxgk is bound successfully on node e2e-test-peterhornyack-windows-node-group-lkqs, 4 nodes evaluated, 2 nodes were found feasible
I0405 03:34:14.071797       1 scheduler.go:575] pod gc-2922/simpletest-rc-to-be-deleted-9jxn7 is bound successfully on node e2e-test-peterhornyack-windows-node-group-lkqs, 4 nodes evaluated, 2 nodes were found feasible
I0405 03:34:17.363028       1 wrap.go:47] GET /healthz: (92.399µs) 200 [kube-probe/1.15+ 127.0.0.1:48952]
I0405 03:34:27.369154       1 wrap.go:47] GET /healthz: (79.365µs) 200 [kube-probe/1.15+ 127.0.0.1:49000]
I0405 03:34:32.617364       1 scheduling_queue.go:895] About to try and schedule pod init-container-4638/pod-init-4f2ef06a-b15e-48d4-a495-a3420bfa0bc3
I0405 03:34:32.617379       1 scheduler.go:454] Attempting to schedule pod: init-container-4638/pod-init-4f2ef06a-b15e-48d4-a495-a3420bfa0bc3
I0405 03:34:32.617942       1 scheduler_binder.go:255] AssumePodVolumes for pod "init-container-4638/pod-init-4f2ef06a-b15e-48d4-a495-a3420bfa0bc3", node "e2e-test-peterhornyack-windows-node-group-rqkw"
I0405 03:34:32.617954       1 scheduler_binder.go:265] AssumePodVolumes for pod "init-container-4638/pod-init-4f2ef06a-b15e-48d4-a495-a3420bfa0bc3", node "e2e-test-peterhornyack-windows-node-group-rqkw": all PVCs bound and nothing to do
I0405 03:34:32.618022       1 factory.go:734] Attempting to bind pod-init-4f2ef06a-b15e-48d4-a495-a3420bfa0bc3 to e2e-test-peterhornyack-windows-node-group-rqkw
I0405 03:34:32.628356       1 scheduler.go:575] pod init-container-4638/pod-init-4f2ef06a-b15e-48d4-a495-a3420bfa0bc3 is bound successfully on node e2e-test-peterhornyack-windows-node-group-rqkw, 4 nodes evaluated, 2 nodes were found feasible
I0405 03:34:37.363051       1 wrap.go:47] GET /healthz: (77.1µs) 200 [kube-probe/1.15+ 127.0.0.1:49038]
I0405 03:34:47.363030       1 wrap.go:47] GET /healthz: (99.46µs) 200 [kube-probe/1.15+ 127.0.0.1:49070]
I0405 03:34:57.363026       1 wrap.go:47] GET /healthz: (112.731µs) 200 [kube-probe/1.15+ 127.0.0.1:49102]
I0405 03:35:02.593235       1 reflector.go:384] k8s.io/client-go/informers/factory.go:133: Watch close - *v1.Service total 3 items received
I0405 03:35:07.362717       1 wrap.go:47] GET /healthz: (83.286µs) 200 [kube-probe/1.15+ 127.0.0.1:49138]
I0405 03:35:12.769378       1 scheduling_queue.go:895] About to try and schedule pod kubectl-5135/redis-master-46spv
I0405 03:35:12.769392       1 scheduler.go:454] Attempting to schedule pod: kubectl-5135/redis-master-46spv
I0405 03:35:12.771314       1 scheduler_binder.go:255] AssumePodVolumes for pod "kubectl-5135/redis-master-46spv", node "e2e-test-peterhornyack-windows-node-group-lkqs"
I0405 03:35:12.771328       1 scheduler_binder.go:265] AssumePodVolumes for pod "kubectl-5135/redis-master-46spv", node "e2e-test-peterhornyack-windows-node-group-lkqs": all PVCs bound and nothing to do
I0405 03:35:12.771381       1 factory.go:734] Attempting to bind redis-master-46spv to e2e-test-peterhornyack-windows-node-group-lkqs
I0405 03:35:12.781129       1 scheduler.go:575] pod kubectl-5135/redis-master-46spv is bound successfully on node e2e-test-peterhornyack-windows-node-group-lkqs, 4 nodes evaluated, 2 nodes were found feasible
I0405 03:35:17.362681       1 wrap.go:47] GET /healthz: (71.845µs) 200 [kube-probe/1.15+ 127.0.0.1:49176]
I0405 03:35:27.362963       1 wrap.go:47] GET /healthz: (102.714µs) 200 [kube-probe/1.15+ 127.0.0.1:49224]
I0405 03:35:37.363032       1 wrap.go:47] GET /healthz: (96.313µs) 200 [kube-probe/1.15+ 127.0.0.1:49258]
I0405 03:35:47.362366       1 wrap.go:47] GET /healthz: (75.875µs) 200 [kube-probe/1.15+ 127.0.0.1:49292]
I0405 03:35:47.598196       1 scheduling_queue.go:895] About to try and schedule pod kubectl-587/e2e-test-nginx-deployment-54fc8fc46-qtrvf
I0405 03:35:47.598222       1 scheduler.go:454] Attempting to schedule pod: kubectl-587/e2e-test-nginx-deployment-54fc8fc46-qtrvf
I0405 03:35:47.601208       1 scheduler_binder.go:255] AssumePodVolumes for pod "kubectl-587/e2e-test-nginx-deployment-54fc8fc46-qtrvf", node "e2e-test-peterhornyack-windows-node-group-lkqs"
I0405 03:35:47.601221       1 scheduler_binder.go:265] AssumePodVolumes for pod "kubectl-587/e2e-test-nginx-deployment-54fc8fc46-qtrvf", node "e2e-test-peterhornyack-windows-node-group-lkqs": all PVCs bound and nothing to do
I0405 03:35:47.601287       1 factory.go:734] Attempting to bind e2e-test-nginx-deployment-54fc8fc46-qtrvf to e2e-test-peterhornyack-windows-node-group-lkqs
I0405 03:35:47.616050       1 scheduler.go:575] pod kubectl-587/e2e-test-nginx-deployment-54fc8fc46-qtrvf is bound successfully on node e2e-test-peterhornyack-windows-node-group-lkqs, 4 nodes evaluated, 2 nodes were found feasible
I0405 03:35:55.973129       1 scheduling_queue.go:895] About to try and schedule pod pods-9840/back-off-cap
I0405 03:35:55.973143       1 scheduler.go:454] Attempting to schedule pod: pods-9840/back-off-cap
I0405 03:35:55.974750       1 scheduler_binder.go:255] AssumePodVolumes for pod "pods-9840/back-off-cap", node "e2e-test-peterhornyack-windows-node-group-lkqs"
I0405 03:35:55.974764       1 scheduler_binder.go:265] AssumePodVolumes for pod "pods-9840/back-off-cap", node "e2e-test-peterhornyack-windows-node-group-lkqs": all PVCs bound and nothing to do
I0405 03:35:55.974825       1 factory.go:734] Attempting to bind back-off-cap to e2e-test-peterhornyack-windows-node-group-lkqs
I0405 03:35:55.983095       1 scheduler.go:575] pod pods-9840/back-off-cap is bound successfully on node e2e-test-peterhornyack-windows-node-group-lkqs, 4 nodes evaluated, 2 nodes were found feasible
I0405 03:35:57.363149       1 wrap.go:47] GET /healthz: (74.526µs) 200 [kube-probe/1.15+ 127.0.0.1:49324]
I0405 03:36:07.363116       1 wrap.go:47] GET /healthz: (91.001µs) 200 [kube-probe/1.15+ 127.0.0.1:49362]
I0405 03:36:17.362799       1 wrap.go:47] GET /healthz: (65.162µs) 200 [kube-probe/1.15+ 127.0.0.1:49398]
I0405 03:36:24.585510       1 reflector.go:384] k8s.io/client-go/informers/factory.go:133: Watch close - *v1.PersistentVolume total 7 items received
I0405 03:36:27.363116       1 wrap.go:47] GET /healthz: (73.668µs) 200 [kube-probe/1.15+ 127.0.0.1:49446]
I0405 03:36:37.362818       1 wrap.go:47] GET /healthz: (81.989µs) 200 [kube-probe/1.15+ 127.0.0.1:49480]
I0405 03:36:47.362797       1 wrap.go:47] GET /healthz: (87.809µs) 200 [kube-probe/1.15+ 127.0.0.1:49512]
I0405 03:36:57.362994       1 wrap.go:47] GET /healthz: (93.276µs) 200 [kube-probe/1.15+ 127.0.0.1:49544]
I0405 03:37:07.363000       1 wrap.go:47] GET /healthz: (91.737µs) 200 [kube-probe/1.15+ 127.0.0.1:49582]
I0405 03:37:17.363118       1 wrap.go:47] GET /healthz: (77.943µs) 200 [kube-probe/1.15+ 127.0.0.1:49618]
I0405 03:37:17.612040       1 reflector.go:384] k8s.io/client-go/informers/factory.go:133: Watch close - *v1.StorageClass total 0 items received
I0405 03:37:27.362643       1 wrap.go:47] GET /healthz: (80.78µs) 200 [kube-probe/1.15+ 127.0.0.1:49666]
I0405 03:37:37.362994       1 wrap.go:47] GET /healthz: (107.427µs) 200 [kube-probe/1.15+ 127.0.0.1:49702]
I0405 03:37:47.363171       1 wrap.go:47] GET /healthz: (78.839µs) 200 [kube-probe/1.15+ 127.0.0.1:49734]
I0405 03:37:57.363038       1 wrap.go:47] GET /healthz: (93.298µs) 200 [kube-probe/1.15+ 127.0.0.1:49766]
I0405 03:38:07.362733       1 wrap.go:47] GET /healthz: (77.847µs) 200 [kube-probe/1.15+ 127.0.0.1:49802]
I0405 03:38:17.362779       1 wrap.go:47] GET /healthz: (67.96µs) 200 [kube-probe/1.15+ 127.0.0.1:49840]
I0405 03:38:27.363262       1 wrap.go:47] GET /healthz: (79.946µs) 200 [kube-probe/1.15+ 127.0.0.1:49888]
I0405 03:38:29.608619       1 reflector.go:384] k8s.io/client-go/informers/factory.go:133: Watch close - *v1.StatefulSet total 0 items received
I0405 03:38:37.363034       1 wrap.go:47] GET /healthz: (93.725µs) 200 [kube-probe/1.15+ 127.0.0.1:49922]
I0405 03:38:46.588404       1 reflector.go:384] k8s.io/client-go/informers/factory.go:133: Watch close - *v1beta1.PodDisruptionBudget total 0 items received
I0405 03:38:47.362980       1 wrap.go:47] GET /healthz: (100.233µs) 200 [kube-probe/1.15+ 127.0.0.1:49954]
I0405 03:38:57.363147       1 wrap.go:47] GET /healthz: (132.501µs) 200 [kube-probe/1.15+ 127.0.0.1:49986]
I0405 03:39:07.363004       1 wrap.go:47] GET /healthz: (96.582µs) 200 [kube-probe/1.15+ 127.0.0.1:50024]
I0405 03:39:10.590002       1 reflector.go:384] k8s.io/client-go/informers/factory.go:133: Watch close - *v1.Node total 27 items received
I0405 03:39:17.363134       1 wrap.go:47] GET /healthz: (90.7µs) 200 [kube-probe/1.15+ 127.0.0.1:50060]
I0405 03:39:27.362825       1 wrap.go:47] GET /healthz: (80.491µs) 200 [kube-probe/1.15+ 127.0.0.1:50108]
I0405 03:39:37.363499       1 wrap.go:47] GET /healthz: (79.908µs) 200 [kube-probe/1.15+ 127.0.0.1:50144]
I0405 03:39:45.597810       1 reflector.go:384] k8s.io/kubernetes/cmd/kube-scheduler/app/server.go:223: Watch close - *v1.Pod total 263 items received
I0405 03:39:47.364633       1 wrap.go:47] GET /healthz: (78.448µs) 200 [kube-probe/1.15+ 127.0.0.1:50176]
I0405 03:39:57.363267       1 wrap.go:47] GET /healthz: (76.432µs) 200 [kube-probe/1.15+ 127.0.0.1:50208]
I0405 03:40:07.362714       1 wrap.go:47] GET /healthz: (75.71µs) 200 [kube-probe/1.15+ 127.0.0.1:50244]
I0405 03:40:15.608004       1 reflector.go:384] k8s.io/client-go/informers/factory.go:133: Watch close - *v1.ReplicationController total 23 items received
I0405 03:40:17.362903       1 wrap.go:47] GET /healthz: (70.677µs) 200 [kube-probe/1.15+ 127.0.0.1:50280]
I0405 03:40:27.363373       1 wrap.go:47] GET /healthz: (81.264µs) 200 [kube-probe/1.15+ 127.0.0.1:50328]
I0405 03:40:37.363058       1 wrap.go:47] GET /healthz: (81.775µs) 200 [kube-probe/1.15+ 127.0.0.1:50364]
I0405 03:40:42.605413       1 reflector.go:384] k8s.io/client-go/informers/factory.go:133: Watch close - *v1.ReplicaSet total 49 items received
I0405 03:40:47.363043       1 wrap.go:47] GET /healthz: (84.549µs) 200 [kube-probe/1.15+ 127.0.0.1:50396]
I0405 03:40:57.363556       1 wrap.go:47] GET /healthz: (63.541µs) 200 [kube-probe/1.15+ 127.0.0.1:50430]
I0405 03:41:07.362713       1 wrap.go:47] GET /healthz: (52.239µs) 200 [kube-probe/1.15+ 127.0.0.1:50466]
I0405 03:41:17.363042       1 wrap.go:47] GET /healthz: (77.574µs) 200 [kube-probe/1.15+ 127.0.0.1:50502]
I0405 03:41:27.363427       1 wrap.go:47] GET /healthz: (82.668µs) 200 [kube-probe/1.15+ 127.0.0.1:50550]
I0405 03:41:37.362949       1 wrap.go:47] GET /healthz: (106.143µs) 200 [kube-probe/1.15+ 127.0.0.1:50584]
I0405 03:41:47.363498       1 wrap.go:47] GET /healthz: (76.541µs) 200 [kube-probe/1.15+ 127.0.0.1:50618]
I0405 03:41:57.363233       1 wrap.go:47] GET /healthz: (107.279µs) 200 [kube-probe/1.15+ 127.0.0.1:50650]
I0405 03:42:07.363534       1 wrap.go:47] GET /healthz: (148.768µs) 200 [kube-probe/1.15+ 127.0.0.1:50690]
I0405 03:42:15.597458       1 reflector.go:384] k8s.io/client-go/informers/factory.go:133: Watch close - *v1.PersistentVolumeClaim total 0 items received
I0405 03:42:17.362970       1 wrap.go:47] GET /healthz: (108.737µs) 200 [kube-probe/1.15+ 127.0.0.1:50726]
I0405 03:42:27.362964       1 wrap.go:47] GET /healthz: (86.721µs) 200 [kube-probe/1.15+ 127.0.0.1:50774]
I0405 03:42:33.614393       1 reflector.go:384] k8s.io/client-go/informers/factory.go:133: Watch close - *v1.StorageClass total 0 items received
I0405 03:42:37.363013       1 wrap.go:47] GET /healthz: (176.148µs) 200 [kube-probe/1.15+ 127.0.0.1:50808]
I0405 03:42:44.595641       1 reflector.go:384] k8s.io/client-go/informers/factory.go:133: Watch close - *v1.Service total 2 items received
I0405 03:42:47.362897       1 wrap.go:47] GET /healthz: (84.544µs) 200 [kube-probe/1.15+ 127.0.0.1:50840]
I0405 03:42:57.363377       1 wrap.go:47] GET /healthz: (224.294µs) 200 [kube-probe/1.15+ 127.0.0.1:50872]
I0405 03:43:07.362627       1 wrap.go:47] GET /healthz: (72.884µs) 200 [kube-probe/1.15+ 127.0.0.1:50908]
I0405 03:43:17.362782       1 wrap.go:47] GET /healthz: (65.574µs) 200 [kube-probe/1.15+ 127.0.0.1:50944]
I0405 03:43:27.363057       1 wrap.go:47] GET /healthz: (84.048µs) 200 [kube-probe/1.15+ 127.0.0.1:50994]
I0405 03:43:37.362619       1 wrap.go:47] GET /healthz: (76.727µs) 200 [kube-probe/1.15+ 127.0.0.1:51030]
I0405 03:43:47.362856       1 wrap.go:47] GET /healthz: (83.072µs) 200 [kube-probe/1.15+ 127.0.0.1:51062]
I0405 03:43:57.363049       1 wrap.go:47] GET /healthz: (79.454µs) 200 [kube-probe/1.15+ 127.0.0.1:51094]
I0405 03:44:07.363103       1 wrap.go:47] GET /healthz: (89.498µs) 200 [kube-probe/1.15+ 127.0.0.1:51130]
I0405 03:44:11.587963       1 reflector.go:384] k8s.io/client-go/informers/factory.go:133: Watch close - *v1.PersistentVolume total 0 items received
I0405 03:44:17.363196       1 wrap.go:47] GET /healthz: (75.28µs) 200 [kube-probe/1.15+ 127.0.0.1:51166]
I0405 03:44:27.363116       1 wrap.go:47] GET /healthz: (86.788µs) 200 [kube-probe/1.15+ 127.0.0.1:51214]
I0405 03:44:37.363042       1 wrap.go:47] GET /healthz: (93.796µs) 200 [kube-probe/1.15+ 127.0.0.1:51250]
I0405 03:44:47.362961       1 wrap.go:47] GET /healthz: (75.62µs) 200 [kube-probe/1.15+ 127.0.0.1:51282]
I0405 03:44:57.363245       1 wrap.go:47] GET /healthz: (92.027µs) 200 [kube-probe/1.15+ 127.0.0.1:51314]
I0405 03:45:07.363084       1 wrap.go:47] GET /healthz: (78.272µs) 200 [kube-probe/1.15+ 127.0.0.1:51352]
I0405 03:45:17.363071       1 wrap.go:47] GET /healthz: (82.524µs) 200 [kube-probe/1.15+ 127.0.0.1:51388]
I0405 03:45:27.363263       1 wrap.go:47] GET /healthz: (90.919µs) 200 [kube-probe/1.15+ 127.0.0.1:51532]
I0405 03:45:37.362864       1 wrap.go:47] GET /healthz: (74.613µs) 200 [kube-probe/1.15+ 127.0.0.1:51566]
I0405 03:45:47.362699       1 wrap.go:47] GET /healthz: (50.812µs) 200 [kube-probe/1.15+ 127.0.0.1:51598]
I0405 03:45:57.363024       1 wrap.go:47] GET /healthz: (95.248µs) 200 [kube-probe/1.15+ 127.0.0.1:51632]
I0405 03:46:07.362709       1 wrap.go:47] GET /healthz: (75.458µs) 200 [kube-probe/1.15+ 127.0.0.1:51668]
I0405 03:46:17.363050       1 wrap.go:47] GET /healthz: (77.796µs) 200 [kube-probe/1.15+ 127.0.0.1:51704]
I0405 03:46:27.363500       1 wrap.go:47] GET /healthz: (88.278µs) 200 [kube-probe/1.15+ 127.0.0.1:51752]
I0405 03:46:37.365043       1 wrap.go:47] GET /healthz: (115.127µs) 200 [kube-probe/1.15+ 127.0.0.1:51788]
I0405 03:46:47.363067       1 wrap.go:47] GET /healthz: (79.147µs) 200 [kube-probe/1.15+ 127.0.0.1:51820]
I0405 03:46:51.614102       1 reflector.go:384] k8s.io/client-go/informers/factory.go:133: Watch close - *v1.StatefulSet total 0 items received
I0405 03:46:57.364351       1 wrap.go:47] GET /healthz: (75.939µs) 200 [kube-probe/1.15+ 127.0.0.1:51852]
I0405 03:47:07.363280       1 wrap.go:47] GET /healthz: (75.808µs) 200 [kube-probe/1.15+ 127.0.0.1:51888]
I0405 03:47:08.590667       1 reflector.go:384] k8s.io/client-go/informers/factory.go:133: Watch close - *v1beta1.PodDisruptionBudget total 0 items received
I0405 03:47:17.363098       1 wrap.go:47] GET /healthz: (90.951µs) 200 [kube-probe/1.15+ 127.0.0.1:51926]
I0405 03:47:22.592455       1 reflector.go:384] k8s.io/client-go/informers/factory.go:133: Watch close - *v1.Node total 42 items received
I0405 03:47:27.362989       1 wrap.go:47] GET /healthz: (86.042µs) 200 [kube-probe/1.15+ 127.0.0.1:51974]
I0405 03:47:37.363300       1 wrap.go:47] GET /healthz: (82.502µs) 200 [kube-probe/1.15+ 127.0.0.1:52008]
I0405 03:47:47.363559       1 wrap.go:47] GET /healthz: (177.276µs) 200 [kube-probe/1.15+ 127.0.0.1:52040]
I0405 03:47:55.599687       1 reflector.go:384] k8s.io/client-go/informers/factory.go:133: Watch close - *v1.PersistentVolumeClaim total 0 items received
I0405 03:47:57.362915       1 wrap.go:47] GET /healthz: (81.247µs) 200 [kube-probe/1.15+ 127.0.0.1:52072]
I0405 03:48:01.600715       1 reflector.go:384] k8s.io/kubernetes/cmd/kube-scheduler/app/server.go:223: Watch close - *v1.Pod total 7 items received
I0405 03:48:07.363329       1 wrap.go:47] GET /healthz: (87.301µs) 200 [kube-probe/1.15+ 127.0.0.1:52110]
I0405 03:48:17.363009       1 wrap.go:47] GET /healthz: (97.314µs) 200 [kube-probe/1.15+ 127.0.0.1:52146]
I0405 03:48:27.364459       1 wrap.go:47] GET /healthz: (79.295µs) 200 [kube-probe/1.15+ 127.0.0.1:52196]
I0405 03:48:37.362981       1 wrap.go:47] GET /healthz: (106.469µs) 200 [kube-probe/1.15+ 127.0.0.1:52230]
I0405 03:48:47.363061       1 wrap.go:47] GET /healthz: (78.154µs) 200 [kube-probe/1.15+ 127.0.0.1:52262]
I0405 03:48:57.362807       1 wrap.go:47] GET /healthz: (87.374µs) 200 [kube-probe/1.15+ 127.0.0.1:52294]
I0405 03:49:07.363219       1 wrap.go:47] GET /healthz: (89.193µs) 200 [kube-probe/1.15+ 127.0.0.1:52330]
I0405 03:49:12.613575       1 reflector.go:384] k8s.io/client-go/informers/factory.go:133: Watch close - *v1.ReplicationController total 0 items received
I0405 03:49:17.362691       1 wrap.go:47] GET /healthz: (58.08µs) 200 [kube-probe/1.15+ 127.0.0.1:52366]
I0405 03:49:26.607894       1 reflector.go:384] k8s.io/client-go/informers/factory.go:133: Watch close - *v1.ReplicaSet total 0 items received
I0405 03:49:27.363282       1 wrap.go:47] GET /healthz: (90.122µs) 200 [kube-probe/1.15+ 127.0.0.1:52414]
I0405 03:49:37.363091       1 wrap.go:47] GET /healthz: (81.18µs) 200 [kube-probe/1.15+ 127.0.0.1:52450]
I0405 03:49:47.367269       1 wrap.go:47] GET /healthz: (87.022µs) 200 [kube-probe/1.15+ 127.0.0.1:52484]
I0405 03:49:57.363503       1 wrap.go:47] GET /healthz: (73.903µs) 200 [kube-probe/1.15+ 127.0.0.1:52516]
I0405 03:50:07.362694       1 wrap.go:47] GET /healthz: (111.99µs) 200 [kube-probe/1.15+ 127.0.0.1:52552]
I0405 03:50:17.363090       1 wrap.go:47] GET /healthz: (76.467µs) 200 [kube-probe/1.15+ 127.0.0.1:52588]
I0405 03:50:27.362898       1 wrap.go:47] GET /healthz: (82.711µs) 200 [kube-probe/1.15+ 127.0.0.1:52636]
I0405 03:50:37.362954       1 wrap.go:47] GET /healthz: (74.557µs) 200 [kube-probe/1.15+ 127.0.0.1:52670]
I0405 03:50:47.363056       1 wrap.go:47] GET /healthz: (79.58µs) 200 [kube-probe/1.15+ 127.0.0.1:52702]
I0405 03:50:57.362906       1 wrap.go:47] GET /healthz: (78.636µs) 200 [kube-probe/1.15+ 127.0.0.1:52736]
I0405 03:51:07.363714       1 wrap.go:47] GET /healthz: (244.312µs) 200 [kube-probe/1.15+ 127.0.0.1:52774]
I0405 03:51:17.363281       1 wrap.go:47] GET /healthz: (78.187µs) 200 [kube-probe/1.15+ 127.0.0.1:52810]
I0405 03:51:18.597764       1 reflector.go:384] k8s.io/client-go/informers/factory.go:133: Watch close - *v1.Service total 0 items received
I0405 03:51:27.362570       1 wrap.go:47] GET /healthz: (56.976µs) 200 [kube-probe/1.15+ 127.0.0.1:52858]
I0405 03:51:37.363150       1 wrap.go:47] GET /healthz: (80.586µs) 200 [kube-probe/1.15+ 127.0.0.1:52892]
I0405 03:51:47.363224       1 wrap.go:47] GET /healthz: (76.437µs) 200 [kube-probe/1.15+ 127.0.0.1:52924]
I0405 03:51:57.362654       1 wrap.go:47] GET /healthz: (76.329µs) 200 [kube-probe/1.15+ 127.0.0.1:52956]
I0405 03:51:58.616639       1 reflector.go:384] k8s.io/client-go/informers/factory.go:133: Watch close - *v1.StorageClass total 0 items received
I0405 03:52:07.362915       1 wrap.go:47] GET /healthz: (78.345µs) 200 [kube-probe/1.15+ 127.0.0.1:52992]
I0405 03:52:17.362745       1 wrap.go:47] GET /healthz: (82.405µs) 200 [kube-probe/1.15+ 127.0.0.1:53030]
I0405 03:52:27.362979       1 wrap.go:47] GET /healthz: (104.253µs) 200 [kube-probe/1.15+ 127.0.0.1:53078]
I0405 03:52:37.362999       1 wrap.go:47] GET /healthz: (96.451µs) 200 [kube-probe/1.15+ 127.0.0.1:53114]
I0405 03:52:47.362970       1 wrap.go:47] GET /healthz: (68.525µs) 200 [kube-probe/1.15+ 127.0.0.1:53148]
I0405 03:52:57.363161       1 wrap.go:47] GET /healthz: (78.003µs) 200 [kube-probe/1.15+ 127.0.0.1:53180]
I0405 03:53:07.362973       1 wrap.go:47] GET /healthz: (93.918µs) 200 [kube-probe/1.15+ 127.0.0.1:53216]
I0405 03:53:17.362678       1 wrap.go:47] GET /healthz: (108.067µs) 200 [kube-probe/1.15+ 127.0.0.1:53252]
I0405 03:53:27.363082       1 wrap.go:47] GET /healthz: (76.582µs) 200 [kube-probe/1.15+ 127.0.0.1:53300]
I0405 03:53:36.592767       1 reflector.go:384] k8s.io/client-go/informers/factory.go:133: Watch close - *v1beta1.PodDisruptionBudget total 0 items received
I0405 03:53:37.363612       1 wrap.go:47] GET /healthz: (74.682µs) 200 [kube-probe/1.15+ 127.0.0.1:53336]
I0405 03:53:47.363137       1 wrap.go:47] GET /healthz: (80.805µs) 200 [kube-probe/1.15+ 127.0.0.1:53368]
I0405 03:53:57.362891       1 wrap.go:47] GET /healthz: (81.113µs) 200 [kube-probe/1.15+ 127.0.0.1:53400]
I0405 03:54:04.590378       1 reflector.go:384] k8s.io/client-go/informers/factory.go:133: Watch close - *v1.PersistentVolume total 0 items received
I0405 03:54:07.362690       1 wrap.go:47] GET /healthz: (90.147µs) 200 [kube-probe/1.15+ 127.0.0.1:53438]
I0405 03:54:12.594636       1 reflector.go:384] k8s.io/client-go/informers/factory.go:133: Watch close - *v1.Node total 33 items received
I0405 03:54:17.362960       1 wrap.go:47] GET /healthz: (77.735µs) 200 [kube-probe/1.15+ 127.0.0.1:53474]
I0405 03:54:27.362858       1 wrap.go:47] GET /healthz: (77.178µs) 200 [kube-probe/1.15+ 127.0.0.1:53522]
I0405 03:54:30.602056       1 reflector.go:384] k8s.io/client-go/informers/factory.go:133: Watch close - *v1.PersistentVolumeClaim total 0 items received
I0405 03:54:37.362915       1 wrap.go:47] GET /healthz: (77.537µs) 200 [kube-probe/1.15+ 127.0.0.1:53556]
I0405 03:54:47.362880       1 wrap.go:47] GET /healthz: (97.667µs) 200 [kube-probe/1.15+ 127.0.0.1:53590]
I0405 03:54:57.363527       1 wrap.go:47] GET /healthz: (614.347µs) 200 [kube-probe/1.15+ 127.0.0.1:53622]
I0405 03:55:07.362950       1 wrap.go:47] GET /healthz: (80.042µs) 200 [kube-probe/1.15+ 127.0.0.1:53658]
I0405 03:55:17.362903       1 wrap.go:47] GET /healthz: (81.161µs) 200 [kube-probe/1.15+ 127.0.0.1:53694]
I0405 03:55:27.362884       1 wrap.go:47] GET /healthz: (76.991µs) 200 [kube-probe/1.15+ 127.0.0.1:53782]
I0405 03:55:31.603264       1 reflector.go:384] k8s.io/kubernetes/cmd/kube-scheduler/app/server.go:223: Watch close - *v1.Pod total 4 items received
I0405 03:55:35.617763       1 reflector.go:384] k8s.io/client-go/informers/factory.go:133: Watch close - *v1.StatefulSet total 0 items received
I0405 03:55:37.363130       1 wrap.go:47] GET /healthz: (69.861µs) 200 [kube-probe/1.15+ 127.0.0.1:53820]
I0405 03:55:47.363134       1 wrap.go:47] GET /healthz: (155.706µs) 200 [kube-probe/1.15+ 127.0.0.1:53852]
I0405 03:55:57.362787       1 wrap.go:47] GET /healthz: (77.235µs) 200 [kube-probe/1.15+ 127.0.0.1:53884]
I0405 03:56:07.362812       1 wrap.go:47] GET /healthz: (81.531µs) 200 [kube-probe/1.15+ 127.0.0.1:53922]
I0405 03:56:17.362784       1 wrap.go:47] GET /healthz: (77.387µs) 200 [kube-probe/1.15+ 127.0.0.1:53958]
I0405 03:56:27.363973       1 wrap.go:47] GET /healthz: (119.761µs) 200 [kube-probe/1.15+ 127.0.0.1:54008]
I0405 03:56:37.362734       1 wrap.go:47] GET /healthz: (62.294µs) 200 [kube-probe/1.15+ 127.0.0.1:54042]
I0405 03:56:47.362563       1 wrap.go:47] GET /healthz: (64.995µs) 200 [kube-probe/1.15+ 127.0.0.1:54074]
I0405 03:56:57.363137       1 wrap.go:47] GET /healthz: (89.333µs) 200 [kube-probe/1.15+ 127.0.0.1:54106]
I0405 03:57:02.618659       1 reflector.go:384] k8s.io/client-go/informers/factory.go:133: Watch close - *v1.StorageClass total 0 items received
I0405 03:57:07.363231       1 wrap.go:47] GET /healthz: (138.875µs) 200 [kube-probe/1.15+ 127.0.0.1:54156]
I0405 03:57:08.609994       1 reflector.go:384] k8s.io/client-go/informers/factory.go:133: Watch close - *v1.ReplicaSet total 0 items received
I0405 03:57:17.362984       1 wrap.go:47] GET /healthz: (93.055µs) 200 [kube-probe/1.15+ 127.0.0.1:54196]
I0405 03:57:27.362597       1 wrap.go:47] GET /healthz: (74.072µs) 200 [kube-probe/1.15+ 127.0.0.1:54244]
I0405 03:57:37.363337       1 wrap.go:47] GET /healthz: (79.431µs) 200 [kube-probe/1.15+ 127.0.0.1:54278]
I0405 03:57:47.362606       1 wrap.go:47] GET /healthz: (73.632µs) 200 [kube-probe/1.15+ 127.0.0.1:54310]
I0405 03:57:57.362818       1 wrap.go:47] GET /healthz: (85.795µs) 200 [kube-probe/1.15+ 127.0.0.1:54342]
I0405 03:58:07.362631       1 wrap.go:47] GET /healthz: (87.631µs) 200 [kube-probe/1.15+ 127.0.0.1:54378]
I0405 03:58:17.362620       1 wrap.go:47] GET /healthz: (76.34µs) 200 [kube-probe/1.15+ 127.0.0.1:54414]
I0405 03:58:23.617062       1 reflector.go:384] k8s.io/client-go/informers/factory.go:133: Watch close - *v1.ReplicationController total 0 items received
I0405 03:58:27.381287       1 wrap.go:47] GET /healthz: (73.949µs) 200 [kube-probe/1.15+ 127.0.0.1:54462]
I0405 03:58:37.369243       1 wrap.go:47] GET /healthz: (81.311µs) 200 [kube-probe/1.15+ 127.0.0.1:54500]
I0405 03:58:47.362880       1 wrap.go:47] GET /healthz: (75.564µs) 200 [kube-probe/1.15+ 127.0.0.1:54532]
I0405 03:58:57.362656       1 wrap.go:47] GET /healthz: (74.226µs) 200 [kube-probe/1.15+ 127.0.0.1:54564]
I0405 03:59:07.362854       1 wrap.go:47] GET /healthz: (77.388µs) 200 [kube-probe/1.15+ 127.0.0.1:54600]
I0405 03:59:17.362836       1 wrap.go:47] GET /healthz: (76.043µs) 200 [kube-probe/1.15+ 127.0.0.1:54636]
I0405 03:59:27.362640       1 wrap.go:47] GET /healthz: (78.905µs) 200 [kube-probe/1.15+ 127.0.0.1:54684]
I0405 03:59:37.364279       1 wrap.go:47] GET /healthz: (89.695µs) 200 [kube-probe/1.15+ 127.0.0.1:54718]
I0405 03:59:47.363106       1 wrap.go:47] GET /healthz: (80.577µs) 200 [kube-probe/1.15+ 127.0.0.1:54750]
I0405 03:59:57.362873       1 wrap.go:47] GET /healthz: (80.64µs) 200 [kube-probe/1.15+ 127.0.0.1:54784]
I0405 03:59:57.604664       1 reflector.go:384] k8s.io/client-go/informers/factory.go:133: Watch close - *v1.PersistentVolumeClaim total 0 items received
I0405 04:00:07.363059       1 wrap.go:47] GET /healthz: (82.405µs) 200 [kube-probe/1.15+ 127.0.0.1:54822]
I0405 04:00:09.599975       1 reflector.go:384] k8s.io/client-go/informers/factory.go:133: Watch close - *v1.Service total 0 items received
I0405 04:00:17.363044       1 wrap.go:47] GET /healthz: (77.307µs) 200 [kube-probe/1.15+ 127.0.0.1:54858]
I0405 04:00:27.362776       1 wrap.go:47] GET /healthz: (79.77µs) 200 [kube-probe/1.15+ 127.0.0.1:54906]
I0405 04:00:37.362846       1 wrap.go:47] GET /healthz: (76.83µs) 200 [kube-probe/1.15+ 127.0.0.1:54940]
I0405 04:00:43.596809       1 reflector.go:384] k8s.io/client-go/informers/factory.go:133: Watch close - *v1.Node total 33 items received
I0405 04:00:47.363619       1 wrap.go:47] GET /healthz: (152.705µs) 200 [kube-probe/1.15+ 127.0.0.1:54972]
I0405 04:00:57.363104       1 wrap.go:47] GET /healthz: (59.181µs) 200 [kube-probe/1.15+ 127.0.0.1:55004]
I0405 04:01:07.362798       1 wrap.go:47] GET /healthz: (79.342µs) 200 [kube-probe/1.15+ 127.0.0.1:55042]
I0405 04:01:17.362811       1 wrap.go:47] GET /healthz: (81.265µs) 200 [kube-probe/1.15+ 127.0.0.1:55078]
I0405 04:01:27.362961       1 wrap.go:47] GET /healthz: (75.842µs) 200 [kube-probe/1.15+ 127.0.0.1:55126]
I0405 04:01:37.362979       1 wrap.go:47] GET /healthz: (106.07µs) 200 [kube-probe/1.15+ 127.0.0.1:55162]
I0405 04:01:47.362641       1 wrap.go:47] GET /healthz: (58.412µs) 200 [kube-probe/1.15+ 127.0.0.1:55194]
I0405 04:01:57.362808       1 wrap.go:47] GET /healthz: (82.459µs) 200 [kube-probe/1.15+ 127.0.0.1:55226]
I0405 04:02:02.603110       1 reflector.go:384] k8s.io/client-go/informers/factory.go:133: Watch close - *v1beta1.PodDisruptionBudget total 0 items received
I0405 04:02:07.363449       1 wrap.go:47] GET /healthz: (86.253µs) 200 [kube-probe/1.15+ 127.0.0.1:55262]
I0405 04:02:17.362875       1 wrap.go:47] GET /healthz: (77.321µs) 200 [kube-probe/1.15+ 127.0.0.1:55298]
I0405 04:02:27.363278       1 wrap.go:47] GET /healthz: (80.977µs) 200 [kube-probe/1.15+ 127.0.0.1:55348]
I0405 04:02:37.362911       1 wrap.go:47] GET /healthz: (86.577µs) 200 [kube-probe/1.15+ 127.0.0.1:55382]
I0405 04:02:37.619974       1 reflector.go:384] k8s.io/client-go/informers/factory.go:133: Watch close - *v1.StatefulSet total 0 items received
I0405 04:02:40.592640       1 reflector.go:384] k8s.io/client-go/informers/factory.go:133: Watch close - *v1.PersistentVolume total 0 items received
I0405 04:02:47.362582       1 wrap.go:47] GET /healthz: (73.727µs) 200 [kube-probe/1.15+ 127.0.0.1:55414]
I0405 04:02:57.363080       1 wrap.go:47] GET /healthz: (92.006µs) 200 [kube-probe/1.15+ 127.0.0.1:55446]
I0405 04:03:06.605710       1 reflector.go:384] k8s.io/kubernetes/cmd/kube-scheduler/app/server.go:223: Watch close - *v1.Pod total 3 items received
I0405 04:03:07.363187       1 wrap.go:47] GET /healthz: (92.375µs) 200 [kube-probe/1.15+ 127.0.0.1:55484]
I0405 04:03:17.362666       1 wrap.go:47] GET /healthz: (80.764µs) 200 [kube-probe/1.15+ 127.0.0.1:55520]
I0405 04:03:27.362605       1 wrap.go:47] GET /healthz: (107.005µs) 200 [kube-probe/1.15+ 127.0.0.1:55568]
I0405 04:03:37.362979       1 wrap.go:47] GET /healthz: (102.391µs) 200 [kube-probe/1.15+ 127.0.0.1:55604]
I0405 04:03:47.363529       1 wrap.go:47] GET /healthz: (85.328µs) 200 [kube-probe/1.15+ 127.0.0.1:55638]
I0405 04:03:57.362642       1 wrap.go:47] GET /healthz: (81.761µs) 200 [kube-probe/1.15+ 127.0.0.1:55670]
I0405 04:04:07.363133       1 wrap.go:47] GET /healthz: (98.5µs) 200 [kube-probe/1.15+ 127.0.0.1:55706]
I0405 04:04:08.619382       1 reflector.go:384] k8s.io/client-go/informers/factory.go:133: Watch close - *v1.ReplicationController total 0 items received
I0405 04:04:17.362880       1 wrap.go:47] GET /healthz: (76.808µs) 200 [kube-probe/1.15+ 127.0.0.1:55742]
I0405 04:04:27.362962       1 wrap.go:47] GET /healthz: (84.567µs) 200 [kube-probe/1.15+ 127.0.0.1:55790]
I0405 04:04:37.363001       1 wrap.go:47] GET /healthz: (102.305µs) 200 [kube-probe/1.15+ 127.0.0.1:55826]
I0405 04:04:47.362587       1 wrap.go:47] GET /healthz: (85.195µs) 200 [kube-probe/1.15+ 127.0.0.1:55858]
I0405 04:04:57.362539       1 wrap.go:47] GET /healthz: (62.719µs) 200 [kube-probe/1.15+ 127.0.0.1:55892]
I0405 04:05:07.363815       1 wrap.go:47] GET /healthz: (88.884µs) 200 [kube-probe/1.15+ 127.0.0.1:55928]
I0405 04:05:17.362773       1 wrap.go:47] GET /healthz: (73.763µs) 200 [kube-probe/1.15+ 127.0.0.1:55964]
I0405 04:05:23.620999       1 reflector.go:384] k8s.io/client-go/informers/factory.go:133: Watch close - *v1.StorageClass total 0 items received
I0405 04:05:27.364088       1 wrap.go:47] GET /healthz: (129.439µs) 200 [kube-probe/1.15+ 127.0.0.1:56124]
I0405 04:05:37.362846       1 wrap.go:47] GET /healthz: (72.112µs) 200 [kube-probe/1.15+ 127.0.0.1:56162]
I0405 04:05:47.363087       1 wrap.go:47] GET /healthz: (79.304µs) 200 [kube-probe/1.15+ 127.0.0.1:56194]
I0405 04:05:57.363011       1 wrap.go:47] GET /healthz: (96.39µs) 200 [kube-probe/1.15+ 127.0.0.1:56226]
I0405 04:06:04.612139       1 reflector.go:384] k8s.io/client-go/informers/factory.go:133: Watch close - *v1.ReplicaSet total 0 items received
I0405 04:06:07.364377       1 wrap.go:47] GET /healthz: (96.527µs) 200 [kube-probe/1.15+ 127.0.0.1:56264]
I0405 04:06:17.363230       1 wrap.go:47] GET /healthz: (78.886µs) 200 [kube-probe/1.15+ 127.0.0.1:56302]
I0405 04:06:23.606934       1 reflector.go:384] k8s.io/client-go/informers/factory.go:133: Watch close - *v1.PersistentVolumeClaim total 0 items received
I0405 04:06:27.362948       1 wrap.go:47] GET /healthz: (83.754µs) 200 [kube-probe/1.15+ 127.0.0.1:56350]
I0405 04:06:36.602178       1 reflector.go:384] k8s.io/client-go/informers/factory.go:133: Watch close - *v1.Service total 0 items received
I0405 04:06:37.362835       1 wrap.go:47] GET /healthz: (76.962µs) 200 [kube-probe/1.15+ 127.0.0.1:56384]
I0405 04:06:47.362957       1 wrap.go:47] GET /healthz: (81.252µs) 200 [kube-probe/1.15+ 127.0.0.1:56416]
I0405 04:06:57.362998       1 wrap.go:47] GET /healthz: (92.407µs) 200 [kube-probe/1.15+ 127.0.0.1:56448]
I0405 04:07:07.363051       1 wrap.go:47] GET /healthz: (83.748µs) 200 [kube-probe/1.15+ 127.0.0.1:56484]
I0405 04:07:17.363313       1 wrap.go:47] GET /healthz: (190.503µs) 200 [kube-probe/1.15+ 127.0.0.1:56520]
I0405 04:07:27.362700       1 wrap.go:47] GET /healthz: (84.646µs) 200 [kube-probe/1.15+ 127.0.0.1:56570]
I0405 04:07:37.365253       1 wrap.go:47] GET /healthz: (74.525µs) 200 [kube-probe/1.15+ 127.0.0.1:56606]
I0405 04:07:47.362960       1 wrap.go:47] GET /healthz: (74.862µs) 200 [kube-probe/1.15+ 127.0.0.1:56638]
I0405 04:07:57.363410       1 wrap.go:47] GET /healthz: (79.315µs) 200 [kube-probe/1.15+ 127.0.0.1:56674]
I0405 04:08:07.363135       1 wrap.go:47] GET /healthz: (140.971µs) 200 [kube-probe/1.15+ 127.0.0.1:56710]
I0405 04:08:17.362635       1 wrap.go:47] GET /healthz: (83.367µs) 200 [kube-probe/1.15+ 127.0.0.1:56746]
I0405 04:08:27.362893       1 wrap.go:47] GET /healthz: (71.896µs) 200 [kube-probe/1.15+ 127.0.0.1:56794]
I0405 04:08:27.594850       1 reflector.go:384] k8s.io/client-go/informers/factory.go:133: Watch close - *v1.PersistentVolume total 0 items received
I0405 04:08:37.362679       1 wrap.go:47] GET /healthz: (82.64µs) 200 [kube-probe/1.15+ 127.0.0.1:56828]
I0405 04:08:47.362979       1 wrap.go:47] GET /healthz: (94.641µs) 200 [kube-probe/1.15+ 127.0.0.1:56862]
I0405 04:08:57.362781       1 wrap.go:47] GET /healthz: (77.142µs) 200 [kube-probe/1.15+ 127.0.0.1:56894]
I0405 04:09:07.363203       1 wrap.go:47] GET /healthz: (79.826µs) 200 [kube-probe/1.15+ 127.0.0.1:56932]
I0405 04:09:08.867722       1 scheduling_queue.go:895] About to try and schedule pod configmap-9856/pod-configmaps-871492e0-c707-4529-bd04-104f30357deb
I0405 04:09:08.867742       1 scheduler.go:454] Attempting to schedule pod: configmap-9856/pod-configmaps-871492e0-c707-4529-bd04-104f30357deb
I0405 04:09:08.868123       1 scheduler_binder.go:255] AssumePodVolumes for pod "configmap-9856/pod-configmaps-871492e0-c707-4529-bd04-104f30357deb", node "e2e-test-peterhornyack-windows-node-group-rqkw"
I0405 04:09:08.868135       1 scheduler_binder.go:265] AssumePodVolumes for pod "configmap-9856/pod-configmaps-871492e0-c707-4529-bd04-104f30357deb", node "e2e-test-peterhornyack-windows-node-group-rqkw": all PVCs bound and nothing to do
I0405 04:09:08.868268       1 factory.go:734] Attempting to bind pod-configmaps-871492e0-c707-4529-bd04-104f30357deb to e2e-test-peterhornyack-windows-node-group-rqkw
I0405 04:09:08.879179       1 scheduler.go:575] pod configmap-9856/pod-configmaps-871492e0-c707-4529-bd04-104f30357deb is bound successfully on node e2e-test-peterhornyack-windows-node-group-rqkw, 4 nodes evaluated, 2 nodes were found feasible
I0405 04:09:17.362640       1 wrap.go:47] GET /healthz: (74.794µs) 200 [kube-probe/1.15+ 127.0.0.1:56968]
I0405 04:09:23.605126       1 reflector.go:384] k8s.io/client-go/informers/factory.go:133: Watch close - *v1beta1.PodDisruptionBudget total 0 items received
I0405 04:09:27.362497       1 wrap.go:47] GET /healthz: (63.465µs) 200 [kube-probe/1.15+ 127.0.0.1:57016]
I0405 04:09:37.362861       1 wrap.go:47] GET /healthz: (77.084µs) 200 [kube-probe/1.15+ 127.0.0.1:57054]
I0405 04:09:42.607907       1 reflector.go:384] k8s.io/kubernetes/cmd/kube-scheduler/app/server.go:223: Watch close - *v1.Pod total 17 items received
I0405 04:09:45.126736       1 scheduling_queue.go:895] About to try and schedule pod gc-221/pod1
I0405 04:09:45.126750       1 scheduler.go:454] Attempting to schedule pod: gc-221/pod1
I0405 04:09:45.127820       1 scheduler_binder.go:255] AssumePodVolumes for pod "gc-221/pod1", node "e2e-test-peterhornyack-windows-node-group-lkqs"
I0405 04:09:45.127833       1 scheduler_binder.go:265] AssumePodVolumes for pod "gc-221/pod1", node "e2e-test-peterhornyack-windows-node-group-lkqs": all PVCs bound and nothing to do
I0405 04:09:45.127888       1 factory.go:734] Attempting to bind pod1 to e2e-test-peterhornyack-windows-node-group-lkqs
I0405 04:09:45.135314       1 scheduler.go:575] pod gc-221/pod1 is bound successfully on node e2e-test-peterhornyack-windows-node-group-lkqs, 4 nodes evaluated, 2 nodes were found feasible
I0405 04:09:45.179538       1 scheduling_queue.go:895] About to try and schedule pod gc-221/pod2
I0405 04:09:45.179554       1 scheduler.go:454] Attempting to schedule pod: gc-221/pod2
I0405 04:09:45.180014       1 scheduler_binder.go:255] AssumePodVolumes for pod "gc-221/pod2", node "e2e-test-peterhornyack-windows-node-group-lkqs"
I0405 04:09:45.180025       1 scheduler_binder.go:265] AssumePodVolumes for pod "gc-221/pod2", node "e2e-test-peterhornyack-windows-node-group-lkqs": all PVCs bound and nothing to do
I0405 04:09:45.180099       1 factory.go:734] Attempting to bind pod2 to e2e-test-peterhornyack-windows-node-group-lkqs
I0405 04:09:45.202476       1 scheduler.go:575] pod gc-221/pod2 is bound successfully on node e2e-test-peterhornyack-windows-node-group-lkqs, 4 nodes evaluated, 2 nodes were found feasible
I0405 04:09:45.234243       1 scheduling_queue.go:895] About to try and schedule pod gc-221/pod3
I0405 04:09:45.234257       1 scheduler.go:454] Attempting to schedule pod: gc-221/pod3
I0405 04:09:45.238619       1 scheduler_binder.go:255] AssumePodVolumes for pod "gc-221/pod3", node "e2e-test-peterhornyack-windows-node-group-lkqs"
I0405 04:09:45.238657       1 scheduler_binder.go:265] AssumePodVolumes for pod "gc-221/pod3", node "e2e-test-peterhornyack-windows-node-group-lkqs": all PVCs bound and nothing to do
I0405 04:09:45.238747       1 factory.go:734] Attempting to bind pod3 to e2e-test-peterhornyack-windows-node-group-lkqs
I0405 04:09:45.258286       1 scheduler.go:575] pod gc-221/pod3 is bound successfully on node e2e-test-peterhornyack-windows-node-group-lkqs, 4 nodes evaluated, 2 nodes were found feasible
I0405 04:09:47.363263       1 wrap.go:47] GET /healthz: (81.997µs) 200 [kube-probe/1.15+ 127.0.0.1:57086]
I0405 04:09:57.362514       1 wrap.go:47] GET /healthz: (51.547µs) 200 [kube-probe/1.15+ 127.0.0.1:57120]
I0405 04:10:06.810868       1 scheduling_queue.go:895] About to try and schedule pod container-lifecycle-hook-5631/pod-handle-http-request
I0405 04:10:06.810897       1 scheduler.go:454] Attempting to schedule pod: container-lifecycle-hook-5631/pod-handle-http-request
I0405 04:10:06.811310       1 scheduler_binder.go:255] AssumePodVolumes for pod "container-lifecycle-hook-5631/pod-handle-http-request", node "e2e-test-peterhornyack-windows-node-group-rqkw"
I0405 04:10:06.811335       1 scheduler_binder.go:265] AssumePodVolumes for pod "container-lifecycle-hook-5631/pod-handle-http-request", node "e2e-test-peterhornyack-windows-node-group-rqkw": all PVCs bound and nothing to do
I0405 04:10:06.811390       1 factory.go:734] Attempting to bind pod-handle-http-request to e2e-test-peterhornyack-windows-node-group-rqkw
I0405 04:10:06.819734       1 scheduler.go:575] pod container-lifecycle-hook-5631/pod-handle-http-request is bound successfully on node e2e-test-peterhornyack-windows-node-group-rqkw, 4 nodes evaluated, 2 nodes were found feasible
I0405 04:10:07.363109       1 wrap.go:47] GET /healthz: (91.071µs) 200 [kube-probe/1.15+ 127.0.0.1:57156]
I0405 04:10:15.005709       1 scheduling_queue.go:895] About to try and schedule pod container-lifecycle-hook-5631/pod-with-poststart-http-hook
I0405 04:10:15.005728       1 scheduler.go:454] Attempting to schedule pod: container-lifecycle-hook-5631/pod-with-poststart-http-hook
I0405 04:10:15.006045       1 scheduler_binder.go:255] AssumePodVolumes for pod "container-lifecycle-hook-5631/pod-with-poststart-http-hook", node "e2e-test-peterhornyack-windows-node-group-lkqs"
I0405 04:10:15.006069       1 scheduler_binder.go:265] AssumePodVolumes for pod "container-lifecycle-hook-5631/pod-with-poststart-http-hook", node "e2e-test-peterhornyack-windows-node-group-lkqs": all PVCs bound and nothing to do
I0405 04:10:15.006149       1 factory.go:734] Attempting to bind pod-with-poststart-http-hook to e2e-test-peterhornyack-windows-node-group-lkqs
I0405 04:10:15.015644       1 scheduler.go:575] pod container-lifecycle-hook-5631/pod-with-poststart-http-hook is bound successfully on node e2e-test-peterhornyack-windows-node-group-lkqs, 4 nodes evaluated, 2 nodes were found feasible
I0405 04:10:17.363048       1 wrap.go:47] GET /healthz: (81.275µs) 200 [kube-probe/1.15+ 127.0.0.1:57192]
I0405 04:10:27.362428       1 wrap.go:47] GET /healthz: (81.349µs) 200 [kube-probe/1.15+ 127.0.0.1:57240]
I0405 04:10:32.603679       1 reflector.go:384] k8s.io/client-go/informers/factory.go:133: Watch close - *v1.Node total 50 items received
I0405 04:10:37.363286       1 wrap.go:47] GET /healthz: (76.465µs) 200 [kube-probe/1.15+ 127.0.0.1:57276]
I0405 04:10:47.363249       1 wrap.go:47] GET /healthz: (78.354µs) 200 [kube-probe/1.15+ 127.0.0.1:57308]
I0405 04:10:51.508475       1 scheduling_queue.go:895] About to try and schedule pod services-9475/pod1
I0405 04:10:51.508502       1 scheduler.go:454] Attempting to schedule pod: services-9475/pod1
I0405 04:10:51.508988       1 scheduler_binder.go:255] AssumePodVolumes for pod "services-9475/pod1", node "e2e-test-peterhornyack-windows-node-group-rqkw"
I0405 04:10:51.508999       1 scheduler_binder.go:265] AssumePodVolumes for pod "services-9475/pod1", node "e2e-test-peterhornyack-windows-node-group-rqkw": all PVCs bound and nothing to do
I0405 04:10:51.509057       1 factory.go:734] Attempting to bind pod1 to e2e-test-peterhornyack-windows-node-group-rqkw
I0405 04:10:51.515327       1 scheduler.go:575] pod services-9475/pod1 is bound successfully on node e2e-test-peterhornyack-windows-node-group-rqkw, 4 nodes evaluated, 2 nodes were found feasible
I0405 04:10:57.362728       1 wrap.go:47] GET /healthz: (83.238µs) 200 [kube-probe/1.15+ 127.0.0.1:57342]
I0405 04:10:59.230659       1 scheduling_queue.go:895] About to try and schedule pod services-9475/pod2
I0405 04:10:59.230674       1 scheduler.go:454] Attempting to schedule pod: services-9475/pod2
I0405 04:10:59.232102       1 scheduler_binder.go:255] AssumePodVolumes for pod "services-9475/pod2", node "e2e-test-peterhornyack-windows-node-group-lkqs"
I0405 04:10:59.232116       1 scheduler_binder.go:265] AssumePodVolumes for pod "services-9475/pod2", node "e2e-test-peterhornyack-windows-node-group-lkqs": all PVCs bound and nothing to do
I0405 04:10:59.232187       1 factory.go:734] Attempting to bind pod2 to e2e-test-peterhornyack-windows-node-group-lkqs
I0405 04:10:59.242151       1 scheduler.go:575] pod services-9475/pod2 is bound successfully on node e2e-test-peterhornyack-windows-node-group-lkqs, 4 nodes evaluated, 2 nodes were found feasible
I0405 04:11:07.362654       1 wrap.go:47] GET /healthz: (51.183µs) 200 [kube-probe/1.15+ 127.0.0.1:57378]
I0405 04:11:11.621407       1 reflector.go:384] k8s.io/client-go/informers/factory.go:133: Watch close - *v1.ReplicationController total 0 items received
I0405 04:11:15.599024       1 scheduling_queue.go:895] About to try and schedule pod projected-5181/pod-projected-secrets-2c89af65-7aa5-4552-a900-7ed0842e63e7
I0405 04:11:15.599040       1 scheduler.go:454] Attempting to schedule pod: projected-5181/pod-projected-secrets-2c89af65-7aa5-4552-a900-7ed0842e63e7
I0405 04:11:15.599485       1 scheduler_binder.go:255] AssumePodVolumes for pod "projected-5181/pod-projected-secrets-2c89af65-7aa5-4552-a900-7ed0842e63e7", node "e2e-test-peterhornyack-windows-node-group-rqkw"
I0405 04:11:15.599514       1 scheduler_binder.go:265] AssumePodVolumes for pod "projected-5181/pod-projected-secrets-2c89af65-7aa5-4552-a900-7ed0842e63e7", node "e2e-test-peterhornyack-windows-node-group-rqkw": all PVCs bound and nothing to do
I0405 04:11:15.599569       1 factory.go:734] Attempting to bind pod-projected-secrets-2c89af65-7aa5-4552-a900-7ed0842e63e7 to e2e-test-peterhornyack-windows-node-group-rqkw
I0405 04:11:15.611118       1 scheduler.go:575] pod projected-5181/pod-projected-secrets-2c89af65-7aa5-4552-a900-7ed0842e63e7 is bound successfully on node e2e-test-peterhornyack-windows-node-group-rqkw, 4 nodes evaluated, 2 nodes were found feasible
I0405 04:11:17.363853       1 wrap.go:47] GET /healthz: (740.027µs) 200 [kube-probe/1.15+ 127.0.0.1:57416]
I0405 04:11:27.362585       1 wrap.go:47] GET /healthz: (75.827µs) 200 [kube-probe/1.15+ 127.0.0.1:57464]
I0405 04:11:37.362898       1 wrap.go:47] GET /healthz: (47.931µs) 200 [kube-probe/1.15+ 127.0.0.1:57498]
I0405 04:11:40.280567       1 scheduling_queue.go:895] About to try and schedule pod pods-377/server-envvars-624ddf3e-cacc-4457-9d31-d171c3e4bc21
I0405 04:11:40.280583       1 scheduler.go:454] Attempting to schedule pod: pods-377/server-envvars-624ddf3e-cacc-4457-9d31-d171c3e4bc21
I0405 04:11:40.282357       1 scheduler_binder.go:255] AssumePodVolumes for pod "pods-377/server-envvars-624ddf3e-cacc-4457-9d31-d171c3e4bc21", node "e2e-test-peterhornyack-windows-node-group-lkqs"
I0405 04:11:40.282375       1 scheduler_binder.go:265] AssumePodVolumes for pod "pods-377/server-envvars-624ddf3e-cacc-4457-9d31-d171c3e4bc21", node "e2e-test-peterhornyack-windows-node-group-lkqs": all PVCs bound and nothing to do
I0405 04:11:40.282440       1 factory.go:734] Attempting to bind server-envvars-624ddf3e-cacc-4457-9d31-d171c3e4bc21 to e2e-test-peterhornyack-windows-node-group-lkqs
I0405 04:11:40.290040       1 scheduler.go:575] pod pods-377/server-envvars-624ddf3e-cacc-4457-9d31-d171c3e4bc21 is bound successfully on node e2e-test-peterhornyack-windows-node-group-lkqs, 4 nodes evaluated, 2 nodes were found feasible
I0405 04:11:47.362685       1 wrap.go:47] GET /healthz: (54.065µs) 200 [kube-probe/1.15+ 127.0.0.1:57530]
I0405 04:11:48.505425       1 scheduling_queue.go:895] About to try and schedule pod pods-377/client-envvars-ad266b0f-f9f4-4f45-984c-ed5521dab8d7
I0405 04:11:48.505451       1 scheduler.go:454] Attempting to schedule pod: pods-377/client-envvars-ad266b0f-f9f4-4f45-984c-ed5521dab8d7
I0405 04:11:48.505882       1 scheduler_binder.go:255] AssumePodVolumes for pod "pods-377/client-envvars-ad266b0f-f9f4-4f45-984c-ed5521dab8d7", node "e2e-test-peterhornyack-windows-node-group-rqkw"
I0405 04:11:48.505895       1 scheduler_binder.go:265] AssumePodVolumes for pod "pods-377/client-envvars-ad266b0f-f9f4-4f45-984c-ed5521dab8d7", node "e2e-test-peterhornyack-windows-node-group-rqkw": all PVCs bound and nothing to do
I0405 04:11:48.505975       1 factory.go:734] Attempting to bind client-envvars-ad266b0f-f9f4-4f45-984c-ed5521dab8d7 to e2e-test-peterhornyack-windows-node-group-rqkw
I0405 04:11:48.514115       1 scheduler.go:575] pod pods-377/client-envvars-ad266b0f-f9f4-4f45-984c-ed5521dab8d7 is bound successfully on node e2e-test-peterhornyack-windows-node-group-rqkw, 4 nodes evaluated, 2 nodes were found feasible
I0405 04:11:53.623372       1 reflector.go:384] k8s.io/client-go/informers/factory.go:133: Watch close - *v1.StorageClass total 0 items received
I0405 04:11:57.362658       1 wrap.go:47] GET /healthz: (52.578µs) 200 [kube-probe/1.15+ 127.0.0.1:57562]
I0405 04:12:07.362884       1 wrap.go:47] GET /healthz: (94.926µs) 200 [kube-probe/1.15+ 127.0.0.1:57600]
I0405 04:12:10.622496       1 reflector.go:384] k8s.io/client-go/informers/factory.go:133: Watch close - *v1.StatefulSet total 0 items received
I0405 04:12:17.363150       1 wrap.go:47] GET /healthz: (131.384µs) 200 [kube-probe/1.15+ 127.0.0.1:57636]
I0405 04:12:20.932241       1 scheduling_queue.go:895] About to try and schedule pod gc-8997/simpletest.rc-h8bhd
I0405 04:12:20.932252       1 scheduler.go:454] Attempting to schedule pod: gc-8997/simpletest.rc-h8bhd
I0405 04:12:20.933861       1 scheduler_binder.go:255] AssumePodVolumes for pod "gc-8997/simpletest.rc-h8bhd", node "e2e-test-peterhornyack-windows-node-group-lkqs"
I0405 04:12:20.934626       1 scheduler_binder.go:265] AssumePodVolumes for pod "gc-8997/simpletest.rc-h8bhd", node "e2e-test-peterhornyack-windows-node-group-lkqs": all PVCs bound and nothing to do
I0405 04:12:20.936560       1 factory.go:734] Attempting to bind simpletest.rc-h8bhd to e2e-test-peterhornyack-windows-node-group-lkqs
I0405 04:12:20.941649       1 scheduling_queue.go:895] About to try and schedule pod gc-8997/simpletest.rc-qd29c
I0405 04:12:20.941659       1 scheduler.go:454] Attempting to schedule pod: gc-8997/simpletest.rc-qd29c
I0405 04:12:20.941899       1 scheduler_binder.go:255] AssumePodVolumes for pod "gc-8997/simpletest.rc-qd29c", node "e2e-test-peterhornyack-windows-node-group-lkqs"
I0405 04:12:20.941908       1 scheduler_binder.go:265] AssumePodVolumes for pod "gc-8997/simpletest.rc-qd29c", node "e2e-test-peterhornyack-windows-node-group-lkqs": all PVCs bound and nothing to do
I0405 04:12:20.945393       1 factory.go:734] Attempting to bind simpletest.rc-qd29c to e2e-test-peterhornyack-windows-node-group-lkqs
I0405 04:12:20.950293       1 scheduler.go:575] pod gc-8997/simpletest.rc-h8bhd is bound successfully on node e2e-test-peterhornyack-windows-node-group-lkqs, 4 nodes evaluated, 2 nodes were found feasible
I0405 04:12:20.969198       1 scheduler.go:575] pod gc-8997/simpletest.rc-qd29c is bound successfully on node e2e-test-peterhornyack-windows-node-group-lkqs, 4 nodes evaluated, 2 nodes were found feasible
I0405 04:12:27.363251       1 wrap.go:47] GET /healthz: (80.712µs) 200 [kube-probe/1.15+ 127.0.0.1:57684]
I0405 04:12:37.363797       1 wrap.go:47] GET /healthz: (107.974µs) 200 [kube-probe/1.15+ 127.0.0.1:57720]
I0405 04:12:47.362667       1 wrap.go:47] GET /healthz: (62.546µs) 200 [kube-probe/1.15+ 127.0.0.1:57752]
I0405 04:12:57.363060       1 wrap.go:47] GET /healthz: (75.964µs) 200 [kube-probe/1.15+ 127.0.0.1:57784]
I0405 04:12:57.934811       1 scheduling_queue.go:895] About to try and schedule pod provisioning-7997/pvc-volume-tester-writer-qbl58
I0405 04:12:57.934824       1 scheduler.go:454] Attempting to schedule pod: provisioning-7997/pvc-volume-tester-writer-qbl58
I0405 04:12:57.935826       1 predicates.go:452] PVC provisioning-7997/pvc-xnfr5 is not bound, assuming PVC matches predicate when counting limits
I0405 04:12:57.935941       1 predicates.go:452] PVC provisioning-7997/pvc-xnfr5 is not bound, assuming PVC matches predicate when counting limits
I0405 04:12:57.935956       1 predicates.go:452] PVC provisioning-7997/pvc-xnfr5 is not bound, assuming PVC matches predicate when counting limits
I0405 04:12:57.935980       1 scheduler_binder.go:683] No matching volumes for Pod "provisioning-7997/pvc-volume-tester-writer-qbl58", PVC "provisioning-7997/pvc-xnfr5" on node "e2e-test-peterhornyack-windows-node-group-lkqs"
I0405 04:12:57.935993       1 scheduler_binder.go:738] Provisioning for claims of pod "provisioning-7997/pvc-volume-tester-writer-qbl58" that has no matching volumes on node "e2e-test-peterhornyack-windows-node-group-lkqs" ...
I0405 04:12:57.936045       1 predicates.go:452] PVC provisioning-7997/pvc-xnfr5 is not bound, assuming PVC matches predicate when counting limits
I0405 04:12:57.937507       1 predicates.go:452] PVC provisioning-7997/pvc-xnfr5 is not bound, assuming PVC matches predicate when counting limits
I0405 04:12:57.937729       1 predicates.go:452] PVC provisioning-7997/pvc-xnfr5 is not bound, assuming PVC matches predicate when counting limits
I0405 04:12:57.937750       1 scheduler_binder.go:683] No matching volumes for Pod "provisioning-7997/pvc-volume-tester-writer-qbl58", PVC "provisioning-7997/pvc-xnfr5" on node "e2e-test-peterhornyack-windows-node-group-rqkw"
I0405 04:12:57.937762       1 scheduler_binder.go:738] Provisioning for claims of pod "provisioning-7997/pvc-volume-tester-writer-qbl58" that has no matching volumes on node "e2e-test-peterhornyack-windows-node-group-rqkw" ...
I0405 04:12:57.938000       1 scheduler_binder.go:255] AssumePodVolumes for pod "provisioning-7997/pvc-volume-tester-writer-qbl58", node "e2e-test-peterhornyack-windows-node-group-lkqs"
I0405 04:12:57.938036       1 scheduler_assume_cache.go:319] Assumed v1.PersistentVolumeClaim "provisioning-7997/pvc-xnfr5", version 16893
I0405 04:12:57.940231       1 scheduler_binder.go:330] BindPodVolumes for pod "provisioning-7997/pvc-volume-tester-writer-qbl58", node "e2e-test-peterhornyack-windows-node-group-lkqs"
I0405 04:12:58.916761       1 cache.go:643] Couldn't expire cache for pod provisioning-7997/pvc-volume-tester-writer-qbl58. Binding is still in progress.
I0405 04:12:59.917130       1 cache.go:643] Couldn't expire cache for pod provisioning-7997/pvc-volume-tester-writer-qbl58. Binding is still in progress.
I0405 04:13:00.917484       1 cache.go:643] Couldn't expire cache for pod provisioning-7997/pvc-volume-tester-writer-qbl58. Binding is still in progress.
I0405 04:13:00.949451       1 scheduler_binder.go:545] All PVCs for pod "provisioning-7997/pvc-volume-tester-writer-qbl58" are bound
I0405 04:13:00.949485       1 factory.go:734] Attempting to bind pvc-volume-tester-writer-qbl58 to e2e-test-peterhornyack-windows-node-group-lkqs
I0405 04:13:00.958251       1 scheduler.go:575] pod provisioning-7997/pvc-volume-tester-writer-qbl58 is bound successfully on node e2e-test-peterhornyack-windows-node-group-lkqs, 4 nodes evaluated, 2 nodes were found feasible
I0405 04:13:07.363080       1 wrap.go:47] GET /healthz: (79.102µs) 200 [kube-probe/1.15+ 127.0.0.1:57822]
I0405 04:13:17.362801       1 wrap.go:47] GET /healthz: (75.892µs) 200 [kube-probe/1.15+ 127.0.0.1:57858]
I0405 04:13:22.614541       1 reflector.go:384] k8s.io/client-go/informers/factory.go:133: Watch close - *v1.ReplicaSet total 0 items received
I0405 04:13:27.362988       1 wrap.go:47] GET /healthz: (91.568µs) 200 [kube-probe/1.15+ 127.0.0.1:57906]
I0405 04:13:37.362722       1 wrap.go:47] GET /healthz: (75.72µs) 200 [kube-probe/1.15+ 127.0.0.1:57942]
I0405 04:13:40.608702       1 reflector.go:384] k8s.io/client-go/informers/factory.go:133: Watch close - *v1.PersistentVolumeClaim total 5 items received
I0405 04:13:47.363773       1 wrap.go:47] GET /healthz: (78.404µs) 200 [kube-probe/1.15+ 127.0.0.1:57976]
I0405 04:13:57.362833       1 wrap.go:47] GET /healthz: (77.476µs) 200 [kube-probe/1.15+ 127.0.0.1:58008]
I0405 04:14:00.604346       1 reflector.go:384] k8s.io/client-go/informers/factory.go:133: Watch close - *v1.Service total 4 items received
I0405 04:14:07.363385       1 wrap.go:47] GET /healthz: (83.591µs) 200 [kube-probe/1.15+ 127.0.0.1:58048]
I0405 04:14:07.597185       1 reflector.go:384] k8s.io/client-go/informers/factory.go:133: Watch close - *v1.PersistentVolume total 3 items received
I0405 04:14:09.349289       1 scheduling_queue.go:895] About to try and schedule pod deployment-937/test-recreate-deployment-78b595d858-gktgq
I0405 04:14:09.349305       1 scheduler.go:454] Attempting to schedule pod: deployment-937/test-recreate-deployment-78b595d858-gktgq
I0405 04:14:09.355695       1 scheduler_binder.go:255] AssumePodVolumes for pod "deployment-937/test-recreate-deployment-78b595d858-gktgq", node "e2e-test-peterhornyack-windows-node-group-lkqs"
I0405 04:14:09.355714       1 scheduler_binder.go:265] AssumePodVolumes for pod "deployment-937/test-recreate-deployment-78b595d858-gktgq", node "e2e-test-peterhornyack-windows-node-group-lkqs": all PVCs bound and nothing to do
I0405 04:14:09.355784       1 factory.go:734] Attempting to bind test-recreate-deployment-78b595d858-gktgq to e2e-test-peterhornyack-windows-node-group-lkqs
I0405 04:14:09.398662       1 scheduler.go:575] pod deployment-937/test-recreate-deployment-78b595d858-gktgq is bound successfully on node e2e-test-peterhornyack-windows-node-group-lkqs, 4 nodes evaluated, 2 nodes were found feasible
I0405 04:14:17.363077       1 wrap.go:47] GET /healthz: (80.939µs) 200 [kube-probe/1.15+ 127.0.0.1:58084]
I0405 04:14:17.690602       1 scheduling_queue.go:895] About to try and schedule pod deployment-937/test-recreate-deployment-5ccf74d6d5-nr89d
I0405 04:14:17.690631       1 scheduler.go:454] Attempting to schedule pod: deployment-937/test-recreate-deployment-5ccf74d6d5-nr89d
I0405 04:14:17.691065       1 scheduler_binder.go:255] AssumePodVolumes for pod "deployment-937/test-recreate-deployment-5ccf74d6d5-nr89d", node "e2e-test-peterhornyack-windows-node-group-lkqs"
I0405 04:14:17.695224       1 scheduler_binder.go:265] AssumePodVolumes for pod "deployment-937/test-recreate-deployment-5ccf74d6d5-nr89d", node "e2e-test-peterhornyack-windows-node-group-lkqs": all PVCs bound and nothing to do
I0405 04:14:17.695319       1 factory.go:734] Attempting to bind test-recreate-deployment-5ccf74d6d5-nr89d to e2e-test-peterhornyack-windows-node-group-lkqs
I0405 04:14:17.716113       1 scheduler.go:575] pod deployment-937/test-recreate-deployment-5ccf74d6d5-nr89d is bound successfully on node e2e-test-peterhornyack-windows-node-group-lkqs, 4 nodes evaluated, 2 nodes were found feasible
I0405 04:14:25.892188       1 scheduling_queue.go:895] About to try and schedule pod replication-controller-8655/pod-release-s4cxz
I0405 04:14:25.892201       1 scheduler.go:454] Attempting to schedule pod: replication-controller-8655/pod-release-s4cxz
I0405 04:14:25.892734       1 scheduler_binder.go:255] AssumePodVolumes for pod "replication-controller-8655/pod-release-s4cxz", node "e2e-test-peterhornyack-windows-node-group-lkqs"
I0405 04:14:25.892745       1 scheduler_binder.go:265] AssumePodVolumes for pod "replication-controller-8655/pod-release-s4cxz", node "e2e-test-peterhornyack-windows-node-group-lkqs": all PVCs bound and nothing to do
I0405 04:14:25.892808       1 factory.go:734] Attempting to bind pod-release-s4cxz to e2e-test-peterhornyack-windows-node-group-lkqs
I0405 04:14:25.908112       1 scheduler.go:575] pod replication-controller-8655/pod-release-s4cxz is bound successfully on node e2e-test-peterhornyack-windows-node-group-lkqs, 4 nodes evaluated, 2 nodes were found feasible
I0405 04:14:26.032786       1 scheduling_queue.go:895] About to try and schedule pod replication-controller-8655/pod-release-j47rg
I0405 04:14:26.032798       1 scheduler.go:454] Attempting to schedule pod: replication-controller-8655/pod-release-j47rg
I0405 04:14:26.033151       1 scheduler_binder.go:255] AssumePodVolumes for pod "replication-controller-8655/pod-release-j47rg", node "e2e-test-peterhornyack-windows-node-group-lkqs"
I0405 04:14:26.033163       1 scheduler_binder.go:265] AssumePodVolumes for pod "replication-controller-8655/pod-release-j47rg", node "e2e-test-peterhornyack-windows-node-group-lkqs": all PVCs bound and nothing to do
I0405 04:14:26.033206       1 factory.go:734] Attempting to bind pod-release-j47rg to e2e-test-peterhornyack-windows-node-group-lkqs
I0405 04:14:26.045597       1 scheduler.go:575] pod replication-controller-8655/pod-release-j47rg is bound successfully on node e2e-test-peterhornyack-windows-node-group-lkqs, 4 nodes evaluated, 2 nodes were found feasible
I0405 04:14:27.362870       1 wrap.go:47] GET /healthz: (81.533µs) 200 [kube-probe/1.15+ 127.0.0.1:58132]
I0405 04:14:37.362957       1 wrap.go:47] GET /healthz: (78.148µs) 200 [kube-probe/1.15+ 127.0.0.1:58166]
I0405 04:14:37.612746       1 reflector.go:384] k8s.io/client-go/informers/factory.go:133: Watch close - *v1beta1.PodDisruptionBudget total 0 items received
I0405 04:14:37.636341       1 scheduling_queue.go:895] About to try and schedule pod kubectl-547/frontend-5fddd6fc77-r8jhr
I0405 04:14:37.636355       1 scheduler.go:454] Attempting to schedule pod: kubectl-547/frontend-5fddd6fc77-r8jhr
I0405 04:14:37.638268       1 scheduler_binder.go:255] AssumePodVolumes for pod "kubectl-547/frontend-5fddd6fc77-r8jhr", node "e2e-test-peterhornyack-windows-node-group-rqkw"
I0405 04:14:37.638286       1 scheduler_binder.go:265] AssumePodVolumes for pod "kubectl-547/frontend-5fddd6fc77-r8jhr", node "e2e-test-peterhornyack-windows-node-group-rqkw": all PVCs bound and nothing to do
I0405 04:14:37.638351       1 factory.go:734] Attempting to bind frontend-5fddd6fc77-r8jhr to e2e-test-peterhornyack-windows-node-group-rqkw
I0405 04:14:37.655269       1 scheduler.go:575] pod kubectl-547/frontend-5fddd6fc77-r8jhr is bound successfully on node e2e-test-peterhornyack-windows-node-group-rqkw, 4 nodes evaluated, 2 nodes were found feasible
I0405 04:14:37.655334       1 scheduling_queue.go:895] About to try and schedule pod kubectl-547/frontend-5fddd6fc77-8df6r
I0405 04:14:37.655340       1 scheduler.go:454] Attempting to schedule pod: kubectl-547/frontend-5fddd6fc77-8df6r
I0405 04:14:37.655904       1 scheduler_binder.go:255] AssumePodVolumes for pod "kubectl-547/frontend-5fddd6fc77-8df6r", node "e2e-test-peterhornyack-windows-node-group-lkqs"
I0405 04:14:37.655915       1 scheduler_binder.go:265] AssumePodVolumes for pod "kubectl-547/frontend-5fddd6fc77-8df6r", node "e2e-test-peterhornyack-windows-node-group-lkqs": all PVCs bound and nothing to do
I0405 04:14:37.661543       1 factory.go:734] Attempting to bind frontend-5fddd6fc77-8df6r to e2e-test-peterhornyack-windows-node-group-lkqs
I0405 04:14:37.666952       1 scheduling_queue.go:895] About to try and schedule pod kubectl-547/frontend-5fddd6fc77-gt7sc
I0405 04:14:37.666967       1 scheduler.go:454] Attempting to schedule pod: kubectl-547/frontend-5fddd6fc77-gt7sc
I0405 04:14:37.667325       1 scheduler_binder.go:255] AssumePodVolumes for pod "kubectl-547/frontend-5fddd6fc77-gt7sc", node "e2e-test-peterhornyack-windows-node-group-rqkw"
I0405 04:14:37.667335       1 scheduler_binder.go:265] AssumePodVolumes for pod "kubectl-547/frontend-5fddd6fc77-gt7sc", node "e2e-test-peterhornyack-windows-node-group-rqkw": all PVCs bound and nothing to do
I0405 04:14:37.667364       1 factory.go:734] Attempting to bind frontend-5fddd6fc77-gt7sc to e2e-test-peterhornyack-windows-node-group-rqkw
I0405 04:14:37.700487       1 scheduler.go:575] pod kubectl-547/frontend-5fddd6fc77-8df6r is bound successfully on node e2e-test-peterhornyack-windows-node-group-lkqs, 4 nodes evaluated, 2 nodes were found feasible
I0405 04:14:37.704025       1 scheduler.go:575] pod kubectl-547/frontend-5fddd6fc77-gt7sc is bound successfully on node e2e-test-peterhornyack-windows-node-group-rqkw, 4 nodes evaluated, 2 nodes were found feasible
I0405 04:14:38.027006       1 scheduling_queue.go:895] About to try and schedule pod kubectl-547/redis-master-84bdd8c4d6-lq9mx
I0405 04:14:38.027046       1 scheduler.go:454] Attempting to schedule pod: kubectl-547/redis-master-84bdd8c4d6-lq9mx
I0405 04:14:38.027573       1 scheduler_binder.go:255] AssumePodVolumes for pod "kubectl-547/redis-master-84bdd8c4d6-lq9mx", node "e2e-test-peterhornyack-windows-node-group-lkqs"
I0405 04:14:38.027584       1 scheduler_binder.go:265] AssumePodVolumes for pod "kubectl-547/redis-master-84bdd8c4d6-lq9mx", node "e2e-test-peterhornyack-windows-node-group-lkqs": all PVCs bound and nothing to do
I0405 04:14:38.027650       1 factory.go:734] Attempting to bind redis-master-84bdd8c4d6-lq9mx to e2e-test-peterhornyack-windows-node-group-lkqs
I0405 04:14:38.048137       1 scheduler.go:575] pod kubectl-547/redis-master-84bdd8c4d6-lq9mx is bound successfully on node e2e-test-peterhornyack-windows-node-group-lkqs, 4 nodes evaluated, 2 nodes were found feasible
I0405 04:14:38.412460       1 scheduling_queue.go:895] About to try and schedule pod kubectl-547/redis-slave-77df8b485c-sflr4
I0405 04:14:38.412474       1 scheduler.go:454] Attempting to schedule pod: kubectl-547/redis-slave-77df8b485c-sflr4
I0405 04:14:38.416915       1 scheduler_binder.go:255] AssumePodVolumes for pod "kubectl-547/redis-slave-77df8b485c-sflr4", node "e2e-test-peterhornyack-windows-node-group-rqkw"
I0405 04:14:38.416956       1 scheduler_binder.go:265] AssumePodVolumes for pod "kubectl-547/redis-slave-77df8b485c-sflr4", node "e2e-test-peterhornyack-windows-node-group-rqkw": all PVCs bound and nothing to do
I0405 04:14:38.417038       1 factory.go:734] Attempting to bind redis-slave-77df8b485c-sflr4 to e2e-test-peterhornyack-windows-node-group-rqkw
I0405 04:14:38.436317       1 scheduling_queue.go:895] About to try and schedule pod kubectl-547/redis-slave-77df8b485c-ndj6b
I0405 04:14:38.436329       1 scheduler.go:454] Attempting to schedule pod: kubectl-547/redis-slave-77df8b485c-ndj6b
I0405 04:14:38.439071       1 scheduler_binder.go:255] AssumePodVolumes for pod "kubectl-547/redis-slave-77df8b485c-ndj6b", node "e2e-test-peterhornyack-windows-node-group-lkqs"
I0405 04:14:38.439082       1 scheduler_binder.go:265] AssumePodVolumes for pod "kubectl-547/redis-slave-77df8b485c-ndj6b", node "e2e-test-peterhornyack-windows-node-group-lkqs": all PVCs bound and nothing to do
I0405 04:14:38.439128       1 factory.go:734] Attempting to bind redis-slave-77df8b485c-ndj6b to e2e-test-peterhornyack-windows-node-group-lkqs
I0405 04:14:38.458339       1 scheduler.go:575] pod kubectl-547/redis-slave-77df8b485c-ndj6b is bound successfully on node e2e-test-peterhornyack-windows-node-group-lkqs, 4 nodes evaluated, 2 nodes were found feasible
I0405 04:14:38.460761       1 scheduler.go:575] pod kubectl-547/redis-slave-77df8b485c-sflr4 is bound successfully on node e2e-test-peterhornyack-windows-node-group-rqkw, 4 nodes evaluated, 2 nodes were found feasible
I0405 04:14:47.362955       1 wrap.go:47] GET /healthz: (76.68µs) 200 [kube-probe/1.15+ 127.0.0.1:58200]
I0405 04:14:57.363036       1 wrap.go:47] GET /healthz: (90.732µs) 200 [kube-probe/1.15+ 127.0.0.1:58232]
I0405 04:15:07.362983       1 wrap.go:47] GET /healthz: (103.307µs) 200 [kube-probe/1.15+ 127.0.0.1:58272]
I0405 04:15:17.362875       1 wrap.go:47] GET /healthz: (59.739µs) 200 [kube-probe/1.15+ 127.0.0.1:58308]
I0405 04:15:27.363442       1 wrap.go:47] GET /healthz: (85.881µs) 200 [kube-probe/1.15+ 127.0.0.1:58356]
I0405 04:15:37.363043       1 wrap.go:47] GET /healthz: (93.953µs) 200 [kube-probe/1.15+ 127.0.0.1:58392]
I0405 04:15:47.362589       1 wrap.go:47] GET /healthz: (71.515µs) 200 [kube-probe/1.15+ 127.0.0.1:58428]
I0405 04:15:57.363059       1 wrap.go:47] GET /healthz: (90.496µs) 200 [kube-probe/1.15+ 127.0.0.1:58462]
I0405 04:16:07.362808       1 wrap.go:47] GET /healthz: (78.74µs) 200 [kube-probe/1.15+ 127.0.0.1:58498]
I0405 04:16:17.364964       1 wrap.go:47] GET /healthz: (88.044µs) 200 [kube-probe/1.15+ 127.0.0.1:58534]
I0405 04:16:18.100640       1 scheduling_queue.go:895] About to try and schedule pod kubectl-204/update-demo-nautilus-wqbzr
I0405 04:16:18.100653       1 scheduler.go:454] Attempting to schedule pod: kubectl-204/update-demo-nautilus-wqbzr
I0405 04:16:18.104310       1 scheduler_binder.go:255] AssumePodVolumes for pod "kubectl-204/update-demo-nautilus-wqbzr", node "e2e-test-peterhornyack-windows-node-group-rqkw"
I0405 04:16:18.104341       1 scheduler_binder.go:265] AssumePodVolumes for pod "kubectl-204/update-demo-nautilus-wqbzr", node "e2e-test-peterhornyack-windows-node-group-rqkw": all PVCs bound and nothing to do
I0405 04:16:18.104394       1 factory.go:734] Attempting to bind update-demo-nautilus-wqbzr to e2e-test-peterhornyack-windows-node-group-rqkw
I0405 04:16:18.111801       1 scheduling_queue.go:895] About to try and schedule pod kubectl-204/update-demo-nautilus-6ptfm
I0405 04:16:18.111813       1 scheduler.go:454] Attempting to schedule pod: kubectl-204/update-demo-nautilus-6ptfm
I0405 04:16:18.112438       1 scheduler_binder.go:255] AssumePodVolumes for pod "kubectl-204/update-demo-nautilus-6ptfm", node "e2e-test-peterhornyack-windows-node-group-lkqs"
I0405 04:16:18.112448       1 scheduler_binder.go:265] AssumePodVolumes for pod "kubectl-204/update-demo-nautilus-6ptfm", node "e2e-test-peterhornyack-windows-node-group-lkqs": all PVCs bound and nothing to do
I0405 04:16:18.112478       1 factory.go:734] Attempting to bind update-demo-nautilus-6ptfm to e2e-test-peterhornyack-windows-node-group-lkqs
I0405 04:16:18.123798       1 scheduler.go:575] pod kubectl-204/update-demo-nautilus-wqbzr is bound successfully on node e2e-test-peterhornyack-windows-node-group-rqkw, 4 nodes evaluated, 2 nodes were found feasible
I0405 04:16:18.131357       1 scheduler.go:575] pod kubectl-204/update-demo-nautilus-6ptfm is bound successfully on node e2e-test-peterhornyack-windows-node-group-lkqs, 4 nodes evaluated, 2 nodes were found feasible
I0405 04:16:27.363144       1 wrap.go:47] GET /healthz: (83.645µs) 200 [kube-probe/1.15+ 127.0.0.1:58584]
I0405 04:16:33.606548       1 reflector.go:384] k8s.io/client-go/informers/factory.go:133: Watch close - *v1.Node total 33 items received
I0405 04:16:37.365405       1 wrap.go:47] GET /healthz: (85.569µs) 200 [kube-probe/1.15+ 127.0.0.1:58624]
I0405 04:16:37.855358       1 scheduling_queue.go:895] About to try and schedule pod kubectl-204/update-demo-nautilus-s9j9x
I0405 04:16:37.855369       1 scheduler.go:454] Attempting to schedule pod: kubectl-204/update-demo-nautilus-s9j9x
I0405 04:16:37.855698       1 scheduler_binder.go:255] AssumePodVolumes for pod "kubectl-204/update-demo-nautilus-s9j9x", node "e2e-test-peterhornyack-windows-node-group-lkqs"
I0405 04:16:37.855746       1 scheduler_binder.go:265] AssumePodVolumes for pod "kubectl-204/update-demo-nautilus-s9j9x", node "e2e-test-peterhornyack-windows-node-group-lkqs": all PVCs bound and nothing to do
I0405 04:16:37.855787       1 factory.go:734] Attempting to bind update-demo-nautilus-s9j9x to e2e-test-peterhornyack-windows-node-group-lkqs
I0405 04:16:37.868451       1 scheduler.go:575] pod kubectl-204/update-demo-nautilus-s9j9x is bound successfully on node e2e-test-peterhornyack-windows-node-group-lkqs, 4 nodes evaluated, 2 nodes were found feasible
I0405 04:16:47.363067       1 wrap.go:47] GET /healthz: (76.058µs) 200 [kube-probe/1.15+ 127.0.0.1:58656]
I0405 04:16:48.623981       1 reflector.go:384] k8s.io/client-go/informers/factory.go:133: Watch close - *v1.ReplicationController total 23 items received
I0405 04:16:57.362628       1 wrap.go:47] GET /healthz: (49.242µs) 200 [kube-probe/1.15+ 127.0.0.1:58690]
I0405 04:16:59.393001       1 scheduling_queue.go:895] About to try and schedule pod statefulset-5706/ss2-0
I0405 04:16:59.393028       1 scheduler.go:454] Attempting to schedule pod: statefulset-5706/ss2-0
I0405 04:16:59.396336       1 scheduler_binder.go:255] AssumePodVolumes for pod "statefulset-5706/ss2-0", node "e2e-test-peterhornyack-windows-node-group-lkqs"
I0405 04:16:59.396367       1 scheduler_binder.go:265] AssumePodVolumes for pod "statefulset-5706/ss2-0", node "e2e-test-peterhornyack-windows-node-group-lkqs": all PVCs bound and nothing to do
I0405 04:16:59.396436       1 factory.go:734] Attempting to bind ss2-0 to e2e-test-peterhornyack-windows-node-group-lkqs
I0405 04:16:59.408798       1 scheduler.go:575] pod statefulset-5706/ss2-0 is bound successfully on node e2e-test-peterhornyack-windows-node-group-lkqs, 4 nodes evaluated, 2 nodes were found feasible
I0405 04:17:07.362634       1 wrap.go:47] GET /healthz: (62.851µs) 200 [kube-probe/1.15+ 127.0.0.1:58728]
I0405 04:17:07.713833       1 scheduling_queue.go:895] About to try and schedule pod statefulset-5706/ss2-1
I0405 04:17:07.713846       1 scheduler.go:454] Attempting to schedule pod: statefulset-5706/ss2-1
I0405 04:17:07.718202       1 scheduler_binder.go:255] AssumePodVolumes for pod "statefulset-5706/ss2-1", node "e2e-test-peterhornyack-windows-node-group-lkqs"
I0405 04:17:07.718217       1 scheduler_binder.go:265] AssumePodVolumes for pod "statefulset-5706/ss2-1", node "e2e-test-peterhornyack-windows-node-group-lkqs": all PVCs bound and nothing to do
I0405 04:17:07.718278       1 factory.go:734] Attempting to bind ss2-1 to e2e-test-peterhornyack-windows-node-group-lkqs
I0405 04:17:07.728264       1 scheduler.go:575] pod statefulset-5706/ss2-1 is bound successfully on node e2e-test-peterhornyack-windows-node-group-lkqs, 4 nodes evaluated, 2 nodes were found feasible
I0405 04:17:13.706400       1 scheduling_queue.go:895] About to try and schedule pod statefulset-5706/ss2-2
I0405 04:17:13.706414       1 scheduler.go:454] Attempting to schedule pod: statefulset-5706/ss2-2
I0405 04:17:13.710241       1 scheduler_binder.go:255] AssumePodVolumes for pod "statefulset-5706/ss2-2", node "e2e-test-peterhornyack-windows-node-group-lkqs"
I0405 04:17:13.710259       1 scheduler_binder.go:265] AssumePodVolumes for pod "statefulset-5706/ss2-2", node "e2e-test-peterhornyack-windows-node-group-lkqs": all PVCs bound and nothing to do
I0405 04:17:13.710336       1 factory.go:734] Attempting to bind ss2-2 to e2e-test-peterhornyack-windows-node-group-lkqs
I0405 04:17:13.728155       1 scheduler.go:575] pod statefulset-5706/ss2-2 is bound successfully on node e2e-test-peterhornyack-windows-node-group-lkqs, 4 nodes evaluated, 2 nodes were found feasible
I0405 04:17:17.362986       1 wrap.go:47] GET /healthz: (149.693µs) 200 [kube-probe/1.15+ 127.0.0.1:58764]
I0405 04:17:27.363004       1 wrap.go:47] GET /healthz: (85.953µs) 200 [kube-probe/1.15+ 127.0.0.1:58812]
I0405 04:17:37.363150       1 wrap.go:47] GET /healthz: (75.355µs) 200 [kube-probe/1.15+ 127.0.0.1:58848]
I0405 04:17:38.449682       1 scheduling_queue.go:895] About to try and schedule pod statefulset-5706/ss2-2
I0405 04:17:38.457070       1 scheduler.go:454] Attempting to schedule pod: statefulset-5706/ss2-2
I0405 04:17:38.457544       1 scheduler_binder.go:255] AssumePodVolumes for pod "statefulset-5706/ss2-2", node "e2e-test-peterhornyack-windows-node-group-rqkw"
I0405 04:17:38.457555       1 scheduler_binder.go:265] AssumePodVolumes for pod "statefulset-5706/ss2-2", node "e2e-test-peterhornyack-windows-node-group-rqkw": all PVCs bound and nothing to do
I0405 04:17:38.457611       1 factory.go:734] Attempting to bind ss2-2 to e2e-test-peterhornyack-windows-node-group-rqkw
I0405 04:17:38.474651       1 scheduler.go:575] pod statefulset-5706/ss2-2 is bound successfully on node e2e-test-peterhornyack-windows-node-group-rqkw, 4 nodes evaluated, 2 nodes were found feasible
I0405 04:17:40.164384       1 scheduling_queue.go:895] About to try and schedule pod statefulset-5706/ss2-0
I0405 04:17:40.164398       1 scheduler.go:454] Attempting to schedule pod: statefulset-5706/ss2-0
I0405 04:17:40.164794       1 scheduler_binder.go:255] AssumePodVolumes for pod "statefulset-5706/ss2-0", node "e2e-test-peterhornyack-windows-node-group-lkqs"
I0405 04:17:40.164805       1 scheduler_binder.go:265] AssumePodVolumes for pod "statefulset-5706/ss2-0", node "e2e-test-peterhornyack-windows-node-group-lkqs": all PVCs bound and nothing to do
I0405 04:17:40.164877       1 factory.go:734] Attempting to bind ss2-0 to e2e-test-peterhornyack-windows-node-group-lkqs
I0405 04:17:40.186505       1 scheduler.go:575] pod statefulset-5706/ss2-0 is bound successfully on node e2e-test-peterhornyack-windows-node-group-lkqs, 4 nodes evaluated, 2 nodes were found feasible
I0405 04:17:47.363286       1 wrap.go:47] GET /healthz: (82.158µs) 200 [kube-probe/1.15+ 127.0.0.1:58880]
I0405 04:17:47.685884       1 scheduling_queue.go:895] About to try and schedule pod statefulset-5706/ss2-2
I0405 04:17:47.685899       1 scheduler.go:454] Attempting to schedule pod: statefulset-5706/ss2-2
I0405 04:17:47.690071       1 scheduler_binder.go:255] AssumePodVolumes for pod "statefulset-5706/ss2-2", node "e2e-test-peterhornyack-windows-node-group-rqkw"
I0405 04:17:47.690103       1 scheduler_binder.go:265] AssumePodVolumes for pod "statefulset-5706/ss2-2", node "e2e-test-peterhornyack-windows-node-group-rqkw": all PVCs bound and nothing to do
I0405 04:17:47.690165       1 factory.go:734] Attempting to bind ss2-2 to e2e-test-peterhornyack-windows-node-group-rqkw
I0405 04:17:47.709770       1 scheduler.go:575] pod statefulset-5706/ss2-2 is bound successfully on node e2e-test-peterhornyack-windows-node-group-rqkw, 4 nodes evaluated, 2 nodes were found feasible
I0405 04:17:57.363286       1 wrap.go:47] GET /healthz: (87.274µs) 200 [kube-probe/1.15+ 127.0.0.1:58912]
I0405 04:18:07.362942       1 wrap.go:47] GET /healthz: (104.491µs) 200 [kube-probe/1.15+ 127.0.0.1:58950]
