I0427 00:00:26.792376       1 reflector.go:384] k8s.io/client-go/informers/factory.go:133: Watch close - *v1.PersistentVolume total 0 items received
I0427 00:00:31.389305       1 wrap.go:47] GET /healthz: (68.376µs) 200 [kube-probe/1.15+ 127.0.0.1:47834]
I0427 00:00:41.389574       1 wrap.go:47] GET /healthz: (73.715µs) 200 [kube-probe/1.15+ 127.0.0.1:47884]
I0427 00:00:51.389404       1 wrap.go:47] GET /healthz: (49.418µs) 200 [kube-probe/1.15+ 127.0.0.1:47916]
I0427 00:01:01.389371       1 wrap.go:47] GET /healthz: (62.225µs) 200 [kube-probe/1.15+ 127.0.0.1:47952]
I0427 00:01:11.389740       1 wrap.go:47] GET /healthz: (78.156µs) 200 [kube-probe/1.15+ 127.0.0.1:47988]
I0427 00:01:17.784742       1 reflector.go:384] k8s.io/client-go/informers/factory.go:133: Watch close - *v1.ReplicationController total 0 items received
I0427 00:01:21.389738       1 wrap.go:47] GET /healthz: (71.604µs) 200 [kube-probe/1.15+ 127.0.0.1:48020]
I0427 00:01:31.389624       1 wrap.go:47] GET /healthz: (74.877µs) 200 [kube-probe/1.15+ 127.0.0.1:48056]
I0427 00:01:41.389818       1 wrap.go:47] GET /healthz: (73.699µs) 200 [kube-probe/1.15+ 127.0.0.1:48106]
I0427 00:01:45.798936       1 reflector.go:384] k8s.io/client-go/informers/factory.go:133: Watch close - *v1.ReplicaSet total 0 items received
I0427 00:01:51.389895       1 wrap.go:47] GET /healthz: (76.849µs) 200 [kube-probe/1.15+ 127.0.0.1:48138]
I0427 00:02:01.389499       1 wrap.go:47] GET /healthz: (70.181µs) 200 [kube-probe/1.15+ 127.0.0.1:48174]
I0427 00:02:06.809124       1 reflector.go:384] k8s.io/client-go/informers/factory.go:133: Watch close - *v1.PersistentVolumeClaim total 0 items received
I0427 00:02:11.389471       1 wrap.go:47] GET /healthz: (46.901µs) 200 [kube-probe/1.15+ 127.0.0.1:48210]
I0427 00:02:13.269320       1 scheduling_queue.go:895] About to try and schedule pod secrets-5257/pod-secrets-da2882a8-bf90-46e4-9e74-57883f84395a
I0427 00:02:13.269347       1 scheduler.go:454] Attempting to schedule pod: secrets-5257/pod-secrets-da2882a8-bf90-46e4-9e74-57883f84395a
I0427 00:02:13.270241       1 scheduler_binder.go:255] AssumePodVolumes for pod "secrets-5257/pod-secrets-da2882a8-bf90-46e4-9e74-57883f84395a", node "e2e-test-peterhornyack-windows-node-group-mdn5"
I0427 00:02:13.270254       1 scheduler_binder.go:265] AssumePodVolumes for pod "secrets-5257/pod-secrets-da2882a8-bf90-46e4-9e74-57883f84395a", node "e2e-test-peterhornyack-windows-node-group-mdn5": all PVCs bound and nothing to do
I0427 00:02:13.270287       1 factory.go:734] Attempting to bind pod-secrets-da2882a8-bf90-46e4-9e74-57883f84395a to e2e-test-peterhornyack-windows-node-group-mdn5
I0427 00:02:13.275833       1 scheduler.go:575] pod secrets-5257/pod-secrets-da2882a8-bf90-46e4-9e74-57883f84395a is bound successfully on node e2e-test-peterhornyack-windows-node-group-mdn5, 5 nodes evaluated, 2 nodes were found feasible
I0427 00:02:21.389642       1 wrap.go:47] GET /healthz: (57.071µs) 200 [kube-probe/1.15+ 127.0.0.1:48242]
I0427 00:02:31.389489       1 wrap.go:47] GET /healthz: (45.213µs) 200 [kube-probe/1.15+ 127.0.0.1:48274]
I0427 00:02:40.489483       1 scheduling_queue.go:895] About to try and schedule pod svcaccounts-3655/pod-service-account-413c53fd-8082-4cf4-b529-7620ed52ab52
I0427 00:02:40.489497       1 scheduler.go:454] Attempting to schedule pod: svcaccounts-3655/pod-service-account-413c53fd-8082-4cf4-b529-7620ed52ab52
I0427 00:02:40.489766       1 scheduler_binder.go:255] AssumePodVolumes for pod "svcaccounts-3655/pod-service-account-413c53fd-8082-4cf4-b529-7620ed52ab52", node "e2e-test-peterhornyack-windows-node-group-mdn5"
I0427 00:02:40.489778       1 scheduler_binder.go:265] AssumePodVolumes for pod "svcaccounts-3655/pod-service-account-413c53fd-8082-4cf4-b529-7620ed52ab52", node "e2e-test-peterhornyack-windows-node-group-mdn5": all PVCs bound and nothing to do
I0427 00:02:40.489817       1 factory.go:734] Attempting to bind pod-service-account-413c53fd-8082-4cf4-b529-7620ed52ab52 to e2e-test-peterhornyack-windows-node-group-mdn5
I0427 00:02:40.500716       1 scheduler.go:575] pod svcaccounts-3655/pod-service-account-413c53fd-8082-4cf4-b529-7620ed52ab52 is bound successfully on node e2e-test-peterhornyack-windows-node-group-mdn5, 5 nodes evaluated, 2 nodes were found feasible
I0427 00:02:41.389530       1 wrap.go:47] GET /healthz: (65.507µs) 200 [kube-probe/1.15+ 127.0.0.1:48326]
I0427 00:02:51.392010       1 wrap.go:47] GET /healthz: (86.884µs) 200 [kube-probe/1.15+ 127.0.0.1:48366]
I0427 00:02:58.508787       1 scheduling_queue.go:895] About to try and schedule pod pod-network-test-1763/netserver-0
I0427 00:02:58.508800       1 scheduler.go:454] Attempting to schedule pod: pod-network-test-1763/netserver-0
I0427 00:02:58.510012       1 scheduler_binder.go:255] AssumePodVolumes for pod "pod-network-test-1763/netserver-0", node "e2e-test-peterhornyack-windows-node-group-9bnh"
I0427 00:02:58.510024       1 scheduler_binder.go:265] AssumePodVolumes for pod "pod-network-test-1763/netserver-0", node "e2e-test-peterhornyack-windows-node-group-9bnh": all PVCs bound and nothing to do
I0427 00:02:58.510056       1 factory.go:734] Attempting to bind netserver-0 to e2e-test-peterhornyack-windows-node-group-9bnh
I0427 00:02:58.518597       1 scheduler.go:575] pod pod-network-test-1763/netserver-0 is bound successfully on node e2e-test-peterhornyack-windows-node-group-9bnh, 5 nodes evaluated, 1 nodes were found feasible
I0427 00:02:58.554339       1 scheduling_queue.go:895] About to try and schedule pod pod-network-test-1763/netserver-1
I0427 00:02:58.554352       1 scheduler.go:454] Attempting to schedule pod: pod-network-test-1763/netserver-1
I0427 00:02:58.554538       1 scheduler_binder.go:255] AssumePodVolumes for pod "pod-network-test-1763/netserver-1", node "e2e-test-peterhornyack-windows-node-group-mdn5"
I0427 00:02:58.554549       1 scheduler_binder.go:265] AssumePodVolumes for pod "pod-network-test-1763/netserver-1", node "e2e-test-peterhornyack-windows-node-group-mdn5": all PVCs bound and nothing to do
I0427 00:02:58.554589       1 factory.go:734] Attempting to bind netserver-1 to e2e-test-peterhornyack-windows-node-group-mdn5
I0427 00:02:58.563835       1 scheduler.go:575] pod pod-network-test-1763/netserver-1 is bound successfully on node e2e-test-peterhornyack-windows-node-group-mdn5, 5 nodes evaluated, 1 nodes were found feasible
I0427 00:03:01.389738       1 wrap.go:47] GET /healthz: (112.251µs) 200 [kube-probe/1.15+ 127.0.0.1:48402]
I0427 00:03:11.389613       1 wrap.go:47] GET /healthz: (56.093µs) 200 [kube-probe/1.15+ 127.0.0.1:48438]
I0427 00:03:21.389462       1 wrap.go:47] GET /healthz: (49.598µs) 200 [kube-probe/1.15+ 127.0.0.1:48470]
I0427 00:03:22.810745       1 scheduling_queue.go:895] About to try and schedule pod pod-network-test-1763/test-container-pod
I0427 00:03:22.810758       1 scheduler.go:454] Attempting to schedule pod: pod-network-test-1763/test-container-pod
I0427 00:03:22.811915       1 scheduler_binder.go:255] AssumePodVolumes for pod "pod-network-test-1763/test-container-pod", node "e2e-test-peterhornyack-windows-node-group-9bnh"
I0427 00:03:22.811928       1 scheduler_binder.go:265] AssumePodVolumes for pod "pod-network-test-1763/test-container-pod", node "e2e-test-peterhornyack-windows-node-group-9bnh": all PVCs bound and nothing to do
I0427 00:03:22.811996       1 factory.go:734] Attempting to bind test-container-pod to e2e-test-peterhornyack-windows-node-group-9bnh
I0427 00:03:22.817061       1 scheduler.go:575] pod pod-network-test-1763/test-container-pod is bound successfully on node e2e-test-peterhornyack-windows-node-group-9bnh, 5 nodes evaluated, 2 nodes were found feasible
I0427 00:03:22.855929       1 scheduling_queue.go:895] About to try and schedule pod pod-network-test-1763/host-test-container-pod
I0427 00:03:22.855941       1 scheduler.go:454] Attempting to schedule pod: pod-network-test-1763/host-test-container-pod
I0427 00:03:22.856232       1 scheduler_binder.go:255] AssumePodVolumes for pod "pod-network-test-1763/host-test-container-pod", node "e2e-test-peterhornyack-windows-node-group-9bnh"
I0427 00:03:22.856259       1 scheduler_binder.go:265] AssumePodVolumes for pod "pod-network-test-1763/host-test-container-pod", node "e2e-test-peterhornyack-windows-node-group-9bnh": all PVCs bound and nothing to do
I0427 00:03:22.856293       1 factory.go:734] Attempting to bind host-test-container-pod to e2e-test-peterhornyack-windows-node-group-9bnh
I0427 00:03:22.862123       1 scheduler.go:575] pod pod-network-test-1763/host-test-container-pod is bound successfully on node e2e-test-peterhornyack-windows-node-group-9bnh, 5 nodes evaluated, 2 nodes were found feasible
I0427 00:03:29.796561       1 reflector.go:384] k8s.io/client-go/informers/factory.go:133: Watch close - *v1.Node total 59 items received
I0427 00:03:31.389743       1 wrap.go:47] GET /healthz: (109.466µs) 200 [kube-probe/1.15+ 127.0.0.1:48502]
I0427 00:03:41.389885       1 wrap.go:47] GET /healthz: (71.787µs) 200 [kube-probe/1.15+ 127.0.0.1:48556]
I0427 00:03:51.389937       1 wrap.go:47] GET /healthz: (76.359µs) 200 [kube-probe/1.15+ 127.0.0.1:48588]
I0427 00:04:00.305733       1 scheduling_queue.go:895] About to try and schedule pod pods-8135/pod-exec-websocket-1d940fdd-5506-4b07-9d2d-2e8e57cd2781
I0427 00:04:00.305746       1 scheduler.go:454] Attempting to schedule pod: pods-8135/pod-exec-websocket-1d940fdd-5506-4b07-9d2d-2e8e57cd2781
I0427 00:04:00.306201       1 scheduler_binder.go:255] AssumePodVolumes for pod "pods-8135/pod-exec-websocket-1d940fdd-5506-4b07-9d2d-2e8e57cd2781", node "e2e-test-peterhornyack-windows-node-group-9bnh"
I0427 00:04:00.306216       1 scheduler_binder.go:265] AssumePodVolumes for pod "pods-8135/pod-exec-websocket-1d940fdd-5506-4b07-9d2d-2e8e57cd2781", node "e2e-test-peterhornyack-windows-node-group-9bnh": all PVCs bound and nothing to do
I0427 00:04:00.306277       1 factory.go:734] Attempting to bind pod-exec-websocket-1d940fdd-5506-4b07-9d2d-2e8e57cd2781 to e2e-test-peterhornyack-windows-node-group-9bnh
I0427 00:04:00.320474       1 scheduler.go:575] pod pods-8135/pod-exec-websocket-1d940fdd-5506-4b07-9d2d-2e8e57cd2781 is bound successfully on node e2e-test-peterhornyack-windows-node-group-9bnh, 5 nodes evaluated, 2 nodes were found feasible
I0427 00:04:01.389795       1 wrap.go:47] GET /healthz: (75.453µs) 200 [kube-probe/1.15+ 127.0.0.1:48626]
I0427 00:04:11.389357       1 wrap.go:47] GET /healthz: (47.34µs) 200 [kube-probe/1.15+ 127.0.0.1:48666]
I0427 00:04:21.389813       1 wrap.go:47] GET /healthz: (80.713µs) 200 [kube-probe/1.15+ 127.0.0.1:48698]
I0427 00:04:26.756413       1 reflector.go:384] k8s.io/client-go/informers/factory.go:133: Watch close - *v1.Service total 0 items received
I0427 00:04:31.389660       1 wrap.go:47] GET /healthz: (80.558µs) 200 [kube-probe/1.15+ 127.0.0.1:48730]
I0427 00:04:32.699102       1 scheduling_queue.go:895] About to try and schedule pod replicaset-3100/my-hostname-basic-6554cdf5-d2e7-4424-bd27-66183cdc49ec-snr4z
I0427 00:04:32.699116       1 scheduler.go:454] Attempting to schedule pod: replicaset-3100/my-hostname-basic-6554cdf5-d2e7-4424-bd27-66183cdc49ec-snr4z
I0427 00:04:32.699761       1 scheduler_binder.go:255] AssumePodVolumes for pod "replicaset-3100/my-hostname-basic-6554cdf5-d2e7-4424-bd27-66183cdc49ec-snr4z", node "e2e-test-peterhornyack-windows-node-group-9bnh"
I0427 00:04:32.699774       1 scheduler_binder.go:265] AssumePodVolumes for pod "replicaset-3100/my-hostname-basic-6554cdf5-d2e7-4424-bd27-66183cdc49ec-snr4z", node "e2e-test-peterhornyack-windows-node-group-9bnh": all PVCs bound and nothing to do
I0427 00:04:32.702103       1 factory.go:734] Attempting to bind my-hostname-basic-6554cdf5-d2e7-4424-bd27-66183cdc49ec-snr4z to e2e-test-peterhornyack-windows-node-group-9bnh
I0427 00:04:32.714622       1 scheduler.go:575] pod replicaset-3100/my-hostname-basic-6554cdf5-d2e7-4424-bd27-66183cdc49ec-snr4z is bound successfully on node e2e-test-peterhornyack-windows-node-group-9bnh, 5 nodes evaluated, 2 nodes were found feasible
I0427 00:04:41.389740       1 wrap.go:47] GET /healthz: (74.409µs) 200 [kube-probe/1.15+ 127.0.0.1:48780]
I0427 00:04:51.391237       1 wrap.go:47] GET /healthz: (106.618µs) 200 [kube-probe/1.15+ 127.0.0.1:48814]
I0427 00:04:54.046903       1 scheduling_queue.go:895] About to try and schedule pod downward-api-8440/downward-api-82e3a703-c92e-4e6b-b27c-b2ac8f883ca3
I0427 00:04:54.046921       1 scheduler.go:454] Attempting to schedule pod: downward-api-8440/downward-api-82e3a703-c92e-4e6b-b27c-b2ac8f883ca3
I0427 00:04:54.047380       1 scheduler_binder.go:255] AssumePodVolumes for pod "downward-api-8440/downward-api-82e3a703-c92e-4e6b-b27c-b2ac8f883ca3", node "e2e-test-peterhornyack-windows-node-group-9bnh"
I0427 00:04:54.047392       1 scheduler_binder.go:265] AssumePodVolumes for pod "downward-api-8440/downward-api-82e3a703-c92e-4e6b-b27c-b2ac8f883ca3", node "e2e-test-peterhornyack-windows-node-group-9bnh": all PVCs bound and nothing to do
I0427 00:04:54.047650       1 factory.go:734] Attempting to bind downward-api-82e3a703-c92e-4e6b-b27c-b2ac8f883ca3 to e2e-test-peterhornyack-windows-node-group-9bnh
I0427 00:04:54.052794       1 scheduler.go:575] pod downward-api-8440/downward-api-82e3a703-c92e-4e6b-b27c-b2ac8f883ca3 is bound successfully on node e2e-test-peterhornyack-windows-node-group-9bnh, 5 nodes evaluated, 2 nodes were found feasible
I0427 00:05:01.389451       1 wrap.go:47] GET /healthz: (62.554µs) 200 [kube-probe/1.15+ 127.0.0.1:48850]
I0427 00:05:10.525030       1 scheduling_queue.go:895] About to try and schedule pod provisioning-1648/pvc-volume-tester-writer-wtgpv
I0427 00:05:10.525040       1 scheduler.go:454] Attempting to schedule pod: provisioning-1648/pvc-volume-tester-writer-wtgpv
I0427 00:05:10.525201       1 predicates.go:452] PVC provisioning-1648/pvc-2hf4g is not bound, assuming PVC matches predicate when counting limits
I0427 00:05:10.525461       1 predicates.go:452] PVC provisioning-1648/pvc-2hf4g is not bound, assuming PVC matches predicate when counting limits
I0427 00:05:10.525476       1 predicates.go:452] PVC provisioning-1648/pvc-2hf4g is not bound, assuming PVC matches predicate when counting limits
I0427 00:05:10.525496       1 scheduler_binder.go:683] No matching volumes for Pod "provisioning-1648/pvc-volume-tester-writer-wtgpv", PVC "provisioning-1648/pvc-2hf4g" on node "e2e-test-peterhornyack-windows-node-group-mdn5"
I0427 00:05:10.525507       1 scheduler_binder.go:738] Provisioning for claims of pod "provisioning-1648/pvc-volume-tester-writer-wtgpv" that has no matching volumes on node "e2e-test-peterhornyack-windows-node-group-mdn5" ...
I0427 00:05:10.525551       1 predicates.go:452] PVC provisioning-1648/pvc-2hf4g is not bound, assuming PVC matches predicate when counting limits
I0427 00:05:10.525570       1 predicates.go:452] PVC provisioning-1648/pvc-2hf4g is not bound, assuming PVC matches predicate when counting limits
I0427 00:05:10.525587       1 predicates.go:452] PVC provisioning-1648/pvc-2hf4g is not bound, assuming PVC matches predicate when counting limits
I0427 00:05:10.526387       1 scheduler_binder.go:683] No matching volumes for Pod "provisioning-1648/pvc-volume-tester-writer-wtgpv", PVC "provisioning-1648/pvc-2hf4g" on node "e2e-test-peterhornyack-windows-node-group-9bnh"
I0427 00:05:10.526431       1 scheduler_binder.go:738] Provisioning for claims of pod "provisioning-1648/pvc-volume-tester-writer-wtgpv" that has no matching volumes on node "e2e-test-peterhornyack-windows-node-group-9bnh" ...
I0427 00:05:10.526606       1 scheduler_binder.go:255] AssumePodVolumes for pod "provisioning-1648/pvc-volume-tester-writer-wtgpv", node "e2e-test-peterhornyack-windows-node-group-mdn5"
I0427 00:05:10.526624       1 scheduler_assume_cache.go:319] Assumed v1.PersistentVolumeClaim "provisioning-1648/pvc-2hf4g", version 19503
I0427 00:05:10.526687       1 scheduler_binder.go:330] BindPodVolumes for pod "provisioning-1648/pvc-volume-tester-writer-wtgpv", node "e2e-test-peterhornyack-windows-node-group-mdn5"
I0427 00:05:10.679357       1 cache.go:643] Couldn't expire cache for pod provisioning-1648/pvc-volume-tester-writer-wtgpv. Binding is still in progress.
I0427 00:05:11.389464       1 wrap.go:47] GET /healthz: (52.923µs) 200 [kube-probe/1.15+ 127.0.0.1:48888]
I0427 00:05:11.680264       1 cache.go:643] Couldn't expire cache for pod provisioning-1648/pvc-volume-tester-writer-wtgpv. Binding is still in progress.
I0427 00:05:12.680503       1 cache.go:643] Couldn't expire cache for pod provisioning-1648/pvc-volume-tester-writer-wtgpv. Binding is still in progress.
I0427 00:05:13.531759       1 scheduler_binder.go:545] All PVCs for pod "provisioning-1648/pvc-volume-tester-writer-wtgpv" are bound
I0427 00:05:13.531783       1 factory.go:734] Attempting to bind pvc-volume-tester-writer-wtgpv to e2e-test-peterhornyack-windows-node-group-mdn5
I0427 00:05:13.540763       1 scheduler.go:575] pod provisioning-1648/pvc-volume-tester-writer-wtgpv is bound successfully on node e2e-test-peterhornyack-windows-node-group-mdn5, 5 nodes evaluated, 2 nodes were found feasible
I0427 00:05:21.389547       1 wrap.go:47] GET /healthz: (71.395µs) 200 [kube-probe/1.15+ 127.0.0.1:48924]
I0427 00:05:31.389831       1 wrap.go:47] GET /healthz: (75.422µs) 200 [kube-probe/1.15+ 127.0.0.1:48958]
I0427 00:05:41.390499       1 wrap.go:47] GET /healthz: (72.584µs) 200 [kube-probe/1.15+ 127.0.0.1:49008]
I0427 00:05:51.389698       1 wrap.go:47] GET /healthz: (82.506µs) 200 [kube-probe/1.15+ 127.0.0.1:49040]
I0427 00:06:01.389933       1 wrap.go:47] GET /healthz: (78.052µs) 200 [kube-probe/1.15+ 127.0.0.1:49078]
I0427 00:06:11.389624       1 wrap.go:47] GET /healthz: (70.961µs) 200 [kube-probe/1.15+ 127.0.0.1:49114]
I0427 00:06:21.390002       1 wrap.go:47] GET /healthz: (75.115µs) 200 [kube-probe/1.15+ 127.0.0.1:49146]
I0427 00:06:31.389318       1 wrap.go:47] GET /healthz: (60.256µs) 200 [kube-probe/1.15+ 127.0.0.1:49178]
I0427 00:06:41.389601       1 wrap.go:47] GET /healthz: (74.025µs) 200 [kube-probe/1.15+ 127.0.0.1:49230]
I0427 00:06:45.735414       1 scheduling_queue.go:895] About to try and schedule pod container-probe-25/test-webserver-640b2b44-aa30-4858-82c7-f2d107b82945
I0427 00:06:45.735428       1 scheduler.go:454] Attempting to schedule pod: container-probe-25/test-webserver-640b2b44-aa30-4858-82c7-f2d107b82945
I0427 00:06:45.736024       1 scheduler_binder.go:255] AssumePodVolumes for pod "container-probe-25/test-webserver-640b2b44-aa30-4858-82c7-f2d107b82945", node "e2e-test-peterhornyack-windows-node-group-9bnh"
I0427 00:06:45.736039       1 scheduler_binder.go:265] AssumePodVolumes for pod "container-probe-25/test-webserver-640b2b44-aa30-4858-82c7-f2d107b82945", node "e2e-test-peterhornyack-windows-node-group-9bnh": all PVCs bound and nothing to do
I0427 00:06:45.736109       1 factory.go:734] Attempting to bind test-webserver-640b2b44-aa30-4858-82c7-f2d107b82945 to e2e-test-peterhornyack-windows-node-group-9bnh
I0427 00:06:45.740501       1 scheduler.go:575] pod container-probe-25/test-webserver-640b2b44-aa30-4858-82c7-f2d107b82945 is bound successfully on node e2e-test-peterhornyack-windows-node-group-9bnh, 5 nodes evaluated, 2 nodes were found feasible
I0427 00:06:51.389629       1 wrap.go:47] GET /healthz: (72.768µs) 200 [kube-probe/1.15+ 127.0.0.1:49264]
I0427 00:06:51.813318       1 reflector.go:384] k8s.io/client-go/informers/factory.go:133: Watch close - *v1.StorageClass total 2 items received
I0427 00:07:01.389563       1 wrap.go:47] GET /healthz: (75.877µs) 200 [kube-probe/1.15+ 127.0.0.1:49300]
I0427 00:07:03.797211       1 reflector.go:384] cmd/kube-scheduler/app/server.go:223: Watch close - *v1.Pod total 82 items received
I0427 00:07:11.389586       1 wrap.go:47] GET /healthz: (80.692µs) 200 [kube-probe/1.15+ 127.0.0.1:49336]
I0427 00:07:11.820264       1 reflector.go:384] k8s.io/client-go/informers/factory.go:133: Watch close - *v1.StatefulSet total 0 items received
I0427 00:07:20.781191       1 reflector.go:384] k8s.io/client-go/informers/factory.go:133: Watch close - *v1beta1.PodDisruptionBudget total 0 items received
I0427 00:07:21.389524       1 wrap.go:47] GET /healthz: (66.457µs) 200 [kube-probe/1.15+ 127.0.0.1:49368]
I0427 00:07:31.389431       1 wrap.go:47] GET /healthz: (63.046µs) 200 [kube-probe/1.15+ 127.0.0.1:49400]
I0427 00:07:35.851193       1 scheduling_queue.go:895] About to try and schedule pod projected-310/pod-projected-secrets-4c4c416b-5ada-449e-b37c-aa04735156ae
I0427 00:07:35.851207       1 scheduler.go:454] Attempting to schedule pod: projected-310/pod-projected-secrets-4c4c416b-5ada-449e-b37c-aa04735156ae
I0427 00:07:35.851565       1 scheduler_binder.go:255] AssumePodVolumes for pod "projected-310/pod-projected-secrets-4c4c416b-5ada-449e-b37c-aa04735156ae", node "e2e-test-peterhornyack-windows-node-group-mdn5"
I0427 00:07:35.851578       1 scheduler_binder.go:265] AssumePodVolumes for pod "projected-310/pod-projected-secrets-4c4c416b-5ada-449e-b37c-aa04735156ae", node "e2e-test-peterhornyack-windows-node-group-mdn5": all PVCs bound and nothing to do
I0427 00:07:35.851649       1 factory.go:734] Attempting to bind pod-projected-secrets-4c4c416b-5ada-449e-b37c-aa04735156ae to e2e-test-peterhornyack-windows-node-group-mdn5
I0427 00:07:35.856911       1 scheduler.go:575] pod projected-310/pod-projected-secrets-4c4c416b-5ada-449e-b37c-aa04735156ae is bound successfully on node e2e-test-peterhornyack-windows-node-group-mdn5, 5 nodes evaluated, 2 nodes were found feasible
I0427 00:07:40.786912       1 reflector.go:384] k8s.io/client-go/informers/factory.go:133: Watch close - *v1.ReplicationController total 0 items received
I0427 00:07:41.389626       1 wrap.go:47] GET /healthz: (73.541µs) 200 [kube-probe/1.15+ 127.0.0.1:49450]
I0427 00:07:51.389371       1 wrap.go:47] GET /healthz: (65.776µs) 200 [kube-probe/1.15+ 127.0.0.1:49482]
I0427 00:08:01.389742       1 wrap.go:47] GET /healthz: (73.434µs) 200 [kube-probe/1.15+ 127.0.0.1:49520]
I0427 00:08:02.449053       1 scheduling_queue.go:895] About to try and schedule pod container-lifecycle-hook-3535/pod-handle-http-request
I0427 00:08:02.449069       1 scheduler.go:454] Attempting to schedule pod: container-lifecycle-hook-3535/pod-handle-http-request
I0427 00:08:02.449400       1 scheduler_binder.go:255] AssumePodVolumes for pod "container-lifecycle-hook-3535/pod-handle-http-request", node "e2e-test-peterhornyack-windows-node-group-9bnh"
I0427 00:08:02.449429       1 scheduler_binder.go:265] AssumePodVolumes for pod "container-lifecycle-hook-3535/pod-handle-http-request", node "e2e-test-peterhornyack-windows-node-group-9bnh": all PVCs bound and nothing to do
I0427 00:08:02.449471       1 factory.go:734] Attempting to bind pod-handle-http-request to e2e-test-peterhornyack-windows-node-group-9bnh
I0427 00:08:02.454621       1 scheduler.go:575] pod container-lifecycle-hook-3535/pod-handle-http-request is bound successfully on node e2e-test-peterhornyack-windows-node-group-9bnh, 5 nodes evaluated, 2 nodes were found feasible
I0427 00:08:10.617739       1 scheduling_queue.go:895] About to try and schedule pod container-lifecycle-hook-3535/pod-with-prestop-exec-hook
I0427 00:08:10.617753       1 scheduler.go:454] Attempting to schedule pod: container-lifecycle-hook-3535/pod-with-prestop-exec-hook
I0427 00:08:10.618150       1 scheduler_binder.go:255] AssumePodVolumes for pod "container-lifecycle-hook-3535/pod-with-prestop-exec-hook", node "e2e-test-peterhornyack-windows-node-group-9bnh"
I0427 00:08:10.618181       1 scheduler_binder.go:265] AssumePodVolumes for pod "container-lifecycle-hook-3535/pod-with-prestop-exec-hook", node "e2e-test-peterhornyack-windows-node-group-9bnh": all PVCs bound and nothing to do
I0427 00:08:10.618226       1 factory.go:734] Attempting to bind pod-with-prestop-exec-hook to e2e-test-peterhornyack-windows-node-group-9bnh
I0427 00:08:10.622474       1 scheduler.go:575] pod container-lifecycle-hook-3535/pod-with-prestop-exec-hook is bound successfully on node e2e-test-peterhornyack-windows-node-group-9bnh, 5 nodes evaluated, 2 nodes were found feasible
I0427 00:08:11.389692       1 wrap.go:47] GET /healthz: (79.403µs) 200 [kube-probe/1.15+ 127.0.0.1:49556]
I0427 00:08:21.389806       1 wrap.go:47] GET /healthz: (73.213µs) 200 [kube-probe/1.15+ 127.0.0.1:49590]
I0427 00:08:29.793974       1 reflector.go:384] k8s.io/client-go/informers/factory.go:133: Watch close - *v1.PersistentVolume total 5 items received
I0427 00:08:31.389365       1 wrap.go:47] GET /healthz: (62.415µs) 200 [kube-probe/1.15+ 127.0.0.1:49622]
I0427 00:08:41.390137       1 wrap.go:47] GET /healthz: (67.26µs) 200 [kube-probe/1.15+ 127.0.0.1:49672]
I0427 00:08:48.989354       1 scheduling_queue.go:895] About to try and schedule pod statefulset-8510/ss-0
I0427 00:08:48.989367       1 scheduler.go:454] Attempting to schedule pod: statefulset-8510/ss-0
I0427 00:08:48.991393       1 scheduler_binder.go:255] AssumePodVolumes for pod "statefulset-8510/ss-0", node "e2e-test-peterhornyack-windows-node-group-9bnh"
I0427 00:08:48.991405       1 scheduler_binder.go:265] AssumePodVolumes for pod "statefulset-8510/ss-0", node "e2e-test-peterhornyack-windows-node-group-9bnh": all PVCs bound and nothing to do
I0427 00:08:48.991454       1 factory.go:734] Attempting to bind ss-0 to e2e-test-peterhornyack-windows-node-group-9bnh
I0427 00:08:49.001378       1 scheduler.go:575] pod statefulset-8510/ss-0 is bound successfully on node e2e-test-peterhornyack-windows-node-group-9bnh, 5 nodes evaluated, 2 nodes were found feasible
I0427 00:08:51.389632       1 wrap.go:47] GET /healthz: (71.592µs) 200 [kube-probe/1.15+ 127.0.0.1:49706]
I0427 00:09:01.389580       1 wrap.go:47] GET /healthz: (65.735µs) 200 [kube-probe/1.15+ 127.0.0.1:49744]
I0427 00:09:09.958360       1 scheduling_queue.go:895] About to try and schedule pod statefulset-8510/ss-1
I0427 00:09:09.958373       1 scheduler.go:454] Attempting to schedule pod: statefulset-8510/ss-1
I0427 00:09:09.958783       1 scheduler_binder.go:255] AssumePodVolumes for pod "statefulset-8510/ss-1", node "e2e-test-peterhornyack-windows-node-group-mdn5"
I0427 00:09:09.958794       1 scheduler_binder.go:265] AssumePodVolumes for pod "statefulset-8510/ss-1", node "e2e-test-peterhornyack-windows-node-group-mdn5": all PVCs bound and nothing to do
I0427 00:09:09.958843       1 factory.go:734] Attempting to bind ss-1 to e2e-test-peterhornyack-windows-node-group-mdn5
I0427 00:09:09.964992       1 scheduler.go:575] pod statefulset-8510/ss-1 is bound successfully on node e2e-test-peterhornyack-windows-node-group-mdn5, 5 nodes evaluated, 2 nodes were found feasible
I0427 00:09:09.973435       1 scheduling_queue.go:895] About to try and schedule pod statefulset-8510/ss-2
I0427 00:09:09.973463       1 scheduler.go:454] Attempting to schedule pod: statefulset-8510/ss-2
I0427 00:09:09.974278       1 scheduler_binder.go:255] AssumePodVolumes for pod "statefulset-8510/ss-2", node "e2e-test-peterhornyack-windows-node-group-9bnh"
I0427 00:09:09.974290       1 scheduler_binder.go:265] AssumePodVolumes for pod "statefulset-8510/ss-2", node "e2e-test-peterhornyack-windows-node-group-9bnh": all PVCs bound and nothing to do
I0427 00:09:09.974320       1 factory.go:734] Attempting to bind ss-2 to e2e-test-peterhornyack-windows-node-group-9bnh
I0427 00:09:09.985954       1 scheduler.go:575] pod statefulset-8510/ss-2 is bound successfully on node e2e-test-peterhornyack-windows-node-group-9bnh, 5 nodes evaluated, 2 nodes were found feasible
I0427 00:09:11.389652       1 wrap.go:47] GET /healthz: (72.39µs) 200 [kube-probe/1.15+ 127.0.0.1:49780]
I0427 00:09:21.390286       1 wrap.go:47] GET /healthz: (74.927µs) 200 [kube-probe/1.15+ 127.0.0.1:49816]
I0427 00:09:31.389401       1 wrap.go:47] GET /healthz: (46.754µs) 200 [kube-probe/1.15+ 127.0.0.1:49852]
I0427 00:09:41.389738       1 wrap.go:47] GET /healthz: (88.202µs) 200 [kube-probe/1.15+ 127.0.0.1:49910]
I0427 00:09:51.389509       1 wrap.go:47] GET /healthz: (76.94µs) 200 [kube-probe/1.15+ 127.0.0.1:49954]
I0427 00:09:52.798631       1 reflector.go:384] k8s.io/client-go/informers/factory.go:133: Watch close - *v1.Node total 46 items received
I0427 00:10:01.389335       1 wrap.go:47] GET /healthz: (64.921µs) 200 [kube-probe/1.15+ 127.0.0.1:49990]
I0427 00:10:09.760028       1 reflector.go:384] k8s.io/client-go/informers/factory.go:133: Watch close - *v1.Service total 2 items received
I0427 00:10:11.392106       1 wrap.go:47] GET /healthz: (67.228µs) 200 [kube-probe/1.15+ 127.0.0.1:50028]
I0427 00:10:12.017698       1 scheduling_queue.go:895] About to try and schedule pod replication-controller-1229/pod-release-l2qpc
I0427 00:10:12.017709       1 scheduler.go:454] Attempting to schedule pod: replication-controller-1229/pod-release-l2qpc
I0427 00:10:12.018053       1 scheduler_binder.go:255] AssumePodVolumes for pod "replication-controller-1229/pod-release-l2qpc", node "e2e-test-peterhornyack-windows-node-group-mdn5"
I0427 00:10:12.018064       1 scheduler_binder.go:265] AssumePodVolumes for pod "replication-controller-1229/pod-release-l2qpc", node "e2e-test-peterhornyack-windows-node-group-mdn5": all PVCs bound and nothing to do
I0427 00:10:12.018118       1 factory.go:734] Attempting to bind pod-release-l2qpc to e2e-test-peterhornyack-windows-node-group-mdn5
I0427 00:10:12.052560       1 scheduler.go:575] pod replication-controller-1229/pod-release-l2qpc is bound successfully on node e2e-test-peterhornyack-windows-node-group-mdn5, 5 nodes evaluated, 2 nodes were found feasible
I0427 00:10:12.162931       1 scheduling_queue.go:895] About to try and schedule pod replication-controller-1229/pod-release-ghldz
I0427 00:10:12.162942       1 scheduler.go:454] Attempting to schedule pod: replication-controller-1229/pod-release-ghldz
I0427 00:10:12.163944       1 scheduler_binder.go:255] AssumePodVolumes for pod "replication-controller-1229/pod-release-ghldz", node "e2e-test-peterhornyack-windows-node-group-9bnh"
I0427 00:10:12.163957       1 scheduler_binder.go:265] AssumePodVolumes for pod "replication-controller-1229/pod-release-ghldz", node "e2e-test-peterhornyack-windows-node-group-9bnh": all PVCs bound and nothing to do
I0427 00:10:12.163985       1 factory.go:734] Attempting to bind pod-release-ghldz to e2e-test-peterhornyack-windows-node-group-9bnh
I0427 00:10:12.174795       1 scheduler.go:575] pod replication-controller-1229/pod-release-ghldz is bound successfully on node e2e-test-peterhornyack-windows-node-group-9bnh, 5 nodes evaluated, 2 nodes were found feasible
I0427 00:10:20.126143       1 scheduling_queue.go:895] About to try and schedule pod containers-6767/client-containers-0f0eeb4f-c40b-4b5f-b3a6-15425870bd4e
I0427 00:10:20.126154       1 scheduler.go:454] Attempting to schedule pod: containers-6767/client-containers-0f0eeb4f-c40b-4b5f-b3a6-15425870bd4e
I0427 00:10:20.127799       1 scheduler_binder.go:255] AssumePodVolumes for pod "containers-6767/client-containers-0f0eeb4f-c40b-4b5f-b3a6-15425870bd4e", node "e2e-test-peterhornyack-windows-node-group-mdn5"
I0427 00:10:20.127812       1 scheduler_binder.go:265] AssumePodVolumes for pod "containers-6767/client-containers-0f0eeb4f-c40b-4b5f-b3a6-15425870bd4e", node "e2e-test-peterhornyack-windows-node-group-mdn5": all PVCs bound and nothing to do
I0427 00:10:20.127843       1 factory.go:734] Attempting to bind client-containers-0f0eeb4f-c40b-4b5f-b3a6-15425870bd4e to e2e-test-peterhornyack-windows-node-group-mdn5
I0427 00:10:20.133208       1 scheduler.go:575] pod containers-6767/client-containers-0f0eeb4f-c40b-4b5f-b3a6-15425870bd4e is bound successfully on node e2e-test-peterhornyack-windows-node-group-mdn5, 5 nodes evaluated, 2 nodes were found feasible
I0427 00:10:21.389945       1 wrap.go:47] GET /healthz: (45.238µs) 200 [kube-probe/1.15+ 127.0.0.1:50060]
I0427 00:10:31.392344       1 wrap.go:47] GET /healthz: (71.884µs) 200 [kube-probe/1.15+ 127.0.0.1:50092]
I0427 00:10:41.418662       1 wrap.go:47] GET /healthz: (78.318µs) 200 [kube-probe/1.15+ 127.0.0.1:50144]
I0427 00:10:44.672375       1 scheduling_queue.go:895] About to try and schedule pod gc-3775/simpletest.deployment-6744478b56-rl5qd
I0427 00:10:44.672387       1 scheduler.go:454] Attempting to schedule pod: gc-3775/simpletest.deployment-6744478b56-rl5qd
I0427 00:10:44.672715       1 scheduler_binder.go:255] AssumePodVolumes for pod "gc-3775/simpletest.deployment-6744478b56-rl5qd", node "e2e-test-peterhornyack-windows-node-group-9bnh"
I0427 00:10:44.672725       1 scheduler_binder.go:265] AssumePodVolumes for pod "gc-3775/simpletest.deployment-6744478b56-rl5qd", node "e2e-test-peterhornyack-windows-node-group-9bnh": all PVCs bound and nothing to do
I0427 00:10:44.673376       1 factory.go:734] Attempting to bind simpletest.deployment-6744478b56-rl5qd to e2e-test-peterhornyack-windows-node-group-9bnh
I0427 00:10:44.682454       1 scheduler.go:575] pod gc-3775/simpletest.deployment-6744478b56-rl5qd is bound successfully on node e2e-test-peterhornyack-windows-node-group-9bnh, 5 nodes evaluated, 2 nodes were found feasible
I0427 00:10:44.684297       1 scheduling_queue.go:895] About to try and schedule pod gc-3775/simpletest.deployment-6744478b56-jbsz8
I0427 00:10:44.684303       1 scheduler.go:454] Attempting to schedule pod: gc-3775/simpletest.deployment-6744478b56-jbsz8
I0427 00:10:44.684454       1 scheduler_binder.go:255] AssumePodVolumes for pod "gc-3775/simpletest.deployment-6744478b56-jbsz8", node "e2e-test-peterhornyack-windows-node-group-mdn5"
I0427 00:10:44.684463       1 scheduler_binder.go:265] AssumePodVolumes for pod "gc-3775/simpletest.deployment-6744478b56-jbsz8", node "e2e-test-peterhornyack-windows-node-group-mdn5": all PVCs bound and nothing to do
I0427 00:10:44.684486       1 factory.go:734] Attempting to bind simpletest.deployment-6744478b56-jbsz8 to e2e-test-peterhornyack-windows-node-group-mdn5
I0427 00:10:44.697409       1 scheduler.go:575] pod gc-3775/simpletest.deployment-6744478b56-jbsz8 is bound successfully on node e2e-test-peterhornyack-windows-node-group-mdn5, 5 nodes evaluated, 2 nodes were found feasible
I0427 00:10:51.389263       1 wrap.go:47] GET /healthz: (42.137µs) 200 [kube-probe/1.15+ 127.0.0.1:50176]
I0427 00:11:01.390446       1 wrap.go:47] GET /healthz: (83.137µs) 200 [kube-probe/1.15+ 127.0.0.1:50214]
I0427 00:11:11.389380       1 wrap.go:47] GET /healthz: (61.945µs) 200 [kube-probe/1.15+ 127.0.0.1:50250]
I0427 00:11:16.800697       1 reflector.go:384] k8s.io/client-go/informers/factory.go:133: Watch close - *v1.ReplicaSet total 11 items received
I0427 00:11:19.811070       1 reflector.go:384] k8s.io/client-go/informers/factory.go:133: Watch close - *v1.PersistentVolumeClaim total 7 items received
I0427 00:11:21.399212       1 wrap.go:47] GET /healthz: (100.81µs) 200 [kube-probe/1.15+ 127.0.0.1:50282]
I0427 00:11:23.017623       1 scheduling_queue.go:895] About to try and schedule pod events-5596/send-events-7c191cc1-206d-4002-bf38-d2cd804f9122
I0427 00:11:23.017647       1 scheduler.go:454] Attempting to schedule pod: events-5596/send-events-7c191cc1-206d-4002-bf38-d2cd804f9122
I0427 00:11:23.018105       1 scheduler_binder.go:255] AssumePodVolumes for pod "events-5596/send-events-7c191cc1-206d-4002-bf38-d2cd804f9122", node "e2e-test-peterhornyack-windows-node-group-9bnh"
I0427 00:11:23.018117       1 scheduler_binder.go:265] AssumePodVolumes for pod "events-5596/send-events-7c191cc1-206d-4002-bf38-d2cd804f9122", node "e2e-test-peterhornyack-windows-node-group-9bnh": all PVCs bound and nothing to do
I0427 00:11:23.018432       1 factory.go:734] Attempting to bind send-events-7c191cc1-206d-4002-bf38-d2cd804f9122 to e2e-test-peterhornyack-windows-node-group-9bnh
I0427 00:11:23.022450       1 scheduler.go:575] pod events-5596/send-events-7c191cc1-206d-4002-bf38-d2cd804f9122 is bound successfully on node e2e-test-peterhornyack-windows-node-group-9bnh, 5 nodes evaluated, 2 nodes were found feasible
I0427 00:11:31.389726       1 wrap.go:47] GET /healthz: (86.709µs) 200 [kube-probe/1.15+ 127.0.0.1:50316]
I0427 00:11:41.389625       1 wrap.go:47] GET /healthz: (71.854µs) 200 [kube-probe/1.15+ 127.0.0.1:50368]
I0427 00:11:45.710867       1 scheduling_queue.go:895] About to try and schedule pod kubectl-5853/redis-master-cdpvq
I0427 00:11:45.710879       1 scheduler.go:454] Attempting to schedule pod: kubectl-5853/redis-master-cdpvq
I0427 00:11:45.711232       1 scheduler_binder.go:255] AssumePodVolumes for pod "kubectl-5853/redis-master-cdpvq", node "e2e-test-peterhornyack-windows-node-group-mdn5"
I0427 00:11:45.711242       1 scheduler_binder.go:265] AssumePodVolumes for pod "kubectl-5853/redis-master-cdpvq", node "e2e-test-peterhornyack-windows-node-group-mdn5": all PVCs bound and nothing to do
I0427 00:11:45.711302       1 factory.go:734] Attempting to bind redis-master-cdpvq to e2e-test-peterhornyack-windows-node-group-mdn5
I0427 00:11:45.722277       1 scheduler.go:575] pod kubectl-5853/redis-master-cdpvq is bound successfully on node e2e-test-peterhornyack-windows-node-group-mdn5, 5 nodes evaluated, 2 nodes were found feasible
I0427 00:11:51.389749       1 wrap.go:47] GET /healthz: (133.247µs) 200 [kube-probe/1.15+ 127.0.0.1:50404]
I0427 00:12:01.389744       1 wrap.go:47] GET /healthz: (77.453µs) 200 [kube-probe/1.15+ 127.0.0.1:50448]
I0427 00:12:09.815201       1 reflector.go:384] k8s.io/client-go/informers/factory.go:133: Watch close - *v1.StorageClass total 0 items received
I0427 00:12:11.389430       1 wrap.go:47] GET /healthz: (66.841µs) 200 [kube-probe/1.15+ 127.0.0.1:50522]
I0427 00:12:18.144513       1 scheduling_queue.go:895] About to try and schedule pod container-probe-6374/test-webserver-fe17ec6b-0226-49c6-98d7-a9c8e16f486e
I0427 00:12:18.144526       1 scheduler.go:454] Attempting to schedule pod: container-probe-6374/test-webserver-fe17ec6b-0226-49c6-98d7-a9c8e16f486e
I0427 00:12:18.145891       1 scheduler_binder.go:255] AssumePodVolumes for pod "container-probe-6374/test-webserver-fe17ec6b-0226-49c6-98d7-a9c8e16f486e", node "e2e-test-peterhornyack-windows-node-group-9bnh"
I0427 00:12:18.145906       1 scheduler_binder.go:265] AssumePodVolumes for pod "container-probe-6374/test-webserver-fe17ec6b-0226-49c6-98d7-a9c8e16f486e", node "e2e-test-peterhornyack-windows-node-group-9bnh": all PVCs bound and nothing to do
I0427 00:12:18.145964       1 factory.go:734] Attempting to bind test-webserver-fe17ec6b-0226-49c6-98d7-a9c8e16f486e to e2e-test-peterhornyack-windows-node-group-9bnh
I0427 00:12:18.150837       1 scheduler.go:575] pod container-probe-6374/test-webserver-fe17ec6b-0226-49c6-98d7-a9c8e16f486e is bound successfully on node e2e-test-peterhornyack-windows-node-group-9bnh, 5 nodes evaluated, 2 nodes were found feasible
I0427 00:12:21.389511       1 wrap.go:47] GET /healthz: (72.013µs) 200 [kube-probe/1.15+ 127.0.0.1:50560]
I0427 00:12:31.389626       1 wrap.go:47] GET /healthz: (55.196µs) 200 [kube-probe/1.15+ 127.0.0.1:50592]
I0427 00:12:41.391543       1 wrap.go:47] GET /healthz: (73.136µs) 200 [kube-probe/1.15+ 127.0.0.1:50642]
I0427 00:12:51.389147       1 wrap.go:47] GET /healthz: (64.846µs) 200 [kube-probe/1.15+ 127.0.0.1:50674]
I0427 00:13:01.389598       1 wrap.go:47] GET /healthz: (74.657µs) 200 [kube-probe/1.15+ 127.0.0.1:50710]
I0427 00:13:11.390479       1 wrap.go:47] GET /healthz: (71.16µs) 200 [kube-probe/1.15+ 127.0.0.1:50746]
I0427 00:13:21.394110       1 wrap.go:47] GET /healthz: (76.884µs) 200 [kube-probe/1.15+ 127.0.0.1:50780]
I0427 00:13:31.389556       1 wrap.go:47] GET /healthz: (50.782µs) 200 [kube-probe/1.15+ 127.0.0.1:50812]
I0427 00:13:35.795890       1 reflector.go:384] k8s.io/client-go/informers/factory.go:133: Watch close - *v1.PersistentVolume total 0 items received
I0427 00:13:41.389960       1 wrap.go:47] GET /healthz: (70.155µs) 200 [kube-probe/1.15+ 127.0.0.1:50864]
I0427 00:13:42.247676       1 scheduling_queue.go:895] About to try and schedule pod projected-1011/pod-projected-configmaps-47f9886e-0854-4073-bf2a-0eb3f9a35326
I0427 00:13:42.247704       1 scheduler.go:454] Attempting to schedule pod: projected-1011/pod-projected-configmaps-47f9886e-0854-4073-bf2a-0eb3f9a35326
I0427 00:13:42.248001       1 scheduler_binder.go:255] AssumePodVolumes for pod "projected-1011/pod-projected-configmaps-47f9886e-0854-4073-bf2a-0eb3f9a35326", node "e2e-test-peterhornyack-windows-node-group-mdn5"
I0427 00:13:42.248013       1 scheduler_binder.go:265] AssumePodVolumes for pod "projected-1011/pod-projected-configmaps-47f9886e-0854-4073-bf2a-0eb3f9a35326", node "e2e-test-peterhornyack-windows-node-group-mdn5": all PVCs bound and nothing to do
I0427 00:13:42.248067       1 factory.go:734] Attempting to bind pod-projected-configmaps-47f9886e-0854-4073-bf2a-0eb3f9a35326 to e2e-test-peterhornyack-windows-node-group-mdn5
I0427 00:13:42.256122       1 scheduler.go:575] pod projected-1011/pod-projected-configmaps-47f9886e-0854-4073-bf2a-0eb3f9a35326 is bound successfully on node e2e-test-peterhornyack-windows-node-group-mdn5, 5 nodes evaluated, 2 nodes were found feasible
I0427 00:13:47.799236       1 reflector.go:384] cmd/kube-scheduler/app/server.go:223: Watch close - *v1.Pod total 115 items received
I0427 00:13:51.389571       1 wrap.go:47] GET /healthz: (73.901µs) 200 [kube-probe/1.15+ 127.0.0.1:50896]
I0427 00:14:01.389549       1 wrap.go:47] GET /healthz: (75.674µs) 200 [kube-probe/1.15+ 127.0.0.1:50932]
I0427 00:14:11.389392       1 wrap.go:47] GET /healthz: (64.961µs) 200 [kube-probe/1.15+ 127.0.0.1:50974]
I0427 00:14:21.390042       1 wrap.go:47] GET /healthz: (181.646µs) 200 [kube-probe/1.15+ 127.0.0.1:51006]
I0427 00:14:23.822199       1 reflector.go:384] k8s.io/client-go/informers/factory.go:133: Watch close - *v1.StatefulSet total 18 items received
I0427 00:14:31.389699       1 wrap.go:47] GET /healthz: (97.069µs) 200 [kube-probe/1.15+ 127.0.0.1:51038]
I0427 00:14:41.389530       1 wrap.go:47] GET /healthz: (68.978µs) 200 [kube-probe/1.15+ 127.0.0.1:51092]
I0427 00:14:51.389795       1 wrap.go:47] GET /healthz: (73.606µs) 200 [kube-probe/1.15+ 127.0.0.1:51124]
I0427 00:15:01.389636       1 wrap.go:47] GET /healthz: (69.475µs) 200 [kube-probe/1.15+ 127.0.0.1:51160]
I0427 00:15:11.390682       1 wrap.go:47] GET /healthz: (90.116µs) 200 [kube-probe/1.15+ 127.0.0.1:51198]
I0427 00:15:21.397228       1 wrap.go:47] GET /healthz: (71.933µs) 200 [kube-probe/1.15+ 127.0.0.1:51230]
I0427 00:15:30.335549       1 scheduling_queue.go:895] About to try and schedule pod var-expansion-1737/var-expansion-f5edd5af-c772-45cf-9a59-ed455f645bd9
I0427 00:15:30.335581       1 scheduler.go:454] Attempting to schedule pod: var-expansion-1737/var-expansion-f5edd5af-c772-45cf-9a59-ed455f645bd9
I0427 00:15:30.336039       1 scheduler_binder.go:255] AssumePodVolumes for pod "var-expansion-1737/var-expansion-f5edd5af-c772-45cf-9a59-ed455f645bd9", node "e2e-test-peterhornyack-windows-node-group-9bnh"
I0427 00:15:30.336051       1 scheduler_binder.go:265] AssumePodVolumes for pod "var-expansion-1737/var-expansion-f5edd5af-c772-45cf-9a59-ed455f645bd9", node "e2e-test-peterhornyack-windows-node-group-9bnh": all PVCs bound and nothing to do
I0427 00:15:30.336106       1 factory.go:734] Attempting to bind var-expansion-f5edd5af-c772-45cf-9a59-ed455f645bd9 to e2e-test-peterhornyack-windows-node-group-9bnh
I0427 00:15:30.340933       1 scheduler.go:575] pod var-expansion-1737/var-expansion-f5edd5af-c772-45cf-9a59-ed455f645bd9 is bound successfully on node e2e-test-peterhornyack-windows-node-group-9bnh, 5 nodes evaluated, 2 nodes were found feasible
I0427 00:15:31.389324       1 wrap.go:47] GET /healthz: (46.816µs) 200 [kube-probe/1.15+ 127.0.0.1:51262]
I0427 00:15:41.389497       1 wrap.go:47] GET /healthz: (51.174µs) 200 [kube-probe/1.15+ 127.0.0.1:51312]
I0427 00:15:46.801144       1 scheduling_queue.go:895] About to try and schedule pod configmap-2484/pod-configmaps-58995c17-91d5-42c6-b21c-99edfbc895e8
I0427 00:15:46.801175       1 scheduler.go:454] Attempting to schedule pod: configmap-2484/pod-configmaps-58995c17-91d5-42c6-b21c-99edfbc895e8
I0427 00:15:46.801412       1 scheduler_binder.go:255] AssumePodVolumes for pod "configmap-2484/pod-configmaps-58995c17-91d5-42c6-b21c-99edfbc895e8", node "e2e-test-peterhornyack-windows-node-group-mdn5"
I0427 00:15:46.801439       1 scheduler_binder.go:265] AssumePodVolumes for pod "configmap-2484/pod-configmaps-58995c17-91d5-42c6-b21c-99edfbc895e8", node "e2e-test-peterhornyack-windows-node-group-mdn5": all PVCs bound and nothing to do
I0427 00:15:46.801476       1 factory.go:734] Attempting to bind pod-configmaps-58995c17-91d5-42c6-b21c-99edfbc895e8 to e2e-test-peterhornyack-windows-node-group-mdn5
I0427 00:15:46.805815       1 scheduler.go:575] pod configmap-2484/pod-configmaps-58995c17-91d5-42c6-b21c-99edfbc895e8 is bound successfully on node e2e-test-peterhornyack-windows-node-group-mdn5, 5 nodes evaluated, 2 nodes were found feasible
I0427 00:15:51.389401       1 wrap.go:47] GET /healthz: (64.828µs) 200 [kube-probe/1.15+ 127.0.0.1:51346]
I0427 00:15:53.800345       1 reflector.go:384] k8s.io/client-go/informers/factory.go:133: Watch close - *v1.Node total 43 items received
I0427 00:16:01.389248       1 wrap.go:47] GET /healthz: (44.8µs) 200 [kube-probe/1.15+ 127.0.0.1:51384]
I0427 00:16:09.782815       1 reflector.go:384] k8s.io/client-go/informers/factory.go:133: Watch close - *v1beta1.PodDisruptionBudget total 0 items received
I0427 00:16:11.389714       1 wrap.go:47] GET /healthz: (80.942µs) 200 [kube-probe/1.15+ 127.0.0.1:51422]
I0427 00:16:21.074536       1 scheduling_queue.go:895] About to try and schedule pod container-probe-6346/liveness-exec
I0427 00:16:21.074549       1 scheduler.go:454] Attempting to schedule pod: container-probe-6346/liveness-exec
I0427 00:16:21.074944       1 scheduler_binder.go:255] AssumePodVolumes for pod "container-probe-6346/liveness-exec", node "e2e-test-peterhornyack-windows-node-group-9bnh"
I0427 00:16:21.074955       1 scheduler_binder.go:265] AssumePodVolumes for pod "container-probe-6346/liveness-exec", node "e2e-test-peterhornyack-windows-node-group-9bnh": all PVCs bound and nothing to do
I0427 00:16:21.074999       1 factory.go:734] Attempting to bind liveness-exec to e2e-test-peterhornyack-windows-node-group-9bnh
I0427 00:16:21.080330       1 scheduler.go:575] pod container-probe-6346/liveness-exec is bound successfully on node e2e-test-peterhornyack-windows-node-group-9bnh, 5 nodes evaluated, 2 nodes were found feasible
I0427 00:16:21.389604       1 wrap.go:47] GET /healthz: (56.119µs) 200 [kube-probe/1.15+ 127.0.0.1:51454]
I0427 00:16:31.389423       1 wrap.go:47] GET /healthz: (62.984µs) 200 [kube-probe/1.15+ 127.0.0.1:51488]
I0427 00:16:41.389613       1 wrap.go:47] GET /healthz: (70.238µs) 200 [kube-probe/1.15+ 127.0.0.1:51682]
I0427 00:16:50.788813       1 reflector.go:384] k8s.io/client-go/informers/factory.go:133: Watch close - *v1.ReplicationController total 11 items received
I0427 00:16:51.389532       1 wrap.go:47] GET /healthz: (69.251µs) 200 [kube-probe/1.15+ 127.0.0.1:51714]
I0427 00:17:01.390129       1 wrap.go:47] GET /healthz: (69.498µs) 200 [kube-probe/1.15+ 127.0.0.1:51754]
I0427 00:17:06.024755       1 scheduling_queue.go:895] About to try and schedule pod kubectl-385/e2e-test-nginx-rc-8wp6d
I0427 00:17:06.024769       1 scheduler.go:454] Attempting to schedule pod: kubectl-385/e2e-test-nginx-rc-8wp6d
I0427 00:17:06.025241       1 scheduler_binder.go:255] AssumePodVolumes for pod "kubectl-385/e2e-test-nginx-rc-8wp6d", node "e2e-test-peterhornyack-windows-node-group-mdn5"
I0427 00:17:06.025280       1 scheduler_binder.go:265] AssumePodVolumes for pod "kubectl-385/e2e-test-nginx-rc-8wp6d", node "e2e-test-peterhornyack-windows-node-group-mdn5": all PVCs bound and nothing to do
I0427 00:17:06.025342       1 factory.go:734] Attempting to bind e2e-test-nginx-rc-8wp6d to e2e-test-peterhornyack-windows-node-group-mdn5
I0427 00:17:06.038108       1 scheduler.go:575] pod kubectl-385/e2e-test-nginx-rc-8wp6d is bound successfully on node e2e-test-peterhornyack-windows-node-group-mdn5, 5 nodes evaluated, 2 nodes were found feasible
I0427 00:17:07.196094       1 scheduling_queue.go:895] About to try and schedule pod kubectl-385/e2e-test-nginx-rc-18c248d6381468af30ee44e8fdfaa2ce-fcpn2
I0427 00:17:07.196106       1 scheduler.go:454] Attempting to schedule pod: kubectl-385/e2e-test-nginx-rc-18c248d6381468af30ee44e8fdfaa2ce-fcpn2
I0427 00:17:07.196386       1 scheduler_binder.go:255] AssumePodVolumes for pod "kubectl-385/e2e-test-nginx-rc-18c248d6381468af30ee44e8fdfaa2ce-fcpn2", node "e2e-test-peterhornyack-windows-node-group-9bnh"
I0427 00:17:07.196398       1 scheduler_binder.go:265] AssumePodVolumes for pod "kubectl-385/e2e-test-nginx-rc-18c248d6381468af30ee44e8fdfaa2ce-fcpn2", node "e2e-test-peterhornyack-windows-node-group-9bnh": all PVCs bound and nothing to do
I0427 00:17:07.196442       1 factory.go:734] Attempting to bind e2e-test-nginx-rc-18c248d6381468af30ee44e8fdfaa2ce-fcpn2 to e2e-test-peterhornyack-windows-node-group-9bnh
I0427 00:17:07.205694       1 scheduler.go:575] pod kubectl-385/e2e-test-nginx-rc-18c248d6381468af30ee44e8fdfaa2ce-fcpn2 is bound successfully on node e2e-test-peterhornyack-windows-node-group-9bnh, 5 nodes evaluated, 2 nodes were found feasible
I0427 00:17:11.389533       1 wrap.go:47] GET /healthz: (69.263µs) 200 [kube-probe/1.15+ 127.0.0.1:51792]
I0427 00:17:21.390295       1 wrap.go:47] GET /healthz: (71.824µs) 200 [kube-probe/1.15+ 127.0.0.1:51824]
I0427 00:17:31.389523       1 wrap.go:47] GET /healthz: (67.717µs) 200 [kube-probe/1.15+ 127.0.0.1:51856]
I0427 00:17:41.392544       1 wrap.go:47] GET /healthz: (49.717µs) 200 [kube-probe/1.15+ 127.0.0.1:51906]
I0427 00:17:48.498944       1 scheduling_queue.go:895] About to try and schedule pod secrets-6582/pod-secrets-d8fc989d-f38a-41fb-8275-ac7e45cd01fb
I0427 00:17:48.498961       1 scheduler.go:454] Attempting to schedule pod: secrets-6582/pod-secrets-d8fc989d-f38a-41fb-8275-ac7e45cd01fb
I0427 00:17:48.499897       1 scheduler_binder.go:255] AssumePodVolumes for pod "secrets-6582/pod-secrets-d8fc989d-f38a-41fb-8275-ac7e45cd01fb", node "e2e-test-peterhornyack-windows-node-group-mdn5"
I0427 00:17:48.499911       1 scheduler_binder.go:265] AssumePodVolumes for pod "secrets-6582/pod-secrets-d8fc989d-f38a-41fb-8275-ac7e45cd01fb", node "e2e-test-peterhornyack-windows-node-group-mdn5": all PVCs bound and nothing to do
I0427 00:17:48.499963       1 factory.go:734] Attempting to bind pod-secrets-d8fc989d-f38a-41fb-8275-ac7e45cd01fb to e2e-test-peterhornyack-windows-node-group-mdn5
I0427 00:17:48.507353       1 scheduler.go:575] pod secrets-6582/pod-secrets-d8fc989d-f38a-41fb-8275-ac7e45cd01fb is bound successfully on node e2e-test-peterhornyack-windows-node-group-mdn5, 5 nodes evaluated, 2 nodes were found feasible
I0427 00:17:51.390602       1 wrap.go:47] GET /healthz: (69.269µs) 200 [kube-probe/1.15+ 127.0.0.1:51940]
I0427 00:17:51.763113       1 reflector.go:384] k8s.io/client-go/informers/factory.go:133: Watch close - *v1.Service total 0 items received
I0427 00:18:01.389662       1 wrap.go:47] GET /healthz: (70.478µs) 200 [kube-probe/1.15+ 127.0.0.1:51976]
I0427 00:18:11.389893       1 wrap.go:47] GET /healthz: (87.319µs) 200 [kube-probe/1.15+ 127.0.0.1:52012]
I0427 00:18:13.604245       1 scheduling_queue.go:895] About to try and schedule pod kubectl-9123/redis-master-vj784
I0427 00:18:13.604259       1 scheduler.go:454] Attempting to schedule pod: kubectl-9123/redis-master-vj784
I0427 00:18:13.604695       1 scheduler_binder.go:255] AssumePodVolumes for pod "kubectl-9123/redis-master-vj784", node "e2e-test-peterhornyack-windows-node-group-mdn5"
I0427 00:18:13.604706       1 scheduler_binder.go:265] AssumePodVolumes for pod "kubectl-9123/redis-master-vj784", node "e2e-test-peterhornyack-windows-node-group-mdn5": all PVCs bound and nothing to do
I0427 00:18:13.604768       1 factory.go:734] Attempting to bind redis-master-vj784 to e2e-test-peterhornyack-windows-node-group-mdn5
I0427 00:18:13.617135       1 scheduler.go:575] pod kubectl-9123/redis-master-vj784 is bound successfully on node e2e-test-peterhornyack-windows-node-group-mdn5, 5 nodes evaluated, 2 nodes were found feasible
I0427 00:18:14.816843       1 reflector.go:384] k8s.io/client-go/informers/factory.go:133: Watch close - *v1.StorageClass total 0 items received
I0427 00:18:21.389806       1 wrap.go:47] GET /healthz: (56.992µs) 200 [kube-probe/1.15+ 127.0.0.1:52048]
I0427 00:18:31.389586       1 wrap.go:47] GET /healthz: (48.673µs) 200 [kube-probe/1.15+ 127.0.0.1:52082]
I0427 00:18:37.802619       1 reflector.go:384] k8s.io/client-go/informers/factory.go:133: Watch close - *v1.ReplicaSet total 1 items received
I0427 00:18:41.389494       1 wrap.go:47] GET /healthz: (47.351µs) 200 [kube-probe/1.15+ 127.0.0.1:52132]
I0427 00:18:47.073968       1 scheduling_queue.go:895] About to try and schedule pod container-runtime-8775/image-pull-test8e29d766-641f-42c5-8e36-69dd65f93fca
I0427 00:18:47.073985       1 scheduler.go:454] Attempting to schedule pod: container-runtime-8775/image-pull-test8e29d766-641f-42c5-8e36-69dd65f93fca
I0427 00:18:47.074240       1 scheduler_binder.go:255] AssumePodVolumes for pod "container-runtime-8775/image-pull-test8e29d766-641f-42c5-8e36-69dd65f93fca", node "e2e-test-peterhornyack-windows-node-group-mdn5"
I0427 00:18:47.074266       1 scheduler_binder.go:265] AssumePodVolumes for pod "container-runtime-8775/image-pull-test8e29d766-641f-42c5-8e36-69dd65f93fca", node "e2e-test-peterhornyack-windows-node-group-mdn5": all PVCs bound and nothing to do
I0427 00:18:47.074296       1 factory.go:734] Attempting to bind image-pull-test8e29d766-641f-42c5-8e36-69dd65f93fca to e2e-test-peterhornyack-windows-node-group-mdn5
I0427 00:18:47.079728       1 scheduler.go:575] pod container-runtime-8775/image-pull-test8e29d766-641f-42c5-8e36-69dd65f93fca is bound successfully on node e2e-test-peterhornyack-windows-node-group-mdn5, 5 nodes evaluated, 2 nodes were found feasible
I0427 00:18:51.389759       1 wrap.go:47] GET /healthz: (78.253µs) 200 [kube-probe/1.15+ 127.0.0.1:52164]
I0427 00:19:01.389356       1 wrap.go:47] GET /healthz: (49.337µs) 200 [kube-probe/1.15+ 127.0.0.1:52202]
I0427 00:19:02.567059       1 scheduling_queue.go:895] About to try and schedule pod pods-4626/pod-qos-class-95b80faf-2d5e-4925-bbbd-a5fd608c0988
I0427 00:19:02.567074       1 scheduler.go:454] Attempting to schedule pod: pods-4626/pod-qos-class-95b80faf-2d5e-4925-bbbd-a5fd608c0988
I0427 00:19:02.567536       1 scheduler_binder.go:255] AssumePodVolumes for pod "pods-4626/pod-qos-class-95b80faf-2d5e-4925-bbbd-a5fd608c0988", node "e2e-test-peterhornyack-windows-node-group-9bnh"
I0427 00:19:02.567548       1 scheduler_binder.go:265] AssumePodVolumes for pod "pods-4626/pod-qos-class-95b80faf-2d5e-4925-bbbd-a5fd608c0988", node "e2e-test-peterhornyack-windows-node-group-9bnh": all PVCs bound and nothing to do
I0427 00:19:02.567623       1 factory.go:734] Attempting to bind pod-qos-class-95b80faf-2d5e-4925-bbbd-a5fd608c0988 to e2e-test-peterhornyack-windows-node-group-9bnh
I0427 00:19:02.575987       1 scheduler.go:575] pod pods-4626/pod-qos-class-95b80faf-2d5e-4925-bbbd-a5fd608c0988 is bound successfully on node e2e-test-peterhornyack-windows-node-group-9bnh, 5 nodes evaluated, 2 nodes were found feasible
I0427 00:19:11.389855       1 wrap.go:47] GET /healthz: (93.935µs) 200 [kube-probe/1.15+ 127.0.0.1:52240]
I0427 00:19:21.389392       1 wrap.go:47] GET /healthz: (69.236µs) 200 [kube-probe/1.15+ 127.0.0.1:52272]
I0427 00:19:31.393074       1 wrap.go:47] GET /healthz: (73.593µs) 200 [kube-probe/1.15+ 127.0.0.1:52304]
I0427 00:19:33.813652       1 reflector.go:384] k8s.io/client-go/informers/factory.go:133: Watch close - *v1.PersistentVolumeClaim total 0 items received
I0427 00:19:38.797652       1 reflector.go:384] k8s.io/client-go/informers/factory.go:133: Watch close - *v1.PersistentVolume total 0 items received
I0427 00:19:41.389684       1 wrap.go:47] GET /healthz: (80.12µs) 200 [kube-probe/1.15+ 127.0.0.1:52354]
I0427 00:19:42.808389       1 scheduling_queue.go:895] About to try and schedule pod kubectl-9155/e2e-test-nginx-pod
I0427 00:19:42.808417       1 scheduler.go:454] Attempting to schedule pod: kubectl-9155/e2e-test-nginx-pod
I0427 00:19:42.808890       1 scheduler_binder.go:255] AssumePodVolumes for pod "kubectl-9155/e2e-test-nginx-pod", node "e2e-test-peterhornyack-windows-node-group-mdn5"
I0427 00:19:42.808932       1 scheduler_binder.go:265] AssumePodVolumes for pod "kubectl-9155/e2e-test-nginx-pod", node "e2e-test-peterhornyack-windows-node-group-mdn5": all PVCs bound and nothing to do
I0427 00:19:42.808970       1 factory.go:734] Attempting to bind e2e-test-nginx-pod to e2e-test-peterhornyack-windows-node-group-mdn5
I0427 00:19:42.814595       1 scheduler.go:575] pod kubectl-9155/e2e-test-nginx-pod is bound successfully on node e2e-test-peterhornyack-windows-node-group-mdn5, 5 nodes evaluated, 2 nodes were found feasible
I0427 00:19:51.389395       1 wrap.go:47] GET /healthz: (64.79µs) 200 [kube-probe/1.15+ 127.0.0.1:52388]
I0427 00:19:57.824204       1 reflector.go:384] k8s.io/client-go/informers/factory.go:133: Watch close - *v1.StatefulSet total 0 items received
I0427 00:20:01.389843       1 wrap.go:47] GET /healthz: (89.173µs) 200 [kube-probe/1.15+ 127.0.0.1:52424]
I0427 00:20:11.389420       1 wrap.go:47] GET /healthz: (60.272µs) 200 [kube-probe/1.15+ 127.0.0.1:52460]
I0427 00:20:13.359814       1 scheduling_queue.go:895] About to try and schedule pod secrets-9102/pod-secrets-049ed9bf-ed06-45b7-b465-edd0d8b3c46a
I0427 00:20:13.359829       1 scheduler.go:454] Attempting to schedule pod: secrets-9102/pod-secrets-049ed9bf-ed06-45b7-b465-edd0d8b3c46a
I0427 00:20:13.360149       1 scheduler_binder.go:255] AssumePodVolumes for pod "secrets-9102/pod-secrets-049ed9bf-ed06-45b7-b465-edd0d8b3c46a", node "e2e-test-peterhornyack-windows-node-group-mdn5"
I0427 00:20:13.360183       1 scheduler_binder.go:265] AssumePodVolumes for pod "secrets-9102/pod-secrets-049ed9bf-ed06-45b7-b465-edd0d8b3c46a", node "e2e-test-peterhornyack-windows-node-group-mdn5": all PVCs bound and nothing to do
I0427 00:20:13.360227       1 factory.go:734] Attempting to bind pod-secrets-049ed9bf-ed06-45b7-b465-edd0d8b3c46a to e2e-test-peterhornyack-windows-node-group-mdn5
I0427 00:20:13.364676       1 scheduler.go:575] pod secrets-9102/pod-secrets-049ed9bf-ed06-45b7-b465-edd0d8b3c46a is bound successfully on node e2e-test-peterhornyack-windows-node-group-mdn5, 5 nodes evaluated, 2 nodes were found feasible
I0427 00:20:21.389804       1 wrap.go:47] GET /healthz: (75.727µs) 200 [kube-probe/1.15+ 127.0.0.1:52492]
I0427 00:20:31.390497       1 wrap.go:47] GET /healthz: (70.408µs) 200 [kube-probe/1.15+ 127.0.0.1:52526]
I0427 00:20:37.938238       1 scheduling_queue.go:895] About to try and schedule pod deployment-5870/test-recreate-deployment-78b595d858-h4sgq
I0427 00:20:37.938265       1 scheduler.go:454] Attempting to schedule pod: deployment-5870/test-recreate-deployment-78b595d858-h4sgq
I0427 00:20:37.940871       1 scheduler_binder.go:255] AssumePodVolumes for pod "deployment-5870/test-recreate-deployment-78b595d858-h4sgq", node "e2e-test-peterhornyack-windows-node-group-mdn5"
I0427 00:20:37.940883       1 scheduler_binder.go:265] AssumePodVolumes for pod "deployment-5870/test-recreate-deployment-78b595d858-h4sgq", node "e2e-test-peterhornyack-windows-node-group-mdn5": all PVCs bound and nothing to do
I0427 00:20:37.941357       1 factory.go:734] Attempting to bind test-recreate-deployment-78b595d858-h4sgq to e2e-test-peterhornyack-windows-node-group-mdn5
I0427 00:20:37.959450       1 scheduler.go:575] pod deployment-5870/test-recreate-deployment-78b595d858-h4sgq is bound successfully on node e2e-test-peterhornyack-windows-node-group-mdn5, 5 nodes evaluated, 2 nodes were found feasible
I0427 00:20:41.389398       1 wrap.go:47] GET /healthz: (64.376µs) 200 [kube-probe/1.15+ 127.0.0.1:52576]
I0427 00:20:46.252109       1 scheduling_queue.go:895] About to try and schedule pod deployment-5870/test-recreate-deployment-5ccf74d6d5-486rx
I0427 00:20:46.252120       1 scheduler.go:454] Attempting to schedule pod: deployment-5870/test-recreate-deployment-5ccf74d6d5-486rx
I0427 00:20:46.252459       1 scheduler_binder.go:255] AssumePodVolumes for pod "deployment-5870/test-recreate-deployment-5ccf74d6d5-486rx", node "e2e-test-peterhornyack-windows-node-group-9bnh"
I0427 00:20:46.252469       1 scheduler_binder.go:265] AssumePodVolumes for pod "deployment-5870/test-recreate-deployment-5ccf74d6d5-486rx", node "e2e-test-peterhornyack-windows-node-group-9bnh": all PVCs bound and nothing to do
I0427 00:20:46.252521       1 factory.go:734] Attempting to bind test-recreate-deployment-5ccf74d6d5-486rx to e2e-test-peterhornyack-windows-node-group-9bnh
I0427 00:20:46.273606       1 scheduler.go:575] pod deployment-5870/test-recreate-deployment-5ccf74d6d5-486rx is bound successfully on node e2e-test-peterhornyack-windows-node-group-9bnh, 5 nodes evaluated, 2 nodes were found feasible
I0427 00:20:51.389995       1 wrap.go:47] GET /healthz: (54.626µs) 200 [kube-probe/1.15+ 127.0.0.1:52608]
I0427 00:20:54.469583       1 scheduling_queue.go:895] About to try and schedule pod deployment-6960/test-cleanup-controller-nk2r6
I0427 00:20:54.469596       1 scheduler.go:454] Attempting to schedule pod: deployment-6960/test-cleanup-controller-nk2r6
I0427 00:20:54.469969       1 scheduler_binder.go:255] AssumePodVolumes for pod "deployment-6960/test-cleanup-controller-nk2r6", node "e2e-test-peterhornyack-windows-node-group-mdn5"
I0427 00:20:54.469981       1 scheduler_binder.go:265] AssumePodVolumes for pod "deployment-6960/test-cleanup-controller-nk2r6", node "e2e-test-peterhornyack-windows-node-group-mdn5": all PVCs bound and nothing to do
I0427 00:20:54.471861       1 factory.go:734] Attempting to bind test-cleanup-controller-nk2r6 to e2e-test-peterhornyack-windows-node-group-mdn5
I0427 00:20:54.483485       1 scheduler.go:575] pod deployment-6960/test-cleanup-controller-nk2r6 is bound successfully on node e2e-test-peterhornyack-windows-node-group-mdn5, 5 nodes evaluated, 2 nodes were found feasible
I0427 00:21:01.389865       1 wrap.go:47] GET /healthz: (69.541µs) 200 [kube-probe/1.15+ 127.0.0.1:52644]
I0427 00:21:02.743338       1 scheduling_queue.go:895] About to try and schedule pod deployment-6960/test-cleanup-deployment-5bc9d9c7bd-dqxsg
I0427 00:21:02.743351       1 scheduler.go:454] Attempting to schedule pod: deployment-6960/test-cleanup-deployment-5bc9d9c7bd-dqxsg
I0427 00:21:02.743764       1 scheduler_binder.go:255] AssumePodVolumes for pod "deployment-6960/test-cleanup-deployment-5bc9d9c7bd-dqxsg", node "e2e-test-peterhornyack-windows-node-group-mdn5"
I0427 00:21:02.743776       1 scheduler_binder.go:265] AssumePodVolumes for pod "deployment-6960/test-cleanup-deployment-5bc9d9c7bd-dqxsg", node "e2e-test-peterhornyack-windows-node-group-mdn5": all PVCs bound and nothing to do
I0427 00:21:02.743834       1 factory.go:734] Attempting to bind test-cleanup-deployment-5bc9d9c7bd-dqxsg to e2e-test-peterhornyack-windows-node-group-mdn5
I0427 00:21:02.764440       1 scheduler.go:575] pod deployment-6960/test-cleanup-deployment-5bc9d9c7bd-dqxsg is bound successfully on node e2e-test-peterhornyack-windows-node-group-mdn5, 5 nodes evaluated, 2 nodes were found feasible
I0427 00:21:11.389404       1 wrap.go:47] GET /healthz: (45.613µs) 200 [kube-probe/1.15+ 127.0.0.1:52682]
I0427 00:21:19.094791       1 scheduling_queue.go:895] About to try and schedule pod secrets-850/pod-secrets-71b39a75-a97b-407e-a498-55f7ff466a6e
I0427 00:21:19.094802       1 scheduler.go:454] Attempting to schedule pod: secrets-850/pod-secrets-71b39a75-a97b-407e-a498-55f7ff466a6e
I0427 00:21:19.095049       1 scheduler_binder.go:255] AssumePodVolumes for pod "secrets-850/pod-secrets-71b39a75-a97b-407e-a498-55f7ff466a6e", node "e2e-test-peterhornyack-windows-node-group-mdn5"
I0427 00:21:19.095060       1 scheduler_binder.go:265] AssumePodVolumes for pod "secrets-850/pod-secrets-71b39a75-a97b-407e-a498-55f7ff466a6e", node "e2e-test-peterhornyack-windows-node-group-mdn5": all PVCs bound and nothing to do
I0427 00:21:19.095109       1 factory.go:734] Attempting to bind pod-secrets-71b39a75-a97b-407e-a498-55f7ff466a6e to e2e-test-peterhornyack-windows-node-group-mdn5
I0427 00:21:19.101619       1 scheduler.go:575] pod secrets-850/pod-secrets-71b39a75-a97b-407e-a498-55f7ff466a6e is bound successfully on node e2e-test-peterhornyack-windows-node-group-mdn5, 5 nodes evaluated, 2 nodes were found feasible
I0427 00:21:21.390035       1 wrap.go:47] GET /healthz: (48.362µs) 200 [kube-probe/1.15+ 127.0.0.1:52714]
I0427 00:21:31.389514       1 wrap.go:47] GET /healthz: (67µs) 200 [kube-probe/1.15+ 127.0.0.1:52746]
I0427 00:21:41.389549       1 wrap.go:47] GET /healthz: (56.701µs) 200 [kube-probe/1.15+ 127.0.0.1:52796]
I0427 00:21:49.801357       1 reflector.go:384] cmd/kube-scheduler/app/server.go:223: Watch close - *v1.Pod total 115 items received
I0427 00:21:51.389942       1 wrap.go:47] GET /healthz: (74.338µs) 200 [kube-probe/1.15+ 127.0.0.1:52828]
I0427 00:22:01.389370       1 wrap.go:47] GET /healthz: (63.7µs) 200 [kube-probe/1.15+ 127.0.0.1:52866]
I0427 00:22:11.389837       1 wrap.go:47] GET /healthz: (76.953µs) 200 [kube-probe/1.15+ 127.0.0.1:52902]
I0427 00:22:21.389857       1 wrap.go:47] GET /healthz: (68.513µs) 200 [kube-probe/1.15+ 127.0.0.1:52934]
I0427 00:22:31.389585       1 wrap.go:47] GET /healthz: (69.791µs) 200 [kube-probe/1.15+ 127.0.0.1:52968]
I0427 00:22:41.389483       1 wrap.go:47] GET /healthz: (46.523µs) 200 [kube-probe/1.15+ 127.0.0.1:53018]
I0427 00:22:51.389735       1 wrap.go:47] GET /healthz: (81.324µs) 200 [kube-probe/1.15+ 127.0.0.1:53050]
I0427 00:23:01.389628       1 wrap.go:47] GET /healthz: (68.486µs) 200 [kube-probe/1.15+ 127.0.0.1:53086]
I0427 00:23:11.390375       1 wrap.go:47] GET /healthz: (57.74µs) 200 [kube-probe/1.15+ 127.0.0.1:53122]
I0427 00:23:21.389366       1 wrap.go:47] GET /healthz: (54.375µs) 200 [kube-probe/1.15+ 127.0.0.1:53156]
I0427 00:23:27.844695       1 scheduling_queue.go:895] About to try and schedule pod projected-1945/pod-projected-secrets-3da8cf50-a550-4bdb-9c38-78e8246c7020
I0427 00:23:27.844707       1 scheduler.go:454] Attempting to schedule pod: projected-1945/pod-projected-secrets-3da8cf50-a550-4bdb-9c38-78e8246c7020
I0427 00:23:27.845055       1 scheduler_binder.go:255] AssumePodVolumes for pod "projected-1945/pod-projected-secrets-3da8cf50-a550-4bdb-9c38-78e8246c7020", node "e2e-test-peterhornyack-windows-node-group-mdn5"
I0427 00:23:27.845069       1 scheduler_binder.go:265] AssumePodVolumes for pod "projected-1945/pod-projected-secrets-3da8cf50-a550-4bdb-9c38-78e8246c7020", node "e2e-test-peterhornyack-windows-node-group-mdn5": all PVCs bound and nothing to do
I0427 00:23:27.845123       1 factory.go:734] Attempting to bind pod-projected-secrets-3da8cf50-a550-4bdb-9c38-78e8246c7020 to e2e-test-peterhornyack-windows-node-group-mdn5
I0427 00:23:27.850917       1 scheduler.go:575] pod projected-1945/pod-projected-secrets-3da8cf50-a550-4bdb-9c38-78e8246c7020 is bound successfully on node e2e-test-peterhornyack-windows-node-group-mdn5, 5 nodes evaluated, 2 nodes were found feasible
I0427 00:23:28.801983       1 reflector.go:384] k8s.io/client-go/informers/factory.go:133: Watch close - *v1.Node total 53 items received
I0427 00:23:31.389481       1 wrap.go:47] GET /healthz: (64.439µs) 200 [kube-probe/1.15+ 127.0.0.1:53188]
I0427 00:23:41.389963       1 wrap.go:47] GET /healthz: (74.463µs) 200 [kube-probe/1.15+ 127.0.0.1:53238]
I0427 00:23:51.390100       1 wrap.go:47] GET /healthz: (45.695µs) 200 [kube-probe/1.15+ 127.0.0.1:53272]
I0427 00:23:52.377433       1 scheduling_queue.go:895] About to try and schedule pod container-runtime-3173/terminate-cmd-rpae5ad335d-b587-4b17-9a0e-8568bd599fe6
I0427 00:23:52.377446       1 scheduler.go:454] Attempting to schedule pod: container-runtime-3173/terminate-cmd-rpae5ad335d-b587-4b17-9a0e-8568bd599fe6
I0427 00:23:52.377715       1 scheduler_binder.go:255] AssumePodVolumes for pod "container-runtime-3173/terminate-cmd-rpae5ad335d-b587-4b17-9a0e-8568bd599fe6", node "e2e-test-peterhornyack-windows-node-group-mdn5"
I0427 00:23:52.377727       1 scheduler_binder.go:265] AssumePodVolumes for pod "container-runtime-3173/terminate-cmd-rpae5ad335d-b587-4b17-9a0e-8568bd599fe6", node "e2e-test-peterhornyack-windows-node-group-mdn5": all PVCs bound and nothing to do
I0427 00:23:52.377777       1 factory.go:734] Attempting to bind terminate-cmd-rpae5ad335d-b587-4b17-9a0e-8568bd599fe6 to e2e-test-peterhornyack-windows-node-group-mdn5
I0427 00:23:52.383049       1 scheduler.go:575] pod container-runtime-3173/terminate-cmd-rpae5ad335d-b587-4b17-9a0e-8568bd599fe6 is bound successfully on node e2e-test-peterhornyack-windows-node-group-mdn5, 5 nodes evaluated, 2 nodes were found feasible
I0427 00:24:01.389831       1 wrap.go:47] GET /healthz: (70.033µs) 200 [kube-probe/1.15+ 127.0.0.1:53308]
I0427 00:24:06.818703       1 reflector.go:384] k8s.io/client-go/informers/factory.go:133: Watch close - *v1.StorageClass total 0 items received
I0427 00:24:11.389679       1 wrap.go:47] GET /healthz: (48.16µs) 200 [kube-probe/1.15+ 127.0.0.1:53344]
I0427 00:24:21.389803       1 wrap.go:47] GET /healthz: (73.615µs) 200 [kube-probe/1.15+ 127.0.0.1:53376]
I0427 00:24:23.784767       1 reflector.go:384] k8s.io/client-go/informers/factory.go:133: Watch close - *v1beta1.PodDisruptionBudget total 0 items received
I0427 00:24:29.131413       1 scheduling_queue.go:895] About to try and schedule pod container-runtime-3173/terminate-cmd-rpof8003a23b-e664-4306-8adb-5af4f635eaae
I0427 00:24:29.131425       1 scheduler.go:454] Attempting to schedule pod: container-runtime-3173/terminate-cmd-rpof8003a23b-e664-4306-8adb-5af4f635eaae
I0427 00:24:29.132842       1 scheduler_binder.go:255] AssumePodVolumes for pod "container-runtime-3173/terminate-cmd-rpof8003a23b-e664-4306-8adb-5af4f635eaae", node "e2e-test-peterhornyack-windows-node-group-9bnh"
I0427 00:24:29.132881       1 scheduler_binder.go:265] AssumePodVolumes for pod "container-runtime-3173/terminate-cmd-rpof8003a23b-e664-4306-8adb-5af4f635eaae", node "e2e-test-peterhornyack-windows-node-group-9bnh": all PVCs bound and nothing to do
I0427 00:24:29.132919       1 factory.go:734] Attempting to bind terminate-cmd-rpof8003a23b-e664-4306-8adb-5af4f635eaae to e2e-test-peterhornyack-windows-node-group-9bnh
I0427 00:24:29.136766       1 scheduler.go:575] pod container-runtime-3173/terminate-cmd-rpof8003a23b-e664-4306-8adb-5af4f635eaae is bound successfully on node e2e-test-peterhornyack-windows-node-group-9bnh, 5 nodes evaluated, 2 nodes were found feasible
I0427 00:24:31.390099       1 wrap.go:47] GET /healthz: (73.814µs) 200 [kube-probe/1.15+ 127.0.0.1:53408]
I0427 00:24:41.389353       1 wrap.go:47] GET /healthz: (49.615µs) 200 [kube-probe/1.15+ 127.0.0.1:53460]
I0427 00:24:47.131435       1 scheduling_queue.go:895] About to try and schedule pod container-runtime-3173/terminate-cmd-rpn8a05b935-e62f-45dd-8b76-9bdef414b5f5
I0427 00:24:47.131446       1 scheduler.go:454] Attempting to schedule pod: container-runtime-3173/terminate-cmd-rpn8a05b935-e62f-45dd-8b76-9bdef414b5f5
I0427 00:24:47.131788       1 scheduler_binder.go:255] AssumePodVolumes for pod "container-runtime-3173/terminate-cmd-rpn8a05b935-e62f-45dd-8b76-9bdef414b5f5", node "e2e-test-peterhornyack-windows-node-group-mdn5"
I0427 00:24:47.131800       1 scheduler_binder.go:265] AssumePodVolumes for pod "container-runtime-3173/terminate-cmd-rpn8a05b935-e62f-45dd-8b76-9bdef414b5f5", node "e2e-test-peterhornyack-windows-node-group-mdn5": all PVCs bound and nothing to do
I0427 00:24:47.131850       1 factory.go:734] Attempting to bind terminate-cmd-rpn8a05b935-e62f-45dd-8b76-9bdef414b5f5 to e2e-test-peterhornyack-windows-node-group-mdn5
I0427 00:24:47.136807       1 scheduler.go:575] pod container-runtime-3173/terminate-cmd-rpn8a05b935-e62f-45dd-8b76-9bdef414b5f5 is bound successfully on node e2e-test-peterhornyack-windows-node-group-mdn5, 5 nodes evaluated, 2 nodes were found feasible
I0427 00:24:51.389403       1 wrap.go:47] GET /healthz: (65.057µs) 200 [kube-probe/1.15+ 127.0.0.1:53492]
I0427 00:25:01.389915       1 wrap.go:47] GET /healthz: (62.066µs) 200 [kube-probe/1.15+ 127.0.0.1:53528]
I0427 00:25:07.047251       1 scheduling_queue.go:895] About to try and schedule pod projected-7855/projected-volume-2d84c226-3de6-471b-8e3f-b3f341b99f87
I0427 00:25:07.047285       1 scheduler.go:454] Attempting to schedule pod: projected-7855/projected-volume-2d84c226-3de6-471b-8e3f-b3f341b99f87
I0427 00:25:07.048989       1 scheduler_binder.go:255] AssumePodVolumes for pod "projected-7855/projected-volume-2d84c226-3de6-471b-8e3f-b3f341b99f87", node "e2e-test-peterhornyack-windows-node-group-9bnh"
I0427 00:25:07.049001       1 scheduler_binder.go:265] AssumePodVolumes for pod "projected-7855/projected-volume-2d84c226-3de6-471b-8e3f-b3f341b99f87", node "e2e-test-peterhornyack-windows-node-group-9bnh": all PVCs bound and nothing to do
I0427 00:25:07.049072       1 factory.go:734] Attempting to bind projected-volume-2d84c226-3de6-471b-8e3f-b3f341b99f87 to e2e-test-peterhornyack-windows-node-group-9bnh
I0427 00:25:07.056312       1 scheduler.go:575] pod projected-7855/projected-volume-2d84c226-3de6-471b-8e3f-b3f341b99f87 is bound successfully on node e2e-test-peterhornyack-windows-node-group-9bnh, 5 nodes evaluated, 2 nodes were found feasible
I0427 00:25:11.389713       1 wrap.go:47] GET /healthz: (109.623µs) 200 [kube-probe/1.15+ 127.0.0.1:53566]
I0427 00:25:20.804659       1 reflector.go:384] k8s.io/client-go/informers/factory.go:133: Watch close - *v1.ReplicaSet total 27 items received
I0427 00:25:21.390033       1 wrap.go:47] GET /healthz: (63.505µs) 200 [kube-probe/1.15+ 127.0.0.1:53598]
I0427 00:25:31.389844       1 wrap.go:47] GET /healthz: (76.191µs) 200 [kube-probe/1.15+ 127.0.0.1:53630]
I0427 00:25:41.389473       1 wrap.go:47] GET /healthz: (70.637µs) 200 [kube-probe/1.15+ 127.0.0.1:53680]
I0427 00:25:43.715254       1 scheduling_queue.go:895] About to try and schedule pod provisioning-8630/pvc-volume-tester-writer-xkshm
I0427 00:25:43.715268       1 scheduler.go:454] Attempting to schedule pod: provisioning-8630/pvc-volume-tester-writer-xkshm
I0427 00:25:43.715421       1 predicates.go:452] PVC provisioning-8630/pvc-2mppc is not bound, assuming PVC matches predicate when counting limits
I0427 00:25:43.715553       1 predicates.go:452] PVC provisioning-8630/pvc-2mppc is not bound, assuming PVC matches predicate when counting limits
I0427 00:25:43.715571       1 predicates.go:452] PVC provisioning-8630/pvc-2mppc is not bound, assuming PVC matches predicate when counting limits
I0427 00:25:43.715635       1 scheduler_binder.go:683] No matching volumes for Pod "provisioning-8630/pvc-volume-tester-writer-xkshm", PVC "provisioning-8630/pvc-2mppc" on node "e2e-test-peterhornyack-windows-node-group-mdn5"
I0427 00:25:43.715663       1 scheduler_binder.go:738] Provisioning for claims of pod "provisioning-8630/pvc-volume-tester-writer-xkshm" that has no matching volumes on node "e2e-test-peterhornyack-windows-node-group-mdn5" ...
I0427 00:25:43.715716       1 predicates.go:452] PVC provisioning-8630/pvc-2mppc is not bound, assuming PVC matches predicate when counting limits
I0427 00:25:43.715741       1 predicates.go:452] PVC provisioning-8630/pvc-2mppc is not bound, assuming PVC matches predicate when counting limits
I0427 00:25:43.715750       1 predicates.go:452] PVC provisioning-8630/pvc-2mppc is not bound, assuming PVC matches predicate when counting limits
I0427 00:25:43.715779       1 scheduler_binder.go:683] No matching volumes for Pod "provisioning-8630/pvc-volume-tester-writer-xkshm", PVC "provisioning-8630/pvc-2mppc" on node "e2e-test-peterhornyack-windows-node-group-9bnh"
I0427 00:25:43.715788       1 scheduler_binder.go:738] Provisioning for claims of pod "provisioning-8630/pvc-volume-tester-writer-xkshm" that has no matching volumes on node "e2e-test-peterhornyack-windows-node-group-9bnh" ...
I0427 00:25:43.715991       1 scheduler_binder.go:255] AssumePodVolumes for pod "provisioning-8630/pvc-volume-tester-writer-xkshm", node "e2e-test-peterhornyack-windows-node-group-mdn5"
I0427 00:25:43.716027       1 scheduler_assume_cache.go:319] Assumed v1.PersistentVolumeClaim "provisioning-8630/pvc-2mppc", version 23039
I0427 00:25:43.716068       1 scheduler_binder.go:330] BindPodVolumes for pod "provisioning-8630/pvc-volume-tester-writer-xkshm", node "e2e-test-peterhornyack-windows-node-group-mdn5"
I0427 00:25:44.121732       1 cache.go:643] Couldn't expire cache for pod provisioning-8630/pvc-volume-tester-writer-xkshm. Binding is still in progress.
I0427 00:25:45.121942       1 cache.go:643] Couldn't expire cache for pod provisioning-8630/pvc-volume-tester-writer-xkshm. Binding is still in progress.
I0427 00:25:46.122237       1 cache.go:643] Couldn't expire cache for pod provisioning-8630/pvc-volume-tester-writer-xkshm. Binding is still in progress.
I0427 00:25:47.122464       1 cache.go:643] Couldn't expire cache for pod provisioning-8630/pvc-volume-tester-writer-xkshm. Binding is still in progress.
I0427 00:25:47.724223       1 scheduler_binder.go:545] All PVCs for pod "provisioning-8630/pvc-volume-tester-writer-xkshm" are bound
I0427 00:25:47.724273       1 factory.go:734] Attempting to bind pvc-volume-tester-writer-xkshm to e2e-test-peterhornyack-windows-node-group-mdn5
I0427 00:25:47.733549       1 scheduler.go:575] pod provisioning-8630/pvc-volume-tester-writer-xkshm is bound successfully on node e2e-test-peterhornyack-windows-node-group-mdn5, 5 nodes evaluated, 2 nodes were found feasible
I0427 00:25:51.389511       1 wrap.go:47] GET /healthz: (47.035µs) 200 [kube-probe/1.15+ 127.0.0.1:53716]
I0427 00:26:01.389637       1 wrap.go:47] GET /healthz: (72.296µs) 200 [kube-probe/1.15+ 127.0.0.1:53754]
I0427 00:26:11.389603       1 wrap.go:47] GET /healthz: (72.225µs) 200 [kube-probe/1.15+ 127.0.0.1:53790]
I0427 00:26:21.389292       1 wrap.go:47] GET /healthz: (58.194µs) 200 [kube-probe/1.15+ 127.0.0.1:53822]
I0427 00:26:30.764946       1 reflector.go:384] k8s.io/client-go/informers/factory.go:133: Watch close - *v1.Service total 2 items received
I0427 00:26:30.815266       1 reflector.go:384] k8s.io/client-go/informers/factory.go:133: Watch close - *v1.PersistentVolumeClaim total 5 items received
I0427 00:26:31.389435       1 wrap.go:47] GET /healthz: (63.558µs) 200 [kube-probe/1.15+ 127.0.0.1:53856]
I0427 00:26:41.389472       1 wrap.go:47] GET /healthz: (63.658µs) 200 [kube-probe/1.15+ 127.0.0.1:54050]
I0427 00:26:41.790629       1 reflector.go:384] k8s.io/client-go/informers/factory.go:133: Watch close - *v1.ReplicationController total 35 items received
I0427 00:26:51.389422       1 wrap.go:47] GET /healthz: (63.363µs) 200 [kube-probe/1.15+ 127.0.0.1:54082]
I0427 00:26:58.639976       1 scheduling_queue.go:895] About to try and schedule pod replicaset-2964/pod-adoption-release
I0427 00:26:58.639988       1 scheduler.go:454] Attempting to schedule pod: replicaset-2964/pod-adoption-release
I0427 00:26:58.641467       1 scheduler_binder.go:255] AssumePodVolumes for pod "replicaset-2964/pod-adoption-release", node "e2e-test-peterhornyack-windows-node-group-9bnh"
I0427 00:26:58.641496       1 scheduler_binder.go:265] AssumePodVolumes for pod "replicaset-2964/pod-adoption-release", node "e2e-test-peterhornyack-windows-node-group-9bnh": all PVCs bound and nothing to do
I0427 00:26:58.641536       1 factory.go:734] Attempting to bind pod-adoption-release to e2e-test-peterhornyack-windows-node-group-9bnh
I0427 00:26:58.646449       1 scheduler.go:575] pod replicaset-2964/pod-adoption-release is bound successfully on node e2e-test-peterhornyack-windows-node-group-9bnh, 5 nodes evaluated, 2 nodes were found feasible
I0427 00:27:01.390238       1 wrap.go:47] GET /healthz: (84.511µs) 200 [kube-probe/1.15+ 127.0.0.1:54118]
I0427 00:27:08.995364       1 scheduling_queue.go:895] About to try and schedule pod replicaset-2964/pod-adoption-release-td7bd
I0427 00:27:08.995376       1 scheduler.go:454] Attempting to schedule pod: replicaset-2964/pod-adoption-release-td7bd
I0427 00:27:08.997240       1 scheduler_binder.go:255] AssumePodVolumes for pod "replicaset-2964/pod-adoption-release-td7bd", node "e2e-test-peterhornyack-windows-node-group-mdn5"
I0427 00:27:08.998407       1 scheduler_binder.go:265] AssumePodVolumes for pod "replicaset-2964/pod-adoption-release-td7bd", node "e2e-test-peterhornyack-windows-node-group-mdn5": all PVCs bound and nothing to do
I0427 00:27:08.998480       1 factory.go:734] Attempting to bind pod-adoption-release-td7bd to e2e-test-peterhornyack-windows-node-group-mdn5
I0427 00:27:09.005879       1 scheduler.go:575] pod replicaset-2964/pod-adoption-release-td7bd is bound successfully on node e2e-test-peterhornyack-windows-node-group-mdn5, 5 nodes evaluated, 2 nodes were found feasible
I0427 00:27:11.389452       1 wrap.go:47] GET /healthz: (55.623µs) 200 [kube-probe/1.15+ 127.0.0.1:54154]
I0427 00:27:21.389418       1 wrap.go:47] GET /healthz: (71.469µs) 200 [kube-probe/1.15+ 127.0.0.1:54188]
I0427 00:27:31.389618       1 wrap.go:47] GET /healthz: (67.348µs) 200 [kube-probe/1.15+ 127.0.0.1:54220]
I0427 00:27:33.031861       1 scheduling_queue.go:895] About to try and schedule pod gc-4747/simpletest.rc-85xp6
I0427 00:27:33.031873       1 scheduler.go:454] Attempting to schedule pod: gc-4747/simpletest.rc-85xp6
I0427 00:27:33.034532       1 scheduler_binder.go:255] AssumePodVolumes for pod "gc-4747/simpletest.rc-85xp6", node "e2e-test-peterhornyack-windows-node-group-9bnh"
I0427 00:27:33.034548       1 scheduler_binder.go:265] AssumePodVolumes for pod "gc-4747/simpletest.rc-85xp6", node "e2e-test-peterhornyack-windows-node-group-9bnh": all PVCs bound and nothing to do
I0427 00:27:33.034615       1 factory.go:734] Attempting to bind simpletest.rc-85xp6 to e2e-test-peterhornyack-windows-node-group-9bnh
I0427 00:27:33.040306       1 scheduling_queue.go:895] About to try and schedule pod gc-4747/simpletest.rc-dxd8t
I0427 00:27:33.040314       1 scheduler.go:454] Attempting to schedule pod: gc-4747/simpletest.rc-dxd8t
I0427 00:27:33.040485       1 scheduler_binder.go:255] AssumePodVolumes for pod "gc-4747/simpletest.rc-dxd8t", node "e2e-test-peterhornyack-windows-node-group-mdn5"
I0427 00:27:33.040494       1 scheduler_binder.go:265] AssumePodVolumes for pod "gc-4747/simpletest.rc-dxd8t", node "e2e-test-peterhornyack-windows-node-group-mdn5": all PVCs bound and nothing to do
I0427 00:27:33.040520       1 factory.go:734] Attempting to bind simpletest.rc-dxd8t to e2e-test-peterhornyack-windows-node-group-mdn5
I0427 00:27:33.047360       1 scheduler.go:575] pod gc-4747/simpletest.rc-85xp6 is bound successfully on node e2e-test-peterhornyack-windows-node-group-9bnh, 5 nodes evaluated, 2 nodes were found feasible
I0427 00:27:33.050083       1 scheduling_queue.go:895] About to try and schedule pod gc-4747/simpletest.rc-glvzh
I0427 00:27:33.050113       1 scheduler.go:454] Attempting to schedule pod: gc-4747/simpletest.rc-glvzh
I0427 00:27:33.050350       1 scheduler_binder.go:255] AssumePodVolumes for pod "gc-4747/simpletest.rc-glvzh", node "e2e-test-peterhornyack-windows-node-group-9bnh"
I0427 00:27:33.050359       1 scheduler_binder.go:265] AssumePodVolumes for pod "gc-4747/simpletest.rc-glvzh", node "e2e-test-peterhornyack-windows-node-group-9bnh": all PVCs bound and nothing to do
I0427 00:27:33.050392       1 factory.go:734] Attempting to bind simpletest.rc-glvzh to e2e-test-peterhornyack-windows-node-group-9bnh
I0427 00:27:33.069922       1 scheduling_queue.go:895] About to try and schedule pod gc-4747/simpletest.rc-ppbq5
I0427 00:27:33.069932       1 scheduler.go:454] Attempting to schedule pod: gc-4747/simpletest.rc-ppbq5
I0427 00:27:33.072632       1 scheduler_binder.go:255] AssumePodVolumes for pod "gc-4747/simpletest.rc-ppbq5", node "e2e-test-peterhornyack-windows-node-group-mdn5"
I0427 00:27:33.072672       1 scheduler_binder.go:265] AssumePodVolumes for pod "gc-4747/simpletest.rc-ppbq5", node "e2e-test-peterhornyack-windows-node-group-mdn5": all PVCs bound and nothing to do
I0427 00:27:33.072702       1 factory.go:734] Attempting to bind simpletest.rc-ppbq5 to e2e-test-peterhornyack-windows-node-group-mdn5
I0427 00:27:33.072979       1 scheduling_queue.go:895] About to try and schedule pod gc-4747/simpletest.rc-pscd9
I0427 00:27:33.072996       1 scheduler.go:454] Attempting to schedule pod: gc-4747/simpletest.rc-pscd9
I0427 00:27:33.073141       1 scheduler_binder.go:255] AssumePodVolumes for pod "gc-4747/simpletest.rc-pscd9", node "e2e-test-peterhornyack-windows-node-group-9bnh"
I0427 00:27:33.073150       1 scheduler_binder.go:265] AssumePodVolumes for pod "gc-4747/simpletest.rc-pscd9", node "e2e-test-peterhornyack-windows-node-group-9bnh": all PVCs bound and nothing to do
I0427 00:27:33.073187       1 factory.go:734] Attempting to bind simpletest.rc-pscd9 to e2e-test-peterhornyack-windows-node-group-9bnh
I0427 00:27:33.078433       1 scheduler.go:575] pod gc-4747/simpletest.rc-dxd8t is bound successfully on node e2e-test-peterhornyack-windows-node-group-mdn5, 5 nodes evaluated, 2 nodes were found feasible
I0427 00:27:33.080293       1 scheduler.go:575] pod gc-4747/simpletest.rc-glvzh is bound successfully on node e2e-test-peterhornyack-windows-node-group-9bnh, 5 nodes evaluated, 2 nodes were found feasible
I0427 00:27:33.080381       1 scheduling_queue.go:895] About to try and schedule pod gc-4747/simpletest.rc-5jh2x
I0427 00:27:33.080386       1 scheduler.go:454] Attempting to schedule pod: gc-4747/simpletest.rc-5jh2x
I0427 00:27:33.082375       1 scheduler_binder.go:255] AssumePodVolumes for pod "gc-4747/simpletest.rc-5jh2x", node "e2e-test-peterhornyack-windows-node-group-mdn5"
I0427 00:27:33.082385       1 scheduler_binder.go:265] AssumePodVolumes for pod "gc-4747/simpletest.rc-5jh2x", node "e2e-test-peterhornyack-windows-node-group-mdn5": all PVCs bound and nothing to do
I0427 00:27:33.082410       1 factory.go:734] Attempting to bind simpletest.rc-5jh2x to e2e-test-peterhornyack-windows-node-group-mdn5
I0427 00:27:33.085345       1 scheduling_queue.go:895] About to try and schedule pod gc-4747/simpletest.rc-2djc2
I0427 00:27:33.085352       1 scheduler.go:454] Attempting to schedule pod: gc-4747/simpletest.rc-2djc2
I0427 00:27:33.085540       1 scheduler_binder.go:255] AssumePodVolumes for pod "gc-4747/simpletest.rc-2djc2", node "e2e-test-peterhornyack-windows-node-group-9bnh"
I0427 00:27:33.085567       1 scheduler_binder.go:265] AssumePodVolumes for pod "gc-4747/simpletest.rc-2djc2", node "e2e-test-peterhornyack-windows-node-group-9bnh": all PVCs bound and nothing to do
I0427 00:27:33.085589       1 factory.go:734] Attempting to bind simpletest.rc-2djc2 to e2e-test-peterhornyack-windows-node-group-9bnh
I0427 00:27:33.095208       1 scheduler.go:575] pod gc-4747/simpletest.rc-pscd9 is bound successfully on node e2e-test-peterhornyack-windows-node-group-9bnh, 5 nodes evaluated, 2 nodes were found feasible
I0427 00:27:33.106606       1 scheduler.go:575] pod gc-4747/simpletest.rc-ppbq5 is bound successfully on node e2e-test-peterhornyack-windows-node-group-mdn5, 5 nodes evaluated, 2 nodes were found feasible
I0427 00:27:33.106684       1 scheduling_queue.go:895] About to try and schedule pod gc-4747/simpletest.rc-pk297
I0427 00:27:33.106691       1 scheduler.go:454] Attempting to schedule pod: gc-4747/simpletest.rc-pk297
I0427 00:27:33.107028       1 scheduler_binder.go:255] AssumePodVolumes for pod "gc-4747/simpletest.rc-pk297", node "e2e-test-peterhornyack-windows-node-group-mdn5"
I0427 00:27:33.107038       1 scheduler_binder.go:265] AssumePodVolumes for pod "gc-4747/simpletest.rc-pk297", node "e2e-test-peterhornyack-windows-node-group-mdn5": all PVCs bound and nothing to do
I0427 00:27:33.107087       1 factory.go:734] Attempting to bind simpletest.rc-pk297 to e2e-test-peterhornyack-windows-node-group-mdn5
I0427 00:27:33.107774       1 scheduling_queue.go:895] About to try and schedule pod gc-4747/simpletest.rc-v7gxf
I0427 00:27:33.107781       1 scheduler.go:454] Attempting to schedule pod: gc-4747/simpletest.rc-v7gxf
I0427 00:27:33.112361       1 scheduler_binder.go:255] AssumePodVolumes for pod "gc-4747/simpletest.rc-v7gxf", node "e2e-test-peterhornyack-windows-node-group-9bnh"
I0427 00:27:33.112372       1 scheduler_binder.go:265] AssumePodVolumes for pod "gc-4747/simpletest.rc-v7gxf", node "e2e-test-peterhornyack-windows-node-group-9bnh": all PVCs bound and nothing to do
I0427 00:27:33.112416       1 factory.go:734] Attempting to bind simpletest.rc-v7gxf to e2e-test-peterhornyack-windows-node-group-9bnh
I0427 00:27:33.112651       1 scheduling_queue.go:895] About to try and schedule pod gc-4747/simpletest.rc-8th55
I0427 00:27:33.112657       1 scheduler.go:454] Attempting to schedule pod: gc-4747/simpletest.rc-8th55
I0427 00:27:33.112803       1 scheduler_binder.go:255] AssumePodVolumes for pod "gc-4747/simpletest.rc-8th55", node "e2e-test-peterhornyack-windows-node-group-mdn5"
I0427 00:27:33.112812       1 scheduler_binder.go:265] AssumePodVolumes for pod "gc-4747/simpletest.rc-8th55", node "e2e-test-peterhornyack-windows-node-group-mdn5": all PVCs bound and nothing to do
I0427 00:27:33.112830       1 factory.go:734] Attempting to bind simpletest.rc-8th55 to e2e-test-peterhornyack-windows-node-group-mdn5
I0427 00:27:33.125753       1 scheduler.go:575] pod gc-4747/simpletest.rc-2djc2 is bound successfully on node e2e-test-peterhornyack-windows-node-group-9bnh, 5 nodes evaluated, 2 nodes were found feasible
I0427 00:27:33.125814       1 scheduler.go:575] pod gc-4747/simpletest.rc-5jh2x is bound successfully on node e2e-test-peterhornyack-windows-node-group-mdn5, 5 nodes evaluated, 2 nodes were found feasible
I0427 00:27:33.136798       1 scheduler.go:575] pod gc-4747/simpletest.rc-8th55 is bound successfully on node e2e-test-peterhornyack-windows-node-group-mdn5, 5 nodes evaluated, 2 nodes were found feasible
I0427 00:27:33.136925       1 scheduler.go:575] pod gc-4747/simpletest.rc-pk297 is bound successfully on node e2e-test-peterhornyack-windows-node-group-mdn5, 5 nodes evaluated, 2 nodes were found feasible
I0427 00:27:33.136980       1 scheduler.go:575] pod gc-4747/simpletest.rc-v7gxf is bound successfully on node e2e-test-peterhornyack-windows-node-group-9bnh, 5 nodes evaluated, 2 nodes were found feasible
I0427 00:27:41.389902       1 wrap.go:47] GET /healthz: (75.398µs) 200 [kube-probe/1.15+ 127.0.0.1:54270]
I0427 00:27:47.293315       1 scheduling_queue.go:895] About to try and schedule pod init-container-877/pod-init-f3784d31-d47d-465b-8057-a60599676ca7
I0427 00:27:47.293328       1 scheduler.go:454] Attempting to schedule pod: init-container-877/pod-init-f3784d31-d47d-465b-8057-a60599676ca7
I0427 00:27:47.293571       1 scheduler_binder.go:255] AssumePodVolumes for pod "init-container-877/pod-init-f3784d31-d47d-465b-8057-a60599676ca7", node "e2e-test-peterhornyack-windows-node-group-9bnh"
I0427 00:27:47.293581       1 scheduler_binder.go:265] AssumePodVolumes for pod "init-container-877/pod-init-f3784d31-d47d-465b-8057-a60599676ca7", node "e2e-test-peterhornyack-windows-node-group-9bnh": all PVCs bound and nothing to do
I0427 00:27:47.293612       1 factory.go:734] Attempting to bind pod-init-f3784d31-d47d-465b-8057-a60599676ca7 to e2e-test-peterhornyack-windows-node-group-9bnh
I0427 00:27:47.299270       1 scheduler.go:575] pod init-container-877/pod-init-f3784d31-d47d-465b-8057-a60599676ca7 is bound successfully on node e2e-test-peterhornyack-windows-node-group-9bnh, 5 nodes evaluated, 2 nodes were found feasible
I0427 00:27:51.389383       1 wrap.go:47] GET /healthz: (61.4µs) 200 [kube-probe/1.15+ 127.0.0.1:54304]
I0427 00:27:54.826071       1 reflector.go:384] k8s.io/client-go/informers/factory.go:133: Watch close - *v1.StatefulSet total 0 items received
I0427 00:28:01.389973       1 wrap.go:47] GET /healthz: (62.906µs) 200 [kube-probe/1.15+ 127.0.0.1:54342]
I0427 00:28:11.389641       1 wrap.go:47] GET /healthz: (71.937µs) 200 [kube-probe/1.15+ 127.0.0.1:54378]
I0427 00:28:14.274876       1 scheduling_queue.go:895] About to try and schedule pod downward-api-5058/downwardapi-volume-f3e297d0-6fd0-4159-9e4b-2e7b7d2319f4
I0427 00:28:14.274888       1 scheduler.go:454] Attempting to schedule pod: downward-api-5058/downwardapi-volume-f3e297d0-6fd0-4159-9e4b-2e7b7d2319f4
I0427 00:28:14.275507       1 scheduler_binder.go:255] AssumePodVolumes for pod "downward-api-5058/downwardapi-volume-f3e297d0-6fd0-4159-9e4b-2e7b7d2319f4", node "e2e-test-peterhornyack-windows-node-group-mdn5"
I0427 00:28:14.275519       1 scheduler_binder.go:265] AssumePodVolumes for pod "downward-api-5058/downwardapi-volume-f3e297d0-6fd0-4159-9e4b-2e7b7d2319f4", node "e2e-test-peterhornyack-windows-node-group-mdn5": all PVCs bound and nothing to do
I0427 00:28:14.275572       1 factory.go:734] Attempting to bind downwardapi-volume-f3e297d0-6fd0-4159-9e4b-2e7b7d2319f4 to e2e-test-peterhornyack-windows-node-group-mdn5
I0427 00:28:14.281961       1 scheduler.go:575] pod downward-api-5058/downwardapi-volume-f3e297d0-6fd0-4159-9e4b-2e7b7d2319f4 is bound successfully on node e2e-test-peterhornyack-windows-node-group-mdn5, 5 nodes evaluated, 2 nodes were found feasible
I0427 00:28:21.389880       1 wrap.go:47] GET /healthz: (77.188µs) 200 [kube-probe/1.15+ 127.0.0.1:54410]
I0427 00:28:30.659470       1 scheduling_queue.go:895] About to try and schedule pod pods-5773/back-off-cap
I0427 00:28:30.659484       1 scheduler.go:454] Attempting to schedule pod: pods-5773/back-off-cap
I0427 00:28:30.659979       1 scheduler_binder.go:255] AssumePodVolumes for pod "pods-5773/back-off-cap", node "e2e-test-peterhornyack-windows-node-group-9bnh"
I0427 00:28:30.659990       1 scheduler_binder.go:265] AssumePodVolumes for pod "pods-5773/back-off-cap", node "e2e-test-peterhornyack-windows-node-group-9bnh": all PVCs bound and nothing to do
I0427 00:28:30.660047       1 factory.go:734] Attempting to bind back-off-cap to e2e-test-peterhornyack-windows-node-group-9bnh
I0427 00:28:30.665245       1 scheduler.go:575] pod pods-5773/back-off-cap is bound successfully on node e2e-test-peterhornyack-windows-node-group-9bnh, 5 nodes evaluated, 2 nodes were found feasible
I0427 00:28:31.389867       1 wrap.go:47] GET /healthz: (76.603µs) 200 [kube-probe/1.15+ 127.0.0.1:54442]
I0427 00:28:41.389950       1 wrap.go:47] GET /healthz: (94.5µs) 200 [kube-probe/1.15+ 127.0.0.1:54492]
I0427 00:28:51.389404       1 wrap.go:47] GET /healthz: (66.12µs) 200 [kube-probe/1.15+ 127.0.0.1:54526]
I0427 00:28:52.799379       1 reflector.go:384] k8s.io/client-go/informers/factory.go:133: Watch close - *v1.PersistentVolume total 5 items received
I0427 00:29:01.389521       1 wrap.go:47] GET /healthz: (72.275µs) 200 [kube-probe/1.15+ 127.0.0.1:54564]
I0427 00:29:11.389818       1 wrap.go:47] GET /healthz: (80.034µs) 200 [kube-probe/1.15+ 127.0.0.1:54600]
I0427 00:29:21.390029       1 wrap.go:47] GET /healthz: (72.666µs) 200 [kube-probe/1.15+ 127.0.0.1:54632]
I0427 00:29:31.390374       1 wrap.go:47] GET /healthz: (74.185µs) 200 [kube-probe/1.15+ 127.0.0.1:54664]
I0427 00:29:41.389447       1 wrap.go:47] GET /healthz: (64.721µs) 200 [kube-probe/1.15+ 127.0.0.1:54714]
I0427 00:29:51.389484       1 wrap.go:47] GET /healthz: (53.086µs) 200 [kube-probe/1.15+ 127.0.0.1:54746]
I0427 00:30:01.389383       1 wrap.go:47] GET /healthz: (61.591µs) 200 [kube-probe/1.15+ 127.0.0.1:54782]
I0427 00:30:11.389370       1 wrap.go:47] GET /healthz: (49.556µs) 200 [kube-probe/1.15+ 127.0.0.1:54820]
I0427 00:30:21.390853       1 wrap.go:47] GET /healthz: (49.34µs) 200 [kube-probe/1.15+ 127.0.0.1:54854]
I0427 00:30:31.389595       1 wrap.go:47] GET /healthz: (47.878µs) 200 [kube-probe/1.15+ 127.0.0.1:54886]
I0427 00:30:32.803604       1 reflector.go:384] k8s.io/client-go/informers/factory.go:133: Watch close - *v1.Node total 51 items received
I0427 00:30:41.390853       1 wrap.go:47] GET /healthz: (201.043µs) 200 [kube-probe/1.15+ 127.0.0.1:54936]
I0427 00:30:51.389609       1 wrap.go:47] GET /healthz: (60.573µs) 200 [kube-probe/1.15+ 127.0.0.1:54968]
I0427 00:31:01.389609       1 wrap.go:47] GET /healthz: (49.375µs) 200 [kube-probe/1.15+ 127.0.0.1:55004]
I0427 00:31:04.803105       1 reflector.go:384] cmd/kube-scheduler/app/server.go:223: Watch close - *v1.Pod total 139 items received
I0427 00:31:11.389906       1 wrap.go:47] GET /healthz: (77.48µs) 200 [kube-probe/1.15+ 127.0.0.1:55040]
I0427 00:31:21.389726       1 wrap.go:47] GET /healthz: (71.681µs) 200 [kube-probe/1.15+ 127.0.0.1:55072]
I0427 00:31:31.389928       1 wrap.go:47] GET /healthz: (80.309µs) 200 [kube-probe/1.15+ 127.0.0.1:55106]
I0427 00:31:41.389712       1 wrap.go:47] GET /healthz: (94.938µs) 200 [kube-probe/1.15+ 127.0.0.1:55158]
I0427 00:31:51.389485       1 wrap.go:47] GET /healthz: (50.718µs) 200 [kube-probe/1.15+ 127.0.0.1:55190]
I0427 00:31:57.820652       1 reflector.go:384] k8s.io/client-go/informers/factory.go:133: Watch close - *v1.StorageClass total 2 items received
I0427 00:32:01.389639       1 wrap.go:47] GET /healthz: (55.649µs) 200 [kube-probe/1.15+ 127.0.0.1:55226]
I0427 00:32:11.389781       1 wrap.go:47] GET /healthz: (83.409µs) 200 [kube-probe/1.15+ 127.0.0.1:55262]
I0427 00:32:21.389605       1 wrap.go:47] GET /healthz: (54.517µs) 200 [kube-probe/1.15+ 127.0.0.1:55294]
I0427 00:32:31.389392       1 wrap.go:47] GET /healthz: (48.977µs) 200 [kube-probe/1.15+ 127.0.0.1:55326]
I0427 00:32:36.767535       1 reflector.go:384] k8s.io/client-go/informers/factory.go:133: Watch close - *v1.Service total 0 items received
I0427 00:32:41.389532       1 wrap.go:47] GET /healthz: (62.778µs) 200 [kube-probe/1.15+ 127.0.0.1:55376]
I0427 00:32:51.389394       1 wrap.go:47] GET /healthz: (64.338µs) 200 [kube-probe/1.15+ 127.0.0.1:55410]
I0427 00:33:01.390799       1 wrap.go:47] GET /healthz: (75.511µs) 200 [kube-probe/1.15+ 127.0.0.1:55448]
I0427 00:33:11.389898       1 wrap.go:47] GET /healthz: (92.937µs) 200 [kube-probe/1.15+ 127.0.0.1:55484]
I0427 00:33:20.806631       1 reflector.go:384] k8s.io/client-go/informers/factory.go:133: Watch close - *v1.ReplicaSet total 5 items received
I0427 00:33:21.389874       1 wrap.go:47] GET /healthz: (70.493µs) 200 [kube-probe/1.15+ 127.0.0.1:55516]
I0427 00:33:31.389731       1 wrap.go:47] GET /healthz: (83.066µs) 200 [kube-probe/1.15+ 127.0.0.1:55548]
I0427 00:33:41.389905       1 wrap.go:47] GET /healthz: (73.721µs) 200 [kube-probe/1.15+ 127.0.0.1:55598]
I0427 00:33:47.793526       1 reflector.go:384] k8s.io/client-go/informers/factory.go:133: Watch close - *v1.ReplicationController total 9 items received
I0427 00:33:51.389809       1 wrap.go:47] GET /healthz: (57.954µs) 200 [kube-probe/1.15+ 127.0.0.1:55630]
I0427 00:33:55.786881       1 reflector.go:384] k8s.io/client-go/informers/factory.go:133: Watch close - *v1beta1.PodDisruptionBudget total 0 items received
I0427 00:34:01.390485       1 wrap.go:47] GET /healthz: (70.062µs) 200 [kube-probe/1.15+ 127.0.0.1:55666]
I0427 00:34:11.390597       1 wrap.go:47] GET /healthz: (72.447µs) 200 [kube-probe/1.15+ 127.0.0.1:55704]
I0427 00:34:21.389634       1 wrap.go:47] GET /healthz: (74.395µs) 200 [kube-probe/1.15+ 127.0.0.1:55738]
I0427 00:34:31.389312       1 wrap.go:47] GET /healthz: (63.217µs) 200 [kube-probe/1.15+ 127.0.0.1:55770]
I0427 00:34:41.389774       1 wrap.go:47] GET /healthz: (73.736µs) 200 [kube-probe/1.15+ 127.0.0.1:55820]
I0427 00:34:51.390181       1 wrap.go:47] GET /healthz: (54.526µs) 200 [kube-probe/1.15+ 127.0.0.1:55852]
I0427 00:35:01.390308       1 wrap.go:47] GET /healthz: (72.742µs) 200 [kube-probe/1.15+ 127.0.0.1:55888]
I0427 00:35:02.817328       1 reflector.go:384] k8s.io/client-go/informers/factory.go:133: Watch close - *v1.PersistentVolumeClaim total 2 items received
I0427 00:35:11.389834       1 wrap.go:47] GET /healthz: (88.551µs) 200 [kube-probe/1.15+ 127.0.0.1:55924]
I0427 00:35:21.389745       1 wrap.go:47] GET /healthz: (73.181µs) 200 [kube-probe/1.15+ 127.0.0.1:55956]
I0427 00:35:31.389380       1 wrap.go:47] GET /healthz: (47.365µs) 200 [kube-probe/1.15+ 127.0.0.1:55988]
I0427 00:35:41.389381       1 wrap.go:47] GET /healthz: (62.306µs) 200 [kube-probe/1.15+ 127.0.0.1:56042]
I0427 00:35:51.389587       1 wrap.go:47] GET /healthz: (52.389µs) 200 [kube-probe/1.15+ 127.0.0.1:56074]
I0427 00:36:01.389680       1 wrap.go:47] GET /healthz: (83.274µs) 200 [kube-probe/1.15+ 127.0.0.1:56110]
I0427 00:36:11.389656       1 wrap.go:47] GET /healthz: (72.742µs) 200 [kube-probe/1.15+ 127.0.0.1:56146]
I0427 00:36:21.389721       1 wrap.go:47] GET /healthz: (80.187µs) 200 [kube-probe/1.15+ 127.0.0.1:56178]
I0427 00:36:31.389280       1 wrap.go:47] GET /healthz: (63.465µs) 200 [kube-probe/1.15+ 127.0.0.1:56210]
I0427 00:36:37.804770       1 reflector.go:384] cmd/kube-scheduler/app/server.go:223: Watch close - *v1.Pod total 6 items received
I0427 00:36:41.389485       1 wrap.go:47] GET /healthz: (49.728µs) 200 [kube-probe/1.15+ 127.0.0.1:56378]
I0427 00:36:51.390083       1 wrap.go:47] GET /healthz: (60.547µs) 200 [kube-probe/1.15+ 127.0.0.1:56410]
I0427 00:37:01.389412       1 wrap.go:47] GET /healthz: (66.357µs) 200 [kube-probe/1.15+ 127.0.0.1:56450]
I0427 00:37:09.805599       1 reflector.go:384] k8s.io/client-go/informers/factory.go:133: Watch close - *v1.Node total 46 items received
I0427 00:37:11.389424       1 wrap.go:47] GET /healthz: (65.163µs) 200 [kube-probe/1.15+ 127.0.0.1:56486]
I0427 00:37:21.389938       1 wrap.go:47] GET /healthz: (76.327µs) 200 [kube-probe/1.15+ 127.0.0.1:56518]
I0427 00:37:31.390776       1 wrap.go:47] GET /healthz: (60.39µs) 200 [kube-probe/1.15+ 127.0.0.1:56550]
I0427 00:37:31.801305       1 reflector.go:384] k8s.io/client-go/informers/factory.go:133: Watch close - *v1.PersistentVolume total 0 items received
I0427 00:37:34.828780       1 reflector.go:384] k8s.io/client-go/informers/factory.go:133: Watch close - *v1.StatefulSet total 0 items received
I0427 00:37:41.389532       1 wrap.go:47] GET /healthz: (65.227µs) 200 [kube-probe/1.15+ 127.0.0.1:56600]
I0427 00:37:51.389381       1 wrap.go:47] GET /healthz: (46.956µs) 200 [kube-probe/1.15+ 127.0.0.1:56632]
I0427 00:38:00.769232       1 reflector.go:384] k8s.io/client-go/informers/factory.go:133: Watch close - *v1.Service total 0 items received
I0427 00:38:01.389429       1 wrap.go:47] GET /healthz: (69.504µs) 200 [kube-probe/1.15+ 127.0.0.1:56668]
I0427 00:38:10.822226       1 reflector.go:384] k8s.io/client-go/informers/factory.go:133: Watch close - *v1.StorageClass total 0 items received
I0427 00:38:11.390027       1 wrap.go:47] GET /healthz: (47.685µs) 200 [kube-probe/1.15+ 127.0.0.1:56706]
I0427 00:38:21.389515       1 wrap.go:47] GET /healthz: (70.02µs) 200 [kube-probe/1.15+ 127.0.0.1:56742]
I0427 00:38:31.389516       1 wrap.go:47] GET /healthz: (68.289µs) 200 [kube-probe/1.15+ 127.0.0.1:56774]
I0427 00:38:41.389326       1 wrap.go:47] GET /healthz: (60.589µs) 200 [kube-probe/1.15+ 127.0.0.1:56824]
I0427 00:38:51.389722       1 wrap.go:47] GET /healthz: (87.702µs) 200 [kube-probe/1.15+ 127.0.0.1:56856]
I0427 00:39:01.389676       1 wrap.go:47] GET /healthz: (86.649µs) 200 [kube-probe/1.15+ 127.0.0.1:56894]
I0427 00:39:11.389373       1 wrap.go:47] GET /healthz: (64.694µs) 200 [kube-probe/1.15+ 127.0.0.1:56930]
I0427 00:39:21.389405       1 wrap.go:47] GET /healthz: (74.419µs) 200 [kube-probe/1.15+ 127.0.0.1:56962]
I0427 00:39:31.389650       1 wrap.go:47] GET /healthz: (87.086µs) 200 [kube-probe/1.15+ 127.0.0.1:56994]
I0427 00:39:41.390059       1 wrap.go:47] GET /healthz: (84.38µs) 200 [kube-probe/1.15+ 127.0.0.1:57048]
I0427 00:39:51.389782       1 wrap.go:47] GET /healthz: (58.913µs) 200 [kube-probe/1.15+ 127.0.0.1:57080]
I0427 00:40:01.389408       1 wrap.go:47] GET /healthz: (60.884µs) 200 [kube-probe/1.15+ 127.0.0.1:57116]
I0427 00:40:05.788708       1 reflector.go:384] k8s.io/client-go/informers/factory.go:133: Watch close - *v1beta1.PodDisruptionBudget total 0 items received
I0427 00:40:11.389649       1 wrap.go:47] GET /healthz: (90.63µs) 200 [kube-probe/1.15+ 127.0.0.1:57152]
I0427 00:40:18.819279       1 reflector.go:384] k8s.io/client-go/informers/factory.go:133: Watch close - *v1.PersistentVolumeClaim total 0 items received
I0427 00:40:21.389722       1 wrap.go:47] GET /healthz: (72.54µs) 200 [kube-probe/1.15+ 127.0.0.1:57184]
I0427 00:40:31.389412       1 wrap.go:47] GET /healthz: (63.078µs) 200 [kube-probe/1.15+ 127.0.0.1:57216]
I0427 00:40:41.389633       1 wrap.go:47] GET /healthz: (83.467µs) 200 [kube-probe/1.15+ 127.0.0.1:57266]
I0427 00:40:51.389357       1 wrap.go:47] GET /healthz: (47.124µs) 200 [kube-probe/1.15+ 127.0.0.1:57298]
I0427 00:41:01.389429       1 wrap.go:47] GET /healthz: (62.91µs) 200 [kube-probe/1.15+ 127.0.0.1:57338]
I0427 00:41:11.389307       1 wrap.go:47] GET /healthz: (66.262µs) 200 [kube-probe/1.15+ 127.0.0.1:57374]
I0427 00:41:21.389760       1 wrap.go:47] GET /healthz: (70.547µs) 200 [kube-probe/1.15+ 127.0.0.1:57406]
I0427 00:41:24.809119       1 reflector.go:384] k8s.io/client-go/informers/factory.go:133: Watch close - *v1.ReplicaSet total 0 items received
I0427 00:41:31.389361       1 wrap.go:47] GET /healthz: (68.707µs) 200 [kube-probe/1.15+ 127.0.0.1:57438]
I0427 00:41:41.389418       1 wrap.go:47] GET /healthz: (64.238µs) 200 [kube-probe/1.15+ 127.0.0.1:57488]
I0427 00:41:51.389456       1 wrap.go:47] GET /healthz: (70.674µs) 200 [kube-probe/1.15+ 127.0.0.1:57520]
I0427 00:42:01.389685       1 wrap.go:47] GET /healthz: (89.944µs) 200 [kube-probe/1.15+ 127.0.0.1:57556]
I0427 00:42:11.389458       1 wrap.go:47] GET /healthz: (56.918µs) 200 [kube-probe/1.15+ 127.0.0.1:57592]
I0427 00:42:15.795137       1 reflector.go:384] k8s.io/client-go/informers/factory.go:133: Watch close - *v1.ReplicationController total 0 items received
I0427 00:42:21.389628       1 wrap.go:47] GET /healthz: (56.073µs) 200 [kube-probe/1.15+ 127.0.0.1:57638]
I0427 00:42:31.389767       1 wrap.go:47] GET /healthz: (70.395µs) 200 [kube-probe/1.15+ 127.0.0.1:57672]
I0427 00:42:41.390757       1 wrap.go:47] GET /healthz: (67.889µs) 200 [kube-probe/1.15+ 127.0.0.1:57722]
I0427 00:42:51.389386       1 wrap.go:47] GET /healthz: (64.022µs) 200 [kube-probe/1.15+ 127.0.0.1:57754]
I0427 00:43:01.389588       1 wrap.go:47] GET /healthz: (72.804µs) 200 [kube-probe/1.15+ 127.0.0.1:57790]
I0427 00:43:11.389669       1 wrap.go:47] GET /healthz: (84.186µs) 200 [kube-probe/1.15+ 127.0.0.1:57826]
I0427 00:43:21.389719       1 wrap.go:47] GET /healthz: (57.636µs) 200 [kube-probe/1.15+ 127.0.0.1:57858]
I0427 00:43:31.389728       1 wrap.go:47] GET /healthz: (96.689µs) 200 [kube-probe/1.15+ 127.0.0.1:57892]
I0427 00:43:41.389614       1 wrap.go:47] GET /healthz: (71.245µs) 200 [kube-probe/1.15+ 127.0.0.1:57942]
I0427 00:43:51.389542       1 wrap.go:47] GET /healthz: (74.328µs) 200 [kube-probe/1.15+ 127.0.0.1:57976]
I0427 00:44:01.389875       1 wrap.go:47] GET /healthz: (73.898µs) 200 [kube-probe/1.15+ 127.0.0.1:58012]
I0427 00:44:11.389514       1 wrap.go:47] GET /healthz: (65.698µs) 200 [kube-probe/1.15+ 127.0.0.1:58048]
I0427 00:44:21.389288       1 wrap.go:47] GET /healthz: (67.563µs) 200 [kube-probe/1.15+ 127.0.0.1:58080]
I0427 00:44:31.389738       1 wrap.go:47] GET /healthz: (55.951µs) 200 [kube-probe/1.15+ 127.0.0.1:58112]
I0427 00:44:41.389624       1 wrap.go:47] GET /healthz: (84.551µs) 200 [kube-probe/1.15+ 127.0.0.1:58162]
I0427 00:44:51.389763       1 wrap.go:47] GET /healthz: (73.216µs) 200 [kube-probe/1.15+ 127.0.0.1:58196]
I0427 00:45:01.389686       1 wrap.go:47] GET /healthz: (88.654µs) 200 [kube-probe/1.15+ 127.0.0.1:58232]
I0427 00:45:11.389626       1 wrap.go:47] GET /healthz: (79.228µs) 200 [kube-probe/1.15+ 127.0.0.1:58270]
I0427 00:45:21.389632       1 wrap.go:47] GET /healthz: (77.45µs) 200 [kube-probe/1.15+ 127.0.0.1:58302]
I0427 00:45:25.830976       1 reflector.go:384] k8s.io/client-go/informers/factory.go:133: Watch close - *v1.StatefulSet total 0 items received
I0427 00:45:31.389501       1 wrap.go:47] GET /healthz: (73.946µs) 200 [kube-probe/1.15+ 127.0.0.1:58334]
I0427 00:45:41.389677       1 wrap.go:47] GET /healthz: (83.5µs) 200 [kube-probe/1.15+ 127.0.0.1:58384]
I0427 00:45:51.389756       1 wrap.go:47] GET /healthz: (83.74µs) 200 [kube-probe/1.15+ 127.0.0.1:58416]
I0427 00:46:01.389441       1 wrap.go:47] GET /healthz: (62.031µs) 200 [kube-probe/1.15+ 127.0.0.1:58452]
I0427 00:46:03.807603       1 reflector.go:384] k8s.io/client-go/informers/factory.go:133: Watch close - *v1.Node total 62 items received
I0427 00:46:06.803344       1 reflector.go:384] k8s.io/client-go/informers/factory.go:133: Watch close - *v1.PersistentVolume total 0 items received
I0427 00:46:08.806331       1 reflector.go:384] cmd/kube-scheduler/app/server.go:223: Watch close - *v1.Pod total 6 items received
I0427 00:46:11.389734       1 wrap.go:47] GET /healthz: (74.819µs) 200 [kube-probe/1.15+ 127.0.0.1:58490]
I0427 00:46:21.389332       1 wrap.go:47] GET /healthz: (47.62µs) 200 [kube-probe/1.15+ 127.0.0.1:58522]
I0427 00:46:31.389412       1 wrap.go:47] GET /healthz: (46.116µs) 200 [kube-probe/1.15+ 127.0.0.1:58556]
I0427 00:46:32.821240       1 reflector.go:384] k8s.io/client-go/informers/factory.go:133: Watch close - *v1.PersistentVolumeClaim total 0 items received
I0427 00:46:41.389714       1 wrap.go:47] GET /healthz: (81.369µs) 200 [kube-probe/1.15+ 127.0.0.1:58666]
I0427 00:46:51.389540       1 wrap.go:47] GET /healthz: (75.207µs) 200 [kube-probe/1.15+ 127.0.0.1:58698]
I0427 00:47:01.389611       1 wrap.go:47] GET /healthz: (70.966µs) 200 [kube-probe/1.15+ 127.0.0.1:58734]
I0427 00:47:10.790666       1 reflector.go:384] k8s.io/client-go/informers/factory.go:133: Watch close - *v1beta1.PodDisruptionBudget total 0 items received
I0427 00:47:11.389545       1 wrap.go:47] GET /healthz: (66.694µs) 200 [kube-probe/1.15+ 127.0.0.1:58770]
I0427 00:47:21.389361       1 wrap.go:47] GET /healthz: (52.567µs) 200 [kube-probe/1.15+ 127.0.0.1:58804]
I0427 00:47:31.389546       1 wrap.go:47] GET /healthz: (71.847µs) 200 [kube-probe/1.15+ 127.0.0.1:58838]
I0427 00:47:32.771039       1 reflector.go:384] k8s.io/client-go/informers/factory.go:133: Watch close - *v1.Service total 0 items received
I0427 00:47:41.389299       1 wrap.go:47] GET /healthz: (63.514µs) 200 [kube-probe/1.15+ 127.0.0.1:58888]
I0427 00:47:51.389534       1 wrap.go:47] GET /healthz: (75.018µs) 200 [kube-probe/1.15+ 127.0.0.1:58922]
I0427 00:47:59.796926       1 reflector.go:384] k8s.io/client-go/informers/factory.go:133: Watch close - *v1.ReplicationController total 0 items received
I0427 00:47:59.824076       1 reflector.go:384] k8s.io/client-go/informers/factory.go:133: Watch close - *v1.StorageClass total 0 items received
I0427 00:48:01.390025       1 wrap.go:47] GET /healthz: (63.827µs) 200 [kube-probe/1.15+ 127.0.0.1:58958]
I0427 00:48:11.389678       1 wrap.go:47] GET /healthz: (93.246µs) 200 [kube-probe/1.15+ 127.0.0.1:58998]
I0427 00:48:21.395863       1 wrap.go:47] GET /healthz: (77.905µs) 200 [kube-probe/1.15+ 127.0.0.1:59030]
I0427 00:48:31.389671       1 wrap.go:47] GET /healthz: (85.287µs) 200 [kube-probe/1.15+ 127.0.0.1:59062]
I0427 00:48:41.389350       1 wrap.go:47] GET /healthz: (47.953µs) 200 [kube-probe/1.15+ 127.0.0.1:59112]
I0427 00:48:51.389492       1 wrap.go:47] GET /healthz: (56.961µs) 200 [kube-probe/1.15+ 127.0.0.1:59146]
I0427 00:49:01.389909       1 wrap.go:47] GET /healthz: (71.444µs) 200 [kube-probe/1.15+ 127.0.0.1:59182]
I0427 00:49:11.389760       1 wrap.go:47] GET /healthz: (84.474µs) 200 [kube-probe/1.15+ 127.0.0.1:59218]
I0427 00:49:21.389551       1 wrap.go:47] GET /healthz: (55.3µs) 200 [kube-probe/1.15+ 127.0.0.1:59252]
I0427 00:49:31.389638       1 wrap.go:47] GET /healthz: (81.975µs) 200 [kube-probe/1.15+ 127.0.0.1:59284]
I0427 00:49:38.811199       1 reflector.go:384] k8s.io/client-go/informers/factory.go:133: Watch close - *v1.ReplicaSet total 0 items received
I0427 00:49:41.389360       1 wrap.go:47] GET /healthz: (70.483µs) 200 [kube-probe/1.15+ 127.0.0.1:59334]
I0427 00:49:51.389291       1 wrap.go:47] GET /healthz: (68.965µs) 200 [kube-probe/1.15+ 127.0.0.1:59366]
I0427 00:50:01.389707       1 wrap.go:47] GET /healthz: (109.996µs) 200 [kube-probe/1.15+ 127.0.0.1:59404]
I0427 00:50:11.389837       1 wrap.go:47] GET /healthz: (71.102µs) 200 [kube-probe/1.15+ 127.0.0.1:59442]
I0427 00:50:21.389352       1 wrap.go:47] GET /healthz: (46.61µs) 200 [kube-probe/1.15+ 127.0.0.1:59474]
I0427 00:50:31.389472       1 wrap.go:47] GET /healthz: (71.093µs) 200 [kube-probe/1.15+ 127.0.0.1:59506]
I0427 00:50:41.389367       1 wrap.go:47] GET /healthz: (64.339µs) 200 [kube-probe/1.15+ 127.0.0.1:59558]
I0427 00:50:51.389551       1 wrap.go:47] GET /healthz: (64.654µs) 200 [kube-probe/1.15+ 127.0.0.1:59590]
I0427 00:51:01.389387       1 wrap.go:47] GET /healthz: (67.084µs) 200 [kube-probe/1.15+ 127.0.0.1:59626]
I0427 00:51:11.389800       1 wrap.go:47] GET /healthz: (82.078µs) 200 [kube-probe/1.15+ 127.0.0.1:59662]
I0427 00:51:21.389366       1 wrap.go:47] GET /healthz: (64.593µs) 200 [kube-probe/1.15+ 127.0.0.1:59694]
I0427 00:51:22.809736       1 reflector.go:384] k8s.io/client-go/informers/factory.go:133: Watch close - *v1.Node total 38 items received
I0427 00:51:31.389581       1 wrap.go:47] GET /healthz: (76.073µs) 200 [kube-probe/1.15+ 127.0.0.1:59728]
I0427 00:51:41.389652       1 wrap.go:47] GET /healthz: (81.628µs) 200 [kube-probe/1.15+ 127.0.0.1:59778]
I0427 00:51:51.389598       1 wrap.go:47] GET /healthz: (70.943µs) 200 [kube-probe/1.15+ 127.0.0.1:59810]
I0427 00:52:01.389657       1 wrap.go:47] GET /healthz: (83.249µs) 200 [kube-probe/1.15+ 127.0.0.1:59848]
I0427 00:52:11.389594       1 wrap.go:47] GET /healthz: (72.723µs) 200 [kube-probe/1.15+ 127.0.0.1:59884]
I0427 00:52:21.390417       1 wrap.go:47] GET /healthz: (74.085µs) 200 [kube-probe/1.15+ 127.0.0.1:59916]
I0427 00:52:31.389594       1 wrap.go:47] GET /healthz: (70.106µs) 200 [kube-probe/1.15+ 127.0.0.1:59948]
I0427 00:52:41.389806       1 wrap.go:47] GET /healthz: (79.684µs) 200 [kube-probe/1.15+ 127.0.0.1:59998]
I0427 00:52:51.389524       1 wrap.go:47] GET /healthz: (64.164µs) 200 [kube-probe/1.15+ 127.0.0.1:60032]
I0427 00:53:01.389695       1 wrap.go:47] GET /healthz: (73.635µs) 200 [kube-probe/1.15+ 127.0.0.1:60068]
I0427 00:53:11.389148       1 wrap.go:47] GET /healthz: (45.855µs) 200 [kube-probe/1.15+ 127.0.0.1:60104]
I0427 00:53:21.389658       1 wrap.go:47] GET /healthz: (79.731µs) 200 [kube-probe/1.15+ 127.0.0.1:60138]
I0427 00:53:31.389632       1 wrap.go:47] GET /healthz: (85.226µs) 200 [kube-probe/1.15+ 127.0.0.1:60170]
I0427 00:53:41.389400       1 wrap.go:47] GET /healthz: (63.795µs) 200 [kube-probe/1.15+ 127.0.0.1:60220]
I0427 00:53:51.389369       1 wrap.go:47] GET /healthz: (63.802µs) 200 [kube-probe/1.15+ 127.0.0.1:60252]
I0427 00:54:01.389411       1 wrap.go:47] GET /healthz: (66.546µs) 200 [kube-probe/1.15+ 127.0.0.1:60288]
I0427 00:54:11.389515       1 wrap.go:47] GET /healthz: (71.703µs) 200 [kube-probe/1.15+ 127.0.0.1:60330]
I0427 00:54:12.792465       1 reflector.go:384] k8s.io/client-go/informers/factory.go:133: Watch close - *v1beta1.PodDisruptionBudget total 0 items received
I0427 00:54:14.805280       1 reflector.go:384] k8s.io/client-go/informers/factory.go:133: Watch close - *v1.PersistentVolume total 0 items received
I0427 00:54:21.389640       1 wrap.go:47] GET /healthz: (80.358µs) 200 [kube-probe/1.15+ 127.0.0.1:60362]
I0427 00:54:31.389784       1 wrap.go:47] GET /healthz: (75.527µs) 200 [kube-probe/1.15+ 127.0.0.1:60394]
I0427 00:54:41.389456       1 wrap.go:47] GET /healthz: (66.742µs) 200 [kube-probe/1.15+ 127.0.0.1:60446]
I0427 00:54:51.389562       1 wrap.go:47] GET /healthz: (75.636µs) 200 [kube-probe/1.15+ 127.0.0.1:60478]
I0427 00:54:51.812370       1 reflector.go:384] cmd/kube-scheduler/app/server.go:223: Watch close - *v1.Pod total 3 items received
I0427 00:54:57.826084       1 reflector.go:384] k8s.io/client-go/informers/factory.go:133: Watch close - *v1.StorageClass total 0 items received
I0427 00:55:01.389772       1 wrap.go:47] GET /healthz: (77.955µs) 200 [kube-probe/1.15+ 127.0.0.1:60514]
I0427 00:55:11.389437       1 wrap.go:47] GET /healthz: (61.856µs) 200 [kube-probe/1.15+ 127.0.0.1:60550]
I0427 00:55:12.823231       1 reflector.go:384] k8s.io/client-go/informers/factory.go:133: Watch close - *v1.PersistentVolumeClaim total 0 items received
I0427 00:55:14.833038       1 reflector.go:384] k8s.io/client-go/informers/factory.go:133: Watch close - *v1.StatefulSet total 0 items received
I0427 00:55:21.389556       1 wrap.go:47] GET /healthz: (66.71µs) 200 [kube-probe/1.15+ 127.0.0.1:60582]
I0427 00:55:23.772876       1 reflector.go:384] k8s.io/client-go/informers/factory.go:133: Watch close - *v1.Service total 0 items received
I0427 00:55:31.389728       1 wrap.go:47] GET /healthz: (57.108µs) 200 [kube-probe/1.15+ 127.0.0.1:60616]
I0427 00:55:41.389767       1 wrap.go:47] GET /healthz: (58.964µs) 200 [kube-probe/1.15+ 127.0.0.1:60666]
I0427 00:55:51.389300       1 wrap.go:47] GET /healthz: (63.356µs) 200 [kube-probe/1.15+ 127.0.0.1:60698]
I0427 00:56:01.389549       1 wrap.go:47] GET /healthz: (104.692µs) 200 [kube-probe/1.15+ 127.0.0.1:60734]
I0427 00:56:11.389863       1 wrap.go:47] GET /healthz: (71.928µs) 200 [kube-probe/1.15+ 127.0.0.1:60772]
I0427 00:56:21.389316       1 wrap.go:47] GET /healthz: (63.282µs) 200 [kube-probe/1.15+ 127.0.0.1:60804]
I0427 00:56:31.389400       1 wrap.go:47] GET /healthz: (46.97µs) 200 [kube-probe/1.15+ 127.0.0.1:60836]
I0427 00:56:41.389519       1 wrap.go:47] GET /healthz: (55.04µs) 200 [kube-probe/1.15+ 127.0.0.1:60906]
I0427 00:56:44.063450       1 scheduling_queue.go:895] About to try and schedule pod security-context-test-947/busybox-readonly-false-5aba6f70-5aae-4d4b-87a0-74c6f79fca86
I0427 00:56:44.063464       1 scheduler.go:454] Attempting to schedule pod: security-context-test-947/busybox-readonly-false-5aba6f70-5aae-4d4b-87a0-74c6f79fca86
I0427 00:56:44.063940       1 scheduler_binder.go:255] AssumePodVolumes for pod "security-context-test-947/busybox-readonly-false-5aba6f70-5aae-4d4b-87a0-74c6f79fca86", node "e2e-test-peterhornyack-windows-node-group-mdn5"
I0427 00:56:44.063972       1 scheduler_binder.go:265] AssumePodVolumes for pod "security-context-test-947/busybox-readonly-false-5aba6f70-5aae-4d4b-87a0-74c6f79fca86", node "e2e-test-peterhornyack-windows-node-group-mdn5": all PVCs bound and nothing to do
I0427 00:56:44.064009       1 factory.go:734] Attempting to bind busybox-readonly-false-5aba6f70-5aae-4d4b-87a0-74c6f79fca86 to e2e-test-peterhornyack-windows-node-group-mdn5
I0427 00:56:44.070938       1 scheduler.go:575] pod security-context-test-947/busybox-readonly-false-5aba6f70-5aae-4d4b-87a0-74c6f79fca86 is bound successfully on node e2e-test-peterhornyack-windows-node-group-mdn5, 5 nodes evaluated, 2 nodes were found feasible
I0427 00:56:50.813318       1 reflector.go:384] k8s.io/client-go/informers/factory.go:133: Watch close - *v1.ReplicaSet total 0 items received
I0427 00:56:51.389687       1 wrap.go:47] GET /healthz: (70.771µs) 200 [kube-probe/1.15+ 127.0.0.1:60940]
I0427 00:57:00.254974       1 scheduling_queue.go:895] About to try and schedule pod hostpath-5087/pod-host-path-test
I0427 00:57:00.255002       1 scheduler.go:454] Attempting to schedule pod: hostpath-5087/pod-host-path-test
I0427 00:57:00.255320       1 scheduler_binder.go:255] AssumePodVolumes for pod "hostpath-5087/pod-host-path-test", node "e2e-test-peterhornyack-windows-node-group-mdn5"
I0427 00:57:00.255347       1 scheduler_binder.go:265] AssumePodVolumes for pod "hostpath-5087/pod-host-path-test", node "e2e-test-peterhornyack-windows-node-group-mdn5": all PVCs bound and nothing to do
I0427 00:57:00.255390       1 factory.go:734] Attempting to bind pod-host-path-test to e2e-test-peterhornyack-windows-node-group-mdn5
I0427 00:57:00.260865       1 scheduler.go:575] pod hostpath-5087/pod-host-path-test is bound successfully on node e2e-test-peterhornyack-windows-node-group-mdn5, 5 nodes evaluated, 2 nodes were found feasible
I0427 00:57:01.390456       1 wrap.go:47] GET /healthz: (70.916µs) 200 [kube-probe/1.15+ 127.0.0.1:60976]
I0427 00:57:11.389740       1 wrap.go:47] GET /healthz: (72.642µs) 200 [kube-probe/1.15+ 127.0.0.1:32780]
I0427 00:57:21.389324       1 wrap.go:47] GET /healthz: (72.598µs) 200 [kube-probe/1.15+ 127.0.0.1:32812]
I0427 00:57:26.919438       1 scheduling_queue.go:895] About to try and schedule pod statefulset-775/ss2-0
I0427 00:57:26.919448       1 scheduler.go:454] Attempting to schedule pod: statefulset-775/ss2-0
I0427 00:57:26.919819       1 scheduler_binder.go:255] AssumePodVolumes for pod "statefulset-775/ss2-0", node "e2e-test-peterhornyack-windows-node-group-mdn5"
I0427 00:57:26.921280       1 scheduler_binder.go:265] AssumePodVolumes for pod "statefulset-775/ss2-0", node "e2e-test-peterhornyack-windows-node-group-mdn5": all PVCs bound and nothing to do
I0427 00:57:26.921319       1 factory.go:734] Attempting to bind ss2-0 to e2e-test-peterhornyack-windows-node-group-mdn5
I0427 00:57:26.932525       1 scheduler.go:575] pod statefulset-775/ss2-0 is bound successfully on node e2e-test-peterhornyack-windows-node-group-mdn5, 5 nodes evaluated, 2 nodes were found feasible
I0427 00:57:29.799003       1 reflector.go:384] k8s.io/client-go/informers/factory.go:133: Watch close - *v1.ReplicationController total 0 items received
I0427 00:57:31.389331       1 wrap.go:47] GET /healthz: (47.883µs) 200 [kube-probe/1.15+ 127.0.0.1:32848]
I0427 00:57:34.245470       1 scheduling_queue.go:895] About to try and schedule pod statefulset-775/ss2-1
I0427 00:57:34.245481       1 scheduler.go:454] Attempting to schedule pod: statefulset-775/ss2-1
I0427 00:57:34.245928       1 scheduler_binder.go:255] AssumePodVolumes for pod "statefulset-775/ss2-1", node "e2e-test-peterhornyack-windows-node-group-9bnh"
I0427 00:57:34.245938       1 scheduler_binder.go:265] AssumePodVolumes for pod "statefulset-775/ss2-1", node "e2e-test-peterhornyack-windows-node-group-9bnh": all PVCs bound and nothing to do
I0427 00:57:34.245992       1 factory.go:734] Attempting to bind ss2-1 to e2e-test-peterhornyack-windows-node-group-9bnh
I0427 00:57:34.254189       1 scheduler.go:575] pod statefulset-775/ss2-1 is bound successfully on node e2e-test-peterhornyack-windows-node-group-9bnh, 5 nodes evaluated, 2 nodes were found feasible
I0427 00:57:41.389736       1 wrap.go:47] GET /healthz: (76.96µs) 200 [kube-probe/1.15+ 127.0.0.1:32898]
I0427 00:57:41.726944       1 scheduling_queue.go:895] About to try and schedule pod statefulset-775/ss2-2
I0427 00:57:41.726958       1 scheduler.go:454] Attempting to schedule pod: statefulset-775/ss2-2
I0427 00:57:41.728536       1 scheduler_binder.go:255] AssumePodVolumes for pod "statefulset-775/ss2-2", node "e2e-test-peterhornyack-windows-node-group-mdn5"
I0427 00:57:41.728547       1 scheduler_binder.go:265] AssumePodVolumes for pod "statefulset-775/ss2-2", node "e2e-test-peterhornyack-windows-node-group-mdn5": all PVCs bound and nothing to do
I0427 00:57:41.728620       1 factory.go:734] Attempting to bind ss2-2 to e2e-test-peterhornyack-windows-node-group-mdn5
I0427 00:57:41.743128       1 scheduler.go:575] pod statefulset-775/ss2-2 is bound successfully on node e2e-test-peterhornyack-windows-node-group-mdn5, 5 nodes evaluated, 2 nodes were found feasible
I0427 00:57:51.389653       1 wrap.go:47] GET /healthz: (83.025µs) 200 [kube-probe/1.15+ 127.0.0.1:32930]
I0427 00:58:01.389412       1 wrap.go:47] GET /healthz: (61.794µs) 200 [kube-probe/1.15+ 127.0.0.1:32970]
I0427 00:58:11.389065       1 wrap.go:47] GET /healthz: (49.08µs) 200 [kube-probe/1.15+ 127.0.0.1:33008]
I0427 00:58:18.789335       1 scheduling_queue.go:895] About to try and schedule pod statefulset-775/ss2-2
I0427 00:58:18.789347       1 scheduler.go:454] Attempting to schedule pod: statefulset-775/ss2-2
I0427 00:58:18.793212       1 scheduler_binder.go:255] AssumePodVolumes for pod "statefulset-775/ss2-2", node "e2e-test-peterhornyack-windows-node-group-9bnh"
I0427 00:58:18.793224       1 scheduler_binder.go:265] AssumePodVolumes for pod "statefulset-775/ss2-2", node "e2e-test-peterhornyack-windows-node-group-9bnh": all PVCs bound and nothing to do
I0427 00:58:18.793289       1 factory.go:734] Attempting to bind ss2-2 to e2e-test-peterhornyack-windows-node-group-9bnh
I0427 00:58:18.809113       1 scheduler.go:575] pod statefulset-775/ss2-2 is bound successfully on node e2e-test-peterhornyack-windows-node-group-9bnh, 5 nodes evaluated, 2 nodes were found feasible
I0427 00:58:21.389538       1 wrap.go:47] GET /healthz: (69.752µs) 200 [kube-probe/1.15+ 127.0.0.1:33040]
I0427 00:58:31.389499       1 wrap.go:47] GET /healthz: (71.801µs) 200 [kube-probe/1.15+ 127.0.0.1:33072]
I0427 00:58:34.232244       1 scheduling_queue.go:895] About to try and schedule pod statefulset-775/ss2-1
I0427 00:58:34.232255       1 scheduler.go:454] Attempting to schedule pod: statefulset-775/ss2-1
I0427 00:58:34.233658       1 scheduler_binder.go:255] AssumePodVolumes for pod "statefulset-775/ss2-1", node "e2e-test-peterhornyack-windows-node-group-9bnh"
I0427 00:58:34.233668       1 scheduler_binder.go:265] AssumePodVolumes for pod "statefulset-775/ss2-1", node "e2e-test-peterhornyack-windows-node-group-9bnh": all PVCs bound and nothing to do
I0427 00:58:34.234912       1 factory.go:734] Attempting to bind ss2-1 to e2e-test-peterhornyack-windows-node-group-9bnh
I0427 00:58:34.243037       1 scheduler.go:575] pod statefulset-775/ss2-1 is bound successfully on node e2e-test-peterhornyack-windows-node-group-9bnh, 5 nodes evaluated, 2 nodes were found feasible
I0427 00:58:41.389430       1 wrap.go:47] GET /healthz: (60.916µs) 200 [kube-probe/1.15+ 127.0.0.1:33122]
I0427 00:58:50.037606       1 scheduling_queue.go:895] About to try and schedule pod statefulset-775/ss2-0
I0427 00:58:50.037616       1 scheduler.go:454] Attempting to schedule pod: statefulset-775/ss2-0
I0427 00:58:50.038281       1 scheduler_binder.go:255] AssumePodVolumes for pod "statefulset-775/ss2-0", node "e2e-test-peterhornyack-windows-node-group-9bnh"
I0427 00:58:50.038292       1 scheduler_binder.go:265] AssumePodVolumes for pod "statefulset-775/ss2-0", node "e2e-test-peterhornyack-windows-node-group-9bnh": all PVCs bound and nothing to do
I0427 00:58:50.038331       1 factory.go:734] Attempting to bind ss2-0 to e2e-test-peterhornyack-windows-node-group-9bnh
I0427 00:58:50.056679       1 scheduler.go:575] pod statefulset-775/ss2-0 is bound successfully on node e2e-test-peterhornyack-windows-node-group-9bnh, 5 nodes evaluated, 2 nodes were found feasible
I0427 00:58:51.389452       1 wrap.go:47] GET /healthz: (60.169µs) 200 [kube-probe/1.15+ 127.0.0.1:33156]
I0427 00:59:01.389455       1 wrap.go:47] GET /healthz: (66.558µs) 200 [kube-probe/1.15+ 127.0.0.1:33194]
I0427 00:59:11.389755       1 wrap.go:47] GET /healthz: (73.26µs) 200 [kube-probe/1.15+ 127.0.0.1:33232]
I0427 00:59:20.639323       1 scheduling_queue.go:895] About to try and schedule pod statefulset-775/ss2-2
I0427 00:59:20.639355       1 scheduler.go:454] Attempting to schedule pod: statefulset-775/ss2-2
I0427 00:59:20.641105       1 scheduler_binder.go:255] AssumePodVolumes for pod "statefulset-775/ss2-2", node "e2e-test-peterhornyack-windows-node-group-mdn5"
I0427 00:59:20.641116       1 scheduler_binder.go:265] AssumePodVolumes for pod "statefulset-775/ss2-2", node "e2e-test-peterhornyack-windows-node-group-mdn5": all PVCs bound and nothing to do
I0427 00:59:20.641191       1 factory.go:734] Attempting to bind ss2-2 to e2e-test-peterhornyack-windows-node-group-mdn5
I0427 00:59:20.653451       1 scheduler.go:575] pod statefulset-775/ss2-2 is bound successfully on node e2e-test-peterhornyack-windows-node-group-mdn5, 5 nodes evaluated, 2 nodes were found feasible
I0427 00:59:21.389730       1 wrap.go:47] GET /healthz: (68.267µs) 200 [kube-probe/1.15+ 127.0.0.1:33266]
I0427 00:59:31.389553       1 wrap.go:47] GET /healthz: (68.689µs) 200 [kube-probe/1.15+ 127.0.0.1:33298]
I0427 00:59:37.831628       1 scheduling_queue.go:895] About to try and schedule pod statefulset-775/ss2-1
I0427 00:59:37.831639       1 scheduler.go:454] Attempting to schedule pod: statefulset-775/ss2-1
I0427 00:59:37.832342       1 scheduler_binder.go:255] AssumePodVolumes for pod "statefulset-775/ss2-1", node "e2e-test-peterhornyack-windows-node-group-9bnh"
I0427 00:59:37.832353       1 scheduler_binder.go:265] AssumePodVolumes for pod "statefulset-775/ss2-1", node "e2e-test-peterhornyack-windows-node-group-9bnh": all PVCs bound and nothing to do
I0427 00:59:37.832390       1 factory.go:734] Attempting to bind ss2-1 to e2e-test-peterhornyack-windows-node-group-9bnh
I0427 00:59:37.842240       1 scheduler.go:575] pod statefulset-775/ss2-1 is bound successfully on node e2e-test-peterhornyack-windows-node-group-9bnh, 5 nodes evaluated, 2 nodes were found feasible
I0427 00:59:41.389537       1 wrap.go:47] GET /healthz: (63.088µs) 200 [kube-probe/1.15+ 127.0.0.1:33348]
I0427 00:59:51.389559       1 wrap.go:47] GET /healthz: (47.401µs) 200 [kube-probe/1.15+ 127.0.0.1:33380]
I0427 00:59:52.794389       1 reflector.go:384] k8s.io/client-go/informers/factory.go:133: Watch close - *v1beta1.PodDisruptionBudget total 0 items received
I0427 00:59:53.369804       1 scheduling_queue.go:895] About to try and schedule pod statefulset-775/ss2-0
I0427 00:59:53.369834       1 scheduler.go:454] Attempting to schedule pod: statefulset-775/ss2-0
I0427 00:59:53.371286       1 scheduler_binder.go:255] AssumePodVolumes for pod "statefulset-775/ss2-0", node "e2e-test-peterhornyack-windows-node-group-mdn5"
I0427 00:59:53.371297       1 scheduler_binder.go:265] AssumePodVolumes for pod "statefulset-775/ss2-0", node "e2e-test-peterhornyack-windows-node-group-mdn5": all PVCs bound and nothing to do
I0427 00:59:53.371348       1 factory.go:734] Attempting to bind ss2-0 to e2e-test-peterhornyack-windows-node-group-mdn5
I0427 00:59:53.382080       1 scheduler.go:575] pod statefulset-775/ss2-0 is bound successfully on node e2e-test-peterhornyack-windows-node-group-mdn5, 5 nodes evaluated, 2 nodes were found feasible
I0427 00:59:54.811350       1 reflector.go:384] k8s.io/client-go/informers/factory.go:133: Watch close - *v1.Node total 60 items received
I0427 01:00:01.389368       1 wrap.go:47] GET /healthz: (63.888µs) 200 [kube-probe/1.15+ 127.0.0.1:33416]
I0427 01:00:11.389863       1 wrap.go:47] GET /healthz: (84.698µs) 200 [kube-probe/1.15+ 127.0.0.1:33454]
I0427 01:00:21.390030       1 wrap.go:47] GET /healthz: (62.607µs) 200 [kube-probe/1.15+ 127.0.0.1:33486]
I0427 01:00:28.824998       1 reflector.go:384] k8s.io/client-go/informers/factory.go:133: Watch close - *v1.PersistentVolumeClaim total 0 items received
I0427 01:00:31.389842       1 wrap.go:47] GET /healthz: (94.84µs) 200 [kube-probe/1.15+ 127.0.0.1:33518]
I0427 01:00:39.491041       1 scheduling_queue.go:895] About to try and schedule pod containers-5688/client-containers-d307670e-d313-4b84-92fc-ba00677ba46c
I0427 01:00:39.491055       1 scheduler.go:454] Attempting to schedule pod: containers-5688/client-containers-d307670e-d313-4b84-92fc-ba00677ba46c
I0427 01:00:39.491386       1 scheduler_binder.go:255] AssumePodVolumes for pod "containers-5688/client-containers-d307670e-d313-4b84-92fc-ba00677ba46c", node "e2e-test-peterhornyack-windows-node-group-mdn5"
I0427 01:00:39.491399       1 scheduler_binder.go:265] AssumePodVolumes for pod "containers-5688/client-containers-d307670e-d313-4b84-92fc-ba00677ba46c", node "e2e-test-peterhornyack-windows-node-group-mdn5": all PVCs bound and nothing to do
I0427 01:00:39.491458       1 factory.go:734] Attempting to bind client-containers-d307670e-d313-4b84-92fc-ba00677ba46c to e2e-test-peterhornyack-windows-node-group-mdn5
I0427 01:00:39.499542       1 scheduler.go:575] pod containers-5688/client-containers-d307670e-d313-4b84-92fc-ba00677ba46c is bound successfully on node e2e-test-peterhornyack-windows-node-group-mdn5, 5 nodes evaluated, 2 nodes were found feasible
I0427 01:00:41.389651       1 wrap.go:47] GET /healthz: (80.937µs) 200 [kube-probe/1.15+ 127.0.0.1:33570]
I0427 01:00:51.389705       1 wrap.go:47] GET /healthz: (71.09µs) 200 [kube-probe/1.15+ 127.0.0.1:33602]
I0427 01:01:01.389636       1 wrap.go:47] GET /healthz: (81.356µs) 200 [kube-probe/1.15+ 127.0.0.1:33640]
I0427 01:01:11.389757       1 wrap.go:47] GET /healthz: (72.404µs) 200 [kube-probe/1.15+ 127.0.0.1:33676]
I0427 01:01:21.389631       1 wrap.go:47] GET /healthz: (91.431µs) 200 [kube-probe/1.15+ 127.0.0.1:33708]
I0427 01:01:31.390148       1 wrap.go:47] GET /healthz: (62.47µs) 200 [kube-probe/1.15+ 127.0.0.1:33740]
I0427 01:01:41.389657       1 wrap.go:47] GET /healthz: (80.631µs) 200 [kube-probe/1.15+ 127.0.0.1:33792]
I0427 01:01:51.389474       1 wrap.go:47] GET /healthz: (68.809µs) 200 [kube-probe/1.15+ 127.0.0.1:33824]
I0427 01:02:01.389340       1 wrap.go:47] GET /healthz: (71.331µs) 200 [kube-probe/1.15+ 127.0.0.1:33862]
I0427 01:02:11.389494       1 wrap.go:47] GET /healthz: (76.564µs) 200 [kube-probe/1.15+ 127.0.0.1:33898]
I0427 01:02:21.389395       1 wrap.go:47] GET /healthz: (62.876µs) 200 [kube-probe/1.15+ 127.0.0.1:33930]
I0427 01:02:31.389655       1 wrap.go:47] GET /healthz: (86.773µs) 200 [kube-probe/1.15+ 127.0.0.1:33962]
I0427 01:02:41.390010       1 wrap.go:47] GET /healthz: (62.337µs) 200 [kube-probe/1.15+ 127.0.0.1:34012]
I0427 01:02:44.774707       1 reflector.go:384] k8s.io/client-go/informers/factory.go:133: Watch close - *v1.Service total 2 items received
I0427 01:02:51.389750       1 wrap.go:47] GET /healthz: (76.78µs) 200 [kube-probe/1.15+ 127.0.0.1:34044]
I0427 01:03:01.389527       1 wrap.go:47] GET /healthz: (63.1µs) 200 [kube-probe/1.15+ 127.0.0.1:34082]
I0427 01:03:11.389581       1 wrap.go:47] GET /healthz: (46.709µs) 200 [kube-probe/1.15+ 127.0.0.1:34118]
I0427 01:03:21.390237       1 wrap.go:47] GET /healthz: (72.09µs) 200 [kube-probe/1.15+ 127.0.0.1:34152]
I0427 01:03:31.389472       1 wrap.go:47] GET /healthz: (62.7µs) 200 [kube-probe/1.15+ 127.0.0.1:34184]
I0427 01:03:33.828363       1 reflector.go:384] k8s.io/client-go/informers/factory.go:133: Watch close - *v1.StorageClass total 0 items received
I0427 01:03:41.389577       1 wrap.go:47] GET /healthz: (77.631µs) 200 [kube-probe/1.15+ 127.0.0.1:34234]
I0427 01:03:51.390006       1 wrap.go:47] GET /healthz: (72.008µs) 200 [kube-probe/1.15+ 127.0.0.1:34266]
I0427 01:03:51.807532       1 reflector.go:384] k8s.io/client-go/informers/factory.go:133: Watch close - *v1.PersistentVolume total 0 items received
I0427 01:03:52.815226       1 reflector.go:384] k8s.io/client-go/informers/factory.go:133: Watch close - *v1.ReplicaSet total 0 items received
I0427 01:04:01.389672       1 wrap.go:47] GET /healthz: (87.858µs) 200 [kube-probe/1.15+ 127.0.0.1:34302]
I0427 01:04:11.389778       1 wrap.go:47] GET /healthz: (73.66µs) 200 [kube-probe/1.15+ 127.0.0.1:34338]
I0427 01:04:21.390342       1 wrap.go:47] GET /healthz: (71.324µs) 200 [kube-probe/1.15+ 127.0.0.1:34372]
I0427 01:04:29.814706       1 reflector.go:384] cmd/kube-scheduler/app/server.go:223: Watch close - *v1.Pod total 112 items received
I0427 01:04:29.834997       1 reflector.go:384] k8s.io/client-go/informers/factory.go:133: Watch close - *v1.StatefulSet total 40 items received
I0427 01:04:31.389460       1 wrap.go:47] GET /healthz: (48.092µs) 200 [kube-probe/1.15+ 127.0.0.1:34404]
I0427 01:04:32.800742       1 reflector.go:384] k8s.io/client-go/informers/factory.go:133: Watch close - *v1.ReplicationController total 0 items received
I0427 01:04:41.389365       1 wrap.go:47] GET /healthz: (64.085µs) 200 [kube-probe/1.15+ 127.0.0.1:34456]
I0427 01:04:51.389357       1 wrap.go:47] GET /healthz: (46.873µs) 200 [kube-probe/1.15+ 127.0.0.1:34488]
I0427 01:05:01.389540       1 wrap.go:47] GET /healthz: (70.001µs) 200 [kube-probe/1.15+ 127.0.0.1:34524]
I0427 01:05:11.389572       1 wrap.go:47] GET /healthz: (79.769µs) 200 [kube-probe/1.15+ 127.0.0.1:34560]
I0427 01:05:21.389667       1 wrap.go:47] GET /healthz: (58.43µs) 200 [kube-probe/1.15+ 127.0.0.1:34592]
I0427 01:05:31.389805       1 wrap.go:47] GET /healthz: (79.022µs) 200 [kube-probe/1.15+ 127.0.0.1:34624]
I0427 01:05:41.389349       1 wrap.go:47] GET /healthz: (48.487µs) 200 [kube-probe/1.15+ 127.0.0.1:34676]
I0427 01:05:51.389444       1 wrap.go:47] GET /healthz: (64.665µs) 200 [kube-probe/1.15+ 127.0.0.1:34714]
I0427 01:05:57.796002       1 reflector.go:384] k8s.io/client-go/informers/factory.go:133: Watch close - *v1beta1.PodDisruptionBudget total 0 items received
I0427 01:05:59.791880       1 scheduling_queue.go:895] About to try and schedule pod kubectl-1746/update-demo-nautilus-7bmq7
I0427 01:05:59.791893       1 scheduler.go:454] Attempting to schedule pod: kubectl-1746/update-demo-nautilus-7bmq7
I0427 01:05:59.792459       1 scheduler_binder.go:255] AssumePodVolumes for pod "kubectl-1746/update-demo-nautilus-7bmq7", node "e2e-test-peterhornyack-windows-node-group-mdn5"
I0427 01:05:59.792471       1 scheduler_binder.go:265] AssumePodVolumes for pod "kubectl-1746/update-demo-nautilus-7bmq7", node "e2e-test-peterhornyack-windows-node-group-mdn5": all PVCs bound and nothing to do
I0427 01:05:59.794387       1 factory.go:734] Attempting to bind update-demo-nautilus-7bmq7 to e2e-test-peterhornyack-windows-node-group-mdn5
I0427 01:05:59.801441       1 scheduling_queue.go:895] About to try and schedule pod kubectl-1746/update-demo-nautilus-q4z5q
I0427 01:05:59.801448       1 scheduler.go:454] Attempting to schedule pod: kubectl-1746/update-demo-nautilus-q4z5q
I0427 01:05:59.801650       1 scheduler_binder.go:255] AssumePodVolumes for pod "kubectl-1746/update-demo-nautilus-q4z5q", node "e2e-test-peterhornyack-windows-node-group-9bnh"
I0427 01:05:59.801660       1 scheduler_binder.go:265] AssumePodVolumes for pod "kubectl-1746/update-demo-nautilus-q4z5q", node "e2e-test-peterhornyack-windows-node-group-9bnh": all PVCs bound and nothing to do
I0427 01:05:59.801689       1 factory.go:734] Attempting to bind update-demo-nautilus-q4z5q to e2e-test-peterhornyack-windows-node-group-9bnh
I0427 01:05:59.810711       1 cache.go:643] Couldn't expire cache for pod kubectl-1746/update-demo-nautilus-q4z5q. Binding is still in progress.
I0427 01:05:59.810801       1 scheduler.go:575] pod kubectl-1746/update-demo-nautilus-7bmq7 is bound successfully on node e2e-test-peterhornyack-windows-node-group-mdn5, 5 nodes evaluated, 2 nodes were found feasible
I0427 01:05:59.822101       1 scheduler.go:575] pod kubectl-1746/update-demo-nautilus-q4z5q is bound successfully on node e2e-test-peterhornyack-windows-node-group-9bnh, 5 nodes evaluated, 2 nodes were found feasible
I0427 01:06:01.389768       1 wrap.go:47] GET /healthz: (68.149µs) 200 [kube-probe/1.15+ 127.0.0.1:34752]
I0427 01:06:11.389463       1 wrap.go:47] GET /healthz: (53.035µs) 200 [kube-probe/1.15+ 127.0.0.1:34788]
I0427 01:06:19.456573       1 scheduling_queue.go:895] About to try and schedule pod kubectl-1746/update-demo-nautilus-m96k4
I0427 01:06:19.456585       1 scheduler.go:454] Attempting to schedule pod: kubectl-1746/update-demo-nautilus-m96k4
I0427 01:06:19.456954       1 scheduler_binder.go:255] AssumePodVolumes for pod "kubectl-1746/update-demo-nautilus-m96k4", node "e2e-test-peterhornyack-windows-node-group-9bnh"
I0427 01:06:19.456965       1 scheduler_binder.go:265] AssumePodVolumes for pod "kubectl-1746/update-demo-nautilus-m96k4", node "e2e-test-peterhornyack-windows-node-group-9bnh": all PVCs bound and nothing to do
I0427 01:06:19.457006       1 factory.go:734] Attempting to bind update-demo-nautilus-m96k4 to e2e-test-peterhornyack-windows-node-group-9bnh
I0427 01:06:19.466961       1 scheduler.go:575] pod kubectl-1746/update-demo-nautilus-m96k4 is bound successfully on node e2e-test-peterhornyack-windows-node-group-9bnh, 5 nodes evaluated, 2 nodes were found feasible
I0427 01:06:21.389659       1 wrap.go:47] GET /healthz: (77.515µs) 200 [kube-probe/1.15+ 127.0.0.1:34824]
I0427 01:06:31.389761       1 wrap.go:47] GET /healthz: (85.663µs) 200 [kube-probe/1.15+ 127.0.0.1:34856]
I0427 01:06:41.394314       1 wrap.go:47] GET /healthz: (173.722µs) 200 [kube-probe/1.15+ 127.0.0.1:35008]
I0427 01:06:41.860126       1 scheduling_queue.go:895] About to try and schedule pod downward-api-6602/downward-api-a3ed3be5-57d5-439a-9ee9-a21e76fc81f2
I0427 01:06:41.860138       1 scheduler.go:454] Attempting to schedule pod: downward-api-6602/downward-api-a3ed3be5-57d5-439a-9ee9-a21e76fc81f2
I0427 01:06:41.860484       1 scheduler_binder.go:255] AssumePodVolumes for pod "downward-api-6602/downward-api-a3ed3be5-57d5-439a-9ee9-a21e76fc81f2", node "e2e-test-peterhornyack-windows-node-group-9bnh"
I0427 01:06:41.860583       1 scheduler_binder.go:265] AssumePodVolumes for pod "downward-api-6602/downward-api-a3ed3be5-57d5-439a-9ee9-a21e76fc81f2", node "e2e-test-peterhornyack-windows-node-group-9bnh": all PVCs bound and nothing to do
I0427 01:06:41.860656       1 factory.go:734] Attempting to bind downward-api-a3ed3be5-57d5-439a-9ee9-a21e76fc81f2 to e2e-test-peterhornyack-windows-node-group-9bnh
I0427 01:06:41.864887       1 scheduler.go:575] pod downward-api-6602/downward-api-a3ed3be5-57d5-439a-9ee9-a21e76fc81f2 is bound successfully on node e2e-test-peterhornyack-windows-node-group-9bnh, 5 nodes evaluated, 2 nodes were found feasible
I0427 01:06:51.389610       1 wrap.go:47] GET /healthz: (69.763µs) 200 [kube-probe/1.15+ 127.0.0.1:35042]
I0427 01:06:58.279482       1 scheduling_queue.go:895] About to try and schedule pod configmap-4091/pod-configmaps-f6e84d87-9276-4842-b62d-d230acef32e7
I0427 01:06:58.279494       1 scheduler.go:454] Attempting to schedule pod: configmap-4091/pod-configmaps-f6e84d87-9276-4842-b62d-d230acef32e7
I0427 01:06:58.279759       1 scheduler_binder.go:255] AssumePodVolumes for pod "configmap-4091/pod-configmaps-f6e84d87-9276-4842-b62d-d230acef32e7", node "e2e-test-peterhornyack-windows-node-group-mdn5"
I0427 01:06:58.279770       1 scheduler_binder.go:265] AssumePodVolumes for pod "configmap-4091/pod-configmaps-f6e84d87-9276-4842-b62d-d230acef32e7", node "e2e-test-peterhornyack-windows-node-group-mdn5": all PVCs bound and nothing to do
I0427 01:06:58.279821       1 factory.go:734] Attempting to bind pod-configmaps-f6e84d87-9276-4842-b62d-d230acef32e7 to e2e-test-peterhornyack-windows-node-group-mdn5
I0427 01:06:58.284353       1 scheduler.go:575] pod configmap-4091/pod-configmaps-f6e84d87-9276-4842-b62d-d230acef32e7 is bound successfully on node e2e-test-peterhornyack-windows-node-group-mdn5, 5 nodes evaluated, 2 nodes were found feasible
I0427 01:07:01.389610       1 wrap.go:47] GET /healthz: (71.426µs) 200 [kube-probe/1.15+ 127.0.0.1:35080]
I0427 01:07:11.389527       1 wrap.go:47] GET /healthz: (75.342µs) 200 [kube-probe/1.15+ 127.0.0.1:35116]
I0427 01:07:14.654217       1 scheduling_queue.go:895] About to try and schedule pod downward-api-3928/labelsupdate0389447a-80ba-4a09-9d31-7153fb84ef8f
I0427 01:07:14.654231       1 scheduler.go:454] Attempting to schedule pod: downward-api-3928/labelsupdate0389447a-80ba-4a09-9d31-7153fb84ef8f
I0427 01:07:14.654546       1 scheduler_binder.go:255] AssumePodVolumes for pod "downward-api-3928/labelsupdate0389447a-80ba-4a09-9d31-7153fb84ef8f", node "e2e-test-peterhornyack-windows-node-group-mdn5"
I0427 01:07:14.654557       1 scheduler_binder.go:265] AssumePodVolumes for pod "downward-api-3928/labelsupdate0389447a-80ba-4a09-9d31-7153fb84ef8f", node "e2e-test-peterhornyack-windows-node-group-mdn5": all PVCs bound and nothing to do
I0427 01:07:14.654612       1 factory.go:734] Attempting to bind labelsupdate0389447a-80ba-4a09-9d31-7153fb84ef8f to e2e-test-peterhornyack-windows-node-group-mdn5
I0427 01:07:14.661118       1 scheduler.go:575] pod downward-api-3928/labelsupdate0389447a-80ba-4a09-9d31-7153fb84ef8f is bound successfully on node e2e-test-peterhornyack-windows-node-group-mdn5, 5 nodes evaluated, 2 nodes were found feasible
I0427 01:07:21.389153       1 wrap.go:47] GET /healthz: (81.385µs) 200 [kube-probe/1.15+ 127.0.0.1:35150]
I0427 01:07:31.389067       1 wrap.go:47] GET /healthz: (68.412µs) 200 [kube-probe/1.15+ 127.0.0.1:35182]
I0427 01:07:41.409703       1 wrap.go:47] GET /healthz: (87.513µs) 200 [kube-probe/1.15+ 127.0.0.1:35232]
I0427 01:07:49.506071       1 scheduling_queue.go:895] About to try and schedule pod projected-2793/downwardapi-volume-ce90562b-3822-407d-8fb6-1c8e2f4f6399
I0427 01:07:49.506085       1 scheduler.go:454] Attempting to schedule pod: projected-2793/downwardapi-volume-ce90562b-3822-407d-8fb6-1c8e2f4f6399
I0427 01:07:49.506363       1 scheduler_binder.go:255] AssumePodVolumes for pod "projected-2793/downwardapi-volume-ce90562b-3822-407d-8fb6-1c8e2f4f6399", node "e2e-test-peterhornyack-windows-node-group-mdn5"
I0427 01:07:49.506377       1 scheduler_binder.go:265] AssumePodVolumes for pod "projected-2793/downwardapi-volume-ce90562b-3822-407d-8fb6-1c8e2f4f6399", node "e2e-test-peterhornyack-windows-node-group-mdn5": all PVCs bound and nothing to do
I0427 01:07:49.508271       1 factory.go:734] Attempting to bind downwardapi-volume-ce90562b-3822-407d-8fb6-1c8e2f4f6399 to e2e-test-peterhornyack-windows-node-group-mdn5
I0427 01:07:49.513260       1 scheduler.go:575] pod projected-2793/downwardapi-volume-ce90562b-3822-407d-8fb6-1c8e2f4f6399 is bound successfully on node e2e-test-peterhornyack-windows-node-group-mdn5, 5 nodes evaluated, 2 nodes were found feasible
I0427 01:07:51.389872       1 wrap.go:47] GET /healthz: (69.769µs) 200 [kube-probe/1.15+ 127.0.0.1:35264]
I0427 01:08:01.389837       1 wrap.go:47] GET /healthz: (87.848µs) 200 [kube-probe/1.15+ 127.0.0.1:35300]
I0427 01:08:05.900885       1 scheduling_queue.go:895] About to try and schedule pod init-container-9994/pod-init-c82ef47b-5545-4663-8c4f-89fe32d083a7
I0427 01:08:05.900899       1 scheduler.go:454] Attempting to schedule pod: init-container-9994/pod-init-c82ef47b-5545-4663-8c4f-89fe32d083a7
I0427 01:08:05.901774       1 scheduler_binder.go:255] AssumePodVolumes for pod "init-container-9994/pod-init-c82ef47b-5545-4663-8c4f-89fe32d083a7", node "e2e-test-peterhornyack-windows-node-group-9bnh"
I0427 01:08:05.901789       1 scheduler_binder.go:265] AssumePodVolumes for pod "init-container-9994/pod-init-c82ef47b-5545-4663-8c4f-89fe32d083a7", node "e2e-test-peterhornyack-windows-node-group-9bnh": all PVCs bound and nothing to do
I0427 01:08:05.901828       1 factory.go:734] Attempting to bind pod-init-c82ef47b-5545-4663-8c4f-89fe32d083a7 to e2e-test-peterhornyack-windows-node-group-9bnh
I0427 01:08:05.909479       1 scheduler.go:575] pod init-container-9994/pod-init-c82ef47b-5545-4663-8c4f-89fe32d083a7 is bound successfully on node e2e-test-peterhornyack-windows-node-group-9bnh, 5 nodes evaluated, 2 nodes were found feasible
I0427 01:08:11.389619       1 wrap.go:47] GET /healthz: (69.544µs) 200 [kube-probe/1.15+ 127.0.0.1:35336]
I0427 01:08:16.776545       1 reflector.go:384] k8s.io/client-go/informers/factory.go:133: Watch close - *v1.Service total 0 items received
I0427 01:08:21.389816       1 wrap.go:47] GET /healthz: (69.724µs) 200 [kube-probe/1.15+ 127.0.0.1:35368]
I0427 01:08:25.691287       1 scheduling_queue.go:895] About to try and schedule pod aggregator-7204/sample-apiserver-deployment-7f7649696-5s6j6
I0427 01:08:25.691300       1 scheduler.go:454] Attempting to schedule pod: aggregator-7204/sample-apiserver-deployment-7f7649696-5s6j6
I0427 01:08:25.693233       1 scheduler_binder.go:255] AssumePodVolumes for pod "aggregator-7204/sample-apiserver-deployment-7f7649696-5s6j6", node "e2e-test-peterhornyack-windows-node-group-mdn5"
I0427 01:08:25.693245       1 scheduler_binder.go:265] AssumePodVolumes for pod "aggregator-7204/sample-apiserver-deployment-7f7649696-5s6j6", node "e2e-test-peterhornyack-windows-node-group-mdn5": all PVCs bound and nothing to do
I0427 01:08:25.693303       1 factory.go:734] Attempting to bind sample-apiserver-deployment-7f7649696-5s6j6 to e2e-test-peterhornyack-windows-node-group-mdn5
I0427 01:08:25.702475       1 scheduler.go:575] pod aggregator-7204/sample-apiserver-deployment-7f7649696-5s6j6 is bound successfully on node e2e-test-peterhornyack-windows-node-group-mdn5, 5 nodes evaluated, 2 nodes were found feasible
I0427 01:08:31.390564       1 wrap.go:47] GET /healthz: (74.36µs) 200 [kube-probe/1.15+ 127.0.0.1:35404]
I0427 01:08:41.389575       1 wrap.go:47] GET /healthz: (70.579µs) 200 [kube-probe/1.15+ 127.0.0.1:35456]
I0427 01:08:51.389399       1 wrap.go:47] GET /healthz: (73.577µs) 200 [kube-probe/1.15+ 127.0.0.1:35488]
I0427 01:08:53.817106       1 reflector.go:384] k8s.io/client-go/informers/factory.go:133: Watch close - *v1.ReplicaSet total 4 items received
I0427 01:08:59.826472       1 reflector.go:384] k8s.io/client-go/informers/factory.go:133: Watch close - *v1.PersistentVolumeClaim total 0 items received
I0427 01:09:01.389310       1 wrap.go:47] GET /healthz: (72.487µs) 200 [kube-probe/1.15+ 127.0.0.1:35524]
I0427 01:09:11.389757       1 wrap.go:47] GET /healthz: (72.222µs) 200 [kube-probe/1.15+ 127.0.0.1:35560]
I0427 01:09:21.389475       1 wrap.go:47] GET /healthz: (53.198µs) 200 [kube-probe/1.15+ 127.0.0.1:35592]
I0427 01:09:25.813116       1 reflector.go:384] k8s.io/client-go/informers/factory.go:133: Watch close - *v1.Node total 66 items received
I0427 01:09:31.389670       1 wrap.go:47] GET /healthz: (82.909µs) 200 [kube-probe/1.15+ 127.0.0.1:35624]
I0427 01:09:41.390557       1 wrap.go:47] GET /healthz: (73.135µs) 200 [kube-probe/1.15+ 127.0.0.1:35674]
I0427 01:09:51.389994       1 wrap.go:47] GET /healthz: (46.306µs) 200 [kube-probe/1.15+ 127.0.0.1:35710]
I0427 01:10:01.389518       1 wrap.go:47] GET /healthz: (64.673µs) 200 [kube-probe/1.15+ 127.0.0.1:35746]
I0427 01:10:11.389684       1 wrap.go:47] GET /healthz: (84.35µs) 200 [kube-probe/1.15+ 127.0.0.1:35786]
I0427 01:10:19.265384       1 scheduling_queue.go:895] About to try and schedule pod volume-9931/exec-volume-test-gcepd-preprovisionedpv-zbgz
I0427 01:10:19.265398       1 scheduler.go:454] Attempting to schedule pod: volume-9931/exec-volume-test-gcepd-preprovisionedpv-zbgz
I0427 01:10:19.266314       1 scheduler_binder.go:651] All bound volumes for Pod "volume-9931/exec-volume-test-gcepd-preprovisionedpv-zbgz" match with Node "e2e-test-peterhornyack-windows-node-group-mdn5"
I0427 01:10:19.266407       1 scheduler_binder.go:651] All bound volumes for Pod "volume-9931/exec-volume-test-gcepd-preprovisionedpv-zbgz" match with Node "e2e-test-peterhornyack-windows-node-group-9bnh"
I0427 01:10:19.266849       1 scheduler_binder.go:255] AssumePodVolumes for pod "volume-9931/exec-volume-test-gcepd-preprovisionedpv-zbgz", node "e2e-test-peterhornyack-windows-node-group-9bnh"
I0427 01:10:19.266883       1 scheduler_binder.go:265] AssumePodVolumes for pod "volume-9931/exec-volume-test-gcepd-preprovisionedpv-zbgz", node "e2e-test-peterhornyack-windows-node-group-9bnh": all PVCs bound and nothing to do
I0427 01:10:19.266927       1 factory.go:734] Attempting to bind exec-volume-test-gcepd-preprovisionedpv-zbgz to e2e-test-peterhornyack-windows-node-group-9bnh
I0427 01:10:19.272730       1 scheduler.go:575] pod volume-9931/exec-volume-test-gcepd-preprovisionedpv-zbgz is bound successfully on node e2e-test-peterhornyack-windows-node-group-9bnh, 5 nodes evaluated, 2 nodes were found feasible
I0427 01:10:21.389947       1 wrap.go:47] GET /healthz: (76.751µs) 200 [kube-probe/1.15+ 127.0.0.1:35820]
I0427 01:10:31.389394       1 wrap.go:47] GET /healthz: (64.002µs) 200 [kube-probe/1.15+ 127.0.0.1:35854]
I0427 01:10:41.389768       1 wrap.go:47] GET /healthz: (130.72µs) 200 [kube-probe/1.15+ 127.0.0.1:35904]
I0427 01:10:51.389375       1 wrap.go:47] GET /healthz: (66.658µs) 200 [kube-probe/1.15+ 127.0.0.1:35936]
I0427 01:11:01.389696       1 wrap.go:47] GET /healthz: (76.027µs) 200 [kube-probe/1.15+ 127.0.0.1:35972]
I0427 01:11:11.389427       1 wrap.go:47] GET /healthz: (64.743µs) 200 [kube-probe/1.15+ 127.0.0.1:36012]
I0427 01:11:14.832337       1 reflector.go:384] k8s.io/client-go/informers/factory.go:133: Watch close - *v1.StorageClass total 0 items received
I0427 01:11:21.389615       1 wrap.go:47] GET /healthz: (54.403µs) 200 [kube-probe/1.15+ 127.0.0.1:36046]
I0427 01:11:23.088274       1 scheduling_queue.go:895] About to try and schedule pod configmap-9170/pod-configmaps-cd303ff5-764f-4237-b8eb-a117796b6157
I0427 01:11:23.088285       1 scheduler.go:454] Attempting to schedule pod: configmap-9170/pod-configmaps-cd303ff5-764f-4237-b8eb-a117796b6157
I0427 01:11:23.088633       1 scheduler_binder.go:255] AssumePodVolumes for pod "configmap-9170/pod-configmaps-cd303ff5-764f-4237-b8eb-a117796b6157", node "e2e-test-peterhornyack-windows-node-group-mdn5"
I0427 01:11:23.088653       1 scheduler_binder.go:265] AssumePodVolumes for pod "configmap-9170/pod-configmaps-cd303ff5-764f-4237-b8eb-a117796b6157", node "e2e-test-peterhornyack-windows-node-group-mdn5": all PVCs bound and nothing to do
I0427 01:11:23.088708       1 factory.go:734] Attempting to bind pod-configmaps-cd303ff5-764f-4237-b8eb-a117796b6157 to e2e-test-peterhornyack-windows-node-group-mdn5
I0427 01:11:23.095280       1 scheduler.go:575] pod configmap-9170/pod-configmaps-cd303ff5-764f-4237-b8eb-a117796b6157 is bound successfully on node e2e-test-peterhornyack-windows-node-group-mdn5, 5 nodes evaluated, 2 nodes were found feasible
I0427 01:11:31.390066       1 wrap.go:47] GET /healthz: (62.502µs) 200 [kube-probe/1.15+ 127.0.0.1:36082]
I0427 01:11:35.809435       1 reflector.go:384] k8s.io/client-go/informers/factory.go:133: Watch close - *v1.PersistentVolume total 7 items received
I0427 01:11:41.389599       1 wrap.go:47] GET /healthz: (47.227µs) 200 [kube-probe/1.15+ 127.0.0.1:36132]
I0427 01:11:42.797809       1 reflector.go:384] k8s.io/client-go/informers/factory.go:133: Watch close - *v1beta1.PodDisruptionBudget total 0 items received
I0427 01:11:45.836813       1 reflector.go:384] k8s.io/client-go/informers/factory.go:133: Watch close - *v1.StatefulSet total 0 items received
I0427 01:11:51.389444       1 wrap.go:47] GET /healthz: (46.662µs) 200 [kube-probe/1.15+ 127.0.0.1:36164]
I0427 01:11:57.429293       1 scheduling_queue.go:895] About to try and schedule pod volume-1152/gcepd-injector-mxxh
I0427 01:11:57.429304       1 scheduler.go:454] Attempting to schedule pod: volume-1152/gcepd-injector-mxxh
I0427 01:11:57.429533       1 predicates.go:452] PVC volume-1152/pvc-2h5bh is not bound, assuming PVC matches predicate when counting limits
I0427 01:11:57.429570       1 predicates.go:452] PVC volume-1152/pvc-2h5bh is not bound, assuming PVC matches predicate when counting limits
I0427 01:11:57.429603       1 predicates.go:452] PVC volume-1152/pvc-2h5bh is not bound, assuming PVC matches predicate when counting limits
I0427 01:11:57.429623       1 scheduler_binder.go:683] No matching volumes for Pod "volume-1152/gcepd-injector-mxxh", PVC "volume-1152/pvc-2h5bh" on node "e2e-test-peterhornyack-windows-node-group-mdn5"
I0427 01:11:57.429635       1 scheduler_binder.go:738] Provisioning for claims of pod "volume-1152/gcepd-injector-mxxh" that has no matching volumes on node "e2e-test-peterhornyack-windows-node-group-mdn5" ...
I0427 01:11:57.429696       1 predicates.go:452] PVC volume-1152/pvc-2h5bh is not bound, assuming PVC matches predicate when counting limits
I0427 01:11:57.429714       1 predicates.go:452] PVC volume-1152/pvc-2h5bh is not bound, assuming PVC matches predicate when counting limits
I0427 01:11:57.429723       1 predicates.go:452] PVC volume-1152/pvc-2h5bh is not bound, assuming PVC matches predicate when counting limits
I0427 01:11:57.429732       1 scheduler_binder.go:683] No matching volumes for Pod "volume-1152/gcepd-injector-mxxh", PVC "volume-1152/pvc-2h5bh" on node "e2e-test-peterhornyack-windows-node-group-9bnh"
I0427 01:11:57.429741       1 scheduler_binder.go:738] Provisioning for claims of pod "volume-1152/gcepd-injector-mxxh" that has no matching volumes on node "e2e-test-peterhornyack-windows-node-group-9bnh" ...
I0427 01:11:57.429902       1 scheduler_binder.go:255] AssumePodVolumes for pod "volume-1152/gcepd-injector-mxxh", node "e2e-test-peterhornyack-windows-node-group-9bnh"
I0427 01:11:57.429935       1 scheduler_assume_cache.go:319] Assumed v1.PersistentVolumeClaim "volume-1152/pvc-2h5bh", version 29872
I0427 01:11:57.429974       1 scheduler_binder.go:330] BindPodVolumes for pod "volume-1152/gcepd-injector-mxxh", node "e2e-test-peterhornyack-windows-node-group-9bnh"
I0427 01:11:57.959480       1 cache.go:643] Couldn't expire cache for pod volume-1152/gcepd-injector-mxxh. Binding is still in progress.
I0427 01:11:58.959714       1 cache.go:643] Couldn't expire cache for pod volume-1152/gcepd-injector-mxxh. Binding is still in progress.
I0427 01:11:59.962565       1 cache.go:643] Couldn't expire cache for pod volume-1152/gcepd-injector-mxxh. Binding is still in progress.
I0427 01:12:00.436425       1 scheduler_binder.go:545] All PVCs for pod "volume-1152/gcepd-injector-mxxh" are bound
I0427 01:12:00.436450       1 factory.go:734] Attempting to bind gcepd-injector-mxxh to e2e-test-peterhornyack-windows-node-group-9bnh
I0427 01:12:00.442040       1 scheduler.go:575] pod volume-1152/gcepd-injector-mxxh is bound successfully on node e2e-test-peterhornyack-windows-node-group-9bnh, 5 nodes evaluated, 2 nodes were found feasible
I0427 01:12:01.389569       1 wrap.go:47] GET /healthz: (62.141µs) 200 [kube-probe/1.15+ 127.0.0.1:36208]
I0427 01:12:11.389478       1 wrap.go:47] GET /healthz: (67.934µs) 200 [kube-probe/1.15+ 127.0.0.1:36244]
I0427 01:12:14.802771       1 reflector.go:384] k8s.io/client-go/informers/factory.go:133: Watch close - *v1.ReplicationController total 13 items received
I0427 01:12:21.392243       1 wrap.go:47] GET /healthz: (77.052µs) 200 [kube-probe/1.15+ 127.0.0.1:36276]
I0427 01:12:30.235930       1 scheduling_queue.go:895] About to try and schedule pod volume-1152/gcepd-client
I0427 01:12:30.235943       1 scheduler.go:454] Attempting to schedule pod: volume-1152/gcepd-client
I0427 01:12:30.236407       1 scheduler_binder.go:651] All bound volumes for Pod "volume-1152/gcepd-client" match with Node "e2e-test-peterhornyack-windows-node-group-mdn5"
I0427 01:12:30.236481       1 scheduler_binder.go:651] All bound volumes for Pod "volume-1152/gcepd-client" match with Node "e2e-test-peterhornyack-windows-node-group-9bnh"
I0427 01:12:30.236675       1 scheduler_binder.go:255] AssumePodVolumes for pod "volume-1152/gcepd-client", node "e2e-test-peterhornyack-windows-node-group-mdn5"
I0427 01:12:30.236702       1 scheduler_binder.go:265] AssumePodVolumes for pod "volume-1152/gcepd-client", node "e2e-test-peterhornyack-windows-node-group-mdn5": all PVCs bound and nothing to do
I0427 01:12:30.236744       1 factory.go:734] Attempting to bind gcepd-client to e2e-test-peterhornyack-windows-node-group-mdn5
I0427 01:12:30.242971       1 scheduler.go:575] pod volume-1152/gcepd-client is bound successfully on node e2e-test-peterhornyack-windows-node-group-mdn5, 5 nodes evaluated, 2 nodes were found feasible
I0427 01:12:31.389712       1 wrap.go:47] GET /healthz: (79.698µs) 200 [kube-probe/1.15+ 127.0.0.1:36312]
I0427 01:12:41.389503       1 wrap.go:47] GET /healthz: (51.423µs) 200 [kube-probe/1.15+ 127.0.0.1:36362]
I0427 01:12:51.389440       1 wrap.go:47] GET /healthz: (44.926µs) 200 [kube-probe/1.15+ 127.0.0.1:36394]
I0427 01:13:01.389642       1 wrap.go:47] GET /healthz: (70.634µs) 200 [kube-probe/1.15+ 127.0.0.1:36432]
I0427 01:13:11.389399       1 wrap.go:47] GET /healthz: (69.642µs) 200 [kube-probe/1.15+ 127.0.0.1:36470]
I0427 01:13:21.389731       1 wrap.go:47] GET /healthz: (84.886µs) 200 [kube-probe/1.15+ 127.0.0.1:36506]
I0427 01:13:31.389514       1 wrap.go:47] GET /healthz: (50.502µs) 200 [kube-probe/1.15+ 127.0.0.1:36542]
I0427 01:13:41.389577       1 wrap.go:47] GET /healthz: (63.222µs) 200 [kube-probe/1.15+ 127.0.0.1:36596]
I0427 01:13:51.389404       1 wrap.go:47] GET /healthz: (48.067µs) 200 [kube-probe/1.15+ 127.0.0.1:36636]
I0427 01:13:57.816360       1 reflector.go:384] cmd/kube-scheduler/app/server.go:223: Watch close - *v1.Pod total 82 items received
I0427 01:14:01.389441       1 wrap.go:47] GET /healthz: (48.132µs) 200 [kube-probe/1.15+ 127.0.0.1:36676]
I0427 01:14:11.389453       1 wrap.go:47] GET /healthz: (66.106µs) 200 [kube-probe/1.15+ 127.0.0.1:36720]
I0427 01:14:21.389325       1 wrap.go:47] GET /healthz: (62.717µs) 200 [kube-probe/1.15+ 127.0.0.1:36752]
I0427 01:14:27.045552       1 scheduling_queue.go:895] About to try and schedule pod emptydir-wrapper-1723/pod-secrets-01160a0f-3dcd-49f6-805d-ad4b4b41293f
I0427 01:14:27.045564       1 scheduler.go:454] Attempting to schedule pod: emptydir-wrapper-1723/pod-secrets-01160a0f-3dcd-49f6-805d-ad4b4b41293f
I0427 01:14:27.046616       1 scheduler_binder.go:255] AssumePodVolumes for pod "emptydir-wrapper-1723/pod-secrets-01160a0f-3dcd-49f6-805d-ad4b4b41293f", node "e2e-test-peterhornyack-windows-node-group-9bnh"
I0427 01:14:27.046629       1 scheduler_binder.go:265] AssumePodVolumes for pod "emptydir-wrapper-1723/pod-secrets-01160a0f-3dcd-49f6-805d-ad4b4b41293f", node "e2e-test-peterhornyack-windows-node-group-9bnh": all PVCs bound and nothing to do
I0427 01:14:27.046698       1 factory.go:734] Attempting to bind pod-secrets-01160a0f-3dcd-49f6-805d-ad4b4b41293f to e2e-test-peterhornyack-windows-node-group-9bnh
I0427 01:14:27.052285       1 scheduler.go:575] pod emptydir-wrapper-1723/pod-secrets-01160a0f-3dcd-49f6-805d-ad4b4b41293f is bound successfully on node e2e-test-peterhornyack-windows-node-group-9bnh, 5 nodes evaluated, 2 nodes were found feasible
I0427 01:14:31.390141       1 wrap.go:47] GET /healthz: (49.928µs) 200 [kube-probe/1.15+ 127.0.0.1:36784]
I0427 01:14:41.389838       1 wrap.go:47] GET /healthz: (74.57µs) 200 [kube-probe/1.15+ 127.0.0.1:36834]
I0427 01:14:43.285268       1 scheduling_queue.go:895] About to try and schedule pod kubelet-test-6902/bin-falsef36dc56b-69cc-4a47-a4a4-d557b8a6540d
I0427 01:14:43.285281       1 scheduler.go:454] Attempting to schedule pod: kubelet-test-6902/bin-falsef36dc56b-69cc-4a47-a4a4-d557b8a6540d
I0427 01:14:43.285611       1 scheduler_binder.go:255] AssumePodVolumes for pod "kubelet-test-6902/bin-falsef36dc56b-69cc-4a47-a4a4-d557b8a6540d", node "e2e-test-peterhornyack-windows-node-group-mdn5"
I0427 01:14:43.285637       1 scheduler_binder.go:265] AssumePodVolumes for pod "kubelet-test-6902/bin-falsef36dc56b-69cc-4a47-a4a4-d557b8a6540d", node "e2e-test-peterhornyack-windows-node-group-mdn5": all PVCs bound and nothing to do
I0427 01:14:43.285738       1 factory.go:734] Attempting to bind bin-falsef36dc56b-69cc-4a47-a4a4-d557b8a6540d to e2e-test-peterhornyack-windows-node-group-mdn5
I0427 01:14:43.291922       1 scheduler.go:575] pod kubelet-test-6902/bin-falsef36dc56b-69cc-4a47-a4a4-d557b8a6540d is bound successfully on node e2e-test-peterhornyack-windows-node-group-mdn5, 5 nodes evaluated, 2 nodes were found feasible
I0427 01:14:44.778228       1 reflector.go:384] k8s.io/client-go/informers/factory.go:133: Watch close - *v1.Service total 2 items received
I0427 01:14:51.389669       1 wrap.go:47] GET /healthz: (69.517µs) 200 [kube-probe/1.15+ 127.0.0.1:36868]
I0427 01:14:59.395490       1 scheduling_queue.go:895] About to try and schedule pod downward-api-8062/downwardapi-volume-3168d1d7-d5fe-4437-be10-78c9505d6b4f
I0427 01:14:59.395503       1 scheduler.go:454] Attempting to schedule pod: downward-api-8062/downwardapi-volume-3168d1d7-d5fe-4437-be10-78c9505d6b4f
I0427 01:14:59.396004       1 scheduler_binder.go:255] AssumePodVolumes for pod "downward-api-8062/downwardapi-volume-3168d1d7-d5fe-4437-be10-78c9505d6b4f", node "e2e-test-peterhornyack-windows-node-group-mdn5"
I0427 01:14:59.396017       1 scheduler_binder.go:265] AssumePodVolumes for pod "downward-api-8062/downwardapi-volume-3168d1d7-d5fe-4437-be10-78c9505d6b4f", node "e2e-test-peterhornyack-windows-node-group-mdn5": all PVCs bound and nothing to do
I0427 01:14:59.396075       1 factory.go:734] Attempting to bind downwardapi-volume-3168d1d7-d5fe-4437-be10-78c9505d6b4f to e2e-test-peterhornyack-windows-node-group-mdn5
I0427 01:14:59.400706       1 scheduler.go:575] pod downward-api-8062/downwardapi-volume-3168d1d7-d5fe-4437-be10-78c9505d6b4f is bound successfully on node e2e-test-peterhornyack-windows-node-group-mdn5, 5 nodes evaluated, 2 nodes were found feasible
I0427 01:15:01.390407       1 wrap.go:47] GET /healthz: (74.296µs) 200 [kube-probe/1.15+ 127.0.0.1:36904]
I0427 01:15:11.390806       1 wrap.go:47] GET /healthz: (71.338µs) 200 [kube-probe/1.15+ 127.0.0.1:36942]
I0427 01:15:15.793152       1 scheduling_queue.go:895] About to try and schedule pod downward-api-1662/downwardapi-volume-b807ecac-d2d5-44b9-838c-9246d612af5c
I0427 01:15:15.793185       1 scheduler.go:454] Attempting to schedule pod: downward-api-1662/downwardapi-volume-b807ecac-d2d5-44b9-838c-9246d612af5c
I0427 01:15:15.793617       1 scheduler_binder.go:255] AssumePodVolumes for pod "downward-api-1662/downwardapi-volume-b807ecac-d2d5-44b9-838c-9246d612af5c", node "e2e-test-peterhornyack-windows-node-group-mdn5"
I0427 01:15:15.793630       1 scheduler_binder.go:265] AssumePodVolumes for pod "downward-api-1662/downwardapi-volume-b807ecac-d2d5-44b9-838c-9246d612af5c", node "e2e-test-peterhornyack-windows-node-group-mdn5": all PVCs bound and nothing to do
I0427 01:15:15.793698       1 factory.go:734] Attempting to bind downwardapi-volume-b807ecac-d2d5-44b9-838c-9246d612af5c to e2e-test-peterhornyack-windows-node-group-mdn5
I0427 01:15:15.800287       1 scheduler.go:575] pod downward-api-1662/downwardapi-volume-b807ecac-d2d5-44b9-838c-9246d612af5c is bound successfully on node e2e-test-peterhornyack-windows-node-group-mdn5, 5 nodes evaluated, 2 nodes were found feasible
I0427 01:15:21.389783       1 wrap.go:47] GET /healthz: (48.436µs) 200 [kube-probe/1.15+ 127.0.0.1:36976]
I0427 01:15:31.389412       1 wrap.go:47] GET /healthz: (47.535µs) 200 [kube-probe/1.15+ 127.0.0.1:37008]
I0427 01:15:32.158928       1 scheduling_queue.go:895] About to try and schedule pod container-runtime-6147/image-pull-test30511833-140a-4ec9-8c05-6da2d430454f
I0427 01:15:32.158938       1 scheduler.go:454] Attempting to schedule pod: container-runtime-6147/image-pull-test30511833-140a-4ec9-8c05-6da2d430454f
I0427 01:15:32.159565       1 scheduler_binder.go:255] AssumePodVolumes for pod "container-runtime-6147/image-pull-test30511833-140a-4ec9-8c05-6da2d430454f", node "e2e-test-peterhornyack-windows-node-group-9bnh"
I0427 01:15:32.159577       1 scheduler_binder.go:265] AssumePodVolumes for pod "container-runtime-6147/image-pull-test30511833-140a-4ec9-8c05-6da2d430454f", node "e2e-test-peterhornyack-windows-node-group-9bnh": all PVCs bound and nothing to do
I0427 01:15:32.159632       1 factory.go:734] Attempting to bind image-pull-test30511833-140a-4ec9-8c05-6da2d430454f to e2e-test-peterhornyack-windows-node-group-9bnh
I0427 01:15:32.164382       1 scheduler.go:575] pod container-runtime-6147/image-pull-test30511833-140a-4ec9-8c05-6da2d430454f is bound successfully on node e2e-test-peterhornyack-windows-node-group-9bnh, 5 nodes evaluated, 2 nodes were found feasible
I0427 01:15:41.389846       1 wrap.go:47] GET /healthz: (55.996µs) 200 [kube-probe/1.15+ 127.0.0.1:37058]
I0427 01:15:41.818908       1 reflector.go:384] k8s.io/client-go/informers/factory.go:133: Watch close - *v1.ReplicaSet total 1 items received
I0427 01:15:46.722147       1 scheduling_queue.go:895] About to try and schedule pod provisioning-4208/pvc-writer-node1-z9pck
I0427 01:15:46.722189       1 scheduler.go:454] Attempting to schedule pod: provisioning-4208/pvc-writer-node1-z9pck
I0427 01:15:46.722602       1 predicates.go:452] PVC provisioning-4208/pvc-xllm6 is not bound, assuming PVC matches predicate when counting limits
I0427 01:15:46.722759       1 predicates.go:452] PVC provisioning-4208/pvc-xllm6 is not bound, assuming PVC matches predicate when counting limits
I0427 01:15:46.722795       1 predicates.go:452] PVC provisioning-4208/pvc-xllm6 is not bound, assuming PVC matches predicate when counting limits
I0427 01:15:46.722820       1 scheduler_binder.go:683] No matching volumes for Pod "provisioning-4208/pvc-writer-node1-z9pck", PVC "provisioning-4208/pvc-xllm6" on node "e2e-test-peterhornyack-windows-node-group-mdn5"
I0427 01:15:46.722832       1 scheduler_binder.go:738] Provisioning for claims of pod "provisioning-4208/pvc-writer-node1-z9pck" that has no matching volumes on node "e2e-test-peterhornyack-windows-node-group-mdn5" ...
I0427 01:15:46.722878       1 predicates.go:452] PVC provisioning-4208/pvc-xllm6 is not bound, assuming PVC matches predicate when counting limits
I0427 01:15:46.722899       1 predicates.go:452] PVC provisioning-4208/pvc-xllm6 is not bound, assuming PVC matches predicate when counting limits
I0427 01:15:46.722907       1 predicates.go:452] PVC provisioning-4208/pvc-xllm6 is not bound, assuming PVC matches predicate when counting limits
I0427 01:15:46.722916       1 scheduler_binder.go:683] No matching volumes for Pod "provisioning-4208/pvc-writer-node1-z9pck", PVC "provisioning-4208/pvc-xllm6" on node "e2e-test-peterhornyack-windows-node-group-9bnh"
I0427 01:15:46.722924       1 scheduler_binder.go:738] Provisioning for claims of pod "provisioning-4208/pvc-writer-node1-z9pck" that has no matching volumes on node "e2e-test-peterhornyack-windows-node-group-9bnh" ...
I0427 01:15:46.723103       1 scheduler_binder.go:255] AssumePodVolumes for pod "provisioning-4208/pvc-writer-node1-z9pck", node "e2e-test-peterhornyack-windows-node-group-mdn5"
I0427 01:15:46.723139       1 scheduler_assume_cache.go:319] Assumed v1.PersistentVolumeClaim "provisioning-4208/pvc-xllm6", version 30516
I0427 01:15:46.723199       1 scheduler_binder.go:330] BindPodVolumes for pod "provisioning-4208/pvc-writer-node1-z9pck", node "e2e-test-peterhornyack-windows-node-group-mdn5"
I0427 01:15:47.056058       1 cache.go:643] Couldn't expire cache for pod provisioning-4208/pvc-writer-node1-z9pck. Binding is still in progress.
I0427 01:15:48.056266       1 cache.go:643] Couldn't expire cache for pod provisioning-4208/pvc-writer-node1-z9pck. Binding is still in progress.
I0427 01:15:49.056480       1 cache.go:643] Couldn't expire cache for pod provisioning-4208/pvc-writer-node1-z9pck. Binding is still in progress.
I0427 01:15:49.727331       1 scheduler_binder.go:545] All PVCs for pod "provisioning-4208/pvc-writer-node1-z9pck" are bound
I0427 01:15:49.727356       1 factory.go:734] Attempting to bind pvc-writer-node1-z9pck to e2e-test-peterhornyack-windows-node-group-mdn5
I0427 01:15:49.734301       1 scheduler.go:575] pod provisioning-4208/pvc-writer-node1-z9pck is bound successfully on node e2e-test-peterhornyack-windows-node-group-mdn5, 5 nodes evaluated, 2 nodes were found feasible
I0427 01:15:51.389473       1 wrap.go:47] GET /healthz: (47.35µs) 200 [kube-probe/1.15+ 127.0.0.1:37092]
I0427 01:16:01.389963       1 wrap.go:47] GET /healthz: (71.411µs) 200 [kube-probe/1.15+ 127.0.0.1:37128]
I0427 01:16:11.389286       1 wrap.go:47] GET /healthz: (61.188µs) 200 [kube-probe/1.15+ 127.0.0.1:37164]
I0427 01:16:18.815058       1 reflector.go:384] k8s.io/client-go/informers/factory.go:133: Watch close - *v1.Node total 57 items received
I0427 01:16:19.610202       1 scheduling_queue.go:895] About to try and schedule pod provisioning-4208/pvc-reader-node2-dp959
I0427 01:16:19.610213       1 scheduler.go:454] Attempting to schedule pod: provisioning-4208/pvc-reader-node2-dp959
I0427 01:16:19.610551       1 scheduler_binder.go:651] All bound volumes for Pod "provisioning-4208/pvc-reader-node2-dp959" match with Node "e2e-test-peterhornyack-windows-node-group-9bnh"
I0427 01:16:19.610631       1 scheduler_binder.go:255] AssumePodVolumes for pod "provisioning-4208/pvc-reader-node2-dp959", node "e2e-test-peterhornyack-windows-node-group-9bnh"
I0427 01:16:19.610641       1 scheduler_binder.go:265] AssumePodVolumes for pod "provisioning-4208/pvc-reader-node2-dp959", node "e2e-test-peterhornyack-windows-node-group-9bnh": all PVCs bound and nothing to do
I0427 01:16:19.610703       1 factory.go:734] Attempting to bind pvc-reader-node2-dp959 to e2e-test-peterhornyack-windows-node-group-9bnh
I0427 01:16:19.615555       1 scheduler.go:575] pod provisioning-4208/pvc-reader-node2-dp959 is bound successfully on node e2e-test-peterhornyack-windows-node-group-9bnh, 5 nodes evaluated, 1 nodes were found feasible
I0427 01:16:21.389474       1 wrap.go:47] GET /healthz: (46.266µs) 200 [kube-probe/1.15+ 127.0.0.1:37198]
I0427 01:16:26.828542       1 reflector.go:384] k8s.io/client-go/informers/factory.go:133: Watch close - *v1.PersistentVolumeClaim total 17 items received
I0427 01:16:31.393963       1 wrap.go:47] GET /healthz: (66.209µs) 200 [kube-probe/1.15+ 127.0.0.1:37232]
I0427 01:16:41.390564       1 wrap.go:47] GET /healthz: (68.914µs) 200 [kube-probe/1.15+ 127.0.0.1:37284]
I0427 01:16:51.389430       1 wrap.go:47] GET /healthz: (67.2µs) 200 [kube-probe/1.15+ 127.0.0.1:37316]
I0427 01:17:01.389734       1 wrap.go:47] GET /healthz: (82.871µs) 200 [kube-probe/1.15+ 127.0.0.1:37352]
I0427 01:17:11.389747       1 wrap.go:47] GET /healthz: (82.273µs) 200 [kube-probe/1.15+ 127.0.0.1:37388]
I0427 01:17:21.389412       1 wrap.go:47] GET /healthz: (65.316µs) 200 [kube-probe/1.15+ 127.0.0.1:37420]
I0427 01:17:31.389581       1 wrap.go:47] GET /healthz: (49.949µs) 200 [kube-probe/1.15+ 127.0.0.1:37452]
I0427 01:17:41.389716       1 wrap.go:47] GET /healthz: (82.52µs) 200 [kube-probe/1.15+ 127.0.0.1:37502]
I0427 01:17:51.394076       1 wrap.go:47] GET /healthz: (56.793µs) 200 [kube-probe/1.15+ 127.0.0.1:37536]
I0427 01:18:01.389642       1 wrap.go:47] GET /healthz: (73.309µs) 200 [kube-probe/1.15+ 127.0.0.1:37574]
I0427 01:18:11.389726       1 wrap.go:47] GET /healthz: (79.52µs) 200 [kube-probe/1.15+ 127.0.0.1:37610]
I0427 01:18:21.389448       1 wrap.go:47] GET /healthz: (59.662µs) 200 [kube-probe/1.15+ 127.0.0.1:37642]
I0427 01:18:31.389466       1 wrap.go:47] GET /healthz: (74.693µs) 200 [kube-probe/1.15+ 127.0.0.1:37674]
I0427 01:18:39.593124       1 scheduling_queue.go:895] About to try and schedule pod projected-6278/downwardapi-volume-fb663672-35cc-4468-b367-e9a2720cb63d
I0427 01:18:39.593142       1 scheduler.go:454] Attempting to schedule pod: projected-6278/downwardapi-volume-fb663672-35cc-4468-b367-e9a2720cb63d
I0427 01:18:39.593479       1 scheduler_binder.go:255] AssumePodVolumes for pod "projected-6278/downwardapi-volume-fb663672-35cc-4468-b367-e9a2720cb63d", node "e2e-test-peterhornyack-windows-node-group-mdn5"
I0427 01:18:39.593492       1 scheduler_binder.go:265] AssumePodVolumes for pod "projected-6278/downwardapi-volume-fb663672-35cc-4468-b367-e9a2720cb63d", node "e2e-test-peterhornyack-windows-node-group-mdn5": all PVCs bound and nothing to do
I0427 01:18:39.593563       1 factory.go:734] Attempting to bind downwardapi-volume-fb663672-35cc-4468-b367-e9a2720cb63d to e2e-test-peterhornyack-windows-node-group-mdn5
I0427 01:18:39.597707       1 scheduler.go:575] pod projected-6278/downwardapi-volume-fb663672-35cc-4468-b367-e9a2720cb63d is bound successfully on node e2e-test-peterhornyack-windows-node-group-mdn5, 5 nodes evaluated, 2 nodes were found feasible
I0427 01:18:41.389305       1 wrap.go:47] GET /healthz: (65.292µs) 200 [kube-probe/1.15+ 127.0.0.1:37724]
I0427 01:18:51.389500       1 wrap.go:47] GET /healthz: (46.868µs) 200 [kube-probe/1.15+ 127.0.0.1:37756]
I0427 01:18:51.834144       1 reflector.go:384] k8s.io/client-go/informers/factory.go:133: Watch close - *v1.StorageClass total 4 items received
I0427 01:18:55.799348       1 reflector.go:384] k8s.io/client-go/informers/factory.go:133: Watch close - *v1beta1.PodDisruptionBudget total 0 items received
I0427 01:18:55.968934       1 scheduling_queue.go:895] About to try and schedule pod downward-api-1293/downward-api-3578b326-23b9-44ec-880b-3f923c08fda6
I0427 01:18:55.968944       1 scheduler.go:454] Attempting to schedule pod: downward-api-1293/downward-api-3578b326-23b9-44ec-880b-3f923c08fda6
I0427 01:18:55.969467       1 scheduler_binder.go:255] AssumePodVolumes for pod "downward-api-1293/downward-api-3578b326-23b9-44ec-880b-3f923c08fda6", node "e2e-test-peterhornyack-windows-node-group-mdn5"
I0427 01:18:55.969480       1 scheduler_binder.go:265] AssumePodVolumes for pod "downward-api-1293/downward-api-3578b326-23b9-44ec-880b-3f923c08fda6", node "e2e-test-peterhornyack-windows-node-group-mdn5": all PVCs bound and nothing to do
I0427 01:18:55.969539       1 factory.go:734] Attempting to bind downward-api-3578b326-23b9-44ec-880b-3f923c08fda6 to e2e-test-peterhornyack-windows-node-group-mdn5
I0427 01:18:55.974344       1 scheduler.go:575] pod downward-api-1293/downward-api-3578b326-23b9-44ec-880b-3f923c08fda6 is bound successfully on node e2e-test-peterhornyack-windows-node-group-mdn5, 5 nodes evaluated, 2 nodes were found feasible
I0427 01:19:01.389408       1 wrap.go:47] GET /healthz: (63.792µs) 200 [kube-probe/1.15+ 127.0.0.1:37792]
I0427 01:19:11.389623       1 wrap.go:47] GET /healthz: (71.123µs) 200 [kube-probe/1.15+ 127.0.0.1:37832]
I0427 01:19:12.435725       1 scheduling_queue.go:895] About to try and schedule pod services-5519/pod1
I0427 01:19:12.435737       1 scheduler.go:454] Attempting to schedule pod: services-5519/pod1
I0427 01:19:12.436204       1 scheduler_binder.go:255] AssumePodVolumes for pod "services-5519/pod1", node "e2e-test-peterhornyack-windows-node-group-9bnh"
I0427 01:19:12.436216       1 scheduler_binder.go:265] AssumePodVolumes for pod "services-5519/pod1", node "e2e-test-peterhornyack-windows-node-group-9bnh": all PVCs bound and nothing to do
I0427 01:19:12.436275       1 factory.go:734] Attempting to bind pod1 to e2e-test-peterhornyack-windows-node-group-9bnh
I0427 01:19:12.441635       1 scheduler.go:575] pod services-5519/pod1 is bound successfully on node e2e-test-peterhornyack-windows-node-group-9bnh, 5 nodes evaluated, 2 nodes were found feasible
I0427 01:19:20.137912       1 scheduling_queue.go:895] About to try and schedule pod services-5519/pod2
I0427 01:19:20.137925       1 scheduler.go:454] Attempting to schedule pod: services-5519/pod2
I0427 01:19:20.140199       1 scheduler_binder.go:255] AssumePodVolumes for pod "services-5519/pod2", node "e2e-test-peterhornyack-windows-node-group-mdn5"
I0427 01:19:20.140210       1 scheduler_binder.go:265] AssumePodVolumes for pod "services-5519/pod2", node "e2e-test-peterhornyack-windows-node-group-mdn5": all PVCs bound and nothing to do
I0427 01:19:20.140260       1 factory.go:734] Attempting to bind pod2 to e2e-test-peterhornyack-windows-node-group-mdn5
I0427 01:19:20.144963       1 scheduler.go:575] pod services-5519/pod2 is bound successfully on node e2e-test-peterhornyack-windows-node-group-mdn5, 5 nodes evaluated, 2 nodes were found feasible
I0427 01:19:21.389906       1 wrap.go:47] GET /healthz: (60.41µs) 200 [kube-probe/1.15+ 127.0.0.1:37868]
I0427 01:19:31.390510       1 wrap.go:47] GET /healthz: (74.233µs) 200 [kube-probe/1.15+ 127.0.0.1:37900]
I0427 01:19:39.811553       1 reflector.go:384] k8s.io/client-go/informers/factory.go:133: Watch close - *v1.PersistentVolume total 10 items received
I0427 01:19:41.389567       1 wrap.go:47] GET /healthz: (72.2µs) 200 [kube-probe/1.15+ 127.0.0.1:37950]
I0427 01:19:51.389337       1 wrap.go:47] GET /healthz: (64.18µs) 200 [kube-probe/1.15+ 127.0.0.1:37982]
I0427 01:19:51.474545       1 scheduling_queue.go:895] About to try and schedule pod secrets-1827/pod-secrets-c905e58d-924e-4073-9679-016f5976bed8
I0427 01:19:51.474557       1 scheduler.go:454] Attempting to schedule pod: secrets-1827/pod-secrets-c905e58d-924e-4073-9679-016f5976bed8
I0427 01:19:51.475645       1 scheduler_binder.go:255] AssumePodVolumes for pod "secrets-1827/pod-secrets-c905e58d-924e-4073-9679-016f5976bed8", node "e2e-test-peterhornyack-windows-node-group-mdn5"
I0427 01:19:51.475658       1 scheduler_binder.go:265] AssumePodVolumes for pod "secrets-1827/pod-secrets-c905e58d-924e-4073-9679-016f5976bed8", node "e2e-test-peterhornyack-windows-node-group-mdn5": all PVCs bound and nothing to do
I0427 01:19:51.475713       1 factory.go:734] Attempting to bind pod-secrets-c905e58d-924e-4073-9679-016f5976bed8 to e2e-test-peterhornyack-windows-node-group-mdn5
I0427 01:19:51.481083       1 scheduler.go:575] pod secrets-1827/pod-secrets-c905e58d-924e-4073-9679-016f5976bed8 is bound successfully on node e2e-test-peterhornyack-windows-node-group-mdn5, 5 nodes evaluated, 2 nodes were found feasible
I0427 01:19:52.804410       1 reflector.go:384] k8s.io/client-go/informers/factory.go:133: Watch close - *v1.ReplicationController total 0 items received
I0427 01:20:01.389688       1 wrap.go:47] GET /healthz: (79.804µs) 200 [kube-probe/1.15+ 127.0.0.1:38020]
I0427 01:20:11.389247       1 wrap.go:47] GET /healthz: (94.497µs) 200 [kube-probe/1.15+ 127.0.0.1:38056]
I0427 01:20:15.818827       1 reflector.go:384] cmd/kube-scheduler/app/server.go:223: Watch close - *v1.Pod total 67 items received
I0427 01:20:21.389477       1 wrap.go:47] GET /healthz: (71.626µs) 200 [kube-probe/1.15+ 127.0.0.1:38088]
I0427 01:20:23.712613       1 scheduling_queue.go:895] About to try and schedule pod gc-2409/simpletest.deployment-7c4f7fdf59-hbt4q
I0427 01:20:23.712629       1 scheduler.go:454] Attempting to schedule pod: gc-2409/simpletest.deployment-7c4f7fdf59-hbt4q
I0427 01:20:23.714455       1 scheduler_binder.go:255] AssumePodVolumes for pod "gc-2409/simpletest.deployment-7c4f7fdf59-hbt4q", node "e2e-test-peterhornyack-windows-node-group-mdn5"
I0427 01:20:23.714466       1 scheduler_binder.go:265] AssumePodVolumes for pod "gc-2409/simpletest.deployment-7c4f7fdf59-hbt4q", node "e2e-test-peterhornyack-windows-node-group-mdn5": all PVCs bound and nothing to do
I0427 01:20:23.716369       1 factory.go:734] Attempting to bind simpletest.deployment-7c4f7fdf59-hbt4q to e2e-test-peterhornyack-windows-node-group-mdn5
I0427 01:20:23.723679       1 scheduling_queue.go:895] About to try and schedule pod gc-2409/simpletest.deployment-7c4f7fdf59-gqkjd
I0427 01:20:23.723690       1 scheduler.go:454] Attempting to schedule pod: gc-2409/simpletest.deployment-7c4f7fdf59-gqkjd
I0427 01:20:23.723970       1 scheduler_binder.go:255] AssumePodVolumes for pod "gc-2409/simpletest.deployment-7c4f7fdf59-gqkjd", node "e2e-test-peterhornyack-windows-node-group-9bnh"
I0427 01:20:23.723981       1 scheduler_binder.go:265] AssumePodVolumes for pod "gc-2409/simpletest.deployment-7c4f7fdf59-gqkjd", node "e2e-test-peterhornyack-windows-node-group-9bnh": all PVCs bound and nothing to do
I0427 01:20:23.724012       1 factory.go:734] Attempting to bind simpletest.deployment-7c4f7fdf59-gqkjd to e2e-test-peterhornyack-windows-node-group-9bnh
I0427 01:20:23.731876       1 scheduler.go:575] pod gc-2409/simpletest.deployment-7c4f7fdf59-hbt4q is bound successfully on node e2e-test-peterhornyack-windows-node-group-mdn5, 5 nodes evaluated, 2 nodes were found feasible
I0427 01:20:23.743454       1 scheduler.go:575] pod gc-2409/simpletest.deployment-7c4f7fdf59-gqkjd is bound successfully on node e2e-test-peterhornyack-windows-node-group-9bnh, 5 nodes evaluated, 2 nodes were found feasible
I0427 01:20:25.838573       1 reflector.go:384] k8s.io/client-go/informers/factory.go:133: Watch close - *v1.StatefulSet total 0 items received
I0427 01:20:31.390040       1 wrap.go:47] GET /healthz: (60.539µs) 200 [kube-probe/1.15+ 127.0.0.1:38126]
I0427 01:20:32.685184       1 scheduling_queue.go:895] About to try and schedule pod secrets-9463/pod-secrets-12d878e6-5fa9-4e12-95d5-785804e0b7bf
I0427 01:20:32.685198       1 scheduler.go:454] Attempting to schedule pod: secrets-9463/pod-secrets-12d878e6-5fa9-4e12-95d5-785804e0b7bf
I0427 01:20:32.685547       1 scheduler_binder.go:255] AssumePodVolumes for pod "secrets-9463/pod-secrets-12d878e6-5fa9-4e12-95d5-785804e0b7bf", node "e2e-test-peterhornyack-windows-node-group-mdn5"
I0427 01:20:32.685558       1 scheduler_binder.go:265] AssumePodVolumes for pod "secrets-9463/pod-secrets-12d878e6-5fa9-4e12-95d5-785804e0b7bf", node "e2e-test-peterhornyack-windows-node-group-mdn5": all PVCs bound and nothing to do
I0427 01:20:32.685607       1 factory.go:734] Attempting to bind pod-secrets-12d878e6-5fa9-4e12-95d5-785804e0b7bf to e2e-test-peterhornyack-windows-node-group-mdn5
I0427 01:20:32.693180       1 scheduler.go:575] pod secrets-9463/pod-secrets-12d878e6-5fa9-4e12-95d5-785804e0b7bf is bound successfully on node e2e-test-peterhornyack-windows-node-group-mdn5, 5 nodes evaluated, 2 nodes were found feasible
I0427 01:20:41.389759       1 wrap.go:47] GET /healthz: (90.302µs) 200 [kube-probe/1.15+ 127.0.0.1:38178]
I0427 01:20:49.080980       1 scheduling_queue.go:895] About to try and schedule pod projected-8029/downwardapi-volume-611f4f59-01b2-451e-a88b-3209d7be3770
I0427 01:20:49.080993       1 scheduler.go:454] Attempting to schedule pod: projected-8029/downwardapi-volume-611f4f59-01b2-451e-a88b-3209d7be3770
I0427 01:20:49.081326       1 scheduler_binder.go:255] AssumePodVolumes for pod "projected-8029/downwardapi-volume-611f4f59-01b2-451e-a88b-3209d7be3770", node "e2e-test-peterhornyack-windows-node-group-mdn5"
I0427 01:20:49.081355       1 scheduler_binder.go:265] AssumePodVolumes for pod "projected-8029/downwardapi-volume-611f4f59-01b2-451e-a88b-3209d7be3770", node "e2e-test-peterhornyack-windows-node-group-mdn5": all PVCs bound and nothing to do
I0427 01:20:49.081396       1 factory.go:734] Attempting to bind downwardapi-volume-611f4f59-01b2-451e-a88b-3209d7be3770 to e2e-test-peterhornyack-windows-node-group-mdn5
I0427 01:20:49.087387       1 scheduler.go:575] pod projected-8029/downwardapi-volume-611f4f59-01b2-451e-a88b-3209d7be3770 is bound successfully on node e2e-test-peterhornyack-windows-node-group-mdn5, 5 nodes evaluated, 2 nodes were found feasible
I0427 01:20:51.389699       1 wrap.go:47] GET /healthz: (75.078µs) 200 [kube-probe/1.15+ 127.0.0.1:38210]
I0427 01:21:01.389382       1 wrap.go:47] GET /healthz: (63.59µs) 200 [kube-probe/1.15+ 127.0.0.1:38246]
I0427 01:21:05.429614       1 scheduling_queue.go:895] About to try and schedule pod job-4856/foo-89qng
I0427 01:21:05.429653       1 scheduler.go:454] Attempting to schedule pod: job-4856/foo-89qng
I0427 01:21:05.430019       1 scheduler_binder.go:255] AssumePodVolumes for pod "job-4856/foo-89qng", node "e2e-test-peterhornyack-windows-node-group-mdn5"
I0427 01:21:05.430029       1 scheduler_binder.go:265] AssumePodVolumes for pod "job-4856/foo-89qng", node "e2e-test-peterhornyack-windows-node-group-mdn5": all PVCs bound and nothing to do
I0427 01:21:05.430082       1 factory.go:734] Attempting to bind foo-89qng to e2e-test-peterhornyack-windows-node-group-mdn5
I0427 01:21:05.434362       1 scheduler.go:575] pod job-4856/foo-89qng is bound successfully on node e2e-test-peterhornyack-windows-node-group-mdn5, 5 nodes evaluated, 2 nodes were found feasible
I0427 01:21:05.449288       1 scheduling_queue.go:895] About to try and schedule pod job-4856/foo-lvq88
I0427 01:21:05.449299       1 scheduler.go:454] Attempting to schedule pod: job-4856/foo-lvq88
I0427 01:21:05.449501       1 scheduler_binder.go:255] AssumePodVolumes for pod "job-4856/foo-lvq88", node "e2e-test-peterhornyack-windows-node-group-9bnh"
I0427 01:21:05.449510       1 scheduler_binder.go:265] AssumePodVolumes for pod "job-4856/foo-lvq88", node "e2e-test-peterhornyack-windows-node-group-9bnh": all PVCs bound and nothing to do
I0427 01:21:05.449540       1 factory.go:734] Attempting to bind foo-lvq88 to e2e-test-peterhornyack-windows-node-group-9bnh
I0427 01:21:05.463726       1 scheduler.go:575] pod job-4856/foo-lvq88 is bound successfully on node e2e-test-peterhornyack-windows-node-group-9bnh, 5 nodes evaluated, 2 nodes were found feasible
I0427 01:21:11.389557       1 wrap.go:47] GET /healthz: (64.986µs) 200 [kube-probe/1.15+ 127.0.0.1:38282]
I0427 01:21:21.389331       1 wrap.go:47] GET /healthz: (50.587µs) 200 [kube-probe/1.15+ 127.0.0.1:38314]
I0427 01:21:27.567929       1 scheduling_queue.go:895] About to try and schedule pod container-runtime-2464/image-pull-test569683cd-336b-4a80-96c7-a99928968dc5
I0427 01:21:27.567939       1 scheduler.go:454] Attempting to schedule pod: container-runtime-2464/image-pull-test569683cd-336b-4a80-96c7-a99928968dc5
I0427 01:21:27.568219       1 scheduler_binder.go:255] AssumePodVolumes for pod "container-runtime-2464/image-pull-test569683cd-336b-4a80-96c7-a99928968dc5", node "e2e-test-peterhornyack-windows-node-group-mdn5"
I0427 01:21:27.568231       1 scheduler_binder.go:265] AssumePodVolumes for pod "container-runtime-2464/image-pull-test569683cd-336b-4a80-96c7-a99928968dc5", node "e2e-test-peterhornyack-windows-node-group-mdn5": all PVCs bound and nothing to do
I0427 01:21:27.568399       1 factory.go:734] Attempting to bind image-pull-test569683cd-336b-4a80-96c7-a99928968dc5 to e2e-test-peterhornyack-windows-node-group-mdn5
I0427 01:21:27.573241       1 scheduler.go:575] pod container-runtime-2464/image-pull-test569683cd-336b-4a80-96c7-a99928968dc5 is bound successfully on node e2e-test-peterhornyack-windows-node-group-mdn5, 5 nodes evaluated, 2 nodes were found feasible
I0427 01:21:31.389192       1 wrap.go:47] GET /healthz: (63.788µs) 200 [kube-probe/1.15+ 127.0.0.1:38346]
I0427 01:21:41.040030       1 scheduling_queue.go:895] About to try and schedule pod gc-5625/simpletest.rc-v76vd
I0427 01:21:41.040058       1 scheduler.go:454] Attempting to schedule pod: gc-5625/simpletest.rc-v76vd
I0427 01:21:41.041191       1 scheduler_binder.go:255] AssumePodVolumes for pod "gc-5625/simpletest.rc-v76vd", node "e2e-test-peterhornyack-windows-node-group-9bnh"
I0427 01:21:41.041204       1 scheduler_binder.go:265] AssumePodVolumes for pod "gc-5625/simpletest.rc-v76vd", node "e2e-test-peterhornyack-windows-node-group-9bnh": all PVCs bound and nothing to do
I0427 01:21:41.042240       1 factory.go:734] Attempting to bind simpletest.rc-v76vd to e2e-test-peterhornyack-windows-node-group-9bnh
I0427 01:21:41.057184       1 scheduling_queue.go:895] About to try and schedule pod gc-5625/simpletest.rc-2bjqf
I0427 01:21:41.057196       1 scheduler.go:454] Attempting to schedule pod: gc-5625/simpletest.rc-2bjqf
I0427 01:21:41.057448       1 scheduler_binder.go:255] AssumePodVolumes for pod "gc-5625/simpletest.rc-2bjqf", node "e2e-test-peterhornyack-windows-node-group-mdn5"
I0427 01:21:41.057458       1 scheduler_binder.go:265] AssumePodVolumes for pod "gc-5625/simpletest.rc-2bjqf", node "e2e-test-peterhornyack-windows-node-group-mdn5": all PVCs bound and nothing to do
I0427 01:21:41.057491       1 factory.go:734] Attempting to bind simpletest.rc-2bjqf to e2e-test-peterhornyack-windows-node-group-mdn5
I0427 01:21:41.061440       1 scheduler.go:575] pod gc-5625/simpletest.rc-v76vd is bound successfully on node e2e-test-peterhornyack-windows-node-group-9bnh, 5 nodes evaluated, 2 nodes were found feasible
I0427 01:21:41.064235       1 scheduling_queue.go:895] About to try and schedule pod gc-5625/simpletest.rc-vtwj2
I0427 01:21:41.064243       1 scheduler.go:454] Attempting to schedule pod: gc-5625/simpletest.rc-vtwj2
I0427 01:21:41.064429       1 scheduler_binder.go:255] AssumePodVolumes for pod "gc-5625/simpletest.rc-vtwj2", node "e2e-test-peterhornyack-windows-node-group-9bnh"
I0427 01:21:41.064438       1 scheduler_binder.go:265] AssumePodVolumes for pod "gc-5625/simpletest.rc-vtwj2", node "e2e-test-peterhornyack-windows-node-group-9bnh": all PVCs bound and nothing to do
I0427 01:21:41.064459       1 factory.go:734] Attempting to bind simpletest.rc-vtwj2 to e2e-test-peterhornyack-windows-node-group-9bnh
I0427 01:21:41.074064       1 scheduler.go:575] pod gc-5625/simpletest.rc-2bjqf is bound successfully on node e2e-test-peterhornyack-windows-node-group-mdn5, 5 nodes evaluated, 2 nodes were found feasible
I0427 01:21:41.076700       1 scheduling_queue.go:895] About to try and schedule pod gc-5625/simpletest.rc-p2qf5
I0427 01:21:41.076707       1 scheduler.go:454] Attempting to schedule pod: gc-5625/simpletest.rc-p2qf5
I0427 01:21:41.077248       1 scheduler_binder.go:255] AssumePodVolumes for pod "gc-5625/simpletest.rc-p2qf5", node "e2e-test-peterhornyack-windows-node-group-mdn5"
I0427 01:21:41.077275       1 scheduler_binder.go:265] AssumePodVolumes for pod "gc-5625/simpletest.rc-p2qf5", node "e2e-test-peterhornyack-windows-node-group-mdn5": all PVCs bound and nothing to do
I0427 01:21:41.077298       1 factory.go:734] Attempting to bind simpletest.rc-p2qf5 to e2e-test-peterhornyack-windows-node-group-mdn5
I0427 01:21:41.085387       1 scheduler.go:575] pod gc-5625/simpletest.rc-vtwj2 is bound successfully on node e2e-test-peterhornyack-windows-node-group-9bnh, 5 nodes evaluated, 2 nodes were found feasible
I0427 01:21:41.087399       1 scheduling_queue.go:895] About to try and schedule pod gc-5625/simpletest.rc-g5qjl
I0427 01:21:41.087406       1 scheduler.go:454] Attempting to schedule pod: gc-5625/simpletest.rc-g5qjl
I0427 01:21:41.090866       1 scheduler_binder.go:255] AssumePodVolumes for pod "gc-5625/simpletest.rc-g5qjl", node "e2e-test-peterhornyack-windows-node-group-9bnh"
I0427 01:21:41.090877       1 scheduler_binder.go:265] AssumePodVolumes for pod "gc-5625/simpletest.rc-g5qjl", node "e2e-test-peterhornyack-windows-node-group-9bnh": all PVCs bound and nothing to do
I0427 01:21:41.090929       1 factory.go:734] Attempting to bind simpletest.rc-g5qjl to e2e-test-peterhornyack-windows-node-group-9bnh
I0427 01:21:41.091607       1 scheduling_queue.go:895] About to try and schedule pod gc-5625/simpletest.rc-kln8h
I0427 01:21:41.091613       1 scheduler.go:454] Attempting to schedule pod: gc-5625/simpletest.rc-kln8h
I0427 01:21:41.092549       1 scheduler_binder.go:255] AssumePodVolumes for pod "gc-5625/simpletest.rc-kln8h", node "e2e-test-peterhornyack-windows-node-group-mdn5"
I0427 01:21:41.092578       1 scheduler_binder.go:265] AssumePodVolumes for pod "gc-5625/simpletest.rc-kln8h", node "e2e-test-peterhornyack-windows-node-group-mdn5": all PVCs bound and nothing to do
I0427 01:21:41.092601       1 factory.go:734] Attempting to bind simpletest.rc-kln8h to e2e-test-peterhornyack-windows-node-group-mdn5
I0427 01:21:41.092801       1 scheduling_queue.go:895] About to try and schedule pod gc-5625/simpletest.rc-j5dzl
I0427 01:21:41.092807       1 scheduler.go:454] Attempting to schedule pod: gc-5625/simpletest.rc-j5dzl
I0427 01:21:41.093004       1 scheduler_binder.go:255] AssumePodVolumes for pod "gc-5625/simpletest.rc-j5dzl", node "e2e-test-peterhornyack-windows-node-group-9bnh"
I0427 01:21:41.093012       1 scheduler_binder.go:265] AssumePodVolumes for pod "gc-5625/simpletest.rc-j5dzl", node "e2e-test-peterhornyack-windows-node-group-9bnh": all PVCs bound and nothing to do
I0427 01:21:41.093032       1 factory.go:734] Attempting to bind simpletest.rc-j5dzl to e2e-test-peterhornyack-windows-node-group-9bnh
I0427 01:21:41.110472       1 scheduler.go:575] pod gc-5625/simpletest.rc-p2qf5 is bound successfully on node e2e-test-peterhornyack-windows-node-group-mdn5, 5 nodes evaluated, 2 nodes were found feasible
I0427 01:21:41.114244       1 scheduler.go:575] pod gc-5625/simpletest.rc-kln8h is bound successfully on node e2e-test-peterhornyack-windows-node-group-mdn5, 5 nodes evaluated, 2 nodes were found feasible
I0427 01:21:41.116469       1 scheduling_queue.go:895] About to try and schedule pod gc-5625/simpletest.rc-zm29t
I0427 01:21:41.116498       1 scheduler.go:454] Attempting to schedule pod: gc-5625/simpletest.rc-zm29t
I0427 01:21:41.116828       1 scheduler_binder.go:255] AssumePodVolumes for pod "gc-5625/simpletest.rc-zm29t", node "e2e-test-peterhornyack-windows-node-group-mdn5"
I0427 01:21:41.116838       1 scheduler_binder.go:265] AssumePodVolumes for pod "gc-5625/simpletest.rc-zm29t", node "e2e-test-peterhornyack-windows-node-group-mdn5": all PVCs bound and nothing to do
I0427 01:21:41.116890       1 factory.go:734] Attempting to bind simpletest.rc-zm29t to e2e-test-peterhornyack-windows-node-group-mdn5
I0427 01:21:41.120301       1 scheduling_queue.go:895] About to try and schedule pod gc-5625/simpletest.rc-wjz2s
I0427 01:21:41.120309       1 scheduler.go:454] Attempting to schedule pod: gc-5625/simpletest.rc-wjz2s
I0427 01:21:41.123559       1 scheduler_binder.go:255] AssumePodVolumes for pod "gc-5625/simpletest.rc-wjz2s", node "e2e-test-peterhornyack-windows-node-group-9bnh"
I0427 01:21:41.123575       1 scheduler_binder.go:265] AssumePodVolumes for pod "gc-5625/simpletest.rc-wjz2s", node "e2e-test-peterhornyack-windows-node-group-9bnh": all PVCs bound and nothing to do
I0427 01:21:41.123932       1 factory.go:734] Attempting to bind simpletest.rc-wjz2s to e2e-test-peterhornyack-windows-node-group-9bnh
I0427 01:21:41.126236       1 scheduling_queue.go:895] About to try and schedule pod gc-5625/simpletest.rc-vpm84
I0427 01:21:41.126242       1 scheduler.go:454] Attempting to schedule pod: gc-5625/simpletest.rc-vpm84
I0427 01:21:41.126424       1 scheduler_binder.go:255] AssumePodVolumes for pod "gc-5625/simpletest.rc-vpm84", node "e2e-test-peterhornyack-windows-node-group-mdn5"
I0427 01:21:41.126432       1 scheduler_binder.go:265] AssumePodVolumes for pod "gc-5625/simpletest.rc-vpm84", node "e2e-test-peterhornyack-windows-node-group-mdn5": all PVCs bound and nothing to do
I0427 01:21:41.126452       1 factory.go:734] Attempting to bind simpletest.rc-vpm84 to e2e-test-peterhornyack-windows-node-group-mdn5
I0427 01:21:41.131206       1 scheduler.go:575] pod gc-5625/simpletest.rc-g5qjl is bound successfully on node e2e-test-peterhornyack-windows-node-group-9bnh, 5 nodes evaluated, 2 nodes were found feasible
I0427 01:21:41.133372       1 scheduler.go:575] pod gc-5625/simpletest.rc-j5dzl is bound successfully on node e2e-test-peterhornyack-windows-node-group-9bnh, 5 nodes evaluated, 2 nodes were found feasible
I0427 01:21:41.146847       1 scheduler.go:575] pod gc-5625/simpletest.rc-vpm84 is bound successfully on node e2e-test-peterhornyack-windows-node-group-mdn5, 5 nodes evaluated, 2 nodes were found feasible
I0427 01:21:41.151096       1 scheduler.go:575] pod gc-5625/simpletest.rc-zm29t is bound successfully on node e2e-test-peterhornyack-windows-node-group-mdn5, 5 nodes evaluated, 2 nodes were found feasible
I0427 01:21:41.157937       1 scheduler.go:575] pod gc-5625/simpletest.rc-wjz2s is bound successfully on node e2e-test-peterhornyack-windows-node-group-9bnh, 5 nodes evaluated, 2 nodes were found feasible
I0427 01:21:41.389706       1 wrap.go:47] GET /healthz: (81.747µs) 200 [kube-probe/1.15+ 127.0.0.1:38396]
I0427 01:21:51.389612       1 wrap.go:47] GET /healthz: (56.866µs) 200 [kube-probe/1.15+ 127.0.0.1:38430]
I0427 01:22:01.389235       1 wrap.go:47] GET /healthz: (73.1µs) 200 [kube-probe/1.15+ 127.0.0.1:38466]
I0427 01:22:11.388936       1 wrap.go:47] GET /healthz: (47.859µs) 200 [kube-probe/1.15+ 127.0.0.1:38504]
I0427 01:22:21.389381       1 wrap.go:47] GET /healthz: (62.228µs) 200 [kube-probe/1.15+ 127.0.0.1:38536]
I0427 01:22:22.780067       1 reflector.go:384] k8s.io/client-go/informers/factory.go:133: Watch close - *v1.Service total 2 items received
I0427 01:22:29.312261       1 scheduling_queue.go:895] About to try and schedule pod replication-controller-4505/my-hostname-basic-114b4478-9192-4919-b726-4aebeb5e463e-gtn4q
I0427 01:22:29.312274       1 scheduler.go:454] Attempting to schedule pod: replication-controller-4505/my-hostname-basic-114b4478-9192-4919-b726-4aebeb5e463e-gtn4q
I0427 01:22:29.314499       1 scheduler_binder.go:255] AssumePodVolumes for pod "replication-controller-4505/my-hostname-basic-114b4478-9192-4919-b726-4aebeb5e463e-gtn4q", node "e2e-test-peterhornyack-windows-node-group-9bnh"
I0427 01:22:29.316450       1 scheduler_binder.go:265] AssumePodVolumes for pod "replication-controller-4505/my-hostname-basic-114b4478-9192-4919-b726-4aebeb5e463e-gtn4q", node "e2e-test-peterhornyack-windows-node-group-9bnh": all PVCs bound and nothing to do
I0427 01:22:29.316524       1 factory.go:734] Attempting to bind my-hostname-basic-114b4478-9192-4919-b726-4aebeb5e463e-gtn4q to e2e-test-peterhornyack-windows-node-group-9bnh
I0427 01:22:29.326555       1 scheduler.go:575] pod replication-controller-4505/my-hostname-basic-114b4478-9192-4919-b726-4aebeb5e463e-gtn4q is bound successfully on node e2e-test-peterhornyack-windows-node-group-9bnh, 5 nodes evaluated, 2 nodes were found feasible
I0427 01:22:31.389755       1 wrap.go:47] GET /healthz: (84.207µs) 200 [kube-probe/1.15+ 127.0.0.1:38568]
I0427 01:22:41.389851       1 wrap.go:47] GET /healthz: (73.432µs) 200 [kube-probe/1.15+ 127.0.0.1:38618]
I0427 01:22:51.389273       1 wrap.go:47] GET /healthz: (47.002µs) 200 [kube-probe/1.15+ 127.0.0.1:38652]
I0427 01:22:56.542715       1 scheduling_queue.go:895] About to try and schedule pod containers-3317/client-containers-9a9a89d9-e564-4e04-868c-a8bd48d0371e
I0427 01:22:56.542729       1 scheduler.go:454] Attempting to schedule pod: containers-3317/client-containers-9a9a89d9-e564-4e04-868c-a8bd48d0371e
I0427 01:22:56.543062       1 scheduler_binder.go:255] AssumePodVolumes for pod "containers-3317/client-containers-9a9a89d9-e564-4e04-868c-a8bd48d0371e", node "e2e-test-peterhornyack-windows-node-group-mdn5"
I0427 01:22:56.543076       1 scheduler_binder.go:265] AssumePodVolumes for pod "containers-3317/client-containers-9a9a89d9-e564-4e04-868c-a8bd48d0371e", node "e2e-test-peterhornyack-windows-node-group-mdn5": all PVCs bound and nothing to do
I0427 01:22:56.543134       1 factory.go:734] Attempting to bind client-containers-9a9a89d9-e564-4e04-868c-a8bd48d0371e to e2e-test-peterhornyack-windows-node-group-mdn5
I0427 01:22:56.549007       1 scheduler.go:575] pod containers-3317/client-containers-9a9a89d9-e564-4e04-868c-a8bd48d0371e is bound successfully on node e2e-test-peterhornyack-windows-node-group-mdn5, 5 nodes evaluated, 2 nodes were found feasible
I0427 01:23:01.389305       1 wrap.go:47] GET /healthz: (64.74µs) 200 [kube-probe/1.15+ 127.0.0.1:38690]
I0427 01:23:03.816744       1 reflector.go:384] k8s.io/client-go/informers/factory.go:133: Watch close - *v1.Node total 52 items received
I0427 01:23:11.389575       1 wrap.go:47] GET /healthz: (70.476µs) 200 [kube-probe/1.15+ 127.0.0.1:38728]
I0427 01:23:12.963147       1 scheduling_queue.go:895] About to try and schedule pod configmap-4557/pod-configmaps-82583255-35d1-4f78-8ce9-03f18fc90024
I0427 01:23:12.963186       1 scheduler.go:454] Attempting to schedule pod: configmap-4557/pod-configmaps-82583255-35d1-4f78-8ce9-03f18fc90024
I0427 01:23:12.963937       1 scheduler_binder.go:255] AssumePodVolumes for pod "configmap-4557/pod-configmaps-82583255-35d1-4f78-8ce9-03f18fc90024", node "e2e-test-peterhornyack-windows-node-group-mdn5"
I0427 01:23:12.963966       1 scheduler_binder.go:265] AssumePodVolumes for pod "configmap-4557/pod-configmaps-82583255-35d1-4f78-8ce9-03f18fc90024", node "e2e-test-peterhornyack-windows-node-group-mdn5": all PVCs bound and nothing to do
I0427 01:23:12.964011       1 factory.go:734] Attempting to bind pod-configmaps-82583255-35d1-4f78-8ce9-03f18fc90024 to e2e-test-peterhornyack-windows-node-group-mdn5
I0427 01:23:12.972433       1 scheduler.go:575] pod configmap-4557/pod-configmaps-82583255-35d1-4f78-8ce9-03f18fc90024 is bound successfully on node e2e-test-peterhornyack-windows-node-group-mdn5, 5 nodes evaluated, 2 nodes were found feasible
I0427 01:23:21.389270       1 wrap.go:47] GET /healthz: (48.476µs) 200 [kube-probe/1.15+ 127.0.0.1:38760]
I0427 01:23:31.397021       1 wrap.go:47] GET /healthz: (80.559µs) 200 [kube-probe/1.15+ 127.0.0.1:38794]
I0427 01:23:37.524200       1 scheduling_queue.go:895] About to try and schedule pod secrets-5688/pod-configmaps-ddcfc8c3-7c68-4b88-a74d-ad6446ebf297
I0427 01:23:37.524213       1 scheduler.go:454] Attempting to schedule pod: secrets-5688/pod-configmaps-ddcfc8c3-7c68-4b88-a74d-ad6446ebf297
I0427 01:23:37.524474       1 scheduler_binder.go:255] AssumePodVolumes for pod "secrets-5688/pod-configmaps-ddcfc8c3-7c68-4b88-a74d-ad6446ebf297", node "e2e-test-peterhornyack-windows-node-group-mdn5"
I0427 01:23:37.524485       1 scheduler_binder.go:265] AssumePodVolumes for pod "secrets-5688/pod-configmaps-ddcfc8c3-7c68-4b88-a74d-ad6446ebf297", node "e2e-test-peterhornyack-windows-node-group-mdn5": all PVCs bound and nothing to do
I0427 01:23:37.526148       1 factory.go:734] Attempting to bind pod-configmaps-ddcfc8c3-7c68-4b88-a74d-ad6446ebf297 to e2e-test-peterhornyack-windows-node-group-mdn5
I0427 01:23:37.531230       1 scheduler.go:575] pod secrets-5688/pod-configmaps-ddcfc8c3-7c68-4b88-a74d-ad6446ebf297 is bound successfully on node e2e-test-peterhornyack-windows-node-group-mdn5, 5 nodes evaluated, 2 nodes were found feasible
I0427 01:23:41.389584       1 wrap.go:47] GET /healthz: (54.849µs) 200 [kube-probe/1.15+ 127.0.0.1:38844]
I0427 01:23:51.389665       1 wrap.go:47] GET /healthz: (72.404µs) 200 [kube-probe/1.15+ 127.0.0.1:38876]
I0427 01:23:53.917250       1 scheduling_queue.go:895] About to try and schedule pod init-container-2258/pod-init-52e95684-e0a4-4faa-919c-a8e2ee239dbd
I0427 01:23:53.917265       1 scheduler.go:454] Attempting to schedule pod: init-container-2258/pod-init-52e95684-e0a4-4faa-919c-a8e2ee239dbd
I0427 01:23:53.918569       1 scheduler_binder.go:255] AssumePodVolumes for pod "init-container-2258/pod-init-52e95684-e0a4-4faa-919c-a8e2ee239dbd", node "e2e-test-peterhornyack-windows-node-group-9bnh"
I0427 01:23:53.918581       1 scheduler_binder.go:265] AssumePodVolumes for pod "init-container-2258/pod-init-52e95684-e0a4-4faa-919c-a8e2ee239dbd", node "e2e-test-peterhornyack-windows-node-group-9bnh": all PVCs bound and nothing to do
I0427 01:23:53.918711       1 factory.go:734] Attempting to bind pod-init-52e95684-e0a4-4faa-919c-a8e2ee239dbd to e2e-test-peterhornyack-windows-node-group-9bnh
I0427 01:23:53.925535       1 scheduler.go:575] pod init-container-2258/pod-init-52e95684-e0a4-4faa-919c-a8e2ee239dbd is bound successfully on node e2e-test-peterhornyack-windows-node-group-9bnh, 5 nodes evaluated, 2 nodes were found feasible
I0427 01:24:01.389326       1 wrap.go:47] GET /healthz: (65.21µs) 200 [kube-probe/1.15+ 127.0.0.1:38912]
I0427 01:24:11.389438       1 wrap.go:47] GET /healthz: (45.883µs) 200 [kube-probe/1.15+ 127.0.0.1:38948]
I0427 01:24:21.389091       1 wrap.go:47] GET /healthz: (71.614µs) 200 [kube-probe/1.15+ 127.0.0.1:38982]
I0427 01:24:26.800696       1 reflector.go:384] k8s.io/client-go/informers/factory.go:133: Watch close - *v1beta1.PodDisruptionBudget total 0 items received
I0427 01:24:31.389330       1 wrap.go:47] GET /healthz: (63.591µs) 200 [kube-probe/1.15+ 127.0.0.1:39014]
I0427 01:24:40.282337       1 scheduling_queue.go:895] About to try and schedule pod downward-api-2824/downwardapi-volume-e4471108-9fe0-4346-8739-a79c3c9a7359
I0427 01:24:40.282351       1 scheduler.go:454] Attempting to schedule pod: downward-api-2824/downwardapi-volume-e4471108-9fe0-4346-8739-a79c3c9a7359
I0427 01:24:40.282717       1 scheduler_binder.go:255] AssumePodVolumes for pod "downward-api-2824/downwardapi-volume-e4471108-9fe0-4346-8739-a79c3c9a7359", node "e2e-test-peterhornyack-windows-node-group-mdn5"
I0427 01:24:40.282730       1 scheduler_binder.go:265] AssumePodVolumes for pod "downward-api-2824/downwardapi-volume-e4471108-9fe0-4346-8739-a79c3c9a7359", node "e2e-test-peterhornyack-windows-node-group-mdn5": all PVCs bound and nothing to do
I0427 01:24:40.282788       1 factory.go:734] Attempting to bind downwardapi-volume-e4471108-9fe0-4346-8739-a79c3c9a7359 to e2e-test-peterhornyack-windows-node-group-mdn5
I0427 01:24:40.288717       1 scheduler.go:575] pod downward-api-2824/downwardapi-volume-e4471108-9fe0-4346-8739-a79c3c9a7359 is bound successfully on node e2e-test-peterhornyack-windows-node-group-mdn5, 5 nodes evaluated, 2 nodes were found feasible
I0427 01:24:41.389402       1 wrap.go:47] GET /healthz: (59.137µs) 200 [kube-probe/1.15+ 127.0.0.1:39064]
I0427 01:24:51.389792       1 wrap.go:47] GET /healthz: (106.972µs) 200 [kube-probe/1.15+ 127.0.0.1:39098]
I0427 01:24:56.671550       1 scheduling_queue.go:895] About to try and schedule pod configmap-5141/pod-configmaps-8bcb6639-f676-4682-b039-6e2d1488f4a9
I0427 01:24:56.671563       1 scheduler.go:454] Attempting to schedule pod: configmap-5141/pod-configmaps-8bcb6639-f676-4682-b039-6e2d1488f4a9
I0427 01:24:56.671906       1 scheduler_binder.go:255] AssumePodVolumes for pod "configmap-5141/pod-configmaps-8bcb6639-f676-4682-b039-6e2d1488f4a9", node "e2e-test-peterhornyack-windows-node-group-9bnh"
I0427 01:24:56.671935       1 scheduler_binder.go:265] AssumePodVolumes for pod "configmap-5141/pod-configmaps-8bcb6639-f676-4682-b039-6e2d1488f4a9", node "e2e-test-peterhornyack-windows-node-group-9bnh": all PVCs bound and nothing to do
I0427 01:24:56.671970       1 factory.go:734] Attempting to bind pod-configmaps-8bcb6639-f676-4682-b039-6e2d1488f4a9 to e2e-test-peterhornyack-windows-node-group-9bnh
I0427 01:24:56.677458       1 scheduler.go:575] pod configmap-5141/pod-configmaps-8bcb6639-f676-4682-b039-6e2d1488f4a9 is bound successfully on node e2e-test-peterhornyack-windows-node-group-9bnh, 5 nodes evaluated, 2 nodes were found feasible
I0427 01:25:01.389734       1 wrap.go:47] GET /healthz: (81.024µs) 200 [kube-probe/1.15+ 127.0.0.1:39134]
I0427 01:25:11.390117       1 wrap.go:47] GET /healthz: (76.5µs) 200 [kube-probe/1.15+ 127.0.0.1:39170]
I0427 01:25:13.027397       1 scheduling_queue.go:895] About to try and schedule pod containers-3341/client-containers-c2ea2051-74ca-4694-9099-e43eafb73926
I0427 01:25:13.027427       1 scheduler.go:454] Attempting to schedule pod: containers-3341/client-containers-c2ea2051-74ca-4694-9099-e43eafb73926
I0427 01:25:13.027736       1 scheduler_binder.go:255] AssumePodVolumes for pod "containers-3341/client-containers-c2ea2051-74ca-4694-9099-e43eafb73926", node "e2e-test-peterhornyack-windows-node-group-mdn5"
I0427 01:25:13.027773       1 scheduler_binder.go:265] AssumePodVolumes for pod "containers-3341/client-containers-c2ea2051-74ca-4694-9099-e43eafb73926", node "e2e-test-peterhornyack-windows-node-group-mdn5": all PVCs bound and nothing to do
I0427 01:25:13.027828       1 factory.go:734] Attempting to bind client-containers-c2ea2051-74ca-4694-9099-e43eafb73926 to e2e-test-peterhornyack-windows-node-group-mdn5
I0427 01:25:13.034737       1 scheduler.go:575] pod containers-3341/client-containers-c2ea2051-74ca-4694-9099-e43eafb73926 is bound successfully on node e2e-test-peterhornyack-windows-node-group-mdn5, 5 nodes evaluated, 2 nodes were found feasible
I0427 01:25:13.830212       1 reflector.go:384] k8s.io/client-go/informers/factory.go:133: Watch close - *v1.PersistentVolumeClaim total 2 items received
I0427 01:25:21.389473       1 wrap.go:47] GET /healthz: (70.489µs) 200 [kube-probe/1.15+ 127.0.0.1:39202]
I0427 01:25:31.389511       1 wrap.go:47] GET /healthz: (69.605µs) 200 [kube-probe/1.15+ 127.0.0.1:39234]
I0427 01:25:33.573022       1 scheduling_queue.go:895] About to try and schedule pod proxy-3182/proxy-service-9vqnd-5fcfp
I0427 01:25:33.573035       1 scheduler.go:454] Attempting to schedule pod: proxy-3182/proxy-service-9vqnd-5fcfp
I0427 01:25:33.574236       1 scheduler_binder.go:255] AssumePodVolumes for pod "proxy-3182/proxy-service-9vqnd-5fcfp", node "e2e-test-peterhornyack-windows-node-group-9bnh"
I0427 01:25:33.574266       1 scheduler_binder.go:265] AssumePodVolumes for pod "proxy-3182/proxy-service-9vqnd-5fcfp", node "e2e-test-peterhornyack-windows-node-group-9bnh": all PVCs bound and nothing to do
I0427 01:25:33.576531       1 factory.go:734] Attempting to bind proxy-service-9vqnd-5fcfp to e2e-test-peterhornyack-windows-node-group-9bnh
I0427 01:25:33.584285       1 scheduler.go:575] pod proxy-3182/proxy-service-9vqnd-5fcfp is bound successfully on node e2e-test-peterhornyack-windows-node-group-9bnh, 5 nodes evaluated, 2 nodes were found feasible
I0427 01:25:35.820834       1 reflector.go:384] k8s.io/client-go/informers/factory.go:133: Watch close - *v1.ReplicaSet total 4 items received
I0427 01:25:41.389302       1 wrap.go:47] GET /healthz: (70.404µs) 200 [kube-probe/1.15+ 127.0.0.1:39288]
I0427 01:25:51.389521       1 wrap.go:47] GET /healthz: (55.205µs) 200 [kube-probe/1.15+ 127.0.0.1:39412]
I0427 01:25:55.840523       1 reflector.go:384] k8s.io/client-go/informers/factory.go:133: Watch close - *v1.StatefulSet total 0 items received
I0427 01:26:00.984458       1 scheduling_queue.go:895] About to try and schedule pod deployment-3650/test-rolling-update-controller-gx525
I0427 01:26:00.984469       1 scheduler.go:454] Attempting to schedule pod: deployment-3650/test-rolling-update-controller-gx525
I0427 01:26:00.984826       1 scheduler_binder.go:255] AssumePodVolumes for pod "deployment-3650/test-rolling-update-controller-gx525", node "e2e-test-peterhornyack-windows-node-group-mdn5"
I0427 01:26:00.984836       1 scheduler_binder.go:265] AssumePodVolumes for pod "deployment-3650/test-rolling-update-controller-gx525", node "e2e-test-peterhornyack-windows-node-group-mdn5": all PVCs bound and nothing to do
I0427 01:26:00.984888       1 factory.go:734] Attempting to bind test-rolling-update-controller-gx525 to e2e-test-peterhornyack-windows-node-group-mdn5
I0427 01:26:00.994297       1 scheduler.go:575] pod deployment-3650/test-rolling-update-controller-gx525 is bound successfully on node e2e-test-peterhornyack-windows-node-group-mdn5, 5 nodes evaluated, 2 nodes were found feasible
I0427 01:26:01.389358       1 wrap.go:47] GET /healthz: (47.071µs) 200 [kube-probe/1.15+ 127.0.0.1:39448]
I0427 01:26:05.835838       1 reflector.go:384] k8s.io/client-go/informers/factory.go:133: Watch close - *v1.StorageClass total 0 items received
I0427 01:26:09.164409       1 scheduling_queue.go:895] About to try and schedule pod deployment-3650/test-rolling-update-deployment-7fcdf5fb94-69bhj
I0427 01:26:09.164421       1 scheduler.go:454] Attempting to schedule pod: deployment-3650/test-rolling-update-deployment-7fcdf5fb94-69bhj
I0427 01:26:09.165729       1 scheduler_binder.go:255] AssumePodVolumes for pod "deployment-3650/test-rolling-update-deployment-7fcdf5fb94-69bhj", node "e2e-test-peterhornyack-windows-node-group-mdn5"
I0427 01:26:09.165771       1 scheduler_binder.go:265] AssumePodVolumes for pod "deployment-3650/test-rolling-update-deployment-7fcdf5fb94-69bhj", node "e2e-test-peterhornyack-windows-node-group-mdn5": all PVCs bound and nothing to do
I0427 01:26:09.165816       1 factory.go:734] Attempting to bind test-rolling-update-deployment-7fcdf5fb94-69bhj to e2e-test-peterhornyack-windows-node-group-mdn5
I0427 01:26:09.185613       1 scheduler.go:575] pod deployment-3650/test-rolling-update-deployment-7fcdf5fb94-69bhj is bound successfully on node e2e-test-peterhornyack-windows-node-group-mdn5, 5 nodes evaluated, 2 nodes were found feasible
I0427 01:26:11.389728       1 wrap.go:47] GET /healthz: (67.567µs) 200 [kube-probe/1.15+ 127.0.0.1:39486]
I0427 01:26:21.389485       1 wrap.go:47] GET /healthz: (66.328µs) 200 [kube-probe/1.15+ 127.0.0.1:39518]
I0427 01:26:25.543493       1 scheduling_queue.go:895] About to try and schedule pod statefulset-6492/ss2-0
I0427 01:26:25.543536       1 scheduler.go:454] Attempting to schedule pod: statefulset-6492/ss2-0
I0427 01:26:25.544830       1 scheduler_binder.go:255] AssumePodVolumes for pod "statefulset-6492/ss2-0", node "e2e-test-peterhornyack-windows-node-group-mdn5"
I0427 01:26:25.544841       1 scheduler_binder.go:265] AssumePodVolumes for pod "statefulset-6492/ss2-0", node "e2e-test-peterhornyack-windows-node-group-mdn5": all PVCs bound and nothing to do
I0427 01:26:25.544877       1 factory.go:734] Attempting to bind ss2-0 to e2e-test-peterhornyack-windows-node-group-mdn5
I0427 01:26:25.557510       1 scheduler.go:575] pod statefulset-6492/ss2-0 is bound successfully on node e2e-test-peterhornyack-windows-node-group-mdn5, 5 nodes evaluated, 2 nodes were found feasible
I0427 01:26:31.389178       1 wrap.go:47] GET /healthz: (61.805µs) 200 [kube-probe/1.15+ 127.0.0.1:39550]
I0427 01:26:33.601763       1 scheduling_queue.go:895] About to try and schedule pod statefulset-6492/ss2-1
I0427 01:26:33.601774       1 scheduler.go:454] Attempting to schedule pod: statefulset-6492/ss2-1
I0427 01:26:33.603275       1 scheduler_binder.go:255] AssumePodVolumes for pod "statefulset-6492/ss2-1", node "e2e-test-peterhornyack-windows-node-group-9bnh"
I0427 01:26:33.603286       1 scheduler_binder.go:265] AssumePodVolumes for pod "statefulset-6492/ss2-1", node "e2e-test-peterhornyack-windows-node-group-9bnh": all PVCs bound and nothing to do
I0427 01:26:33.603343       1 factory.go:734] Attempting to bind ss2-1 to e2e-test-peterhornyack-windows-node-group-9bnh
I0427 01:26:33.609875       1 scheduler.go:575] pod statefulset-6492/ss2-1 is bound successfully on node e2e-test-peterhornyack-windows-node-group-9bnh, 5 nodes evaluated, 2 nodes were found feasible
I0427 01:26:40.843467       1 scheduling_queue.go:895] About to try and schedule pod statefulset-6492/ss2-2
I0427 01:26:40.843479       1 scheduler.go:454] Attempting to schedule pod: statefulset-6492/ss2-2
I0427 01:26:40.843846       1 scheduler_binder.go:255] AssumePodVolumes for pod "statefulset-6492/ss2-2", node "e2e-test-peterhornyack-windows-node-group-mdn5"
I0427 01:26:40.843856       1 scheduler_binder.go:265] AssumePodVolumes for pod "statefulset-6492/ss2-2", node "e2e-test-peterhornyack-windows-node-group-mdn5": all PVCs bound and nothing to do
I0427 01:26:40.843913       1 factory.go:734] Attempting to bind ss2-2 to e2e-test-peterhornyack-windows-node-group-mdn5
I0427 01:26:40.854964       1 scheduler.go:575] pod statefulset-6492/ss2-2 is bound successfully on node e2e-test-peterhornyack-windows-node-group-mdn5, 5 nodes evaluated, 2 nodes were found feasible
I0427 01:26:41.389304       1 wrap.go:47] GET /healthz: (63.419µs) 200 [kube-probe/1.15+ 127.0.0.1:39600]
I0427 01:26:43.821840       1 reflector.go:384] cmd/kube-scheduler/app/server.go:223: Watch close - *v1.Pod total 187 items received
I0427 01:26:51.389428       1 wrap.go:47] GET /healthz: (61.058µs) 200 [kube-probe/1.15+ 127.0.0.1:39632]
I0427 01:27:01.389403       1 wrap.go:47] GET /healthz: (44.387µs) 200 [kube-probe/1.15+ 127.0.0.1:39670]
I0427 01:27:04.337574       1 scheduling_queue.go:895] About to try and schedule pod statefulset-6492/ss2-2
I0427 01:27:04.337584       1 scheduler.go:454] Attempting to schedule pod: statefulset-6492/ss2-2
I0427 01:27:04.337913       1 scheduler_binder.go:255] AssumePodVolumes for pod "statefulset-6492/ss2-2", node "e2e-test-peterhornyack-windows-node-group-9bnh"
I0427 01:27:04.337923       1 scheduler_binder.go:265] AssumePodVolumes for pod "statefulset-6492/ss2-2", node "e2e-test-peterhornyack-windows-node-group-9bnh": all PVCs bound and nothing to do
I0427 01:27:04.337983       1 factory.go:734] Attempting to bind ss2-2 to e2e-test-peterhornyack-windows-node-group-9bnh
I0427 01:27:04.353520       1 scheduler.go:575] pod statefulset-6492/ss2-2 is bound successfully on node e2e-test-peterhornyack-windows-node-group-9bnh, 5 nodes evaluated, 2 nodes were found feasible
I0427 01:27:06.255865       1 scheduling_queue.go:895] About to try and schedule pod statefulset-6492/ss2-0
I0427 01:27:06.255876       1 scheduler.go:454] Attempting to schedule pod: statefulset-6492/ss2-0
I0427 01:27:06.256899       1 scheduler_binder.go:255] AssumePodVolumes for pod "statefulset-6492/ss2-0", node "e2e-test-peterhornyack-windows-node-group-mdn5"
I0427 01:27:06.256910       1 scheduler_binder.go:265] AssumePodVolumes for pod "statefulset-6492/ss2-0", node "e2e-test-peterhornyack-windows-node-group-mdn5": all PVCs bound and nothing to do
I0427 01:27:06.256970       1 factory.go:734] Attempting to bind ss2-0 to e2e-test-peterhornyack-windows-node-group-mdn5
I0427 01:27:06.266055       1 scheduler.go:575] pod statefulset-6492/ss2-0 is bound successfully on node e2e-test-peterhornyack-windows-node-group-mdn5, 5 nodes evaluated, 2 nodes were found feasible
I0427 01:27:11.389653       1 wrap.go:47] GET /healthz: (64.334µs) 200 [kube-probe/1.15+ 127.0.0.1:39706]
I0427 01:27:14.268330       1 scheduling_queue.go:895] About to try and schedule pod statefulset-6492/ss2-2
I0427 01:27:14.268340       1 scheduler.go:454] Attempting to schedule pod: statefulset-6492/ss2-2
I0427 01:27:14.269628       1 scheduler_binder.go:255] AssumePodVolumes for pod "statefulset-6492/ss2-2", node "e2e-test-peterhornyack-windows-node-group-9bnh"
I0427 01:27:14.269639       1 scheduler_binder.go:265] AssumePodVolumes for pod "statefulset-6492/ss2-2", node "e2e-test-peterhornyack-windows-node-group-9bnh": all PVCs bound and nothing to do
I0427 01:27:14.269701       1 factory.go:734] Attempting to bind ss2-2 to e2e-test-peterhornyack-windows-node-group-9bnh
I0427 01:27:14.274140       1 cache.go:643] Couldn't expire cache for pod statefulset-6492/ss2-2. Binding is still in progress.
I0427 01:27:14.278689       1 scheduler.go:575] pod statefulset-6492/ss2-2 is bound successfully on node e2e-test-peterhornyack-windows-node-group-9bnh, 5 nodes evaluated, 2 nodes were found feasible
I0427 01:27:21.389379       1 wrap.go:47] GET /healthz: (63.137µs) 200 [kube-probe/1.15+ 127.0.0.1:39738]
I0427 01:27:26.781601       1 reflector.go:384] k8s.io/client-go/informers/factory.go:133: Watch close - *v1.Service total 3 items received
I0427 01:27:30.806210       1 reflector.go:384] k8s.io/client-go/informers/factory.go:133: Watch close - *v1.ReplicationController total 18 items received
I0427 01:27:31.389445       1 wrap.go:47] GET /healthz: (48.412µs) 200 [kube-probe/1.15+ 127.0.0.1:39772]
I0427 01:27:34.676460       1 scheduling_queue.go:895] About to try and schedule pod statefulset-6492/ss2-1
I0427 01:27:34.676471       1 scheduler.go:454] Attempting to schedule pod: statefulset-6492/ss2-1
I0427 01:27:34.676843       1 scheduler_binder.go:255] AssumePodVolumes for pod "statefulset-6492/ss2-1", node "e2e-test-peterhornyack-windows-node-group-9bnh"
I0427 01:27:34.676853       1 scheduler_binder.go:265] AssumePodVolumes for pod "statefulset-6492/ss2-1", node "e2e-test-peterhornyack-windows-node-group-9bnh": all PVCs bound and nothing to do
I0427 01:27:34.676890       1 factory.go:734] Attempting to bind ss2-1 to e2e-test-peterhornyack-windows-node-group-9bnh
I0427 01:27:34.693858       1 scheduler.go:575] pod statefulset-6492/ss2-1 is bound successfully on node e2e-test-peterhornyack-windows-node-group-9bnh, 5 nodes evaluated, 2 nodes were found feasible
I0427 01:27:41.389325       1 wrap.go:47] GET /healthz: (67.662µs) 200 [kube-probe/1.15+ 127.0.0.1:39822]
I0427 01:27:51.389026       1 wrap.go:47] GET /healthz: (46.522µs) 200 [kube-probe/1.15+ 127.0.0.1:39854]
I0427 01:28:01.389691       1 wrap.go:47] GET /healthz: (75.917µs) 200 [kube-probe/1.15+ 127.0.0.1:39890]
I0427 01:28:11.389504       1 wrap.go:47] GET /healthz: (63.933µs) 200 [kube-probe/1.15+ 127.0.0.1:39926]
I0427 01:28:13.326822       1 scheduling_queue.go:895] About to try and schedule pod statefulset-6492/ss2-0
I0427 01:28:13.326832       1 scheduler.go:454] Attempting to schedule pod: statefulset-6492/ss2-0
I0427 01:28:13.327208       1 scheduler_binder.go:255] AssumePodVolumes for pod "statefulset-6492/ss2-0", node "e2e-test-peterhornyack-windows-node-group-9bnh"
I0427 01:28:13.327218       1 scheduler_binder.go:265] AssumePodVolumes for pod "statefulset-6492/ss2-0", node "e2e-test-peterhornyack-windows-node-group-9bnh": all PVCs bound and nothing to do
I0427 01:28:13.328154       1 factory.go:734] Attempting to bind ss2-0 to e2e-test-peterhornyack-windows-node-group-9bnh
I0427 01:28:13.338600       1 scheduler.go:575] pod statefulset-6492/ss2-0 is bound successfully on node e2e-test-peterhornyack-windows-node-group-9bnh, 5 nodes evaluated, 2 nodes were found feasible
I0427 01:28:21.389330       1 wrap.go:47] GET /healthz: (49.758µs) 200 [kube-probe/1.15+ 127.0.0.1:39960]
I0427 01:28:31.389602       1 wrap.go:47] GET /healthz: (72.648µs) 200 [kube-probe/1.15+ 127.0.0.1:39992]
I0427 01:28:41.389436       1 wrap.go:47] GET /healthz: (77.163µs) 200 [kube-probe/1.15+ 127.0.0.1:40042]
I0427 01:28:51.389270       1 wrap.go:47] GET /healthz: (47.456µs) 200 [kube-probe/1.15+ 127.0.0.1:40074]
I0427 01:29:01.389849       1 wrap.go:47] GET /healthz: (77.604µs) 200 [kube-probe/1.15+ 127.0.0.1:40112]
I0427 01:29:05.326139       1 scheduling_queue.go:895] About to try and schedule pod downward-api-1679/annotationupdateae6255aa-fb56-440a-b15b-531af7086642
I0427 01:29:05.326153       1 scheduler.go:454] Attempting to schedule pod: downward-api-1679/annotationupdateae6255aa-fb56-440a-b15b-531af7086642
I0427 01:29:05.326491       1 scheduler_binder.go:255] AssumePodVolumes for pod "downward-api-1679/annotationupdateae6255aa-fb56-440a-b15b-531af7086642", node "e2e-test-peterhornyack-windows-node-group-mdn5"
I0427 01:29:05.326519       1 scheduler_binder.go:265] AssumePodVolumes for pod "downward-api-1679/annotationupdateae6255aa-fb56-440a-b15b-531af7086642", node "e2e-test-peterhornyack-windows-node-group-mdn5": all PVCs bound and nothing to do
I0427 01:29:05.326564       1 factory.go:734] Attempting to bind annotationupdateae6255aa-fb56-440a-b15b-531af7086642 to e2e-test-peterhornyack-windows-node-group-mdn5
I0427 01:29:05.331764       1 scheduler.go:575] pod downward-api-1679/annotationupdateae6255aa-fb56-440a-b15b-531af7086642 is bound successfully on node e2e-test-peterhornyack-windows-node-group-mdn5, 5 nodes evaluated, 2 nodes were found feasible
I0427 01:29:11.389440       1 wrap.go:47] GET /healthz: (78.07µs) 200 [kube-probe/1.15+ 127.0.0.1:40148]
I0427 01:29:19.813641       1 reflector.go:384] k8s.io/client-go/informers/factory.go:133: Watch close - *v1.PersistentVolume total 0 items received
I0427 01:29:21.390078       1 wrap.go:47] GET /healthz: (65.231µs) 200 [kube-probe/1.15+ 127.0.0.1:40180]
I0427 01:29:31.389379       1 wrap.go:47] GET /healthz: (65.282µs) 200 [kube-probe/1.15+ 127.0.0.1:40212]
I0427 01:29:40.167837       1 scheduling_queue.go:895] About to try and schedule pod windows-volumes-4504/pod-ec1a5091-6886-4c26-9994-caa8cedecfb9
I0427 01:29:40.167851       1 scheduler.go:454] Attempting to schedule pod: windows-volumes-4504/pod-ec1a5091-6886-4c26-9994-caa8cedecfb9
I0427 01:29:40.168814       1 scheduler_binder.go:255] AssumePodVolumes for pod "windows-volumes-4504/pod-ec1a5091-6886-4c26-9994-caa8cedecfb9", node "e2e-test-peterhornyack-windows-node-group-9bnh"
I0427 01:29:40.168843       1 scheduler_binder.go:265] AssumePodVolumes for pod "windows-volumes-4504/pod-ec1a5091-6886-4c26-9994-caa8cedecfb9", node "e2e-test-peterhornyack-windows-node-group-9bnh": all PVCs bound and nothing to do
I0427 01:29:40.168893       1 factory.go:734] Attempting to bind pod-ec1a5091-6886-4c26-9994-caa8cedecfb9 to e2e-test-peterhornyack-windows-node-group-9bnh
I0427 01:29:40.172692       1 scheduler.go:575] pod windows-volumes-4504/pod-ec1a5091-6886-4c26-9994-caa8cedecfb9 is bound successfully on node e2e-test-peterhornyack-windows-node-group-9bnh, 5 nodes evaluated, 2 nodes were found feasible
I0427 01:29:41.389383       1 wrap.go:47] GET /healthz: (47.148µs) 200 [kube-probe/1.15+ 127.0.0.1:40264]
I0427 01:29:48.715635       1 scheduling_queue.go:895] About to try and schedule pod windows-volumes-4504/pod-6bf266ad-5eca-4879-b6ed-b139f9efd90b
I0427 01:29:48.715649       1 scheduler.go:454] Attempting to schedule pod: windows-volumes-4504/pod-6bf266ad-5eca-4879-b6ed-b139f9efd90b
I0427 01:29:48.715918       1 scheduler_binder.go:255] AssumePodVolumes for pod "windows-volumes-4504/pod-6bf266ad-5eca-4879-b6ed-b139f9efd90b", node "e2e-test-peterhornyack-windows-node-group-mdn5"
I0427 01:29:48.715930       1 scheduler_binder.go:265] AssumePodVolumes for pod "windows-volumes-4504/pod-6bf266ad-5eca-4879-b6ed-b139f9efd90b", node "e2e-test-peterhornyack-windows-node-group-mdn5": all PVCs bound and nothing to do
I0427 01:29:48.715966       1 factory.go:734] Attempting to bind pod-6bf266ad-5eca-4879-b6ed-b139f9efd90b to e2e-test-peterhornyack-windows-node-group-mdn5
I0427 01:29:48.723573       1 scheduler.go:575] pod windows-volumes-4504/pod-6bf266ad-5eca-4879-b6ed-b139f9efd90b is bound successfully on node e2e-test-peterhornyack-windows-node-group-mdn5, 5 nodes evaluated, 2 nodes were found feasible
I0427 01:29:51.390150       1 wrap.go:47] GET /healthz: (55.697µs) 200 [kube-probe/1.15+ 127.0.0.1:40298]
I0427 01:30:01.389897       1 wrap.go:47] GET /healthz: (79.352µs) 200 [kube-probe/1.15+ 127.0.0.1:40340]
I0427 01:30:11.389584       1 wrap.go:47] GET /healthz: (70.433µs) 200 [kube-probe/1.15+ 127.0.0.1:40376]
I0427 01:30:14.803370       1 reflector.go:384] k8s.io/client-go/informers/factory.go:133: Watch close - *v1beta1.PodDisruptionBudget total 0 items received
I0427 01:30:21.389733       1 wrap.go:47] GET /healthz: (80.444µs) 200 [kube-probe/1.15+ 127.0.0.1:40410]
I0427 01:30:24.162045       1 scheduling_queue.go:895] About to try and schedule pod configmap-6346/pod-configmaps-988f53e2-ecb2-44dc-bfdd-6a06443b60c6
I0427 01:30:24.162058       1 scheduler.go:454] Attempting to schedule pod: configmap-6346/pod-configmaps-988f53e2-ecb2-44dc-bfdd-6a06443b60c6
I0427 01:30:24.164173       1 scheduler_binder.go:255] AssumePodVolumes for pod "configmap-6346/pod-configmaps-988f53e2-ecb2-44dc-bfdd-6a06443b60c6", node "e2e-test-peterhornyack-windows-node-group-mdn5"
I0427 01:30:24.164187       1 scheduler_binder.go:265] AssumePodVolumes for pod "configmap-6346/pod-configmaps-988f53e2-ecb2-44dc-bfdd-6a06443b60c6", node "e2e-test-peterhornyack-windows-node-group-mdn5": all PVCs bound and nothing to do
I0427 01:30:24.164250       1 factory.go:734] Attempting to bind pod-configmaps-988f53e2-ecb2-44dc-bfdd-6a06443b60c6 to e2e-test-peterhornyack-windows-node-group-mdn5
I0427 01:30:24.170270       1 scheduler.go:575] pod configmap-6346/pod-configmaps-988f53e2-ecb2-44dc-bfdd-6a06443b60c6 is bound successfully on node e2e-test-peterhornyack-windows-node-group-mdn5, 5 nodes evaluated, 2 nodes were found feasible
I0427 01:30:31.389514       1 wrap.go:47] GET /healthz: (77.622µs) 200 [kube-probe/1.15+ 127.0.0.1:40442]
I0427 01:30:41.389470       1 wrap.go:47] GET /healthz: (70.912µs) 200 [kube-probe/1.15+ 127.0.0.1:40492]
I0427 01:30:51.389620       1 wrap.go:47] GET /healthz: (71.973µs) 200 [kube-probe/1.15+ 127.0.0.1:40524]
I0427 01:31:01.389298       1 wrap.go:47] GET /healthz: (49.25µs) 200 [kube-probe/1.15+ 127.0.0.1:40562]
I0427 01:31:11.390472       1 wrap.go:47] GET /healthz: (69.675µs) 200 [kube-probe/1.15+ 127.0.0.1:40598]
I0427 01:31:16.842423       1 reflector.go:384] k8s.io/client-go/informers/factory.go:133: Watch close - *v1.StatefulSet total 35 items received
I0427 01:31:21.390437       1 wrap.go:47] GET /healthz: (75.527µs) 200 [kube-probe/1.15+ 127.0.0.1:40630]
I0427 01:31:31.389815       1 wrap.go:47] GET /healthz: (115.337µs) 200 [kube-probe/1.15+ 127.0.0.1:40662]
I0427 01:31:41.390345       1 wrap.go:47] GET /healthz: (73.661µs) 200 [kube-probe/1.15+ 127.0.0.1:40714]
I0427 01:31:47.832260       1 reflector.go:384] k8s.io/client-go/informers/factory.go:133: Watch close - *v1.PersistentVolumeClaim total 0 items received
I0427 01:31:51.389625       1 wrap.go:47] GET /healthz: (72.101µs) 200 [kube-probe/1.15+ 127.0.0.1:40746]
I0427 01:31:56.818564       1 reflector.go:384] k8s.io/client-go/informers/factory.go:133: Watch close - *v1.Node total 62 items received
I0427 01:32:01.389580       1 wrap.go:47] GET /healthz: (57.221µs) 200 [kube-probe/1.15+ 127.0.0.1:40782]
I0427 01:32:06.253660       1 scheduling_queue.go:895] About to try and schedule pod dns-3080/dns-test-f71f2757-b46a-4576-b74b-d240d9269d8f
I0427 01:32:06.253674       1 scheduler.go:454] Attempting to schedule pod: dns-3080/dns-test-f71f2757-b46a-4576-b74b-d240d9269d8f
I0427 01:32:06.254186       1 scheduler_binder.go:255] AssumePodVolumes for pod "dns-3080/dns-test-f71f2757-b46a-4576-b74b-d240d9269d8f", node "e2e-test-peterhornyack-windows-node-group-9bnh"
I0427 01:32:06.254200       1 scheduler_binder.go:265] AssumePodVolumes for pod "dns-3080/dns-test-f71f2757-b46a-4576-b74b-d240d9269d8f", node "e2e-test-peterhornyack-windows-node-group-9bnh": all PVCs bound and nothing to do
I0427 01:32:06.255750       1 factory.go:734] Attempting to bind dns-test-f71f2757-b46a-4576-b74b-d240d9269d8f to e2e-test-peterhornyack-windows-node-group-9bnh
I0427 01:32:06.260580       1 scheduler.go:575] pod dns-3080/dns-test-f71f2757-b46a-4576-b74b-d240d9269d8f is bound successfully on node e2e-test-peterhornyack-windows-node-group-9bnh, 5 nodes evaluated, 2 nodes were found feasible
I0427 01:32:08.823704       1 reflector.go:384] cmd/kube-scheduler/app/server.go:223: Watch close - *v1.Pod total 95 items received
I0427 01:32:11.389627       1 wrap.go:47] GET /healthz: (71.245µs) 200 [kube-probe/1.15+ 127.0.0.1:40818]
I0427 01:32:21.389601       1 wrap.go:47] GET /healthz: (55.833µs) 200 [kube-probe/1.15+ 127.0.0.1:40854]
I0427 01:32:31.389309       1 wrap.go:47] GET /healthz: (55.122µs) 200 [kube-probe/1.15+ 127.0.0.1:40886]
I0427 01:32:34.743508       1 scheduling_queue.go:895] About to try and schedule pod pod-network-test-6515/netserver-0
I0427 01:32:34.743518       1 scheduler.go:454] Attempting to schedule pod: pod-network-test-6515/netserver-0
I0427 01:32:34.744229       1 scheduler_binder.go:255] AssumePodVolumes for pod "pod-network-test-6515/netserver-0", node "e2e-test-peterhornyack-windows-node-group-mdn5"
I0427 01:32:34.744240       1 scheduler_binder.go:265] AssumePodVolumes for pod "pod-network-test-6515/netserver-0", node "e2e-test-peterhornyack-windows-node-group-mdn5": all PVCs bound and nothing to do
I0427 01:32:34.744300       1 factory.go:734] Attempting to bind netserver-0 to e2e-test-peterhornyack-windows-node-group-mdn5
I0427 01:32:34.750982       1 scheduler.go:575] pod pod-network-test-6515/netserver-0 is bound successfully on node e2e-test-peterhornyack-windows-node-group-mdn5, 5 nodes evaluated, 1 nodes were found feasible
I0427 01:32:34.785829       1 scheduling_queue.go:895] About to try and schedule pod pod-network-test-6515/netserver-1
I0427 01:32:34.785839       1 scheduler.go:454] Attempting to schedule pod: pod-network-test-6515/netserver-1
I0427 01:32:34.786029       1 scheduler_binder.go:255] AssumePodVolumes for pod "pod-network-test-6515/netserver-1", node "e2e-test-peterhornyack-windows-node-group-9bnh"
I0427 01:32:34.786039       1 scheduler_binder.go:265] AssumePodVolumes for pod "pod-network-test-6515/netserver-1", node "e2e-test-peterhornyack-windows-node-group-9bnh": all PVCs bound and nothing to do
I0427 01:32:34.786085       1 factory.go:734] Attempting to bind netserver-1 to e2e-test-peterhornyack-windows-node-group-9bnh
I0427 01:32:34.793015       1 scheduler.go:575] pod pod-network-test-6515/netserver-1 is bound successfully on node e2e-test-peterhornyack-windows-node-group-9bnh, 5 nodes evaluated, 1 nodes were found feasible
I0427 01:32:41.389328       1 wrap.go:47] GET /healthz: (64.768µs) 200 [kube-probe/1.15+ 127.0.0.1:40936]
I0427 01:32:51.389556       1 wrap.go:47] GET /healthz: (70.678µs) 200 [kube-probe/1.15+ 127.0.0.1:40968]
I0427 01:32:59.039136       1 scheduling_queue.go:895] About to try and schedule pod pod-network-test-6515/test-container-pod
I0427 01:32:59.039147       1 scheduler.go:454] Attempting to schedule pod: pod-network-test-6515/test-container-pod
I0427 01:32:59.039430       1 scheduler_binder.go:255] AssumePodVolumes for pod "pod-network-test-6515/test-container-pod", node "e2e-test-peterhornyack-windows-node-group-9bnh"
I0427 01:32:59.039441       1 scheduler_binder.go:265] AssumePodVolumes for pod "pod-network-test-6515/test-container-pod", node "e2e-test-peterhornyack-windows-node-group-9bnh": all PVCs bound and nothing to do
I0427 01:32:59.039479       1 factory.go:734] Attempting to bind test-container-pod to e2e-test-peterhornyack-windows-node-group-9bnh
I0427 01:32:59.043385       1 scheduler.go:575] pod pod-network-test-6515/test-container-pod is bound successfully on node e2e-test-peterhornyack-windows-node-group-9bnh, 5 nodes evaluated, 2 nodes were found feasible
I0427 01:32:59.081359       1 scheduling_queue.go:895] About to try and schedule pod pod-network-test-6515/host-test-container-pod
I0427 01:32:59.081371       1 scheduler.go:454] Attempting to schedule pod: pod-network-test-6515/host-test-container-pod
I0427 01:32:59.081558       1 scheduler_binder.go:255] AssumePodVolumes for pod "pod-network-test-6515/host-test-container-pod", node "e2e-test-peterhornyack-windows-node-group-9bnh"
I0427 01:32:59.081568       1 scheduler_binder.go:265] AssumePodVolumes for pod "pod-network-test-6515/host-test-container-pod", node "e2e-test-peterhornyack-windows-node-group-9bnh": all PVCs bound and nothing to do
I0427 01:32:59.081599       1 factory.go:734] Attempting to bind host-test-container-pod to e2e-test-peterhornyack-windows-node-group-9bnh
I0427 01:32:59.090537       1 scheduler.go:575] pod pod-network-test-6515/host-test-container-pod is bound successfully on node e2e-test-peterhornyack-windows-node-group-9bnh, 5 nodes evaluated, 2 nodes were found feasible
I0427 01:33:01.389311       1 wrap.go:47] GET /healthz: (63.851µs) 200 [kube-probe/1.15+ 127.0.0.1:41006]
I0427 01:33:11.390814       1 wrap.go:47] GET /healthz: (66.948µs) 200 [kube-probe/1.15+ 127.0.0.1:41044]
I0427 01:33:21.389363       1 wrap.go:47] GET /healthz: (69.016µs) 200 [kube-probe/1.15+ 127.0.0.1:41078]
I0427 01:33:31.389480       1 wrap.go:47] GET /healthz: (70.052µs) 200 [kube-probe/1.15+ 127.0.0.1:41110]
I0427 01:33:38.050233       1 scheduling_queue.go:895] About to try and schedule pod gc-9505/simpletest-rc-to-be-deleted-75zz5
I0427 01:33:38.050264       1 scheduler.go:454] Attempting to schedule pod: gc-9505/simpletest-rc-to-be-deleted-75zz5
I0427 01:33:38.050721       1 scheduler_binder.go:255] AssumePodVolumes for pod "gc-9505/simpletest-rc-to-be-deleted-75zz5", node "e2e-test-peterhornyack-windows-node-group-9bnh"
I0427 01:33:38.050733       1 scheduler_binder.go:265] AssumePodVolumes for pod "gc-9505/simpletest-rc-to-be-deleted-75zz5", node "e2e-test-peterhornyack-windows-node-group-9bnh": all PVCs bound and nothing to do
I0427 01:33:38.050802       1 factory.go:734] Attempting to bind simpletest-rc-to-be-deleted-75zz5 to e2e-test-peterhornyack-windows-node-group-9bnh
I0427 01:33:38.061105       1 scheduler.go:575] pod gc-9505/simpletest-rc-to-be-deleted-75zz5 is bound successfully on node e2e-test-peterhornyack-windows-node-group-9bnh, 5 nodes evaluated, 2 nodes were found feasible
I0427 01:33:38.063343       1 scheduling_queue.go:895] About to try and schedule pod gc-9505/simpletest-rc-to-be-deleted-5g6wh
I0427 01:33:38.063351       1 scheduler.go:454] Attempting to schedule pod: gc-9505/simpletest-rc-to-be-deleted-5g6wh
I0427 01:33:38.063584       1 scheduler_binder.go:255] AssumePodVolumes for pod "gc-9505/simpletest-rc-to-be-deleted-5g6wh", node "e2e-test-peterhornyack-windows-node-group-mdn5"
I0427 01:33:38.063594       1 scheduler_binder.go:265] AssumePodVolumes for pod "gc-9505/simpletest-rc-to-be-deleted-5g6wh", node "e2e-test-peterhornyack-windows-node-group-mdn5": all PVCs bound and nothing to do
I0427 01:33:38.063620       1 factory.go:734] Attempting to bind simpletest-rc-to-be-deleted-5g6wh to e2e-test-peterhornyack-windows-node-group-mdn5
I0427 01:33:38.066852       1 scheduling_queue.go:895] About to try and schedule pod gc-9505/simpletest-rc-to-be-deleted-wlx8m
I0427 01:33:38.066859       1 scheduler.go:454] Attempting to schedule pod: gc-9505/simpletest-rc-to-be-deleted-wlx8m
I0427 01:33:38.067010       1 scheduler_binder.go:255] AssumePodVolumes for pod "gc-9505/simpletest-rc-to-be-deleted-wlx8m", node "e2e-test-peterhornyack-windows-node-group-9bnh"
I0427 01:33:38.067019       1 scheduler_binder.go:265] AssumePodVolumes for pod "gc-9505/simpletest-rc-to-be-deleted-wlx8m", node "e2e-test-peterhornyack-windows-node-group-9bnh": all PVCs bound and nothing to do
I0427 01:33:38.067048       1 factory.go:734] Attempting to bind simpletest-rc-to-be-deleted-wlx8m to e2e-test-peterhornyack-windows-node-group-9bnh
I0427 01:33:38.076766       1 scheduler.go:575] pod gc-9505/simpletest-rc-to-be-deleted-5g6wh is bound successfully on node e2e-test-peterhornyack-windows-node-group-mdn5, 5 nodes evaluated, 2 nodes were found feasible
I0427 01:33:38.089507       1 scheduler.go:575] pod gc-9505/simpletest-rc-to-be-deleted-wlx8m is bound successfully on node e2e-test-peterhornyack-windows-node-group-9bnh, 5 nodes evaluated, 2 nodes were found feasible
I0427 01:33:38.089830       1 scheduling_queue.go:895] About to try and schedule pod gc-9505/simpletest-rc-to-be-deleted-xvmkk
I0427 01:33:38.089837       1 scheduler.go:454] Attempting to schedule pod: gc-9505/simpletest-rc-to-be-deleted-xvmkk
I0427 01:33:38.092397       1 scheduler_binder.go:255] AssumePodVolumes for pod "gc-9505/simpletest-rc-to-be-deleted-xvmkk", node "e2e-test-peterhornyack-windows-node-group-mdn5"
I0427 01:33:38.092409       1 scheduler_binder.go:265] AssumePodVolumes for pod "gc-9505/simpletest-rc-to-be-deleted-xvmkk", node "e2e-test-peterhornyack-windows-node-group-mdn5": all PVCs bound and nothing to do
I0427 01:33:38.092440       1 factory.go:734] Attempting to bind simpletest-rc-to-be-deleted-xvmkk to e2e-test-peterhornyack-windows-node-group-mdn5
I0427 01:33:38.095645       1 scheduling_queue.go:895] About to try and schedule pod gc-9505/simpletest-rc-to-be-deleted-m5r8r
I0427 01:33:38.095651       1 scheduler.go:454] Attempting to schedule pod: gc-9505/simpletest-rc-to-be-deleted-m5r8r
I0427 01:33:38.095817       1 scheduler_binder.go:255] AssumePodVolumes for pod "gc-9505/simpletest-rc-to-be-deleted-m5r8r", node "e2e-test-peterhornyack-windows-node-group-9bnh"
I0427 01:33:38.095826       1 scheduler_binder.go:265] AssumePodVolumes for pod "gc-9505/simpletest-rc-to-be-deleted-m5r8r", node "e2e-test-peterhornyack-windows-node-group-9bnh": all PVCs bound and nothing to do
I0427 01:33:38.095844       1 factory.go:734] Attempting to bind simpletest-rc-to-be-deleted-m5r8r to e2e-test-peterhornyack-windows-node-group-9bnh
I0427 01:33:38.097232       1 scheduling_queue.go:895] About to try and schedule pod gc-9505/simpletest-rc-to-be-deleted-96fcv
I0427 01:33:38.097239       1 scheduler.go:454] Attempting to schedule pod: gc-9505/simpletest-rc-to-be-deleted-96fcv
I0427 01:33:38.097399       1 scheduler_binder.go:255] AssumePodVolumes for pod "gc-9505/simpletest-rc-to-be-deleted-96fcv", node "e2e-test-peterhornyack-windows-node-group-mdn5"
I0427 01:33:38.097408       1 scheduler_binder.go:265] AssumePodVolumes for pod "gc-9505/simpletest-rc-to-be-deleted-96fcv", node "e2e-test-peterhornyack-windows-node-group-mdn5": all PVCs bound and nothing to do
I0427 01:33:38.097426       1 factory.go:734] Attempting to bind simpletest-rc-to-be-deleted-96fcv to e2e-test-peterhornyack-windows-node-group-mdn5
I0427 01:33:38.099944       1 scheduling_queue.go:895] About to try and schedule pod gc-9505/simpletest-rc-to-be-deleted-4wpnk
I0427 01:33:38.099950       1 scheduler.go:454] Attempting to schedule pod: gc-9505/simpletest-rc-to-be-deleted-4wpnk
I0427 01:33:38.100102       1 scheduler_binder.go:255] AssumePodVolumes for pod "gc-9505/simpletest-rc-to-be-deleted-4wpnk", node "e2e-test-peterhornyack-windows-node-group-9bnh"
I0427 01:33:38.100111       1 scheduler_binder.go:265] AssumePodVolumes for pod "gc-9505/simpletest-rc-to-be-deleted-4wpnk", node "e2e-test-peterhornyack-windows-node-group-9bnh": all PVCs bound and nothing to do
I0427 01:33:38.100130       1 factory.go:734] Attempting to bind simpletest-rc-to-be-deleted-4wpnk to e2e-test-peterhornyack-windows-node-group-9bnh
I0427 01:33:38.124738       1 scheduling_queue.go:895] About to try and schedule pod gc-9505/simpletest-rc-to-be-deleted-sfvvm
I0427 01:33:38.124750       1 scheduler.go:454] Attempting to schedule pod: gc-9505/simpletest-rc-to-be-deleted-sfvvm
I0427 01:33:38.125121       1 scheduler_binder.go:255] AssumePodVolumes for pod "gc-9505/simpletest-rc-to-be-deleted-sfvvm", node "e2e-test-peterhornyack-windows-node-group-mdn5"
I0427 01:33:38.125132       1 scheduler_binder.go:265] AssumePodVolumes for pod "gc-9505/simpletest-rc-to-be-deleted-sfvvm", node "e2e-test-peterhornyack-windows-node-group-mdn5": all PVCs bound and nothing to do
I0427 01:33:38.128373       1 factory.go:734] Attempting to bind simpletest-rc-to-be-deleted-sfvvm to e2e-test-peterhornyack-windows-node-group-mdn5
I0427 01:33:38.128649       1 scheduling_queue.go:895] About to try and schedule pod gc-9505/simpletest-rc-to-be-deleted-x2jch
I0427 01:33:38.128655       1 scheduler.go:454] Attempting to schedule pod: gc-9505/simpletest-rc-to-be-deleted-x2jch
I0427 01:33:38.128864       1 scheduler_binder.go:255] AssumePodVolumes for pod "gc-9505/simpletest-rc-to-be-deleted-x2jch", node "e2e-test-peterhornyack-windows-node-group-9bnh"
I0427 01:33:38.128873       1 scheduler_binder.go:265] AssumePodVolumes for pod "gc-9505/simpletest-rc-to-be-deleted-x2jch", node "e2e-test-peterhornyack-windows-node-group-9bnh": all PVCs bound and nothing to do
I0427 01:33:38.128910       1 factory.go:734] Attempting to bind simpletest-rc-to-be-deleted-x2jch to e2e-test-peterhornyack-windows-node-group-9bnh
I0427 01:33:38.132846       1 scheduler.go:575] pod gc-9505/simpletest-rc-to-be-deleted-4wpnk is bound successfully on node e2e-test-peterhornyack-windows-node-group-9bnh, 5 nodes evaluated, 2 nodes were found feasible
I0427 01:33:38.132924       1 scheduler.go:575] pod gc-9505/simpletest-rc-to-be-deleted-xvmkk is bound successfully on node e2e-test-peterhornyack-windows-node-group-mdn5, 5 nodes evaluated, 2 nodes were found feasible
I0427 01:33:38.132994       1 scheduler.go:575] pod gc-9505/simpletest-rc-to-be-deleted-m5r8r is bound successfully on node e2e-test-peterhornyack-windows-node-group-9bnh, 5 nodes evaluated, 2 nodes were found feasible
I0427 01:33:38.133039       1 scheduler.go:575] pod gc-9505/simpletest-rc-to-be-deleted-96fcv is bound successfully on node e2e-test-peterhornyack-windows-node-group-mdn5, 5 nodes evaluated, 2 nodes were found feasible
I0427 01:33:38.139106       1 scheduling_queue.go:895] About to try and schedule pod gc-9505/simpletest-rc-to-be-deleted-xnmg4
I0427 01:33:38.139113       1 scheduler.go:454] Attempting to schedule pod: gc-9505/simpletest-rc-to-be-deleted-xnmg4
I0427 01:33:38.139303       1 scheduler_binder.go:255] AssumePodVolumes for pod "gc-9505/simpletest-rc-to-be-deleted-xnmg4", node "e2e-test-peterhornyack-windows-node-group-mdn5"
I0427 01:33:38.139313       1 scheduler_binder.go:265] AssumePodVolumes for pod "gc-9505/simpletest-rc-to-be-deleted-xnmg4", node "e2e-test-peterhornyack-windows-node-group-mdn5": all PVCs bound and nothing to do
I0427 01:33:38.139333       1 factory.go:734] Attempting to bind simpletest-rc-to-be-deleted-xnmg4 to e2e-test-peterhornyack-windows-node-group-mdn5
I0427 01:33:38.150572       1 scheduler.go:575] pod gc-9505/simpletest-rc-to-be-deleted-sfvvm is bound successfully on node e2e-test-peterhornyack-windows-node-group-mdn5, 5 nodes evaluated, 2 nodes were found feasible
I0427 01:33:38.159413       1 scheduler.go:575] pod gc-9505/simpletest-rc-to-be-deleted-x2jch is bound successfully on node e2e-test-peterhornyack-windows-node-group-9bnh, 5 nodes evaluated, 2 nodes were found feasible
I0427 01:33:38.159476       1 scheduler.go:575] pod gc-9505/simpletest-rc-to-be-deleted-xnmg4 is bound successfully on node e2e-test-peterhornyack-windows-node-group-mdn5, 5 nodes evaluated, 2 nodes were found feasible
I0427 01:33:41.390589       1 wrap.go:47] GET /healthz: (77.313µs) 200 [kube-probe/1.15+ 127.0.0.1:41162]
I0427 01:33:48.783327       1 reflector.go:384] k8s.io/client-go/informers/factory.go:133: Watch close - *v1.Service total 1 items received
I0427 01:33:49.822810       1 reflector.go:384] k8s.io/client-go/informers/factory.go:133: Watch close - *v1.ReplicaSet total 14 items received
I0427 01:33:51.389564       1 wrap.go:47] GET /healthz: (76.567µs) 200 [kube-probe/1.15+ 127.0.0.1:41194]
I0427 01:33:56.628583       1 scheduling_queue.go:895] About to try and schedule pod container-probe-5280/liveness-http
I0427 01:33:56.628596       1 scheduler.go:454] Attempting to schedule pod: container-probe-5280/liveness-http
I0427 01:33:56.630461       1 scheduler_binder.go:255] AssumePodVolumes for pod "container-probe-5280/liveness-http", node "e2e-test-peterhornyack-windows-node-group-9bnh"
I0427 01:33:56.630473       1 scheduler_binder.go:265] AssumePodVolumes for pod "container-probe-5280/liveness-http", node "e2e-test-peterhornyack-windows-node-group-9bnh": all PVCs bound and nothing to do
I0427 01:33:56.630531       1 factory.go:734] Attempting to bind liveness-http to e2e-test-peterhornyack-windows-node-group-9bnh
I0427 01:33:56.635389       1 scheduler.go:575] pod container-probe-5280/liveness-http is bound successfully on node e2e-test-peterhornyack-windows-node-group-9bnh, 5 nodes evaluated, 2 nodes were found feasible
I0427 01:34:01.389400       1 wrap.go:47] GET /healthz: (61.444µs) 200 [kube-probe/1.15+ 127.0.0.1:41232]
I0427 01:34:11.389764       1 wrap.go:47] GET /healthz: (80.96µs) 200 [kube-probe/1.15+ 127.0.0.1:41268]
I0427 01:34:21.389439       1 wrap.go:47] GET /healthz: (66.638µs) 200 [kube-probe/1.15+ 127.0.0.1:41302]
I0427 01:34:31.389356       1 wrap.go:47] GET /healthz: (61.406µs) 200 [kube-probe/1.15+ 127.0.0.1:41334]
I0427 01:34:41.389558       1 wrap.go:47] GET /healthz: (70.577µs) 200 [kube-probe/1.15+ 127.0.0.1:41384]
I0427 01:34:51.389390       1 wrap.go:47] GET /healthz: (71.67µs) 200 [kube-probe/1.15+ 127.0.0.1:41416]
I0427 01:35:01.389645       1 wrap.go:47] GET /healthz: (54.248µs) 200 [kube-probe/1.15+ 127.0.0.1:41454]
I0427 01:35:11.389605       1 wrap.go:47] GET /healthz: (72.887µs) 200 [kube-probe/1.15+ 127.0.0.1:41490]
I0427 01:35:21.389697       1 wrap.go:47] GET /healthz: (71.927µs) 200 [kube-probe/1.15+ 127.0.0.1:41522]
I0427 01:35:22.837739       1 reflector.go:384] k8s.io/client-go/informers/factory.go:133: Watch close - *v1.StorageClass total 0 items received
I0427 01:35:25.805637       1 reflector.go:384] k8s.io/client-go/informers/factory.go:133: Watch close - *v1beta1.PodDisruptionBudget total 0 items received
I0427 01:35:31.389290       1 wrap.go:47] GET /healthz: (64.934µs) 200 [kube-probe/1.15+ 127.0.0.1:41554]
I0427 01:35:41.389442       1 wrap.go:47] GET /healthz: (50.23µs) 200 [kube-probe/1.15+ 127.0.0.1:41604]
I0427 01:35:42.815381       1 reflector.go:384] k8s.io/client-go/informers/factory.go:133: Watch close - *v1.PersistentVolume total 0 items received
I0427 01:35:51.389626       1 wrap.go:47] GET /healthz: (74.11µs) 200 [kube-probe/1.15+ 127.0.0.1:41638]
I0427 01:35:59.809921       1 reflector.go:384] k8s.io/client-go/informers/factory.go:133: Watch close - *v1.ReplicationController total 17 items received
I0427 01:36:01.389614       1 wrap.go:47] GET /healthz: (71.863µs) 200 [kube-probe/1.15+ 127.0.0.1:41674]
I0427 01:36:11.389374       1 wrap.go:47] GET /healthz: (64.534µs) 200 [kube-probe/1.15+ 127.0.0.1:41710]
I0427 01:36:21.391030       1 wrap.go:47] GET /healthz: (66.685µs) 200 [kube-probe/1.15+ 127.0.0.1:41744]
I0427 01:36:31.389707       1 wrap.go:47] GET /healthz: (74.318µs) 200 [kube-probe/1.15+ 127.0.0.1:41776]
I0427 01:36:41.389646       1 wrap.go:47] GET /healthz: (70.449µs) 200 [kube-probe/1.15+ 127.0.0.1:41826]
I0427 01:36:51.389727       1 wrap.go:47] GET /healthz: (77.163µs) 200 [kube-probe/1.15+ 127.0.0.1:41858]
I0427 01:37:01.389639       1 wrap.go:47] GET /healthz: (79.486µs) 200 [kube-probe/1.15+ 127.0.0.1:41894]
I0427 01:37:11.389642       1 wrap.go:47] GET /healthz: (69.232µs) 200 [kube-probe/1.15+ 127.0.0.1:41932]
I0427 01:37:21.389748       1 wrap.go:47] GET /healthz: (84.026µs) 200 [kube-probe/1.15+ 127.0.0.1:41964]
I0427 01:37:31.389618       1 wrap.go:47] GET /healthz: (72.753µs) 200 [kube-probe/1.15+ 127.0.0.1:41998]
I0427 01:37:41.390235       1 wrap.go:47] GET /healthz: (79.994µs) 200 [kube-probe/1.15+ 127.0.0.1:42048]
I0427 01:37:51.389618       1 wrap.go:47] GET /healthz: (63.946µs) 200 [kube-probe/1.15+ 127.0.0.1:42080]
I0427 01:38:01.389324       1 wrap.go:47] GET /healthz: (46.263µs) 200 [kube-probe/1.15+ 127.0.0.1:42116]
I0427 01:38:11.389826       1 wrap.go:47] GET /healthz: (71.592µs) 200 [kube-probe/1.15+ 127.0.0.1:42152]
I0427 01:38:18.844405       1 reflector.go:384] k8s.io/client-go/informers/factory.go:133: Watch close - *v1.StatefulSet total 0 items received
I0427 01:38:21.389848       1 wrap.go:47] GET /healthz: (89.227µs) 200 [kube-probe/1.15+ 127.0.0.1:42186]
I0427 01:38:23.714823       1 scheduling_queue.go:895] About to try and schedule pod var-expansion-9025/var-expansion-6fa3f451-97d7-4181-9722-044c2a5dce2c
I0427 01:38:23.714843       1 scheduler.go:454] Attempting to schedule pod: var-expansion-9025/var-expansion-6fa3f451-97d7-4181-9722-044c2a5dce2c
I0427 01:38:23.715355       1 scheduler_binder.go:255] AssumePodVolumes for pod "var-expansion-9025/var-expansion-6fa3f451-97d7-4181-9722-044c2a5dce2c", node "e2e-test-peterhornyack-windows-node-group-mdn5"
I0427 01:38:23.715368       1 scheduler_binder.go:265] AssumePodVolumes for pod "var-expansion-9025/var-expansion-6fa3f451-97d7-4181-9722-044c2a5dce2c", node "e2e-test-peterhornyack-windows-node-group-mdn5": all PVCs bound and nothing to do
I0427 01:38:23.715426       1 factory.go:734] Attempting to bind var-expansion-6fa3f451-97d7-4181-9722-044c2a5dce2c to e2e-test-peterhornyack-windows-node-group-mdn5
I0427 01:38:23.721310       1 scheduler.go:575] pod var-expansion-9025/var-expansion-6fa3f451-97d7-4181-9722-044c2a5dce2c is bound successfully on node e2e-test-peterhornyack-windows-node-group-mdn5, 5 nodes evaluated, 2 nodes were found feasible
I0427 01:38:31.389756       1 wrap.go:47] GET /healthz: (91.304µs) 200 [kube-probe/1.15+ 127.0.0.1:42220]
I0427 01:38:35.820283       1 reflector.go:384] k8s.io/client-go/informers/factory.go:133: Watch close - *v1.Node total 46 items received
I0427 01:38:40.088129       1 scheduling_queue.go:895] About to try and schedule pod container-lifecycle-hook-450/pod-handle-http-request
I0427 01:38:40.088230       1 scheduler.go:454] Attempting to schedule pod: container-lifecycle-hook-450/pod-handle-http-request
I0427 01:38:40.088657       1 scheduler_binder.go:255] AssumePodVolumes for pod "container-lifecycle-hook-450/pod-handle-http-request", node "e2e-test-peterhornyack-windows-node-group-9bnh"
I0427 01:38:40.088668       1 scheduler_binder.go:265] AssumePodVolumes for pod "container-lifecycle-hook-450/pod-handle-http-request", node "e2e-test-peterhornyack-windows-node-group-9bnh": all PVCs bound and nothing to do
I0427 01:38:40.088716       1 factory.go:734] Attempting to bind pod-handle-http-request to e2e-test-peterhornyack-windows-node-group-9bnh
I0427 01:38:40.094069       1 scheduler.go:575] pod container-lifecycle-hook-450/pod-handle-http-request is bound successfully on node e2e-test-peterhornyack-windows-node-group-9bnh, 5 nodes evaluated, 2 nodes were found feasible
I0427 01:38:41.389235       1 wrap.go:47] GET /healthz: (72.549µs) 200 [kube-probe/1.15+ 127.0.0.1:42270]
I0427 01:38:48.256103       1 scheduling_queue.go:895] About to try and schedule pod container-lifecycle-hook-450/pod-with-poststart-http-hook
I0427 01:38:48.256116       1 scheduler.go:454] Attempting to schedule pod: container-lifecycle-hook-450/pod-with-poststart-http-hook
I0427 01:38:48.256966       1 scheduler_binder.go:255] AssumePodVolumes for pod "container-lifecycle-hook-450/pod-with-poststart-http-hook", node "e2e-test-peterhornyack-windows-node-group-mdn5"
I0427 01:38:48.256979       1 scheduler_binder.go:265] AssumePodVolumes for pod "container-lifecycle-hook-450/pod-with-poststart-http-hook", node "e2e-test-peterhornyack-windows-node-group-mdn5": all PVCs bound and nothing to do
I0427 01:38:48.257474       1 factory.go:734] Attempting to bind pod-with-poststart-http-hook to e2e-test-peterhornyack-windows-node-group-mdn5
I0427 01:38:48.264821       1 scheduler.go:575] pod container-lifecycle-hook-450/pod-with-poststart-http-hook is bound successfully on node e2e-test-peterhornyack-windows-node-group-mdn5, 5 nodes evaluated, 2 nodes were found feasible
I0427 01:38:51.389408       1 wrap.go:47] GET /healthz: (54.134µs) 200 [kube-probe/1.15+ 127.0.0.1:42304]
I0427 01:39:01.389507       1 wrap.go:47] GET /healthz: (71.181µs) 200 [kube-probe/1.15+ 127.0.0.1:42340]
I0427 01:39:11.390023       1 wrap.go:47] GET /healthz: (75.305µs) 200 [kube-probe/1.15+ 127.0.0.1:42378]
I0427 01:39:20.824574       1 reflector.go:384] k8s.io/client-go/informers/factory.go:133: Watch close - *v1.ReplicaSet total 0 items received
I0427 01:39:21.389609       1 wrap.go:47] GET /healthz: (71.227µs) 200 [kube-probe/1.15+ 127.0.0.1:42414]
I0427 01:39:26.626545       1 scheduling_queue.go:895] About to try and schedule pod gc-1097/pod1
I0427 01:39:26.626559       1 scheduler.go:454] Attempting to schedule pod: gc-1097/pod1
I0427 01:39:26.627648       1 scheduler_binder.go:255] AssumePodVolumes for pod "gc-1097/pod1", node "e2e-test-peterhornyack-windows-node-group-9bnh"
I0427 01:39:26.627659       1 scheduler_binder.go:265] AssumePodVolumes for pod "gc-1097/pod1", node "e2e-test-peterhornyack-windows-node-group-9bnh": all PVCs bound and nothing to do
I0427 01:39:26.627723       1 factory.go:734] Attempting to bind pod1 to e2e-test-peterhornyack-windows-node-group-9bnh
I0427 01:39:26.631754       1 scheduler.go:575] pod gc-1097/pod1 is bound successfully on node e2e-test-peterhornyack-windows-node-group-9bnh, 5 nodes evaluated, 2 nodes were found feasible
I0427 01:39:26.669745       1 scheduling_queue.go:895] About to try and schedule pod gc-1097/pod2
I0427 01:39:26.669758       1 scheduler.go:454] Attempting to schedule pod: gc-1097/pod2
I0427 01:39:26.669985       1 scheduler_binder.go:255] AssumePodVolumes for pod "gc-1097/pod2", node "e2e-test-peterhornyack-windows-node-group-mdn5"
I0427 01:39:26.669996       1 scheduler_binder.go:265] AssumePodVolumes for pod "gc-1097/pod2", node "e2e-test-peterhornyack-windows-node-group-mdn5": all PVCs bound and nothing to do
I0427 01:39:26.670029       1 factory.go:734] Attempting to bind pod2 to e2e-test-peterhornyack-windows-node-group-mdn5
I0427 01:39:26.676422       1 scheduler.go:575] pod gc-1097/pod2 is bound successfully on node e2e-test-peterhornyack-windows-node-group-mdn5, 5 nodes evaluated, 2 nodes were found feasible
I0427 01:39:26.716628       1 scheduling_queue.go:895] About to try and schedule pod gc-1097/pod3
I0427 01:39:26.716641       1 scheduler.go:454] Attempting to schedule pod: gc-1097/pod3
I0427 01:39:26.716961       1 scheduler_binder.go:255] AssumePodVolumes for pod "gc-1097/pod3", node "e2e-test-peterhornyack-windows-node-group-9bnh"
I0427 01:39:26.716973       1 scheduler_binder.go:265] AssumePodVolumes for pod "gc-1097/pod3", node "e2e-test-peterhornyack-windows-node-group-9bnh": all PVCs bound and nothing to do
I0427 01:39:26.717025       1 factory.go:734] Attempting to bind pod3 to e2e-test-peterhornyack-windows-node-group-9bnh
I0427 01:39:26.723188       1 scheduler.go:575] pod gc-1097/pod3 is bound successfully on node e2e-test-peterhornyack-windows-node-group-9bnh, 5 nodes evaluated, 2 nodes were found feasible
I0427 01:39:31.389643       1 wrap.go:47] GET /healthz: (70.631µs) 200 [kube-probe/1.15+ 127.0.0.1:42446]
I0427 01:39:41.390382       1 wrap.go:47] GET /healthz: (81.918µs) 200 [kube-probe/1.15+ 127.0.0.1:42496]
I0427 01:39:49.099512       1 scheduling_queue.go:895] About to try and schedule pod volume-7520/gcepd-injector-8pqm
I0427 01:39:49.099526       1 scheduler.go:454] Attempting to schedule pod: volume-7520/gcepd-injector-8pqm
I0427 01:39:49.099780       1 scheduler_binder.go:651] All bound volumes for Pod "volume-7520/gcepd-injector-8pqm" match with Node "e2e-test-peterhornyack-windows-node-group-mdn5"
I0427 01:39:49.099842       1 scheduler_binder.go:651] All bound volumes for Pod "volume-7520/gcepd-injector-8pqm" match with Node "e2e-test-peterhornyack-windows-node-group-9bnh"
I0427 01:39:49.099980       1 scheduler_binder.go:255] AssumePodVolumes for pod "volume-7520/gcepd-injector-8pqm", node "e2e-test-peterhornyack-windows-node-group-mdn5"
I0427 01:39:49.099991       1 scheduler_binder.go:265] AssumePodVolumes for pod "volume-7520/gcepd-injector-8pqm", node "e2e-test-peterhornyack-windows-node-group-mdn5": all PVCs bound and nothing to do
I0427 01:39:49.100027       1 factory.go:734] Attempting to bind gcepd-injector-8pqm to e2e-test-peterhornyack-windows-node-group-mdn5
I0427 01:39:49.106558       1 scheduler.go:575] pod volume-7520/gcepd-injector-8pqm is bound successfully on node e2e-test-peterhornyack-windows-node-group-mdn5, 5 nodes evaluated, 2 nodes were found feasible
I0427 01:39:51.389651       1 wrap.go:47] GET /healthz: (70.4µs) 200 [kube-probe/1.15+ 127.0.0.1:42538]
I0427 01:39:52.834392       1 reflector.go:384] k8s.io/client-go/informers/factory.go:133: Watch close - *v1.PersistentVolumeClaim total 3 items received
I0427 01:40:01.390198       1 wrap.go:47] GET /healthz: (89.657µs) 200 [kube-probe/1.15+ 127.0.0.1:42576]
I0427 01:40:11.389562       1 wrap.go:47] GET /healthz: (72.656µs) 200 [kube-probe/1.15+ 127.0.0.1:42614]
I0427 01:40:19.861940       1 scheduling_queue.go:895] About to try and schedule pod volume-7520/gcepd-client
I0427 01:40:19.861951       1 scheduler.go:454] Attempting to schedule pod: volume-7520/gcepd-client
I0427 01:40:19.863209       1 scheduler_binder.go:651] All bound volumes for Pod "volume-7520/gcepd-client" match with Node "e2e-test-peterhornyack-windows-node-group-mdn5"
I0427 01:40:19.863292       1 scheduler_binder.go:651] All bound volumes for Pod "volume-7520/gcepd-client" match with Node "e2e-test-peterhornyack-windows-node-group-9bnh"
I0427 01:40:19.863565       1 scheduler_binder.go:255] AssumePodVolumes for pod "volume-7520/gcepd-client", node "e2e-test-peterhornyack-windows-node-group-9bnh"
I0427 01:40:19.863577       1 scheduler_binder.go:265] AssumePodVolumes for pod "volume-7520/gcepd-client", node "e2e-test-peterhornyack-windows-node-group-9bnh": all PVCs bound and nothing to do
I0427 01:40:19.863614       1 factory.go:734] Attempting to bind gcepd-client to e2e-test-peterhornyack-windows-node-group-9bnh
I0427 01:40:19.868257       1 scheduler.go:575] pod volume-7520/gcepd-client is bound successfully on node e2e-test-peterhornyack-windows-node-group-9bnh, 5 nodes evaluated, 2 nodes were found feasible
I0427 01:40:21.389490       1 wrap.go:47] GET /healthz: (91.857µs) 200 [kube-probe/1.15+ 127.0.0.1:42646]
I0427 01:40:25.825451       1 reflector.go:384] cmd/kube-scheduler/app/server.go:223: Watch close - *v1.Pod total 145 items received
I0427 01:40:30.808035       1 reflector.go:384] k8s.io/client-go/informers/factory.go:133: Watch close - *v1beta1.PodDisruptionBudget total 0 items received
I0427 01:40:31.389412       1 wrap.go:47] GET /healthz: (61.773µs) 200 [kube-probe/1.15+ 127.0.0.1:42678]
I0427 01:40:41.389646       1 wrap.go:47] GET /healthz: (71.819µs) 200 [kube-probe/1.15+ 127.0.0.1:42728]
I0427 01:40:51.389719       1 wrap.go:47] GET /healthz: (63.342µs) 200 [kube-probe/1.15+ 127.0.0.1:42762]
I0427 01:41:01.389322       1 wrap.go:47] GET /healthz: (46.058µs) 200 [kube-probe/1.15+ 127.0.0.1:42800]
I0427 01:41:11.389702       1 wrap.go:47] GET /healthz: (81.111µs) 200 [kube-probe/1.15+ 127.0.0.1:42842]
I0427 01:41:21.389610       1 wrap.go:47] GET /healthz: (72.248µs) 200 [kube-probe/1.15+ 127.0.0.1:42878]
I0427 01:41:27.785252       1 reflector.go:384] k8s.io/client-go/informers/factory.go:133: Watch close - *v1.Service total 0 items received
I0427 01:41:31.389852       1 wrap.go:47] GET /healthz: (77.54µs) 200 [kube-probe/1.15+ 127.0.0.1:42916]
I0427 01:41:41.389544       1 wrap.go:47] GET /healthz: (73.138µs) 200 [kube-probe/1.15+ 127.0.0.1:42970]
I0427 01:41:51.389874       1 wrap.go:47] GET /healthz: (56.929µs) 200 [kube-probe/1.15+ 127.0.0.1:43004]
I0427 01:42:01.391332       1 wrap.go:47] GET /healthz: (69.49µs) 200 [kube-probe/1.15+ 127.0.0.1:43040]
I0427 01:42:11.389592       1 wrap.go:47] GET /healthz: (73.336µs) 200 [kube-probe/1.15+ 127.0.0.1:43076]
I0427 01:42:21.389380       1 wrap.go:47] GET /healthz: (63.533µs) 200 [kube-probe/1.15+ 127.0.0.1:43108]
I0427 01:42:31.389454       1 wrap.go:47] GET /healthz: (55.734µs) 200 [kube-probe/1.15+ 127.0.0.1:43140]
I0427 01:42:41.389598       1 wrap.go:47] GET /healthz: (69.5µs) 200 [kube-probe/1.15+ 127.0.0.1:43192]
I0427 01:42:51.389740       1 wrap.go:47] GET /healthz: (84.626µs) 200 [kube-probe/1.15+ 127.0.0.1:43226]
I0427 01:43:01.389652       1 wrap.go:47] GET /healthz: (74.137µs) 200 [kube-probe/1.15+ 127.0.0.1:43262]
I0427 01:43:11.389675       1 wrap.go:47] GET /healthz: (73.849µs) 200 [kube-probe/1.15+ 127.0.0.1:43298]
I0427 01:43:21.393411       1 wrap.go:47] GET /healthz: (78.203µs) 200 [kube-probe/1.15+ 127.0.0.1:43330]
